<?xml version="1.0" ?>
<!-- =================================================================================== -->
<!-- |    This document was autogenerated by xacro from /home/fandes/workspace/kuavo-ros-control/src/humanoid-control/humanoid_interface_drake/models/biped_gen4.0/urdf/Larm.xacro | -->
<!-- |    EDITING THIS FILE BY HAND IS NOT RECOMMENDED                                 | -->
<!-- =================================================================================== -->
<robot name="Larm" xmlns:drake="https://drake.mit.edu">
  <!-- =========================================================== Arms ================================================================= -->
  <link name="l_arm_pitch">
    <inertial>
      <origin rpy="0 0 0" xyz="0.0146835191418715 -0.0166604103758634 -6.82857133371129E-05"/>
      <mass value="0.794"/>
      <inertia ixx="0.0002674432873971" ixy="-2.5654089149164E-05" ixz="-1.72966133127553E-07" iyy="0.000125796784291983" iyz="-1.66717296343013E-06" izz="0.000196186976742156"/>
    </inertial>
    <visual>
      <origin rpy="0 0 0" xyz="0 0 0"/>
      <geometry>
        <mesh filename="../../meshes/l_arm_pitch.STL"/>
      </geometry>
      <material name="">
        <color rgba="1 1 1 1"/>
      </material>
    </visual>
  </link>
  <joint name="l_arm_pitch" type="continuous">
    <origin rpy="0 0 0" xyz="-0.0175475823124921 0.254700000000031 0.324500000000024"/>
    <parent link="torso"/>
    <child link="l_arm_pitch"/>
    <axis xyz="0 1 0"/>
    <limit effort="100" lower="-1.57" upper="1.57" velocity="35"/>
  </joint>
  <transmission type="SimpleTransmission">
    <joint name="l_arm_pitch"/>
    <actuator name="l_arm_pitch_motor"/>
  </transmission>
  <link name="l_arm_roll">
    <inertial>
      <origin rpy="0 0 0" xyz="0.0222872651779299 0.0156945544195473 -0.0202262244341484"/>
      <mass value="0.20735"/>
      <inertia ixx="0.000160370067223081" ixy="6.30811840859269E-06" ixz="-1.13259246453495E-05" iyy="0.000262365778589962" iyz="3.14941259087024E-05" izz="0.00023601403628197"/>
    </inertial>
    <visual>
      <origin rpy="0 0 0" xyz="0 0 0"/>
      <geometry>
        <mesh filename="../../meshes/l_arm_roll.STL"/>
      </geometry>
      <material name="">
        <color rgba="1 1 1 1"/>
      </material>
    </visual>
  </link>
  <joint name="l_arm_roll" type="continuous">
    <origin rpy="0 0 0" xyz="0 0 0"/>
    <parent link="l_arm_pitch"/>
    <child link="l_arm_roll"/>
    <axis xyz="1 0 0"/>
    <limit effort="100" lower="-1.57" upper="1.57" velocity="35"/>
  </joint>
  <transmission type="SimpleTransmission">
    <joint name="l_arm_roll"/>
    <actuator name="l_arm_roll_motor"/>
  </transmission>
  <link name="l_arm_yaw">
    <inertial>
      <origin rpy="0 0 0" xyz="6.16940440451783E-05 0.00525815062784063 -0.128821944854616"/>
      <mass value="1.120632"/>
      <inertia ixx="7.00575957554699E-05" ixy="-6.81658291272877E-10" ixz="2.69427050743199E-10" iyy="8.53612265336777E-05" iyz="6.95899873075699E-06" izz="8.82223899453285E-05"/>
    </inertial>
    <visual>
      <origin rpy="0 0 0" xyz="0 0 0"/>
      <geometry>
        <mesh filename="../../meshes/l_arm_yaw.STL"/>
      </geometry>
      <material name="">
        <color rgba="1 1 1 1"/>
      </material>
    </visual>
  </link>
  <joint name="l_arm_yaw" type="continuous">
    <origin rpy="0 0 0" xyz="0 0 0"/>
    <parent link="l_arm_roll"/>
    <child link="l_arm_yaw"/>
    <axis xyz="0 0 1"/>
    <limit effort="100" lower="-1.57" upper="1.57" velocity="35"/>
  </joint>
  <transmission type="SimpleTransmission">
    <joint name="l_arm_yaw"/>
    <actuator name="l_arm_yaw_motor"/>
  </transmission>
  <link name="l_forearm_pitch">
    <inertial>
      <origin rpy="0 0 0" xyz="-1.4281929799409E-05 0.00938313949959718 -0.0522687552263489"/>
      <mass value="0.395825"/>
      <inertia ixx="9.558084476069E-05" ixy="-4.53863490387433E-08" ixz="5.39342118513253E-08" iyy="0.000126326373178391" iyz="-9.58160032696958E-06" izz="0.000121032474884238"/>
    </inertial>
    <visual>
      <origin rpy="0 0 0" xyz="0 0 0"/>
      <geometry>
        <mesh filename="../../meshes/l_forearm_pitch.STL"/>
      </geometry>
      <material name="">
        <color rgba="1 1 1 1"/>
      </material>
    </visual>
  </link>
  <joint name="l_forearm_pitch" type="continuous">
    <origin rpy="0 0 0" xyz="0 0 -0.163599999999998"/>
    <parent link="l_arm_yaw"/>
    <child link="l_forearm_pitch"/>
    <axis xyz="0 1 0"/>
    <limit effort="100" lower="-1.57" upper="1.57" velocity="35"/>
  </joint>
  <transmission type="SimpleTransmission">
    <joint name="l_forearm_pitch"/>
    <actuator name="l_forearm_pitch_motor"/>
  </transmission>
  <link name="l_hand_yaw">
    <inertial>
      <origin rpy="0 0 0" xyz="0.000113133463122583 0.00969227839919062 0.0817960696431681"/>
      <mass value="0.380792"/>
      <inertia ixx="7.64923984145487E-05" ixy="8.51098127601464E-09" ixz="-1.4070355859132E-08" iyy="0.000122231132554914" iyz="1.11226968994633E-06" izz="8.44935061342021E-05"/>
    </inertial>
    <visual>
      <origin rpy="0 0 0" xyz="0 0 0"/>
      <geometry>
        <mesh filename="../../meshes/l_hand_yaw.STL"/>
      </geometry>
      <material name="">
        <color rgba="1 1 1 1"/>
      </material>
    </visual>
  </link>
  <joint name="l_hand_yaw" type="continuous">
    <origin rpy="0 0 0" xyz="0 0 -0.191049997298861"/>
    <parent link="l_forearm_pitch"/>
    <child link="l_hand_yaw"/>
    <axis xyz="0 0 1"/>
    <limit effort="100" lower="-1.57" upper="1.57" velocity="35"/>
  </joint>
  <transmission type="SimpleTransmission">
    <joint name="l_hand_yaw"/>
    <actuator name="l_hand_yaw_motor"/>
  </transmission>
  <link name="l_hand_pitch">
    <inertial>
      <origin rpy="0 0 0" xyz="0.00810609786663821 0.00489663150092601 0.00622488608908427"/>
      <mass value="0.376651"/>
      <inertia ixx="4.77321490368476E-05" ixy="3.05261917457107E-06" ixz="4.77827164947654E-06" iyy="3.43814769749139E-05" iyz="-4.59311499587155E-06" izz="2.49955336560135E-05"/>
    </inertial>
    <visual>
      <origin rpy="0 0 0" xyz="0 0 0"/>
      <geometry>
        <mesh filename="../../meshes/l_hand_pitch.STL"/>
      </geometry>
      <material name="">
        <color rgba="1 1 1 1"/>
      </material>
    </visual>
  </link>
  <joint name="l_hand_pitch" type="continuous">
    <origin rpy="0 0 0" xyz="0 0 0"/>
    <parent link="l_hand_yaw"/>
    <child link="l_hand_pitch"/>
    <axis xyz="0 1 0"/>
    <limit effort="100" lower="-1.57" upper="1.57" velocity="35"/>
  </joint>
  <transmission type="SimpleTransmission">
    <joint name="l_hand_pitch"/>
    <actuator name="l_hand_pitch_motor"/>
  </transmission>
  <link name="l_hand_roll">
    <inertial>
      <origin rpy="0 0 0" xyz="0.0055750097939089 0.00647363667890594 -0.0826245715087526"/>
      <mass value="0.704669"/>
      <inertia ixx="8.04371746531483E-05" ixy="2.770174858381E-07" ixz="-4.63354764745673E-06" iyy="0.000116536814280971" iyz="1.04534418501281E-05" izz="0.000111690600253046"/>
    </inertial>
    <visual>
      <origin rpy="0 0 0" xyz="0 0 0"/>
      <geometry>
        <mesh filename="../../meshes/l_hand_roll.STL"/>
      </geometry>
      <material name="">
        <color rgba="1 1 1 1"/>
      </material>
    </visual>
  </link>
  <joint name="l_hand_roll" type="continuous">
    <origin rpy="0 0 0" xyz="0 0 0"/>
    <parent link="l_hand_pitch"/>
    <child link="l_hand_roll"/>
    <axis xyz="1 0 0"/>
    <limit effort="100" lower="-1.57" upper="1.57" velocity="35"/>
  </joint>
  <transmission type="SimpleTransmission">
    <joint name="l_hand_roll"/>
    <actuator name="l_hand_roll_motor"/>
  </transmission>
  <!-- end frame -->
  <!-- <frame link="l_hand_pitch" name="l_hand_sole" xyz="0 0 -0.1" /> -->
</robot>

