<?xml version="1.0" ?>
<!-- =================================================================================== -->
<!-- |    This document was autogenerated by xacro from /home/fandes/workspace/kuavo-ros-control/src/humanoid-control/humanoid_interface_drake/models/biped_gen4.0/urdf/Rarm.xacro | -->
<!-- |    EDITING THIS FILE BY HAND IS NOT RECOMMENDED                                 | -->
<!-- =================================================================================== -->
<robot name="Rarm" xmlns:drake="https://drake.mit.edu">
  <!-- right arm -->
  <link name="r_arm_pitch">
    <inertial>
      <origin rpy="0 0 0" xyz="0.0146743511434554 0.0168298008224051 -8.16711977456031E-05"/>
      <mass value="0.794"/>
      <inertia ixx="0.000267364314112701" ixy="2.58822573731612E-05" ixz="-1.74450019197634E-07" iyy="0.000125724274127356" iyz="1.71810516637517E-06" izz="0.000196179895851995"/>
    </inertial>
    <visual>
      <origin rpy="0 0 0" xyz="0 0 0"/>
      <geometry>
        <mesh filename="../../meshes/r_arm_pitch.STL"/>
      </geometry>
      <material name="">
        <color rgba="1 1 1 1"/>
      </material>
    </visual>
  </link>
  <joint name="r_arm_pitch" type="continuous">
    <origin rpy="0 0 0" xyz="-0.0175475823119764 -0.254700000000003 0.324500000000024"/>
    <parent link="torso"/>
    <child link="r_arm_pitch"/>
    <axis xyz="0 1 0"/>
    <limit effort="100" lower="-1.57" upper="1.57" velocity="35"/>
  </joint>
  <transmission type="SimpleTransmission">
    <joint name="r_arm_pitch"/>
    <actuator name="r_arm_pitch_motor"/>
  </transmission>
  <link name="r_arm_roll">
    <inertial>
      <origin rpy="0 0 0" xyz="0.0223009070030529 -0.0156950170482436 -0.0202307747650334"/>
      <mass value="0.20735"/>
      <inertia ixx="0.00016058853411588" ixy="-6.25733649402466E-06" ixz="-1.13236198708706E-05" iyy="0.000262566981542989" iyz="-3.14930415013909E-05" izz="0.000236151535262186"/>
    </inertial>
    <visual>
      <origin rpy="0 0 0" xyz="0 0 0"/>
      <geometry>
        <mesh filename="../../meshes/r_arm_roll.STL"/>
      </geometry>
      <material name="">
        <color rgba="1 1 1 1"/>
      </material>
    </visual>
  </link>
  <joint name="r_arm_roll" type="continuous">
    <origin rpy="0 0 0" xyz="0 0 0"/>
    <parent link="r_arm_pitch"/>
    <child link="r_arm_roll"/>
    <axis xyz="1 0 0"/>
    <limit effort="100" lower="-1.57" upper="1.57" velocity="35"/>
  </joint>
  <transmission type="SimpleTransmission">
    <joint name="r_arm_roll"/>
    <actuator name="r_arm_roll_motor"/>
  </transmission>
  <link name="r_arm_yaw">
    <inertial>
      <origin rpy="0 0 0" xyz="-4.82749435400213E-05 -0.0052581506278393 -0.128821944854617"/>
      <mass value="1.120632"/>
      <inertia ixx="7.00575957554697E-05" ixy="-6.81658260938682E-10" ixz="-2.69427064597612E-10" iyy="8.53612265336775E-05" iyz="-6.95899873075696E-06" izz="8.82223899453284E-05"/>
    </inertial>
    <visual>
      <origin rpy="0 0 0" xyz="0 0 0"/>
      <geometry>
        <mesh filename="../../meshes/r_arm_yaw.STL"/>
      </geometry>
      <material name="">
        <color rgba="1 1 1 1"/>
      </material>
    </visual>
  </link>
  <joint name="r_arm_yaw" type="continuous">
    <origin rpy="0 0 0" xyz="0 0 0"/>
    <parent link="r_arm_roll"/>
    <child link="r_arm_yaw"/>
    <axis xyz="0 0 1"/>
    <limit effort="100" lower="-1.57" upper="1.57" velocity="35"/>
  </joint>
  <transmission type="SimpleTransmission">
    <joint name="r_arm_yaw"/>
    <actuator name="r_arm_yaw_motor"/>
  </transmission>
  <link name="r_forearm_pitch">
    <inertial>
      <origin rpy="0 0 0" xyz="-0.000127232990745116 -0.00951602649232586 -0.0522687552263488"/>
      <mass value="0.395825"/>
      <inertia ixx="9.55808447606916E-05" ixy="-4.53863489774233E-08" ixz="-5.41060583443891E-08" iyy="0.000126326373178394" iyz="9.40982665987077E-06" izz="0.00012103247488424"/>
    </inertial>
    <visual>
      <origin rpy="0 0 0" xyz="0 0 0"/>
      <geometry>
        <mesh filename="../../meshes/r_forearm_pitch.STL"/>
      </geometry>
      <material name="">
        <color rgba="1 1 1 1"/>
      </material>
    </visual>
  </link>
  <joint name="r_forearm_pitch" type="continuous">
    <origin rpy="0 0 0" xyz="0 0 -0.1636"/>
    <parent link="r_arm_yaw"/>
    <child link="r_forearm_pitch"/>
    <axis xyz="0 1 0"/>
    <limit effort="100" lower="-1.57" upper="1.57" velocity="35"/>
  </joint>
  <transmission type="SimpleTransmission">
    <joint name="r_forearm_pitch"/>
    <actuator name="r_forearm_pitch_motor"/>
  </transmission>
  <link name="r_hand_yaw">
    <inertial>
      <origin rpy="0 0 0" xyz="-0.000113133331993445 -0.0097448351680483 0.0817960724173413"/>
      <mass value="0.380792"/>
      <inertia ixx="7.64923982725728E-05" ixy="8.51115986496426E-09" ixz="1.40703608309957E-08" iyy="0.000122231132626729" iyz="-1.11226978982942E-06" izz="8.44935061081861E-05"/>
    </inertial>
    <visual>
      <origin rpy="0 0 0" xyz="0 0 0"/>
      <geometry>
        <mesh filename="../../meshes/r_hand_yaw.STL"/>
      </geometry>
      <material name="">
        <color rgba="1 1 1 1"/>
      </material>
    </visual>
  </link>
  <joint name="r_hand_yaw" type="continuous">
    <origin rpy="0 0 0" xyz="0 0 -0.191050000125729"/>
    <parent link="r_forearm_pitch"/>
    <child link="r_hand_yaw"/>
    <axis xyz="0 0 1"/>
    <limit effort="100" lower="-1.57" upper="1.57" velocity="35"/>
  </joint>
  <transmission type="SimpleTransmission">
    <joint name="r_hand_yaw"/>
    <actuator name="r_hand_yaw_motor"/>
  </transmission>
  <link name="r_hand_pitch">
    <inertial>
      <origin rpy="0 0 0" xyz="0.00735986990228184 -0.0047523802551166 0.00605888061339196"/>
      <mass value="0.376651"/>
      <inertia ixx="4.77321358097824E-05" ixy="-2.99709432812988E-06" ixz="4.71488437974188E-06" iyy="3.42470226388499E-05" iyz="4.61094199971347E-06" izz="2.51299600072388E-05"/>
    </inertial>
    <visual>
      <origin rpy="0 0 0" xyz="0 0 0"/>
      <geometry>
        <mesh filename="../../meshes/r_hand_pitch.STL"/>
      </geometry>
      <material name="">
        <color rgba="1 1 1 1"/>
      </material>
    </visual>
  </link>
  <joint name="r_hand_pitch" type="continuous">
    <origin rpy="0 0 0" xyz="0 0 0"/>
    <parent link="r_hand_yaw"/>
    <child link="r_hand_pitch"/>
    <axis xyz="0 1 0"/>
    <limit effort="100" lower="-1.57" upper="1.57" velocity="35"/>
  </joint>
  <transmission type="SimpleTransmission">
    <joint name="r_hand_pitch"/>
    <actuator name="r_hand_pitch_motor"/>
  </transmission>
  <link name="r_hand_roll">
    <inertial>
      <origin rpy="0 0 0" xyz="0.0045944493552252 -0.00586927010446042 -0.0836324643988434"/>
      <mass value="0.704669"/>
      <inertia ixx="0.000160651543151659" ixy="-5.37963063503334E-07" ixz="-9.47669219939636E-06" iyy="0.000229393712149694" iyz="-2.08351527945055E-05" izz="0.000219277776699058"/>
    </inertial>
    <visual>
      <origin rpy="0 0 0" xyz="0 0 0"/>
      <geometry>
        <mesh filename="../../meshes/r_hand_roll.STL"/>
      </geometry>
      <material name="">
        <color rgba="1 1 1 1"/>
      </material>
    </visual>
  </link>
  <joint name="r_hand_roll" type="continuous">
    <origin rpy="0 0 0" xyz="0 0 0"/>
    <parent link="r_hand_pitch"/>
    <child link="r_hand_roll"/>
    <axis xyz="1 0 0"/>
    <limit effort="100" lower="-1.57" upper="1.57" velocity="35"/>
  </joint>
  <transmission type="SimpleTransmission">
    <joint name="r_hand_roll"/>
    <actuator name="r_hand_roll_motor"/>
  </transmission>
  <!-- end frame -->
  <!-- <frame link="r_hand_pitch" name="r_hand_sole" xyz="0 0 -0.1" /> -->
</robot>

