<?xml version="1.0" ?>
<!-- =================================================================================== -->
<!-- |    This document was autogenerated by xacro from /home/fandes/workspace/kuavo-ros-control/src/humanoid-control/humanoid_interface_drake/models/biped_gen4.0/urdf/Rleg.xacro | -->
<!-- |    EDITING THIS FILE BY HAND IS NOT RECOMMENDED                                 | -->
<!-- =================================================================================== -->
<robot name="Rleg" xmlns:drake="https://drake.mit.edu">
  <link name="base_link">
    <inertial>
      <origin rpy="0 0 0" xyz="0.00080045 0.00004225 -0.12049699"/>
      <mass value="1.62911540"/>
      <inertia ixx="0.01343597" ixy="0.00000234" ixz="0.00020391" iyy="0.01359234" iyz="-0.00018311" izz="0.00092149"/>
    </inertial>
    <visual>
      <origin rpy="0 0 0" xyz="0 0 0"/>
      <geometry>
        <mesh filename="../../meshes/r_knee.STL"/>
      </geometry>
      <material name="">
        <color rgba="0.686274509803922 0.658823529411765 0.63921568627451 1"/>
      </material>
    </visual>
  </link>
  <link name="r_foot_pitch">
    <inertial>
      <origin rpy="0 0 0" xyz="0 0.02100018 0"/>
      <mass value="0.05444454"/>
      <inertia ixx="0.00000411" ixy="0" ixz="0" iyy="0.00000411" iyz="0" izz="0.00000728"/>
    </inertial>
    <visual>
      <origin rpy="0 0 0" xyz="0 0 0"/>
      <geometry>
        <mesh filename="../../meshes/r_foot_pitch.STL"/>
      </geometry>
      <material name="">
        <color rgba="0.690196078431373 0.658823529411765 0.63921568627451 1"/>
      </material>
    </visual>
  </link>
  <joint name="r_foot_pitch_joint" type="continuous">
    <origin rpy="0 0 0" xyz="0 0.0022 -0.346"/>
    <parent link="base_link"/>
    <child link="r_foot_pitch"/>
    <axis xyz="0 1 0"/>
    <limit effort="100" lower="-1.57" upper="1.57" velocity="25"/>
  </joint>
  <!--        ssss -->
  <!-- sssssssss -->
  <link name="r_foot_roll">
    <inertial>
      <origin rpy="0 0 0" xyz="-0.03594837 -0.00000972 -0.02713025"/>
      <mass value="0.46707428"/>
      <inertia ixx="0.00040710" ixy="-0.00000016" ixz="-0.00023147" iyy="0.00127525" iyz="0.00000006" izz="0.00135359"/>
    </inertial>
    <visual>
      <origin rpy="0 0 0" xyz="0 0 0"/>
      <geometry>
        <mesh filename="../../meshes/r_foot_roll.STL"/>
      </geometry>
      <material name="">
        <color rgba="0.690196078431373 0.658823529411765 0.63921568627451 1"/>
      </material>
    </visual>
    <visual>
      <origin rpy="0 0 0" xyz="-0.09 0.05 -0.0465"/>
      <geometry>
        <sphere radius="0.005"/>
      </geometry>
    </visual>
    <collision>
      <origin rpy="0 0 0" xyz="-0.09 0.05 -0.0465"/>
      <geometry>
        <sphere radius="0.005"/>
      </geometry>
    </collision>
    <visual>
      <origin rpy="0 0 0" xyz="-0.09 -0.05 -0.0465"/>
      <geometry>
        <sphere radius="0.005"/>
      </geometry>
    </visual>
    <collision>
      <origin rpy="0 0 0" xyz="-0.09 -0.05 -0.0465"/>
      <geometry>
        <sphere radius="0.005"/>
      </geometry>
    </collision>
    <visual>
      <origin rpy="0 0 0" xyz="0.15 0.05 -0.0465"/>
      <geometry>
        <sphere radius="0.005"/>
      </geometry>
    </visual>
    <collision>
      <origin rpy="0 0 0" xyz="0.15 0.05 -0.0465"/>
      <geometry>
        <sphere radius="0.005"/>
      </geometry>
    </collision>
    <visual>
      <origin rpy="0 0 0" xyz="0.15 -0.05 -0.0465"/>
      <geometry>
        <sphere radius="0.005"/>
      </geometry>
    </visual>
    <collision>
      <origin rpy="0 0 0" xyz="0.15 -0.05 -0.0465"/>
      <geometry>
        <sphere radius="0.005"/>
      </geometry>
    </collision>
  </link>
  <joint name="r_foot_roll_joint" type="continuous">
    <origin rpy="0 0 0" xyz="0 0 0"/>
    <parent link="r_foot_pitch"/>
    <child link="r_foot_roll"/>
    <axis xyz="1 0 0"/>
    <limit effort="100" lower="-1.39" upper="0.78" velocity="25"/>
  </joint>
  <!--        ssss -->
  <!-- sssssssss -->
  <link name="r_r_bar_y">
    <inertial>
      <origin rpy="0 0 0" xyz="-0.0176387949701166 0.0012332409395871 0.00472242692632874"/>
      <mass value="0.0413794520732275"/>
      <inertia ixx="6.34865185942549E-06" ixy="2.71679945417066E-06" ixz="4.93236590933488E-06" iyy="2.83792003165434E-05" iyz="-7.27368169902599E-07" izz="2.34510462869433E-05"/>
    </inertial>
    <visual>
      <origin rpy="0 0 0" xyz="0 0 0"/>
      <geometry>
        <mesh filename="../../meshes/r_r_bar.STL"/>
      </geometry>
      <material name="">
        <color rgba="0.690196078431373 0.658823529411765 0.63921568627451 1"/>
      </material>
    </visual>
    <!-- <collision>
      <origin xyz="0 0 0" rpy="0 0 0" />
      <geometry>
        <mesh filename="../../meshes/r_r_bar.STL" />
      </geometry>
    </collision> -->
  </link>
  <joint name="r_r_bar_y" type="continuous">
    <origin rpy="0 0 0" xyz="0 -0.0318 -0.09"/>
    <parent link="base_link"/>
    <child link="r_r_bar_y"/>
    <axis xyz="0 1 0"/>
  </joint>
  <link name="r_r_tendon_y">
    <inertial>
      <origin rpy="0 0 0" xyz="-1.36421989666846E-05 0.000483312127349173 -0.139530966436641"/>
      <mass value="0.132228698944171"/>
      <inertia ixx="0.000491608612358556" ixy="-3.05402199174078E-12" ixz="1.51985653969833E-08" iyy="0.000489725321370326" iyz="2.42627969905164E-07" izz="4.77496090027913E-06"/>
    </inertial>
    <visual>
      <origin rpy="0 0 0" xyz="0 0 0"/>
      <geometry>
        <mesh filename="../../meshes/r_r_tendon.STL"/>
      </geometry>
      <material name="">
        <color rgba="0.690196078431373 0.658823529411765 0.63921568627451 1"/>
      </material>
    </visual>
    <!-- <collision>
      <origin xyz="0 0 0" rpy="0 0 0" />
      <geometry>
        <mesh filename="../../meshes/r_r_tendon.STL" />
      </geometry>
    </collision> -->
  </link>
  <drake:joint name="r_r_tendon_y" type="universal">
    <origin rpy="0 0 0" xyz="-0.056027 0.0085 0.015"/>
    <parent link="r_r_bar_y"/>
    <child link="r_r_tendon_y"/>
  </drake:joint>
  <frame link="r_r_tendon_y" name="r_r_tendon_socket" xyz="0 0 -0.256"/>
  <transmission type="SimpleTransmission">
    <joint name="r_r_bar_y"/>
    <actuator name="r_r_bar_y_motor">
      <drake:gear_ratio value="10.0"/>
      <drake:rotor_inertia value="0.0001002"/>
    </actuator>
  </transmission>
  <link name="r_l_bar_y">
    <inertial>
      <origin rpy="0 0 0" xyz="-0.0176387868876003 -0.00123323826800568 0.00472240978820238"/>
      <mass value="0.0413794348706216"/>
      <inertia ixx="6.34864114001538E-06" ixy="-2.71679701707313E-06" ixz="4.93234664344148E-06" iyy="2.83791841625158E-05" iyz="7.2736352651351E-07" izz="2.34510398457472E-05"/>
    </inertial>
    <visual>
      <origin rpy="0 0 0" xyz="0 0 0"/>
      <geometry>
        <mesh filename="../../meshes/r_l_bar.STL"/>
      </geometry>
      <material name="">
        <color rgba="0.690196078431373 0.658823529411765 0.63921568627451 1"/>
      </material>
    </visual>
    <!-- <collision>
      <origin xyz="0 0 0" rpy="0 0 0" />
      <geometry>
        <mesh filename="../../meshes/r_l_bar.STL" />
      </geometry>
    </collision> -->
  </link>
  <joint name="r_l_bar_y" type="continuous">
    <origin rpy="0 0 0" xyz="0 0.0362 -0.153"/>
    <parent link="base_link"/>
    <child link="r_l_bar_y"/>
    <axis xyz="0 1 0"/>
  </joint>
  <transmission type="SimpleTransmission">
    <joint name="r_l_bar_y"/>
    <actuator name="r_l_bar_y_motor">
      <drake:gear_ratio value="10.0"/>
      <drake:rotor_inertia value="0.0001002"/>
    </actuator>
  </transmission>
  <link name="r_l_tendon_y">
    <inertial>
      <origin rpy="0 0 0" xyz="-1.97765085516513E-05 -0.00047926628765782 -0.106248164342492"/>
      <mass value="0.106425376742002"/>
      <inertia ixx="0.000197199480044112" ixy="-4.20204697681874E-12" ixz="-1.28105270857608E-08" iyy="0.00019587468108075" iyz="-1.73407864727289E-07" izz="3.91523487668242E-06"/>
    </inertial>
    <visual>
      <origin rpy="0 0 0" xyz="0 0 0"/>
      <geometry>
        <mesh filename="../../meshes/r_l_tendon.STL"/>
      </geometry>
      <material name="">
        <color rgba="0.690196078431373 0.658823529411765 0.63921568627451 1"/>
      </material>
    </visual>
    <!-- <collision>
      <origin xyz="0 0 0" rpy="0 0 0" />
      <geometry>
        <mesh filename="../../meshes/r_l_tendon.STL" />
      </geometry>
    </collision> -->
  </link>
  <drake:joint name="r_l_tendon_y" type="universal">
    <origin rpy="0 0 0" xyz="-0.056027 -0.0085 0.015"/>
    <parent link="r_l_bar_y"/>
    <child link="r_l_tendon_y"/>
  </drake:joint>
  <frame link="r_l_tendon_y" name="r_l_tendon_socket" xyz="0 0 -0.193"/>
  <frame link="r_foot_roll" name="r_l_foot_socket" xyz="-0.056027 0.0255 0.015"/>
  <frame link="r_foot_roll" name="r_r_foot_socket" xyz="-0.056027 -0.0255 0.015"/>
  <!-- 曲柄 -->
  <frame link="r_l_bar_y" name="r_l_foot_bar_frame" xyz="0 -0.0085 0"/>
  <frame link="r_r_bar_y" name="r_r_foot_bar_frame" xyz="0 0.0085 0"/>
</robot>

