<?xml version='1.0' encoding='utf-8'?>
<mujoco model="biped_s52">
  <compiler angle="radian" meshdir="../meshes/"/>
  <size njmax="500" nconmax="100" />
  <default>
    <joint limited="true" armature="0.05" damping="0.02" frictionloss="0.02"/>
    <motor ctrllimited="true" ctrlrange="-100 100"/>
    <!-- <geom contype="1" conaffinity="1" condim="1" solref="0.005 1"/> -->
    <!-- <geom solref="0.01 0.35"/> -->
    <equality solref="0.005 1"/>
    <default class="collision">
      <!-- User parameter for geoms is used to identify collision types -->
      <geom material="collision" contype="4" conaffinity="4" user="2" group="3" rgba="0.9 0.3 0.3 0.2"/>
      <default class="collision-left">
        <geom contype="1" conaffinity="2" group="3" rgba="0.3 0.9 0.3 0.2"/>
      </default>
      <default class="collision-right">
        <geom contype="2" conaffinity="1" group="3" rgba="0.3 0.3 0.9 0.2"/>
      </default>
    </default>
  </default>
  <asset>
    <texture type="skybox" builtin="gradient" rgb1="0.4 0.6 0.8" width="128" height="128"/>
    <texture name="grid" type="2d" builtin="checker" rgb1=".1 .2 .3" rgb2=".2 .3 .4" width="300" height="300"/>
    <material name="grid" texture="grid" texrepeat="8 8" reflectance=".1"/>
    <material name="collision" rgba="0.1 0.5 0.9 0"/>
    <mesh name="torso" file="torso.STL"/>
    <mesh name="waist_yaw" file="waist_yaw.STL"/>
    <mesh name="l_leg_roll" file="l_leg_roll.STL"/>
    <mesh name="l_leg_yaw" file="l_leg_yaw.STL"/>
    <mesh name="l_leg_pitch" file="l_leg_pitch.STL"/>
    <mesh name="l_knee" file="l_knee.STL"/>
    <mesh name="l_foot_pitch" file="l_foot_pitch.STL"/>
    <mesh name="l_foot_roll" file="l_foot_roll.STL"/>
    <mesh name="r_leg_roll" file="r_leg_roll.STL"/>
    <mesh name="r_leg_yaw" file="r_leg_yaw.STL"/>
    <mesh name="r_leg_pitch" file="r_leg_pitch.STL"/>
    <mesh name="r_knee" file="r_knee.STL"/>
    <mesh name="r_foot_pitch" file="r_foot_pitch.STL"/>
    <mesh name="r_foot_roll" file="r_foot_roll.STL"/>
    <mesh name="l_arm_pitch" file="l_arm_pitch.STL"/>
    <mesh name="l_arm_roll" file="l_arm_roll.STL"/>
    <mesh name="l_arm_yaw" file="l_arm_yaw.STL"/>
    <mesh name="l_forearm" file="l_forearm.STL"/>
    <mesh name="l_hand_yaw" file="l_hand_yaw.STL"/>
    <mesh name="l_hand_roll" file="l_hand_roll.STL"/>
    <mesh name="l_hand_pitch" file="l_hand_pitch.STL"/>
    <mesh name="l_hand_pitch_nohand" file="l_hand_pitch_nohand.STL"/>
    <mesh name="r_arm_pitch" file="r_arm_pitch.STL"/>
    <mesh name="r_arm_roll" file="r_arm_roll.STL"/>
    <mesh name="r_arm_yaw" file="r_arm_yaw.STL"/>
    <mesh name="r_forearm" file="r_forearm.STL"/>
    <mesh name="r_hand_yaw" file="r_hand_yaw.STL"/>
    <mesh name="r_hand_roll" file="r_hand_roll.STL"/>
    <mesh name="r_hand_pitch" file="r_hand_pitch.STL"/>
    <mesh name="r_hand_pitch_nohand" file="r_hand_pitch_nohand.STL"/>
    <mesh name="head_yaw" file="head_yaw.STL"/>
    <mesh name="head_pitch" file="head_pitch.STL"/>
    <mesh name="head_camera" file="head_camera.STL"/>
    <mesh name="head_rader" file="head_rader.STL"/>
    <mesh name="waist_camera" file="waist_camera.STL"/>
  </asset>
  <worldbody>
    <body name="base_link" pos="0 0 0.82">
      <freejoint />
      <site name="imu" pos="0 0 0" />
      <inertial pos="-0.0549595 -0.00028705 -0.0146801" quat="0.275587 0.275587 -0.651192 0.651192" mass="7.06405" diaginertia="0.0939215 0.0558908 0.0549759"/>
      <geom type="mesh" contype="0" conaffinity="0" group="1" density="0" rgba="1 1 1 1" mesh="torso"/>
      <!-- base_link碰撞体 -->
      <geom size="0.06 0.12" pos="-0.025 0.095 -0.065" quat="0.707388 0 0.706825 0" type="cylinder" class="collision-left"/>
      <geom size="0.06 0.12" pos="-0.025 -0.095 -0.065" quat="0.707388 0 0.706825 0" type="cylinder" class="collision-right"/>
      <body name="leg_l1_link" pos="0 0.095075 -0.066">
        <inertial pos="-0.00560896 0.00032862 -0.00212773" quat="-0.0055419 0.705371 0.0126897 0.708703" mass="1.55641" diaginertia="0.00260596 0.00254377 0.00191083"/>
        <joint name="leg_l1_joint" pos="0 0 0" axis="1 0 0" range="-0.314159 0.663225" actuatorfrcrange="-127 127" damping="0.02"/>
        <geom type="mesh" contype="0" conaffinity="0" group="1" density="0" rgba="1 1 1 1" mesh="l_leg_roll"/>
        <body name="leg_l2_link">
          <inertial pos="6.341e-05 -0.00960017 -0.0930895" quat="0.501062 0.865401 0.00393595 -0.00135372" mass="0.75873" diaginertia="0.00348987 0.00253732 0.00183645"/>
          <joint name="leg_l2_joint" pos="0 0 0" axis="0 0 1" range="-0.785398 1.91986" actuatorfrcrange="-71 71" damping="0.02"/>
          <geom type="mesh" contype="0" conaffinity="0" group="1" density="0" rgba="1 1 1 1" mesh="l_leg_yaw"/>
          <body name="leg_l3_link" pos="0 0 -0.1437">
            <inertial pos="0.00273544 0.0147842 -0.090115" quat="0.998893 0.00918128 0.018169 0.04241" mass="6.68074" diaginertia="0.0616257 0.0599923 0.0156779"/>
            <joint name="leg_l3_joint" pos="0 0 0" axis="0 1 0" range="-1.91986 1.5708" actuatorfrcrange="-132 132" damping="0.02"/>
            <geom type="mesh" contype="0" conaffinity="0" group="1" density="0" rgba="1 1 1 1" mesh="l_leg_pitch"/>
            <geom type="capsule" size="0.065 0.125" pos="0 0 -0.11" quat="0.707388 0 0 0.706825" class="collision-left"/>
            <geom size="0.06 0.02" pos="0.005 0.075 -0.115" quat="0.707388 0.706825 0 0" type="cylinder" class="collision-left"/>
            <body name="leg_l4_link" pos="-0.0011639 0 -0.284">
              <inertial pos="0.00684787 6.281e-05 -0.162627" quat="0.999903 -0.000924951 -0.00641315 0.0123647" mass="3.64666" diaginertia="0.0437338 0.0435702 0.00246292"/>
              <joint name="leg_l4_joint" pos="0 0 0" axis="0 1 0" range="0 2.53073" actuatorfrcrange="-280 280" damping="0.02"/>
              <geom type="mesh" contype="0" conaffinity="0" group="1" density="0" rgba="1 1 1 1" mesh="l_knee"/>
              <geom type="capsule" size="0.05 0.15" pos="0 0 -0.23" quat="0.707388 0 0 0.706825" class="collision-left"/>
              <body name="leg_l5_link" pos="0.002 0 -0.416">
                <inertial pos="0 0 0" quat="0.5 0.5 -0.5 0.5" mass="0.07848" diaginertia="1.318e-05 7.57e-06 7.57e-06"/>
                <joint name="leg_l5_joint" pos="0 0 0" axis="0 1 0" range="-0.872665 0.349066" actuatorfrcrange="-91.6 91.6" damping="0.02"/>
                <geom type="mesh" contype="0" conaffinity="0" group="1" density="0" rgba="1 1 1 1" mesh="l_foot_pitch"/>
                <body name="leg_l6_link">
                  <site name="l_ft_frame" pos="0 0 0" size="0.02 0.02 0.02" rgba="1 1 1 1" type="box" group="3"/>
                  <inertial pos="0.0266596 -4.5175e-05 -0.0338466" quat="0.000561393 0.740425 0.00103702 0.672138" mass="0.695562" diaginertia="0.00206157 0.00194955 0.00050711"/>
                  <joint name="leg_l6_joint" pos="0 0 0" axis="1 0 0" range="-0.261799 0.261799" actuatorfrcrange="-68.4 68.4" damping="0.02"/>
                  <geom type="mesh" contype="0" conaffinity="0" group="1" density="0" rgba="1 1 1 1" mesh="l_foot_roll"/>

                  <geom type="capsule" size="0.008" fromto="-0.008 -0.046 -0.044 -0.008  0.046 -0.044" class="collision-left"/>
                  <geom type="capsule" size="0.008" fromto="-0.016 -0.046 -0.051 -0.016  0.046 -0.051" class="collision-left"/>
                  <geom type="box" size="0.045 0.05 0.0054" pos=" 0.042 0.0 -0.041" class="collision-left"/>
                  <geom type="capsule" size="0.008" fromto="-0.063 -0.038 -0.054 -0.063  0.038 -0.054" class="collision-left"/>
                  <geom type="box" size="0.021 0.048 0.0054" pos=" -0.036 0.0 -0.054" class="collision-left"/>
                  <geom type="capsule" size="0.008" fromto="0.09 -0.046 -0.043 0.09  0.046 -0.043" class="collision-left"/>
                  <geom type="capsule" size="0.008" fromto="0.1 -0.046 -0.046 0.1  0.046 -0.046" class="collision-left"/>
                  <geom type="capsule" size="0.008" fromto="0.109 -0.046 -0.05 0.109  0.046 -0.05" class="collision-left"/>
                  <geom type="capsule" size="0.008" fromto="0.12 -0.046 -0.053 0.12  0.046 -0.053" class="collision-left"/>
                  <geom type="capsule" size="0.008" fromto="0.13 -0.046 -0.054 0.13  0.046 -0.054" class="collision-left"/>
                  <geom type="capsule" size="0.008" fromto="0.139 -0.041 -0.054 0.139  0.041 -0.054" class="collision-left"/>
                  <geom type="capsule" size="0.008" fromto="0.152 -0.032 -0.054 0.152 0.032 -0.054" class="collision-left"/>
                  <geom type="capsule" size="0.008" fromto="0.165 -0.02 -0.054 0.165  0.02 -0.054" class="collision-left"/>

                </body>
              </body>
            </body>
          </body>
        </body>
      </body>
      <body name="leg_r1_link" pos="0 -0.095075 -0.066">
        <inertial pos="-0.00560896 -0.00032862 -0.00212773" quat="0.00645594 0.708641 -0.0118102 0.705441" mass="1.55641" diaginertia="0.00260596 0.00254377 0.00191083"/>
        <joint name="leg_r1_joint" pos="0 0 0" axis="1 0 0" range="-0.663225 0.314159" actuatorfrcrange="-127 127" damping="0.02"/>
        <geom type="mesh" contype="0" conaffinity="0" group="1" density="0" rgba="1 1 1 1" mesh="r_leg_roll"/>
        <body name="leg_r2_link">
          <inertial pos="6.341e-05 0.00960017 -0.0930895" quat="0.865416 0.501048 -0.00253853 -0.000476679" mass="0.75873" diaginertia="0.00348984 0.00253738 0.00183642"/>
          <joint name="leg_r2_joint" pos="0 0 0" axis="0 0 1" range="-1.91986 0.785398" actuatorfrcrange="-71 71" damping="0.02"/>
          <geom type="mesh" contype="0" conaffinity="0" group="1" density="0" rgba="1 1 1 1" mesh="r_leg_yaw"/>
          <body name="leg_r3_link" pos="0 0 -0.1437">
            <inertial pos="0.00273544 -0.0147842 -0.090115" quat="0.998054 -0.00715911 -0.0189374 -0.0589798" mass="6.68074" diaginertia="0.0616367 0.0599808 0.0156783"/>
            <joint name="leg_r3_joint" pos="0 0 0" axis="0 1 0" range="-1.91986 1.5708" actuatorfrcrange="-132 132" damping="0.02"/>
            <geom type="mesh" contype="0" conaffinity="0" group="1" density="0" rgba="1 1 1 1" mesh="r_leg_pitch"/>
            <geom type="capsule" size="0.065 0.125" pos="0 0 -0.11" quat="0.707388 0 0 0.706825" class="collision-right"/>
            <geom size="0.06 0.02" pos="0.005 -0.075 -0.115" quat="0.707388 0.706825 0 0" type="cylinder" class="collision-right"/>
            <body name="leg_r4_link" pos="-0.0011639 0 -0.284">
              <inertial pos="0.00684787 -6.281e-05 -0.162627" quat="0.99982 0.000729458 0.00643812 -0.0178147" mass="3.64666" diaginertia="0.0437339 0.0435701 0.00246292"/>
              <joint name="leg_r4_joint" pos="0 0 0" axis="0 1 0" range="0 2.53073" actuatorfrcrange="-280 280" damping="0.02"/>
              <geom type="mesh" contype="0" conaffinity="0" group="1" density="0" rgba="1 1 1 1" mesh="r_knee"/>
              <geom type="capsule" size="0.05 0.15" pos="0 0 -0.23" quat="0.707388 0 0 0.706825" class="collision-right"/>
              <body name="leg_r5_link" pos="0.002 0 -0.416">
                <inertial pos="0 0 0" quat="0.5 0.5 -0.5 0.5" mass="0.07848" diaginertia="1.318e-05 7.57e-06 7.57e-06"/>
                <joint name="leg_r5_joint" pos="0 0 0" axis="0 1 0" range="-0.872665 0.349066" actuatorfrcrange="-91.6 91.6" damping="0.02"/>
                <geom type="mesh" contype="0" conaffinity="0" group="1" density="0" rgba="1 1 1 1" mesh="r_foot_pitch"/>
                <body name="leg_r6_link">
                  <site name="r_ft_frame" pos="0 0 0" size="0.02 0.02 0.02" rgba="1 1 1 1" type="box" group="3"/>
                  <inertial pos="0.0266596 -4.5175e-05 -0.0338466" quat="0.000561393 0.740425 0.00103702 0.672138" mass="0.695562" diaginertia="0.00206157 0.00194955 0.00050711"/>
                  <joint name="leg_r6_joint" pos="0 0 0" axis="1 0 0" range="-0.261799 0.261799" actuatorfrcrange="-68.4 68.4" damping="0.02"/>
                  <geom type="mesh" contype="0" conaffinity="0" group="1" density="0" rgba="1 1 1 1" mesh="r_foot_roll"/>

                  <geom type="box" size="0.045 0.05 0.0054" pos=" 0.042 0.0 -0.041" class="collision-right"/>
                  <geom type="capsule" size="0.008" fromto="-0.008 -0.046 -0.044 -0.008  0.046 -0.044" class="collision-right"/>
                  <geom type="capsule" size="0.008" fromto="-0.016 -0.046 -0.051 -0.016  0.046 -0.051" class="collision-right"/>
                  <geom type="capsule" size="0.008" fromto="-0.063 -0.038 -0.054 -0.063  0.038 -0.054" class="collision-right"/>
                  <geom type="box" size="0.021 0.048 0.0054" pos=" -0.036 0.0 -0.054" class="collision-right"/>
                  <geom type="capsule" size="0.008" fromto="0.09 -0.046 -0.043 0.09  0.046 -0.043" class="collision-right"/>
                  <geom type="capsule" size="0.008" fromto="0.1 -0.046 -0.046 0.1  0.046 -0.046" class="collision-right"/>
                  <geom type="capsule" size="0.008" fromto="0.109 -0.046 -0.05 0.109  0.046 -0.05" class="collision-right"/>
                  <geom type="capsule" size="0.008" fromto="0.12 -0.046 -0.053 0.12  0.046 -0.053" class="collision-right"/>
                  <geom type="capsule" size="0.008" fromto="0.13 -0.046 -0.054 0.13  0.046 -0.054" class="collision-right"/>
                  <geom type="capsule" size="0.008" fromto="0.139 -0.041 -0.054 0.139  0.041 -0.054" class="collision-right"/>
                  <geom type="capsule" size="0.008" fromto="0.152 -0.032 -0.054 0.152 0.032 -0.054" class="collision-right"/>
                  <geom type="capsule" size="0.008" fromto="0.165 -0.02 -0.054 0.165  0.02 -0.054" class="collision-right"/>

                </body>
              </body>
            </body>
          </body>
        </body>
      </body>
      <body name="waist_yaw" pos="0 0 0.1114">
        <inertial pos="0.0405387 -0.000615184 0.166422" quat="0.999998 0.00167928 -0.000969638 -0.00034323" mass="16.1894" diaginertia="0.34243 0.25856 0.201854"/>
        <joint name="waist_yaw_joint" pos="0 0 0" axis="0 0 1" range="-3.14 3.14" actuatorfrcrange="-102 102"/>
        <geom type="mesh" contype="0" conaffinity="0" group="1" density="0" rgba="1 1 1 1" mesh="waist_yaw"/>
        <!-- waist_yaw碰撞体 -->
        <geom type="capsule" size="0.13 0.06" pos="0.008 0 0.2486" quat="0.707388 0.706825 0 0" class="collision"/>
        <geom type="capsule" size="0.13 0.03" pos="0.008 0 0.0886" class="collision"/>
        <body name="waist_camera_link" pos="0.09538 0 -0.01091" quat="0.868 0 0.497 0">
          <inertial pos="0.0048485 0.00025646 0.013977" mass=".0483" diaginertia="5.9781e-05 5.8328e-06 5.9293e-05"/>
          <geom type="mesh" contype="0" conaffinity="0" group="1" density="0" rgba="1 1 1 1" mesh="waist_camera"/>
          <camera name="waist_camera" pos="0.01229 0.02375 0.01452" xyaxes="0 -1 0 0 0 1" fovy="80" />
        </body>
        <body name="zarm_l1_link" pos="-0.003 0.2527 0.283">
          <inertial pos="0.00080154 -0.00930333 0.00031203" quat="0.535076 0.531531 -0.469812 0.458743" mass="0.94521" diaginertia="0.00133871 0.00133347 0.000886059"/>
          <joint name="zarm_l1_joint" pos="0 0 0" axis="0 1 0" range="-3.14159 1.5708" actuatorfrcrange="-66 66" damping="0.02"/>
          <geom type="mesh" contype="0" conaffinity="0" group="1" density="0" rgba="1 1 1 1" mesh="l_arm_pitch"/>
          <geom type="capsule" size="0.05 0.02" quat="0.707105 0 0.707108 0" class="collision-left"/>
          <body name="zarm_l2_link">
            <inertial pos="-0.00087383 -3.89e-06 -0.0469021" quat="0.704249 0.0645783 0.0643665 0.704074" mass="0.41921" diaginertia="0.00123033 0.000853265 0.000739085"/>
            <joint name="zarm_l2_joint" pos="0 0 0" axis="1 0 0" range="-0.349066 3.49066" actuatorfrcrange="-75 75" damping="0.02"/>
            <geom type="mesh" contype="0" conaffinity="0" group="1" density="0" rgba="1 1 1 1" mesh="l_arm_roll"/>
            <body name="zarm_l3_link">
              <inertial pos="0.00961457 0.0030332 -0.229919" quat="0.956594 0.0480954 -0.066399 -0.279653" mass="1.78857" diaginertia="0.00723595 0.00718703 0.00177127"/>
              <joint name="zarm_l3_joint" pos="0 0 0" axis="0 0 1" range="-1.48353 1.48353" actuatorfrcrange="-57 57" damping="0.02"/>
              <geom type="mesh" contype="0" conaffinity="0" group="1" density="0" rgba="1 1 1 1" mesh="l_arm_yaw"/>
              <geom type="capsule" size="0.045 0.07" pos="0 0 -0.18" class="collision-left"/>
              <body name="zarm_l4_link" pos="0.02 0 -0.2837">
                <inertial pos="-0.0181527 0.00143762 -0.0674828" quat="0.996844 -0.0262299 0.0747913 -0.00450566" mass="0.63149" diaginertia="0.00154199 0.00131348 0.000669608"/>
                <joint name="zarm_l4_joint" pos="0 0 0" axis="0 1 0" range="-2.61799 0" actuatorfrcrange="-75 75" damping="0.02"/>
                <geom type="mesh" contype="0" conaffinity="0" group="1" density="0" rgba="1 1 1 1" mesh="l_forearm"/>
                <geom type="capsule" size="0.045 0.09" pos="-0.02 0 -0.14" class="collision-left"/>
                <body name="zarm_l5_link" pos="-0.02 0 -0.1201">
                  <inertial pos="-0.00516386 1.56e-05 -0.055897" quat="0.704938 0.0566996 0.0566958 0.704722" mass="0.60828" diaginertia="0.00092404 0.000663309 0.000494671"/>
                  <joint name="zarm_l5_joint" pos="0 0 0" axis="0 0 1" range="-1.5708 1.5708" actuatorfrcrange="-14.1 14.1" damping="0.02"/>
                  <geom type="mesh" contype="0" conaffinity="0" group="1" density="0" rgba="1 1 1 1" mesh="l_hand_yaw"/>
                  <body name="zarm_l6_link" pos="0 0 -0.114">
                    <inertial pos="-0.00674799 0.00638282 -0.00862654" quat="0.683664 -0.18421 -0.287548 0.644969" mass="0.50616" diaginertia="0.000525572 0.00049405 0.000209028"/>
                    <joint name="zarm_l6_joint" pos="0 0 0" axis="1 0 0" range="-1.309 0.698132" actuatorfrcrange="-14.1 14.1" damping="0.02"/>
                    <geom type="mesh" contype="0" conaffinity="0" group="1" density="0" rgba="1 1 1 1" mesh="l_hand_roll"/>
                    <body name="zarm_l7_link" pos="0 0 -0.021">
                      <inertial pos="0.00481393 0.00873606 -0.0837543" quat="0.773545 0.00191573 -0.00427249 0.633725" mass="0.7374" diaginertia="0.00133239 0.00112502 0.000373427"/>
                      <joint name="zarm_l7_joint" pos="0 0 0" axis="0 1 0" range="-0.698132 0.698132" actuatorfrcrange="-14.1 14.1" damping="0.02"/>
                      <geom type="mesh" contype="0" conaffinity="0" group="1" density="0" rgba="1 1 1 1" mesh="l_hand_pitch_nohand"/>
                      <geom size="0.04 0.025 0.08" pos="0 0 -0.158" quat="4.63268e-05 0 0 -1" type="box" class="collision-left"/>
                      <geom size="0.01 0.04" pos="0.0505 -0.0292 -0.116372" quat="0.991915 0 -0.126907 0" type="cylinder" class="collision-left"/>
                    </body>
                  </body>
                </body>
              </body>
            </body>
          </body>
        </body>
        <body name="zarm_r1_link" pos="-0.003 -0.2527 0.283">
          <inertial pos="0.00162594 0.00950442 -0.00031733" quat="0.704772 0.709052 0.0231382 -0.00249502" mass="0.92947" diaginertia="0.0013282 0.0013006 0.000847374"/>
          <joint name="zarm_r1_joint" pos="0 0 0" axis="0 1 0" range="-3.14159 1.5708" actuatorfrcrange="-66 66" damping="0.02"/>
          <geom type="mesh" contype="0" conaffinity="0" group="1" density="0" rgba="1 1 1 1" mesh="r_arm_pitch"/>
          <geom type="capsule" size="0.05 0.02" quat="0.707105 0 0.707108 0" class="collision-right"/>
          <body name="zarm_r2_link">
            <inertial pos="-0.00082502 -6.18e-06 -0.0469992" quat="0.704307 0.0639585 0.0637456 0.704129" mass="0.41523" diaginertia="0.00122057 0.000848506 0.000732414"/>
            <joint name="zarm_r2_joint" pos="0 0 0" axis="1 0 0" range="-3.49066 0.349066" actuatorfrcrange="-75 75" damping="0.02"/>
            <geom type="mesh" contype="0" conaffinity="0" group="1" density="0" rgba="1 1 1 1" mesh="r_arm_roll"/>
            <body name="zarm_r3_link">
              <inertial pos="0.00936686 -0.00338228 -0.22947" quat="0.946156 -0.0542044 -0.0622438 0.313013" mass="1.78473" diaginertia="0.00720155 0.00716402 0.00172727"/>
              <joint name="zarm_r3_joint" pos="0 0 0" axis="0 0 1" range="-1.48353 1.48353" actuatorfrcrange="-57 57" damping="0.02"/>
              <geom type="mesh" contype="0" conaffinity="0" group="1" density="0" rgba="1 1 1 1" mesh="r_arm_yaw"/>
              <geom type="capsule" size="0.045 0.07" pos="0 0 -0.18" class="collision-right"/>
              <body name="zarm_r4_link" pos="0.02 0 -0.2837">
                <inertial pos="-0.0180859 -0.00140005 -0.0672275" quat="0.996883 0.0252575 0.074588 0.00475547" mass="0.63548" diaginertia="0.00156558 0.00133498 0.000680646"/>
                <joint name="zarm_r4_joint" pos="0 0 0" axis="0 1 0" range="-2.61799 0" actuatorfrcrange="-75 75" damping="0.02"/>
                <geom type="mesh" contype="0" conaffinity="0" group="1" density="0" rgba="1 1 1 1" mesh="r_forearm"/>
                <geom type="capsule" size="0.045 0.09" pos="-0.02 0 -0.14" class="collision-right"/>
                <body name="zarm_r5_link" pos="-0.02 0 -0.1201">
                  <inertial pos="-0.00505317 1.432e-05 -0.0561914" quat="0.705017 0.0560238 0.0560187 0.704751" mass="0.61021" diaginertia="0.00092519 0.000660915 0.000498385"/>
                  <joint name="zarm_r5_joint" pos="0 0 0" axis="0 0 1" range="-1.5708 1.5708" actuatorfrcrange="-14.1 14.1" damping="0.02"/>
                  <geom type="mesh" contype="0" conaffinity="0" group="1" density="0" rgba="1 1 1 1" mesh="r_hand_yaw"/>
                  <body name="zarm_r6_link" pos="0 0 -0.114">
                    <inertial pos="-0.0063308 -0.00581708 -0.00833296" quat="0.62875 -0.304552 -0.198407 0.687427" mass="0.53821" diaginertia="0.000569989 0.000523319 0.000243602"/>
                    <joint name="zarm_r6_joint" pos="0 0 0" axis="1 0 0" range="-0.698132 1.309" actuatorfrcrange="-14.1 14.1" damping="0.02"/>
                    <geom type="mesh" contype="0" conaffinity="0" group="1" density="0" rgba="1 1 1 1" mesh="r_hand_roll"/>
                    <body name="zarm_r7_link" pos="0 0 -0.021">
                      <inertial pos="0.00481393 -0.00870857 -0.0836411" quat="0.631284 0.000713926 0.000542849 0.775551" mass="0.7374" diaginertia="0.00131607 0.00110836 0.000374168"/>
                      <joint name="zarm_r7_joint" pos="0 0 0" axis="0 1 0" range="-0.698132 0.698132" actuatorfrcrange="-14.1 14.1" damping="0.02"/>
                      <geom type="mesh" contype="0" conaffinity="0" group="1" density="0" rgba="1 1 1 1" mesh="r_hand_pitch_nohand"/>
                      <geom size="0.04 0.025 0.08" pos="0 0 -0.158" quat="4.63268e-05 0 0 -1" type="box" class="collision-right"/>
                      <geom size="0.01 0.04" pos="0.0505 0.0292 -0.116372" quat="0.991915 0 -0.126907 0" type="cylinder" class="collision-right"/>
                    </body>
                  </body>
                </body>
              </body>
            </body>
          </body>
        </body>
        <body name="zhead_1_link" pos="-0.003 0 0.49535">
          <inertial pos="-0.0248643 -0.00253574 -0.0180227" quat="0.716489 -0.190513 -0.215527 0.635529" mass="0.8375" diaginertia="0.00323032 0.00268059 0.00110415"/>
          <joint name="zhead_1_joint" pos="0 0 0" axis="0 0 1" range="-1.5708 1.5708" actuatorfrcrange="-1.5 1.5" damping="0.02"/>
          <geom type="mesh" contype="0" conaffinity="0" group="1" density="0" rgba="1 1 1 1" mesh="head_yaw"/>
          <geom pos="0 0 -0.078253" quat="1 0 0 0" type="mesh" contype="0" conaffinity="0" group="1" density="0" rgba="0.61176 0.65882 0.67059 1" mesh="head_rader"/>
          <body name="zhead_2_link">
            <inertial pos="0.0280516 0.000563 0.0355241" quat="0 0.859603 0 0.510962" mass="0.73448" diaginertia="0.00490263 0.00457039 0.00388671"/>
            <joint name="zhead_2_joint" pos="0 0 0" axis="0 1 0" range="-0.523599 0.523599" actuatorfrcrange="-12 12" damping="0.02"/>
            <geom type="mesh" contype="0" conaffinity="0" group="1" density="0" rgba="1 1 1 1" mesh="head_pitch"/>
            <geom type="sphere" size="0.1" pos="0.04 0 0.01" class="collision"/>
            <geom pos="0.093839 0.0475 0.050077" quat="0.985534 0 0.169478 0" type="mesh" contype="0" conaffinity="0" group="1" density="0" rgba="1 1 1 1" mesh="head_camera"/>
          </body>
        </body>
      </body>
    </body>
  </worldbody>
  <actuator>
    <motor gear="1" joint="leg_l1_joint" name="leg_l1_joint_motor" ctrllimited="true" ctrlrange="-127 127" />
    <motor gear="1" joint="leg_l2_joint" name="leg_l2_joint_motor" ctrllimited="true" ctrlrange="-71 71" />
    <motor gear="1" joint="leg_l3_joint" name="leg_l3_joint_motor" ctrllimited="true" ctrlrange="-132 132" />
    <motor gear="1" joint="leg_l4_joint" name="leg_l4_joint_motor" ctrllimited="true" ctrlrange="-280 280" />
    <motor gear="1" joint="leg_l5_joint" name="leg_l5_joint_motor" ctrllimited="true" ctrlrange="-91.6 91.6" />
    <motor gear="1" joint="leg_l6_joint" name="leg_l6_joint_motor" ctrllimited="true" ctrlrange="-68.4 68.4" />
    <motor gear="1" joint="leg_r1_joint" name="leg_r1_joint_motor" ctrllimited="true" ctrlrange="-127 127" />
    <motor gear="1" joint="leg_r2_joint" name="leg_r2_joint_motor" ctrllimited="true" ctrlrange="-71 71" />
    <motor gear="1" joint="leg_r3_joint" name="leg_r3_joint_motor" ctrllimited="true" ctrlrange="-132 132" />
    <motor gear="1" joint="leg_r4_joint" name="leg_r4_joint_motor" ctrllimited="true" ctrlrange="-280 280" />
    <motor gear="1" joint="leg_r5_joint" name="leg_r5_joint_motor" ctrllimited="true" ctrlrange="-91.6 91.6" />
    <motor gear="1" joint="leg_r6_joint" name="leg_r6_joint_motor" ctrllimited="true" ctrlrange="-68.4 68.4" />
    <motor gear="1" joint="waist_yaw_joint" name="waist_yaw_joint_motor" ctrllimited="true" ctrlrange="-102 102" />
    <motor gear="1" joint="zarm_l1_joint" name="zarm_l1_joint_motor" ctrllimited="true" ctrlrange="-66 66" />
    <motor gear="1" joint="zarm_l2_joint" name="zarm_l2_joint_motor" ctrllimited="true" ctrlrange="-75 75" />
    <motor gear="1" joint="zarm_l3_joint" name="zarm_l3_joint_motor" ctrllimited="true" ctrlrange="-57 57" />
    <motor gear="1" joint="zarm_l4_joint" name="zarm_l4_joint_motor" ctrllimited="true" ctrlrange="-75 75" />
    <motor gear="1" joint="zarm_l5_joint" name="zarm_l5_joint_motor" ctrllimited="true" ctrlrange="-14.1 14.1" />
    <motor gear="1" joint="zarm_l6_joint" name="zarm_l6_joint_motor" ctrllimited="true" ctrlrange="-14.1 14.1" />
    <motor gear="1" joint="zarm_l7_joint" name="zarm_l7_joint_motor" ctrllimited="true" ctrlrange="-14.1 14.1" />
    <motor gear="1" joint="zarm_r1_joint" name="zarm_r1_joint_motor" ctrllimited="true" ctrlrange="-66 66" />
    <motor gear="1" joint="zarm_r2_joint" name="zarm_r2_joint_motor" ctrllimited="true" ctrlrange="-75 75" />
    <motor gear="1" joint="zarm_r3_joint" name="zarm_r3_joint_motor" ctrllimited="true" ctrlrange="-57 57" />
    <motor gear="1" joint="zarm_r4_joint" name="zarm_r4_joint_motor" ctrllimited="true" ctrlrange="-75 75" />
    <motor gear="1" joint="zarm_r5_joint" name="zarm_r5_joint_motor" ctrllimited="true" ctrlrange="-14.1 14.1" />
    <motor gear="1" joint="zarm_r6_joint" name="zarm_r6_joint_motor" ctrllimited="true" ctrlrange="-14.1 14.1" />
    <motor gear="1" joint="zarm_r7_joint" name="zarm_r7_joint_motor" ctrllimited="true" ctrlrange="-14.1 14.1" />
    <motor gear="1" joint="zhead_1_joint" name="zhead_1_joint_motor" ctrllimited="true" ctrlrange="-14.1 14.1" />
    <motor gear="1" joint="zhead_2_joint" name="zhead_2_joint_motor" ctrllimited="true" ctrlrange="-14.1 14.1" />
  </actuator>
  <sensor>
    <accelerometer name="BodyAcc" site="imu" />
    <velocimeter name="BodyVel" site="imu" />
    <gyro name="BodyGyro" site="imu" />
    <framepos name="BodyPos" objtype="site" objname="imu" />
    <framequat name="BodyQuat" objtype="site" objname="imu" />
    <jointpos name="leg_l1_joint_pos" joint="leg_l1_joint" />
    <jointpos name="leg_l2_joint_pos" joint="leg_l2_joint" />
    <jointpos name="leg_l3_joint_pos" joint="leg_l3_joint" />
    <jointpos name="leg_l4_joint_pos" joint="leg_l4_joint" />
    <jointpos name="leg_l5_joint_pos" joint="leg_l5_joint" />
    <jointpos name="leg_l6_joint_pos" joint="leg_l6_joint" />
    <jointpos name="leg_r1_joint_pos" joint="leg_r1_joint" />
    <jointpos name="leg_r2_joint_pos" joint="leg_r2_joint" />
    <jointpos name="leg_r3_joint_pos" joint="leg_r3_joint" />
    <jointpos name="leg_r4_joint_pos" joint="leg_r4_joint" />
    <jointpos name="leg_r5_joint_pos" joint="leg_r5_joint" />
    <jointpos name="leg_r6_joint_pos" joint="leg_r6_joint" />
    <jointpos name="waist_yaw_joint_pos" joint="waist_yaw_joint" />
    <jointpos name="zarm_l1_joint_pos" joint="zarm_l1_joint" />
    <jointpos name="zarm_l2_joint_pos" joint="zarm_l2_joint" />
    <jointpos name="zarm_l3_joint_pos" joint="zarm_l3_joint" />
    <jointpos name="zarm_l4_joint_pos" joint="zarm_l4_joint" />
    <jointpos name="zarm_l5_joint_pos" joint="zarm_l5_joint" />
    <jointpos name="zarm_l6_joint_pos" joint="zarm_l6_joint" />
    <jointpos name="zarm_l7_joint_pos" joint="zarm_l7_joint" />
    <jointpos name="zarm_r1_joint_pos" joint="zarm_r1_joint" />
    <jointpos name="zarm_r2_joint_pos" joint="zarm_r2_joint" />
    <jointpos name="zarm_r3_joint_pos" joint="zarm_r3_joint" />
    <jointpos name="zarm_r4_joint_pos" joint="zarm_r4_joint" />
    <jointpos name="zarm_r5_joint_pos" joint="zarm_r5_joint" />
    <jointpos name="zarm_r6_joint_pos" joint="zarm_r6_joint" />
    <jointpos name="zarm_r7_joint_pos" joint="zarm_r7_joint" />
    <jointpos name="zhead_1_joint_pos" joint="zhead_1_joint" />
    <jointpos name="zhead_2_joint_pos" joint="zhead_2_joint" />
    <jointvel name="leg_l1_joint_vel" joint="leg_l1_joint" />
    <jointvel name="leg_l2_joint_vel" joint="leg_l2_joint" />
    <jointvel name="leg_l3_joint_vel" joint="leg_l3_joint" />
    <jointvel name="leg_l4_joint_vel" joint="leg_l4_joint" />
    <jointvel name="leg_l5_joint_vel" joint="leg_l5_joint" />
    <jointvel name="leg_l6_joint_vel" joint="leg_l6_joint" />
    <jointvel name="leg_r1_joint_vel" joint="leg_r1_joint" />
    <jointvel name="leg_r2_joint_vel" joint="leg_r2_joint" />
    <jointvel name="leg_r3_joint_vel" joint="leg_r3_joint" />
    <jointvel name="leg_r4_joint_vel" joint="leg_r4_joint" />
    <jointvel name="leg_r5_joint_vel" joint="leg_r5_joint" />
    <jointvel name="leg_r6_joint_vel" joint="leg_r6_joint" />
    <jointvel name="waist_yaw_joint_vel" joint="waist_yaw_joint" />
    <jointvel name="zarm_l1_joint_vel" joint="zarm_l1_joint" />
    <jointvel name="zarm_l2_joint_vel" joint="zarm_l2_joint" />
    <jointvel name="zarm_l3_joint_vel" joint="zarm_l3_joint" />
    <jointvel name="zarm_l4_joint_vel" joint="zarm_l4_joint" />
    <jointvel name="zarm_l5_joint_vel" joint="zarm_l5_joint" />
    <jointvel name="zarm_l6_joint_vel" joint="zarm_l6_joint" />
    <jointvel name="zarm_l7_joint_vel" joint="zarm_l7_joint" />
    <jointvel name="zarm_r1_joint_vel" joint="zarm_r1_joint" />
    <jointvel name="zarm_r2_joint_vel" joint="zarm_r2_joint" />
    <jointvel name="zarm_r3_joint_vel" joint="zarm_r3_joint" />
    <jointvel name="zarm_r4_joint_vel" joint="zarm_r4_joint" />
    <jointvel name="zarm_r5_joint_vel" joint="zarm_r5_joint" />
    <jointvel name="zarm_r6_joint_vel" joint="zarm_r6_joint" />
    <jointvel name="zarm_r7_joint_vel" joint="zarm_r7_joint" />
    <jointvel name="zhead_1_joint_vel" joint="zhead_1_joint" />
    <jointvel name="zhead_2_joint_vel" joint="zhead_2_joint" />
    <!-- FT sensors for left and right foot -->
    <force name="l_force" site="l_ft_frame" />
    <torque name="l_torque" site="l_ft_frame" />
    <force name="r_force" site="r_ft_frame" />
    <torque name="r_torque" site="r_ft_frame" />       
  </sensor>
</mujoco>
