<mujoco model="biped_s17">
  <compiler angle="radian" meshdir="../meshes/"/>
  <default>
    <default class="collision">
      <geom material="collision" contype="1" conaffinity="1" user="2" rgba="0.9 0.3 0.3 0.2"/>
    </default>
  </default>
  <asset>
    <material name="collision"/>
    <mesh name="torso" file="torso.STL"/>
    <mesh name="waist" file="waist.STL"/>
    <mesh name="l_leg_pitch" file="l_leg_pitch.STL"/>
    <mesh name="l_leg_roll" file="l_leg_roll.STL"/>
    <mesh name="l_leg_yaw" file="l_leg_yaw.STL"/>
    <mesh name="l_knee" file="l_knee.STL"/>
    <mesh name="l_foot_pitch" file="l_foot_pitch.STL"/>
    <mesh name="l_foot_roll" file="l_foot_roll.STL"/>
    <mesh name="r_leg_pitch" file="r_leg_pitch.STL"/>
    <mesh name="r_leg_roll" file="r_leg_roll.STL"/>
    <mesh name="r_leg_yaw" file="r_leg_yaw.STL"/>
    <mesh name="r_knee" file="r_knee.STL"/>
    <mesh name="r_foot_pitch" file="r_foot_pitch.STL"/>
    <mesh name="r_foot_roll" file="r_foot_roll.STL"/>
    <mesh name="l_arm_pitch" file="l_arm_pitch.STL"/>
    <mesh name="l_arm_roll" file="l_arm_roll.STL"/>
    <mesh name="l_arm_yaw" file="l_arm_yaw.STL"/>
    <mesh name="l_forearm" file="l_forearm.STL"/>
    <mesh name="l_handball" file="l_handball.STL"/>
    <mesh name="r_arm_pitch" file="r_arm_pitch.STL"/>
    <mesh name="r_arm_roll" file="r_arm_roll.STL"/>
    <mesh name="r_arm_yaw" file="r_arm_yaw.STL"/>
    <mesh name="r_forearm" file="r_forearm.STL"/>
    <mesh name="r_handball" file="r_handball.STL"/>
    <mesh name="head_yaw" file="head_yaw.STL"/>
    <mesh name="head_pitch" file="head_pitch.STL"/>
    <mesh name="head_camera_base" file="head_camera_base.STL"/>
    <mesh name="head_radar" file="head_radar.STL"/>
  </asset>

  <worldbody>
    <body name="base_link">
      <inertial pos="0.00202324 -3.822e-05 -0.122827" quat="0.70674 0.707473 0.000728125 0.000692342" mass="5.27737" diaginertia="0.0265656 0.0208074 0.0182124"/>
      <joint name="dummy_to_base_link" type="free" limited="false" actuatorfrclimited="false"/>
      <geom type="mesh" contype="0" conaffinity="0" group="1" density="0" rgba="1 1 1 1" mesh="waist"/>
      <geom size="0.08" pos="0.005 0 -0.12" quat="0.923764 0.382961 0 0" class="collision"/>

      <body name="leg_l1_link" pos="0 0.12441 -0.22265">
          <inertial pos="-3.227e-05 -0.0333442 0.0336706" quat="0.297024 0.642176 0.28184 0.648038" mass="0.6865" diaginertia="0.00221996 0.00213144 0.00126331"/>
          <joint name="leg_l1_joint" pos="0 0 0" axis="0 0.707107 -0.707107" range="-3.228 2.44346" actuatorfrcrange="-150 150" armature="0.003" damping="0.2" frictionloss="0.0"/>
          <geom type="mesh" contype="0" conaffinity="0" group="1" density="0" rgba="1 1 1 1" mesh="l_leg_pitch"/>
          <geom size="0.042 0.03" pos="-0.035 -0.02 0.02" quat="0.923764 0.382961 0 0" type="capsule" class="collision"/>
          <geom size="0.042 0.03" pos="0.035 -0.02 0.02" quat="0.923764 0.382961 0 0" type="capsule" class="collision"/>
          <body name="leg_l2_link">
            <inertial pos="0.0099775 6.468e-05 -0.00976037" quat="0.997557 -0.00250866 0.0689965 0.0105985" mass="2.054" diaginertia="0.00433516 0.00400691 0.00324202"/>
            <joint name="leg_l2_joint" pos="0 0 0" axis="1 0 0" range="-0.837758 2.40855" actuatorfrcrange="-150 150" armature="0.003" damping="0.2" frictionloss="0.0"/>
            <geom type="mesh" contype="0" conaffinity="0" group="1" density="0" rgba="1 1 1 1" mesh="l_leg_roll"/>
            <geom size="0.055 0.07" pos="0 0 -0.065" type="capsule" class="collision"/>
            <body name="leg_l3_link">
              <inertial pos="-0.0140249 -0.00139317 -0.159939" quat="0.679959 0.088223 0.102708 0.720641" mass="3.2746" diaginertia="0.0146119 0.0141249 0.00493058"/>
              <joint name="leg_l3_joint" pos="0 0 0" axis="0 0 1" range="-1.7453 1.7453" actuatorfrcrange="-70 70" armature="0.003" damping="0.2" frictionloss="0.0"/>
              <geom type="mesh" contype="0" conaffinity="0" group="1" density="0" rgba="1 1 1 1" mesh="l_leg_yaw"/>
              <geom size="0.055 0.015" pos="-0.025 0 -0.21" quat="0.707388 0.706825 0 0" type="capsule" class="collision"/>
              <body name="leg_l4_link" pos="-0.03 0 -0.213">
                <inertial pos="0.0226698 0.00479531 -0.114129" quat="0.887764 -0.0647792 0.0155609 0.455451" mass="2.4454" diaginertia="0.0136352 0.0131904 0.00300404"/>
                <joint name="leg_l4_joint" pos="0 0 0" axis="0 1 0" range="-0.0872665 2.53073" actuatorfrcrange="-150 150" armature="0.003" damping="0.2" frictionloss="0.0"/>
                <geom type="mesh" contype="0" conaffinity="0" group="1" density="0" rgba="1 1 1 1" mesh="l_knee"/>
                <geom size="0.05 0.075" pos="0.021 0 -0.17" type="capsule" class="collision"/>
                <geom size="0.005 0.025" pos="0.068 0 -0.02" quat="0.707388 0.706825 0 0" type="capsule" class="collision"/>
                <geom size="0.005 0.025" pos="0.074 0 -0.05" quat="0.707388 0.706825 0 0" type="capsule" class="collision"/>
                <body name="leg_l5_link" pos="0.03 0 -0.276">
                  <inertial pos="-0.00344503 -7.52e-06 -0.00936005" quat="0.692953 0.140769 0.140769 0.692953" mass="0.1314" diaginertia="2.431e-05 2.158e-05 1.245e-05"/>
                  <joint name="leg_l5_joint" pos="0 0 0" axis="0 1 0" range="-0.872665 0.523599" actuatorfrcrange="-74 74" armature="0.003" damping="0.2" frictionloss="0.0"/>
                  <geom type="mesh" contype="0" conaffinity="0" group="1" density="0" rgba="1 1 1 1" mesh="l_foot_pitch"/>
                  <body name="leg_l6_link" pos="0 0 -0.018">
                    <inertial pos="0.0287112 7.42268e-05 -0.019887" quat="-0.00243081 0.74057 -0.00273045 0.671969" mass="0.581469" diaginertia="0.0016337 0.0015067 0.000277446"/>
                    <joint name="leg_l6_joint" pos="0 0 0" axis="1 0 0" range="-0.261799 0.261799" actuatorfrcrange="-74 74" armature="0.003" damping="0.2" frictionloss="0.0"/>
                    <geom type="mesh" contype="0" conaffinity="0" group="1" density="0" rgba="1 1 1 1" mesh="l_foot_roll"/>
                    <geom size="0.035 0.005" pos="-0.02 0 -0.035" type="cylinder" class="collision"/>
                    <geom size="0.04 0.005" pos="0.11 0 -0.035" type="cylinder" class="collision"/>
                    <geom size="0.06 0.035 0.005" pos="0.038 0 -0.035" type="box" class="collision"/>
                    <geom size="0.005" pos="0.1510 0.0415 -0.03" type="sphere" class="collision"/>
                    <geom size="0.005" pos="-0.0538 0.0415 -0.03" type="sphere" class="collision"/>
                    <geom size="0.005" pos="0.1510 -0.0415 -0.03" type="sphere" class="collision"/>
                    <geom size="0.005" pos="-0.0538 -0.0415 -0.03" type="sphere" class="collision"/>
                    <geom size="0.005" pos="0.1510 0 -0.03" type="sphere" class="collision"/>
                    <geom size="0.005" pos="-0.0538 0 -0.03" type="sphere" class="collision"/>
                  </body>
                </body>
              </body>
            </body>
          </body>
        </body>
        <body name="leg_r1_link" pos="0 -0.12441 -0.22265">
          <inertial pos="-3.227e-05 0.0333442 0.0336706" quat="0.648038 0.28184 0.642176 0.297024" mass="0.6865" diaginertia="0.00221996 0.00213144 0.00126331"/>
          <joint name="leg_r1_joint" pos="0 0 0" axis="0 -0.707107 -0.707107" range="-2.44346 3.228" actuatorfrcrange="-150 150" armature="0.003" damping="0.2" frictionloss="0.0"/>
          <geom type="mesh" contype="0" conaffinity="0" group="1" density="0" rgba="1 1 1 1" mesh="r_leg_pitch"/>
          <geom size="0.042 0.03" pos="-0.035 0.02 0.02" quat="0.923764 -0.382961 0 0" type="capsule" class="collision"/>
          <geom size="0.042 0.03" pos="0.035 0.02 0.02" quat="0.923764 -0.382961 0 0" type="capsule" class="collision"/>
          <body name="leg_r2_link">
            <inertial pos="0.0099775 -6.468e-05 -0.00976037" quat="0.997557 0.00250866 0.0689965 -0.0105985" mass="2.054" diaginertia="0.00433516 0.00400691 0.00324202"/>
            <joint name="leg_r2_joint" pos="0 0 0" axis="1 0 0" range="-2.40855 0.837758" actuatorfrcrange="-150 150" armature="0.003" damping="0.2" frictionloss="0.0"/>
            <geom type="mesh" contype="0" conaffinity="0" group="1" density="0" rgba="1 1 1 1" mesh="r_leg_roll"/>
            <geom size="0.055 0.07" pos="0 0 -0.065" type="capsule" class="collision"/>
            <body name="leg_r3_link">
              <inertial pos="-0.0140249 0.00139317 -0.159939" quat="0.720641 0.102708 0.088223 0.679959" mass="3.2746" diaginertia="0.0146119 0.0141249 0.00493058"/>
              <joint name="leg_r3_joint" pos="0 0 0" axis="0 0 1" range="-1.7453 1.7453" actuatorfrcrange="-70 70" armature="0.003" damping="0.2" frictionloss="0.0"/>
              <geom type="mesh" contype="0" conaffinity="0" group="1" density="0" rgba="1 1 1 1" mesh="r_leg_yaw"/>
              <geom size="0.055 0.015" pos="-0.025 0 -0.21" quat="0.707388 0.706825 0 0" type="capsule" class="collision"/>
              <body name="leg_r4_link" pos="-0.03 0 -0.213">
                <inertial pos="0.0226698 -0.00479531 -0.114129" quat="0.455451 0.0155609 -0.0647792 0.887764" mass="2.4454" diaginertia="0.0136352 0.0131904 0.00300404"/>
                <joint name="leg_r4_joint" pos="0 0 0" axis="0 1 0" range="-0.0872665 2.53073" actuatorfrcrange="-150 150" armature="0.003" damping="0.2" frictionloss="0.0"/>
                <geom type="mesh" contype="0" conaffinity="0" group="1" density="0" rgba="1 1 1 1" mesh="r_knee"/>
                <geom size="0.05 0.075" pos="0.021 0 -0.17" type="capsule" class="collision"/>
                <geom size="0.005 0.025" pos="0.068 0 -0.02" quat="0.707388 0.706825 0 0" type="capsule" class="collision"/>
                <geom size="0.005 0.025" pos="0.074 0 -0.05" quat="0.707388 0.706825 0 0" type="capsule" class="collision"/>
                <body name="leg_r5_link" pos="0.03 0 -0.276">
                  <inertial pos="-0.00344503 7.52e-06 -0.00936005" quat="0.692953 0.140769 0.140769 0.692953" mass="0.1314" diaginertia="2.431e-05 2.158e-05 1.245e-05"/>
                  <joint name="leg_r5_joint" pos="0 0 0" axis="0 1 0" range="-0.872665 0.523599" actuatorfrcrange="-74 74" armature="0.003" damping="0.2" frictionloss="0.0"/>
                  <geom type="mesh" contype="0" conaffinity="0" group="1" density="0" rgba="1 1 1 1" mesh="r_foot_pitch"/>
                  <body name="leg_r6_link" pos="0 0 -0.018">
                    <inertial pos="0.0287112 -7.42268e-05 -0.019887" quat="0.0024308 0.740571 0.00273042 0.671968" mass="0.581469" diaginertia="0.0016337 0.0015067 0.000277446"/>
                    <joint name="leg_r6_joint" pos="0 0 0" axis="1 0 0" range="-0.261799 0.261799" actuatorfrcrange="-74 74" armature="0.003" damping="0.2" frictionloss="0.0"/>
                    <geom type="mesh" contype="0" conaffinity="0" group="1" density="0" rgba="1 1 1 1" mesh="r_foot_roll"/>
                    <geom size="0.035 0.005" pos="-0.02 0 -0.035" type="cylinder" class="collision"/>
                    <geom size="0.04 0.005" pos="0.11 0 -0.035" type="cylinder" class="collision"/>
                    <geom size="0.06 0.035 0.005" pos="0.038 0 -0.035" type="box" class="collision"/>
                    <geom size="0.005" pos="0.1510 0.0415 -0.03" type="sphere" class="collision"/>
                    <geom size="0.005" pos="-0.0538 0.0415 -0.03" type="sphere" class="collision"/>
                    <geom size="0.005" pos="0.1510 -0.0415 -0.03" type="sphere" class="collision"/>
                    <geom size="0.005" pos="-0.0538 -0.0415 -0.03" type="sphere" class="collision"/>
                    <geom size="0.005" pos="0.1510 0 -0.03" type="sphere" class="collision"/>
                    <geom size="0.005" pos="-0.0538 0 -0.03" type="sphere" class="collision"/>
                  </body>
                </body>
              </body>
            </body>
          </body>
        </body>
      <body name="torso">
        <site name="imu" pos="0 0 0" />
        <inertial pos="-0.0100514 -0.00110498 0.140586" quat="0.999642 -0.0162049 -0.0199132 0.00748437" mass="8.37745" diaginertia="0.104453 0.0832724 0.0491503"/>
        <joint name="waist_yaw_joint" pos="0 0 0" axis="0 0 1" range="-2.61799 2.61799" actuatorfrcrange="-50 50" armature="0.003" damping="0.2" frictionloss="0.0"/>
        <geom type="mesh" contype="0" conaffinity="0" group="1" density="0" rgba="1 1 1 1" mesh="torso"/>
        <geom size="0.07 0.1 0.13" pos="0.01 0 0.14" type="box" class="collision"/>
        <geom size="0.008 0.0625" pos="-0.102 0 0.288" quat="0.707105 0.707108 0 0" type="cylinder" class="collision"/>
        <body name="zarm_l1_link" pos="0 0.181 0.23843">
          <inertial pos="0.017736 -0.00289047 -6.872e-05" quat="-0.0901289 0.70032 0.0825321 0.70329" mass="0.8476" diaginertia="0.00101124 0.000899135 0.000720515"/>
          <joint name="zarm_l1_joint" pos="0 0 0" axis="0 1 0" range="-3.14159 2.0944" actuatorfrcrange="-14.1 14.1" armature="0.003" damping="0.2" frictionloss="0.0"/>
          <geom type="mesh" contype="0" conaffinity="0" group="1" density="0" rgba="1 1 1 1" mesh="l_arm_pitch"/>
          <geom size="0.04 0.02" quat="0.707105 0 0.707108 0" type="capsule" class="collision"/>
          <body name="zarm_l2_link" quat="0.996195 0.0871543 0 0">
            <inertial pos="0.00199256 0 -0.0321465" quat="0.597799 0.377699 0.377686 0.597773" mass="0.3668" diaginertia="0.00078576 0.000587472 0.000526228"/>
            <joint name="zarm_l2_joint" pos="0 0 0" axis="1 0 0" range="-0.52 3.316" actuatorfrcrange="-37 37" armature="0.003" damping="0.2" frictionloss="0.0"/>
            <geom type="mesh" contype="0" conaffinity="0" group="1" density="0" rgba="1 1 1 1" mesh="l_arm_roll"/>
            <geom size="0.035 0.0175" pos="0 0 -0.0525" type="capsule" class="collision"/>
            <body name="zarm_l3_link">
              <inertial pos="-7.73e-05 -0.0099364 -0.150833" quat="0.996992 -0.077485 -0.000148127 0.00175793" mass="1.5166" diaginertia="0.00716994 0.00690726 0.00128492"/>
              <joint name="zarm_l3_joint" pos="0 0 0" axis="0 0 1" range="-1.5708 1.5708" actuatorfrcrange="-37 37" armature="0.003" damping="0.2" frictionloss="0.0"/>
              <geom type="mesh" contype="0" conaffinity="0" group="1" density="0" rgba="1 1 1 1" mesh="l_arm_yaw"/>
              <geom size="0.035 0.025" pos="0 0 -0.125" type="capsule" class="collision"/>
              <body name="zarm_l4_link" pos="0 0 -0.2085">
                <inertial pos="-0.000693279 -0.00191472 -0.0925486" quat="0.999843 0.0163619 -0.00329901 0.00594719" mass="0.522124" diaginertia="0.00347786 0.00326967 0.000556314"/>
                <joint name="zarm_l4_joint" pos="0 0 0" axis="0 1 0" range="-2.26893 0.08726" actuatorfrcrange="-37 37" armature="0.003" damping="0.2" frictionloss="0.0"/>
                <geom type="mesh" contype="0" conaffinity="0" group="1" density="0" rgba="1 1 1 1" mesh="l_forearm"/>
                <geom size="0.045 0.015" quat="0.707388 0.706825 0 0" type="capsule" class="collision"/>
                <geom size="0.02 0.06" pos="0 0 -0.1" type="capsule" class="collision"/>
                <geom size="0.03" pos="0 0 -0.2175" class="collision" friction="0.0001 0.005 0.0001"/>
                <geom pos="0 0 -0.085236" quat="1 0 0 0" type="mesh" contype="0" conaffinity="0" group="1" density="0" rgba="1 1 1 1" mesh="l_handball"/>
                <geom size="0.005" pos="0 0 -0.2175" type="sphere" class="collision"/>
              </body>
            </body>
          </body>
        </body>
        <body name="zarm_r1_link" pos="0 -0.181 0.23843">
          <inertial pos="0.017736 0.00289047 -6.872e-05" quat="0.0901289 0.70032 -0.0825321 0.70329" mass="0.8476" diaginertia="0.00101124 0.000899135 0.000720515"/>
          <joint name="zarm_r1_joint" pos="0 0 0" axis="0 1 0" range="-3.14159 2.0944" actuatorfrcrange="-14.1 14.1" armature="0.003" damping="0.2" frictionloss="0.0"/>
          <geom type="mesh" contype="0" conaffinity="0" group="1" density="0" rgba="1 1 1 1" mesh="r_arm_pitch"/>
          <geom size="0.04 0.02" quat="0.707105 0 0.707108 0" type="capsule" class="collision"/>
          <body name="zarm_r2_link" quat="0.996195 -0.0871543 0 0">
            <inertial pos="0.00199256 0 -0.0321465" quat="0.597773 0.377686 0.377699 0.597799" mass="0.3668" diaginertia="0.00078576 0.000587472 0.000526228"/>
            <joint name="zarm_r2_joint" pos="0 0 0" axis="1 0 0" range="-3.3161 0.52" actuatorfrcrange="-37 37" armature="0.003" damping="0.2" frictionloss="0.0"/>
            <geom type="mesh" contype="0" conaffinity="0" group="1" density="0" rgba="1 1 1 1" mesh="r_arm_roll"/>
            <geom size="0.035 0.0175" pos="0 0 -0.0525" type="capsule" class="collision"/>
            <body name="zarm_r3_link">
              <inertial pos="-7.73e-05 0.0099364 -0.150833" quat="0.996992 0.077485 -0.000148127 -0.00175793" mass="1.5166" diaginertia="0.00716994 0.00690726 0.00128492"/>
              <joint name="zarm_r3_joint" pos="0 0 0" axis="0 0 1" range="-1.5708 1.5708" actuatorfrcrange="-37 37" armature="0.003" damping="0.2" frictionloss="0.0"/>
              <geom type="mesh" contype="0" conaffinity="0" group="1" density="0" rgba="1 1 1 1" mesh="r_arm_yaw"/>
              <geom size="0.035 0.025" pos="0 0 -0.125" type="capsule" class="collision"/>
              <body name="zarm_r4_link" pos="0 0 -0.2085">
                <inertial pos="-0.000693279 0.00191472 -0.0925486" quat="0.999843 -0.0163619 -0.00329901 -0.00594719" mass="0.522124" diaginertia="0.00347786 0.00326967 0.000556314"/>
                <joint name="zarm_r4_joint" pos="0 0 0" axis="0 1 0" range="-2.26893 0.08726" actuatorfrcrange="-37 37" armature="0.003" damping="0.2" frictionloss="0.0"/>
                <geom type="mesh" contype="0" conaffinity="0" group="1" density="0" rgba="1 1 1 1" mesh="r_forearm"/>
                <geom size="0.045 0.015" quat="0.707388 0.706825 0 0" type="capsule" class="collision"/>
                <geom size="0.02 0.06" pos="0 0 -0.1" type="capsule" class="collision"/>
                <geom size="0.03" pos="0 0 -0.2175" class="collision" friction="0.0001 0.005 0.0001"/>
                <geom pos="0 0 -0.085236" quat="1 0 0 0" type="mesh" contype="0" conaffinity="0" group="1" density="0" rgba="1 1 1 1" mesh="r_handball"/>
                <geom size="0.005" pos="0 0 -0.2175" type="sphere" class="collision"/>
              </body>
            </body>
          </body>
        </body>
        <body name="zhead_1_link" pos="0.0042 0 0.35369">
          <inertial pos="-0.0006027 0.00784135 0.0120802" quat="0.993684 -0.112148 0.00355464 0.00165384" mass="1.07556" diaginertia="0.00274017 0.00240047 0.00101587"/>
          <joint name="zhead_1_joint" pos="0 0 0" axis="0 0 1" range="-1.5708 1.5708" actuatorfrcrange="-1.5 1.5" armature="0.003" damping="0.2" frictionloss="0.0"/>
          <geom type="mesh" contype="0" conaffinity="0" group="1" density="0" rgba="1 1 1 1" mesh="head_yaw"/>
          <geom size="0.035 0.05" type="capsule" class="collision"/>
          <geom pos="0 0 -0.026453" quat="1 0 0 0" type="mesh" contype="0" conaffinity="0" group="1" density="0" rgba="1 1 1 1" mesh="head_radar"/>
          <body name="zhead_2_link">
            <inertial pos="0.0112168 -1.52669e-05 0.058128" quat="-0.0025487 0.842744 -0.00355735 0.538297" mass="0.61001" diaginertia="0.00293286 0.002812 0.00219503"/>
            <joint name="zhead_2_joint" pos="0 0 0" axis="0 1 0" range="-0.349066 0.785398" actuatorfrcrange="-12 12" armature="0.003" damping="0.2" frictionloss="0.0"/>
            <geom type="mesh" contype="0" conaffinity="0" group="1" density="0" rgba="1 1 1 1" mesh="head_pitch"/>
            <geom size="0.075" pos="0 0 0.035" class="collision"/>
            <geom pos="0.047118 0 0.051192" quat="0.990799 0 0.135343 0" type="mesh" contype="0" conaffinity="0" group="1" density="0" rgba="1 1 1 1" mesh="head_camera_base"/>
          </body>
        </body>
      </body>
    </body>
  </worldbody>
  <actuator>
    <motor gear="1" joint="leg_l1_joint" name="leg_l1_joint_motor" ctrllimited="true" ctrlrange="-150 150" />
    <motor gear="1" joint="leg_l2_joint" name="leg_l2_joint_motor" ctrllimited="true" ctrlrange="-150 150" />
    <motor gear="1" joint="leg_l3_joint" name="leg_l3_joint_motor" ctrllimited="true" ctrlrange="-70 70" />
    <motor gear="1" joint="leg_l4_joint" name="leg_l4_joint_motor" ctrllimited="true" ctrlrange="-150 150" />
    <motor gear="1" joint="leg_l5_joint" name="leg_l5_joint_motor" ctrllimited="true" ctrlrange="-74 74" />
    <motor gear="1" joint="leg_l6_joint" name="leg_l6_joint_motor" ctrllimited="true" ctrlrange="-74 74" />
    <motor gear="1" joint="leg_r1_joint" name="leg_r1_joint_motor" ctrllimited="true" ctrlrange="-150 150" />
    <motor gear="1" joint="leg_r2_joint" name="leg_r2_joint_motor" ctrllimited="true" ctrlrange="-150 150" />
    <motor gear="1" joint="leg_r3_joint" name="leg_r3_joint_motor" ctrllimited="true" ctrlrange="-70 70" />
    <motor gear="1" joint="leg_r4_joint" name="leg_r4_joint_motor" ctrllimited="true" ctrlrange="-150 150" />
    <motor gear="1" joint="leg_r5_joint" name="leg_r5_joint_motor" ctrllimited="true" ctrlrange="-74 74" />
    <motor gear="1" joint="leg_r6_joint" name="leg_r6_joint_motor" ctrllimited="true" ctrlrange="-74 74" />
    <motor gear="1" joint="waist_yaw_joint" name="waist_yaw_joint_motor" ctrllimited="true" ctrlrange="-80 80" />
    <motor gear="1" joint="zarm_l1_joint" name="zarm_l1_joint_motor" ctrllimited="true" ctrlrange="-14.1 14.1" />
    <motor gear="1" joint="zarm_l2_joint" name="zarm_l2_joint_motor" ctrllimited="true" ctrlrange="-37 37" />
    <motor gear="1" joint="zarm_l3_joint" name="zarm_l3_joint_motor" ctrllimited="true" ctrlrange="-37 37" />
    <motor gear="1" joint="zarm_l4_joint" name="zarm_l4_joint_motor" ctrllimited="true" ctrlrange="-37 37" />
    <motor gear="1" joint="zarm_r1_joint" name="zarm_r1_joint_motor" ctrllimited="true" ctrlrange="-14.1 14.1" />
    <motor gear="1" joint="zarm_r2_joint" name="zarm_r2_joint_motor" ctrllimited="true" ctrlrange="-37 37" />
    <motor gear="1" joint="zarm_r3_joint" name="zarm_r3_joint_motor" ctrllimited="true" ctrlrange="-37 37" />
    <motor gear="1" joint="zarm_r4_joint" name="zarm_r4_joint_motor" ctrllimited="true" ctrlrange="-37 37" />
    <motor gear="1" joint="zhead_1_joint" name="zhead_1_joint_motor" ctrllimited="true" ctrlrange="-14.1 14.1" />
    <motor gear="1" joint="zhead_2_joint" name="zhead_2_joint_motor" ctrllimited="true" ctrlrange="-14.1 14.1" />
  </actuator>
  <sensor>
    <accelerometer name="BodyAcc" site="imu" />
    <velocimeter name="BodyVel" site="imu" />
    <gyro name="BodyGyro" site="imu" />
    <framepos name="BodyPos" objtype="site" objname="imu" />
    <framequat name="BodyQuat" objtype="site" objname="imu" />
    <jointpos name="leg_l1_joint_pos" joint="leg_l1_joint" />
    <jointpos name="leg_l2_joint_pos" joint="leg_l2_joint" />
    <jointpos name="leg_l3_joint_pos" joint="leg_l3_joint" />
    <jointpos name="leg_l4_joint_pos" joint="leg_l4_joint" />
    <jointpos name="leg_l5_joint_pos" joint="leg_l5_joint" />
    <jointpos name="leg_l6_joint_pos" joint="leg_l6_joint" />
    <jointpos name="leg_r1_joint_pos" joint="leg_r1_joint" />
    <jointpos name="leg_r2_joint_pos" joint="leg_r2_joint" />
    <jointpos name="leg_r3_joint_pos" joint="leg_r3_joint" />
    <jointpos name="leg_r4_joint_pos" joint="leg_r4_joint" />
    <jointpos name="leg_r5_joint_pos" joint="leg_r5_joint" />
    <jointpos name="leg_r6_joint_pos" joint="leg_r6_joint" />
    <jointpos name="waist_yaw_joint_pos" joint="waist_yaw_joint" />
    <jointpos name="zarm_l1_joint_pos" joint="zarm_l1_joint" />
    <jointpos name="zarm_l2_joint_pos" joint="zarm_l2_joint" />
    <jointpos name="zarm_l3_joint_pos" joint="zarm_l3_joint" />
    <jointpos name="zarm_l4_joint_pos" joint="zarm_l4_joint" />
    <jointpos name="zarm_r1_joint_pos" joint="zarm_r1_joint" />
    <jointpos name="zarm_r2_joint_pos" joint="zarm_r2_joint" />
    <jointpos name="zarm_r3_joint_pos" joint="zarm_r3_joint" />
    <jointpos name="zarm_r4_joint_pos" joint="zarm_r4_joint" />
    <jointpos name="zhead_1_joint_pos" joint="zhead_1_joint" />
    <jointpos name="zhead_2_joint_pos" joint="zhead_2_joint" />
    <jointvel name="leg_l1_joint_vel" joint="leg_l1_joint" />
    <jointvel name="leg_l2_joint_vel" joint="leg_l2_joint" />
    <jointvel name="leg_l3_joint_vel" joint="leg_l3_joint" />
    <jointvel name="leg_l4_joint_vel" joint="leg_l4_joint" />
    <jointvel name="leg_l5_joint_vel" joint="leg_l5_joint" />
    <jointvel name="leg_l6_joint_vel" joint="leg_l6_joint" />
    <jointvel name="leg_r1_joint_vel" joint="leg_r1_joint" />
    <jointvel name="leg_r2_joint_vel" joint="leg_r2_joint" />
    <jointvel name="leg_r3_joint_vel" joint="leg_r3_joint" />
    <jointvel name="leg_r4_joint_vel" joint="leg_r4_joint" />
    <jointvel name="leg_r5_joint_vel" joint="leg_r5_joint" />
    <jointvel name="leg_r6_joint_vel" joint="leg_r6_joint" />
    <jointvel name="waist_yaw_joint_vel" joint="waist_yaw_joint" />
    <jointvel name="zarm_l1_joint_vel" joint="zarm_l1_joint" />
    <jointvel name="zarm_l2_joint_vel" joint="zarm_l2_joint" />
    <jointvel name="zarm_l3_joint_vel" joint="zarm_l3_joint" />
    <jointvel name="zarm_l4_joint_vel" joint="zarm_l4_joint" />
    <jointvel name="zarm_r1_joint_vel" joint="zarm_r1_joint" />
    <jointvel name="zarm_r2_joint_vel" joint="zarm_r2_joint" />
    <jointvel name="zarm_r3_joint_vel" joint="zarm_r3_joint" />
    <jointvel name="zarm_r4_joint_vel" joint="zarm_r4_joint" />
    <jointvel name="zhead_1_joint_vel" joint="zhead_1_joint" />
    <jointvel name="zhead_2_joint_vel" joint="zhead_2_joint" />
  </sensor>
</mujoco>
