<?xml version="1.0" ?>
<!-- =================================================================================== -->
<!-- |    This document was autogenerated by xacro from /home/fandes/workspace/kuavo-ros-control/src/humanoid-control/humanoid_interface_drake/models/biped_gen4.2/urdf/biped_v3.xacro | -->
<!-- |    EDITING THIS FILE BY HAND IS NOT RECOMMENDED                                 | -->
<!-- =================================================================================== -->
<robot name="biped_v3" xmlns:drake="https://drake.mit.edu">
  <link name="torso">
    <inertial>
      <origin xyz="-0.0185005 0.00031952 0.1929569" rpy="0 0 0" />
      <mass value="39.51433803" />
      <inertia ixx="0.93103133" ixy="0.00011763" ixz="-0.07210993" iyy="0.82590532" iyz="6.88e-06" izz="0.27686612" />
    </inertial>
    <visual>
      <origin rpy="0 0 0" xyz="0 0 0"/>
      <geometry>
        <mesh filename="../../meshes/torso.STL"/>
      </geometry>
      <material name="">
        <color rgba="0.43137 0.45098 0.43137 1"/>
      </material>
    </visual>
    <!-- <collision>
      <origin xyz="0 0 0" rpy="0 0 0" />
      <geometry>
        <mesh filename="../../meshes/torso.STL" />
      </geometry>
    </collision> -->
  </link>
  <link name="leg_l1_link">
    <inertial>
      <origin xyz="-0.00430148 -2.708e-05 -0.00851195" rpy="0 0 0" />
      <mass value="1.71093115" />
      <inertia ixx="0.00206092" ixy="1.97e-06" ixz="6.944e-05" iyy="0.00277274" iyz="-5.1e-06" izz="0.00370826" />
    </inertial>
    <visual>
      <origin xyz="0 0 0" rpy="0 0 0" />
      <geometry>
        <mesh filename="../../meshes/l_leg_roll.STL" />
      </geometry>
      <material name="">
        <color rgba="1 1 1 1" />
      </material>
    </visual>
  </link>
  <joint name="leg_l1_joint" type="revolute">
    <origin xyz="-0.0024999 0.087 -0.066" rpy="0 0 0" />
    <parent link="torso" />
    <child link="leg_l1_link" />
    <axis xyz="1 0 0" />
    <limit lower="-0.314159265358979" upper="0.663225115757845" effort="180.0" velocity="23.55" />
  </joint>
  <transmission type="SimpleTransmission">
    <joint name="leg_l1_joint" />
    <actuator name="leg_l1_joint_motor" />
  </transmission>
  <link name="leg_l2_link">
    <inertial>
      <origin xyz="0.0 -0.00231118 -0.09062539" rpy="0 0 0" />
      <mass value="0.58029165" />
      <inertia ixx="0.00223984" ixy="0.0" ixz="3e-08" iyy="0.00123175" iyz="-6.98e-06" izz="0.00146391" />
    </inertial>
    <visual>
      <origin xyz="0 0 0" rpy="0 0 0" />
      <geometry>
        <mesh filename="../../meshes/l_leg_yaw.STL" />
      </geometry>
      <material name="">
        <color rgba="1 1 1 1" />
      </material>
    </visual>
  </link>
  <joint name="leg_l2_joint" type="revolute">
    <origin xyz="0 0 0" rpy="0 0 0" />
    <parent link="leg_l1_link" />
    <child link="leg_l2_link" />
    <axis xyz="0 0 1" />
    <limit lower="-0.872664625997165" upper="0.785398163397448" effort="100.0" velocity="41.3433333333333" />
  </joint>
  <transmission type="SimpleTransmission">
    <joint name="leg_l2_joint" />
    <actuator name="leg_l2_joint_motor" />
  </transmission>
  <link name="leg_l3_link">
    <inertial>
      <origin xyz="0.00150537 0.01199614 -0.08411619" rpy="0 0 0" />
      <mass value="4.50393141" />
      <inertia ixx="0.0389365" ixy="7.866e-05" ixz="0.00102086" iyy="0.03942609" iyz="0.00219138" izz="0.00999961" />
    </inertial>
    <visual>
      <origin xyz="0 0 0" rpy="0 0 0" />
      <geometry>
        <mesh filename="../../meshes/l_leg_pitch.STL" />
      </geometry>
      <material name="">
        <color rgba="1 1 1 1" />
      </material>
    </visual>
  </link>
  <joint name="leg_l3_joint" type="revolute">
    <origin xyz="0.000500354536093913 -0.00100000000000011 -0.1287" rpy="0 0 0" />
    <parent link="leg_l2_link" />
    <child link="leg_l3_link" />
    <axis xyz="0 1 0" />
    <limit lower="-2.00712863979348" upper="1.5707963267949" effort="100.0" velocity="41.3433333333333" />
  </joint>
  <transmission type="SimpleTransmission">
    <joint name="leg_l3_joint" />
    <actuator name="leg_l3_joint_motor" />
  </transmission>
  <link name="leg_l4_link">
    <inertial>
      <origin xyz="0.00696242 5.314e-05 -0.11549851" rpy="0 0 0" />
      <mass value="1.62776815" />
      <inertia ixx="0.01243912" ixy="-2.29e-06" ixz="5.881e-05" iyy="0.01229563" iyz="-2.895e-05" izz="0.00097937" />
    </inertial>
    <visual>
      <origin xyz="0 0 0" rpy="0 0 0" />
      <geometry>
        <mesh filename="../../meshes/l_knee.STL" />
      </geometry>
      <material name="">
        <color rgba="1 1 1 1" />
      </material>
    </visual>
  </link>
  <joint name="leg_l4_joint" type="revolute">
    <origin xyz="-6.87185435835039E-05 0 -0.284" rpy="0 0 0" />
    <parent link="leg_l3_link" />
    <child link="leg_l4_link" />
    <axis xyz="0 1 0" />
    <limit lower="0.0" upper="2.53072741539178" effort="180.0" velocity="23.55" />
  </joint>
  <transmission type="SimpleTransmission">
    <joint name="leg_l4_joint" />
    <actuator name="leg_l4_joint_motor" />
  </transmission>
  <link name="leg_l5_link">
    <inertial>
      <origin xyz="0.0 0.0 0.0" rpy="0 0 0" />
      <mass value="0.07193524" />
      <inertia ixx="6.92e-06" ixy="0.0" ixz="0.0" iyy="6.92e-06" iyz="0.0" izz="1.218e-05" />
    </inertial>
    <visual>
      <origin xyz="0 0 0" rpy="0 0 0" />
      <geometry>
        <mesh filename="../../meshes/l_foot_pitch.STL" />
      </geometry>
      <material name="">
        <color rgba="1 1 1 1" />
      </material>
    </visual>
  </link>
  <joint name="leg_l5_joint" type="revolute">
    <origin xyz="-0.000431635992531742 0 -0.346000000000001" rpy="0 0 0" />
    <parent link="leg_l4_link" />
    <child link="leg_l5_link" />
    <axis xyz="0 1 0" />
    <limit lower="-0.872664625997165" upper="0.349065850398866" effort="36.0" velocity="23.0266666666667" />
  </joint>
  <transmission type="SimpleTransmission">
    <joint name="leg_l5_joint" />
    <actuator name="leg_l5_joint_motor" />
  </transmission>
  <link name="leg_l6_link">
    <inertial>
      <origin xyz="0.03732754 -2.22e-06 -0.03883977" rpy="0 0 0" />
      <mass value="0.49861272" />
      <inertia ixx="0.00039242" ixy="3e-08" ixz="4.664e-05" iyy="0.00158655" iyz="0.0" izz="0.00172576" />
    </inertial>
    <visual>
      <origin xyz="0 0 0" rpy="0 0 0" />
      <geometry>
        <mesh filename="../../meshes/l_foot_roll.STL" />
      </geometry>
      <material name="">
        <color rgba="1 1 1 1" />
      </material>
    </visual>
  </link>
  <joint name="leg_l6_joint" type="revolute">
    <origin xyz="0 0 0" rpy="0 0 0" />
    <parent link="leg_l5_link" />
    <child link="leg_l6_link" />
    <axis xyz="1 0 0" />
    <limit lower="-0.261799387799149" upper="0.261799387799149" effort="36.0" velocity="23.0266666666667" />
  </joint>
  <transmission type="SimpleTransmission">
    <joint name="leg_l6_joint" />
    <actuator name="leg_l6_joint_motor" />
  </transmission>
  <!-- sssssssss -->
  <frame link="leg_l6_link" name="l_foot_sole" xyz="0.048838 0.0 -0.0593"/>
  <frame link="leg_l6_link" name="l_foot_toe" xyz="0.17084 0.0 -0.0593"/>
  <frame link="leg_l6_link" name="l_foot_heel" xyz="-0.073164 0.0 -0.0593"/>
  <link name="leg_r1_link">
    <inertial>
      <origin xyz="-0.00430146 2.709e-05 -0.00851195" rpy="0 0 0" />
      <mass value="1.71093008" />
      <inertia ixx="0.00206092" ixy="-1.97e-06" ixz="6.944e-05" iyy="0.00277274" iyz="5.1e-06" izz="0.00370826" />
    </inertial>
    <visual>
      <origin xyz="0 0 0" rpy="0 0 0" />
      <geometry>
        <mesh filename="../../meshes/r_leg_roll.STL" />
      </geometry>
      <material name="">
        <color rgba="1 1 1 1" />
      </material>
    </visual>
  </link>
  <joint name="leg_r1_joint" type="revolute">
    <origin xyz="-0.0024999 -0.087 -0.066" rpy="0 0 0" />
    <parent link="torso" />
    <child link="leg_r1_link" />
    <axis xyz="1 0 0" />
    <limit lower="-0.663225115757845" upper="0.314159265358979" effort="180.0" velocity="23.55" />
  </joint>
  <transmission type="SimpleTransmission">
    <joint name="leg_r1_joint" />
    <actuator name="leg_r1_joint_motor" />
  </transmission>
  <link name="leg_r2_link">
    <inertial>
      <origin xyz="0.0 0.00231118 -0.09062539" rpy="0 0 0" />
      <mass value="0.58029165" />
      <inertia ixx="0.00223984" ixy="0.0" ixz="-3e-08" iyy="0.00123175" iyz="6.98e-06" izz="0.00146391" />
    </inertial>
    <visual>
      <origin xyz="0 0 0" rpy="0 0 0" />
      <geometry>
        <mesh filename="../../meshes/r_leg_yaw.STL" />
      </geometry>
      <material name="">
        <color rgba="1 1 1 1" />
      </material>
    </visual>
  </link>
  <joint name="leg_r2_joint" type="revolute">
    <origin xyz="0 0 0" rpy="0 0 0" />
    <parent link="leg_r1_link" />
    <child link="leg_r2_link" />
    <axis xyz="0 0 1" />
    <limit lower="-0.785398163397448" upper="0.872664625997165" effort="100.0" velocity="41.3433333333333" />
  </joint>
  <transmission type="SimpleTransmission">
    <joint name="leg_r2_joint" />
    <actuator name="leg_r2_joint_motor" />
  </transmission>
  <link name="leg_r3_link">
    <inertial>
      <origin xyz="0.00208315 -0.01199644 -0.08411379" rpy="0 0 0" />
      <mass value="4.50385993" />
      <inertia ixx="0.03893478" ixy="-7.792e-05" ixz="0.00103064" iyy="0.03942522" iyz="-0.00219154" izz="0.01000016" />
    </inertial>
    <visual>
      <origin xyz="0 0 0" rpy="0 0 0" />
      <geometry>
        <mesh filename="../../meshes/r_leg_pitch.STL" />
      </geometry>
      <material name="">
        <color rgba="1 1 1 1" />
      </material>
    </visual>
  </link>
  <joint name="leg_r3_joint" type="revolute">
    <origin xyz="-4.88006581312577E-05 0 -0.1287" rpy="0 0 0" />
    <parent link="leg_r2_link" />
    <child link="leg_r3_link" />
    <axis xyz="0 1 0" />
    <limit lower="-2.00712863979348" upper="1.5707963267949" effort="100.0" velocity="41.3433333333333" />
  </joint>
  <transmission type="SimpleTransmission">
    <joint name="leg_r3_joint" />
    <actuator name="leg_r3_joint_motor" />
  </transmission>
  <link name="leg_r4_link">
    <inertial>
      <origin xyz="0.00743231 -5.343e-05 -0.11558701" rpy="0 0 0" />
      <mass value="1.62655699" />
      <inertia ixx="0.01241258" ixy="2.28e-06" ixz="6.289e-05" iyy="0.0122692" iyz="2.902e-05" izz="0.00097927" />
    </inertial>
    <visual>
      <origin xyz="0 0 0" rpy="0 0 0" />
      <geometry>
        <mesh filename="../../meshes/r_knee.STL" />
      </geometry>
      <material name="">
        <color rgba="1 1 1 1" />
      </material>
    </visual>
  </link>
  <joint name="leg_r4_joint" type="revolute">
    <origin xyz="0.000147138572785148 0 -0.283999982974744" rpy="0 0 0" />
    <parent link="leg_r3_link" />
    <child link="leg_r4_link" />
    <axis xyz="0 1 0" />
    <limit lower="0.0" upper="2.53072741539178" effort="180.0" velocity="23.55" />
  </joint>
  <transmission type="SimpleTransmission">
    <joint name="leg_r4_joint" />
    <actuator name="leg_r4_joint_motor" />
  </transmission>
  <link name="leg_r5_link">
    <inertial>
      <origin xyz="0.0 0.0 0.0" rpy="0 0 0" />
      <mass value="0.07193524" />
      <inertia ixx="6.92e-06" ixy="0.0" ixz="0.0" iyy="6.92e-06" iyz="0.0" izz="1.218e-05" />
    </inertial>
    <visual>
      <origin xyz="0 0 0" rpy="0 0 0" />
      <geometry>
        <mesh filename="../../meshes/r_foot_pitch.STL" />
      </geometry>
      <material name="">
        <color rgba="1 1 1 1" />
      </material>
    </visual>
  </link>
  <joint name="leg_r5_joint" type="revolute">
    <origin xyz="0.000119806050928577 0 -0.345999979257963" rpy="0 0 0" />
    <parent link="leg_r4_link" />
    <child link="leg_r5_link" />
    <axis xyz="0 1 0" />
    <limit lower="-0.872664625997165" upper="0.349065850398866" effort="36.0" velocity="23.0266666666667" />
  </joint>
  <transmission type="SimpleTransmission">
    <joint name="leg_r5_joint" />
    <actuator name="leg_r5_joint_motor" />
  </transmission>
  <link name="leg_r6_link">
    <inertial>
      <origin xyz="0.03734098 -2.22e-06 -0.03882684" rpy="0 0 0" />
      <mass value="0.49861272" />
      <inertia ixx="0.00039238" ixy="3e-08" ixz="4.618e-05" iyy="0.00158655" iyz="0.0" izz="0.00172579" />
    </inertial>
    <visual>
      <origin xyz="0 0 0" rpy="0 0 0" />
      <geometry>
        <mesh filename="../../meshes/r_foot_roll.STL" />
      </geometry>
      <material name="">
        <color rgba="1 1 1 1" />
      </material>
    </visual>
  </link>
  <joint name="leg_r6_joint" type="revolute">
    <origin xyz="0 0 0" rpy="0 0 0" />
    <parent link="leg_r5_link" />
    <child link="leg_r6_link" />
    <axis xyz="1 0 0" />
    <limit lower="-0.261799387799149" upper="0.261799387799149" effort="36.0" velocity="23.0266666666667" />
  </joint>
  <transmission type="SimpleTransmission">
    <joint name="leg_r6_joint" />
    <actuator name="leg_r6_joint_motor" />
  </transmission>
  <!-- sssssssss -->
  <frame link="leg_r6_link" name="r_foot_sole" xyz="0.048838 0.0 -0.0593"/>
  <frame link="leg_r6_link" name="r_foot_toe" xyz="0.17084 0.0 -0.0593"/>
  <frame link="leg_r6_link" name="r_foot_heel" xyz="-0.073164 0.0 -0.0593"/>
</robot>

