<?xml version="1.0" ?>
<!-- =================================================================================== -->
<!-- |    This document was autogenerated by xacro from /home/fandes/workspace/kuavo-ros-control/src/humanoid-control/humanoid_interface_drake/models/biped_gen4.2/urdf/biped_v3_all_joint.xacro | -->
<!-- |    EDITING THIS FILE BY HAND IS NOT RECOMMENDED                                 | -->
<!-- =================================================================================== -->
<robot name="biped_v3_all_joint" xmlns:drake="https://drake.mit.edu">
  <link name="torso">
    <inertial>
      <origin rpy="0 0 0" xyz="-0.01779947 0.00029663 0.18176446"/>
      <mass value="28.48754316"/>
      <inertia ixx="0.84217451" ixy="-0.00019450" ixz="0.06746774" iyy="0.73769958" iyz="-0.00007935" izz="0.24371683"/>
    </inertial>
    <visual>
      <origin rpy="0 0 0" xyz="0 0 0"/>
      <geometry>
        <mesh filename="../../meshes/torso.STL"/>
      </geometry>
      <material name="">
        <color rgba="0.43137 0.45098 0.43137 1"/>
      </material>
    </visual>
    <!-- <collision>
      <origin xyz="0 0 0" rpy="0 0 0" />
      <geometry>
        <mesh filename="../../meshes/torso.STL" />
      </geometry>
    </collision> -->
  </link>
  <link name="leg_l1_link">
    <inertial>
      <origin xyz="-0.00430148 -2.708e-05 -0.00851195" rpy="0 0 0" />
      <mass value="1.71093115" />
      <inertia ixx="0.00206092" ixy="1.97e-06" ixz="6.944e-05" iyy="0.00277274" iyz="-5.1e-06" izz="0.00370826" />
    </inertial>
    <visual>
      <origin xyz="0 0 0" rpy="0 0 0" />
      <geometry>
        <mesh filename="../../meshes/l_leg_roll.STL" />
      </geometry>
      <material name="">
        <color rgba="1 1 1 1" />
      </material>
    </visual>
  </link>
  <joint name="leg_l1_joint" type="revolute">
    <origin xyz="-0.0024999 0.087 -0.066" rpy="0 0 0" />
    <parent link="torso" />
    <child link="leg_l1_link" />
    <axis xyz="1 0 0" />
    <limit lower="-0.314159265358979" upper="0.663225115757845" effort="180.0" velocity="23.55" />
  </joint>
  <transmission type="SimpleTransmission">
    <joint name="leg_l1_joint" />
    <actuator name="leg_l1_joint_motor" />
  </transmission>
  <link name="leg_l2_link">
    <inertial>
      <origin xyz="0.0 -0.00231118 -0.09062539" rpy="0 0 0" />
      <mass value="0.58029165" />
      <inertia ixx="0.00223984" ixy="0.0" ixz="3e-08" iyy="0.00123175" iyz="-6.98e-06" izz="0.00146391" />
    </inertial>
    <visual>
      <origin xyz="0 0 0" rpy="0 0 0" />
      <geometry>
        <mesh filename="../../meshes/l_leg_yaw.STL" />
      </geometry>
      <material name="">
        <color rgba="1 1 1 1" />
      </material>
    </visual>
  </link>
  <joint name="leg_l2_joint" type="revolute">
    <origin xyz="0 0 0" rpy="0 0 0" />
    <parent link="leg_l1_link" />
    <child link="leg_l2_link" />
    <axis xyz="0 0 1" />
    <limit lower="-0.872664625997165" upper="0.785398163397448" effort="100.0" velocity="41.3433333333333" />
  </joint>
  <transmission type="SimpleTransmission">
    <joint name="leg_l2_joint" />
    <actuator name="leg_l2_joint_motor" />
  </transmission>
  <link name="leg_l3_link">
    <inertial>
      <origin xyz="0.00150537 0.01199614 -0.08411619" rpy="0 0 0" />
      <mass value="4.50393141" />
      <inertia ixx="0.0389365" ixy="7.866e-05" ixz="0.00102086" iyy="0.03942609" iyz="0.00219138" izz="0.00999961" />
    </inertial>
    <visual>
      <origin xyz="0 0 0" rpy="0 0 0" />
      <geometry>
        <mesh filename="../../meshes/l_leg_pitch.STL" />
      </geometry>
      <material name="">
        <color rgba="1 1 1 1" />
      </material>
    </visual>
  </link>
  <joint name="leg_l3_joint" type="revolute">
    <origin xyz="0.000500354536093913 -0.00100000000000011 -0.1287" rpy="0 0 0" />
    <parent link="leg_l2_link" />
    <child link="leg_l3_link" />
    <axis xyz="0 1 0" />
    <limit lower="-2.00712863979348" upper="1.5707963267949" effort="100.0" velocity="41.3433333333333" />
  </joint>
  <transmission type="SimpleTransmission">
    <joint name="leg_l3_joint" />
    <actuator name="leg_l3_joint_motor" />
  </transmission>
  <link name="leg_l4_link">
    <inertial>
      <origin xyz="0.00696242 5.314e-05 -0.11549851" rpy="0 0 0" />
      <mass value="1.62776815" />
      <inertia ixx="0.01243912" ixy="-2.29e-06" ixz="5.881e-05" iyy="0.01229563" iyz="-2.895e-05" izz="0.00097937" />
    </inertial>
    <visual>
      <origin xyz="0 0 0" rpy="0 0 0" />
      <geometry>
        <mesh filename="../../meshes/l_knee.STL" />
      </geometry>
      <material name="">
        <color rgba="1 1 1 1" />
      </material>
    </visual>
  </link>
  <joint name="leg_l4_joint" type="revolute">
    <origin xyz="-6.87185435835039E-05 0 -0.284" rpy="0 0 0" />
    <parent link="leg_l3_link" />
    <child link="leg_l4_link" />
    <axis xyz="0 1 0" />
    <limit lower="0.0" upper="2.53072741539178" effort="180.0" velocity="23.55" />
  </joint>
  <transmission type="SimpleTransmission">
    <joint name="leg_l4_joint" />
    <actuator name="leg_l4_joint_motor" />
  </transmission>
  <link name="leg_l5_link">
    <inertial>
      <origin xyz="0.0 0.0 0.0" rpy="0 0 0" />
      <mass value="0.07193524" />
      <inertia ixx="6.92e-06" ixy="0.0" ixz="0.0" iyy="6.92e-06" iyz="0.0" izz="1.218e-05" />
    </inertial>
    <visual>
      <origin xyz="0 0 0" rpy="0 0 0" />
      <geometry>
        <mesh filename="../../meshes/l_foot_pitch.STL" />
      </geometry>
      <material name="">
        <color rgba="1 1 1 1" />
      </material>
    </visual>
  </link>
  <joint name="leg_l5_joint" type="revolute">
    <origin xyz="-0.000431635992531742 0 -0.346000000000001" rpy="0 0 0" />
    <parent link="leg_l4_link" />
    <child link="leg_l5_link" />
    <axis xyz="0 1 0" />
    <limit lower="-0.872664625997165" upper="0.349065850398866" effort="36.0" velocity="23.0266666666667" />
  </joint>
  <transmission type="SimpleTransmission">
    <joint name="leg_l5_joint" />
    <actuator name="leg_l5_joint_motor" />
  </transmission>
  <link name="leg_l6_link">
    <inertial>
      <origin xyz="0.03732754 -2.22e-06 -0.03883977" rpy="0 0 0" />
      <mass value="0.49861272" />
      <inertia ixx="0.00039242" ixy="3e-08" ixz="4.664e-05" iyy="0.00158655" iyz="0.0" izz="0.00172576" />
    </inertial>
    <visual>
      <origin xyz="0 0 0" rpy="0 0 0" />
      <geometry>
        <mesh filename="../../meshes/l_foot_roll.STL" />
      </geometry>
      <material name="">
        <color rgba="1 1 1 1" />
      </material>
    </visual>
  </link>
  <joint name="leg_l6_joint" type="revolute">
    <origin xyz="0 0 0" rpy="0 0 0" />
    <parent link="leg_l5_link" />
    <child link="leg_l6_link" />
    <axis xyz="1 0 0" />
    <limit lower="-0.261799387799149" upper="0.261799387799149" effort="36.0" velocity="23.0266666666667" />
  </joint>
  <transmission type="SimpleTransmission">
    <joint name="leg_l6_joint" />
    <actuator name="leg_l6_joint_motor" />
  </transmission>
  <!-- sssssssss -->
  <link name="l_l_bar_y">
    <inertial>
      <origin rpy="0 0 0" xyz="-0.017639 -0.0012332 0.0047224"/>
      <mass value="0.041379"/>
      <inertia ixx="6.3487E-06" ixy="-2.7168E-06" ixz="4.9324E-06" iyy="2.8379E-05" iyz="7.2737E-07" izz="2.3451E-05"/>
    </inertial>
    <visual>
      <origin rpy="0 0 0" xyz="0 0 0"/>
      <geometry>
        <mesh filename="../../meshes/l_l_bar.STL"/>
      </geometry>
      <material name="">
        <color rgba="0.6902 0.65882 0.63922 1"/>
      </material>
    </visual>
    <!-- <collision>
      <origin xyz="0 0 0" rpy="0 0 0" />
      <geometry>
        <mesh filename="../../meshes/l_l_bar.STL" />
      </geometry>
    </collision> -->
  </link>
  <joint name="l_l_bar_y" type="continuous">
    <origin rpy="0 0 0" xyz="0 0.0318 -0.09"/>
    <parent link="leg_l4_link"/>
    <child link="l_l_bar_y"/>
    <axis xyz="0 1 0"/>
    <!-- <limit lower="-1.58" upper="0.50" effort="74" velocity="47" /> -->
  </joint>
  <transmission type="SimpleTransmission">
    <joint name="l_l_bar_y"/>
    <actuator name="l_l_bar_y_motor">
      <drake:gear_ratio value="10.0"/>
      <drake:rotor_inertia value="0.0001002"/>
    </actuator>
  </transmission>
  <link name="l_l_tendon_y">
    <inertial>
      <origin rpy="0 0 0" xyz="-1.3642E-05 -0.00048331 -0.13953"/>
      <mass value="0.13223"/>
      <inertia ixx="0.00049161" ixy="3.0645E-12" ixz="1.52E-08" iyy="0.00048973" iyz="-2.4263E-07" izz="4.775E-06"/>
    </inertial>
    <visual>
      <origin rpy="0 0 0" xyz="0 0 0"/>
      <geometry>
        <mesh filename="../../meshes/l_l_tendon.STL"/>
      </geometry>
      <material name="">
        <color rgba="0.6902 0.65882 0.63922 1"/>
      </material>
    </visual>
    <!-- <collision>
      <origin xyz="0 0 0" rpy="0 0 0" />
      <geometry>
        <mesh filename="../../meshes/l_l_tendon.STL" />
      </geometry>
    </collision> -->
  </link>
  <drake:joint name="l_l_tendon_y" type="universal">
    <origin rpy="0 0 0" xyz="-0.056027 -0.0085 0.015"/>
    <parent link="l_l_bar_y"/>
    <child link="l_l_tendon_y"/>
  </drake:joint>
  <frame link="l_l_tendon_y" name="l_l_tendon_socket" xyz="0 0 -0.256"/>
  <link name="l_r_bar_y">
    <inertial>
      <origin rpy="0 0 0" xyz="-0.017639 0.0012332 0.0047224"/>
      <mass value="0.041379"/>
      <inertia ixx="6.3486E-06" ixy="2.7168E-06" ixz="4.9323E-06" iyy="2.8379E-05" iyz="-7.2736E-07" izz="2.3451E-05"/>
    </inertial>
    <visual>
      <origin rpy="0 0 0" xyz="0 0 0"/>
      <geometry>
        <mesh filename="../../meshes/l_r_bar.STL"/>
      </geometry>
      <material name="">
        <color rgba="0.6902 0.65882 0.63922 1"/>
      </material>
    </visual>
    <!-- <collision>
      <origin xyz="0 0 0" rpy="0 0 0" />
      <geometry>
        <mesh filename="../../meshes/l_r_bar.STL" />
      </geometry>
    </collision> -->
  </link>
  <joint name="l_r_bar_y" type="continuous">
    <origin rpy="0 0 0" xyz="0 -0.0362 -0.153"/>
    <parent link="leg_l4_link"/>
    <child link="l_r_bar_y"/>
    <axis xyz="0 1 0"/>
  </joint>
  <link name="l_r_tendon_y">
    <inertial>
      <origin rpy="0 0 0" xyz="-1.9777E-05 0.00047927 -0.10625"/>
      <mass value="0.10643"/>
      <inertia ixx="0.0001972" ixy="4.1988E-12" ixz="-1.2811E-08" iyy="0.00019587" iyz="1.7341E-07" izz="3.9152E-06"/>
    </inertial>
    <visual>
      <origin rpy="0 0 0" xyz="0 0 0"/>
      <geometry>
        <mesh filename="../../meshes/l_r_tendon.STL"/>
      </geometry>
      <material name="">
        <color rgba="0.6902 0.65882 0.63922 1"/>
      </material>
    </visual>
    <!-- <collision>
      <origin xyz="0 0 0" rpy="0 0 0" />
      <geometry>
        <mesh filename="../../meshes/l_r_tendon.STL" />
      </geometry>
    </collision> -->
  </link>
  <drake:joint name="l_r_tendon_y" type="universal">
    <origin rpy="0 0 0" xyz="-0.056027 0.0085 0.015"/>
    <parent link="l_r_bar_y"/>
    <child link="l_r_tendon_y"/>
  </drake:joint>
  <frame link="l_r_tendon_y" name="l_r_tendon_socket" xyz="0 0 -0.193"/>
  <transmission type="SimpleTransmission">
    <joint name="l_r_bar_y"/>
    <actuator name="l_r_bar_y_motor">
      <drake:gear_ratio value="10.0"/>
      <drake:rotor_inertia value="0.0001002"/>
    </actuator>
  </transmission>
  <frame link="leg_l6_link" name="l_l_foot_socket" xyz="-0.056027 0.0255 0.015"/>
  <frame link="leg_l6_link" name="l_r_foot_socket" xyz="-0.056027 -0.0255 0.015"/>
  <!-- 曲柄 -->
  <frame link="l_l_bar_y" name="l_l_foot_bar_frame" xyz="0 -0.0085 0"/>
  <frame link="l_r_bar_y" name="l_r_foot_bar_frame" xyz="0 0.0085 0"/>
  <link name="leg_r1_link">
    <inertial>
      <origin xyz="-0.00430146 2.709e-05 -0.00851195" rpy="0 0 0" />
      <mass value="1.71093008" />
      <inertia ixx="0.00206092" ixy="-1.97e-06" ixz="6.944e-05" iyy="0.00277274" iyz="5.1e-06" izz="0.00370826" />
    </inertial>
    <visual>
      <origin xyz="0 0 0" rpy="0 0 0" />
      <geometry>
        <mesh filename="../../meshes/r_leg_roll.STL" />
      </geometry>
      <material name="">
        <color rgba="1 1 1 1" />
      </material>
    </visual>
  </link>
  <joint name="leg_r1_joint" type="revolute">
    <origin xyz="-0.0024999 -0.087 -0.066" rpy="0 0 0" />
    <parent link="torso" />
    <child link="leg_r1_link" />
    <axis xyz="1 0 0" />
    <limit lower="-0.663225115757845" upper="0.314159265358979" effort="180.0" velocity="23.55" />
  </joint>
  <transmission type="SimpleTransmission">
    <joint name="leg_r1_joint" />
    <actuator name="leg_r1_joint_motor" />
  </transmission>
  <link name="leg_r2_link">
    <inertial>
      <origin xyz="0.0 0.00231118 -0.09062539" rpy="0 0 0" />
      <mass value="0.58029165" />
      <inertia ixx="0.00223984" ixy="0.0" ixz="-3e-08" iyy="0.00123175" iyz="6.98e-06" izz="0.00146391" />
    </inertial>
    <visual>
      <origin xyz="0 0 0" rpy="0 0 0" />
      <geometry>
        <mesh filename="../../meshes/r_leg_yaw.STL" />
      </geometry>
      <material name="">
        <color rgba="1 1 1 1" />
      </material>
    </visual>
  </link>
  <joint name="leg_r2_joint" type="revolute">
    <origin xyz="0 0 0" rpy="0 0 0" />
    <parent link="leg_r1_link" />
    <child link="leg_r2_link" />
    <axis xyz="0 0 1" />
    <limit lower="-0.785398163397448" upper="0.872664625997165" effort="100.0" velocity="41.3433333333333" />
  </joint>
  <transmission type="SimpleTransmission">
    <joint name="leg_r2_joint" />
    <actuator name="leg_r2_joint_motor" />
  </transmission>
  <link name="leg_r3_link">
    <inertial>
      <origin xyz="0.00208315 -0.01199644 -0.08411379" rpy="0 0 0" />
      <mass value="4.50385993" />
      <inertia ixx="0.03893478" ixy="-7.792e-05" ixz="0.00103064" iyy="0.03942522" iyz="-0.00219154" izz="0.01000016" />
    </inertial>
    <visual>
      <origin xyz="0 0 0" rpy="0 0 0" />
      <geometry>
        <mesh filename="../../meshes/r_leg_pitch.STL" />
      </geometry>
      <material name="">
        <color rgba="1 1 1 1" />
      </material>
    </visual>
  </link>
  <joint name="leg_r3_joint" type="revolute">
    <origin xyz="-4.88006581312577E-05 0 -0.1287" rpy="0 0 0" />
    <parent link="leg_r2_link" />
    <child link="leg_r3_link" />
    <axis xyz="0 1 0" />
    <limit lower="-2.00712863979348" upper="1.5707963267949" effort="100.0" velocity="41.3433333333333" />
  </joint>
  <transmission type="SimpleTransmission">
    <joint name="leg_r3_joint" />
    <actuator name="leg_r3_joint_motor" />
  </transmission>
  <link name="leg_r4_link">
    <inertial>
      <origin xyz="0.00743231 -5.343e-05 -0.11558701" rpy="0 0 0" />
      <mass value="1.62655699" />
      <inertia ixx="0.01241258" ixy="2.28e-06" ixz="6.289e-05" iyy="0.0122692" iyz="2.902e-05" izz="0.00097927" />
    </inertial>
    <visual>
      <origin xyz="0 0 0" rpy="0 0 0" />
      <geometry>
        <mesh filename="../../meshes/r_knee.STL" />
      </geometry>
      <material name="">
        <color rgba="1 1 1 1" />
      </material>
    </visual>
  </link>
  <joint name="leg_r4_joint" type="revolute">
    <origin xyz="0.000147138572785148 0 -0.283999982974744" rpy="0 0 0" />
    <parent link="leg_r3_link" />
    <child link="leg_r4_link" />
    <axis xyz="0 1 0" />
    <limit lower="0.0" upper="2.53072741539178" effort="180.0" velocity="23.55" />
  </joint>
  <transmission type="SimpleTransmission">
    <joint name="leg_r4_joint" />
    <actuator name="leg_r4_joint_motor" />
  </transmission>
  <link name="leg_r5_link">
    <inertial>
      <origin xyz="0.0 0.0 0.0" rpy="0 0 0" />
      <mass value="0.07193524" />
      <inertia ixx="6.92e-06" ixy="0.0" ixz="0.0" iyy="6.92e-06" iyz="0.0" izz="1.218e-05" />
    </inertial>
    <visual>
      <origin xyz="0 0 0" rpy="0 0 0" />
      <geometry>
        <mesh filename="../../meshes/r_foot_pitch.STL" />
      </geometry>
      <material name="">
        <color rgba="1 1 1 1" />
      </material>
    </visual>
  </link>
  <joint name="leg_r5_joint" type="revolute">
    <origin xyz="0.000119806050928577 0 -0.345999979257963" rpy="0 0 0" />
    <parent link="leg_r4_link" />
    <child link="leg_r5_link" />
    <axis xyz="0 1 0" />
    <limit lower="-0.872664625997165" upper="0.349065850398866" effort="36.0" velocity="23.0266666666667" />
  </joint>
  <transmission type="SimpleTransmission">
    <joint name="leg_r5_joint" />
    <actuator name="leg_r5_joint_motor" />
  </transmission>
  <link name="leg_r6_link">
    <inertial>
      <origin xyz="0.03734098 -2.22e-06 -0.03882684" rpy="0 0 0" />
      <mass value="0.49861272" />
      <inertia ixx="0.00039238" ixy="3e-08" ixz="4.618e-05" iyy="0.00158655" iyz="0.0" izz="0.00172579" />
    </inertial>
    <visual>
      <origin xyz="0 0 0" rpy="0 0 0" />
      <geometry>
        <mesh filename="../../meshes/r_foot_roll.STL" />
      </geometry>
      <material name="">
        <color rgba="1 1 1 1" />
      </material>
    </visual>
  </link>
  <joint name="leg_r6_joint" type="revolute">
    <origin xyz="0 0 0" rpy="0 0 0" />
    <parent link="leg_r5_link" />
    <child link="leg_r6_link" />
    <axis xyz="1 0 0" />
    <limit lower="-0.261799387799149" upper="0.261799387799149" effort="36.0" velocity="23.0266666666667" />
  </joint>
  <transmission type="SimpleTransmission">
    <joint name="leg_r6_joint" />
    <actuator name="leg_r6_joint_motor" />
  </transmission>
  <!--        ssss -->
  <!-- sssssssss -->
  <link name="r_r_bar_y">
    <inertial>
      <origin rpy="0 0 0" xyz="-0.0176387949701166 0.0012332409395871 0.00472242692632874"/>
      <mass value="0.0413794520732275"/>
      <inertia ixx="6.34865185942549E-06" ixy="2.71679945417066E-06" ixz="4.93236590933488E-06" iyy="2.83792003165434E-05" iyz="-7.27368169902599E-07" izz="2.34510462869433E-05"/>
    </inertial>
    <visual>
      <origin rpy="0 0 0" xyz="0 0 0"/>
      <geometry>
        <mesh filename="../../meshes/r_r_bar.STL"/>
      </geometry>
      <material name="">
        <color rgba="0.690196078431373 0.658823529411765 0.63921568627451 1"/>
      </material>
    </visual>
    <!-- <collision>
      <origin xyz="0 0 0" rpy="0 0 0" />
      <geometry>
        <mesh filename="../../meshes/r_r_bar.STL" />
      </geometry>
    </collision> -->
  </link>
  <joint name="r_r_bar_y" type="continuous">
    <origin rpy="0 0 0" xyz="0 -0.0318 -0.09"/>
    <parent link="leg_r4_link"/>
    <child link="r_r_bar_y"/>
    <axis xyz="0 1 0"/>
  </joint>
  <link name="r_r_tendon_y">
    <inertial>
      <origin rpy="0 0 0" xyz="-1.36421989666846E-05 0.000483312127349173 -0.139530966436641"/>
      <mass value="0.132228698944171"/>
      <inertia ixx="0.000491608612358556" ixy="-3.05402199174078E-12" ixz="1.51985653969833E-08" iyy="0.000489725321370326" iyz="2.42627969905164E-07" izz="4.77496090027913E-06"/>
    </inertial>
    <visual>
      <origin rpy="0 0 0" xyz="0 0 0"/>
      <geometry>
        <mesh filename="../../meshes/r_r_tendon.STL"/>
      </geometry>
      <material name="">
        <color rgba="0.690196078431373 0.658823529411765 0.63921568627451 1"/>
      </material>
    </visual>
    <!-- <collision>
      <origin xyz="0 0 0" rpy="0 0 0" />
      <geometry>
        <mesh filename="../../meshes/r_r_tendon.STL" />
      </geometry>
    </collision> -->
  </link>
  <drake:joint name="r_r_tendon_y" type="universal">
    <origin rpy="0 0 0" xyz="-0.056027 0.0085 0.015"/>
    <parent link="r_r_bar_y"/>
    <child link="r_r_tendon_y"/>
  </drake:joint>
  <frame link="r_r_tendon_y" name="r_r_tendon_socket" xyz="0 0 -0.256"/>
  <transmission type="SimpleTransmission">
    <joint name="r_r_bar_y"/>
    <actuator name="r_r_bar_y_motor">
      <drake:gear_ratio value="10.0"/>
      <drake:rotor_inertia value="0.0001002"/>
    </actuator>
  </transmission>
  <link name="r_l_bar_y">
    <inertial>
      <origin rpy="0 0 0" xyz="-0.0176387868876003 -0.00123323826800568 0.00472240978820238"/>
      <mass value="0.0413794348706216"/>
      <inertia ixx="6.34864114001538E-06" ixy="-2.71679701707313E-06" ixz="4.93234664344148E-06" iyy="2.83791841625158E-05" iyz="7.2736352651351E-07" izz="2.34510398457472E-05"/>
    </inertial>
    <visual>
      <origin rpy="0 0 0" xyz="0 0 0"/>
      <geometry>
        <mesh filename="../../meshes/r_l_bar.STL"/>
      </geometry>
      <material name="">
        <color rgba="0.690196078431373 0.658823529411765 0.63921568627451 1"/>
      </material>
    </visual>
    <!-- <collision>
      <origin xyz="0 0 0" rpy="0 0 0" />
      <geometry>
        <mesh filename="../../meshes/r_l_bar.STL" />
      </geometry>
    </collision> -->
  </link>
  <joint name="r_l_bar_y" type="continuous">
    <origin rpy="0 0 0" xyz="0 0.0362 -0.153"/>
    <parent link="leg_r4_link"/>
    <child link="r_l_bar_y"/>
    <axis xyz="0 1 0"/>
  </joint>
  <transmission type="SimpleTransmission">
    <joint name="r_l_bar_y"/>
    <actuator name="r_l_bar_y_motor">
      <drake:gear_ratio value="10.0"/>
      <drake:rotor_inertia value="0.0001002"/>
    </actuator>
  </transmission>
  <link name="r_l_tendon_y">
    <inertial>
      <origin rpy="0 0 0" xyz="-1.97765085516513E-05 -0.00047926628765782 -0.106248164342492"/>
      <mass value="0.106425376742002"/>
      <inertia ixx="0.000197199480044112" ixy="-4.20204697681874E-12" ixz="-1.28105270857608E-08" iyy="0.00019587468108075" iyz="-1.73407864727289E-07" izz="3.91523487668242E-06"/>
    </inertial>
    <visual>
      <origin rpy="0 0 0" xyz="0 0 0"/>
      <geometry>
        <mesh filename="../../meshes/r_l_tendon.STL"/>
      </geometry>
      <material name="">
        <color rgba="0.690196078431373 0.658823529411765 0.63921568627451 1"/>
      </material>
    </visual>
    <!-- <collision>
      <origin xyz="0 0 0" rpy="0 0 0" />
      <geometry>
        <mesh filename="../../meshes/r_l_tendon.STL" />
      </geometry>
    </collision> -->
  </link>
  <drake:joint name="r_l_tendon_y" type="universal">
    <origin rpy="0 0 0" xyz="-0.056027 -0.0085 0.015"/>
    <parent link="r_l_bar_y"/>
    <child link="r_l_tendon_y"/>
  </drake:joint>
  <frame link="r_l_tendon_y" name="r_l_tendon_socket" xyz="0 0 -0.193"/>
  <frame link="leg_r6_link" name="r_l_foot_socket" xyz="-0.056027 0.0255 0.015"/>
  <frame link="leg_r6_link" name="r_r_foot_socket" xyz="-0.056027 -0.0255 0.015"/>
  <!-- 曲柄 -->
  <frame link="r_l_bar_y" name="r_l_foot_bar_frame" xyz="0 -0.0085 0"/>
  <frame link="r_r_bar_y" name="r_r_foot_bar_frame" xyz="0 0.0085 0"/>
  <!-- =========================================================== Arms ================================================================= -->
  <link name="zarm_l1_link">
    <inertial>
      <origin xyz="-0.00083 -0.02218 0.00035" rpy="0 0 0" />
      <mass value="0.962" />
      <inertia ixx="0.00225" ixy="-3e-05" ixz="0.0" iyy="0.00099" iyz="-2e-05" izz="0.00227" />
    </inertial>
    <visual>
      <origin xyz="0 0 0" rpy="0 0 0" />
      <geometry>
        <mesh filename="../../meshes/l_arm_pitch.STL" />
      </geometry>
      <material name="">
        <color rgba="1 1 1 1" />
      </material>
    </visual>
  </link>
  <joint name="zarm_l1_joint" type="revolute">
    <origin xyz="-0.017499853 0.29269999999999996 0.4245" rpy="0 0 0" />
    <parent link="torso" />
    <child link="zarm_l1_link" />
    <axis xyz="0 1 0" />
    <limit lower="-3.14159265358979" upper="1.5707963267949" effort="100.0" velocity="41.3433333333333" />
  </joint>
  <transmission type="SimpleTransmission">
    <joint name="zarm_l1_joint" />
    <actuator name="zarm_l1_joint_motor" />
  </transmission>
  <link name="zarm_l2_link">
    <inertial>
      <origin xyz="-0.00791 0.0 -0.04655" rpy="0 0 0" />
      <mass value="0.57" />
      <inertia ixx="0.00163" ixy="0.0" ixz="5e-05" iyy="0.00211" iyz="0.0" izz="0.00122" />
    </inertial>
    <visual>
      <origin xyz="0 0 0" rpy="0 0 0" />
      <geometry>
        <mesh filename="../../meshes/l_arm_roll.STL" />
      </geometry>
      <material name="">
        <color rgba="1 1 1 1" />
      </material>
    </visual>
  </link>
  <joint name="zarm_l2_joint" type="revolute">
    <origin xyz="0 0 0" rpy="0 0 0" />
    <parent link="zarm_l1_link" />
    <child link="zarm_l2_link" />
    <axis xyz="1 0 0" />
    <limit lower="-0.349065850398866" upper="2.0943951023932" effort="50.0" velocity="19.154" />
  </joint>
  <transmission type="SimpleTransmission">
    <joint name="zarm_l2_joint" />
    <actuator name="zarm_l2_joint_motor" />
  </transmission>
  <link name="zarm_l3_link">
    <inertial>
      <origin xyz="0.00628 0.00107 -0.20878" rpy="0 0 0" />
      <mass value="1.65" />
      <inertia ixx="0.00815" ixy="-4e-05" ixz="0.00085" iyy="0.00828" iyz="0.00014" izz="0.00206" />
    </inertial>
    <visual>
      <origin xyz="0 0 0" rpy="0 0 0" />
      <geometry>
        <mesh filename="../../meshes/l_arm_yaw.STL" />
      </geometry>
      <material name="">
        <color rgba="1 1 1 1" />
      </material>
    </visual>
  </link>
  <joint name="zarm_l3_joint" type="revolute">
    <origin xyz="0 0 0" rpy="0 0 0" />
    <parent link="zarm_l2_link" />
    <child link="zarm_l3_link" />
    <axis xyz="0 0 1" />
    <limit lower="-1.5707963267949" upper="1.5707963267949" effort="39.0" velocity="18.84" />
  </joint>
  <transmission type="SimpleTransmission">
    <joint name="zarm_l3_joint" />
    <actuator name="zarm_l3_joint_motor" />
  </transmission>
  <link name="zarm_l4_link">
    <inertial>
      <origin xyz="-0.01611 0.00143 -0.04857" rpy="0 0 0" />
      <mass value="0.429" />
      <inertia ixx="0.00135" ixy="0.0" ixz="-0.0001" iyy="0.00114" iyz="0.0" izz="0.00083" />
    </inertial>
    <visual>
      <origin xyz="0 0 0" rpy="0 0 0" />
      <geometry>
        <mesh filename="../../meshes/l_forearm.STL" />
      </geometry>
      <material name="">
        <color rgba="1 1 1 1" />
      </material>
    </visual>
  </link>
  <joint name="zarm_l4_joint" type="revolute">
    <origin xyz="0.0200000000000006 0 -0.283699999999996" rpy="0 0 0" />
    <parent link="zarm_l3_link" />
    <child link="zarm_l4_link" />
    <axis xyz="0 1 0" />
    <limit lower="-2.61799387799149" upper="0.0" effort="50.0" velocity="18.84" />
  </joint>
  <transmission type="SimpleTransmission">
    <joint name="zarm_l4_joint" />
    <actuator name="zarm_l4_joint_motor" />
  </transmission>
  <link name="zarm_l5_link">
    <inertial>
      <origin xyz="-0.00207 0.00018 -0.05079" rpy="0 0 0" />
      <mass value="0.61" />
      <inertia ixx="0.00107" ixy="0.0" ixz="-4e-05" iyy="0.00146" iyz="0.0" izz="0.00083" />
    </inertial>
    <visual>
      <origin xyz="0 0 0" rpy="0 0 0" />
      <geometry>
        <mesh filename="../../meshes/l_hand_yaw.STL" />
      </geometry>
      <material name="">
        <color rgba="1 1 1 1" />
      </material>
    </visual>
  </link>
  <joint name="zarm_l5_joint" type="revolute">
    <origin xyz="-0.0200000000000025 0 -0.127037274261591" rpy="0 0 0" />
    <parent link="zarm_l4_link" />
    <child link="zarm_l5_link" />
    <axis xyz="0 0 1" />
    <limit lower="-1.5707963267949" upper="1.5707963267949" effort="12.0" velocity="21.666" />
  </joint>
  <transmission type="SimpleTransmission">
    <joint name="zarm_l5_joint" />
    <actuator name="zarm_l5_joint_motor" />
  </transmission>
  <link name="zarm_l6_link">
    <inertial>
      <origin xyz="-0.00111 0.00335 -0.01335" rpy="0 0 0" />
      <mass value="0.331" />
      <inertia ixx="0.00022" ixy="0.0" ixz="0.0" iyy="0.00027" iyz="0.0" izz="0.00028" />
    </inertial>
    <visual>
      <origin xyz="0 0 0" rpy="0 0 0" />
      <geometry>
        <mesh filename="../../meshes/l_hand_roll.STL" />
      </geometry>
      <material name="">
        <color rgba="1 1 1 1" />
      </material>
    </visual>
  </link>
  <joint name="zarm_l6_joint" type="revolute">
    <origin xyz="0.000199999999999079 0 -0.106462725738415" rpy="0 0 0" />
    <parent link="zarm_l5_link" />
    <child link="zarm_l6_link" />
    <axis xyz="1 0 0" />
    <limit lower="-1.30899693899575" upper="0.698131700797732" effort="12.0" velocity="21.666" />
  </joint>
  <transmission type="SimpleTransmission">
    <joint name="zarm_l6_joint" />
    <actuator name="zarm_l6_joint_motor" />
  </transmission>
  <link name="zarm_l7_link">
    <inertial>
      <origin xyz="0.00186 0.01014 -0.09044" rpy="0 0 0" />
      <mass value="0.64" />
      <inertia ixx="0.00071" ixy="1e-05" ixz="2e-05" iyy="0.0007" iyz="-4e-05" izz="0.00012" />
    </inertial>
    <visual>
      <origin xyz="0 0 0" rpy="0 0 0" />
      <geometry>
        <mesh filename="../../meshes/l_hand_pitch.STL" />
      </geometry>
      <material name="">
        <color rgba="1 1 1 1" />
      </material>
    </visual>
  </link>
  <joint name="zarm_l7_joint" type="revolute">
    <origin xyz="0 0 -0.0210004653879916" rpy="0 0 0" />
    <parent link="zarm_l6_link" />
    <child link="zarm_l7_link" />
    <axis xyz="0 1 0" />
    <limit lower="-0.698131700797732" upper="0.698131700797732" effort="12.0" velocity="21.666" />
  </joint>
  <transmission type="SimpleTransmission">
    <joint name="zarm_l7_joint" />
    <actuator name="zarm_l7_joint_motor" />
  </transmission>
  <!-- right arm -->
  <link name="zarm_r1_link">
    <inertial>
      <origin xyz="-0.00083 0.02218 0.00035" rpy="0 0 0" />
      <mass value="0.962" />
      <inertia ixx="0.00225" ixy="3e-05" ixz="0.0" iyy="0.00099" iyz="2e-05" izz="0.00227" />
    </inertial>
    <visual>
      <origin xyz="0 0 0" rpy="0 0 0" />
      <geometry>
        <mesh filename="../../meshes/r_arm_pitch.STL" />
      </geometry>
      <material name="">
        <color rgba="1 1 1 1" />
      </material>
    </visual>
  </link>
  <joint name="zarm_r1_joint" type="revolute">
    <origin xyz="-0.017499853 -0.29269999999999996 0.4245" rpy="0 0 0" />
    <parent link="torso" />
    <child link="zarm_r1_link" />
    <axis xyz="0 1 0" />
    <limit lower="-3.14159265358979" upper="1.5707963267949" effort="100.0" velocity="41.3433333333333" />
  </joint>
  <transmission type="SimpleTransmission">
    <joint name="zarm_r1_joint" />
    <actuator name="zarm_r1_joint_motor" />
  </transmission>
  <link name="zarm_r2_link">
    <inertial>
      <origin xyz="-0.00791 0.0 -0.04655" rpy="0 0 0" />
      <mass value="0.57" />
      <inertia ixx="0.00163" ixy="0.0" ixz="5e-05" iyy="0.00211" iyz="0.0" izz="0.00122" />
    </inertial>
    <visual>
      <origin xyz="0 0 0" rpy="0 0 0" />
      <geometry>
        <mesh filename="../../meshes/r_arm_roll.STL" />
      </geometry>
      <material name="">
        <color rgba="1 1 1 1" />
      </material>
    </visual>
  </link>
  <joint name="zarm_r2_joint" type="revolute">
    <origin xyz="0 0 0" rpy="0 0 0" />
    <parent link="zarm_r1_link" />
    <child link="zarm_r2_link" />
    <axis xyz="1 0 0" />
    <limit lower="-2.0943951023932" upper="0.349065850398866" effort="50.0" velocity="19.154" />
  </joint>
  <transmission type="SimpleTransmission">
    <joint name="zarm_r2_joint" />
    <actuator name="zarm_r2_joint_motor" />
  </transmission>
  <link name="zarm_r3_link">
    <inertial>
      <origin xyz="0.00628 -0.00107 -0.20878" rpy="0 0 0" />
      <mass value="1.65" />
      <inertia ixx="0.00815" ixy="4e-05" ixz="0.00085" iyy="0.00828" iyz="-0.00014" izz="0.00206" />
    </inertial>
    <visual>
      <origin xyz="0 0 0" rpy="0 0 0" />
      <geometry>
        <mesh filename="../../meshes/r_arm_yaw.STL" />
      </geometry>
      <material name="">
        <color rgba="1 1 1 1" />
      </material>
    </visual>
  </link>
  <joint name="zarm_r3_joint" type="revolute">
    <origin xyz="0 0 0" rpy="0 0 0" />
    <parent link="zarm_r2_link" />
    <child link="zarm_r3_link" />
    <axis xyz="0 0 1" />
    <limit lower="-1.5707963267949" upper="1.5707963267949" effort="39.0" velocity="18.84" />
  </joint>
  <transmission type="SimpleTransmission">
    <joint name="zarm_r3_joint" />
    <actuator name="zarm_r3_joint_motor" />
  </transmission>
  <link name="zarm_r4_link">
    <inertial>
      <origin xyz="-0.01611 -0.00143 -0.04857" rpy="0 0 0" />
      <mass value="0.429" />
      <inertia ixx="0.00135" ixy="0.0" ixz="-0.0001" iyy="0.00114" iyz="0.0" izz="0.00083" />
    </inertial>
    <visual>
      <origin xyz="0 0 0" rpy="0 0 0" />
      <geometry>
        <mesh filename="../../meshes/r_forearm.STL" />
      </geometry>
      <material name="">
        <color rgba="1 1 1 1" />
      </material>
    </visual>
  </link>
  <joint name="zarm_r4_joint" type="revolute">
    <origin xyz="0.0200000000000024 0 -0.2837" rpy="0 0 0" />
    <parent link="zarm_r3_link" />
    <child link="zarm_r4_link" />
    <axis xyz="0 1 0" />
    <limit lower="-2.61799387799149" upper="0.0" effort="50.0" velocity="18.84" />
  </joint>
  <transmission type="SimpleTransmission">
    <joint name="zarm_r4_joint" />
    <actuator name="zarm_r4_joint_motor" />
  </transmission>
  <link name="zarm_r5_link">
    <inertial>
      <origin xyz="-0.00207 -0.00018 -0.05079" rpy="0 0 0" />
      <mass value="0.61" />
      <inertia ixx="0.00107" ixy="0.0" ixz="-4e-05" iyy="0.00146" iyz="0.0" izz="0.00083" />
    </inertial>
    <visual>
      <origin xyz="0 0 0" rpy="0 0 0" />
      <geometry>
        <mesh filename="../../meshes/r_hand_yaw.STL" />
      </geometry>
      <material name="">
        <color rgba="1 1 1 1" />
      </material>
    </visual>
  </link>
  <joint name="zarm_r5_joint" type="revolute">
    <origin xyz="-0.0200000000000001 0 -0.127037274261587" rpy="0 0 0" />
    <parent link="zarm_r4_link" />
    <child link="zarm_r5_link" />
    <axis xyz="0 0 1" />
    <limit lower="-1.5707963267949" upper="1.5707963267949" effort="12.0" velocity="21.666" />
  </joint>
  <transmission type="SimpleTransmission">
    <joint name="zarm_r5_joint" />
    <actuator name="zarm_r5_joint_motor" />
  </transmission>
  <link name="zarm_r6_link">
    <inertial>
      <origin xyz="-0.00111 -0.00335 -0.01335" rpy="0 0 0" />
      <mass value="0.331" />
      <inertia ixx="0.00022" ixy="0.0" ixz="0.0" iyy="0.00027" iyz="0.0" izz="0.00028" />
    </inertial>
    <visual>
      <origin xyz="0 0 0" rpy="0 0 0" />
      <geometry>
        <mesh filename="../../meshes/r_hand_roll.STL" />
      </geometry>
      <material name="">
        <color rgba="1 1 1 1" />
      </material>
    </visual>
  </link>
  <joint name="zarm_r6_joint" type="revolute">
    <origin xyz="0 0 -0.106462725738415" rpy="0 0 0" />
    <parent link="zarm_r5_link" />
    <child link="zarm_r6_link" />
    <axis xyz="1 0 0" />
    <limit lower="-0.698131700797732" upper="1.30899693899575" effort="12.0" velocity="21.666" />
  </joint>
  <transmission type="SimpleTransmission">
    <joint name="zarm_r6_joint" />
    <actuator name="zarm_r6_joint_motor" />
  </transmission>
  <link name="zarm_r7_link">
    <inertial>
      <origin xyz="0.00186 -0.01014 -0.09044" rpy="0 0 0" />
      <mass value="0.64" />
      <inertia ixx="0.00069" ixy="-1e-05" ixz="2e-05" iyy="0.00068" iyz="5e-05" izz="0.00012" />
    </inertial>
    <visual>
      <origin xyz="0 0 0" rpy="0 0 0" />
      <geometry>
        <mesh filename="../../meshes/r_hand_pitch.STL" />
      </geometry>
      <material name="">
        <color rgba="1 1 1 1" />
      </material>
    </visual>
  </link>
  <joint name="zarm_r7_joint" type="revolute">
    <origin xyz="0 0 -0.0209999999999999" rpy="0 0 0" />
    <parent link="zarm_r6_link" />
    <child link="zarm_r7_link" />
    <axis xyz="0 1 0" />
    <limit lower="-0.698131700797732" upper="0.698131700797732" effort="12.0" velocity="21.666" />
  </joint>
  <transmission type="SimpleTransmission">
    <joint name="zarm_r7_joint" />
    <actuator name="zarm_r7_joint_motor" />
  </transmission>
  <!-- end frame -->
  <!-- <frame link="l_hand_pitch" name="l_hand_sole" xyz="0 0 -0.1" /> -->
  <!-- end frame -->
  <!-- <frame link="r_hand_pitch" name="r_hand_sole" xyz="0 0 -0.1" /> -->
</robot>

