<mujoco model="biped_s41">
  <compiler angle="radian" meshdir="./meshes/"/>
  <size njmax="500" nconmax="100" />
  <asset>
    <texture type="skybox" builtin="gradient" rgb1="0.4 0.6 0.8" width="128" height="128"/>
    <texture name="grid" type="2d" builtin="checker" rgb1=".1 .2 .3" rgb2=".2 .3 .4" width="300" height="300"/>
    <material name="grid" texture="grid" texrepeat="8 8" reflectance=".1"/>
    <mesh name="base_link" file="torso.STL"/>
    <mesh name="l_leg_roll" file="l_leg_roll.STL"/>
    <mesh name="l_leg_yaw" file="l_leg_yaw.STL"/>
    <mesh name="l_leg_pitch" file="l_leg_pitch.STL"/>
    <mesh name="l_knee" file="l_knee.STL"/>
    <mesh name="l_foot_pitch" file="l_foot_pitch.STL"/>
    <mesh name="l_foot_roll" file="l_foot_roll.STL"/>
    <mesh name="r_leg_roll" file="r_leg_roll.STL"/>
    <mesh name="r_leg_yaw" file="r_leg_yaw.STL"/>
    <mesh name="r_leg_pitch" file="r_leg_pitch.STL"/>
    <mesh name="r_knee" file="r_knee.STL"/>
    <mesh name="r_foot_pitch" file="r_foot_pitch.STL"/>
    <mesh name="r_foot_roll" file="r_foot_roll.STL"/>
    <mesh name="l_arm_pitch" file="l_arm_pitch.obj"/>
    <mesh name="l_arm_roll" file="l_arm_roll.obj"/>
    <mesh name="l_arm_yaw" file="l_arm_yaw.obj"/>
    <mesh name="l_forearm_pitch" file="l_forearm_pitch.obj"/>
    <mesh name="l_hand_yaw" file="l_hand_yaw.obj"/>
    <mesh name="l_hand_pitch" file="l_hand_pitch.obj"/>
    <mesh name="l_hand_roll" file="l_hand_roll.obj"/>
    <mesh name="r_arm_pitch" file="r_arm_pitch.obj"/>
    <mesh name="r_arm_roll" file="r_arm_roll.obj"/>
    <mesh name="r_arm_yaw" file="r_arm_yaw.obj"/>
    <mesh name="r_forearm_pitch" file="r_forearm_pitch.obj"/>
    <mesh name="r_hand_yaw" file="r_hand_yaw.obj"/>
    <mesh name="r_hand_pitch" file="r_hand_pitch.obj"/>
    <mesh name="r_hand_roll" file="r_hand_roll.obj"/>
  </asset>
  <worldbody>
    <body name="base_link" pos="0 0 0.82">
      <freejoint/>
      <inertial pos="-0.0177995 0.00029663 0.181764" quat="0.998463 -7.08433e-06 -0.0554125 -0.000904055" mass="27.2576" diaginertia="0.849687 0.737699 0.236205"/>
      <geom type="mesh" contype="0" conaffinity="0" group="1" density="0" rgba="1 1 1 1" mesh="base_link"/>
      <geom type="mesh" rgba="1 1 1 1" mesh="base_link"/>
      <site name="imu" pos="0 0 0"/>
      <body name="leg_l1_link" pos="-0.0024999 0.087 -0.066">
        <inertial pos="-0.00430148 -2.708e-05 -0.00851195" quat="0.00114226 0.692081 0.00279499 0.721814" mass="1.71093" diaginertia="0.00371121 0.00277272 0.00205799"/>
        <joint name="leg_l1_joint" pos="0 0 0" axis="1 0 0" range="-0.31416 0.66323" damping='0.2' />
        <geom type="mesh" contype="0" conaffinity="0" group="1" density="0" rgba="1 1 1 1" mesh="l_leg_roll"/>
        <body name="leg_l2_link">
          <inertial pos="0 -0.0032256 -0.0908087" quat="0.769899 0.638166 1.50247e-05 -1.35996e-05" mass="0.557629" diaginertia="0.00213816 0.00140333 0.00117498"/>
          <joint name="leg_l2_joint" pos="0 0 0" axis="0 0 1" range="-0.87266 0.7854" damping='0.2' />
          <geom type="mesh" contype="0" conaffinity="0" group="1" density="0" rgba="1 1 1 1" mesh="l_leg_yaw"/>
          <body name="leg_l3_link" pos="0 0 -0.1287">
            <inertial pos="0.00185677 0.0102346 -0.0855838" quat="0.724347 0.00513635 0.0261431 0.688921" mass="4.43577" diaginertia="0.0434466 0.0427748 0.0109324"/>
            <joint name="leg_l3_joint" pos="0 0 0" axis="0 1 0" range="-1.5708 2.0071" damping='0.2' />
            <geom type="mesh" contype="0" conaffinity="0" group="1" density="0" rgba="1 1 1 1" mesh="l_leg_pitch"/>
            <body name="leg_l4_link" pos="0 0 -0.284">
              <inertial pos="0.00716677 -6.696e-05 -0.114819" quat="0.999988 0.000491325 0.000347396 0.0048566" mass="1.61275" diaginertia="0.011037 0.0109512 0.000872235"/>
              <joint name="leg_l4_joint" pos="0 0 0" axis="0 1 0" range="0 2.618" damping='0.2' />
              <geom type="mesh" contype="0" conaffinity="0" group="1" density="0" rgba="1 1 1 1" mesh="l_knee"/>
              <body name="leg_l5_link" pos="0 0 -0.346">
                <inertial pos="0 0 0" quat="0.5 0.5 -0.5 0.5" mass="0.0719352" diaginertia="1.218e-05 6.92e-06 6.92e-06"/>
                <joint name="leg_l5_joint" pos="0 0 0" axis="0 1 0" range="-0.73304 0.38397" damping='0.2' />
                <geom type="mesh" contype="0" conaffinity="0" group="1" density="0" rgba="0.647059 0.619608 0.588235 1" mesh="l_foot_pitch"/>
                <body name="leg_l6_link">
                  <inertial pos="0.0373958 -2.2061e-06 -0.0389679" quat="-5.61629e-06 0.695245 1.1461e-05 0.718773" mass="0.501754" diaginertia="0.00177876 0.00163456 0.000397"/>
                  <joint name="leg_l6_joint" pos="0 0 0" axis="1 0 0" range="-0.5236 0.5236" damping='0.2' />
                  <geom type="mesh" contype="0" conaffinity="0" group="1" density="0" rgba="1 1 1 1" mesh="l_foot_roll"/>
                  <geom size="0.005" pos="-0.07316 0.04773 -0.0593" contype="0" conaffinity="0" group="1" density="0" rgba="1 1 1 1"/>
                  <geom size="0.005" pos="-0.07316 0.04773 -0.0593" rgba="1 1 1 1"/>
                  <geom size="0.005" pos="-0.07316 -0.04773 -0.0593" contype="0" conaffinity="0" group="1" density="0" rgba="1 1 1 1"/>
                  <geom size="0.005" pos="-0.07316 -0.04773 -0.0593" rgba="1 1 1 1"/>
                  <geom size="0.005" pos="0.16902 0.04773 -0.0593" contype="0" conaffinity="0" group="1" density="0" rgba="1 1 1 1"/>
                  <geom size="0.005" pos="0.16902 0.04773 -0.0593" rgba="1 1 1 1"/>
                  <geom size="0.005" pos="0.16902 -0.04773 -0.0593" contype="0" conaffinity="0" group="1" density="0" rgba="1 1 1 1"/>
                  <geom size="0.005" pos="0.16902 -0.04773 -0.0593" rgba="1 1 1 1"/>
                </body>
              </body>
            </body>
          </body>
        </body>
      </body>
      <body name="leg_r1_link" pos="-0.0024999 -0.087 -0.066">
        <inertial pos="-0.00430146 2.709e-05 -0.00851195" quat="-0.00114226 0.692081 -0.00279499 0.721814" mass="1.71093" diaginertia="0.00371121 0.00277272 0.00205799"/>
        <joint name="leg_r1_joint" pos="0 0 0" axis="1 0 0" range="-0.31416 0.66323" damping='0.2' />
        <geom type="mesh" contype="0" conaffinity="0" group="1" density="0" rgba="1 1 1 1" mesh="r_leg_roll"/>
        <body name="leg_r2_link">
          <inertial pos="0 0.00322561 -0.0908087" quat="0.638166 0.769899 1.35996e-05 -1.50247e-05" mass="0.557629" diaginertia="0.00213816 0.00140333 0.00117498"/>
          <joint name="leg_r2_joint" pos="0 0 0" axis="0 0 1" range="-0.87266 0.7854" damping='0.2' />
          <geom type="mesh" contype="0" conaffinity="0" group="1" density="0" rgba="1 1 1 1" mesh="r_leg_yaw"/>
          <body name="leg_r3_link" pos="0 0 -0.1287">
            <inertial pos="0.00185677 -0.0102346 -0.0855838" quat="0.714834 0.0057373 0.0258337 0.698793" mass="4.43577" diaginertia="0.0442361 0.0427757 0.010933"/>
            <joint name="leg_r3_joint" pos="0 0 0" axis="0 1 0" range="-1.5708 2.0071" damping='0.2' />
            <geom type="mesh" contype="0" conaffinity="0" group="1" density="0" rgba="1 1 1 1" mesh="r_leg_pitch"/>
            <body name="leg_r4_link" pos="0 0 -0.284">
              <inertial pos="0.00716677 6.696e-05 -0.114819" quat="0.999988 0.000491325 0.000347396 0.0048566" mass="1.61275" diaginertia="0.011037 0.0109512 0.000872235"/>
              <joint name="leg_r4_joint" pos="0 0 0" axis="0 1 0" range="0 2.618" damping='0.2' />
              <geom type="mesh" contype="0" conaffinity="0" group="1" density="0" rgba="1 1 1 1" mesh="r_knee"/>
              <body name="leg_r5_link" pos="0 0 -0.346">
                <inertial pos="0 0 0" quat="0.5 0.5 -0.5 0.5" mass="0.0719352" diaginertia="1.218e-05 6.92e-06 6.92e-06"/>
                <joint name="leg_r5_joint" pos="0 0 0" axis="0 1 0" range="-0.73304 0.38397" damping='0.2' />
                <geom type="mesh" contype="0" conaffinity="0" group="1" density="0" rgba="0.647059 0.619608 0.588235 1" mesh="r_foot_pitch"/>
                <body name="leg_r6_link">
                  <inertial pos="0.0373958 -2.2061e-06 -0.0389679" quat="-5.61629e-06 0.695245 1.1461e-05 0.718773" mass="0.501754" diaginertia="0.00177876 0.00163456 0.000397"/>
                  <joint name="leg_r6_joint" pos="0 0 0" axis="1 0 0" range="-0.5236 0.5236" damping='0.2' />
                  <geom type="mesh" contype="0" conaffinity="0" group="1" density="0" rgba="1 1 1 1" mesh="r_foot_roll"/>
                  <geom size="0.005" pos="-0.07316 0.04773 -0.0593" contype="0" conaffinity="0" group="1" density="0" rgba="1 1 1 1"/>
                  <geom size="0.005" pos="-0.07316 0.04773 -0.0593" rgba="1 1 1 1"/>
                  <geom size="0.005" pos="-0.07316 -0.04773 -0.0593" contype="0" conaffinity="0" group="1" density="0" rgba="1 1 1 1"/>
                  <geom size="0.005" pos="-0.07316 -0.04773 -0.0593" rgba="1 1 1 1"/>
                  <geom size="0.005" pos="0.16902 0.04773 -0.0593" contype="0" conaffinity="0" group="1" density="0" rgba="1 1 1 1"/>
                  <geom size="0.005" pos="0.16902 0.04773 -0.0593" rgba="1 1 1 1"/>
                  <geom size="0.005" pos="0.16902 -0.04773 -0.0593" contype="0" conaffinity="0" group="1" density="0" rgba="1 1 1 1"/>
                  <geom size="0.005" pos="0.16902 -0.04773 -0.0593" rgba="1 1 1 1"/>
                </body>
              </body>
            </body>
          </body>
        </body>
      </body>
      <body name="zarm_l1_link" pos="-0.0175476 0.2627 0.4245">
        <inertial pos="0.0146835 -0.0166604 -6.82857e-05" quat="0.696586 0.712206 -0.0625859 -0.0601207" mass="0.794" diaginertia="0.000271947 0.000196224 0.000121256"/>
        <joint name="zarm_l1_joint" pos="0 0 0" axis="0 1 0" range="-2.0933 0.5233" actuatorfrcrange="-60 60" damping='0.2' />
        <geom type="mesh" contype="0" conaffinity="0" group="1" density="0" rgba="1 1 1 1" mesh="l_arm_pitch"/>
        <body name="zarm_l2_link">
          <inertial pos="0.0222873 0.0156946 -0.0202262" quat="0.398328 0.58059 0.26378 0.659295" mass="0.20735" diaginertia="0.000283338 0.000217951 0.000157462"/>
          <joint name="zarm_l2_joint" pos="0 0 0" axis="1 0 0" range="-0.3489 2.0933" actuatorfrcrange="-82.8 82.8" damping='0.2' />
          <geom type="mesh" contype="0" conaffinity="0" group="1" density="0" rgba="1 1 1 1" mesh="l_arm_roll"/>
          <body name="zarm_l3_link">
            <inertial pos="6.1694e-05 0.00525815 -0.128822" quat="0.237126 0.666158 0.237177 0.666147" mass="1.12063" diaginertia="9.38963e-05 7.96873e-05 7.00576e-05"/>
            <joint name="zarm_l3_joint" pos="0 0 0" axis="0 0 1" range="-1.57 1.57" actuatorfrcrange="-60 60" damping='0.2' />
            <geom type="mesh" contype="0" conaffinity="0" group="1" density="0" rgba="1 1 1 1" mesh="l_arm_yaw"/>
            <body name="zarm_l4_link" pos="0 0 -0.1636">
              <inertial pos="-1.42819e-05 0.00938314 -0.0522688" quat="0.632873 0.313955 0.634285 0.313985" mass="0.395825" diaginertia="0.00013362 0.000113739 9.55807e-05"/>
              <joint name="zarm_l4_joint" pos="0 0 0" axis="0 1 0" range="-2.0933 0" actuatorfrcrange="-60 60" damping='0.2' />
              <geom type="mesh" contype="0" conaffinity="0" group="1" density="0" rgba="1 1 1 1" mesh="l_forearm_pitch"/>
              <body name="zarm_l5_link" pos="0 0 -0.19105">
                <inertial pos="0.000113133 0.00969228 0.0817961" quat="0.493085 0.506908 0.492087 0.507703" mass="0.380792" diaginertia="0.000122264 8.44608e-05 7.64924e-05"/>
                <joint name="zarm_l5_joint" pos="0 0 0" axis="0 0 1" range="-1.657 1.657" actuatorfrcrange="-6 6" damping='0.2' />
                <geom type="mesh" contype="0" conaffinity="0" group="1" density="0" rgba="1 1 1 1" mesh="l_hand_yaw"/>
                <body name="zarm_l6_link">
                  <inertial pos="0.0081061 0.00489663 0.00622489" quat="0.972746 -0.202646 -0.0967872 0.0577326" mass="0.376651" diaginertia="4.90153e-05 3.61802e-05 2.19136e-05"/>
                  <joint name="zarm_l6_joint" pos="0 0 0" axis="0 1 0" range="-1.657 1.657" actuatorfrcrange="-6 6" damping='0.2' />
                  <geom type="mesh" contype="0" conaffinity="0" group="1" density="0" rgba="1 1 1 1" mesh="l_hand_pitch"/>
                  <body name="zarm_l7_link">
                    <inertial pos="0.00557087 0.00644656 -0.0826894" quat="0.378878 0.570642 0.285709 0.670216" mass="0.705193" diaginertia="0.000126318 0.000107575 8.42004e-05"/>
                    <joint name="zarm_l7_joint" pos="0 0 0" axis="1 0 0" range="-1.57 1.57" actuatorfrcrange="-6 6" damping='0.2' />
                    <geom type="mesh" contype="0" conaffinity="0" group="1" density="0" rgba="1 1 1 1" mesh="l_hand_roll"/>
                    <geom size="0.005" pos="0 -0.03 -0.17"/>
                  </body>
                </body>
              </body>
            </body>
          </body>
        </body>
      </body>
      <body name="zarm_r1_link" pos="-0.0175476 -0.2627 0.4245">
        <inertial pos="0.0146744 0.0168298 -8.16712e-05" quat="0.712375 0.696324 0.0605536 0.0631598" mass="0.794" diaginertia="0.000271946 0.000196219 0.000121103"/>
        <joint name="zarm_r1_joint" pos="0 0 0" axis="0 1 0" range="-2.0933 0.5233" actuatorfrcrange="-60 60" damping='0.2' />
        <geom type="mesh" contype="0" conaffinity="0" group="1" density="0" rgba="1 1 1 1" mesh="r_arm_pitch"/>
        <body name="zarm_r2_link">
          <inertial pos="0.0223009 -0.015695 -0.0202308" quat="0.65931 0.264022 0.580473 0.398313" mass="0.20735" diaginertia="0.000283519 0.000218099 0.000157689"/>
          <joint name="zarm_r2_joint" pos="0 0 0" axis="1 0 0" range="-2.0933 0.3489" actuatorfrcrange="-82.8 82.8" damping='0.2' />
          <geom type="mesh" contype="0" conaffinity="0" group="1" density="0" rgba="1 1 1 1" mesh="r_arm_roll"/>
          <body name="zarm_r3_link">
            <inertial pos="-4.82749e-05 -0.00525815 -0.128822" quat="-0.237177 0.666147 -0.237126 0.666158" mass="1.12063" diaginertia="9.38963e-05 7.96873e-05 7.00576e-05"/>
            <joint name="zarm_r3_joint" pos="0 0 0" axis="0 0 1" range="-1.57 1.57" actuatorfrcrange="-60 60" damping='0.2' />
            <geom type="mesh" contype="0" conaffinity="0" group="1" density="0" rgba="1 1 1 1" mesh="r_arm_yaw"/>
            <body name="zarm_r4_link" pos="0 0 -0.1636">
              <inertial pos="-0.000127233 -0.00951603 -0.0522688" quat="0.314696 0.632501 0.314725 0.633922" mass="0.395825" diaginertia="0.000133455 0.000113904 9.55807e-05"/>
              <joint name="zarm_r4_joint" pos="0 0 0" axis="0 1 0" range="-2.0933 0" actuatorfrcrange="-60 60" damping='0.2' />
              <geom type="mesh" contype="0" conaffinity="0" group="1" density="0" rgba="1 1 1 1" mesh="r_forearm_pitch"/>
              <body name="zarm_r5_link" pos="0 0 -0.19105">
                <inertial pos="-0.000113133 -0.00974484 0.0817961" quat="0.506908 0.493085 0.507703 0.492087" mass="0.380792" diaginertia="0.000122264 8.44608e-05 7.64924e-05"/>
                <joint name="zarm_r5_joint" pos="0 0 0" axis="0 0 1" range="-1.657 1.657" actuatorfrcrange="-6 6" damping='0.2' />
                <geom type="mesh" contype="0" conaffinity="0" group="1" density="0" rgba="1 1 1 1" mesh="r_hand_yaw"/>
                <body name="zarm_r6_link">
                  <inertial pos="0.00735987 -0.00475238 0.00605888" quat="0.97227 0.205866 -0.0962427 -0.0552063" mass="0.376651" diaginertia="4.89785e-05 3.6108e-05 2.20226e-05"/>
                  <joint name="zarm_r6_joint" pos="0 0 0" axis="0 1 0" range="-1.657 1.657" actuatorfrcrange="-6 6" damping='0.2' />
                  <geom type="mesh" contype="0" conaffinity="0" group="1" density="0" rgba="1 1 1 1" mesh="r_hand_pitch"/>
                  <body name="zarm_r7_link">
                    <inertial pos="0.00459104 -0.00584264 -0.0836966" quat="0.678609 0.268346 0.578196 0.364925" mass="0.705193" diaginertia="0.000247322 0.000207835 0.000163356"/>
                    <joint name="zarm_r7_joint" pos="0 0 0" axis="1 0 0" range="-1.57 1.57" actuatorfrcrange="-6 6" damping='0.2' />
                    <geom type="mesh" contype="0" conaffinity="0" group="1" density="0" rgba="1 1 1 1" mesh="r_hand_roll"/>
                    <geom size="0.005" pos="0 0.03 -0.17"/>
                  </body>
                </body>
              </body>
            </body>
          </body>
        </body>
      </body>
    </body>
  </worldbody>
  <actuator>
        <motor gear="1" joint="leg_l1_joint" name="leg_l1_motor" ctrllimited="true"  ctrlrange='-150 150'/>
        <motor gear="1" joint="leg_l2_joint" name="leg_l2_motor" ctrllimited="true"  ctrlrange='-150 150'/>
        <motor gear="1" joint="leg_l3_joint" name="leg_l3_motor" ctrllimited="true"  ctrlrange='-200 200'/>
        <motor gear="1" joint="leg_l4_joint" name="leg_l4_motor" ctrllimited="true"  ctrlrange='-200 200'/>
        <motor gear="1" joint="leg_l5_joint" name="leg_l5_motor" ctrllimited="true"  ctrlrange='-90 90'/>
        <motor gear="1" joint="leg_l6_joint" name="leg_l6_motor" ctrllimited="true"  ctrlrange='-90 90'/>

        <motor gear="1" joint="leg_r1_joint" name="leg_r1_motor" ctrllimited="true"  ctrlrange='-150 150'/>
        <motor gear="1" joint="leg_r2_joint" name="leg_r2_motor" ctrllimited="true"  ctrlrange='-150 150'/>
        <motor gear="1" joint="leg_r3_joint" name="leg_r3_motor" ctrllimited="true"  ctrlrange='-200 200'/>
        <motor gear="1" joint="leg_r4_joint" name="leg_r4_motor" ctrllimited="true"  ctrlrange='-200 200'/>
        <motor gear="1" joint="leg_r5_joint" name="leg_r5_motor" ctrllimited="true"  ctrlrange='-90 90'/>
        <motor gear="1" joint="leg_r6_joint" name="leg_r6_motor" ctrllimited="true"  ctrlrange='-90 90'/>

        <motor gear="1" joint="zarm_l1_joint" name="zarm_l1_motor" ctrllimited="true"  ctrlrange='-150 150'/>
        <motor gear="1" joint="zarm_l2_joint" name="zarm_l2_motor" ctrllimited="true"  ctrlrange='-150 150'/>
        <motor gear="1" joint="zarm_l3_joint" name="zarm_l3_motor" ctrllimited="true"  ctrlrange='-200 200'/>
        <motor gear="1" joint="zarm_l4_joint" name="zarm_l4_motor" ctrllimited="true"  ctrlrange='-200 200'/>
        <motor gear="1" joint="zarm_l5_joint" name="zarm_l5_motor" ctrllimited="true"  ctrlrange='-90 90'/>
        <motor gear="1" joint="zarm_l6_joint" name="zarm_l6_motor" ctrllimited="true"  ctrlrange='-90 90'/>
        <motor gear="1" joint="zarm_l7_joint" name="zarm_l7_motor" ctrllimited="true"  ctrlrange='-90 90'/>

        <motor gear="1" joint="zarm_r1_joint" name="zarm_r1_motor" ctrllimited="true"  ctrlrange='-150 150'/>
        <motor gear="1" joint="zarm_r2_joint" name="zarm_r2_motor" ctrllimited="true"  ctrlrange='-150 150'/>
        <motor gear="1" joint="zarm_r3_joint" name="zarm_r3_motor" ctrllimited="true"  ctrlrange='-200 200'/>
        <motor gear="1" joint="zarm_r4_joint" name="zarm_r4_motor" ctrllimited="true"  ctrlrange='-200 200'/>
        <motor gear="1" joint="zarm_r5_joint" name="zarm_r5_motor" ctrllimited="true"  ctrlrange='-90 90'/>
        <motor gear="1" joint="zarm_r6_joint" name="zarm_r6_motor" ctrllimited="true"  ctrlrange='-90 90'/>
        <motor gear="1" joint="zarm_r7_joint" name="zarm_r7_motor" ctrllimited="true"  ctrlrange='-90 90'/>
  </actuator>
  <sensor>
      <accelerometer name="BodyAcc" site="imu"/>
      <velocimeter name="BodyVel" site="imu"/>
      <gyro name="BodyGyro" site="imu"/>
      <framepos name="BodyPos" objtype="site" objname="imu"/>
      <framequat name="BodyQuat" objtype="site" objname="imu"/>

      <jointpos name="leg_l1_pos" joint="leg_l1_joint"/>
      <jointpos name="leg_l2_pos" joint="leg_l2_joint"/>
      <jointpos name="leg_l3_pos" joint="leg_l3_joint"/>
      <jointpos name="leg_l4_pos" joint="leg_l4_joint"/>
      <jointpos name="leg_l5_pos" joint="leg_l5_joint"/>
      <jointpos name="leg_l6_pos" joint="leg_l6_joint"/>

      <jointpos name="leg_r1_pos" joint="leg_r1_joint"/>
      <jointpos name="leg_r2_pos" joint="leg_r2_joint"/>
      <jointpos name="leg_r3_pos" joint="leg_r3_joint"/>
      <jointpos name="leg_r4_pos" joint="leg_r4_joint"/>
      <jointpos name="leg_r5_pos" joint="leg_r5_joint"/>
      <jointpos name="leg_r6_pos" joint="leg_r6_joint"/>

      <jointpos name="zarm_l1_pos" joint="zarm_l1_joint"/>
      <jointpos name="zarm_l2_pos" joint="zarm_l2_joint"/>
      <jointpos name="zarm_l3_pos" joint="zarm_l3_joint"/>
      <jointpos name="zarm_l4_pos" joint="zarm_l4_joint"/>
      <jointpos name="zarm_l5_pos" joint="zarm_l5_joint"/>
      <jointpos name="zarm_l6_pos" joint="zarm_l6_joint"/>
      <jointpos name="zarm_l7_pos" joint="zarm_l7_joint"/>

      <jointpos name="zarm_r1_pos" joint="zarm_r1_joint"/>
      <jointpos name="zarm_r2_pos" joint="zarm_r2_joint"/>
      <jointpos name="zarm_r3_pos" joint="zarm_r3_joint"/>
      <jointpos name="zarm_r4_pos" joint="zarm_r4_joint"/>
      <jointpos name="zarm_r5_pos" joint="zarm_r5_joint"/>
      <jointpos name="zarm_r6_pos" joint="zarm_r6_joint"/>
      <jointpos name="zarm_r7_pos" joint="zarm_r7_joint"/>

      <jointvel name="leg_l1_vel" joint="leg_l1_joint"/>
      <jointvel name="leg_l2_vel" joint="leg_l2_joint"/>
      <jointvel name="leg_l3_vel" joint="leg_l3_joint"/>
      <jointvel name="leg_l4_vel" joint="leg_l4_joint"/>
      <jointvel name="leg_l5_vel" joint="leg_l5_joint"/>
      <jointvel name="leg_l6_vel" joint="leg_l6_joint"/>

      <jointvel name="leg_r1_vel" joint="leg_r1_joint"/>
      <jointvel name="leg_r2_vel" joint="leg_r2_joint"/>
      <jointvel name="leg_r3_vel" joint="leg_r3_joint"/>
      <jointvel name="leg_r4_vel" joint="leg_r4_joint"/>
      <jointvel name="leg_r5_vel" joint="leg_r5_joint"/>
      <jointvel name="leg_r6_vel" joint="leg_r6_joint"/>

      <jointvel name="zarm_l1_vel" joint="zarm_l1_joint"/>
      <jointvel name="zarm_l2_vel" joint="zarm_l2_joint"/>
      <jointvel name="zarm_l3_vel" joint="zarm_l3_joint"/>
      <jointvel name="zarm_l4_vel" joint="zarm_l4_joint"/>
      <jointvel name="zarm_l5_vel" joint="zarm_l5_joint"/>
      <jointvel name="zarm_l6_vel" joint="zarm_l6_joint"/>
      <jointvel name="zarm_l7_vel" joint="zarm_l7_joint"/>

      <jointvel name="zarm_r1_vel" joint="zarm_r1_joint"/>
      <jointvel name="zarm_r2_vel" joint="zarm_r2_joint"/>
      <jointvel name="zarm_r3_vel" joint="zarm_r3_joint"/>
      <jointvel name="zarm_r4_vel" joint="zarm_r4_joint"/>
      <jointvel name="zarm_r5_vel" joint="zarm_r5_joint"/>
      <jointvel name="zarm_r6_vel" joint="zarm_r6_joint"/>
      <jointvel name="zarm_r7_vel" joint="zarm_r7_joint"/>
  </sensor>
</mujoco>
