<?xml version='1.0' encoding='utf-8'?>
<robot name="biped_s40">
  <mujoco>
    <compiler meshdir="../meshes/" balanceinertia="true" discardvisual="false" />
  </mujoco>
  <link name="dummy_link" />
  <link name="base_link">
    <inertial>
      <origin xyz="-0.00505 0.0014 0.18077" rpy="0 0 0" />
      <mass value="22.6889" />
      <inertia ixx="0.28214" ixy="3e-05" ixz="0.01114" iyy="0.20534" iyz="0.00044" izz="0.13735" />
    </inertial>
    <visual>
      <origin xyz="0 0 0" rpy="0 0 0" />
      <geometry>
        <mesh filename="package://kuavo_assets/models/biped_s40/meshes/base_link.STL" />
      </geometry>
      <material name="">
        <color rgba="1 1 1 1" />
      </material>
    </visual>
  </link>
  <joint name="base_link_to_dummy_link" type="fixed">
    <origin xyz="0 0 0" rpy="0 0 0" />
    <parent link="base_link" />
    <child link="dummy_link" />
  </joint>
  <link name="leg_l1_link">
    <inertial>
      <origin xyz="-0.00624961 -5.6e-06 -0.00874166" rpy="0 0 0" />
      <mass value="1.79206533" />
      <inertia ixx="0.00211603" ixy="7.6e-07" ixz="0.000107" iyy="0.00302948" iyz="4.73e-06" izz="0.00399385" />
    </inertial>
    <visual>
      <origin xyz="0 0 0" rpy="0 0 0" />
      <geometry>
        <mesh filename="package://kuavo_assets/models/biped_s40/meshes/l_leg_roll.STL" />
      </geometry>
      <material name="">
        <color rgba="1 1 1 1" />
      </material>
    </visual>
  </link>
  <joint name="leg_l1_joint" type="revolute">
    <origin xyz="-0.0025 0.087 -0.066" rpy="0 0 0" />
    <parent link="base_link" />
    <child link="leg_l1_link" />
    <axis xyz="1 0 0" />
    <limit lower="-0.314159265358979" upper="0.663225115757845" effort="180.0" velocity="23.55" />
  </joint>
  <link name="leg_l2_link">
    <inertial>
      <origin xyz="4.471e-05 0.04985881 -0.11682314" rpy="0 0 0" />
      <mass value="1.67630577" />
      <inertia ixx="0.00548763" ixy="-2.73e-06" ixz="-9.2e-07" iyy="0.0041542" iyz="0.00050833" izz="0.00426092" />
    </inertial>
    <visual>
      <origin xyz="0 0 0" rpy="0 0 0" />
      <geometry>
        <mesh filename="package://kuavo_assets/models/biped_s40/meshes/l_leg_yaw.STL" />
      </geometry>
      <material name="">
        <color rgba="1 1 1 1" />
      </material>
    </visual>
  </link>
  <joint name="leg_l2_joint" type="revolute">
    <origin xyz="0 0 0" rpy="0 0 0" />
    <parent link="leg_l1_link" />
    <child link="leg_l2_link" />
    <axis xyz="0 0 1" />
    <limit lower="-1.0471975511966" upper="0.523598775598299" effort="100.0" velocity="41.3433333333333" />
  </joint>
  <link name="leg_l3_link">
    <inertial>
      <origin xyz="-0.00238348 -0.02309435 -0.06304956" rpy="0 0 0" />
      <mass value="2.46847" />
      <inertia ixx="0.02435272" ixy="4.518e-05" ixz="0.00123822" iyy="0.02479772" iyz="0.00261624" izz="0.00478829" />
    </inertial>
    <visual>
      <origin xyz="0 0 0" rpy="0 0 0" />
      <geometry>
        <mesh filename="package://kuavo_assets/models/biped_s40/meshes/l_leg_pitch.STL" />
      </geometry>
      <material name="">
        <color rgba="1 1 1 1" />
      </material>
    </visual>
  </link>
  <joint name="leg_l3_joint" type="revolute">
    <origin xyz="0 0.02545000000000 -0.1287" rpy="0 0 0" />
    <parent link="leg_l2_link" />
    <child link="leg_l3_link" />
    <axis xyz="0 1 0" />
    <limit lower="-1.83259571459405" upper="1.0471975511966" effort="100.0" velocity="41.3433333333333" />
  </joint>
  <link name="leg_l4_link">
    <inertial>
      <origin xyz="0.00304104 -4.1e-05 -0.12213928" rpy="0 0 0" />
      <mass value="1.86452506" />
      <inertia ixx="0.01537791" ixy="7.85e-06" ixz="-0.00010781" iyy="0.01559985" iyz="-0.00015323" izz="0.00123021" />
    </inertial>
    <visual>
      <origin xyz="0 0 0" rpy="0 0 0" />
      <geometry>
        <mesh filename="package://kuavo_assets/models/biped_s40/meshes/l_knee.STL" />
      </geometry>
      <material name="">
        <color rgba="1 1 1 1" />
      </material>
    </visual>
  </link>
  <joint name="leg_l4_joint" type="revolute">
    <origin xyz="-0.010390161952608 0 -0.249783995753446" rpy="0 0 0" />
    <parent link="leg_l3_link" />
    <child link="leg_l4_link" />
    <axis xyz="0 1 0" />
    <limit lower="0.0" upper="2.18166156499291" effort="100.0" velocity="41.3433333333333" />
  </joint>
  <link name="leg_l5_link">
    <inertial>
      <origin xyz="0.0 0.0 0.0" rpy="0 0 0" />
      <mass value="0.06923929" />
      <inertia ixx="6.66e-06" ixy="0.0" ixz="0.0" iyy="6.66e-06" iyz="0.0" izz="1.172e-05" />
    </inertial>
    <visual>
      <origin xyz="0 0 0" rpy="0 0 0" />
      <geometry>
        <mesh filename="package://kuavo_assets/models/biped_s40/meshes/l_foot_pitch.STL" />
      </geometry>
      <material name="">
        <color rgba="1 1 1 1" />
      </material>
    </visual>
  </link>
  <joint name="leg_l5_joint" type="revolute">
    <origin xyz="0 0 -0.346000000000004" rpy="0 0 0" />
    <parent link="leg_l4_link" />
    <child link="leg_l5_link" />
    <axis xyz="0 1 0" />
    <limit lower="-0.610865238198015" upper="0.523598775598299" effort="36.0" velocity="23.0266666666667" />
  </joint>
  <link name="leg_l6_link">
    <inertial>
      <origin xyz="-0.00987056 -7.58e-06 -0.03365514" rpy="0 0 0" />
      <mass value="0.58358325" />
      <inertia ixx="0.0006342" ixy="1.4e-07" ixz="0.00031564" iyy="0.00227317" iyz="-2e-08" izz="0.00239382" />
    </inertial>
    <visual>
      <origin xyz="0 0 0" rpy="0 0 0" />
      <geometry>
        <mesh filename="package://kuavo_assets/models/biped_s40/meshes/l_foot_roll.STL" />
      </geometry>
      <material name="">
        <color rgba="1 1 1 1" />
      </material>
    </visual>
    <collision>
	    <origin xyz="0.0488 0 0" rpy="0 0 0"/>
	    <geometry>
		    <box size="0.25 0.1 0.04"/>
	    </geometry>
    </collision>
  </link>
  <joint name="leg_l6_joint" type="revolute">
    <origin xyz="0 0 0" rpy="0 0 0" />
    <parent link="leg_l5_link" />
    <child link="leg_l6_link" />
    <axis xyz="1 0 0" />
    <limit lower="-0.349065850398866" upper="0.349065850398866" effort="36.0" velocity="23.0266666666667" />
  </joint>
  <link name="ll_foot_toe">
    <collision>
      <origin rpy="0 0 0" xyz="0 0 0" />
      <geometry>
        <sphere radius="0.005" />
      </geometry>
    </collision>
  </link>
  <joint name="ll_foot_toe_joint" type="fixed">
    <origin xyz="0.142507 0.04773 -0.0595" rpy="0 0 0" />
    <parent link="leg_l6_link" />
    <child link="ll_foot_toe" />
  </joint>
  <link name="ll_foot_heel">
    <collision>
      <origin rpy="0 0 0" xyz="0 0 0" />
      <geometry>
        <sphere radius="0.005" />
      </geometry>
    </collision>
  </link>
  <joint name="ll_foot_heel_joint" type="fixed">
    <origin xyz="-0.10149 0.04773 -0.0595" rpy="0 0 0" />
    <parent link="leg_l6_link" />
    <child link="ll_foot_heel" />
  </joint>
  <link name="lr_foot_toe">
    <collision>
      <origin rpy="0 0 0" xyz="0 0 0" />
      <geometry>
        <sphere radius="0.005" />
      </geometry>
    </collision>
  </link>
  <joint name="lr_foot_toe_joint" type="fixed">
    <origin xyz="0.142507 -0.04773 -0.0595" rpy="0 0 0" />
    <parent link="leg_l6_link" />
    <child link="lr_foot_toe" />
  </joint>
  <link name="lr_foot_heel">
    <collision>
      <origin rpy="0 0 0" xyz="0 0 0" />
      <geometry>
        <sphere radius="0.005" />
      </geometry>
    </collision>
  </link>
  <joint name="lr_foot_heel_joint" type="fixed">
    <origin xyz="-0.10149 -0.04773 -0.0595" rpy="0 0 0" />
    <parent link="leg_l6_link" />
    <child link="lr_foot_heel" />
  </joint>
  <link name="l_foot_toe">
    <collision>
      <origin rpy="0 0 0" xyz="0 0 0" />
      <geometry>
        <sphere radius="0.005" />
      </geometry>
    </collision>
  </link>
  <joint name="l_foot_toe_joint" type="fixed">
    <origin xyz="0.142507 0.0 -0.0595" rpy="0 0 0" />
    <parent link="leg_l6_link" />
    <child link="l_foot_toe" />
  </joint>
  <link name="l_foot_heel">
    <collision>
      <origin rpy="0 0 0" xyz="0 0 0" />
      <geometry>
        <sphere radius="0.005" />
      </geometry>
    </collision>
  </link>
  <joint name="l_foot_heel_joint" type="fixed">
    <origin xyz="-0.10149 0.0 -0.0595" rpy="0 0 0" />
    <parent link="leg_l6_link" />
    <child link="l_foot_heel" />
  </joint>
  <link name="leg_r1_link">
    <inertial>
      <origin xyz="-0.00624961 5.65e-06 -0.00874165" rpy="0 0 0" />
      <mass value="1.79206572" />
      <inertia ixx="0.00211603" ixy="-7.6e-07" ixz="0.000107" iyy="0.00302948" iyz="-4.73e-06" izz="0.00399385" />
    </inertial>
    <visual>
      <origin xyz="0 0 0" rpy="0 0 0" />
      <geometry>
        <mesh filename="package://kuavo_assets/models/biped_s40/meshes/r_leg_roll.STL" />
      </geometry>
      <material name="">
        <color rgba="1 1 1 1" />
      </material>
    </visual>
  </link>
  <joint name="leg_r1_joint" type="revolute">
    <origin xyz="-0.0025 -0.087 -0.066" rpy="0 0 0" />
    <parent link="base_link" />
    <child link="leg_r1_link" />
    <axis xyz="1 0 0" />
    <limit lower="-0.663225115757845" upper="0.314159265358979" effort="180.0" velocity="23.55" />
  </joint>
  <link name="leg_r2_link">
    <inertial>
      <origin xyz="4.471e-05 -0.04985878 -0.11682313" rpy="0 0 0" />
      <mass value="1.67630636" />
      <inertia ixx="0.00548764" ixy="2.73e-06" ixz="-9.2e-07" iyy="0.00415421" iyz="-0.00050832" izz="0.00426093" />
    </inertial>
    <visual>
      <origin xyz="0 0 0" rpy="0 0 0" />
      <geometry>
        <mesh filename="package://kuavo_assets/models/biped_s40/meshes/r_leg_yaw.STL" />
      </geometry>
      <material name="">
        <color rgba="1 1 1 1" />
      </material>
    </visual>
  </link>
  <joint name="leg_r2_joint" type="revolute">
    <origin xyz="0 0 0" rpy="0 0 0" />
    <parent link="leg_r1_link" />
    <child link="leg_r2_link" />
    <axis xyz="0 0 1" />
    <limit lower="-0.523598775598299" upper="1.0471975511966" effort="100.0" velocity="41.3433333333333" />
  </joint>
  <link name="leg_r3_link">
    <inertial>
      <origin xyz="-0.00238153 0.02309009 -0.06305853" rpy="0 0 0" />
      <mass value="2.46916674" />
      <inertia ixx="0.02435155" ixy="-4.518e-05" ixz="0.00123747" iyy="0.02479853" iyz="-0.00261573" izz="0.0047908" />
    </inertial>
    <visual>
      <origin xyz="0 0 0" rpy="0 0 0" />
      <geometry>
        <mesh filename="package://kuavo_assets/models/biped_s40/meshes/r_leg_pitch.STL" />
      </geometry>
      <material name="">
        <color rgba="1 1 1 1" />
      </material>
    </visual>
  </link>
  <joint name="leg_r3_joint" type="revolute">
    <origin xyz="0 -0.02545000000000 -0.1287" rpy="0 0 0" />
    <parent link="leg_r2_link" />
    <child link="leg_r3_link" />
    <axis xyz="0 1 0" />
    <limit lower="-1.83259571459405" upper="1.0471975511966" effort="100.0" velocity="41.3433333333333" />
  </joint>
  <link name="leg_r4_link">
    <inertial>
      <origin xyz="0.00304109 4.102e-05 -0.12213983" rpy="0 0 0" />
      <mass value="1.86454133" />
      <inertia ixx="0.01537809" ixy="-7.85e-06" ixz="-0.00010779" iyy="0.01560001" iyz="0.00015322" izz="0.00123022" />
    </inertial>
    <visual>
      <origin xyz="0 0 0" rpy="0 0 0" />
      <geometry>
        <mesh filename="package://kuavo_assets/models/biped_s40/meshes/r_knee.STL" />
      </geometry>
      <material name="">
        <color rgba="1 1 1 1" />
      </material>
    </visual>
  </link>
  <joint name="leg_r4_joint" type="revolute">
    <origin xyz="-0.0103901619526017 0 -0.249783995753447" rpy="0 0 0" />
    <parent link="leg_r3_link" />
    <child link="leg_r4_link" />
    <axis xyz="0 1 0" />
    <limit lower="0.0" upper="2.18166156499291" effort="100.0" velocity="41.3433333333333" />
  </joint>
  <link name="leg_r5_link">
    <inertial>
      <origin xyz="0.0 0.0 0.0" rpy="0 0 0" />
      <mass value="0.06923929" />
      <inertia ixx="6.66e-06" ixy="0.0" ixz="0.0" iyy="6.66e-06" iyz="0.0" izz="1.172e-05" />
    </inertial>
    <visual>
      <origin xyz="0 0 0" rpy="0 0 0" />
      <geometry>
        <mesh filename="package://kuavo_assets/models/biped_s40/meshes/r_foot_pitch.STL" />
      </geometry>
      <material name="">
        <color rgba="1 1 1 1" />
      </material>
    </visual>
  </link>
  <joint name="leg_r5_joint" type="revolute">
    <origin xyz="0 0 -0.346000000000011" rpy="0 0 0" />
    <parent link="leg_r4_link" />
    <child link="leg_r5_link" />
    <axis xyz="0 1 0" />
    <limit lower="-0.523598775598299" upper="0.523598775598299" effort="36.0" velocity="23.0266666666667" />
  </joint>
  <link name="leg_r6_link">
    <inertial>
      <origin xyz="-0.00987049 7.65e-06 -0.03365512" rpy="0 0 0" />
      <mass value="0.58358273" />
      <inertia ixx="0.0006342" ixy="-1.4e-07" ixz="0.00031564" iyy="0.00227317" iyz="2e-08" izz="0.00239382" />
    </inertial>
    <visual>
      <origin xyz="0 0 0" rpy="0 0 0" />
      <geometry>
        <mesh filename="package://kuavo_assets/models/biped_s40/meshes/r_foot_roll.STL" />
      </geometry>
      <material name="">
        <color rgba="1 1 1 1" />
      </material>
    </visual>
    <collision>
    	<origin xyz="0.0488 0 0" rpy="0 0 0"/>
	    <geometry>
		    <box size="0.25 0.1 0.04"/>
	    </geometry>
    </collision>
  </link>
  <joint name="leg_r6_joint" type="revolute">
    <origin xyz="0 0 0" rpy="0 0 0" />
    <parent link="leg_r5_link" />
    <child link="leg_r6_link" />
    <axis xyz="1 0 0" />
    <limit lower="-0.349065850398866" upper="0.349065850398866" effort="36.0" velocity="23.0266666666667" />
  </joint>
  <link name="rl_foot_toe">
    <collision>
      <origin rpy="0 0 0" xyz="0 0 0" />
      <geometry>
        <sphere radius="0.005" />
      </geometry>
    </collision>
  </link>
  <joint name="rl_foot_toe_joint" type="fixed">
    <origin xyz="0.142507 0.04773 -0.0595" rpy="0 0 0" />
    <parent link="leg_r6_link" />
    <child link="rl_foot_toe" />
  </joint>
  <link name="rl_foot_heel">
    <collision>
      <origin rpy="0 0 0" xyz="0 0 0" />
      <geometry>
        <sphere radius="0.005" />
      </geometry>
    </collision>
  </link>
  <joint name="rl_foot_heel_joint" type="fixed">
    <origin xyz="-0.10149 0.04773 -0.0595" rpy="0 0 0" />
    <parent link="leg_r6_link" />
    <child link="rl_foot_heel" />
  </joint>
  <link name="rr_foot_toe">
    <collision>
      <origin rpy="0 0 0" xyz="0 0 0" />
      <geometry>
        <sphere radius="0.005" />
      </geometry>
    </collision>
  </link>
  <joint name="rr_foot_toe_joint" type="fixed">
    <origin xyz="0.142507 -0.04773 -0.0595" rpy="0 0 0" />
    <parent link="leg_r6_link" />
    <child link="rr_foot_toe" />
  </joint>
  <link name="rr_foot_heel">
    <collision>
      <origin rpy="0 0 0" xyz="0 0 0" />
      <geometry>
        <sphere radius="0.005" />
      </geometry>
    </collision>
  </link>
  <joint name="rr_foot_heel_joint" type="fixed">
    <origin xyz="-0.10149 -0.04773 -0.0595" rpy="0 0 0" />
    <parent link="leg_r6_link" />
    <child link="rr_foot_heel" />
  </joint>
  <link name="r_foot_toe">
    <collision>
      <origin rpy="0 0 0" xyz="0 0 0" />
      <geometry>
        <sphere radius="0.005" />
      </geometry>
    </collision>
  </link>
  <joint name="r_foot_toe_joint" type="fixed">
    <origin xyz="0.142507 0.0 -0.0595" rpy="0 0 0" />
    <parent link="leg_r6_link" />
    <child link="r_foot_toe" />
  </joint>
  <link name="r_foot_heel">
    <collision>
      <origin rpy="0 0 0" xyz="0 0 0" />
      <geometry>
        <sphere radius="0.005" />
      </geometry>
    </collision>
  </link>
  <joint name="r_foot_heel_joint" type="fixed">
    <origin xyz="-0.10149 0.0 -0.0595" rpy="0 0 0" />
    <parent link="leg_r6_link" />
    <child link="r_foot_heel" />
  </joint>
  <link name="zarm_l1_link">
    <inertial>
      <origin xyz="0.008 -0.00158 0.0036" rpy="0 0 0" />
      <mass value="1.15" />
      <inertia ixx="0.0006" ixy="5e-05" ixz="1e-05" iyy="0.00048" iyz="-6e-05" izz="0.0007" />
    </inertial>
    <visual>
      <origin xyz="0 0 0" rpy="0 0 0" />
      <geometry>
        <mesh filename="package://kuavo_assets/models/biped_s40/meshes/l_arm_pitch.STL" />
      </geometry>
      <material name="">
        <color rgba="1 1 1 1" />
      </material>
    </visual>
  </link>
  <joint name="zarm_l1_joint" type="revolute">
    <origin xyz="-0.0175 0.25886 0.3245" rpy="0 0 0" />
    <parent link="base_link" />
    <child link="zarm_l1_link" />
    <axis xyz="0 1 0" />
    <limit lower="-2.61799387799149" upper="0.523598775598299" effort="100.0" velocity="41.3433333333333" />
  </joint>
  <link name="zarm_l2_link">
    <inertial>
      <origin xyz="0.00144 0.02159 -0.0202" rpy="0 0 0" />
      <mass value="0.226" />
      <inertia ixx="0.0003" ixy="3e-05" ixz="1e-05" iyy="0.00061" iyz="5e-05" izz="0.00057" />
    </inertial>
    <visual>
      <origin xyz="0 0 0" rpy="0 0 0" />
      <geometry>
        <mesh filename="package://kuavo_assets/models/biped_s40/meshes/l_arm_roll.STL" />
      </geometry>
      <material name="">
        <color rgba="1 1 1 1" />
      </material>
    </visual>
  </link>
  <joint name="zarm_l2_joint" type="revolute">
    <origin xyz="0 0 0" rpy="0 0 0" />
    <parent link="zarm_l1_link" />
    <child link="zarm_l2_link" />
    <axis xyz="1 0 0" />
    <limit lower="-0.349065850398866" upper="2.0943951023932" effort="50.0" velocity="19.154" />
  </joint>
  <link name="zarm_l3_link">
    <inertial>
      <origin xyz="-0.00157 -3e-05 -0.13318" rpy="0 0 0" />
      <mass value="1.166" />
      <inertia ixx="0.00245" ixy="-1e-05" ixz="-1e-05" iyy="0.0022" iyz="0.0" izz="0.00112" />
    </inertial>
    <visual>
      <origin xyz="0 0 0" rpy="0 0 0" />
      <geometry>
        <mesh filename="package://kuavo_assets/models/biped_s40/meshes/l_arm_yaw.STL" />
      </geometry>
      <material name="">
        <color rgba="1 1 1 1" />
      </material>
    </visual>
  </link>
  <joint name="zarm_l3_joint" type="revolute">
    <origin xyz="0 0 0" rpy="0 0 0" />
    <parent link="zarm_l2_link" />
    <child link="zarm_l3_link" />
    <axis xyz="0 0 1" />
    <limit lower="-1.5707963267949" upper="1.5707963267949" effort="20.0" velocity="18.84" />
  </joint>
  <link name="zarm_l4_link">
    <inertial>
      <origin xyz="-4e-05 0.0098 -0.05283" rpy="0 0 0" />
      <mass value="0.575" />
      <inertia ixx="0.00098" ixy="0.0" ixz="0.0" iyy="0.00062" iyz="-0.00016" izz="0.00088" />
    </inertial>
    <visual>
      <origin xyz="0 0 0" rpy="0 0 0" />
      <geometry>
        <mesh filename="package://kuavo_assets/models/biped_s40/meshes/l_forearm.STL" />
      </geometry>
      <material name="">
        <color rgba="1 1 1 1" />
      </material>
    </visual>
  </link>
  <joint name="zarm_l4_joint" type="revolute">
    <origin xyz="0 0 -0.1646" rpy="0 0 0" />
    <parent link="zarm_l3_link" />
    <child link="zarm_l4_link" />
    <axis xyz="0 1 0" />
    <limit lower="-1.5707963267949" upper="0.0" effort="20.0" velocity="18.84" />
  </joint>
  <link name="zarm_l5_link">
    <inertial>
      <origin xyz="-0.00011 0.00421 -0.11168" rpy="0 0 0" />
      <mass value="0.46" />
      <inertia ixx="0.00077" ixy="0.0" ixz="0.0" iyy="0.0005" iyz="-4e-05" izz="0.00063" />
    </inertial>
    <visual>
      <origin xyz="0 0 0" rpy="0 0 0" />
      <geometry>
        <mesh filename="package://kuavo_assets/models/biped_s40/meshes/l_hand_yaw.STL" />
      </geometry>
      <material name="">
        <color rgba="1 1 1 1" />
      </material>
    </visual>
  </link>
  <joint name="zarm_l5_joint" type="revolute">
    <origin xyz="0 0 0" rpy="0 0 0" />
    <parent link="zarm_l4_link" />
    <child link="zarm_l5_link" />
    <axis xyz="0 0 1" />
    <limit lower="-1.5707963267949" upper="1.5707963267949" effort="6.0" velocity="21.666" />
  </joint>
  <link name="zarm_l6_link">
    <inertial>
      <origin xyz="0.00253 0.00382 -0.05356" rpy="0 0 0" />
      <mass value="0.35" />
      <inertia ixx="0.00023" ixy="0.0" ixz="0.0" iyy="0.00024" iyz="-4e-05" izz="0.00019" />
    </inertial>
    <visual>
      <origin xyz="0 0 0" rpy="0 0 0" />
      <geometry>
        <mesh filename="package://kuavo_assets/models/biped_s40/meshes/l_hand_pitch.STL" />
      </geometry>
      <material name="">
        <color rgba="1 1 1 1" />
      </material>
    </visual>
  </link>
  <joint name="zarm_l6_joint" type="revolute">
    <origin xyz="0 0 -0.132050000125748" rpy="0 0 0" />
    <parent link="zarm_l5_link" />
    <child link="zarm_l6_link" />
    <axis xyz="0 1 0" />
    <limit lower="-1.5707963267949" upper="1.5707963267949" effort="6.0" velocity="21.666" />
  </joint>
  <link name="zarm_l7_link">
    <inertial>
      <origin xyz="0.00267 0.00748 -0.07162" rpy="0 0 0" />
      <mass value="0.81" />
      <inertia ixx="0.00117" ixy="2e-05" ixz="0.0" iyy="0.00128" iyz="-2e-05" izz="0.00036" />
    </inertial>
    <visual>
      <origin xyz="0 0 0" rpy="0 0 0" />
      <geometry>
        <mesh filename="package://kuavo_assets/models/biped_s40/meshes/l_hand_roll.STL" />
      </geometry>
      <material name="">
        <color rgba="1 1 1 1" />
      </material>
    </visual>
  </link>
  <joint name="zarm_l7_joint" type="revolute">
    <origin xyz="0 0 -0.0589999999999999" rpy="0 0 0" />
    <parent link="zarm_l6_link" />
    <child link="zarm_l7_link" />
    <axis xyz="1 0 0" />
    <limit lower="-1.5707963267949" upper="1.5707963267949" effort="6.0" velocity="21.666" />
  </joint>
  <link name="zarm_l7_end_effector">
    <collision>
      <origin rpy="0 0 0" xyz="0 0 0" />
      <geometry>
        <sphere radius="0.005" />
      </geometry>
    </collision>
  </link>
  <joint name="zarm_l7_end_effector_joint" type="fixed">
    <origin xyz="0 -0.03 -0.17" rpy="0 0 0" />
    <parent link="zarm_l7_link" />
    <child link="zarm_l7_end_effector" />
  </joint>
  <link name="zarm_r1_link">
    <inertial>
      <origin xyz="0.008 0.00158 -0.0036" rpy="0 0 0" />
      <mass value="1.15" />
      <inertia ixx="0.0006" ixy="-5e-05" ixz="-1e-05" iyy="0.00048" iyz="-6e-05" izz="0.0007" />
    </inertial>
    <visual>
      <origin xyz="0 0 0" rpy="0 0 0" />
      <geometry>
        <mesh filename="package://kuavo_assets/models/biped_s40/meshes/r_arm_pitch.STL" />
      </geometry>
      <material name="">
        <color rgba="1 1 1 1" />
      </material>
    </visual>
  </link>
  <joint name="zarm_r1_joint" type="revolute">
    <origin xyz="-0.0175 -0.25886 0.3245" rpy="0 0 0" />
    <parent link="base_link" />
    <child link="zarm_r1_link" />
    <axis xyz="0 1 0" />
    <limit lower="-2.61799387799149" upper="0.523598775598299" effort="100.0" velocity="41.3433333333333" />
  </joint>
  <link name="zarm_r2_link">
    <inertial>
      <origin xyz="0.00144 -0.02159 -0.02021" rpy="0 0 0" />
      <mass value="0.226" />
      <inertia ixx="0.0003" ixy="-3e-05" ixz="1e-05" iyy="0.00061" iyz="-5e-05" izz="0.00057" />
    </inertial>
    <visual>
      <origin xyz="0 0 0" rpy="0 0 0" />
      <geometry>
        <mesh filename="package://kuavo_assets/models/biped_s40/meshes/r_arm_roll.STL" />
      </geometry>
      <material name="">
        <color rgba="1 1 1 1" />
      </material>
    </visual>
  </link>
  <joint name="zarm_r2_joint" type="revolute">
    <origin xyz="0 0 0" rpy="0 0 0" />
    <parent link="zarm_r1_link" />
    <child link="zarm_r2_link" />
    <axis xyz="1 0 0" />
    <limit lower="-2.0943951023932" upper="0.349065850398866" effort="50.0" velocity="19.154" />
  </joint>
  <link name="zarm_r3_link">
    <inertial>
      <origin xyz="-0.00157 3e-05 -0.13318" rpy="0 0 0" />
      <mass value="1.166" />
      <inertia ixx="0.00245" ixy="1e-05" ixz="-1e-05" iyy="0.0022" iyz="0.0" izz="0.00112" />
    </inertial>
    <visual>
      <origin xyz="0 0 0" rpy="0 0 0" />
      <geometry>
        <mesh filename="package://kuavo_assets/models/biped_s40/meshes/r_arm_yaw.STL" />
      </geometry>
      <material name="">
        <color rgba="1 1 1 1" />
      </material>
    </visual>
  </link>
  <joint name="zarm_r3_joint" type="revolute">
    <origin xyz="0 0 0" rpy="0 0 0" />
    <parent link="zarm_r2_link" />
    <child link="zarm_r3_link" />
    <axis xyz="0 0 1" />
    <limit lower="-1.5707963267949" upper="1.5707963267949" effort="20.0" velocity="18.84" />
  </joint>
  <link name="zarm_r4_link">
    <inertial>
      <origin xyz="-4e-05 -0.0098 -0.05283" rpy="0 0 0" />
      <mass value="0.575" />
      <inertia ixx="0.00098" ixy="0.0" ixz="0.0" iyy="0.00062" iyz="0.00016" izz="0.00088" />
    </inertial>
    <visual>
      <origin xyz="0 0 0" rpy="0 0 0" />
      <geometry>
        <mesh filename="package://kuavo_assets/models/biped_s40/meshes/r_forearm.STL" />
      </geometry>
      <material name="">
        <color rgba="1 1 1 1" />
      </material>
    </visual>
  </link>
  <joint name="zarm_r4_joint" type="revolute">
    <origin xyz="0 0 -0.1646" rpy="0 0 0" />
    <parent link="zarm_r3_link" />
    <child link="zarm_r4_link" />
    <axis xyz="0 1 0" />
    <limit lower="-1.5707963267949" upper="0.0" effort="20.0" velocity="18.84" />
  </joint>
  <link name="zarm_r5_link">
    <inertial>
      <origin xyz="-0.00011 -0.00421 -0.11168" rpy="0 0 0" />
      <mass value="0.46" />
      <inertia ixx="0.00077" ixy="0.0" ixz="0.0" iyy="0.0005" iyz="4e-05" izz="0.00063" />
    </inertial>
    <visual>
      <origin xyz="0 0 0" rpy="0 0 0" />
      <geometry>
        <mesh filename="package://kuavo_assets/models/biped_s40/meshes/r_hand_yaw.STL" />
      </geometry>
      <material name="">
        <color rgba="1 1 1 1" />
      </material>
    </visual>
  </link>
  <joint name="zarm_r5_joint" type="revolute">
    <origin xyz="0 0 0" rpy="0 0 0" />
    <parent link="zarm_r4_link" />
    <child link="zarm_r5_link" />
    <axis xyz="0 0 1" />
    <limit lower="-1.5707963267949" upper="1.5707963267949" effort="6.0" velocity="21.666" />
  </joint>
  <link name="zarm_r6_link">
    <inertial>
      <origin xyz="0.00253 -0.00382 -0.05356" rpy="0 0 0" />
      <mass value="0.35" />
      <inertia ixx="0.00023" ixy="0.0" ixz="0.0" iyy="0.00024" iyz="4e-05" izz="0.00019" />
    </inertial>
    <visual>
      <origin xyz="0 0 0" rpy="0 0 0" />
      <geometry>
        <mesh filename="package://kuavo_assets/models/biped_s40/meshes/r_hand_pitch.STL" />
      </geometry>
      <material name="">
        <color rgba="1 1 1 1" />
      </material>
    </visual>
  </link>
  <joint name="zarm_r6_joint" type="revolute">
    <origin xyz="0 0 -0.132050000240097" rpy="0 0 0" />
    <parent link="zarm_r5_link" />
    <child link="zarm_r6_link" />
    <axis xyz="0 1 0" />
    <limit lower="-1.5707963267949" upper="1.5707963267949" effort="6.0" velocity="21.666" />
  </joint>
  <link name="zarm_r7_link">
    <inertial>
      <origin xyz="0.00267 -0.00748 -0.07162" rpy="0 0 0" />
      <mass value="0.81" />
      <inertia ixx="0.00098" ixy="-1e-05" ixz="1e-05" iyy="0.00104" iyz="1e-05" izz="0.00027" />
    </inertial>
    <visual>
      <origin xyz="0 0 0" rpy="0 0 0" />
      <geometry>
        <mesh filename="package://kuavo_assets/models/biped_s40/meshes/r_hand_roll.STL" />
      </geometry>
      <material name="">
        <color rgba="1 1 1 1" />
      </material>
    </visual>
  </link>
  <joint name="zarm_r7_joint" type="revolute">
    <origin xyz="0 0 -0.0589999999999999" rpy="0 0 0" />
    <parent link="zarm_r6_link" />
    <child link="zarm_r7_link" />
    <axis xyz="1 0 0" />
    <limit lower="-1.5707963267949" upper="1.5707963267949" effort="6.0" velocity="21.666" />
  </joint>
  <link name="zarm_r7_end_effector">
    <collision>
      <origin rpy="0 0 0" xyz="0 0 0" />
      <geometry>
        <sphere radius="0.005" />
      </geometry>
    </collision>
  </link>
  <joint name="zarm_r7_end_effector_joint" type="fixed">
    <origin xyz="0 0.03 -0.17" rpy="0 0 0" />
    <parent link="zarm_r7_link" />
    <child link="zarm_r7_end_effector" />
  </joint>
  <link name="zhead_1_link">
    <inertial>
      <origin xyz="0.0 0.01245 -0.02982" rpy="0 0 0" />
      <mass value="0.082" />
      <inertia ixx="7e-05" ixy="0.0" ixz="0.0" iyy="6e-05" iyz="-2e-05" izz="8e-05" />
    </inertial>
    <visual>
      <origin xyz="0 0 0" rpy="0 0 0" />
      <geometry>
        <mesh filename="package://kuavo_assets/models/biped_s40/meshes/head_yaw.STL" />
      </geometry>
      <material name="">
        <color rgba="1 1 1 1" />
      </material>
    </visual>
  </link>
  <joint name="zhead_1_joint" type="revolute">
    <origin xyz="-0.0175 0.0 0.5014" rpy="0 0 0" />
    <parent link="base_link" />
    <child link="zhead_1_link" />
    <axis xyz="0 0 1" />
    <limit lower="-1.5707963267949" upper="1.5707963267949" effort="1.5" velocity="5.23333333333333" />
  </joint>
  <link name="zhead_2_link">
    <inertial>
      <origin xyz="0.01106 0.00069 0.0586" rpy="0 0 0" />
      <mass value="1.379" />
      <inertia ixx="0.003" ixy="1e-05" ixz="0.0003" iyy="0.00301" iyz="5e-05" izz="0.00281" />
    </inertial>
    <visual>
      <origin xyz="0 0 0" rpy="0 0 0" />
      <geometry>
        <mesh filename="package://kuavo_assets/models/biped_s40/meshes/head_pitch.STL" />
      </geometry>
      <material name="">
        <color rgba="1 1 1 1" />
      </material>
    </visual>
  </link>
  <joint name="zhead_2_joint" type="revolute">
    <origin xyz="0 0 0" rpy="0 0 0" />
    <parent link="zhead_1_link" />
    <child link="zhead_2_link" />
    <axis xyz="0 1 0" />
    <limit lower="-0.523598775598299" upper="0.523598775598299" effort="6.0" velocity="9.734" />
  </joint>
  <link name="camera">
    <inertial>
      <origin xyz="-0.04336 -0.01736 -0.01161" rpy="0 0 0" />
      <mass value="0.047" />
      <inertia ixx="0.00065" ixy="0.0" ixz="0.00015" iyy="0.00091" iyz="0.0" izz="0.00105" />
    </inertial>
    <visual>
      <origin xyz="0 0 0" rpy="0 0 0" />
      <geometry>
        <mesh filename="package://kuavo_assets/models/biped_s40/meshes/camera.STL" />
      </geometry>
      <material name="">
        <color rgba="1 1 1 1" />
      </material>
    </visual>
  </link>
  <joint name="camera" type="fixed">
    <origin xyz="0.0919101155958193 0.0175000000022731 0.0617838754768194" rpy="0 0.610865238198013 0" />
    <parent link="zhead_2_link" />
    <child link="camera" />
  </joint>

  <link
    name="camera_base">
    <inertial>
      <origin
        xyz="0.00354055612698423 0.00140393663616134 0.0124511788327371"
        rpy="0 0 0" />
      <mass
        value="0.0170255961584929" />
      <inertia
        ixx="1.09182620877589E-05"
        ixy="1.05354237503678E-07"
        ixz="1.05871360812799E-08"
        iyy="8.57178923448405E-07"
        iyz="1.6401848102306E-08"
        izz="1.02869873531782E-05" />
    </inertial>
    <visual>
      <origin
        xyz="0 0 0"
        rpy="0 0 0" />
      <geometry>
        <mesh
          filename="package://kuavo_assets/models/biped_s40/meshes/camera_base.STL" />
      </geometry>
      <material
        name="">
        <color
          rgba="1 1 1 1" />
      </material>
    </visual>
    <collision>
      <origin
        xyz="0 0 0"
        rpy="0 0 0" />
      <geometry>
        <mesh
          filename="package://kuavo_assets/models/biped_s40/meshes/camera_base.STL" />
      </geometry>
    </collision>
  </link>
  <joint
    name="camera_base"
    type="fixed">
    <origin
      xyz="0.0766792844154498 0 0.0571889355165869"
      rpy="0 0.610865238198013 0" />
    <parent
      link="zhead_2_link" />
    <child
      link="camera_base" />
  </joint>
  
</robot>
