<?xml version="1.0" ?>
<!-- =================================================================================== -->
<!-- |    This document was autogenerated by xacro from /home/fandes/workspace/kuavo-ros-control/src/humanoid-control/humanoid_interface_drake/models/biped_gen4.2/urdf/biped_v3.xacro | -->
<!-- |    EDITING THIS FILE BY HAND IS NOT RECOMMENDED                                 | -->
<!-- =================================================================================== -->
<robot name="biped_v3" xmlns:drake="https://drake.mit.edu">
  <link name="torso">
   <inertial>
    <!-- 质心：( -0.05495950, -0.00028705, -0.01468007 ) -->
    <origin xyz="-0.05495950 -0.00028705 -0.01468007" rpy="0 0 0" />
    <!-- 质量：7.06404632 kg -->
    <mass value="7.06405" />
    <!-- ✅ 由重心决定，并且对齐输出的坐标系（使用负张量记数法）- 来自torso Lxx/Lyy/Lzz -->
    <inertia
      ixx="0.07432439"
      ixy="0.0"
      ixz="-0.01900645"
      iyy="0.05497594"
      iyz="0.0"
      izz="0.07548789" />
    </inertial>
    <visual>
      <origin xyz="0 0 0" rpy="0 0 0" />
      <geometry>
        <mesh filename="../../meshes/torso.STL" />
      </geometry>
      <material name="">
        <color rgba="0.752941176470588 0.752941176470588 0.752941176470588 1" />
      </material>
    </visual>
    <!-- <collision>
      <origin xyz="0 0 0" rpy="0 0 0" />
      <geometry>
        <mesh filename="../../meshes/torso.STL" />
      </geometry>
    </collision> -->
  </link>
  <link name="waist_yaw_link">
    <inertial>
      <!-- 质心：( -0.00044187, -0.00068282, 0.16674017 ) -->
      <origin xyz="0.05349912 -0.00068282 0.16674017" rpy="0 0 0" />
      <!-- 质量：17.11065787 kg -->
      <mass value="34.54246" />
      <!-- ✅ 由重心决定，并且对齐输出的坐标系（使用负张量记数法）- 来自waist_yaw Lxx/Lyy/Lzz -->
      <inertia
        ixx="0.34143343"
        ixy="0.0"
        ixz="0.0"
        iyy="0.25757527"
        iyz="0.0"
        izz="0.20167280" />
    </inertial>
    <visual>
      <origin xyz="0 0 0" rpy="0 0 0" />
      <geometry>
        <mesh filename="../../meshes/waist_yaw.STL" />
      </geometry>
      <material name="">
        <color rgba="1 1 1 1" />
      </material>
    </visual>
  </link>
  <joint name="waist_yaw_joint" type="fixed">
    <origin xyz="0 0 0.1114" rpy="0 0 0" />
    <parent link="torso" />
    <child link="waist_yaw_link" />
    <axis xyz="0 0 1" />
    <limit lower="-3.14159" upper="3.14159" effort="102.0" velocity="8.7" />
    <dynamics damping="0.02" friction="0.0" />
  </joint>
   <!-- ============ l_leg_roll ============ -->
  <!-- 坐标系：l_leg_yaw_roll -->
  <!-- 对称源：r_leg_roll (X-Z平面对称) -->
  <link name="leg_l1_link">
    <inertial>
      <!-- 质心：右腿(-0.00560896, -0.00032862, -0.00212773) -> 左腿(-0.00560896, +0.00032862, -0.00212773) -->
      <origin xyz="-0.00560896 0.00032862 -0.00212773" rpy="0 0 0" />
      <!-- 质量：1.55641268 kg -->
      <mass value="1.55641" />
      <!-- ✅ 惯性张量：由重心决定，对齐输出坐标系，负张量记数法，ixy/ixz/iyz符号取反 -->
      <inertia
        ixx="0.00191127"
        ixy="-0.00001633"      
        ixz="-0.00000320"     
        iyy="0.00254335"
        iyz="0.00000055"     
        izz="0.00260594" />
    </inertial>
    <visual>
      <origin xyz="0 0 0" rpy="0 0 0" />
      <geometry>
        <mesh filename="../../meshes/l_leg_roll.STL" />
      </geometry>
      <material name="">
        <color rgba="1 1 1 1" />
      </material>
    </visual>
  </link>
  <joint name="leg_l1_joint" type="revolute">
    <origin xyz="0.0 0.095075 -0.066" rpy="0 0 0" />
    <parent link="torso" />
    <child link="leg_l1_link" />
    <axis xyz="1 0 0" />
    <limit lower="-0.314159265358979" upper="0.663225115757845" effort="127.0" velocity="10.4" />
    <dynamics damping="0.02" friction="0.0" />
  </joint>
  <transmission type="SimpleTransmission">
    <joint name="leg_l1_joint" />
    <actuator name="leg_l1_joint_motor" />
  </transmission>
  <!-- ============ l_leg_yaw ============ -->
  <!-- 坐标系：l_leg_yaw_roll -->
  <!-- 对称源：r_leg_yaw (X-Z平面对称) -->
  <link name="leg_l2_link">
    <inertial>
      <!-- 质心：右腿(0.00006341, 0.00960017, -0.09308949) -> 左腿(0.00006341, -0.00960017, -0.09308949) -->
      <origin xyz="0.00006341 -0.00960017 -0.09308949" rpy="0 0 0" />
      <!-- 质量：0.75872512 kg -->
      <mass value="0.75873" />
      <!-- ✅ 惯性张量：由重心决定，对齐输出坐标系，负张量记数法，ixy/ixz/iyz符号取反 -->
      <inertia
        ixx="0.00348980"
        ixy="0.00000617"     
        ixz="-0.00000543"      
        iyy="0.00201021"
        iyz="-0.00030265"      
        izz="0.00236363" />
    </inertial>
    <visual>
      <origin xyz="0 0 0" rpy="0 0 0" />
      <geometry>
        <mesh filename="../../meshes/l_leg_yaw.STL" />
      </geometry>
      <material name="">
        <color rgba="1 1 1 1" />
      </material>
    </visual>
  </link>
  <joint name="leg_l2_joint" type="revolute">
    <origin xyz="0 0 0" rpy="0 0 0" />
    <parent link="leg_l1_link" />
    <child link="leg_l2_link" />
    <axis xyz="0 0 1" />
    <limit lower="-0.785398163397448" upper="1.91986217719376" effort="71.0" velocity="8.7" />
    <dynamics damping="0.02" friction="0.0" />
  </joint>
  <transmission type="SimpleTransmission">
    <joint name="leg_l2_joint" />
    <actuator name="leg_l2_joint_motor" />
  </transmission>
  <!-- ============ l_leg_pitch ============ -->
  <!-- 坐标系：l_leg_pitch -->
  <!-- 对称源：r_leg_pitch (X-Z平面对称) -->
  <link name="leg_l3_link">
    <inertial>
      <!-- 质心：右腿(0.00273544, -0.01478421, -0.09011501) -> 左腿(0.00273544, +0.01478421, -0.09011501) -->
      <origin xyz="0.00273544 0.01478421 -0.09011501" rpy="0 0 0" />
      <!-- 质量：6.68074305 kg -->
      <mass value="6.68074" />
      <!-- ✅ 惯性张量：由重心决定，对齐输出坐标系，负张量记数法，ixy/ixz/iyz符号取反 -->
      <inertia
        ixx="0.06155086"
        ixy="0.00016595"      
        ixz="-0.00169943"      
        iyy="0.05999156"
        iyz="0.00073898"     
        izz="0.01575336" />
    </inertial>
    <visual>
      <origin xyz="0 0 0" rpy="0 0 0" />
      <geometry>
        <mesh filename="../../meshes/l_leg_pitch.STL" />
      </geometry>
      <material name="">
        <color rgba="1 1 1 1" />
      </material>
    </visual>
  </link>
  <joint name="leg_l3_joint" type="revolute">
    <origin xyz="0 0 -0.1437" rpy="0 0 0" />
    <parent link="leg_l2_link" />
    <child link="leg_l3_link" />
    <axis xyz="0 1 0" />
    <limit lower="-1.91986217719376" upper="1.5707963267949" effort="132" velocity="12.7" />
    <dynamics damping="0.02" friction="0.0" />
  </joint>
  <transmission type="SimpleTransmission">
    <joint name="leg_l3_joint" />
    <actuator name="leg_l3_joint_motor" />
  </transmission>
  <!-- ============ l_knee ============ -->
  <!-- 坐标系：l_knee -->
  <!-- 对称源：r_knee (X-Z平面对称) -->
  <link name="leg_l4_link">
    <inertial>
      <!-- 质心：右腿(0.00684787, -0.00006281, -0.16262733) -> 左腿(0.00684787, +0.00006281, -0.16262733) -->
      <origin xyz="0.00684787 0.00006281 -0.16262733" rpy="0 0 0" />
      <!-- 质量：3.64665831 kg -->
      <mass value="3.64666" />
      <!-- ✅ 惯性张量：由重心决定，对齐输出坐标系，负张量记数法，ixy/ixz/iyz符号取反 -->
      <inertia
        ixx="0.04372691"
        ixy="0.00000494"     
        ixz="0.00053020"      
        iyy="0.04357016"
        iyz="-0.00006946"      
        izz="0.00246985" />
    </inertial>
    <visual>
      <origin xyz="0 0 0" rpy="0 0 0" />
      <geometry>
        <mesh filename="../../meshes/l_knee.STL" />
      </geometry>
      <material name="">
        <color rgba="1 1 1 1" />
      </material>
    </visual>
  </link>
  <joint name="leg_l4_joint" type="revolute">
    <origin xyz="-0.0011639 0 -0.284" rpy="0 0 0" />
    <parent link="leg_l3_link" />
    <child link="leg_l4_link" />
    <axis xyz="0 1 0" />
    <limit lower="0.0" upper="2.53072741539178" effort="280.0" velocity="10.4" />
    <dynamics damping="0.02" friction="0.0" />
  </joint>
  <transmission type="SimpleTransmission">
    <joint name="leg_l4_joint" />
    <actuator name="leg_l4_joint_motor" />
  </transmission>
  <!-- ============ l_foot_pitch ============ -->
  <!-- 坐标系：l_foot_pitch_roll -->
  <!-- 对称源：r_foot_pitch (完全对称) -->
  <link name="leg_l5_link">
    <inertial>
      <!-- 质心：( 0, 0, 0 ) -->
      <origin xyz="0 0 0" rpy="0 0 0" />
      <!-- 质量：0.07848005 kg -->
      <mass value="0.07848" />
      <!-- ✅ 惯性张量：完全对称，与右腿完全相同 -->
      <inertia
        ixx="0.00000757"
        ixy="0.00000000"
        ixz="0.00000000"
        iyy="0.00000757"
        iyz="0.00000000"
        izz="0.00001318" />
    </inertial>
    <visual>
      <origin xyz="0 0 0" rpy="0 0 0" />
      <geometry>
        <mesh filename="../../meshes/l_foot_pitch.STL" />
      </geometry>
      <material name="">
        <color rgba="1 1 1 1" />
      </material>
    </visual>
  </link>
  <joint name="leg_l5_joint" type="revolute">
    <origin xyz="0.002 0 -0.416" rpy="0 0 0" />
    <parent link="leg_l4_link" />
    <child link="leg_l5_link" />
    <axis xyz="0 1 0" />
    <limit lower="-0.872664625997165" upper="0.349065850398866" effort="91.6" velocity="17.8" />
    <dynamics damping="0.02" friction="0.0" />
  </joint>
  <transmission type="SimpleTransmission">
    <joint name="leg_l5_joint" />
    <actuator name="leg_l5_joint_motor" />
  </transmission>
  <!-- ============ l_foot_roll ============ -->
  <!-- 坐标系：l_foot_pitch_roll -->
  <!-- 对称源：r_foot_roll (完全对称，用户覆盖值相同) -->
  <link name="leg_l6_link">
    <inertial>
      <!-- 质心（用户覆盖）：( 0.02655895, -0.00004538, -0.03373024 ) -->
      <origin xyz="0.02655895 -0.00004538 -0.03373024" rpy="0 0 0" />
      <!-- 质量（用户覆盖）：0.69242441 kg -->
      <mass value="0.69242" />
      <!-- ✅ 惯性张量：完全对称，与右腿完全相同（质心Y为负，无需镜像） -->
      <inertia
        ixx="0.00051423"
        ixy="-0.00000078"
        ixz="0.00014745"
        iyy="0.00189913"
        iyz="0.00000033"
        izz="0.00199352" />
    </inertial>
    <visual>
      <origin xyz="0 0 0" rpy="0 0 0" />
      <geometry>
        <mesh filename="../../meshes/l_foot_roll.STL" />
      </geometry>
      <material name="">
        <color rgba="1 1 1 1" />
      </material>
    </visual>
  </link>
  <joint name="leg_l6_joint" type="revolute">
    <origin xyz="0 0 0" rpy="0 0 0" />
    <parent link="leg_l5_link" />
    <child link="leg_l6_link" />
    <axis xyz="1 0 0" />
    <limit lower="-0.261799387799149" upper="0.261799387799149" effort="30.0" velocity="17.8" />
    <dynamics damping="0.02" friction="0.0" />
  </joint>
  <transmission type="SimpleTransmission">
    <joint name="leg_l6_joint" />
    <actuator name="leg_l6_joint_motor" />
  </transmission>
  <frame link="leg_l6_link" name="l_foot_sole" xyz="0.04883799999999999 0.0 -0.0595" />
  <frame link="leg_l6_link" name="l_foot_toe" xyz="0.17084 0.0 -0.0595" />
  <frame link="leg_l6_link" name="l_foot_heel" xyz="-0.073164 0.0 -0.0595" />
  <!-- ============ r_leg_roll ============ -->
  <!-- 坐标系：r_leg_roll_yaw -->
  <link name="leg_r1_link">
    <inertial>
      <!-- 质心：( -0.00560896, -0.00032862, -0.00212773 ) -->
      <origin xyz="-0.00560896 -0.00032862 -0.00212773" rpy="0 0 0" />
      <!-- 质量：1.55641268 kg -->
      <mass value="1.55641" />
      <!-- ✅ 由重心决定，并且对齐输出的坐标系（使用负张量记数法） -->
      <inertia
        ixx="0.00191127"
        ixy="0.00001633"
        ixz="0.00000320"
        iyy="0.00254335"
        iyz="-0.00000055"
        izz="0.00260594" />
    </inertial>
    <visual>
      <origin xyz="0 0 0" rpy="0 0 0" />
      <geometry>
        <mesh filename="../../meshes/r_leg_roll.STL" />
      </geometry>
      <material name="">
        <color rgba="1 1 1 1" />
      </material>
    </visual>
  </link>
  <joint name="leg_r1_joint" type="revolute">
    <origin xyz="0.0 -0.095075 -0.066" rpy="0 0 0" />
    <parent link="torso" />
    <child link="leg_r1_link" />
    <axis xyz="1 0 0" />
    <limit lower="-0.663225115757845" upper="0.314159265358979" effort="127.0" velocity="10.4" />
    <dynamics damping="0.02" friction="0.0" />
  </joint>
  <transmission type="SimpleTransmission">
    <joint name="leg_r1_joint" />
    <actuator name="leg_r1_joint_motor" />
  </transmission>
  <!-- ============ r_leg_yaw ============ -->
  <!-- 坐标系：r_leg_roll_yaw -->
  <link name="leg_r2_link">
    <inertial>
      <!-- 质心：( 0.00006341, 0.00960017, -0.09308949 ) -->
      <origin xyz="0.00006341 0.00960017 -0.09308949" rpy="0 0 0" />
      <!-- 质量：0.75872512 kg -->
      <mass value="0.75873" />
      <!-- ✅ 由重心决定，并且对齐输出的坐标系（使用负张量记数法） -->
      <inertia
        ixx="0.00348980"
        ixy="-0.00000617"
        ixz="0.00000543"
        iyy="0.00201021"
        iyz="0.00030265"
        izz="0.00236363" />
    </inertial>
    <visual>
      <origin xyz="0 0 0" rpy="0 0 0" />
      <geometry>
        <mesh filename="../../meshes/r_leg_yaw.STL" />
      </geometry>
      <material name="">
        <color rgba="1 1 1 1" />
      </material>
    </visual>
  </link>
  <joint name="leg_r2_joint" type="revolute">
    <origin xyz="0 0 0" rpy="0 0 0" />
    <parent link="leg_r1_link" />
    <child link="leg_r2_link" />
    <axis xyz="0 0 1" />
    <limit lower="-1.91986217719376" upper="0.785398163397448" effort="71.0" velocity="8.7" />
    <dynamics damping="0.02" friction="0.0" />
  </joint>
  <transmission type="SimpleTransmission">
    <joint name="leg_r2_joint" />
    <actuator name="leg_r2_joint_motor" />
  </transmission>
  <!-- ============ r_leg_pitch ============ -->
  <!-- 坐标系：r_leg_pitch -->
  <link name="leg_r3_link">
    <inertial>
      <!-- 质心：( 0.00273544, -0.01478421, -0.09011501 ) -->
      <origin xyz="0.00273544 -0.01478421 -0.09011501" rpy="0 0 0" />
      <!-- 质量：6.68074305 kg -->
      <mass value="6.68074" />
      <!-- ✅ 由重心决定，并且对齐输出的坐标系（使用负张量记数法） -->
      <inertia
        ixx="0.06155086"
        ixy="-0.00016595"
        ixz="0.00169943"
        iyy="0.05999156"
        iyz="-0.00073898"
        izz="0.01575336" />
    </inertial>
    <visual>
      <origin xyz="0 0 0" rpy="0 0 0" />
      <geometry>
        <mesh filename="../../meshes/r_leg_pitch.STL" />
      </geometry>
      <material name="">
        <color rgba="1 1 1 1" />
      </material>
    </visual>
  </link>
  <joint name="leg_r3_joint" type="revolute">
    <origin xyz="0 0 -0.1437" rpy="0 0 0" />
    <parent link="leg_r2_link" />
    <child link="leg_r3_link" />
    <axis xyz="0 1 0" />
    <limit lower="-1.91986217719376" upper="1.5707963267949" effort="132.0" velocity="12.7" />
    <dynamics damping="0.02" friction="0.0" />
  </joint>
  <transmission type="SimpleTransmission">
    <joint name="leg_r3_joint" />
    <actuator name="leg_r3_joint_motor" />
  </transmission>
  <!-- ============ r_knee ============ -->
  <!-- 坐标系：r_knee -->
  <link name="leg_r4_link">
    <inertial>
      <!-- 质心：( 0.00684787, -0.00006281, -0.16262733 ) -->
      <origin xyz="0.00684787 -0.00006281 -0.16262733" rpy="0 0 0" />
      <!-- 质量：3.64665831 kg -->
      <mass value="3.64666" />
      <!-- ✅ 由重心决定，并且对齐输出的坐标系（使用负张量记数法） -->
      <inertia
        ixx="0.04372691"
        ixy="-0.00000494"
        ixz="-0.00053020"
        iyy="0.04357016"
        iyz="0.00006946"
        izz="0.00246985" />
    </inertial>
    <visual>
      <origin xyz="0 0 0" rpy="0 0 0" />
      <geometry>
        <mesh filename="../../meshes/r_knee.STL" />
      </geometry>
      <material name="">
        <color rgba="1 1 1 1" />
      </material>
    </visual>
  </link>
  <joint name="leg_r4_joint" type="revolute">
    <origin xyz="-0.0011639 0 -0.284" rpy="0 0 0" />
    <parent link="leg_r3_link" />
    <child link="leg_r4_link" />
    <axis xyz="0 1 0" />
    <limit lower="0.0" upper="2.53072741539178" effort="280.0" velocity="10.4" />
    <dynamics damping="0.02" friction="0.0" />
  </joint>
  <transmission type="SimpleTransmission">
    <joint name="leg_r4_joint" />
    <actuator name="leg_r4_joint_motor" />
  </transmission>
  <!-- ============ r_foot_pitch ============ -->
  <!-- 坐标系：r_foot_pitch_roll -->
  <link name="leg_r5_link">
    <inertial>
      <!-- 质心：( 0, 0, 0 ) -->
      <origin xyz="0 0 0" rpy="0 0 0" />
      <!-- 质量：0.07848005 kg -->
      <mass value="0.07848" />
      <!-- ✅ 由重心决定，并且对齐输出的坐标系（使用负张量记数法）- 与输出坐标系相同因为质心在原点 -->
      <inertia
        ixx="0.00000757"
        ixy="0.00000000"
        ixz="0.00000000"
        iyy="0.00000757"
        iyz="0.00000000"
        izz="0.00001318" />
    </inertial>
    <visual>
      <origin xyz="0 0 0" rpy="0 0 0" />
      <geometry>
        <mesh filename="../../meshes/r_foot_pitch.STL" />
      </geometry>
      <material name="">
        <color rgba="1 1 1 1" />
      </material>
    </visual>
  </link>
  <joint name="leg_r5_joint" type="revolute">
    <origin xyz="0.002 0 -0.416" rpy="0 0 0" />
    <parent link="leg_r4_link" />
    <child link="leg_r5_link" />
    <axis xyz="0 1 0" />
    <limit lower="-0.872664625997165" upper="0.349065850398866" effort="91.6" velocity="17.8" />
    <dynamics damping="0.02" friction="0.0" />
  </joint>
  <transmission type="SimpleTransmission">
    <joint name="leg_r5_joint" />
    <actuator name="leg_r5_joint_motor" />
  </transmission>
  <!-- ============ r_foot_roll ============ -->
  <!-- 坐标系：r_foot_pitch_roll -->
  <link name="leg_r6_link">
    <inertial>
      <!-- 质心（用户覆盖）：( 0.02655895, -0.00004538, -0.03373024 ) -->
      <origin xyz="0.02655895 -0.00004538 -0.03373024" rpy="0 0 0" />
      <!-- 质量（用户覆盖）：0.69242441 kg -->
      <mass value="0.69242" />
      <!-- ✅ 由重心决定，并且对齐输出的坐标系（使用负张量记数法） -->
      <inertia
        ixx="0.00051423"
        ixy="-0.00000078"
        ixz="0.00014745"
        iyy="0.00189913"
        iyz="0.00000033"
        izz="0.00199352" />
    </inertial>
    <visual>
      <origin xyz="0 0 0" rpy="0 0 0" />
      <geometry>
        <mesh filename="../../meshes/r_foot_roll.STL" />
      </geometry>
      <material name="">
        <color rgba="1 1 1 1" />
      </material>
    </visual>
  </link>
  <joint name="leg_r6_joint" type="revolute">
    <origin xyz="0 0 0" rpy="0 0 0" />
    <parent link="leg_r5_link" />
    <child link="leg_r6_link" />
    <axis xyz="1 0 0" />
    <limit lower="-0.261799387799149" upper="0.261799387799149" effort="30.0" velocity="17.8" />
    <dynamics damping="0.02" friction="0.0" />
  </joint>
  <transmission type="SimpleTransmission">
    <joint name="leg_r6_joint" />
    <actuator name="leg_r6_joint_motor" />
  </transmission>
  <frame link="leg_r6_link" name="r_foot_sole" xyz="0.04883799999999999 0.0 -0.0595" />
  <frame link="leg_r6_link" name="r_foot_toe" xyz="0.17084 0.0 -0.0595" />
  <frame link="leg_r6_link" name="r_foot_heel" xyz="-0.073164 0.0 -0.0595" />
</robot>

