<?xml version='1.0' encoding='utf-8'?>
<robot name="biped_s47">
  <mujoco>
    <compiler meshdir="../meshes/" balanceinertia="true" discardvisual="false" />
  </mujoco>
  <link name="dummy_link" />
  <link name="base_link">
    <inertial>
      <origin xyz="-0.0185005 0.00031952 0.1929569" rpy="0 0 0" />
      <mass value="27.63993803" />
      <inertia ixx="0.93103133" ixy="0.00011763" ixz="-0.07210993" iyy="0.82590532" iyz="6.88e-06" izz="0.27686612" />
    </inertial>
    <visual>
      <origin xyz="0 0 0" rpy="0 0 0" />
      <geometry>
        <mesh filename="package://kuavo_assets/models/biped_s47/meshes/torso.STL" />
      </geometry>
      <material name="">
        <color rgba="1 1 1 1" />
      </material>
    </visual>
  </link>
  <joint name="dummy_to_base_link" type="fixed">
    <origin xyz="0 0 0" rpy="0 0 0" />
    <parent link="dummy_link" />
    <child link="base_link" />
    <dynamics damping="0.02" friction="0.02" />
  </joint>
  <link name="leg_l1_link">
    <inertial>
      <origin xyz="-0.00430148 -2.708e-05 -0.00851195" rpy="0 0 0" />
      <mass value="1.71093115" />
      <inertia ixx="0.00206092" ixy="1.97e-06" ixz="6.944e-05" iyy="0.00277274" iyz="-5.1e-06" izz="0.00370826" />
    </inertial>
    <visual>
      <origin xyz="0 0 0" rpy="0 0 0" />
      <geometry>
        <mesh filename="package://kuavo_assets/models/biped_s47/meshes/l_leg_roll.STL" />
      </geometry>
      <material name="">
        <color rgba="1 1 1 1" />
      </material>
    </visual>
  </link>
  <joint name="leg_l1_joint" type="revolute">
    <origin xyz="-0.0024999 0.087 -0.066" rpy="0 0 0" />
    <parent link="base_link" />
    <child link="leg_l1_link" />
    <axis xyz="1 0 0" />
    <limit lower="-0.314159265358979" upper="0.663225115757845" effort="127.0" velocity="10.46" />
    <dynamics damping="0.02" friction="0.02" />
  </joint>
  <link name="leg_l2_link">
    <inertial>
      <origin xyz="0.0 -0.00231118 -0.09062539" rpy="0 0 0" />
      <mass value="0.58029165" />
      <inertia ixx="0.00223984" ixy="0.0" ixz="3e-08" iyy="0.00123175" iyz="-6.98e-06" izz="0.00146391" />
    </inertial>
    <visual>
      <origin xyz="0 0 0" rpy="0 0 0" />
      <geometry>
        <mesh filename="package://kuavo_assets/models/biped_s47/meshes/l_leg_yaw.STL" />
      </geometry>
      <material name="">
        <color rgba="1 1 1 1" />
      </material>
    </visual>
  </link>
  <joint name="leg_l2_joint" type="revolute">
    <origin xyz="0 0 0" rpy="0 0 0" />
    <parent link="leg_l1_link" />
    <child link="leg_l2_link" />
    <axis xyz="0 0 1" />
    <limit lower="-0.872664625997165" upper="0.785398163397448" effort="22.2" velocity="10.46" />
    <dynamics damping="0.5" friction="0.0" />
  </joint>
  <link name="leg_l3_link">
    <inertial>
      <origin xyz="0.00150537 0.01199614 -0.08411619" rpy="0 0 0" />
      <mass value="4.50393141" />
      <inertia ixx="0.0389365" ixy="7.866e-05" ixz="0.00102086" iyy="0.03942609" iyz="0.00219138" izz="0.00999961" />
    </inertial>
    <visual>
      <origin xyz="0 0 0" rpy="0 0 0" />
      <geometry>
        <mesh filename="package://kuavo_assets/models/biped_s47/meshes/l_leg_pitch.STL" />
      </geometry>
      <material name="">
        <color rgba="1 1 1 1" />
      </material>
    </visual>
  </link>
  <joint name="leg_l3_joint" type="revolute">
    <origin xyz="0.000500354536093913 -0.00100000000000011 -0.1287" rpy="0 0 0" />
    <parent link="leg_l2_link" />
    <child link="leg_l3_link" />
    <axis xyz="0 1 0" />
    <limit lower="-2.00712863979348" upper="1.5707963267949" effort="72.0" velocity="20.93" />
    <dynamics damping="0.02" friction="0.02" />
  </joint>
  <link name="leg_l4_link">
    <inertial>
      <origin xyz="0.00696242 5.314e-05 -0.11549851" rpy="0 0 0" />
      <mass value="1.62776815" />
      <inertia ixx="0.01243912" ixy="-2.29e-06" ixz="5.881e-05" iyy="0.01229563" iyz="-2.895e-05" izz="0.00097937" />
    </inertial>
    <visual>
      <origin xyz="0 0 0" rpy="0 0 0" />
      <geometry>
        <mesh filename="package://kuavo_assets/models/biped_s47/meshes/l_knee.STL" />
      </geometry>
      <material name="">
        <color rgba="1 1 1 1" />
      </material>
    </visual>
  </link>
  <joint name="leg_l4_joint" type="revolute">
    <origin xyz="-6.87185435835039E-05 0 -0.284" rpy="0 0 0" />
    <parent link="leg_l3_link" />
    <child link="leg_l4_link" />
    <axis xyz="0 1 0" />
    <limit lower="0.0" upper="2.53072741539178" effort="135.0" velocity="11.62" />
    <dynamics damping="0.02" friction="0.02" />
  </joint>
  <link name="leg_l5_link">
    <inertial>
      <origin xyz="0.0 0.0 0.0" rpy="0 0 0" />
      <mass value="0.07193524" />
      <inertia ixx="6.92e-04" ixy="0.0" ixz="0.0" iyy="6.92e-04" iyz="0.0" izz="1.218e-04" />
    </inertial>
    <visual>
      <origin xyz="0 0 0" rpy="0 0 0" />
      <geometry>
        <mesh filename="package://kuavo_assets/models/biped_s47/meshes/l_foot_pitch.STL" />
      </geometry>
      <material name="">
        <color rgba="1 1 1 1" />
      </material>
    </visual>
  </link>
  <joint name="leg_l5_joint" type="revolute">
    <origin xyz="-0.000431635992531742 0 -0.346000000000001" rpy="0 0 0" />
    <parent link="leg_l4_link" />
    <child link="leg_l5_link" />
    <axis xyz="0 1 0" />
    <limit lower="-0.872664625997165" upper="0.349065850398866" effort="46.0" velocity="10.46" />
    <dynamics damping="0.02" friction="0.02" />
  </joint>
  <link name="leg_l6_link">
    <inertial>
      <origin xyz="0.03732754 -2.22e-06 -0.03883977" rpy="0 0 0" />
      <mass value="0.49861272" />
      <inertia ixx="0.00039242" ixy="3e-08" ixz="4.664e-05" iyy="0.00158655" iyz="0.0" izz="0.00172576" />
    </inertial>
    <visual>
      <origin xyz="0 0 0" rpy="0 0 0" />
      <geometry>
        <mesh filename="package://kuavo_assets/models/biped_s47/meshes/l_foot_roll.STL" />
      </geometry>
      <material name="">
        <color rgba="1 1 1 1" />
      </material>
    </visual>
  </link>
  <joint name="leg_l6_joint" type="revolute">
    <origin xyz="0 0 0" rpy="0 0 0" />
    <parent link="leg_l5_link" />
    <child link="leg_l6_link" />
    <axis xyz="1 0 0" />
    <limit lower="-0.261799387799149" upper="0.261799387799149" effort="30.0" velocity="10.46" />
    <dynamics damping="0.02" friction="0.02" />
  </joint>
  <link name="ll_foot_toe">
    <collision>
      <origin rpy="0 0 0" xyz="0 0 0" />
      <geometry>
        <sphere radius="0.005" />
      </geometry>
    </collision>
  </link>
  <joint name="ll_foot_toe_joint" type="fixed">
    <origin xyz="0.17084 0.04773 -0.0595" rpy="0 0 0" />
    <parent link="leg_l6_link" />
    <child link="ll_foot_toe" />
    <dynamics damping="0.02" friction="0.02" />
  </joint>
  <link name="ll_foot_heel">
    <collision>
      <origin rpy="0 0 0" xyz="0 0 0" />
      <geometry>
        <sphere radius="0.005" />
      </geometry>
    </collision>
  </link>
  <joint name="ll_foot_heel_joint" type="fixed">
    <origin xyz="-0.073164 0.04773 -0.0595" rpy="0 0 0" />
    <parent link="leg_l6_link" />
    <child link="ll_foot_heel" />
    <dynamics damping="0.02" friction="0.02" />
  </joint>
  <link name="lr_foot_toe">
    <collision>
      <origin rpy="0 0 0" xyz="0 0 0" />
      <geometry>
        <sphere radius="0.005" />
      </geometry>
    </collision>
  </link>
  <joint name="lr_foot_toe_joint" type="fixed">
    <origin xyz="0.17084 -0.04773 -0.0595" rpy="0 0 0" />
    <parent link="leg_l6_link" />
    <child link="lr_foot_toe" />
    <dynamics damping="0.02" friction="0.02" />
  </joint>
  <link name="lr_foot_heel">
    <collision>
      <origin rpy="0 0 0" xyz="0 0 0" />
      <geometry>
        <sphere radius="0.005" />
      </geometry>
    </collision>
  </link>
  <joint name="lr_foot_heel_joint" type="fixed">
    <origin xyz="-0.073164 -0.04773 -0.0595" rpy="0 0 0" />
    <parent link="leg_l6_link" />
    <child link="lr_foot_heel" />
    <dynamics damping="0.02" friction="0.02" />
  </joint>
  <link name="l_foot_toe">
    <collision>
      <origin rpy="0 0 0" xyz="0 0 0" />
      <geometry>
        <sphere radius="0.005" />
      </geometry>
    </collision>
  </link>
  <joint name="l_foot_toe_joint" type="fixed">
    <origin xyz="0.0 -0.04773 -0.0595" rpy="0 0 0" />
    <parent link="leg_l6_link" />
    <child link="l_foot_toe" />
    <dynamics damping="0.02" friction="0.02" />
  </joint>
  <link name="l_foot_heel">
    <collision>
      <origin rpy="0 0 0" xyz="0 0 0" />
      <geometry>
        <sphere radius="0.005" />
      </geometry>
    </collision>
  </link>
  <joint name="l_foot_heel_joint" type="fixed">
    <origin xyz="-0.0 0.04773 -0.0595" rpy="0 0 0" />
    <parent link="leg_l6_link" />
    <child link="l_foot_heel" />
    <dynamics damping="0.02" friction="0.02" />
  </joint>
  <link name="leg_r1_link">
    <inertial>
      <origin xyz="-0.00430146 2.709e-05 -0.00851195" rpy="0 0 0" />
      <mass value="1.71093008" />
      <inertia ixx="0.00206092" ixy="-1.97e-06" ixz="6.944e-05" iyy="0.00277274" iyz="5.1e-06" izz="0.00370826" />
    </inertial>
    <visual>
      <origin xyz="0 0 0" rpy="0 0 0" />
      <geometry>
        <mesh filename="package://kuavo_assets/models/biped_s47/meshes/r_leg_roll.STL" />
      </geometry>
      <material name="">
        <color rgba="1 1 1 1" />
      </material>
    </visual>
  </link>
  <joint name="leg_r1_joint" type="revolute">
    <origin xyz="-0.0024999 -0.087 -0.066" rpy="0 0 0" />
    <parent link="base_link" />
    <child link="leg_r1_link" />
    <axis xyz="1 0 0" />
    <limit lower="-0.663225115757845" upper="0.314159265358979" effort="127.0" velocity="10.46" />
    <dynamics damping="0.02" friction="0.02" />
  </joint>
  <link name="leg_r2_link">
    <inertial>
      <origin xyz="0.0 0.00231118 -0.09062539" rpy="0 0 0" />
      <mass value="0.58029165" />
      <inertia ixx="0.00223984" ixy="0.0" ixz="-3e-08" iyy="0.00123175" iyz="6.98e-06" izz="0.00146391" />
    </inertial>
    <visual>
      <origin xyz="0 0 0" rpy="0 0 0" />
      <geometry>
        <mesh filename="package://kuavo_assets/models/biped_s47/meshes/r_leg_yaw.STL" />
      </geometry>
      <material name="">
        <color rgba="1 1 1 1" />
      </material>
    </visual>
  </link>
  <joint name="leg_r2_joint" type="revolute">
    <origin xyz="0 0 0" rpy="0 0 0" />
    <parent link="leg_r1_link" />
    <child link="leg_r2_link" />
    <axis xyz="0 0 1" />
    <limit lower="-0.785398163397448" upper="0.872664625997165" effort="22.2" velocity="10.46" />
    <dynamics damping="0.5" friction="0.0" />
  </joint>
  <link name="leg_r3_link">
    <inertial>
      <origin xyz="0.00208315 -0.01199644 -0.08411379" rpy="0 0 0" />
      <mass value="4.50385993" />
      <inertia ixx="0.03893478" ixy="-7.792e-05" ixz="0.00103064" iyy="0.03942522" iyz="-0.00219154" izz="0.01000016" />
    </inertial>
    <visual>
      <origin xyz="0 0 0" rpy="0 0 0" />
      <geometry>
        <mesh filename="package://kuavo_assets/models/biped_s47/meshes/r_leg_pitch.STL" />
      </geometry>
      <material name="">
        <color rgba="1 1 1 1" />
      </material>
    </visual>
  </link>
  <joint name="leg_r3_joint" type="revolute">
    <origin xyz="-4.88006581312577E-05 0 -0.1287" rpy="0 0 0" />
    <parent link="leg_r2_link" />
    <child link="leg_r3_link" />
    <axis xyz="0 1 0" />
    <limit lower="-2.00712863979348" upper="1.5707963267949" effort="72.0" velocity="20.93" />
    <dynamics damping="0.02" friction="0.02" />
  </joint>
  <link name="leg_r4_link">
    <inertial>
      <origin xyz="0.00743231 -5.343e-05 -0.11558701" rpy="0 0 0" />
      <mass value="1.62655699" />
      <inertia ixx="0.01241258" ixy="2.28e-06" ixz="6.289e-05" iyy="0.0122692" iyz="2.902e-05" izz="0.00097927" />
    </inertial>
    <visual>
      <origin xyz="0 0 0" rpy="0 0 0" />
      <geometry>
        <mesh filename="package://kuavo_assets/models/biped_s47/meshes/r_knee.STL" />
      </geometry>
      <material name="">
        <color rgba="1 1 1 1" />
      </material>
    </visual>
  </link>
  <joint name="leg_r4_joint" type="revolute">
    <origin xyz="0.000147138572785148 0 -0.283999982974744" rpy="0 0 0" />
    <parent link="leg_r3_link" />
    <child link="leg_r4_link" />
    <axis xyz="0 1 0" />
    <limit lower="0.0" upper="2.53072741539178" effort="135.0" velocity="11.62" />
    <dynamics damping="0.02" friction="0.02" />
  </joint>
  <link name="leg_r5_link">
    <inertial>
      <origin xyz="0.0 0.0 0.0" rpy="0 0 0" />
      <mass value="0.07193524" />
      <inertia ixx="6.92e-04" ixy="0.0" ixz="0.0" iyy="6.92e-04" iyz="0.0" izz="1.218e-04" />
    </inertial>
    <visual>
      <origin xyz="0 0 0" rpy="0 0 0" />
      <geometry>
        <mesh filename="package://kuavo_assets/models/biped_s47/meshes/r_foot_pitch.STL" />
      </geometry>
      <material name="">
        <color rgba="1 1 1 1" />
      </material>
    </visual>
  </link>
  <joint name="leg_r5_joint" type="revolute">
    <origin xyz="0.000119806050928577 0 -0.345999979257963" rpy="0 0 0" />
    <parent link="leg_r4_link" />
    <child link="leg_r5_link" />
    <axis xyz="0 1 0" />
    <limit lower="-0.872664625997165" upper="0.349065850398866" effort="46.0" velocity="10.46" />
    <dynamics damping="0.02" friction="0.02" />
  </joint>
  <link name="leg_r6_link">
    <inertial>
      <origin xyz="0.03734098 -2.22e-06 -0.03882684" rpy="0 0 0" />
      <mass value="0.49861272" />
      <inertia ixx="0.00039238" ixy="3e-08" ixz="4.618e-05" iyy="0.00158655" iyz="0.0" izz="0.00172579" />
    </inertial>
    <visual>
      <origin xyz="0 0 0" rpy="0 0 0" />
      <geometry>
        <mesh filename="package://kuavo_assets/models/biped_s47/meshes/r_foot_roll.STL" />
      </geometry>
      <material name="">
        <color rgba="1 1 1 1" />
      </material>
    </visual>
  </link>
  <joint name="leg_r6_joint" type="revolute">
    <origin xyz="0 0 0" rpy="0 0 0" />
    <parent link="leg_r5_link" />
    <child link="leg_r6_link" />
    <axis xyz="1 0 0" />
    <limit lower="-0.261799387799149" upper="0.261799387799149" effort="30.0" velocity="10.46" />
    <dynamics damping="0.02" friction="0.02" />
  </joint>
  <link name="rl_foot_toe">
    <collision>
      <origin rpy="0 0 0" xyz="0 0 0" />
      <geometry>
        <sphere radius="0.005" />
      </geometry>
    </collision>
  </link>
  <joint name="rl_foot_toe_joint" type="fixed">
    <origin xyz="0.17084 0.04773 -0.0595" rpy="0 0 0" />
    <parent link="leg_r6_link" />
    <child link="rl_foot_toe" />
    <dynamics damping="0.02" friction="0.02" />
  </joint>
  <link name="rl_foot_heel">
    <collision>
      <origin rpy="0 0 0" xyz="0 0 0" />
      <geometry>
        <sphere radius="0.005" />
      </geometry>
    </collision>
  </link>
  <joint name="rl_foot_heel_joint" type="fixed">
    <origin xyz="-0.073164 0.04773 -0.0595" rpy="0 0 0" />
    <parent link="leg_r6_link" />
    <child link="rl_foot_heel" />
    <dynamics damping="0.02" friction="0.02" />
  </joint>
  <link name="rr_foot_toe">
    <collision>
      <origin rpy="0 0 0" xyz="0 0 0" />
      <geometry>
        <sphere radius="0.005" />
      </geometry>
    </collision>
  </link>
  <joint name="rr_foot_toe_joint" type="fixed">
    <origin xyz="0.17084 -0.04773 -0.0595" rpy="0 0 0" />
    <parent link="leg_r6_link" />
    <child link="rr_foot_toe" />
    <dynamics damping="0.02" friction="0.02" />
  </joint>
  <link name="rr_foot_heel">
    <collision>
      <origin rpy="0 0 0" xyz="0 0 0" />
      <geometry>
        <sphere radius="0.005" />
      </geometry>
    </collision>
  </link>
  <joint name="rr_foot_heel_joint" type="fixed">
    <origin xyz="-0.073164 -0.04773 -0.0595" rpy="0 0 0" />
    <parent link="leg_r6_link" />
    <child link="rr_foot_heel" />
    <dynamics damping="0.02" friction="0.02" />
  </joint>
  <link name="r_foot_toe">
    <collision>
      <origin rpy="0 0 0" xyz="0 0 0" />
      <geometry>
        <sphere radius="0.005" />
      </geometry>
    </collision>
  </link>
  <joint name="r_foot_toe_joint" type="fixed">
    <origin xyz="0.0 -0.04773 -0.0595" rpy="0 0 0" />
    <parent link="leg_r6_link" />
    <child link="r_foot_toe" />
    <dynamics damping="0.02" friction="0.02" />
  </joint>
  <link name="r_foot_heel">
    <collision>
      <origin rpy="0 0 0" xyz="0 0 0" />
      <geometry>
        <sphere radius="0.005" />
      </geometry>
    </collision>
  </link>
  <joint name="r_foot_heel_joint" type="fixed">
    <origin xyz="-0.0 0.04773 -0.0595" rpy="0 0 0" />
    <parent link="leg_r6_link" />
    <child link="r_foot_heel" />
    <dynamics damping="0.02" friction="0.02" />
  </joint>
  <link name="zarm_l1_link">
    <inertial>
      <origin xyz="0.00194934 -0.01222074 -0.00024523" rpy="0 0 0" />
      <mass value="0.95200000" />
      <inertia ixx="0.00177952" ixy="-0.00003936" ixz="-0.00000075" iyy="0.00088093" iyz="0.00000096" izz="0.00174476" />
    </inertial>
    <visual>
      <origin xyz="0 0 0" rpy="0 0 0" />
      <geometry>
        <mesh filename="package://kuavo_assets/models/biped_s47/meshes/l_arm_pitch.STL" />
      </geometry>
      <material name="">
        <color rgba="1 1 1 1" />
      </material>
    </visual>
  </link>
  <joint name="zarm_l1_joint" type="revolute">
    <origin xyz="-0.017499853 0.29269999999999996 0.4245" rpy="0 0 0" />
    <parent link="base_link" />
    <child link="zarm_l1_link" />
    <axis xyz="0 1 0" />
    <limit lower="-3.14159265358979" upper="1.5707963267949" effort="66.67" velocity="18.8" />
    <dynamics damping="0.02" friction="0.02" />
  </joint>
  <link name="zarm_l2_link">
    <inertial>
      <origin xyz="-0.00112901 0.00000665 -0.04637050" rpy="0 0 0" />
      <mass value="0.38500000" />
      <inertia ixx="0.00080437" ixy="-0.00000011" ixz="-0.00001699" iyy="0.00115579" iyz="-0.00000014" izz="0.00070010" />
    </inertial>
    <visual>
      <origin xyz="0 0 0" rpy="0 0 0" />
      <geometry>
        <mesh filename="package://kuavo_assets/models/biped_s47/meshes/l_arm_roll.STL" />
      </geometry>
      <material name="">
        <color rgba="1 1 1 1" />
      </material>
    </visual>
  </link>
  <joint name="zarm_l2_joint" type="revolute">
    <origin xyz="0 0 0" rpy="0 0 0" />
    <parent link="zarm_l1_link" />
    <child link="zarm_l2_link" />
    <axis xyz="1 0 0" />
    <limit lower="-0.349065850398866" upper="2.0943951023932" effort="75.0" velocity="8.0" />
    <dynamics damping="0.02" friction="0.02" />
  </joint>
  <link name="zarm_l3_link">
    <inertial>
      <origin xyz="0.00936999 0.00334408 -0.22965779" rpy="0 0 0" />
      <mass value="1.75450000" />
      <inertia ixx="0.00694471" ixy="-0.00006963" ixz="0.00081484" iyy="0.00704370" iyz="0.00033391" izz="0.00183829" />
    </inertial>
    <visual>
      <origin xyz="0 0 0" rpy="0 0 0" />
      <geometry>
        <mesh filename="package://kuavo_assets/models/biped_s47/meshes/l_arm_yaw.STL" />
      </geometry>
      <material name="">
        <color rgba="1 1 1 1" />
      </material>
    </visual>
  </link>
  <joint name="zarm_l3_joint" type="revolute">
    <origin xyz="0 0 0" rpy="0 0 0" />
    <parent link="zarm_l2_link" />
    <child link="zarm_l3_link" />
    <axis xyz="0 0 1" />
    <limit lower="-1.5707963267949" upper="1.5707963267949" effort="57.0" velocity="7.5" />
    <dynamics damping="0.02" friction="0.02" />
  </joint>
  <link name="zarm_l4_link">
    <inertial>
      <origin xyz="-0.01825634 0.00149605 -0.06877688" rpy="0 0 0" />
      <mass value="0.60780000" />
      <inertia ixx="0.00144524" ixy="-0.00000754" ixz="-0.00012207" iyy="0.00125753" iyz="-0.00003303" izz="0.00065063" />
    </inertial>
    <visual>
      <origin xyz="0 0 0" rpy="0 0 0" />
      <geometry>
        <mesh filename="package://kuavo_assets/models/biped_s47/meshes/l_forearm.STL" />
      </geometry>
      <material name="">
        <color rgba="1 1 1 1" />
      </material>
    </visual>
  </link>
  <joint name="zarm_l4_joint" type="revolute">
    <origin xyz="0.0200000000000006 0 -0.283699999999996" rpy="0 0 0" />
    <parent link="zarm_l3_link" />
    <child link="zarm_l4_link" />
    <axis xyz="0 1 0" />
    <limit lower="-2.61799387799149" upper="0.0" effort="75.0" velocity="8.0" />
    <dynamics damping="0.02" friction="0.02" />
  </joint>
  <link name="zarm_l5_link">
    <inertial>
      <origin xyz="-0.00874165 -0.00001372 -0.05033323" rpy="0 0 0" />
      <mass value="0.63690000" />
      <inertia ixx="0.00063700" ixy="-0.00000007" ixz="-0.00005666" iyy="0.00094941" iyz="0.00000002" izz="0.00054303" />
    </inertial>
    <visual>
      <origin xyz="0 0 0" rpy="0 0 0" />
      <geometry>
        <mesh filename="package://kuavo_assets/models/biped_s47/meshes/l_hand_yaw.STL" />
      </geometry>
      <material name="">
        <color rgba="1 1 1 1" />
      </material>
    </visual>
  </link>
  <joint name="zarm_l5_joint" type="revolute">
    <origin xyz="-0.0200000000000025 0 -0.127037274261591" rpy="0 0 0" />
    <parent link="zarm_l4_link" />
    <child link="zarm_l5_link" />
    <axis xyz="0 0 1" />
    <limit lower="-1.5707963267949" upper="1.5707963267949" effort="14.1" velocity="17.5" />
    <dynamics damping="0.02" friction="0.02" />
  </joint>
  <link name="zarm_l6_link">
    <inertial>
      <origin xyz="-0.00158864 0.00654094 -0.01506679" rpy="0 0 0" />
      <mass value="0.47390000" />
      <inertia ixx="0.00018068" ixy="-0.00000464" ixz="0.00001148" iyy="0.00025494" iyz="0.00001047" izz="0.00026772" />
    </inertial>
    <visual>
      <origin xyz="0 0 0" rpy="0 0 0" />
      <geometry>
        <mesh filename="package://kuavo_assets/models/biped_s47/meshes/l_hand_roll.STL" />
      </geometry>
      <material name="">
        <color rgba="1 1 1 1" />
      </material>
    </visual>
  </link>
  <joint name="zarm_l6_joint" type="revolute">
    <origin xyz="0.000199999999999079 0 -0.106462725738415" rpy="0 0 0" />
    <parent link="zarm_l5_link" />
    <child link="zarm_l6_link" />
    <axis xyz="1 0 0" />
    <limit lower="-1.30899693899575" upper="0.698131700797732" effort="14.1" velocity="17.5" />
    <dynamics damping="0.02" friction="0.02" />
  </joint>
  <link name="zarm_l7_link">
    <inertial>
      <origin xyz="0.00186 0.01014 -0.09044" rpy="0 0 0" />
      <mass value="0.64" />
      <inertia ixx="0.00071" ixy="1e-05" ixz="2e-05" iyy="0.0007" iyz="-4e-05" izz="0.00012" />
    </inertial>
    <visual>
      <origin xyz="0 0 0" rpy="0 0 0" />
      <geometry>
        <mesh filename="package://kuavo_assets/models/biped_s47/meshes/l_hand_pitch.STL" />
      </geometry>
      <material name="">
        <color rgba="1 1 1 1" />
      </material>
    </visual>
  </link>
  <joint name="zarm_l7_joint" type="revolute">
    <origin xyz="0 0 -0.0210004653879916" rpy="0 0 0" />
    <parent link="zarm_l6_link" />
    <child link="zarm_l7_link" />
    <axis xyz="0 1 0" />
    <limit lower="-0.698131700797732" upper="0.698131700797732" effort="14.1" velocity="17.5" />
    <dynamics damping="0.02" friction="0.02" />
  </joint>
  <link name="zarm_l7_end_effector">
    <collision>
      <origin rpy="0 0 0" xyz="0 0 0" />
      <geometry>
        <sphere radius="0.005" />
      </geometry>
    </collision>
  </link>
  <joint name="zarm_l7_end_effector_joint" type="fixed">
    <origin xyz="0 -0.03 -0.17" rpy="0 0 0" />
    <parent link="zarm_l7_link" />
    <child link="zarm_l7_end_effector" />
  </joint>
  <link name="l_f_claw_1">
    <inertial>
      <origin xyz="0.00725 1e-05 -0.01052" rpy="0 0 0" />
      <mass value="0.045" />
      <inertia ixx="1e-05" ixy="0.0" ixz="0.0" iyy="1e-05" iyz="0.0" izz="1e-05" />
    </inertial>
    <visual>
      <origin xyz="0 0 0" rpy="0 0 0" />
      <geometry>
        <mesh filename="package://kuavo_assets/models/biped_s47/meshes/l_f_claw_1.STL" />
      </geometry>
      <material name="">
        <color rgba="1 1 1 1" />
      </material>
    </visual>
  </link>
  <joint name="l_f_claw_1" type="fixed">
    <origin xyz="0.0220000003906073 0 -0.111399999999999" rpy="0 0 0" />
    <parent link="zarm_l7_link" />
    <child link="l_f_claw_1" />
    <axis xyz="0 1 0" />
    <limit lower="-0.698" upper="0.698" effort="0" velocity="0" />
  </joint>
  <link name="l_f_claw_2">
    <inertial>
      <origin xyz="-0.00783 0.0 -0.01475" rpy="0 0 0" />
      <mass value="0.009" />
      <inertia ixx="1e-05" ixy="0.0" ixz="0.0" iyy="1e-05" iyz="0.0" izz="1e-05" />
    </inertial>
    <visual>
      <origin xyz="0 0 0" rpy="0 0 0" />
      <geometry>
        <mesh filename="package://kuavo_assets/models/biped_s47/meshes/l_f_claw_2.STL" />
      </geometry>
      <material name="">
        <color rgba="1 1 1 1" />
      </material>
    </visual>
  </link>
  <joint name="l_f_claw_2" type="fixed">
    <origin xyz="0.025438097941138 0 -0.0464962705293307" rpy="0 0 0" />
    <parent link="l_f_claw_1" />
    <child link="l_f_claw_2" />
    <axis xyz="0 1 0" />
  </joint>
  <link name="l_f_finger">
    <inertial>
      <origin xyz="-0.01551 -1e-05 -0.01331" rpy="0 0 0" />
      <mass value="0.014" />
      <inertia ixx="1e-05" ixy="0.0" ixz="0.0" iyy="1e-05" iyz="0.0" izz="1e-05" />
    </inertial>
    <visual>
      <origin xyz="0 0 0" rpy="0 0 0" />
      <geometry>
        <mesh filename="package://kuavo_assets/models/biped_s47/meshes/l_f_finger.STL" />
      </geometry>
      <material name="">
        <color rgba="1 1 1 1" />
      </material>
    </visual>
  </link>
  <joint name="l_f_finger" type="fixed">
    <origin xyz="-0.0191548518271909 0 -0.0292932014550821" rpy="0 0 0" />
    <parent link="l_f_claw_2" />
    <child link="l_f_finger" />
    <axis xyz="0 1 0" />
  </joint>
  <link name="l_f_claw_3">
    <inertial>
      <origin xyz="-0.00169 -6e-05 -0.02723" rpy="0 0 0" />
      <mass value="0.013" />
      <inertia ixx="1e-05" ixy="0.0" ixz="0.0" iyy="1e-05" iyz="0.0" izz="1e-05" />
    </inertial>
    <visual>
      <origin xyz="0 0 0" rpy="0 0 0" />
      <geometry>
        <mesh filename="package://kuavo_assets/models/biped_s47/meshes/l_f_claw_3.STL" />
      </geometry>
      <material name="">
        <color rgba="1 1 1 1" />
      </material>
    </visual>
  </link>
  <joint name="l_f_claw_3" type="fixed">
    <origin xyz="0.0239578932739072 0 -0.135271672920607" rpy="0 0 0" />
    <parent link="zarm_l7_link" />
    <child link="l_f_claw_3" />
    <axis xyz="0 1 0" />
  </joint>
  <link name="l_b_claw_1">
    <inertial>
      <origin xyz="0.00725 1e-05 -0.01052" rpy="0 0 0" />
      <mass value="0.045" />
      <inertia ixx="1e-05" ixy="0.0" ixz="0.0" iyy="1e-05" iyz="0.0" izz="1e-05" />
    </inertial>
    <visual>
      <origin xyz="0 0 0" rpy="0 0 0" />
      <geometry>
        <mesh filename="package://kuavo_assets/models/biped_s47/meshes/l_b_claw_1.STL" />
      </geometry>
      <material name="">
        <color rgba="1 1 1 1" />
      </material>
    </visual>
  </link>
  <joint name="l_b_claw_1" type="fixed">
    <origin xyz="-0.0219999996097237 0 -0.1114" rpy="0 0 0" />
    <parent link="zarm_l7_link" />
    <child link="l_b_claw_1" />
    <axis xyz="0 1 0" />
  </joint>
  <link name="l_b_claw_2">
    <inertial>
      <origin xyz="-0.00783 0.0 -0.01475" rpy="0 0 0" />
      <mass value="0.009" />
      <inertia ixx="1e-05" ixy="0.0" ixz="0.0" iyy="1e-05" iyz="0.0" izz="1e-05" />
    </inertial>
    <visual>
      <origin xyz="0 0 0" rpy="0 0 0" />
      <geometry>
        <mesh filename="package://kuavo_assets/models/biped_s47/meshes/l_b_claw_2.STL" />
      </geometry>
      <material name="">
        <color rgba="1 1 1 1" />
      </material>
    </visual>
  </link>
  <joint name="l_b_claw_2" type="fixed">
    <origin xyz="-0.0254380979411351 0 -0.0464962705293328" rpy="0 0 0" />
    <parent link="l_b_claw_1" />
    <child link="l_b_claw_2" />
    <axis xyz="0 1 0" />
  </joint>
  <link name="l_b_finger">
    <inertial>
      <origin xyz="0.01551 1e-05 -0.01331" rpy="0 0 0" />
      <mass value="0.014" />
      <inertia ixx="1e-05" ixy="0.0" ixz="0.0" iyy="1e-05" iyz="0.0" izz="1e-05" />
    </inertial>
    <visual>
      <origin xyz="0 0 0" rpy="0 0 0" />
      <geometry>
        <mesh filename="package://kuavo_assets/models/biped_s47/meshes/l_b_finger.STL" />
      </geometry>
      <material name="">
        <color rgba="1 1 1 1" />
      </material>
    </visual>
  </link>
  <joint name="l_b_finger" type="fixed">
    <origin xyz="0.0191548518271917 0 -0.0292932014550803" rpy="0 0 0" />
    <parent link="l_b_claw_2" />
    <child link="l_b_finger" />
    <axis xyz="0 1 0" />
  </joint>
  <link name="l_b_claw_3">
    <inertial>
      <origin xyz="-0.00169 -6e-05 -0.02723" rpy="0 0 0" />
      <mass value="0.013" />
      <inertia ixx="1e-05" ixy="0.0" ixz="0.0" iyy="1e-05" iyz="0.0" izz="1e-05" />
    </inertial>
    <visual>
      <origin xyz="0 0 0" rpy="0 0 0" />
      <geometry>
        <mesh filename="package://kuavo_assets/models/biped_s47/meshes/l_b_claw_3.STL" />
      </geometry>
      <material name="">
        <color rgba="1 1 1 1" />
      </material>
    </visual>
  </link>
  <joint name="l_b_claw_3" type="fixed">
    <origin xyz="-0.0239578924930216 0 -0.135271672920607" rpy="0 0 0" />
    <parent link="zarm_l7_link" />
    <child link="l_b_claw_3" />
    <axis xyz="0 1 0" />
  </joint>
  <link name="zarm_r1_link">
    <inertial>
      <origin xyz="0.00194934 0.01222074 -0.00024523" rpy="0 0 0" />
      <mass value="0.95200000" />
      <inertia ixx="0.00177952" ixy="0.00003936" ixz="-0.00000075" iyy="0.00088093" iyz="-0.00000096" izz="0.00174476" />
    </inertial>
    <visual>
      <origin xyz="0 0 0" rpy="0 0 0" />
      <geometry>
        <mesh filename="package://kuavo_assets/models/biped_s47/meshes/r_arm_pitch.STL" />
      </geometry>
      <material name="">
        <color rgba="1 1 1 1" />
      </material>
    </visual>
  </link>
  <joint name="zarm_r1_joint" type="revolute">
    <origin xyz="-0.017499853 -0.29269999999999996 0.4245" rpy="0 0 0" />
    <parent link="base_link" />
    <child link="zarm_r1_link" />
    <axis xyz="0 1 0" />
    <limit lower="-3.14159265358979" upper="1.5707963267949" effort="66.67" velocity="18.8" />
    <dynamics damping="0.02" friction="0.02" />
  </joint>
  <link name="zarm_r2_link">
    <inertial>
      <origin xyz="-0.00112901 -0.00000665 -0.04637050" rpy="0 0 0" />
      <mass value="0.38500000" />
      <inertia ixx="0.00080437" ixy="0.00000011" ixz="-0.00001699" iyy="0.00115579" iyz="0.00000014" izz="0.00070010" />
    </inertial>
    <visual>
      <origin xyz="0 0 0" rpy="0 0 0" />
      <geometry>
        <mesh filename="package://kuavo_assets/models/biped_s47/meshes/r_arm_roll.STL" />
      </geometry>
      <material name="">
        <color rgba="1 1 1 1" />
      </material>
    </visual>
  </link>
  <joint name="zarm_r2_joint" type="revolute">
    <origin xyz="0 0 0" rpy="0 0 0" />
    <parent link="zarm_r1_link" />
    <child link="zarm_r2_link" />
    <axis xyz="1 0 0" />
    <limit lower="-2.0943951023932" upper="0.349065850398866" effort="75.0" velocity="8.0" />
    <dynamics damping="0.02" friction="0.02" />
  </joint>
  <link name="zarm_r3_link">
    <inertial>
      <origin xyz="0.00936999 -0.00334408 -0.22965779" rpy="0 0 0" />
      <mass value="1.75450000" />
      <inertia ixx="0.00694471" ixy="0.00006963" ixz="0.00081484" iyy="0.00704370" iyz="-0.00033391" izz="0.00183829" />
    </inertial>
    <visual>
      <origin xyz="0 0 0" rpy="0 0 0" />
      <geometry>
        <mesh filename="package://kuavo_assets/models/biped_s47/meshes/r_arm_yaw.STL" />
      </geometry>
      <material name="">
        <color rgba="1 1 1 1" />
      </material>
    </visual>
  </link>
  <joint name="zarm_r3_joint" type="revolute">
    <origin xyz="0 0 0" rpy="0 0 0" />
    <parent link="zarm_r2_link" />
    <child link="zarm_r3_link" />
    <axis xyz="0 0 1" />
    <limit lower="-1.5707963267949" upper="1.5707963267949" effort="57.0" velocity="7.5" />
    <dynamics damping="0.02" friction="0.02" />
  </joint>
  <link name="zarm_r4_link">
    <inertial>
      <origin xyz="-0.01825634 -0.00149605 -0.06877688" rpy="0 0 0" />
      <mass value="0.60780000" />
      <inertia ixx="0.00144524" ixy="0.00000754" ixz="-0.00012207" iyy="0.00125753" iyz="0.00003303" izz="0.00065063" />
    </inertial>
    <visual>
      <origin xyz="0 0 0" rpy="0 0 0" />
      <geometry>
        <mesh filename="package://kuavo_assets/models/biped_s47/meshes/r_forearm.STL" />
      </geometry>
      <material name="">
        <color rgba="1 1 1 1" />
      </material>
    </visual>
  </link>
  <joint name="zarm_r4_joint" type="revolute">
    <origin xyz="0.0200000000000024 0 -0.2837" rpy="0 0 0" />
    <parent link="zarm_r3_link" />
    <child link="zarm_r4_link" />
    <axis xyz="0 1 0" />
    <limit lower="-2.61799387799149" upper="0.0" effort="75.0" velocity="8.0" />
    <dynamics damping="0.02" friction="0.02" />
  </joint>
  <link name="zarm_r5_link">
    <inertial>
      <origin xyz="-0.00874165 0.00001372 -0.05033323" rpy="0 0 0" />
      <mass value="0.63690000" />
      <inertia ixx="0.00063700" ixy="0.00000007" ixz="-0.00005666" iyy="0.00094941" iyz="-0.00000002" izz="0.00054303" />
    </inertial>
    <visual>
      <origin xyz="0 0 0" rpy="0 0 0" />
      <geometry>
        <mesh filename="package://kuavo_assets/models/biped_s47/meshes/r_hand_yaw.STL" />
      </geometry>
      <material name="">
        <color rgba="1 1 1 1" />
      </material>
    </visual>
  </link>
  <joint name="zarm_r5_joint" type="revolute">
    <origin xyz="-0.0200000000000001 0 -0.127037274261587" rpy="0 0 0" />
    <parent link="zarm_r4_link" />
    <child link="zarm_r5_link" />
    <axis xyz="0 0 1" />
    <limit lower="-1.5707963267949" upper="1.5707963267949" effort="14.1" velocity="17.5" />
    <dynamics damping="0.02" friction="0.02" />
  </joint>
  <link name="zarm_r6_link">
    <inertial>
      <origin xyz="-0.00158864 -0.00654094 -0.01506679" rpy="0 0 0" />
      <mass value="0.47390000" />
      <inertia ixx="0.00018068" ixy="0.00000464" ixz="0.00001148" iyy="0.00025494" iyz="-0.00001047" izz="0.00026772" />
    </inertial>
    <visual>
      <origin xyz="0 0 0" rpy="0 0 0" />
      <geometry>
        <mesh filename="package://kuavo_assets/models/biped_s47/meshes/r_hand_roll.STL" />
      </geometry>
      <material name="">
        <color rgba="1 1 1 1" />
      </material>
    </visual>
  </link>
  <joint name="zarm_r6_joint" type="revolute">
    <origin xyz="0 0 -0.106462725738415" rpy="0 0 0" />
    <parent link="zarm_r5_link" />
    <child link="zarm_r6_link" />
    <axis xyz="1 0 0" />
    <limit lower="-0.698131700797732" upper="1.30899693899575" effort="14.1" velocity="17.5" />
    <dynamics damping="0.02" friction="0.02" />
  </joint>
  <link name="zarm_r7_link">
    <inertial>
      <origin xyz="0.00186 -0.01014 -0.09044" rpy="0 0 0" />
      <mass value="0.64" />
      <inertia ixx="0.00069" ixy="-1e-05" ixz="2e-05" iyy="0.00068" iyz="5e-05" izz="0.00012" />
    </inertial>
    <visual>
      <origin xyz="0 0 0" rpy="0 0 0" />
      <geometry>
        <mesh filename="package://kuavo_assets/models/biped_s47/meshes/r_hand_pitch.STL" />
      </geometry>
      <material name="">
        <color rgba="1 1 1 1" />
      </material>
    </visual>
  </link>
  <joint name="zarm_r7_joint" type="revolute">
    <origin xyz="0 0 -0.0209999999999999" rpy="0 0 0" />
    <parent link="zarm_r6_link" />
    <child link="zarm_r7_link" />
    <axis xyz="0 1 0" />
    <limit lower="-0.698131700797732" upper="0.698131700797732" effort="14.1" velocity="17.5" />
    <dynamics damping="0.02" friction="0.02" />
  </joint>
  <link name="zarm_r7_end_effector">
    <collision>
      <origin rpy="0 0 0" xyz="0 0 0" />
      <geometry>
        <sphere radius="0.005" />
      </geometry>
    </collision>
  </link>
  <joint name="zarm_r7_end_effector_joint" type="fixed">
    <origin xyz="0 0.03 -0.17" rpy="0 0 0" />
    <parent link="zarm_r7_link" />
    <child link="zarm_r7_end_effector" />
  </joint>
  <link name="r_f_claw_1">
    <inertial>
      <origin xyz="0.00725 0.00051 -0.01052" rpy="0 0 0" />
      <mass value="0.045" />
      <inertia ixx="1e-05" ixy="0.0" ixz="0.0" iyy="1e-05" iyz="0.0" izz="1e-05" />
    </inertial>
    <visual>
      <origin xyz="0 0 0" rpy="0 0 0" />
      <geometry>
        <mesh filename="package://kuavo_assets/models/biped_s47/meshes/r_f_claw_1.STL" />
      </geometry>
      <material name="">
        <color rgba="1 1 1 1" />
      </material>
    </visual>
  </link>
  <joint name="r_f_claw_1" type="fixed">
    <origin xyz="0.0219999996097342 -0.000500000000000958 -0.1114" rpy="0 0 0" />
    <parent link="zarm_r7_link" />
    <child link="r_f_claw_1" />
    <axis xyz="0 1 0" />
    <limit lower="-0.698" upper="0.698" effort="0" velocity="0" />
  </joint>
  <link name="r_f_claw_2">
    <inertial>
      <origin xyz="-0.00783 0.0005 -0.01475" rpy="0 0 0" />
      <mass value="0.0034" />
      <inertia ixx="1e-05" ixy="0.0" ixz="0.0" iyy="1e-05" iyz="0.0" izz="1e-05" />
    </inertial>
    <visual>
      <origin xyz="0 0 0" rpy="0 0 0" />
      <geometry>
        <mesh filename="package://kuavo_assets/models/biped_s47/meshes/r_f_claw_2.STL" />
      </geometry>
      <material name="">
        <color rgba="1 1 1 1" />
      </material>
    </visual>
  </link>
  <joint name="r_f_claw_2" type="fixed">
    <origin xyz="0.0254380979411394 0 -0.0464962705293306" rpy="0 0 0" />
    <parent link="r_f_claw_1" />
    <child link="r_f_claw_2" />
    <axis xyz="0 1 0" />
  </joint>
  <link name="r_f_finger">
    <inertial>
      <origin xyz="-0.01551 0.00079 -0.01331" rpy="0 0 0" />
      <mass value="0.014" />
      <inertia ixx="1e-05" ixy="0.0" ixz="0.0" iyy="1e-05" iyz="0.0" izz="1e-05" />
    </inertial>
    <visual>
      <origin xyz="0 0 0" rpy="0 0 0" />
      <geometry>
        <mesh filename="package://kuavo_assets/models/biped_s47/meshes/r_f_finger.STL" />
      </geometry>
      <material name="">
        <color rgba="1 1 1 1" />
      </material>
    </visual>
  </link>
  <joint name="r_f_finger" type="fixed">
    <origin xyz="-0.0191548518271941 0 -0.0292932014550819" rpy="0 0 0" />
    <parent link="r_f_claw_2" />
    <child link="r_f_finger" />
    <axis xyz="0 1 0" />
  </joint>
  <link name="r_f_claw_3">
    <inertial>
      <origin xyz="-0.00169 0.00044 -0.02723" rpy="0 0 0" />
      <mass value="0.013" />
      <inertia ixx="1e-05" ixy="0.0" ixz="0.0" iyy="1e-05" iyz="0.0" izz="1e-05" />
    </inertial>
    <visual>
      <origin xyz="0 0 0" rpy="0 0 0" />
      <geometry>
        <mesh filename="package://kuavo_assets/models/biped_s47/meshes/r_f_claw_3.STL" />
      </geometry>
      <material name="">
        <color rgba="1 1 1 1" />
      </material>
    </visual>
  </link>
  <joint name="r_f_claw_3" type="fixed">
    <origin xyz="0.023957892493034 -0.000500000000001166 -0.135271672920607" rpy="0 0 0" />
    <parent link="zarm_r7_link" />
    <child link="r_f_claw_3" />
    <axis xyz="0 1 0" />
  </joint>
  <link name="r_b_claw_1">
    <inertial>
      <origin xyz="-0.00725 0.00049 -0.01052" rpy="0 0 0" />
      <mass value="0.045" />
      <inertia ixx="1e-05" ixy="0.0" ixz="0.0" iyy="1e-05" iyz="0.0" izz="1e-05" />
    </inertial>
    <visual>
      <origin xyz="0 0 0" rpy="0 0 0" />
      <geometry>
        <mesh filename="package://kuavo_assets/models/biped_s47/meshes/r_b_claw_1.STL" />
      </geometry>
      <material name="">
        <color rgba="1 1 1 1" />
      </material>
    </visual>
  </link>
  <joint name="r_b_claw_1" type="fixed">
    <origin xyz="-0.022000000390599 -0.000500000000001402 -0.111399999999999" rpy="0 0 0" />
    <parent link="zarm_r7_link" />
    <child link="r_b_claw_1" />
    <axis xyz="0 1 0" />
  </joint>
  <link name="r_b_claw_2">
    <inertial>
      <origin xyz="0.00783 0.0005 -0.01475" rpy="0 0 0" />
      <mass value="0.009" />
      <inertia ixx="1e-05" ixy="0.0" ixz="0.0" iyy="1e-05" iyz="0.0" izz="1e-05" />
    </inertial>
    <visual>
      <origin xyz="0 0 0" rpy="0 0 0" />
      <geometry>
        <mesh filename="package://kuavo_assets/models/biped_s47/meshes/r_b_claw_2.STL" />
      </geometry>
      <material name="">
        <color rgba="1 1 1 1" />
      </material>
    </visual>
  </link>
  <joint name="r_b_claw_2" type="fixed">
    <origin xyz="-0.0254380979411353 0 -0.0464962705293326" rpy="0 0 0" />
    <parent link="r_b_claw_1" />
    <child link="r_b_claw_2" />
    <axis xyz="0 1 0" />
  </joint>
  <link name="r_b_finger">
    <inertial>
      <origin xyz="0.01551 0.00081 -0.01331" rpy="0 0 0" />
      <mass value="0.014" />
      <inertia ixx="1e-05" ixy="0.0" ixz="0.0" iyy="1e-05" iyz="0.0" izz="1e-05" />
    </inertial>
    <visual>
      <origin xyz="0 0 0" rpy="0 0 0" />
      <geometry>
        <mesh filename="package://kuavo_assets/models/biped_s47/meshes/r_b_finger.STL" />
      </geometry>
      <material name="">
        <color rgba="1 1 1 1" />
      </material>
    </visual>
  </link>
  <joint name="r_b_finger" type="fixed">
    <origin xyz="0.0191548518271923 0 -0.0292932014550809" rpy="0 0 0" />
    <parent link="r_b_claw_2" />
    <child link="r_b_finger" />
    <axis xyz="0 1 0" />
  </joint>
  <link name="r_b_claw_3">
    <inertial>
      <origin xyz="0.00169 0.00056 -0.02723" rpy="0 0 0" />
      <mass value="0.013" />
      <inertia ixx="1e-05" ixy="0.0" ixz="0.0" iyy="1e-05" iyz="0.0" izz="1e-05" />
    </inertial>
    <visual>
      <origin xyz="0 0 0" rpy="0 0 0" />
      <geometry>
        <mesh filename="package://kuavo_assets/models/biped_s47/meshes/r_b_claw_3.STL" />
      </geometry>
      <material name="">
        <color rgba="1 1 1 1" />
      </material>
    </visual>
  </link>
  <joint name="r_b_claw_3" type="fixed">
    <origin xyz="-0.0239578932738948 -0.000500000000001666 -0.135271672920607" rpy="0 0 0" />
    <parent link="zarm_r7_link" />
    <child link="r_b_claw_3" />
  </joint>
  <link name="zhead_1_link">
    <inertial>
      <origin xyz="2e-05 0.00605 -0.01052" rpy="0 0 0" />
      <mass value="0.35" />
      <inertia ixx="7e-05" ixy="0.0" ixz="0.0" iyy="5e-05" iyz="0.0" izz="5e-05" />
    </inertial>
    <visual>
      <origin xyz="0 0 0" rpy="0 0 0" />
      <geometry>
        <mesh filename="package://kuavo_assets/models/biped_s47/meshes/head_yaw.STL" />
      </geometry>
      <material name="">
        <color rgba="1 1 1 1" />
      </material>
    </visual>
  </link>
  <joint name="zhead_1_joint" type="revolute">
    <origin xyz="-0.018499853 0.0 0.6014" rpy="0 0 0" />
    <parent link="base_link" />
    <child link="zhead_1_link" />
    <axis xyz="0 0 1" />
    <limit lower="-1.5707963267949" upper="1.5707963267949" effort="1.5" velocity="5.23333333333333" />
    <dynamics damping="0.02" friction="0.02" />
  </joint>
  <link name="zhead_2_link">
    <inertial>
      <origin xyz="0.02648 -0.00142 0.10674" rpy="0 0 0" />
      <mass value="0.5492" />
      <inertia ixx="0.00346" ixy="-3e-05" ixz="0.00017" iyy="0.00348" iyz="-7e-05" izz="0.00222" />
    </inertial>
    <visual>
      <origin xyz="0 0 0" rpy="0 0 0" />
      <geometry>
        <mesh filename="package://kuavo_assets/models/biped_s47/meshes/head_pitch.STL" />
      </geometry>
      <material name="">
        <color rgba="1 1 1 1" />
      </material>
    </visual>
  </link>
  <joint name="zhead_2_joint" type="revolute">
    <origin xyz="0 0 0" rpy="0 0 0" />
    <parent link="zhead_1_link" />
    <child link="zhead_2_link" />
    <axis xyz="0 1 0" />
    <limit lower="-0.523598775598299" upper="0.523598775598299" effort="12.0" velocity="5.23333333333333" />
    <dynamics damping="0.02" friction="0.02" />
  </joint>
  <link name="camera">
    <inertial>
      <origin xyz="-0.04257 -0.01736 -0.01161" rpy="0 0 0" />
      <mass value="0.047" />
      <inertia ixx="0.00065" ixy="0.0" ixz="0.00015" iyy="0.00091" iyz="0.0" izz="0.00105" />
    </inertial>
    <visual>
      <origin xyz="0 0 0" rpy="0 0 0" />
      <geometry>
        <mesh filename="package://kuavo_assets/models/biped_s47/meshes/camera.STL" />
      </geometry>
      <material name="">
        <color rgba="1 1 1 1" />
      </material>
    </visual>
  </link>
  <joint name="camera" type="fixed">
    <origin xyz="0.0967509784707853 0.0175003248712456 0.125953265112721" rpy="0 0.488692190558413 0" />
    <parent link="zhead_2_link" />
    <child link="camera" />
    <dynamics damping="0.02" friction="0.02" />
  </joint>

  <link name="camera_base">
    <inertial>
      <origin xyz="0.00354055659132058 0.00140392784997684 0.0124511787517705" rpy="0 0 0" />
      <mass value="0.0170256015508834" />
      <inertia ixx="1.0918264029313E-05" ixy="1.05354408167889E-07" ixz="1.05871497323805E-08" iyy="8.57178950734466E-07" iyz="1.64018651463453E-08" izz="1.02869893338382E-05" />
    </inertial>
    <visual>
      <origin xyz="0 0 0" rpy="0 0 0" />
      <geometry>
        <mesh filename="package://kuavo_assets/models/biped_s47/meshes/camera_base.STL" />
      </geometry>
      <material name="">
        <color rgba="1 1 1 1" />
      </material>
    </visual>
    <collision>
      <origin xyz="0 0 0" rpy="0 0 0" />
      <geometry>
        <mesh filename="package://kuavo_assets/models/biped_s47/meshes/camera_base.STL" />
      </geometry>
    </collision>
  </link>
  <joint name="camera_base" type="fixed">
    <origin xyz="0.0828919080642966 0 0.119165137551254" rpy="0 0.488692190558416 0" />
    <parent link="zhead_2_link" />
    <child link="camera_base" />
  </joint>

  <link name="radar">
    <inertial>
      <origin xyz="-0.00018 1e-05 0.01777" rpy="0 0 0" />
      <mass value="0.2688" />
      <inertia ixx="0.00013" ixy="0.0" ixz="0.0" iyy="0.00014" iyz="0.0" izz="0.00014" />
    </inertial>
    <visual>
      <origin xyz="0 0 0" rpy="0 0 0" />
      <geometry>
        <mesh filename="package://kuavo_assets/models/biped_s47/meshes/radar.STL" />
      </geometry>
      <material name="">
        <color rgba="1 1 1 1" />
      </material>
    </visual>
  </link>
  <joint name="radar" type="fixed">
    <origin xyz="0.0217799337881943 0 0.105417258037133" rpy="0 0.229686043245049 0" />
    <parent link="zhead_2_link" />
    <child link="radar" />
    <dynamics damping="0.02" friction="0.02" />
  </joint>

  
  
  
  <gazebo>
    <plugin filename="libgazebo_ros_p3d.so" name="p3d_base_controller">
      <alwaysOn>true</alwaysOn>
      <updateRate>500.0</updateRate>
      <bodyName>base_link</bodyName>
      <topicName>ground_truth/state</topicName>
      <gaussianNoise>0</gaussianNoise>
      <frameName>world</frameName>
      <xyzOffsets>0 0 0</xyzOffsets>
      <rpyOffsets>0 0 0</rpyOffsets>
    </plugin>
  </gazebo>

  
  <gazebo reference="leg_l6_link">
    <mu1>1.5</mu1>
    <mu2>2.5</mu2>
    <self_collide>1</self_collide>
    <kp value="1000000.0" />
    <kd value="100.0" />
    <maxVel>3</maxVel>
    <minDepth>0.00</minDepth>
  </gazebo>
  <gazebo reference="l_foot_heel">
    <mu1>1.5</mu1>
    <mu2>2.5</mu2>
    <self_collide>1</self_collide>
    <kp value="1000000.0" />
    <kd value="100.0" />
    <maxVel>3</maxVel>
    <minDepth>0.00</minDepth>
  </gazebo>
  <gazebo reference="l_foot_toe">
    <mu1>1.5</mu1>
    <mu2>2.5</mu2>
    <self_collide>1</self_collide>
    <kp value="1000000.0" />
    <kd value="100.0" />
    <maxVel>3</maxVel>
    <minDepth>0.00</minDepth>
  </gazebo>
  <gazebo reference="lr_foot_heel">
    <mu1>1.5</mu1>
    <mu2>2.5</mu2>
    <self_collide>1</self_collide>
    <kp value="1000000.0" />
    <kd value="100.0" />
    <maxVel>3</maxVel>
    <minDepth>0.00</minDepth>
  </gazebo>
  <gazebo reference="lr_foot_toe">
    <mu1>1.5</mu1>
    <mu2>2.5</mu2>
    <self_collide>1</self_collide>
    <kp value="1000000.0" />
    <kd value="100.0" />
    <maxVel>3</maxVel>
    <minDepth>0.00</minDepth>
  </gazebo>
  <gazebo reference="ll_foot_heel">
    <mu1>1.5</mu1>
    <mu2>2.5</mu2>
    <self_collide>1</self_collide>
    <kp value="1000000.0" />
    <kd value="100.0" />
    <maxVel>3</maxVel>
    <minDepth>0.00</minDepth>
  </gazebo>
  <gazebo reference="ll_foot_toe">
    <mu1>1.5</mu1>
    <mu2>2.5</mu2>
    <self_collide>1</self_collide>
    <kp value="1000000.0" />
    <kd value="100.0" />
    <maxVel>3</maxVel>
    <minDepth>0.00</minDepth>
  </gazebo>

  
  <gazebo reference="leg_r6_link">
    <mu1>1.5</mu1>
    <mu2>2.5</mu2>
    <self_collide>1</self_collide>
    <kp value="1000000.0" />
    <kd value="100.0" />
    <maxVel>3</maxVel>
    <minDepth>0.00</minDepth>
  </gazebo>
  <gazebo reference="r_foot_heel">
    <mu1>1.5</mu1>
    <mu2>2.5</mu2>
    <self_collide>1</self_collide>
    <kp value="1000000.0" />
    <kd value="100.0" />
    <maxVel>3</maxVel>
    <minDepth>0.00</minDepth>
  </gazebo>
  <gazebo reference="r_foot_toe">
    <mu1>1.5</mu1>
    <mu2>2.5</mu2>
    <self_collide>1</self_collide>
    <kp value="1000000.0" />
    <kd value="100.0" />
    <maxVel>3</maxVel>
    <minDepth>0.00</minDepth>
  </gazebo>
  <gazebo reference="rl_foot_toe">
    <mu1>1.5</mu1>
    <mu2>2.5</mu2>
    <self_collide>1</self_collide>
    <kp value="1000000.0" />
    <kd value="100.0" />
    <maxVel>3</maxVel>
    <minDepth>0.00</minDepth>
  </gazebo>
  <gazebo reference="rl_foot_heel">
    <mu1>1.5</mu1>
    <mu2>2.5</mu2>
    <self_collide>1</self_collide>
    <kp value="1000000.0" />
    <kd value="100.0" />
    <maxVel>3</maxVel>
    <minDepth>0.00</minDepth>
  </gazebo>
  <gazebo reference="rr_foot_toe">
    <mu1>1.5</mu1>
    <mu2>2.5</mu2>
    <self_collide>1</self_collide>
    <kp value="1000000.0" />
    <kd value="100.0" />
    <maxVel>3</maxVel>
    <minDepth>0.00</minDepth>
  </gazebo>
  <gazebo reference="rr_foot_heel">
    <mu1>1.5</mu1>
    <mu2>2.5</mu2>
    <self_collide>1</self_collide>
    <kp value="1000000.0" />
    <kd value="100.0" />
    <maxVel>3</maxVel>
    <minDepth>0.00</minDepth>
  </gazebo>

  
  <gazebo>
    <plugin name="gazebo_shm_interface" filename="libgazebo_sim_shm_interface.so">
      
      <imu>
        <frame_id>dummy_link</frame_id>
      </imu>
      
      
      <joints>
        
        <joint><name>leg_l1_joint</name></joint>
        <joint><name>leg_l2_joint</name></joint>
        <joint><name>leg_l3_joint</name></joint>
        <joint><name>leg_l4_joint</name></joint>
        <joint><name>leg_l5_joint</name></joint>
        <joint><name>leg_l6_joint</name></joint>
        
        
        <joint><name>leg_r1_joint</name></joint>
        <joint><name>leg_r2_joint</name></joint>
        <joint><name>leg_r3_joint</name></joint>
        <joint><name>leg_r4_joint</name></joint>
        <joint><name>leg_r5_joint</name></joint>
        <joint><name>leg_r6_joint</name></joint>
        
        
        <joint><name>zarm_l1_joint</name></joint>
        <joint><name>zarm_l2_joint</name></joint>
        <joint><name>zarm_l3_joint</name></joint>
        <joint><name>zarm_l4_joint</name></joint>
        <joint><name>zarm_l5_joint</name></joint>
        <joint><name>zarm_l6_joint</name></joint>
        <joint><name>zarm_l7_joint</name></joint>
        
        
        <joint><name>zarm_r1_joint</name></joint>
        <joint><name>zarm_r2_joint</name></joint>
        <joint><name>zarm_r3_joint</name></joint>
        <joint><name>zarm_r4_joint</name></joint>
        <joint><name>zarm_r5_joint</name></joint>
        <joint><name>zarm_r6_joint</name></joint>
        <joint><name>zarm_r7_joint</name></joint>
        
        
        <joint><name>zhead_1_joint</name></joint>
        <joint><name>zhead_2_joint</name></joint>
      </joints>
      
      
      <contacts>
        <contact><link>ll_foot_toe</link></contact>
        <contact><link>ll_foot_heel</link></contact>
        <contact><link>lr_foot_toe</link></contact>
        <contact><link>lr_foot_heel</link></contact>
        <contact><link>rl_foot_toe</link></contact>
        <contact><link>rl_foot_heel</link></contact>
        <contact><link>rr_foot_toe</link></contact>
        <contact><link>rr_foot_heel</link></contact>
      </contacts>
      </plugin>
  </gazebo>
  
</robot>