<?xml version='1.0' encoding='utf-8'?>
<mujoco model="biped_s53">
  <compiler angle="radian" meshdir="../meshes/"/>
  <size njmax="500" nconmax="100" />
  <default>
    <joint limited="true" armature="0.05" damping="0.02" frictionloss="0.02"/>
    <motor ctrllimited="true" ctrlrange="-100 100"/>
    <!-- <geom contype="1" conaffinity="1" condim="1" solref="0.005 1"/> -->
    <equality solref="0.005 1"/>
    <default class="collision">
      <!-- User parameter for geoms is used to identify collision types -->
      <geom material="collision" contype="4" conaffinity="4" user="2" group="3" rgba="0.9 0.3 0.3 0.2"/>
      <default class="collision-left">
        <geom contype="1" conaffinity="2" group="3" rgba="0.3 0.9 0.3 0.2"/>
      </default>
      <default class="collision-right">
        <geom contype="2" conaffinity="1" group="3" rgba="0.3 0.3 0.9 0.2"/>
      </default>
    </default>
  </default>
  <asset>
    <texture type="skybox" builtin="gradient" rgb1="0.4 0.6 0.8" width="128" height="128"/>
    <texture name="grid" type="2d" builtin="checker" rgb1=".1 .2 .3" rgb2=".2 .3 .4" width="300" height="300"/>
    <material name="grid" texture="grid" texrepeat="8 8" reflectance=".1"/>
    <material name="collision" rgba="0.1 0.5 0.9 0"/>
    <mesh name="torso" file="torso.STL"/>
    <mesh name="waist_yaw" file="waist_yaw.STL"/>
    <mesh name="l_leg_roll" file="l_leg_roll.STL"/>
    <mesh name="l_leg_yaw" file="l_leg_yaw.STL"/>
    <mesh name="l_leg_pitch" file="l_leg_pitch.STL"/>
    <mesh name="l_knee" file="l_knee.STL"/>
    <mesh name="l_foot_pitch" file="l_foot_pitch.STL"/>
    <mesh name="l_foot_roll" file="l_foot_roll.STL"/>
    <mesh name="r_leg_roll" file="r_leg_roll.STL"/>
    <mesh name="r_leg_yaw" file="r_leg_yaw.STL"/>
    <mesh name="r_leg_pitch" file="r_leg_pitch.STL"/>
    <mesh name="r_knee" file="r_knee.STL"/>
    <mesh name="r_foot_pitch" file="r_foot_pitch.STL"/>
    <mesh name="r_foot_roll" file="r_foot_roll.STL"/>
    <mesh name="l_arm_pitch" file="l_arm_pitch.STL"/>
    <mesh name="l_arm_roll" file="l_arm_roll.STL"/>
    <mesh name="l_arm_yaw" file="l_arm_yaw.STL"/>
    <mesh name="l_forearm" file="l_forearm.STL"/>
    <mesh name="l_hand_yaw" file="l_hand_yaw.STL"/>
    <mesh name="l_hand_roll" file="l_hand_roll.STL"/>
    <mesh name="l_hand_pitch" file="l_hand_pitch.STL"/>
    <mesh name="l_hand_pitch_nohand" file="l_hand_pitch_nohand.STL"/>
    <mesh name="r_arm_pitch" file="r_arm_pitch.STL"/>
    <mesh name="r_arm_roll" file="r_arm_roll.STL"/>
    <mesh name="r_arm_yaw" file="r_arm_yaw.STL"/>
    <mesh name="r_forearm" file="r_forearm.STL"/>
    <mesh name="r_hand_yaw" file="r_hand_yaw.STL"/>
    <mesh name="r_hand_roll" file="r_hand_roll.STL"/>
    <mesh name="r_hand_pitch" file="r_hand_pitch.STL"/>
    <mesh name="r_hand_pitch_nohand" file="r_hand_pitch_nohand.STL"/>
    <mesh name="head_yaw" file="head_yaw.STL"/>
    <mesh name="head_pitch" file="head_pitch.STL"/>
    <mesh name="head_camera" file="head_camera.STL"/>
    <mesh name="head_rader" file="head_rader.STL"/>
    <mesh name="waist_camera" file="waist_camera.STL"/>
  </asset>
  <worldbody>
    <body name="base_link" pos="0 0 0.82">
      <freejoint />
      <site name="imu" pos="0 0 0" />
      <inertial pos="-0.0505652 -0.00027382 -0.00742912" quat="0.923611 0.0403128 0.38083 -0.0168842" mass="8.04799" diaginertia="0.104723 0.0623837 0.0608765"/>
      <geom type="mesh" contype="0" conaffinity="0" group="1" density="0" rgba="1 1 1 1" mesh="torso"/>
      <!-- base_link碰撞体 -->
      <geom size="0.06 0.12" pos="-0.025 0.095 -0.065" quat="0.707388 0 0.706825 0" type="cylinder" class="collision-left"/>
      <geom size="0.06 0.12" pos="-0.025 -0.095 -0.065" quat="0.707388 0 0.706825 0" type="cylinder" class="collision-right"/>
      <body name="leg_l1_link" pos="0 0.095075 -0.066">
        <inertial pos="-0.00387208 9.033e-05 0.00079719" quat="0.00792154 0.700569 0.0190281 0.713287" mass="1.89946" diaginertia="0.00349044 0.00305646 0.00238638"/>
        <joint name="leg_l1_joint" pos="0 0 0" axis="1 0 0" range="-0.314159 0.663225" actuatorfrcrange="-127 127" damping="0.02"/>
        <geom type="mesh" contype="0" conaffinity="0" group="1" density="0" rgba="1 1 1 1" mesh="l_leg_roll"/>
        <body name="leg_l2_link">
          <inertial pos="0.0002359 -0.00789588 -0.0910478" quat="0.470447 0.88241 0.00509804 -0.00260327" mass="0.7864" diaginertia="0.00359008 0.00259357 0.00190572"/>
          <joint name="leg_l2_joint" pos="0 0 0" axis="0 0 1" range="-0.785398 1.91986" actuatorfrcrange="-71 71" damping="0.02"/>
          <geom type="mesh" contype="0" conaffinity="0" group="1" density="0" rgba="1 1 1 1" mesh="l_leg_yaw"/>
          <body name="leg_l3_link" pos="0 0 -0.1437">
            <inertial pos="0.00279916 0.0153274 -0.0858676" quat="0.997679 0.012625 -0.0186943 0.064242" mass="6.52392" diaginertia="0.058727 0.0573321 0.0154733"/>
            <joint name="leg_l3_joint" pos="0 0 0" axis="0 1 0" range="-1.91986 1.5708" actuatorfrcrange="-132 132" damping="0.02"/>
            <geom type="mesh" contype="0" conaffinity="0" group="1" density="0" rgba="1 1 1 1" mesh="l_leg_pitch"/>
            <geom type="capsule" size="0.065 0.125" pos="0 0 -0.11" quat="0.707388 0 0 0.706825" class="collision-left"/>
            <geom size="0.06 0.02" pos="0.005 0.075 -0.115" quat="0.707388 0.706825 0 0" type="cylinder" class="collision-left"/>
            <body name="leg_l4_link" pos="-0.0011639 0 -0.284">
              <inertial pos="0.00569729 -5.18e-05 -0.161592" quat="0.999987 -0.000524235 0.00510477 4.51483e-06" mass="3.55159" diaginertia="0.0430538 0.0426274 0.00324531"/>
              <joint name="leg_l4_joint" pos="0 0 0" axis="0 1 0" range="0 2.53073" actuatorfrcrange="-280 280" damping="0.02"/>
              <geom type="mesh" contype="0" conaffinity="0" group="1" density="0" rgba="1 1 1 1" mesh="l_knee"/>
              <geom type="capsule" size="0.05 0.15" pos="0 0 -0.23" quat="0.707388 0 0 0.706825" class="collision-left"/>
              <body name="leg_l5_link" pos="0.002 0 -0.416">
                <inertial pos="0 0 0" quat="0.5 0.5 -0.5 0.5" mass="0.07554" diaginertia="1.268e-05 7.29e-06 7.29e-06"/>
                <joint name="leg_l5_joint" pos="0 0 0" axis="0 1 0" range="-0.872665 0.349066" actuatorfrcrange="-91.6 91.6" damping="0.02"/>
                <geom type="mesh" contype="0" conaffinity="0" group="1" density="0" rgba="1 1 1 1" mesh="l_foot_pitch"/>
                <body name="leg_l6_link">
                  <site name="l_ft_frame" pos="0 0 0" size="0.02 0.02 0.02" rgba="1 1 1 1" type="box" group="3"/>
                  <inertial pos="0.0301552 -1.60169e-06 -0.0354358" quat="2.0895e-05 0.739647 2.55497e-06 0.672995" mass="0.608522" diaginertia="0.0020548 0.00193363 0.000487855"/>
                  <joint name="leg_l6_joint" pos="0 0 0" axis="1 0 0" range="-0.261799 0.261799" actuatorfrcrange="-68.4 68.4" damping="0.02"/>
                  <geom type="mesh" contype="0" conaffinity="0" group="1" density="0" rgba="1 1 1 1" mesh="l_foot_roll"/>

                  <geom type="capsule" size="0.008" fromto="-0.008 -0.046 -0.044 -0.008  0.046 -0.044" class="collision-left"/>
                  <geom type="capsule" size="0.008" fromto="-0.016 -0.046 -0.051 -0.016  0.046 -0.051" class="collision-left"/>
                  <geom type="box" size="0.045 0.05 0.0054" pos=" 0.042 0.0 -0.041" class="collision-left"/>
                  <geom type="capsule" size="0.008" fromto="-0.063 -0.038 -0.054 -0.063  0.038 -0.054" class="collision-left"/>
                  <geom type="box" size="0.021 0.048 0.0054" pos=" -0.036 0.0 -0.054" class="collision-left"/>
                  <geom type="capsule" size="0.008" fromto="0.09 -0.046 -0.043 0.09  0.046 -0.043" class="collision-left"/>
                  <geom type="capsule" size="0.008" fromto="0.1 -0.046 -0.046 0.1  0.046 -0.046" class="collision-left"/>
                  <geom type="capsule" size="0.008" fromto="0.109 -0.046 -0.05 0.109  0.046 -0.05" class="collision-left"/>
                  <geom type="capsule" size="0.008" fromto="0.12 -0.046 -0.053 0.12  0.046 -0.053" class="collision-left"/>
                  <geom type="capsule" size="0.008" fromto="0.13 -0.046 -0.054 0.13  0.046 -0.054" class="collision-left"/>
                  <geom type="capsule" size="0.008" fromto="0.139 -0.041 -0.054 0.139  0.041 -0.054" class="collision-left"/>
                  <geom type="capsule" size="0.008" fromto="0.152 -0.032 -0.054 0.152 0.032 -0.054" class="collision-left"/>
                  <geom type="capsule" size="0.008" fromto="0.165 -0.02 -0.054 0.165  0.02 -0.054" class="collision-left"/>

                </body>
              </body>
            </body>
          </body>
        </body>
      </body>
      <body name="leg_r1_link" pos="0 -0.095075 -0.066">
        <inertial pos="-0.00387208 -9.033e-05 0.00079719" quat="-0.00792154 0.700569 -0.0190281 0.713287" mass="1.89946" diaginertia="0.00349044 0.00305646 0.00238638"/>
        <joint name="leg_r1_joint" pos="0 0 0" axis="1 0 0" range="-0.663225 0.314159" actuatorfrcrange="-127 127" damping="0.02"/>
        <geom type="mesh" contype="0" conaffinity="0" group="1" density="0" rgba="1 1 1 1" mesh="r_leg_roll"/>
        <body name="leg_r2_link">
          <inertial pos="0.0002359 0.00789588 -0.0910478" quat="0.88241 0.470447 0.00260327 -0.00509804" mass="0.7864" diaginertia="0.00359008 0.00259357 0.00190572"/>
          <joint name="leg_r2_joint" pos="0 0 0" axis="0 0 1" range="-1.91986 0.785398" actuatorfrcrange="-71 71" damping="0.02"/>
          <geom type="mesh" contype="0" conaffinity="0" group="1" density="0" rgba="1 1 1 1" mesh="r_leg_yaw"/>
          <body name="leg_r3_link" pos="0 0 -0.1437">
            <inertial pos="0.00279916 -0.0153274 -0.0858676" quat="0.997679 -0.012625 -0.0186943 -0.064242" mass="6.52392" diaginertia="0.058727 0.0573321 0.0154733"/>
            <joint name="leg_r3_joint" pos="0 0 0" axis="0 1 0" range="-1.91986 1.5708" actuatorfrcrange="-132 132" damping="0.02"/>
            <geom type="mesh" contype="0" conaffinity="0" group="1" density="0" rgba="1 1 1 1" mesh="r_leg_pitch"/>
            <geom type="capsule" size="0.065 0.125" pos="0 0 -0.11" quat="0.707388 0 0 0.706825" class="collision-right"/>
            <geom size="0.06 0.02" pos="0.005 -0.075 -0.115" quat="0.707388 0.706825 0 0" type="cylinder" class="collision-right"/>
            <body name="leg_r4_link" pos="-0.0011639 0 -0.284">
              <inertial pos="0.00569729 5.18e-05 -0.161592" quat="0.999987 0.000524235 0.00510477 -4.51483e-06" mass="3.55159" diaginertia="0.0430538 0.0426274 0.00324531"/>
              <joint name="leg_r4_joint" pos="0 0 0" axis="0 1 0" range="0 2.53073" actuatorfrcrange="-280 280" damping="0.02"/>
              <geom type="mesh" contype="0" conaffinity="0" group="1" density="0" rgba="1 1 1 1" mesh="r_knee"/>
              <geom type="capsule" size="0.05 0.15" pos="0 0 -0.23" quat="0.707388 0 0 0.706825" class="collision-right"/>
              <body name="leg_r5_link" pos="0.002 0 -0.416">
                <inertial pos="0 0 0" quat="0.5 0.5 -0.5 0.5" mass="0.07554" diaginertia="1.268e-05 7.29e-06 7.29e-06"/>
                <joint name="leg_r5_joint" pos="0 0 0" axis="0 1 0" range="-0.872665 0.349066" actuatorfrcrange="-91.6 91.6" damping="0.02"/>
                <geom type="mesh" contype="0" conaffinity="0" group="1" density="0" rgba="1 1 1 1" mesh="r_foot_pitch"/>
                <body name="leg_r6_link">
                  <site name="r_ft_frame" pos="0 0 0" size="0.02 0.02 0.02" rgba="1 1 1 1" type="box" group="3"/>
                  <inertial pos="0.0301552 1.60169e-06 -0.0354358" quat="-2.09683e-05 0.739647 -2.6356e-06 0.672995" mass="0.608522" diaginertia="0.0020548 0.00193363 0.000487855"/>
                  <joint name="leg_r6_joint" pos="0 0 0" axis="1 0 0" range="-0.261799 0.261799" actuatorfrcrange="-68.4 68.4" damping="0.02"/>
                  <geom type="mesh" contype="0" conaffinity="0" group="1" density="0" rgba="1 1 1 1" mesh="r_foot_roll"/>

                  <geom type="box" size="0.045 0.05 0.0054" pos=" 0.042 0.0 -0.041" class="collision-right"/>
                  <geom type="capsule" size="0.008" fromto="-0.008 -0.046 -0.044 -0.008  0.046 -0.044" class="collision-right"/>
                  <geom type="capsule" size="0.008" fromto="-0.016 -0.046 -0.051 -0.016  0.046 -0.051" class="collision-right"/>
                  <geom type="capsule" size="0.008" fromto="-0.063 -0.038 -0.054 -0.063  0.038 -0.054" class="collision-right"/>
                  <geom type="box" size="0.021 0.048 0.0054" pos=" -0.036 0.0 -0.054" class="collision-right"/>
                  <geom type="capsule" size="0.008" fromto="0.09 -0.046 -0.043 0.09  0.046 -0.043" class="collision-right"/>
                  <geom type="capsule" size="0.008" fromto="0.1 -0.046 -0.046 0.1  0.046 -0.046" class="collision-right"/>
                  <geom type="capsule" size="0.008" fromto="0.109 -0.046 -0.05 0.109  0.046 -0.05" class="collision-right"/>
                  <geom type="capsule" size="0.008" fromto="0.12 -0.046 -0.053 0.12  0.046 -0.053" class="collision-right"/>
                  <geom type="capsule" size="0.008" fromto="0.13 -0.046 -0.054 0.13  0.046 -0.054" class="collision-right"/>
                  <geom type="capsule" size="0.008" fromto="0.139 -0.041 -0.054 0.139  0.041 -0.054" class="collision-right"/>
                  <geom type="capsule" size="0.008" fromto="0.152 -0.032 -0.054 0.152 0.032 -0.054" class="collision-right"/>
                  <geom type="capsule" size="0.008" fromto="0.165 -0.02 -0.054 0.165  0.02 -0.054" class="collision-right"/>

                </body>
              </body>
            </body>
          </body>
        </body>
      </body>
      <body name="waist_yaw" pos="0 0 0.1114">
        <inertial pos="-0.0029446 -0.000739956 0.172598" quat="0.999841 0.0114116 -0.0136465 -0.000968776" mass="20.1088" diaginertia="0.350479 0.274099 0.212075"/>
        <joint name="waist_yaw_joint" pos="0 0 0" axis="0 0 1" range="-3.14159 3.14159" actuatorfrcrange="-102 102" damping="0.02"/>
        <geom type="mesh" contype="0" conaffinity="0" group="1" density="0" rgba="1 1 1 1" mesh="waist_yaw"/>
        <!-- waist_yaw碰撞体 -->
        <geom type="capsule" size="0.13 0.06" pos="0.008 0 0.2486" quat="0.707388 0.706825 0 0" class="collision"/>
        <geom type="capsule" size="0.13 0.03" pos="0.008 0 0.0886" class="collision"/>
        <body name="zarm_l1_link" pos="-0.003 0.2527 0.283">
          <inertial pos="0.00140078 -0.010235 -0.00030514" quat="0.708449 0.7049 -0.00774269 -0.034" mass="1.01296" diaginertia="0.00147543 0.00144282 0.000964459"/>
          <joint name="zarm_l1_joint" pos="0 0 0" axis="0 1 0" range="-3.14159 1.5708" actuatorfrcrange="-66 66" damping="0.02"/>
          <geom type="mesh" contype="0" conaffinity="0" group="1" density="0" rgba="1 1 1 1" mesh="l_arm_pitch"/>
          <geom type="capsule" size="0.05 0.02" quat="0.707105 0 0.707108 0" class="collision-left"/>
          <body name="zarm_l2_link">
            <inertial pos="-0.00070214 -6.01e-06 -0.0462779" quat="0.703645 0.0708044 0.070601 0.703482" mass="0.43789" diaginertia="0.00128467 0.000885488 0.000770102"/>
            <joint name="zarm_l2_joint" pos="0 0 0" axis="1 0 0" range="-0.349066 3.49066" actuatorfrcrange="-75 75" damping="0.02"/>
            <geom type="mesh" contype="0" conaffinity="0" group="1" density="0" rgba="1 1 1 1" mesh="l_arm_roll"/>
            <body name="zarm_l3_link">
              <inertial pos="0.00964741 0.00319323 -0.229195" quat="0.938551 0.0522811 -0.059591 -0.335912" mass="1.83545" diaginertia="0.00743246 0.00738062 0.00181201"/>
              <joint name="zarm_l3_joint" pos="0 0 0" axis="0 0 1" range="-1.48353 1.48353" actuatorfrcrange="-57 57" damping="0.02"/>
              <geom type="mesh" contype="0" conaffinity="0" group="1" density="0" rgba="1 1 1 1" mesh="l_arm_yaw"/>
              <geom type="capsule" size="0.045 0.07" pos="0 0 -0.18" class="collision-left"/>
              <body name="zarm_l4_link" pos="0.02 0 -0.2837">
                <inertial pos="-0.0182629 0.00208235 -0.0669584" quat="0.996082 -0.0410279 0.0783038 -0.00235936" mass="0.6577" diaginertia="0.00157685 0.00134433 0.00068768"/>
                <joint name="zarm_l4_joint" pos="0 0 0" axis="0 1 0" range="-2.61799 0" actuatorfrcrange="-75 75" damping="0.02"/>
                <geom type="mesh" contype="0" conaffinity="0" group="1" density="0" rgba="1 1 1 1" mesh="l_forearm"/>
                <geom type="capsule" size="0.045 0.09" pos="-0.02 0 -0.14" class="collision-left"/>
                <body name="zarm_l5_link" pos="-0.02 0 -0.1201">
                  <inertial pos="-0.00889277 1.406e-05 -0.0568964" quat="0.691897 0.147131 0.14938 0.690881" mass="0.67878" diaginertia="0.00105528 0.000734737 0.000564267"/>
                  <joint name="zarm_l5_joint" pos="0 0 0" axis="0 0 1" range="-1.5708 1.5708" actuatorfrcrange="-14.1 14.1" damping="0.02"/>
                  <geom type="mesh" contype="0" conaffinity="0" group="1" density="0" rgba="1 1 1 1" mesh="l_hand_yaw"/>
                  <body name="zarm_l6_link" pos="0 0 -0.114">
                    <inertial pos="-0.0017411 0.00664955 -0.0143008" quat="0.192371 0.701835 0.263078 0.633412" mass="0.51231" diaginertia="0.000316031 0.000292605 0.000195864"/>
                    <joint name="zarm_l6_joint" pos="0 0 0" axis="1 0 0" range="-1.309 0.698132" actuatorfrcrange="-14.1 14.1" damping="0.02"/>
                    <geom type="mesh" contype="0" conaffinity="0" group="1" density="0" rgba="1 1 1 1" mesh="l_hand_roll"/>
                    <body name="zarm_l7_link" pos="0 0 -0.021">
                      <inertial pos="0.00481393 0.00873606 -0.0837543" quat="0.707107 0 0 0.707107" mass="0.7374" diaginertia="0.00133239 0.00112502 0.000373427"/>
                      <joint name="zarm_l7_joint" pos="0 0 0" axis="0 1 0" range="-0.698132 0.698132" actuatorfrcrange="-14.1 14.1" damping="0.02"/>
                      <geom type="mesh" contype="0" conaffinity="0" group="1" density="0" rgba="1 1 1 1" mesh="l_hand_pitch_nohand"/>
                      <geom size="0.04 0.025 0.08" pos="0 0 -0.158" quat="4.63268e-05 0 0 -1" type="box" class="collision-left"/>
                      <geom size="0.01 0.04" pos="0.0505 -0.0292 -0.116372" quat="0.991915 0 -0.126907 0" type="cylinder" class="collision-left"/>
                    </body>
                  </body>
                </body>
              </body>
            </body>
          </body>
        </body>
        <body name="zarm_r1_link" pos="-0.003 -0.2527 0.283">
          <inertial pos="0.00140078 0.010235 -0.00030514" quat="0.7049 0.708449 0.034 0.00774269" mass="1.01296" diaginertia="0.00147543 0.00144282 0.000964459"/>
          <joint name="zarm_r1_joint" pos="0 0 0" axis="0 1 0" range="-3.14159 1.5708" actuatorfrcrange="-66 66" damping="0.02"/>
          <geom pos="0 0 0" quat="1 0 0 0" type="mesh" contype="0" conaffinity="0" group="1" density="0" rgba="1 1 1 1" mesh="r_arm_pitch"/>
          <geom type="capsule" size="0.05 0.02" quat="0.707105 0 0.707108 0" class="collision-right"/>
          <body name="zarm_r2_link">
            <inertial pos="-0.00070214 6.01e-06 -0.0462779" quat="0.703482 0.070601 0.0708044 0.703645" mass="0.43789" diaginertia="0.00128467 0.000885488 0.000770102"/>
            <joint name="zarm_r2_joint" pos="0 0 0" axis="1 0 0" range="-3.49066 0.349066" actuatorfrcrange="-75 75" damping="0.02"/>
            <geom type="mesh" contype="0" conaffinity="0" group="1" density="0" rgba="1 1 1 1" mesh="r_arm_roll"/>
            <body name="zarm_r3_link">
              <inertial pos="0.00964741 -0.00319323 -0.229195" quat="0.938551 -0.0522811 -0.059591 0.335912" mass="1.83545" diaginertia="0.00743246 0.00738062 0.00181201"/>
              <joint name="zarm_r3_joint" pos="0 0 0" axis="0 0 1" range="-1.48353 1.48353" actuatorfrcrange="-57 57" damping="0.02"/>
              <geom type="mesh" contype="0" conaffinity="0" group="1" density="0" rgba="1 1 1 1" mesh="r_arm_yaw"/>
              <geom type="capsule" size="0.045 0.07" pos="0 0 -0.18" class="collision-right"/>
              <body name="zarm_r4_link" pos="0.02 0 -0.2837">
                <inertial pos="-0.0182629 -0.00208235 -0.0669584" quat="0.996082 0.0410279 0.0783038 0.00235936" mass="0.6577" diaginertia="0.00157685 0.00134433 0.00068768"/>
                <joint name="zarm_r4_joint" pos="0 0 0" axis="0 1 0" range="-2.61799 0" actuatorfrcrange="-75 75" damping="0.02"/>
                <geom type="mesh" contype="0" conaffinity="0" group="1" density="0" rgba="1 1 1 1" mesh="r_forearm"/>
                <geom type="capsule" size="0.045 0.09" pos="-0.02 0 -0.14" class="collision-right"/>
                <body name="zarm_r5_link" pos="-0.02 0 -0.1201">
                  <inertial pos="-0.00889277 -1.406e-05 -0.0568964" quat="0.690881 0.14938 0.147131 0.691897" mass="0.67878" diaginertia="0.00105528 0.000734737 0.000564267"/>
                  <joint name="zarm_r5_joint" pos="0 0 0" axis="0 0 1" range="-1.5708 1.5708" actuatorfrcrange="-14.1 14.1" damping="0.02"/>
                  <geom type="mesh" contype="0" conaffinity="0" group="1" density="0" rgba="1 1 1 1" mesh="r_hand_yaw"/>
                  <body name="zarm_r6_link" pos="0 0 -0.114">
                    <inertial pos="-0.0017411 -0.00664955 -0.0143008" quat="-0.192371 0.701835 -0.263078 0.633412" mass="0.51231" diaginertia="0.000316031 0.000292605 0.000195864"/>
                    <joint name="zarm_r6_joint" pos="0 0 0" axis="1 0 0" range="-0.698132 1.309" actuatorfrcrange="-14.1 14.1" damping="0.02"/>
                    <geom type="mesh" contype="0" conaffinity="0" group="1" density="0" rgba="1 1 1 1" mesh="r_hand_roll"/>
                    <body name="zarm_r7_link" pos="0 0 -0.021">
                      <inertial pos="0.00481393 -0.00870857 -0.0836411" quat="0.707107 0 0 0.707107" mass="0.7374" diaginertia="0.00131607 0.00110836 0.000374168"/>
                      <joint name="zarm_r7_joint" pos="0 0 0" axis="0 1 0" range="-0.698132 0.698132" actuatorfrcrange="-14.1 14.1" damping="0.02"/>
                      <geom type="mesh" contype="0" conaffinity="0" group="1" density="0" rgba="1 1 1 1" mesh="r_hand_pitch_nohand"/>
                      <geom size="0.04 0.025 0.08" pos="0 0 -0.158" quat="4.63268e-05 0 0 -1" type="box" class="collision-right"/>
                      <geom size="0.01 0.04" pos="0.0505 0.0292 -0.116372" quat="0.991915 0 -0.126907 0" type="cylinder" class="collision-right"/>
                    </body>
                  </body>
                </body>
              </body>
            </body>
          </body>
        </body>
        <body name="zhead_1_link" pos="-0.003 0 0.49535">
          <inertial pos="-0.00029696 -0.0027932 -0.0376999" quat="0.999679 0.0249396 0.00153832 0.00413552" mass="0.81695" diaginertia="0.00206265 0.00192336 0.000654121"/>
          <joint name="zhead_1_joint" pos="0 0 0" axis="0 0 1" range="-1.5708 1.5708" actuatorfrcrange="-1.5 1.5" damping="0.02"/>
          <geom type="mesh" contype="0" conaffinity="0" group="1" density="0" rgba="1 1 1 1" mesh="head_yaw"/>
          <geom pos="0 0 -0.078253" quat="1 0 0 0" type="mesh" contype="0" conaffinity="0" group="1" density="0" rgba="0.61176 0.65882 0.67059 1" mesh="head_rader"/>
          <body name="zhead_2_link">
            <inertial pos="0.0352257 0.00045985 0.0449437" quat="0.0539262 0.840844 0.0771762 0.533027" mass="0.8238" diaginertia="0.00481577 0.00472128 0.00406429"/>
            <joint name="zhead_2_joint" pos="0 0 0" axis="0 1 0" range="-0.523599 0.523599" actuatorfrcrange="-12 12" damping="0.02"/>
            <geom type="mesh" contype="0" conaffinity="0" group="1" density="0" rgba="1 1 1 1" mesh="head_pitch"/>
            <geom type="sphere" size="0.1" pos="0.04 0 0.01" class="collision"/>
            <geom pos="0.093839 0.0475 0.050077" quat="0.985534 0 0.169478 0" type="mesh" contype="0" conaffinity="0" group="1" density="0" rgba="1 1 1 1" mesh="head_camera"/>
          </body>
        </body>
      </body>
    </body>
  </worldbody>
  <actuator>
    <motor gear="1" joint="leg_l1_joint" name="leg_l1_joint_motor" ctrllimited="true" ctrlrange="-127 127" />
    <motor gear="1" joint="leg_l2_joint" name="leg_l2_joint_motor" ctrllimited="true" ctrlrange="-71 71" />
    <motor gear="1" joint="leg_l3_joint" name="leg_l3_joint_motor" ctrllimited="true" ctrlrange="-132 132" />
    <motor gear="1" joint="leg_l4_joint" name="leg_l4_joint_motor" ctrllimited="true" ctrlrange="-280 280" />
    <motor gear="1" joint="leg_l5_joint" name="leg_l5_joint_motor" ctrllimited="true" ctrlrange="-91.6 91.6" />
    <motor gear="1" joint="leg_l6_joint" name="leg_l6_joint_motor" ctrllimited="true" ctrlrange="-68.4 68.4" />
    <motor gear="1" joint="leg_r1_joint" name="leg_r1_joint_motor" ctrllimited="true" ctrlrange="-127 127" />
    <motor gear="1" joint="leg_r2_joint" name="leg_r2_joint_motor" ctrllimited="true" ctrlrange="-71 71" />
    <motor gear="1" joint="leg_r3_joint" name="leg_r3_joint_motor" ctrllimited="true" ctrlrange="-132 132" />
    <motor gear="1" joint="leg_r4_joint" name="leg_r4_joint_motor" ctrllimited="true" ctrlrange="-280 280" />
    <motor gear="1" joint="leg_r5_joint" name="leg_r5_joint_motor" ctrllimited="true" ctrlrange="-91.6 91.6" />
    <motor gear="1" joint="leg_r6_joint" name="leg_r6_joint_motor" ctrllimited="true" ctrlrange="-68.4 68.4" />
    <motor gear="1" joint="waist_yaw_joint" name="waist_yaw_joint_motor" ctrllimited="true" ctrlrange="-102 102" />
    <motor gear="1" joint="zarm_l1_joint" name="zarm_l1_joint_motor" ctrllimited="true" ctrlrange="-66 66" />
    <motor gear="1" joint="zarm_l2_joint" name="zarm_l2_joint_motor" ctrllimited="true" ctrlrange="-75 75" />
    <motor gear="1" joint="zarm_l3_joint" name="zarm_l3_joint_motor" ctrllimited="true" ctrlrange="-57 57" />
    <motor gear="1" joint="zarm_l4_joint" name="zarm_l4_joint_motor" ctrllimited="true" ctrlrange="-75 75" />
    <motor gear="1" joint="zarm_l5_joint" name="zarm_l5_joint_motor" ctrllimited="true" ctrlrange="-14.1 14.1" />
    <motor gear="1" joint="zarm_l6_joint" name="zarm_l6_joint_motor" ctrllimited="true" ctrlrange="-14.1 14.1" />
    <motor gear="1" joint="zarm_l7_joint" name="zarm_l7_joint_motor" ctrllimited="true" ctrlrange="-14.1 14.1" />
    <motor gear="1" joint="zarm_r1_joint" name="zarm_r1_joint_motor" ctrllimited="true" ctrlrange="-66 66" />
    <motor gear="1" joint="zarm_r2_joint" name="zarm_r2_joint_motor" ctrllimited="true" ctrlrange="-75 75" />
    <motor gear="1" joint="zarm_r3_joint" name="zarm_r3_joint_motor" ctrllimited="true" ctrlrange="-57 57" />
    <motor gear="1" joint="zarm_r4_joint" name="zarm_r4_joint_motor" ctrllimited="true" ctrlrange="-75 75" />
    <motor gear="1" joint="zarm_r5_joint" name="zarm_r5_joint_motor" ctrllimited="true" ctrlrange="-14.1 14.1" />
    <motor gear="1" joint="zarm_r6_joint" name="zarm_r6_joint_motor" ctrllimited="true" ctrlrange="-14.1 14.1" />
    <motor gear="1" joint="zarm_r7_joint" name="zarm_r7_joint_motor" ctrllimited="true" ctrlrange="-14.1 14.1" />
    <motor gear="1" joint="zhead_1_joint" name="zhead_1_joint_motor" ctrllimited="true" ctrlrange="-14.1 14.1" />
    <motor gear="1" joint="zhead_2_joint" name="zhead_2_joint_motor" ctrllimited="true" ctrlrange="-14.1 14.1" />
  </actuator>
  <sensor>
    <accelerometer name="BodyAcc" site="imu" />
    <velocimeter name="BodyVel" site="imu" />
    <gyro name="BodyGyro" site="imu" />
    <framepos name="BodyPos" objtype="site" objname="imu" />
    <framequat name="BodyQuat" objtype="site" objname="imu" />
    <jointpos name="leg_l1_joint_pos" joint="leg_l1_joint" />
    <jointpos name="leg_l2_joint_pos" joint="leg_l2_joint" />
    <jointpos name="leg_l3_joint_pos" joint="leg_l3_joint" />
    <jointpos name="leg_l4_joint_pos" joint="leg_l4_joint" />
    <jointpos name="leg_l5_joint_pos" joint="leg_l5_joint" />
    <jointpos name="leg_l6_joint_pos" joint="leg_l6_joint" />
    <jointpos name="leg_r1_joint_pos" joint="leg_r1_joint" />
    <jointpos name="leg_r2_joint_pos" joint="leg_r2_joint" />
    <jointpos name="leg_r3_joint_pos" joint="leg_r3_joint" />
    <jointpos name="leg_r4_joint_pos" joint="leg_r4_joint" />
    <jointpos name="leg_r5_joint_pos" joint="leg_r5_joint" />
    <jointpos name="leg_r6_joint_pos" joint="leg_r6_joint" />
    <jointpos name="waist_yaw_joint_pos" joint="waist_yaw_joint" />
    <jointpos name="zarm_l1_joint_pos" joint="zarm_l1_joint" />
    <jointpos name="zarm_l2_joint_pos" joint="zarm_l2_joint" />
    <jointpos name="zarm_l3_joint_pos" joint="zarm_l3_joint" />
    <jointpos name="zarm_l4_joint_pos" joint="zarm_l4_joint" />
    <jointpos name="zarm_l5_joint_pos" joint="zarm_l5_joint" />
    <jointpos name="zarm_l6_joint_pos" joint="zarm_l6_joint" />
    <jointpos name="zarm_l7_joint_pos" joint="zarm_l7_joint" />
    <jointpos name="zarm_r1_joint_pos" joint="zarm_r1_joint" />
    <jointpos name="zarm_r2_joint_pos" joint="zarm_r2_joint" />
    <jointpos name="zarm_r3_joint_pos" joint="zarm_r3_joint" />
    <jointpos name="zarm_r4_joint_pos" joint="zarm_r4_joint" />
    <jointpos name="zarm_r5_joint_pos" joint="zarm_r5_joint" />
    <jointpos name="zarm_r6_joint_pos" joint="zarm_r6_joint" />
    <jointpos name="zarm_r7_joint_pos" joint="zarm_r7_joint" />
    <jointpos name="zhead_1_joint_pos" joint="zhead_1_joint" />
    <jointpos name="zhead_2_joint_pos" joint="zhead_2_joint" />
    <jointvel name="leg_l1_joint_vel" joint="leg_l1_joint" />
    <jointvel name="leg_l2_joint_vel" joint="leg_l2_joint" />
    <jointvel name="leg_l3_joint_vel" joint="leg_l3_joint" />
    <jointvel name="leg_l4_joint_vel" joint="leg_l4_joint" />
    <jointvel name="leg_l5_joint_vel" joint="leg_l5_joint" />
    <jointvel name="leg_l6_joint_vel" joint="leg_l6_joint" />
    <jointvel name="leg_r1_joint_vel" joint="leg_r1_joint" />
    <jointvel name="leg_r2_joint_vel" joint="leg_r2_joint" />
    <jointvel name="leg_r3_joint_vel" joint="leg_r3_joint" />
    <jointvel name="leg_r4_joint_vel" joint="leg_r4_joint" />
    <jointvel name="leg_r5_joint_vel" joint="leg_r5_joint" />
    <jointvel name="leg_r6_joint_vel" joint="leg_r6_joint" />
    <jointvel name="waist_yaw_joint_vel" joint="waist_yaw_joint" />
    <jointvel name="zarm_l1_joint_vel" joint="zarm_l1_joint" />
    <jointvel name="zarm_l2_joint_vel" joint="zarm_l2_joint" />
    <jointvel name="zarm_l3_joint_vel" joint="zarm_l3_joint" />
    <jointvel name="zarm_l4_joint_vel" joint="zarm_l4_joint" />
    <jointvel name="zarm_l5_joint_vel" joint="zarm_l5_joint" />
    <jointvel name="zarm_l6_joint_vel" joint="zarm_l6_joint" />
    <jointvel name="zarm_l7_joint_vel" joint="zarm_l7_joint" />
    <jointvel name="zarm_r1_joint_vel" joint="zarm_r1_joint" />
    <jointvel name="zarm_r2_joint_vel" joint="zarm_r2_joint" />
    <jointvel name="zarm_r3_joint_vel" joint="zarm_r3_joint" />
    <jointvel name="zarm_r4_joint_vel" joint="zarm_r4_joint" />
    <jointvel name="zarm_r5_joint_vel" joint="zarm_r5_joint" />
    <jointvel name="zarm_r6_joint_vel" joint="zarm_r6_joint" />
    <jointvel name="zarm_r7_joint_vel" joint="zarm_r7_joint" />
    <jointvel name="zhead_1_joint_vel" joint="zhead_1_joint" />
    <jointvel name="zhead_2_joint_vel" joint="zhead_2_joint" />
    <!-- FT sensors for left and right foot -->
    <force name="l_force" site="l_ft_frame" />
    <torque name="l_torque" site="l_ft_frame" />
    <force name="r_force" site="r_ft_frame" />
    <torque name="r_torque" site="r_ft_frame" />    
  </sensor>
</mujoco>
