<?xml version="1.0" ?>
<!-- =================================================================================== -->
<!-- |    This document was autogenerated by xacro from /home/fandes/workspace/kuavo-ros-control/src/humanoid-control/humanoid_interface_drake/models/biped_gen4.2/urdf/biped_v3_full.xacro | -->
<!-- |    EDITING THIS FILE BY HAND IS NOT RECOMMENDED                                 | -->
<!-- =================================================================================== -->
<robot name="biped_v3_full" xmlns:drake="https://drake.mit.edu">
  <mujoco>
    <compiler meshdir="../meshes/" balanceinertia="true" discardvisual="false" />
  </mujoco>
  <link name="chassis_link">
    <inertial>
      <origin xyz="0.000389910994978911 0.00140427472303049 0.059155398355868" rpy="0 0 0" />
      <mass value="97.77291318" />
      <inertia ixx="0.0019898467172166" ixy="-9.8e-05" ixz="5e-05" iyy="0.00328176736755805" iyz="0.000182260661996114" izz="0.00200808104859443" />
    </inertial>
    <visual>
      <origin xyz="0 0 0" rpy="0 0 0" />
      <geometry>
        <mesh filename="../../meshes/chassic.STL" />
      </geometry>
      <material name="">
        <color rgba="1 1 1 1" />
      </material>
    </visual>
  </link>
  <link name="knee_link">
    <inertial>
      <origin xyz="-0.23814509 0.06477318 0.05709786" rpy="0 0 0" />
      <mass value="5.39660196" />
      <inertia ixx="0.0181941" ixy="-3.368e-05" ixz="0.03867457" iyy="0.18698546" iyz="9.1e-05" izz="0.1696571" />
    </inertial>
    <visual>
      <origin xyz="0 0 0" rpy="0 0 0" />
      <geometry>
        <mesh filename="../../meshes/knee_pitch.STL" />
      </geometry>
      <material name="">
        <color rgba="1 1 1 1" />
      </material>
    </visual>
  </link>
  <joint name="knee_joint" type="revolute">
    <origin xyz="0 0 0.0805" rpy="0 0 0" />
    <parent link="chassis_link" />
    <child link="knee_link" />
    <axis xyz="0 1 0" />
    <limit lower="0" upper="1.448" effort="668" velocity="22.5" />
    <dynamics damping="0.2" friction="0.0" />
  </joint>
  <transmission type="SimpleTransmission">
    <joint name="knee_joint" />
    <actuator name="knee_joint_motor" />
  </transmission>
  <link name="leg_link">
    <inertial>
      <origin xyz="0.23828732 -0.00731845 0.03851197" rpy="0 0 0" />
      <mass value="12.35650958" />
      <inertia ixx="0.04100244" ixy="-0.0044715" ixz="-0.09155463" iyy="0.62558367" iyz="-0.00089808" izz="0.60922308" />
    </inertial>
    <visual>
      <origin xyz="0 0 0" rpy="0 0 0" />
      <geometry>
        <mesh filename="../../meshes/leg_pitch.STL" />
      </geometry>
      <material name="">
        <color rgba="1 1 1 1" />
      </material>
    </visual>
  </link>
  <joint name="leg_joint" type="revolute">
    <origin xyz="-0.48618 0 0.11672" rpy="0 0 0" />
    <parent link="knee_link" />
    <child link="leg_link" />
    <axis xyz="0 1 0" />
    <limit lower="-2.81" upper="0.0" effort="668" velocity="22.5" />
  </joint>
  <transmission type="SimpleTransmission">
    <joint name="leg_joint" />
    <actuator name="leg_joint_motor" />
  </transmission>
  <link name="waist_link">
    <inertial>
      <origin xyz="-0.00042629 -0.01633525 0.12667958" rpy="0 0 0" />
      <mass value="5.4305643" />
      <inertia ixx="0.03360578" ixy="-0.00023065" ixz="-0.00020076" iyy="0.02736911" iyz="0.00037584" izz="0.02207442" />
    </inertial>
    <visual>
      <origin xyz="0 0 0" rpy="0 0 0" />
      <geometry>
        <mesh filename="../../meshes/waist_pitch.STL" />
      </geometry>
      <material name="">
        <color rgba="1 1 1 1" />
      </material>
    </visual>
  </link>
  <joint name="waist_pitch_joint" type="revolute">
    <origin xyz="0.49384 0 0.078217" rpy="0 0 0" />
    <parent link="leg_link" />
    <child link="waist_link" />
    <axis xyz=" 0 1 0" />
    <limit lower="0.0" upper="2.984" effort="267" velocity="22.5" />
    <dynamics damping="0.2" friction="0.0" />
  </joint>
  <transmission type="SimpleTransmission">
    <joint name="waist_pitch_joint" />
    <actuator name="waist_pitch_joint_motor" />
  </transmission>
  <link name="base_link">
    <inertial>
      <origin xyz="-0.00726828 0.00439736 0.16711928" rpy="0 0 0" />
      <mass value="8.79680408" />
      <inertia ixx="0.16806684" ixy="-0.00051754" ixz="0.00343898" iyy="0.08071775" iyz="0.00078646" izz="0.11582658" />
    </inertial>
    <visual>
      <origin xyz="0 0 0" rpy="0 0 0" />
      <geometry>
        <mesh filename="../../meshes/torso.STL" />
      </geometry>
      <material name="">
        <color rgba="1 1 1 1" />
      </material>
    </visual>
    <collision>
      <origin xyz="0 0 0.2" rpy="0 0 0" />
      <geometry>
        <cylinder radius="0.15" length="0.6" />
      </geometry>
    </collision>
  </link>
  <joint name="waist_yaw_joint" type="revolute">
    <origin xyz="0.0 -0.017 0.2" rpy="0 0 0" />
    <parent link="waist_link" />
    <child link="base_link" />
    <axis xyz=" 0 0 1" />
    <limit lower="-3.14" upper="3.14" effort="267" velocity="22.5" />
    <dynamics damping="0.2" friction="0.0" />
  </joint>
  <transmission type="SimpleTransmission">
    <joint name="waist_yaw_joint" />
    <actuator name="waist_yaw_joint_motor" />
  </transmission>
  <link name="zarm_l1_link">
    <inertial>
      <origin xyz="-0.00083 -0.02218 0.00035" rpy="0 0 0" />
      <mass value="0.962" />
      <inertia ixx="0.00225" ixy="-3e-05" ixz="0.0" iyy="0.00099" iyz="-2e-05" izz="0.00227" />
    </inertial>
    <visual>
      <origin xyz="0 0 0" rpy="0 0 0" />
      <geometry>
        <mesh filename="../../meshes/l_arm_pitch.STL" />
      </geometry>
      <material name="">
        <color rgba="1 1 1 1" />
      </material>
    </visual>
  </link>
  <joint name="zarm_l1_joint" type="revolute">
    <origin xyz="-0.02250000 0.28970000 0.20400000" rpy="0 0 0" />
    <parent link="base_link" />
    <child link="zarm_l1_link" />
    <axis xyz="0 1 0" />
    <limit lower="-2.0933" upper="0.5233" effort="0.5" velocity="2.198" />
    <dynamics damping="0.2" friction="0.0" />
  </joint>
  <transmission type="SimpleTransmission">
    <joint name="zarm_l1_joint" />
    <actuator name="zarm_l1_joint_motor" />
  </transmission>
  <link name="zarm_l2_link">
    <inertial>
      <origin xyz="-0.00791 0.0 -0.04655" rpy="0 0 0" />
      <mass value="0.57" />
      <inertia ixx="0.00163" ixy="0.0" ixz="5e-05" iyy="0.00211" iyz="0.0" izz="0.00122" />
    </inertial>
    <visual>
      <origin xyz="0 0 0" rpy="0 0 0" />
      <geometry>
        <mesh filename="../../meshes/l_arm_roll.STL" />
      </geometry>
      <material name="">
        <color rgba="1 1 1 1" />
      </material>
    </visual>
  </link>
  <joint name="zarm_l2_joint" type="revolute">
    <origin xyz="0 0 0" rpy="0 0 0" />
    <parent link="zarm_l1_link" />
    <child link="zarm_l2_link" />
    <axis xyz="1 0 0" />
    <limit lower="-0.3489" upper="2.0933" effort="1.5" velocity="2.198" />
    <dynamics damping="0.2" friction="0.0" />
  </joint>
  <transmission type="SimpleTransmission">
    <joint name="zarm_l2_joint" />
    <actuator name="zarm_l2_joint_motor" />
  </transmission>
  <link name="zarm_l3_link">
    <inertial>
      <origin xyz="0.00628 0.00107 -0.20878" rpy="0 0 0" />
      <mass value="1.65" />
      <inertia ixx="0.00815" ixy="-4e-05" ixz="0.00085" iyy="0.00828" iyz="0.00014" izz="0.00206" />
    </inertial>
    <visual>
      <origin xyz="0 0 0" rpy="0 0 0" />
      <geometry>
        <mesh filename="../../meshes/l_arm_yaw.STL" />
      </geometry>
      <material name="">
        <color rgba="1 1 1 1" />
      </material>
    </visual>
  </link>
  <joint name="zarm_l3_joint" type="revolute">
    <origin xyz="0 0 0" rpy="0 0 0" />
    <parent link="zarm_l2_link" />
    <child link="zarm_l3_link" />
    <axis xyz="0 0 1" />
    <limit lower="-1.57" upper="1.57" effort="2.5" velocity="2.198" />
    <dynamics damping="0.2" friction="0.0" />
  </joint>
  <transmission type="SimpleTransmission">
    <joint name="zarm_l3_joint" />
    <actuator name="zarm_l3_joint_motor" />
  </transmission>
  <link name="zarm_l4_link">
    <inertial>
      <origin xyz="-0.0161081858253221 0.00143419729886191 -0.0485597358583735" rpy="0 0 0" />
      <mass value="0.42900" />
      <inertia ixx="0.000378810410248752" ixy="2.2e-05" ixz="4.15629759693738E-05" iyy="0.000498964515234446" iyz="-1.3e-05" izz="0.000202125335962635" />
    </inertial>
    <visual>
      <origin xyz="0 0 0" rpy="0 0 0" />
      <geometry>
        <mesh filename="../../meshes/l_arm_foream.STL" />
      </geometry>
      <material name="">
        <color rgba="1 1 1 1" />
      </material>
    </visual>
  </link>
  <joint name="zarm_l4_joint" type="revolute">
    <origin xyz="0.0200000000000006 0 -0.283699999999996" rpy="0 0 0" />
    <parent link="zarm_l3_link" />
    <child link="zarm_l4_link" />
    <axis xyz="0 1 0" />
    <limit lower="-1.518" upper="1.518" effort="10" velocity="2.0" />
    <dynamics damping="0.2" friction="0.0" />
  </joint>
  <transmission type="SimpleTransmission">
    <joint name="zarm_l4_joint" />
    <actuator name="zarm_l4_joint_motor" />
  </transmission>
  <link name="zarm_l5_link">
    <inertial>
      <origin xyz="-0.00207 0.00018 -0.05079" rpy="0 0 0" />
      <mass value="0.61" />
      <inertia ixx="0.00107" ixy="0.0" ixz="-4e-05" iyy="0.00146" iyz="0.0" izz="0.00083" />
    </inertial>
    <visual>
      <origin xyz="0 0 0" rpy="0 0 0" />
      <geometry>
        <mesh filename="../../meshes/l_hand_yaw.STL" />
      </geometry>
      <material name="">
        <color rgba="1 1 1 1" />
      </material>
    </visual>
  </link>
  <joint name="zarm_l5_joint" type="revolute">
    <origin xyz="-0.0200000000000025 0 -0.127037274261591" rpy="0 0 0" />
    <parent link="zarm_l4_link" />
    <child link="zarm_l5_link" />
    <axis xyz="0 0 1" />
    <limit lower="-1.657" upper="1.657" effort="4.5" velocity="2.198" />
    <dynamics damping="0.2" friction="0.0" />
  </joint>
  <transmission type="SimpleTransmission">
    <joint name="zarm_l5_joint" />
    <actuator name="zarm_l5_joint_motor" />
  </transmission>
  <link name="zarm_l6_link">
    <inertial>
      <origin xyz="-0.00111 0.00335 -0.01335" rpy="0 0 0" />
      <mass value="0.331" />
      <inertia ixx="0.00022" ixy="0.0" ixz="0.0" iyy="0.00027" iyz="0.0" izz="0.00028" />
    </inertial>
    <visual>
      <origin xyz="0 0 0" rpy="0 0 0" />
      <geometry>
        <mesh filename="../../meshes/l_hand_roll.STL" />
      </geometry>
      <material name="">
        <color rgba="1 1 1 1" />
      </material>
    </visual>
  </link>
  <joint name="zarm_l6_joint" type="revolute">
    <origin xyz="0.000199999999999079 0 -0.106462725738415" rpy="0 0 0" />
    <parent link="zarm_l5_link" />
    <child link="zarm_l6_link" />
    <axis xyz="1 0 0" />
    <limit lower="-1.57" upper="1.57" effort="6.5" velocity="2.198" />
    <dynamics damping="0.2" friction="0.0" />
  </joint>
  <transmission type="SimpleTransmission">
    <joint name="zarm_l6_joint" />
    <actuator name="zarm_l6_joint_motor" />
  </transmission>
  <link name="zarm_l7_link">
    <inertial>
      <origin xyz="0.00186 0.01014 -0.09044" rpy="0 0 0" />
      <mass value="0.64" />
      <inertia ixx="0.00071" ixy="1e-05" ixz="2e-05" iyy="0.0007" iyz="-4e-05" izz="0.00012" />
    </inertial>
    <visual>
      <origin xyz="0 0 0" rpy="0 0 0" />
      <geometry>
        <mesh filename="../../meshes/l_hand_pitch.STL" />
      </geometry>
      <material name="">
        <color rgba="1 1 1 1" />
      </material>
    </visual>
  </link>
  <joint name="zarm_l7_joint" type="revolute">
    <origin xyz="0 0 -0.0210004653879916" rpy="0 0 0" />
    <parent link="zarm_l6_link" />
    <child link="zarm_l7_link" />
    <axis xyz="0 1 0" />
    <limit lower="-1.657" upper="1.657" effort="5.5" velocity="2.198" />
    <dynamics damping="0.2" friction="0.0" />
  </joint>
  <transmission type="SimpleTransmission">
    <joint name="zarm_l7_joint" />
    <actuator name="zarm_l7_joint_motor" />
  </transmission>
  <link name="zarm_r1_link">
    <inertial>
      <origin xyz="-0.00083 0.02218 0.00035" rpy="0 0 0" />
      <mass value="0.962" />
      <inertia ixx="0.00225" ixy="3e-05" ixz="0.0" iyy="0.00099" iyz="2e-05" izz="0.00227" />
    </inertial>
    <visual>
      <origin xyz="0 0 0" rpy="0 0 0" />
      <geometry>
        <mesh filename="../../meshes/r_arm_pitch.STL" />
      </geometry>
      <material name="">
        <color rgba="1 1 1 1" />
      </material>
    </visual>
  </link>
  <joint name="zarm_r1_joint" type="revolute">
    <origin xyz="-0.02250000 -0.28970000 0.20400000" rpy="0 0 0" />
    <parent link="base_link" />
    <child link="zarm_r1_link" />
    <axis xyz="0 1 0" />
    <limit lower="-2.0933" upper="0.5233" effort="7.5" velocity="2.198" />
    <dynamics damping="0.2" friction="0.0" />
  </joint>
  <transmission type="SimpleTransmission">
    <joint name="zarm_r1_joint" />
    <actuator name="zarm_r1_joint_motor" />
  </transmission>
  <link name="zarm_r2_link">
    <inertial>
      <origin xyz="-0.00791 0.0 -0.04655" rpy="0 0 0" />
      <mass value="0.57" />
      <inertia ixx="0.00163" ixy="0.0" ixz="5e-05" iyy="0.00211" iyz="0.0" izz="0.00122" />
    </inertial>
    <visual>
      <origin xyz="0 0 0" rpy="0 0 0" />
      <geometry>
        <mesh filename="../../meshes/r_arm_roll.STL" />
      </geometry>
      <material name="">
        <color rgba="1 1 1 1" />
      </material>
    </visual>
  </link>
  <joint name="zarm_r2_joint" type="revolute">
    <origin xyz="0 0 0" rpy="0 0 0" />
    <parent link="zarm_r1_link" />
    <child link="zarm_r2_link" />
    <axis xyz="1 0 0" />
    <limit lower="-0.3489" upper="2.0933" effort="8.5" velocity="2.198" />
    <dynamics damping="0.2" friction="0.0" />
  </joint>
  <transmission type="SimpleTransmission">
    <joint name="zarm_r2_joint" />
    <actuator name="zarm_r2_joint_motor" />
  </transmission>
  <link name="zarm_r3_link">
    <inertial>
      <origin xyz="0.00628 -0.00107 -0.20878" rpy="0 0 0" />
      <mass value="1.65" />
      <inertia ixx="0.00815" ixy="4e-05" ixz="0.00085" iyy="0.00828" iyz="-0.00014" izz="0.00206" />
    </inertial>
    <visual>
      <origin xyz="0 0 0" rpy="0 0 0" />
      <geometry>
        <mesh filename="../../meshes/r_arm_yaw.STL" />
      </geometry>
      <material name="">
        <color rgba="1 1 1 1" />
      </material>
    </visual>
  </link>
  <joint name="zarm_r3_joint" type="revolute">
    <origin xyz="0 0 0" rpy="0 0 0" />
    <parent link="zarm_r2_link" />
    <child link="zarm_r3_link" />
    <axis xyz="0 0 1" />
    <limit lower="-1.57" upper="1.57" effort="9.5" velocity="2.198" />
    <dynamics damping="0.2" friction="0.0" />
  </joint>
  <transmission type="SimpleTransmission">
    <joint name="zarm_r3_joint" />
    <actuator name="zarm_r3_joint_motor" />
  </transmission>
  <link name="zarm_r4_link">
    <inertial>
      <origin xyz="-0.01611 -0.00143 -0.04857" rpy="0 0 0" />
      <mass value="0.429" />
      <inertia ixx="0.00135" ixy="0.0" ixz="-0.0001" iyy="0.00114" iyz="0.0" izz="0.00083" />
    </inertial>
    <visual>
      <origin xyz="0 0 0" rpy="0 0 0" />
      <geometry>
        <mesh filename="../../meshes/r_foream.STL" />
      </geometry>
      <material name="">
        <color rgba="1 1 1 1" />
      </material>
    </visual>
  </link>
  <joint name="zarm_r4_joint" type="revolute">
    <origin xyz="0.0200000000000024 0 -0.2837" rpy="0 0 0" />
    <parent link="zarm_r3_link" />
    <child link="zarm_r4_link" />
    <axis xyz="0 1 0" />
    <limit lower="-1.518" upper="1.518" effort="10" velocity="2.0" />
    <dynamics damping="0.2" friction="0.0" />
  </joint>
  <transmission type="SimpleTransmission">
    <joint name="zarm_r4_joint" />
    <actuator name="zarm_r4_joint_motor" />
  </transmission>
  <link name="zarm_r5_link">
    <inertial>
      <origin xyz="-0.00207 -0.00018 -0.05079" rpy="0 0 0" />
      <mass value="0.61" />
      <inertia ixx="0.00107" ixy="0.0" ixz="-4e-05" iyy="0.00146" iyz="0.0" izz="0.00083" />
    </inertial>
    <visual>
      <origin xyz="0 0 0" rpy="0 0 0" />
      <geometry>
        <mesh filename="../../meshes/r_hand_yaw.STL" />
      </geometry>
      <material name="">
        <color rgba="1 1 1 1" />
      </material>
    </visual>
  </link>
  <joint name="zarm_r5_joint" type="revolute">
    <origin xyz="-0.0200000000000001 0 -0.127037274261587" rpy="0 0 0" />
    <parent link="zarm_r4_link" />
    <child link="zarm_r5_link" />
    <axis xyz="0 0 1" />
    <limit lower="-1.657" upper="1.657" effort="11.5" velocity="2.198" />
    <dynamics damping="0.2" friction="0.0" />
  </joint>
  <transmission type="SimpleTransmission">
    <joint name="zarm_r5_joint" />
    <actuator name="zarm_r5_joint_motor" />
  </transmission>
  <link name="zarm_r6_link">
    <inertial>
      <origin xyz="-0.00111 -0.00335 -0.01335" rpy="0 0 0" />
      <mass value="0.331" />
      <inertia ixx="0.00022" ixy="0.0" ixz="0.0" iyy="0.00027" iyz="0.0" izz="0.00028" />
    </inertial>
    <visual>
      <origin xyz="0 0 0" rpy="0 0 0" />
      <geometry>
        <mesh filename="../../meshes/r_hand_roll.STL" />
      </geometry>
      <material name="">
        <color rgba="1 1 1 1" />
      </material>
    </visual>
  </link>
  <joint name="zarm_r6_joint" type="revolute">
    <origin xyz="0 0 -0.106462725738415" rpy="0 0 0" />
    <parent link="zarm_r5_link" />
    <child link="zarm_r6_link" />
    <axis xyz="1 0 0" />
    <limit lower="-1.57" upper="1.57" effort="13.5" velocity="2.198" />
    <dynamics damping="0.2" friction="0.0" />
  </joint>
  <transmission type="SimpleTransmission">
    <joint name="zarm_r6_joint" />
    <actuator name="zarm_r6_joint_motor" />
  </transmission>
  <link name="zarm_r7_link">
    <inertial>
      <origin xyz="0.00186 -0.01014 -0.09044" rpy="0 0 0" />
      <mass value="0.64" />
      <inertia ixx="0.00069" ixy="-1e-05" ixz="2e-05" iyy="0.00068" iyz="5e-05" izz="0.00012" />
    </inertial>
    <visual>
      <origin xyz="0 0 0" rpy="0 0 0" />
      <geometry>
        <mesh filename="../../meshes/r_hand_pitch.STL" />
      </geometry>
      <material name="">
        <color rgba="1 1 1 1" />
      </material>
    </visual>
  </link>
  <joint name="zarm_r7_joint" type="revolute">
    <origin xyz="0 0 -0.0209999999999999" rpy="0 0 0" />
    <parent link="zarm_r6_link" />
    <child link="zarm_r7_link" />
    <axis xyz="0 1 0" />
    <limit lower="-1.657" upper="1.657" effort="12.5" velocity="2.198" />
    <dynamics damping="0.2" friction="0.0" />
  </joint>
  <transmission type="SimpleTransmission">
    <joint name="zarm_r7_joint" />
    <actuator name="zarm_r7_joint_motor" />
  </transmission>
  <link name="zhead_1_link">
    <inertial>
      <origin xyz="-0.00012661 0.00876748 0.01122625" rpy="0 0 0" />
      <mass value="1.06289355" />
      <inertia ixx="0.0023901" ixy="6.1e-05" ixz="-1.8e-05" iyy="0.00208785" iyz="-0.00026293" izz="0.00077419" />
    </inertial>
    <visual>
      <origin xyz="0 0 0" rpy="0 0 0" />
      <geometry>
        <mesh filename="../../meshes/head_yaw.STL" />
      </geometry>
      <material name="">
        <color rgba="1 1 1 1" />
      </material>
    </visual>
  </link>
  <joint name="zhead_1_joint" type="revolute">
    <origin xyz="-0.02250000 0.0 0.38440000" rpy="0 0 0" />
    <parent link="base_link" />
    <child link="zhead_1_link" />
    <axis xyz="0 0 1" />
    <limit lower="-1.57" upper="1.57" effort="15.5" velocity="2.198" />
    <dynamics damping="0.2" friction="0.0" />
  </joint>
  <transmission type="SimpleTransmission">
    <joint name="zhead_1_joint" />
    <actuator name="zhead_1_joint_motor" />
  </transmission>
  <link name="zhead_2_link">
    <inertial>
      <origin xyz="0.03750799 -0.00034616 0.07726513" rpy="0 0 0" />
      <mass value="0.20029579" />
      <inertia ixx="0.00093337" ixy="-2.3e-05" ixz="-0.00020762" iyy="0.00056" iyz="-4.7e-05" izz="0.00061831" />
    </inertial>
    <visual>
      <origin xyz="0 0 0" rpy="0 0 0" />
      <geometry>
        <mesh filename="../../meshes/head_pitch.STL" />
      </geometry>
      <material name="">
        <color rgba="1 1 1 1" />
      </material>
    </visual>
  </link>
  <joint name="zhead_2_joint" type="revolute">
    <origin xyz="0 0 0" rpy="0 0 0" />
    <parent link="zhead_1_link" />
    <child link="zhead_2_link" />
    <axis xyz="0 1 0" />
    <limit lower="-0.526" upper="0.526" effort="14.5" velocity="2.198" />
    <dynamics damping="0.2" friction="0.0" />
  </joint>
  <transmission type="SimpleTransmission">
    <joint name="zhead_2_joint" />
    <actuator name="zhead_2_joint_motor" />
  </transmission>
  <link name="camera">
    <inertial>
      <origin xyz="-0.0109467295615343 -0.00025332024893314 0.000333522154238597" rpy="0 0 0" />
      <mass value="1e-6" />
      <inertia ixx="1e-6" ixy="0" ixz="0" iyy="1e-6" iyz="0" izz="1e-6" />
    </inertial>
    <visual>
      <origin xyz="0 0 0" rpy="0 0 0" />
      <geometry>
        <mesh filename="../../meshes/camera.STL" />
      </geometry>
      <material name="">
        <color rgba="1 1 1 1" />
      </material>
    </visual>
  </link>
  <joint name="camera" type="fixed">
    <origin xyz="0.094395257832706 0 0.11395418930214" rpy="0 0.310766624316135 0" />
    <parent link="zhead_2_link" />
    <child link="camera" />
  </joint>
  <link name="radar">
    <inertial>
      <origin xyz="-0.000185053261368732 7.99053325137813E-06 0.0177696265681251" rpy="0 0 0" />
      <mass value="1e-6" />
      <inertia ixx="1e-6" ixy="0" ixz="0" iyy="1e-6" iyz="0" izz="1e-6" />
    </inertial>
    <visual>
      <origin xyz="0 0 0" rpy="0 0 0" />
      <geometry>
        <mesh filename="../../meshes/radar.STL" />
      </geometry>
      <material name="">
        <color rgba="1 1 1 1" />
      </material>
    </visual>
  </link>
  <joint name="radar" type="fixed">
    <origin xyz="0 0 -0.0264531741828733" rpy="0 0 0" />
    <parent link="zhead_1_link" />
    <child link="radar" />
  </joint>
</robot>
