<?xml version='1.0' encoding='utf-8'?>
<mujoco model="biped_s200049">
  <compiler angle="radian" meshdir="../meshes/" />
  <size njmax="500" nconmax="100" />
  <default>
    <joint type="hinge" armature="0.0001" damping="0.2" frictionloss="0.01"/>
    <geom condim="4" friction="1 1 1 " solref="1e-3 1" solimp=".99 .99 .01"/>
    <default class="visual">
    <geom contype="1" conaffinity="1"/>
    </default>
    </default>
    <visual>
    <map znear="0.01" zfar="50"/>
    </visual>
  <asset>
    <mesh name="torso" file="torso.STL" />
    <mesh name="l_leg_roll" file="l_leg_roll.STL" />
    <mesh name="l_leg_yaw" file="l_leg_yaw.STL" />
    <mesh name="l_leg_pitch" file="l_leg_pitch.STL" />
    <mesh name="l_knee" file="l_knee.STL" />
    <mesh name="l_foot_pitch" file="l_foot_pitch.STL" />
    <mesh name="l_foot_roll" file="l_foot_roll.STL" />
    <mesh name="r_leg_roll" file="r_leg_roll.STL" />
    <mesh name="r_leg_yaw" file="r_leg_yaw.STL" />
    <mesh name="r_leg_pitch" file="r_leg_pitch.STL" />
    <mesh name="r_knee" file="r_knee.STL" />
    <mesh name="r_foot_pitch" file="r_foot_pitch.STL" />
    <mesh name="r_foot_roll" file="r_foot_roll.STL" />
    <mesh name="l_arm_pitch" file="l_arm_pitch.STL" />
    <mesh name="l_arm_roll" file="l_arm_roll.STL" />
    <mesh name="l_arm_yaw" file="l_arm_yaw.STL" />
    <mesh name="l_forearm" file="l_forearm.STL" />
    <mesh name="l_hand_yaw" file="l_hand_yaw.STL" />
    <mesh name="l_hand_roll" file="l_hand_roll.STL" />
    <mesh name="l_hand_pitch" file="l_hand_pitch.STL" />
   
    <mesh name="r_arm_pitch" file="r_arm_pitch.STL" />
    <mesh name="r_arm_roll" file="r_arm_roll.STL" />
    <mesh name="r_arm_yaw" file="r_arm_yaw.STL" />
    <mesh name="r_forearm" file="r_forearm.STL" />
    <mesh name="r_hand_yaw" file="r_hand_yaw.STL" />
    <mesh name="r_hand_roll" file="r_hand_roll.STL" />
    <mesh name="r_hand_pitch" file="r_hand_pitch.STL" />

    <mesh name="head_yaw" file="head_yaw.STL" />
    <mesh name="head_pitch" file="head_pitch.STL" />
    <mesh name="camera" file="camera.STL" />
    <mesh name="radar" file="radar.STL" />

     <!-- 左手夹爪网格定义 -->
    <mesh name="l_f_bar-1" content_type="model/stl" file="l_f_bar-1.STL"/>
    <mesh name="l_f_bar-2" content_type="model/stl" file="l_f_bar-2.STL"/>
    <mesh name="l_f_bar-3" content_type="model/stl" file="l_f_bar-3.STL"/>
    <mesh name="l_f_fingers" content_type="model/stl" file="l_f_fingers.STL"/>
    <mesh name="l_b_bar-1" content_type="model/stl" file="l_b_bar-1.STL"/>
    <mesh name="l_b_bar-2" content_type="model/stl" file="l_b_bar-2.STL"/>
    <mesh name="l_b_bar-3" content_type="model/stl" file="l_b_bar-3.STL"/>
    <mesh name="l_b_fingers" content_type="model/stl" file="l_b_fingers.STL"/>
    
    <!-- 右手夹爪网格定义 -->
    <mesh name="r_f_bar-1" content_type="model/stl" file="r_f_bar_1.STL"/>
    <mesh name="r_f_bar-2" content_type="model/stl" file="r_f_bar-2.STL"/>
    <mesh name="r_f_bar-3" content_type="model/stl" file="r_f_bar-3.STL"/>
    <mesh name="r_f_fingers" content_type="model/stl" file="r_f_finger.STL"/>
    <mesh name="r_b_bar-1" content_type="model/stl" file="r_b_bar-1.STL"/>
    <mesh name="r_b_bar-2" content_type="model/stl" file="r_b_bar-2.STL"/>
    <mesh name="r_b_bar-3" content_type="model/stl" file="r_b_bar-3.STL"/>
    <mesh name="r_b_fingers" content_type="model/stl" file="r_b_fingers.STL"/>

    <include file="./convex_dec_include/l_f_fingers_asset_include.xml"/>
    <include file="./convex_dec_include/l_b_fingers_asset_include.xml"/>
    <include file="./convex_dec_include/r_f_fingers_asset_include.xml"/>
    <include file="./convex_dec_include/r_b_fingers_asset_include.xml"/>


  </asset>
  <worldbody>
    <body name="base_link" pos="0 0 0.82">
      <freejoint />
      <site name="imu" pos="0 0 0" />
      <inertial pos="-0.0185005 0.00031952 0.192957" quat="0.998529 9.91828e-05 0.0542216 0.000479777" mass="29.5235" diaginertia="0.938886 0.825905 0.269012" />
      <geom type="mesh" contype="0" conaffinity="0" group="1" density="0" rgba="1 1 1 1" mesh="torso" />
      <body name="leg_l1_link" pos="-0.0024999 0.087 -0.066">
        <inertial pos="-0.00430148 -2.708e-05 -0.00851195" quat="-0.00722771 0.721515 -0.0299316 0.691714" mass="1.71093" diaginertia="0.00371385 0.00277076 0.00205731" />
        <joint name="leg_l1_joint" pos="0 0 0" axis="1 0 0" range="-0.314159 0.663225" actuatorfrcrange="-180 180" damping="0.2" />
        <geom type="mesh" contype="0" conaffinity="0" group="1" density="0" rgba="1 1 1 1" mesh="l_leg_roll" />
        <body name="leg_l2_link">
          <inertial pos="0 -0.00231118 -0.0906254" quat="0.60447 0.796391 -0.0128093 0.0146492" mass="0.580292" diaginertia="0.00224101 0.00148228 0.00121221" />
          <joint name="leg_l2_joint" pos="0 0 0" axis="0 0 1" range="-0.872665 0.785398" actuatorfrcrange="-100 100" damping="0.2" />
          <geom type="mesh" contype="0" conaffinity="0" group="1" density="0" rgba="1 1 1 1" mesh="l_leg_yaw" />
          <body name="leg_l3_link" pos="0.000500355 -0.001 -0.1287">
            <inertial pos="0.00150537 0.0119961 -0.0841162" quat="0.783717 0.018124 -0.0364866 0.619781" mass="4.50393" diaginertia="0.0396246 0.0389355 0.00980214" />
            <joint name="leg_l3_joint" pos="0 0 0" axis="0 1 0" range="-2.00713 1.5708" actuatorfrcrange="-100 100" damping="0.2" />
            <geom type="mesh" contype="0" conaffinity="0" group="1" density="0" rgba="1 1 1 1" mesh="l_leg_pitch" />
            <body name="leg_l4_link" pos="-6.87185e-05 0 -0.284">
              <inertial pos="0.00696242 5.314e-05 -0.115499" quat="0.996962 -0.00107009 -0.00265467 -0.0778332" mass="1.62777" diaginertia="0.0124431 0.0122921 0.000978995" />
              <joint name="leg_l4_joint" pos="0 0 0" axis="0 1 0" range="0 2.53073" actuatorfrcrange="-180 180" damping="0.2" />
              <geom type="mesh" contype="0" conaffinity="0" group="1" density="0" rgba="1 1 1 1" mesh="l_knee" />
              <body name="leg_l5_link" pos="-0.000431636 0 -0.346">
                <inertial pos="0 0 0" mass="0.0719352" diaginertia="6.9e-05 6.9e-05 1.218e-05" />
                <joint name="leg_l5_joint" pos="0 0 0" axis="0 1 0" range="-0.872665 0.349066" actuatorfrcrange="-36 36" damping="0.2" />
                <geom type="mesh" contype="0" conaffinity="0" group="1" density="0" rgba="1 1 1 1" mesh="l_foot_pitch" />
                <body name="leg_l6_link">
                  <inertial pos="0.0373996 -2.2061e-06 -0.0389691" quat="0.0111887 0.719096 -0.00582945 0.694796" mass="0.501754" diaginertia="0.00177937 0.00163581 0.000396204" />
                  <joint name="leg_l6_joint" pos="0 0 0" axis="1 0 0" range="-0.261799 0.261799" actuatorfrcrange="-36 36" damping="0.2" />
                  <geom type="mesh" contype="0" conaffinity="0" group="1" density="0" rgba="1 1 1 1" mesh="l_foot_roll" />
                  <geom size="0.005" pos="0.17084 0.04773 -0.0595" />
                  <geom size="0.005" pos="-0.073164 0.04773 -0.0595" />
                  <geom size="0.005" pos="0.17084 -0.04773 -0.0595" />
                  <geom size="0.005" pos="-0.073164 -0.04773 -0.0595" />
                  <geom size="0.005" pos="0.17084 0 -0.0595" />
                  <geom size="0.005" pos="-0.073164 0 -0.0595" />
                </body>
              </body>
            </body>
          </body>
        </body>
      </body>
      <body name="leg_r1_link" pos="-0.0024999 -0.087 -0.066">
        <inertial pos="-0.00430146 2.709e-05 -0.00851195" quat="0.00722771 0.721515 0.0299316 0.691714" mass="1.71093" diaginertia="0.00371385 0.00277076 0.00205731" />
        <joint name="leg_r1_joint" pos="0 0 0" axis="1 0 0" range="-0.663225 0.314159" actuatorfrcrange="-180 180" damping="0.2" />
        <geom type="mesh" contype="0" conaffinity="0" group="1" density="0" rgba="1 1 1 1" mesh="r_leg_roll" />
        <body name="leg_r2_link">
          <inertial pos="0 0.00231118 -0.0906254" quat="0.796391 0.60447 0.0146492 -0.0128093" mass="0.580292" diaginertia="0.00224101 0.00148228 0.00121221" />
          <joint name="leg_r2_joint" pos="0 0 0" axis="0 0 1" range="-0.785398 0.872665" actuatorfrcrange="-100 100" damping="0.2" />
          <geom type="mesh" contype="0" conaffinity="0" group="1" density="0" rgba="1 1 1 1" mesh="r_leg_yaw" />
          <body name="leg_r3_link" pos="-4.88007e-05 0 -0.1287">
            <inertial pos="0.00208315 -0.0119964 -0.0841138" quat="0.619803 -0.0366218 0.0180205 0.783696" mass="4.50386" diaginertia="0.0396237 0.0389344 0.00980197" />
            <joint name="leg_r3_joint" pos="0 0 0" axis="0 1 0" range="-2.00713 1.5708" actuatorfrcrange="-100 100" damping="0.2" />
            <geom type="mesh" contype="0" conaffinity="0" group="1" density="0" rgba="1 1 1 1" mesh="r_leg_pitch" />
            <body name="leg_r4_link" pos="0.000147139 0 -0.284">
              <inertial pos="0.00743231 -5.343e-05 -0.115587" quat="0.996956 0.00106122 -0.00283895 0.0779016" mass="1.62656" diaginertia="0.0124166 0.0122656 0.00097885" />
              <joint name="leg_r4_joint" pos="0 0 0" axis="0 1 0" range="0 2.53073" actuatorfrcrange="-180 180" damping="0.2" />
              <geom type="mesh" contype="0" conaffinity="0" group="1" density="0" rgba="1 1 1 1" mesh="r_knee" />
              <body name="leg_r5_link" pos="0.000119806 0 -0.346">
                <inertial pos="0 0 0" mass="0.0719352" diaginertia="6.9e-05 6.9e-05 1.218e-05" />
                <joint name="leg_r5_joint" pos="0 0 0" axis="0 1 0" range="-0.872665 0.349066" actuatorfrcrange="-36 36" damping="0.2" />
                <geom type="mesh" contype="0" conaffinity="0" group="1" density="0" rgba="1 1 1 1" mesh="r_foot_pitch" />
                <body name="leg_r6_link">
                  <inertial pos="0.037413 -2.2061e-06 -0.0389563" quat="0.0111636 0.71898 -0.00585637 0.694916" mass="0.501754" diaginertia="0.00177937 0.00163581 0.000396197" />
                  <joint name="leg_r6_joint" pos="0 0 0" axis="1 0 0" range="-0.261799 0.261799" actuatorfrcrange="-36 36" damping="0.2" />
                  <geom type="mesh" contype="0" conaffinity="0" group="1" density="0" rgba="1 1 1 1" mesh="r_foot_roll" />
                  <geom size="0.005" pos="0.17084 0.04773 -0.0595" />
                  <geom size="0.005" pos="-0.073164 0.04773 -0.0595" />
                  <geom size="0.005" pos="0.17084 -0.04773 -0.0595" />
                  <geom size="0.005" pos="-0.073164 -0.04773 -0.0595" />
                  <geom size="0.005" pos="0.17084 0 -0.0595" />
                  <geom size="0.005" pos="-0.073164 0 -0.0595" />
                </body>
              </body>
            </body>
          </body>
        </body>
      </body>
      <body name="zarm_l1_link" pos="-0.0174999 0.2927 0.4245">
        <inertial pos="0.00194934 -0.01222074 -0.00024523" quat="0.507855 0.504005 -0.503768 0.484025" mass="0.95200000" diaginertia="0.00177952 0.00088093 0.00174476" />
        <joint name="zarm_l1_joint" pos="0 0 0" axis="0 1 0" range="-3.14159 1.5708" actuatorfrcrange="-100 100" damping="0.2" />
        <geom type="mesh" contype="0" conaffinity="0" group="1" density="0" rgba="1 1 1 1" mesh="l_arm_pitch" />
        <body name="zarm_l2_link">
          <inertial pos="-0.00112901 0.00000665 -0.04637050" quat="0.705843 -0.0422654 -0.0422654 0.705843" mass="0.38500000" diaginertia="0.00080437 0.00115579 0.00070010" />
          <joint name="zarm_l2_joint" pos="0 0 0" axis="1 0 0" range="-0.349066 2.0944" actuatorfrcrange="-50 50" damping="0.2" />
          <geom type="mesh" contype="0" conaffinity="0" group="1" density="0" rgba="1 1 1 1" mesh="l_arm_roll" />
          <body name="zarm_l3_link">
            <inertial pos="0.00936999 0.00334408 -0.22965779" quat="0.46857 -0.0547044 -0.0420079 0.88073" mass="1.75450000" diaginertia="0.00694471 0.00704370 0.00183829" />
            <joint name="zarm_l3_joint" pos="0 0 0" axis="0 0 1" range="-1.5708 1.5708" actuatorfrcrange="-39 39" damping="0.2" />
            <geom type="mesh" contype="0" conaffinity="0" group="1" density="0" rgba="1 1 1 1" mesh="l_arm_yaw" />
            <body name="zarm_l4_link" pos="0.02 0 -0.2837">
              <inertial pos="-0.01825634 0.00149605 -0.06877688" quat="0.99579 0 0.0916646 0" mass="0.60780000" diaginertia="0.00144524 0.00125753 0.00065063" />
              <joint name="zarm_l4_joint" pos="0 0 0" axis="0 1 0" range="-2.61799 0" actuatorfrcrange="-50 50" damping="0.2" />
              <geom type="mesh" contype="0" conaffinity="0" group="1" density="0" rgba="1 1 1 1" mesh="l_forearm" />
              <body name="zarm_l5_link" pos="-0.02 0 -0.127037">
                <inertial pos="-0.00874165 -0.00001372 -0.05033323" quat="0.70482 0.0568167 0.0568167 0.70482" mass="0.63690000" diaginertia="0.00063700 0.00094941 0.00054303" />
                <joint name="zarm_l5_joint" pos="0 0 0" axis="0 0 1" range="-1.5708 1.5708" actuatorfrcrange="-12 12" damping="0.2" />
                <geom type="mesh" contype="0" conaffinity="0" group="1" density="0" rgba="1 1 1 1" mesh="l_hand_yaw" />
                <body name="zarm_l6_link" pos="0 0 -0.106463">
                  <inertial pos="-0.00158864 0.00654094 -0.01506679" quat="0 0.707107 0 0.707107" mass="0.47390000" diaginertia="0.00018068 0.00025494 0.00026772" />
                  <joint name="zarm_l6_joint" pos="0 0 0" axis="1 0 0" range="-1.309 0.698132" actuatorfrcrange="-12 12" damping="0.2" />
                  <geom type="mesh" contype="0" conaffinity="0" group="1" density="0" rgba="1 1 1 1" mesh="l_hand_roll" />
                  <body name="zarm_l7_link" pos="0 0 -0.021">
                    <inertial pos="0.000915595 0.000230482 -0.100975" quat="0.707289 -0.0108076 0.0101588 0.706769" mass="0.522524" diaginertia="0.00109031 0.000981059 0.000278816" />
                    <joint name="zarm_l7_joint" pos="0 0 0" axis="0 1 0" range="-0.698132 0.698132" actuatorfrcrange="-12 12" damping="0.2" />
                    <geom type="mesh" contype="0" conaffinity="0" group="1" density="0" rgba="1 1 1 1" mesh="l_hand_pitch" />
                    <geom size="0.005" pos="0 -0.03 -0.17" />


                    <!-- 左手夹爪网格定义 -->
                    <body name="l_f_bar-1" pos="0.022 -0.0005 -0.1114">
                      <inertial pos="0.00725282 7.30389e-06 -0.0105238" quat="0.681328 0.190601 0.190818 0.680479" mass="0.00947618" diaginertia="2.54905e-06 2.45142e-06 6.90545e-07"/>
                      <joint name="l_f_bar-1" pos="0 0 0" axis="0 1 0" range="-0.698 0.698"/>
                      <geom type="mesh" rgba="1 1 1 1" mesh="l_f_bar-1"/>
                      
                      <body name="l_f_bar-2" pos="0.0254381 0 -0.0464963">
                        <inertial pos="-0.00783156 -3.80165e-07 -0.0147534" quat="0.959822 3.27996e-05 -0.280609 -1.7466e-05" mass="0.00339831" diaginertia="5.36424e-07 4.35206e-07 1.44855e-07"/>
                        <joint name="l_f_bar-2" pos="0 0 0" axis="0 1 0" range="-0.698 0.698"/>
                        <geom type="mesh" rgba="1 1 1 1" mesh="l_f_bar-2"/>
                        
                        <body name="l_f_fingers" pos="-0.0191549 0 -0.0292932">
                          <inertial pos="-0.0155126 -9.14842e-06 -0.0133067" quat="0.98314 0.00016864 -0.182853 0.000283624" mass="0.00951656" diaginertia="1.30492e-06 1.16036e-06 4.56037e-07"/>
                          <joint name="l_f_fingers" pos="0 0 0" axis="0 1 0" range="-0.698 0.698"/>
                          <include file="./convex_dec_include/l_f_fingers_geom_include.xml"/>
                          <body name="l_f_fingers_end" pos="-0.0105 0 0.002"></body>
                        </body>
                      </body>
                    </body>
                    
                    <body name="l_f_bar-3" pos="0.0239579 -0.0005 -0.135272">
                      <inertial pos="-0.00168674 -5.51128e-05 -0.0272296" quat="0.9985 -1.03512e-06 -0.0547471 -5.6755e-08" mass="0.00913148" diaginertia="2.12519e-06 1.59797e-06 6.56966e-07"/>
                      <joint name="l_f_bar-3" pos="0 0 0" axis="0 1 0" range="-0.698 0.698"/>
                      <geom type="mesh" rgba="1 1 1 1" mesh="l_f_bar-3"/>
                      <body name="l_f_bar-3_end" pos="-0.00618 0 -0.05"></body>
                    </body>
                    
                    <body name="l_b_bar-1" pos="-0.022 -0.0005 -0.1114">
                      <inertial pos="-0.00725282 -7.30389e-06 -0.0105238" quat="0.681328 -0.190601 -0.190818 0.680479" mass="0.00947618" diaginertia="2.54905e-06 2.45142e-06 6.90545e-07"/>
                      <joint name="l_b_bar-1" pos="0 0 0" axis="0 -1 0" range="-0.698 0.698"/>
                      <geom type="mesh" rgba="1 1 1 1" mesh="l_b_bar-1"/>
                      
                      <body name="l_b_bar-2" pos="-0.0254381 0 -0.0464963">
                        <inertial pos="0.00783156 3.80165e-07 -0.0147534" quat="0.959822 -3.27996e-05 0.280609 -1.7466e-05" mass="0.00339831" diaginertia="5.36424e-07 4.35206e-07 1.44855e-07"/>
                        <joint name="l_b_bar-2" pos="0 0 0" axis="0 -1 0" range="-0.698 0.698"/>
                        <geom type="mesh" rgba="1 1 1 1" mesh="l_b_bar-2"/>
                        
                        <body name="l_b_fingers" pos="0.0191549 0 -0.0292932">
                          <inertial pos="0.0155126 9.14842e-06 -0.0133067" quat="0.98314 -0.000168639 0.182853 0.000283631" mass="0.00951656" diaginertia="1.30492e-06 1.16036e-06 4.56037e-07"/>
                          <joint name="l_b_fingers" pos="0 0 0" axis="0 -1 0" range="-0.698 0.698"/>
                          <include file="./convex_dec_include/l_b_fingers_geom_include.xml"/>
                          <body name="l_b_fingers_end" pos="0.0105 0 0.002"></body>
                        </body>
                      </body>
                    </body>
                    
                    <body name="l_b_bar-3" pos="-0.0239579 0 -0.135272">
                      <inertial pos="0.00168674 0.000555113 -0.0272296" quat="0.9985 1.03512e-06 0.0547471 -5.6755e-08" mass="0.00913148" diaginertia="2.12519e-06 1.59797e-06 6.56966e-07"/>
                      <joint name="l_b_bar-3" pos="0 0 0" axis="0 -1 0" range="-0.698 0.698"/>
                      <geom type="mesh" rgba="1 1 1 1" mesh="l_b_bar-3"/>
                      <body name="l_b_bar-3_end" pos="0.00618 0 -0.05"></body>
                      <site type="sphere" pos="0.024 0 -0.07" size="0.015" rgba="0 0 1 1"/>
                      </body>
                  </body>
                </body>
              </body>
            </body>
          </body>
        </body>
      </body>
      <body name="zarm_r1_link" pos="-0.0174999 -0.2927 0.4245">
        <inertial pos="0.00194934 0.01222074 -0.00024523" quat="0.504005 0.507855 -0.484025 0.503768" mass="0.95200000" diaginertia="0.00177952 0.00088093 0.00174476" />
        <joint name="zarm_r1_joint" pos="0 0 0" axis="0 1 0" range="-3.14159 1.5708" actuatorfrcrange="-100 100" damping="0.2" />
        <geom type="mesh" contype="0" conaffinity="0" group="1" density="0" rgba="1 1 1 1" mesh="r_arm_pitch" />
        <body name="zarm_r2_link">
          <inertial pos="-0.00112901 -0.00000665 -0.04637050" quat="0.705843 -0.0422654 -0.0422654 0.705843" mass="0.38500000" diaginertia="0.00080437 0.00115579 0.00070010" />
          <joint name="zarm_r2_joint" pos="0 0 0" axis="1 0 0" range="-2.0944 0.349066" actuatorfrcrange="-50 50" damping="0.2" />
          <geom type="mesh" contype="0" conaffinity="0" group="1" density="0" rgba="1 1 1 1" mesh="r_arm_roll" />
          <body name="zarm_r3_link">
            <inertial pos="0.00936999 -0.00334408 -0.22965779" quat="0.88073 -0.0420079 -0.0547044 0.46857" mass="1.75450000" diaginertia="0.00694471 0.00704370 0.00183829" />
            <joint name="zarm_r3_joint" pos="0 0 0" axis="0 0 1" range="-1.5708 1.5708" actuatorfrcrange="-39 39" damping="0.2" />
            <geom type="mesh" contype="0" conaffinity="0" group="1" density="0" rgba="1 1 1 1" mesh="r_arm_yaw" />
            <body name="zarm_r4_link" pos="0.02 0 -0.2837">
              <inertial pos="-0.01825634 -0.00149605 -0.06877688" quat="0.99579 0 0.0916646 0" mass="0.60780000" diaginertia="0.00144524 0.00125753 0.00065063" />
              <joint name="zarm_r4_joint" pos="0 0 0" axis="0 1 0" range="-2.61799 0" actuatorfrcrange="-50 50" damping="0.2" />
              <geom type="mesh" contype="0" conaffinity="0" group="1" density="0" rgba="1 1 1 1" mesh="r_forearm" />
              <body name="zarm_r5_link" pos="-0.02 0 -0.127037">
                <inertial pos="-0.00874165 0.00001372 -0.05033323" quat="0.70482 0.0568167 0.0568167 0.70482" mass="0.63690000" diaginertia="0.00063700 0.00094941 0.00054303" />
                <joint name="zarm_r5_joint" pos="0 0 0" axis="0 0 1" range="-1.5708 1.5708" actuatorfrcrange="-12 12" damping="0.2" />
                <geom type="mesh" contype="0" conaffinity="0" group="1" density="0" rgba="1 1 1 1" mesh="r_hand_yaw" />
                <body name="zarm_r6_link" pos="0 0 -0.106463">
                  <inertial pos="-0.00158864 -0.00654094 -0.01506679" quat="0 0.707107 0 0.707107" mass="0.47390000" diaginertia="0.00018068 0.00025494 0.00026772" />
                  <joint name="zarm_r6_joint" pos="0 0 0" axis="1 0 0" range="-0.698132 1.309" actuatorfrcrange="-12 12" damping="0.2" />
                  <geom type="mesh" contype="0" conaffinity="0" group="1" density="0" rgba="1 1 1 1" mesh="r_hand_roll" />
                  <body name="zarm_r7_link" pos="0.0002 0 -0.021">
                    <inertial pos="-0.00044998 -0.000218005 -0.100198" quat="0.70546 0.0195371 -0.00283545 0.708475" mass="0.516924" diaginertia="0.00106608 0.00095236 0.00028316" />
                    <joint name="zarm_r7_joint" pos="0 0 0" axis="0 1 0" range="-0.698132 0.698132" actuatorfrcrange="-12 12" damping="0.2" />
                    <geom type="mesh" contype="0" conaffinity="0" group="1" density="0" rgba="1 1 1 1" mesh="r_hand_pitch" />
                    <geom size="0.005" pos="0 0.03 -0.17" />
                    <!-- 右手夹爪结构 -->
                    <body name="r_f_bar-1" pos="0.022 -0.0005 -0.1114">
                      <inertial pos="0.00725282 7.30389e-06 -0.0105238" quat="0.681328 0.190601 0.190818 0.680479" mass="0.00947618" diaginertia="2.54905e-06 2.45142e-06 6.90545e-07"/>
                      <joint name="r_f_bar-1" pos="0 0 0" axis="0 1 0" range="-0.698 0.698"/>
                      <geom type="mesh" rgba="1 1 1 1" mesh="r_f_bar-1"/>
                      
                      <body name="r_f_bar-2" pos="0.0254381 0 -0.0464963">
                        <inertial pos="-0.00783156 -3.80165e-07 -0.0147534" quat="0.959822 3.27996e-05 -0.280609 -1.7466e-05" mass="0.00339831" diaginertia="5.36424e-07 4.35206e-07 1.44855e-07"/>
                        <joint name="r_f_bar-2" pos="0 0 0" axis="0 1 0" range="-0.698 0.698"/>
                        <geom type="mesh" rgba="1 1 1 1" mesh="r_f_bar-2"/>
                        
                        <body name="r_f_fingers" pos="-0.0191549 0 -0.0292932">
                          <inertial pos="-0.0155126 -9.14842e-06 -0.0133067" quat="0.98314 0.00016864 -0.182853 0.000283624" mass="0.00951656" diaginertia="1.30492e-06 1.16036e-06 4.56037e-07"/>
                          <joint name="r_f_fingers" pos="0 0 0" axis="0 1 0" range="-0.698 0.698"/>
                          <include file="./convex_dec_include/r_f_fingers_geom_include.xml"/>
                          <body name="r_f_fingers_end" pos="-0.0105 0 0.002"></body>
                        </body>
                      </body>
                    </body>
                    
                    <body name="r_f_bar-3" pos="0.0239579 -0.0005 -0.135272">
                      <inertial pos="-0.00168674 -5.51128e-05 -0.0272296" quat="0.9985 -1.03512e-06 -0.0547471 -5.6755e-08" mass="0.00913148" diaginertia="2.12519e-06 1.59797e-06 6.56966e-07"/>
                      <joint name="r_f_bar-3" pos="0 0 0" axis="0 1 0" range="-0.698 0.698"/>
                      <geom type="mesh" rgba="1 1 1 1" mesh="r_f_bar-3"/>
                      <body name="r_f_bar-3_end" pos="-0.00618 0 -0.05"></body>
                    </body>
                    
                    <body name="r_b_bar-1" pos="-0.022 -0.0005 -0.1114">
                      <inertial pos="-0.00725282 -7.30389e-06 -0.0105238" quat="0.681328 -0.190601 -0.190818 0.680479" mass="0.00947618" diaginertia="2.54905e-06 2.45142e-06 6.90545e-07"/>
                      <joint name="r_b_bar-1" pos="0 0 0" axis="0 -1 0" range="-0.698 0.698"/>
                      <geom type="mesh" rgba="1 1 1 1" mesh="r_b_bar-1"/>
                      
                      <body name="r_b_bar-2" pos="-0.0254381 0 -0.0464963">
                        <inertial pos="0.00783156 3.80165e-07 -0.0147534" quat="0.959822 -3.27996e-05 0.280609 -1.7466e-05" mass="0.00339831" diaginertia="5.36424e-07 4.35206e-07 1.44855e-07"/>
                        <joint name="r_b_bar-2" pos="0 0 0" axis="0 -1 0" range="-0.698 0.698"/>
                        <geom type="mesh" rgba="1 1 1 1" mesh="r_b_bar-2"/>
                        
                        <body name="r_b_fingers" pos="0.0191549 0 -0.0292932">
                          <inertial pos="0.0155126 9.14842e-06 -0.0133067" quat="0.98314 -0.000168639 0.182853 0.000283631" mass="0.00951656" diaginertia="1.30492e-06 1.16036e-06 4.56037e-07"/>
                          <joint name="r_b_fingers" pos="0 0 0" axis="0 -1 0" range="-0.698 0.698"/>
                          <include file="./convex_dec_include/r_b_fingers_geom_include.xml"/>
                          <body name="r_b_fingers_end" pos="0.0105 0 0.002"></body>
                        </body>
                      </body>
                    </body>
                    
                    <body name="r_b_bar-3" pos="-0.0239579 0 -0.135272">
                      <inertial pos="0.00168674 0.000555113 -0.0272296" quat="0.9985 1.03512e-06 0.0547471 -5.6755e-08" mass="0.00913148" diaginertia="2.12519e-06 1.59797e-06 6.56966e-07"/>
                      <joint name="r_b_bar-3" pos="0 0 0" axis="0 -1 0" range="-0.698 0.698"/>
                      <geom type="mesh" rgba="1 1 1 1" mesh="r_b_bar-3"/>
                      <body name="r_b_bar-3_end" pos="0.00618 0 -0.05"></body>
                      <site type="sphere" pos="0.024 0 -0.07" size="0.015" rgba="0 0 1 1"/>
                    </body>
                  </body>
                </body>
              </body>
            </body>
          </body>
        </body>
      </body>
      <body name="zhead_1_link" pos="-0.0184999 0 0.6014">
        <inertial pos="2e-05 0.00605 -0.01052" mass="0.35" diaginertia="7e-05 5e-05 5e-05" />
        <joint name="zhead_1_joint" pos="0 0 0" axis="0 0 1" range="-1.5708 1.5708" actuatorfrcrange="-1.5 1.5" damping="0.2" />
        <geom type="mesh" contype="0" conaffinity="0" group="1" density="0" rgba="1 1 1 1" mesh="head_yaw" />
        <body name="zhead_2_link">
          <inertial pos="0.0277019 -0.000890845 0.113292" quat="0.385654 -0.133514 -0.0333113 0.912324" mass="0.865" diaginertia="0.00468715 0.00458653 0.00311717" />
          <joint name="zhead_2_joint" pos="0 0 0" axis="0 1 0" range="-0.523599 0.523599" actuatorfrcrange="-12 12" damping="0.2" />
          <geom type="mesh" contype="0" conaffinity="0" group="1" density="0" rgba="1 1 1 1" mesh="head_pitch" />
          <geom pos="0.096751 0.0375003 0.125953" quat="0.970296 0 0.241922 0" type="mesh" contype="0" conaffinity="0" group="1" density="0" rgba="1 1 1 1" mesh="camera" />
          <geom pos="0.0217799 0 0.105417" quat="0.993413 0 0.114591 0" type="mesh" contype="0" conaffinity="0" group="1" density="0" rgba="1 1 1 1" mesh="radar" />
        </body>
      </body>
    </body>
  </worldbody>
  <contact>
      <exclude name="e0" body1="l_f_bar-3" body2="l_f_fingers" />
      <exclude name="e1" body1="l_f_bar-2" body2="l_f_fingers" />
      <exclude name="e2" body1="l_f_bar-1" body2="l_f_fingers" />
      <exclude name="e3" body1="l_f_bar-1" body2="l_f_bar-2" />
      <exclude name="e4" body1="l_f_bar-2" body2="l_f_bar-3" />
      <exclude name="e5" body1="l_f_bar-3" body2="l_f_bar-1" />
      <exclude name="e6" body1="l_b_bar-3" body2="l_b_fingers" />
      <exclude name="e7" body1="l_b_bar-2" body2="l_b_fingers" />
      <exclude name="e8" body1="l_b_bar-1" body2="l_b_fingers" />
      <exclude name="e9" body1="l_b_bar-1" body2="l_b_bar-2" />
      <exclude name="e10" body1="l_b_bar-2" body2="l_b_bar-3" />
      <exclude name="e11" body1="l_b_bar-3" body2="l_b_bar-1" />
      <exclude name="e12" body1="r_f_bar-3" body2="r_f_fingers" />
      <exclude name="e13" body1="r_f_bar-2" body2="r_f_fingers" />
      <exclude name="e14" body1="r_f_bar-1" body2="r_f_fingers" />
      <exclude name="e15" body1="r_f_bar-1" body2="r_f_bar-2" />
      <exclude name="e16" body1="r_f_bar-2" body2="r_f_bar-3" />
      <exclude name="e17" body1="r_f_bar-3" body2="r_f_bar-1" />
      <exclude name="e18" body1="r_b_bar-3" body2="r_b_fingers" />
      <exclude name="e19" body1="r_b_bar-2" body2="r_b_fingers" />
      <exclude name="e20" body1="r_b_bar-1" body2="r_b_fingers" />
      <exclude name="e21" body1="r_b_bar-1" body2="r_b_bar-2" />
      <exclude name="e22" body1="r_b_bar-2" body2="r_b_bar-3" />
      <exclude name="e23" body1="r_b_bar-3" body2="r_b_bar-1" />
  </contact>

  <equality>
    <weld name="c1" body1="l_f_fingers_end" body2="l_f_bar-3_end" torquescale='0' solref='1e-4 1' solimp=".9999 .9999 .01"/>
    <weld name="c2" body1="l_b_fingers_end" body2="l_b_bar-3_end" torquescale='0' solref='1e-4 1' solimp=".9999 .9999 .01"/>
    <weld name="c3" body1="r_f_fingers_end" body2="r_f_bar-3_end" torquescale='0' solref='1e-4 1' solimp=".9999 .9999 .01"/>
    <weld name="c4" body1="r_b_fingers_end" body2="r_b_bar-3_end" torquescale='0' solref='1e-4 1' solimp=".9999 .9999 .01"/>

    <joint joint1="l_f_bar-1" joint2="l_b_bar-1" polycoef="0 1 0 0 0" solref='1e-4 1' solimp=".99 .99 .01"/>
    <joint joint1="l_f_bar-1" joint2="l_f_bar-2" polycoef="0 1 0 0 0" solref='1e-2 1' solimp=".99 .99 .01"/>
    <joint joint1="l_f_bar-1" joint2="l_f_fingers" polycoef="0 -1 0 0 0" solref='1e-2 1' solimp=".99 .99 .01"/>

    <joint joint1="l_b_bar-1" joint2="l_b_bar-2" polycoef="0 1 0 0 0" solref='1e-2 1' solimp=".99 .99 .01"/>
    <joint joint1="l_b_bar-1" joint2="l_b_fingers" polycoef="0 -1 0 0 0" solref='1e-2 1' solimp=".99 .99 .01"/>

    <joint joint1="r_f_bar-1" joint2="r_b_bar-1" polycoef="0 1 0 0 0" solref='1e-4 1' solimp=".99 .99 .01"/>
    <joint joint1="r_f_bar-1" joint2="r_f_bar-2" polycoef="0 1 0 0 0" solref='1e-2 1' solimp=".99 .99 .01"/>
    <joint joint1="r_f_bar-1" joint2="r_f_fingers" polycoef="0 -1 0 0 0" solref='1e-2 1' solimp=".99 .99 .01"/>

    <joint joint1="r_b_bar-1" joint2="r_b_bar-2" polycoef="0 1 0 0 0" solref='1e-2 1' solimp=".99 .99 .01"/>
    <joint joint1="r_b_bar-1" joint2="r_b_fingers" polycoef="0 -1 0 0 0" solref='1e-2 1' solimp=".99 .99 .01"/>


  </equality>
  <tendon>
    <fixed name="l_claw_split">
      <joint joint="l_f_bar-1" coef="0.5" />
      <joint joint="l_b_bar-1" coef="0.5" />
    </fixed>
    <fixed name="r_claw_split">
      <joint joint="r_f_bar-1" coef="0.5" />
      <joint joint="r_b_bar-1" coef="0.5" />
    </fixed>
  </tendon>
  <actuator>
    <motor gear="1" joint="leg_l1_joint" name="leg_l1_joint_motor" ctrllimited="true" ctrlrange="-180 180" />
    <motor gear="1" joint="leg_l2_joint" name="leg_l2_joint_motor" ctrllimited="true" ctrlrange="-100 100" />
    <motor gear="1" joint="leg_l3_joint" name="leg_l3_joint_motor" ctrllimited="true" ctrlrange="-100 100" />
    <motor gear="1" joint="leg_l4_joint" name="leg_l4_joint_motor" ctrllimited="true" ctrlrange="-180 180" />
    <motor gear="1" joint="leg_l5_joint" name="leg_l5_joint_motor" ctrllimited="true" ctrlrange="-36 36" />
    <motor gear="1" joint="leg_l6_joint" name="leg_l6_joint_motor" ctrllimited="true" ctrlrange="-36 36" />
    <motor gear="1" joint="leg_r1_joint" name="leg_r1_joint_motor" ctrllimited="true" ctrlrange="-180 180" />
    <motor gear="1" joint="leg_r2_joint" name="leg_r2_joint_motor" ctrllimited="true" ctrlrange="-100 100" />
    <motor gear="1" joint="leg_r3_joint" name="leg_r3_joint_motor" ctrllimited="true" ctrlrange="-100 100" />
    <motor gear="1" joint="leg_r4_joint" name="leg_r4_joint_motor" ctrllimited="true" ctrlrange="-180 180" />
    <motor gear="1" joint="leg_r5_joint" name="leg_r5_joint_motor" ctrllimited="true" ctrlrange="-36 36" />
    <motor gear="1" joint="leg_r6_joint" name="leg_r6_joint_motor" ctrllimited="true" ctrlrange="-36 36" />
    <motor gear="1" joint="zarm_l1_joint" name="zarm_l1_joint_motor" ctrllimited="true" ctrlrange="-100 100" />
    <motor gear="1" joint="zarm_l2_joint" name="zarm_l2_joint_motor" ctrllimited="true" ctrlrange="-50 50" />
    <motor gear="1" joint="zarm_l3_joint" name="zarm_l3_joint_motor" ctrllimited="true" ctrlrange="-39 39" />
    <motor gear="1" joint="zarm_l4_joint" name="zarm_l4_joint_motor" ctrllimited="true" ctrlrange="-50 50" />
    <motor gear="1" joint="zarm_l5_joint" name="zarm_l5_joint_motor" ctrllimited="true" ctrlrange="-12 12" />
    <motor gear="1" joint="zarm_l6_joint" name="zarm_l6_joint_motor" ctrllimited="true" ctrlrange="-12 12" />
    <motor gear="1" joint="zarm_l7_joint" name="zarm_l7_joint_motor" ctrllimited="true" ctrlrange="-12 12" />
    <motor gear="1" joint="zarm_r1_joint" name="zarm_r1_joint_motor" ctrllimited="true" ctrlrange="-100 100" />
    <motor gear="1" joint="zarm_r2_joint" name="zarm_r2_joint_motor" ctrllimited="true" ctrlrange="-50 50" />
    <motor gear="1" joint="zarm_r3_joint" name="zarm_r3_joint_motor" ctrllimited="true" ctrlrange="-39 39" />
    <motor gear="1" joint="zarm_r4_joint" name="zarm_r4_joint_motor" ctrllimited="true" ctrlrange="-50 50" />
    <motor gear="1" joint="zarm_r5_joint" name="zarm_r5_joint_motor" ctrllimited="true" ctrlrange="-12 12" />
    <motor gear="1" joint="zarm_r6_joint" name="zarm_r6_joint_motor" ctrllimited="true" ctrlrange="-12 12" />
    <motor gear="1" joint="zarm_r7_joint" name="zarm_r7_joint_motor" ctrllimited="true" ctrlrange="-12 12" />
    <motor gear="1" joint="zhead_1_joint" name="zhead_1_joint_motor" ctrllimited="true" ctrlrange="-1.5 1.5" />
    <motor gear="1" joint="zhead_2_joint" name="zhead_2_joint_motor" ctrllimited="true" ctrlrange="-12 12" />
  </actuator>

  <actuator>
    <general biastype="affine" name="l_fingers_actuator" tendon="l_claw_split"
      forcerange="-100 100" ctrlrange="-100 0"
      gainprm="1 0 0" biasprm="0 -100 -5"/>
    <general biastype="affine" name="r_fingers_actuator" tendon="r_claw_split"
      forcerange="-100 100" ctrlrange="-100 0"
      gainprm="1 0 0" biasprm="0 -100 -5"/>

  </actuator>
  
  <sensor>
    <accelerometer name="BodyAcc" site="imu" />
    <velocimeter name="BodyVel" site="imu" />
    <gyro name="BodyGyro" site="imu" />
    <framepos name="BodyPos" objtype="site" objname="imu" />
    <framequat name="BodyQuat" objtype="site" objname="imu" />
    <jointpos name="leg_l1_joint_pos" joint="leg_l1_joint" />
    <jointpos name="leg_l2_joint_pos" joint="leg_l2_joint" />
    <jointpos name="leg_l3_joint_pos" joint="leg_l3_joint" />
    <jointpos name="leg_l4_joint_pos" joint="leg_l4_joint" />
    <jointpos name="leg_l5_joint_pos" joint="leg_l5_joint" />
    <jointpos name="leg_l6_joint_pos" joint="leg_l6_joint" />
    <jointpos name="leg_r1_joint_pos" joint="leg_r1_joint" />
    <jointpos name="leg_r2_joint_pos" joint="leg_r2_joint" />
    <jointpos name="leg_r3_joint_pos" joint="leg_r3_joint" />
    <jointpos name="leg_r4_joint_pos" joint="leg_r4_joint" />
    <jointpos name="leg_r5_joint_pos" joint="leg_r5_joint" />
    <jointpos name="leg_r6_joint_pos" joint="leg_r6_joint" />
    <jointpos name="zarm_l1_joint_pos" joint="zarm_l1_joint" />
    <jointpos name="zarm_l2_joint_pos" joint="zarm_l2_joint" />
    <jointpos name="zarm_l3_joint_pos" joint="zarm_l3_joint" />
    <jointpos name="zarm_l4_joint_pos" joint="zarm_l4_joint" />
    <jointpos name="zarm_l5_joint_pos" joint="zarm_l5_joint" />
    <jointpos name="zarm_l6_joint_pos" joint="zarm_l6_joint" />
    <jointpos name="zarm_l7_joint_pos" joint="zarm_l7_joint" />
    <jointpos name="zarm_r1_joint_pos" joint="zarm_r1_joint" />
    <jointpos name="zarm_r2_joint_pos" joint="zarm_r2_joint" />
    <jointpos name="zarm_r3_joint_pos" joint="zarm_r3_joint" />
    <jointpos name="zarm_r4_joint_pos" joint="zarm_r4_joint" />
    <jointpos name="zarm_r5_joint_pos" joint="zarm_r5_joint" />
    <jointpos name="zarm_r6_joint_pos" joint="zarm_r6_joint" />
    <jointpos name="zarm_r7_joint_pos" joint="zarm_r7_joint" />
    <jointpos name="zhead_1_joint_pos" joint="zhead_1_joint" />
    <jointpos name="zhead_2_joint_pos" joint="zhead_2_joint" />
    <jointvel name="leg_l1_joint_vel" joint="leg_l1_joint" />
    <jointvel name="leg_l2_joint_vel" joint="leg_l2_joint" />
    <jointvel name="leg_l3_joint_vel" joint="leg_l3_joint" />
    <jointvel name="leg_l4_joint_vel" joint="leg_l4_joint" />
    <jointvel name="leg_l5_joint_vel" joint="leg_l5_joint" />
    <jointvel name="leg_l6_joint_vel" joint="leg_l6_joint" />
    <jointvel name="leg_r1_joint_vel" joint="leg_r1_joint" />
    <jointvel name="leg_r2_joint_vel" joint="leg_r2_joint" />
    <jointvel name="leg_r3_joint_vel" joint="leg_r3_joint" />
    <jointvel name="leg_r4_joint_vel" joint="leg_r4_joint" />
    <jointvel name="leg_r5_joint_vel" joint="leg_r5_joint" />
    <jointvel name="leg_r6_joint_vel" joint="leg_r6_joint" />
    <jointvel name="zarm_l1_joint_vel" joint="zarm_l1_joint" />
    <jointvel name="zarm_l2_joint_vel" joint="zarm_l2_joint" />
    <jointvel name="zarm_l3_joint_vel" joint="zarm_l3_joint" />
    <jointvel name="zarm_l4_joint_vel" joint="zarm_l4_joint" />
    <jointvel name="zarm_l5_joint_vel" joint="zarm_l5_joint" />
    <jointvel name="zarm_l6_joint_vel" joint="zarm_l6_joint" />
    <jointvel name="zarm_l7_joint_vel" joint="zarm_l7_joint" />
    <jointvel name="zarm_r1_joint_vel" joint="zarm_r1_joint" />
    <jointvel name="zarm_r2_joint_vel" joint="zarm_r2_joint" />
    <jointvel name="zarm_r3_joint_vel" joint="zarm_r3_joint" />
    <jointvel name="zarm_r4_joint_vel" joint="zarm_r4_joint" />
    <jointvel name="zarm_r5_joint_vel" joint="zarm_r5_joint" />
    <jointvel name="zarm_r6_joint_vel" joint="zarm_r6_joint" />
    <jointvel name="zarm_r7_joint_vel" joint="zarm_r7_joint" />
    <jointvel name="zhead_1_joint_vel" joint="zhead_1_joint" />
    <jointvel name="zhead_2_joint_vel" joint="zhead_2_joint" />
  </sensor>
</mujoco>
