<?xml version='1.0' encoding='utf-8'?>
<robot name="biped_s13">
  <mujoco>
    <compiler meshdir="../meshes/" balanceinertia="true" discardvisual="false" />
  </mujoco>
  <link name="dummy_link" />
  <link name="base_link">
    <inertial>
      <origin xyz="0.0016929 0.0 -0.11846153" rpy="0 0 0" />
      <mass value="5.17438719" />
      <inertia ixx="0.02255553" ixy="0.0" ixz="0.0" iyy="0.01532955" iyz="0.0" izz="0.01667096" />
    </inertial>
    <visual>
      <origin xyz="0 0 0" rpy="0 0 0" />
      <geometry>
        <mesh filename="package://kuavo_assets/models/biped_s13/meshes/waist.STL" />
      </geometry>
      <material name="">
        <color rgba="1 1 1 1" />
      </material>
    </visual>
  </link>
  <joint name="dummy_to_base_link" type="fixed">
    <origin xyz="0 0 0" rpy="0 0 0" />
    <parent link="dummy_link" />
    <child link="base_link" />
    <dynamics damping="0.2" friction="0.0"/>
  </joint>
  <link name="waist_yaw_link">
    <inertial>
      <origin xyz="0.00227055 0.0 0.1163574" rpy="0 0 0" />
      <mass value="4.09458758" />
      <inertia ixx="0.06356019" ixy="0.0" ixz="0.0" iyy="0.05314952" iyz="0.0" izz="0.03434989" />
    </inertial>
    <visual>
      <origin xyz="0 0 0" rpy="0 0 0" />
      <geometry>
        <mesh filename="package://kuavo_assets/models/biped_s13/meshes/torso.STL" />
      </geometry>
      <material name="">
        <color rgba="1 1 1 1" />
      </material>
    </visual>
  </link>
  <joint name="waist_yaw_joint" type="revolute">
    <origin xyz="0 0 0" rpy="0 0 0" />
    <parent link="base_link" />
    <child link="waist_yaw_link" />
    <axis xyz="0 0 1" />
    <limit lower="-2.0943951023932" upper="2.0943951023932" effort="50" velocity="8.37333333333333" />
    <dynamics damping="0.2" friction="0.0"/>
  </joint>
  <link name="leg_l1_link">
    <inertial>
      <origin xyz="-0.01281625 -0.02411867 0.0242652" rpy="0 0 0" />
      <mass value="0.41179806" />
      <inertia ixx="0.00053434" ixy="-1.716e-05" ixz="1.637e-05" iyy="0.00095375" iyz="6.321e-05" izz="0.00095062" />
    </inertial>
    <visual>
      <origin xyz="0 0 0" rpy="0 0 0" />
      <geometry>
        <mesh filename="package://kuavo_assets/models/biped_s13/meshes/l_leg_pitch.STL" />
      </geometry>
      <material name="">
        <color rgba="1 1 1 1" />
      </material>
    </visual>
  </link>
  <joint name="leg_l1_joint" type="revolute">
    <origin xyz="0.0 0.1143350698 -0.21673502307" rpy="0 0 0" />
    <parent link="base_link" />
    <child link="leg_l1_link" />
    <axis xyz="0 0.70711 -0.70711" />
    <limit lower="-1.65806278939461" upper="1.5707963267949" effort="180" velocity="23.55" />
    <dynamics damping="0.2" friction="0.0" />
  </joint>
  <link name="leg_l2_link">
    <inertial>
      <origin xyz="-0.00113407 0.00022674 -0.055039" rpy="0 0 0" />
      <mass value="2.60733021" />
      <inertia ixx="0.00748166" ixy="0.0" ixz="0.0" iyy="0.00726718" iyz="0.0" izz="0.00283326" />
    </inertial>
    <visual>
      <origin xyz="0 0 0" rpy="0 0 0" />
      <geometry>
        <mesh filename="package://kuavo_assets/models/biped_s13/meshes/l_leg_roll.STL" />
      </geometry>
      <material name="">
        <color rgba="1 1 1 1" />
      </material>
    </visual>
  </link>
  <joint name="leg_l2_joint" type="revolute">
    <origin xyz="0 0 0" rpy="0 0 0" />
    <parent link="leg_l1_link" />
    <child link="leg_l2_link" />
    <axis xyz="1 0 0" />
    <limit lower="-1.0471975511966" upper="0.847008285992848" effort="100" velocity="41.3433333333333" />
    <dynamics damping="0.2" friction="0.0" />
  </joint>
  <link name="leg_l3_link">
    <inertial>
      <origin xyz="-0.01486413 -0.00438159 -0.17562576" rpy="0 0 0" />
      <mass value="1.03798929" />
      <inertia ixx="0.00130665" ixy="0.0" ixz="0.0" iyy="0.00143771" iyz="0.0" izz="0.00092289" />
    </inertial>
    <visual>
      <origin xyz="0 0 0" rpy="0 0 0" />
      <geometry>
        <mesh filename="package://kuavo_assets/models/biped_s13/meshes/l_leg_yaw.STL" />
      </geometry>
      <material name="">
        <color rgba="1 1 1 1" />
      </material>
    </visual>
  </link>
  <joint name="leg_l3_joint" type="revolute">
    <origin xyz="0 0 0" rpy="0 0 0" />
    <parent link="leg_l2_link" />
    <child link="leg_l3_link" />
    <axis xyz="0 0 1" />
    <limit lower="-1.91986217719376" upper="0.878424212528746" effort="100" velocity="41.3433333333333" />
    <dynamics damping="0.2" friction="0.0" />
  </joint>
  <link name="leg_l4_link">
    <inertial>
      <origin xyz="0.02276414 0.00634133 -0.09717249" rpy="0 0 0" />
      <mass value="1.78407172" />
      <inertia ixx="0.00775509" ixy="0.0" ixz="0.0" iyy="0.00820174" iyz="0.0" izz="0.00156093" />
    </inertial>
    <visual>
      <origin xyz="0 0 0" rpy="0 0 0" />
      <geometry>
        <mesh filename="package://kuavo_assets/models/biped_s13/meshes/l_knee.STL" />
      </geometry>
      <material name="">
        <color rgba="1 1 1 1" />
      </material>
    </visual>
  </link>
  <joint name="leg_l4_joint" type="revolute">
    <origin xyz="-0.021 0 -0.182" rpy="0 0 0" />
    <parent link="leg_l3_link" />
    <child link="leg_l4_link" />
    <axis xyz="0 1 0" />
    <limit lower="0.0" upper="2.61799387799149" effort="180" velocity="23.55" />
    <dynamics damping="0.2" friction="0.0" />
  </joint>
  <link name="leg_l5_link">
    <inertial>
      <origin xyz="0.0 0.0 0.0" rpy="0 0 0" />
      <mass value="0.06923766" />
      <inertia ixx="6.7e-04" ixy="0.0" ixz="0.0" iyy="6.7e-04" iyz="0.0" izz="1.172e-04" />
    </inertial>
    <visual>
      <origin xyz="0 0 0" rpy="0 0 0" />
      <geometry>
        <mesh filename="package://kuavo_assets/models/biped_s13/meshes/l_foot_pitch.STL" />
      </geometry>
      <material name="">
        <color rgba="1 1 1 1" />
      </material>
    </visual>
  </link>
  <joint name="leg_l5_joint" type="revolute">
    <origin xyz="0.021 0 -0.235" rpy="0 0 0" />
    <parent link="leg_l4_link" />
    <child link="leg_l5_link" />
    <axis xyz="0 1 0" />
    <limit lower="-0.872664625997165" upper="0.523598775598299" effort="36" velocity="23.0266666666667" />
    <dynamics damping="0.2" friction="0.0" />
  </joint>
  <link name="leg_l6_link">
    <inertial>
      <origin xyz="-0.00076721 2.797e-05 -0.02337788" rpy="0 0 0" />
      <mass value="0.38565431" />
      <inertia ixx="0.00026927" ixy="0.0" ixz="0.0" iyy="0.00114572" iyz="0.0" izz="0.00129886" />
    </inertial>
    <visual>
      <origin xyz="0 0 0" rpy="0 0 0" />
      <geometry>
        <mesh filename="package://kuavo_assets/models/biped_s13/meshes/l_foot_roll_big.STL" />
      </geometry>
      <material name="">
        <color rgba="1 1 1 1" />
      </material>
    </visual>
  </link>
  <joint name="leg_l6_joint" type="revolute">
    <origin xyz="0 0 0" rpy="0 0 0" />
    <parent link="leg_l5_link" />
    <child link="leg_l6_link" />
    <axis xyz="1 0 0" />
    <limit lower="-0.261799387799149" upper="0.261799387799149" effort="36" velocity="23.0266666666667" />
    <dynamics damping="0.2" friction="0.0" />
  </joint>
  <link name="ll_foot_toe">
    <collision>
      <origin rpy="0 0 0" xyz="0 0 0" />
      <geometry>
        <sphere radius="0.005" />
      </geometry>
    </collision>
  </link>
  <joint name="ll_foot_toe_joint" type="fixed">
    <origin xyz="0.126 0.05 -0.0435" rpy="0 0 0" />
    <parent link="leg_l6_link" />
    <child link="ll_foot_toe" />
  </joint>
  <link name="ll_foot_heel">
    <collision>
      <origin rpy="0 0 0" xyz="0 0 0" />
      <geometry>
        <sphere radius="0.005" />
      </geometry>
    </collision>
  </link>
  <joint name="ll_foot_heel_joint" type="fixed">
    <origin xyz="-0.089 0.05 -0.0435" rpy="0 0 0" />
    <parent link="leg_l6_link" />
    <child link="ll_foot_heel" />
  </joint>
  <link name="lr_foot_toe">
    <collision>
      <origin rpy="0 0 0" xyz="0 0 0" />
      <geometry>
        <sphere radius="0.005" />
      </geometry>
    </collision>
  </link>
  <joint name="lr_foot_toe_joint" type="fixed">
    <origin xyz="0.126 -0.05 -0.0435" rpy="0 0 0" />
    <parent link="leg_l6_link" />
    <child link="lr_foot_toe" />
  </joint>
  <link name="lr_foot_heel">
    <collision>
      <origin rpy="0 0 0" xyz="0 0 0" />
      <geometry>
        <sphere radius="0.005" />
      </geometry>
    </collision>
  </link>
  <joint name="lr_foot_heel_joint" type="fixed">
    <origin xyz="-0.089 -0.05 -0.0435" rpy="0 0 0" />
    <parent link="leg_l6_link" />
    <child link="lr_foot_heel" />
  </joint>
  <link name="l_foot_toe">
    <collision>
      <origin rpy="0 0 0" xyz="0 0 0" />
      <geometry>
        <sphere radius="0.005" />
      </geometry>
    </collision>
  </link>
  <joint name="l_foot_toe_joint" type="fixed">
    <origin xyz="0.126 0.0 -0.0435" rpy="0 0 0" />
    <parent link="leg_l6_link" />
    <child link="l_foot_toe" />
  </joint>
  <link name="l_foot_heel">
    <collision>
      <origin rpy="0 0 0" xyz="0 0 0" />
      <geometry>
        <sphere radius="0.005" />
      </geometry>
    </collision>
  </link>
  <joint name="l_foot_heel_joint" type="fixed">
    <origin xyz="-0.089 0.0 -0.0435" rpy="0 0 0" />
    <parent link="leg_l6_link" />
    <child link="l_foot_heel" />
  </joint>
  <link name="leg_r1_link">
    <inertial>
      <origin xyz="-0.01281237 0.02411826 0.02426469" rpy="0 0 0" />
      <mass value="0.4119068" />
      <inertia ixx="0.00053445" ixy="1.725e-05" ixz="1.639e-05" iyy="0.00095388" iyz="-6.324e-05" izz="0.00095076" />
    </inertial>
    <visual>
      <origin xyz="0 0 0" rpy="0 0 0" />
      <geometry>
        <mesh filename="package://kuavo_assets/models/biped_s13/meshes/r_leg_pitch.STL" />
      </geometry>
      <material name="">
        <color rgba="1 1 1 1" />
      </material>
    </visual>
  </link>
  <joint name="leg_r1_joint" type="revolute">
    <origin xyz="0.0 -0.1143350698 -0.21673502307" rpy="0 0 0" />
    <parent link="base_link" />
    <child link="leg_r1_link" />
    <axis xyz="0 -0.70711 -0.70711" />
    <limit lower="-1.65806278939461" upper="1.5707963267949" effort="180" velocity="23.55" />
    <dynamics damping="0.2" friction="0.0" />
  </joint>
  <link name="leg_r2_link">
    <inertial>
      <origin xyz="-0.00091249 -5.402e-05 -0.0552687" rpy="0 0 0" />
      <mass value="2.60770806" />
      <inertia ixx="0.00748166" ixy="0.0" ixz="0.0" iyy="0.00726718" iyz="0.0" izz="0.00283326" />
    </inertial>
    <visual>
      <origin xyz="0 0 0" rpy="0 0 0" />
      <geometry>
        <mesh filename="package://kuavo_assets/models/biped_s13/meshes/r_leg_roll.STL" />
      </geometry>
      <material name="">
        <color rgba="1 1 1 1" />
      </material>
    </visual>
  </link>
  <joint name="leg_r2_joint" type="revolute">
    <origin xyz="0 0 0" rpy="0 0 0" />
    <parent link="leg_r1_link" />
    <child link="leg_r2_link" />
    <axis xyz="1 0 0" />
    <limit lower="-1.0471975511966" upper="0.847008285992848" effort="100" velocity="41.3433333333333" />
    <dynamics damping="0.2" friction="0.0" />
  </joint>
  <link name="leg_r3_link">
    <inertial>
      <origin xyz="-0.0150602 0.00499577 -0.17454657" rpy="0 0 0" />
      <mass value="1.03798252" />
      <inertia ixx="0.00130665" ixy="0.0" ixz="0.0" iyy="0.00143771" iyz="0.0" izz="0.00092289" />
    </inertial>
    <visual>
      <origin xyz="0 0 0" rpy="0 0 0" />
      <geometry>
        <mesh filename="package://kuavo_assets/models/biped_s13/meshes/r_leg_yaw.STL" />
      </geometry>
      <material name="">
        <color rgba="1 1 1 1" />
      </material>
    </visual>
  </link>
  <joint name="leg_r3_joint" type="revolute">
    <origin xyz="0 0 0" rpy="0 0 0" />
    <parent link="leg_r2_link" />
    <child link="leg_r3_link" />
    <axis xyz="0 0 1" />
    <limit lower="-1.91986217719376" upper="0.878424212528746" effort="100" velocity="41.3433333333333" />
    <dynamics damping="0.2" friction="0.0" />
  </joint>
  <link name="leg_r4_link">
    <inertial>
      <origin xyz="0.02271993 -0.0079271 -0.09808788" rpy="0 0 0" />
      <mass value="1.78444026" />
      <inertia ixx="0.00775509" ixy="0.0" ixz="0.0" iyy="0.00820174" iyz="0.0" izz="0.00156093" />
    </inertial>
    <visual>
      <origin xyz="0 0 0" rpy="0 0 0" />
      <geometry>
        <mesh filename="package://kuavo_assets/models/biped_s13/meshes/r_knee.STL" />
      </geometry>
      <material name="">
        <color rgba="1 1 1 1" />
      </material>
    </visual>
  </link>
  <joint name="leg_r4_joint" type="revolute">
    <origin xyz="-0.021 0 -0.182" rpy="0 0 0" />
    <parent link="leg_r3_link" />
    <child link="leg_r4_link" />
    <axis xyz="0 1 0" />
    <limit lower="0.0" upper="2.61799387799149" effort="180" velocity="23.55" />
    <dynamics damping="0.2" friction="0.0" />
  </joint>
  <link name="leg_r5_link">
    <inertial>
      <origin xyz="0.0 0.0 0.0" rpy="0 0 0" />
      <mass value="0.06923766" />
      <inertia ixx="6.7e-04" ixy="0.0" ixz="0.0" iyy="6.7e-04" iyz="0.0" izz="1.172e-04" />
    </inertial>
    <visual>
      <origin xyz="0 0 0" rpy="0 0 0" />
      <geometry>
        <mesh filename="package://kuavo_assets/models/biped_s13/meshes/r_foot_pitch.STL" />
      </geometry>
      <material name="">
        <color rgba="1 1 1 1" />
      </material>
    </visual>
  </link>
  <joint name="leg_r5_joint" type="revolute">
    <origin xyz="0.021 0 -0.235" rpy="0 0 0" />
    <parent link="leg_r4_link" />
    <child link="leg_r5_link" />
    <axis xyz="0 1 0" />
    <limit lower="-0.872664625997165" upper="0.523598775598299" effort="36" velocity="23.0266666666667" />
    <dynamics damping="0.2" friction="0.0" />
  </joint>
  <link name="leg_r6_link">
    <inertial>
      <origin xyz="-0.00075494 -2.665e-05 -0.02339266" rpy="0 0 0" />
      <mass value="0.38537958" />
      <inertia ixx="0.00026927" ixy="0.0" ixz="0.0" iyy="0.00114572" iyz="0.0" izz="0.00129886" />
    </inertial>
    <visual>
      <origin xyz="0 0 0" rpy="0 0 0" />
      <geometry>
        <mesh filename="package://kuavo_assets/models/biped_s13/meshes/r_foot_roll_big.STL" />
      </geometry>
      <material name="">
        <color rgba="1 1 1 1" />
      </material>
    </visual>
  </link>
  <joint name="leg_r6_joint" type="revolute">
    <origin xyz="0 0 0" rpy="0 0 0" />
    <parent link="leg_r5_link" />
    <child link="leg_r6_link" />
    <axis xyz="1 0 0" />
    <limit lower="-0.261799387799149" upper="0.261799387799149" effort="36" velocity="23.0266666666667" />
    <dynamics damping="0.2" friction="0.0" />
  </joint>
  <link name="rl_foot_toe">
    <collision>
      <origin rpy="0 0 0" xyz="0 0 0" />
      <geometry>
        <sphere radius="0.005" />
      </geometry>
    </collision>
  </link>
  <joint name="rl_foot_toe_joint" type="fixed">
    <origin xyz="0.126 0.05 -0.0435" rpy="0 0 0" />
    <parent link="leg_r6_link" />
    <child link="rl_foot_toe" />
  </joint>
  <link name="rl_foot_heel">
    <collision>
      <origin rpy="0 0 0" xyz="0 0 0" />
      <geometry>
        <sphere radius="0.005" />
      </geometry>
    </collision>
  </link>
  <joint name="rl_foot_heel_joint" type="fixed">
    <origin xyz="-0.089 0.05 -0.0435" rpy="0 0 0" />
    <parent link="leg_r6_link" />
    <child link="rl_foot_heel" />
  </joint>
  <link name="rr_foot_toe">
    <collision>
      <origin rpy="0 0 0" xyz="0 0 0" />
      <geometry>
        <sphere radius="0.005" />
      </geometry>
    </collision>
  </link>
  <joint name="rr_foot_toe_joint" type="fixed">
    <origin xyz="0.126 -0.05 -0.0435" rpy="0 0 0" />
    <parent link="leg_r6_link" />
    <child link="rr_foot_toe" />
  </joint>
  <link name="rr_foot_heel">
    <collision>
      <origin rpy="0 0 0" xyz="0 0 0" />
      <geometry>
        <sphere radius="0.005" />
      </geometry>
    </collision>
  </link>
  <joint name="rr_foot_heel_joint" type="fixed">
    <origin xyz="-0.089 -0.05 -0.0435" rpy="0 0 0" />
    <parent link="leg_r6_link" />
    <child link="rr_foot_heel" />
  </joint>
  <link name="r_foot_toe">
    <collision>
      <origin rpy="0 0 0" xyz="0 0 0" />
      <geometry>
        <sphere radius="0.005" />
      </geometry>
    </collision>
  </link>
  <joint name="r_foot_toe_joint" type="fixed">
    <origin xyz="0.126 0.0 -0.0435" rpy="0 0 0" />
    <parent link="leg_r6_link" />
    <child link="r_foot_toe" />
  </joint>
  <link name="r_foot_heel">
    <collision>
      <origin rpy="0 0 0" xyz="0 0 0" />
      <geometry>
        <sphere radius="0.005" />
      </geometry>
    </collision>
  </link>
  <joint name="r_foot_heel_joint" type="fixed">
    <origin xyz="-0.089 0.0 -0.0435" rpy="0 0 0" />
    <parent link="leg_r6_link" />
    <child link="r_foot_heel" />
  </joint>
  <link name="zarm_l1_link">
    <inertial>
      <origin xyz="0.00335591 -0.00249177 1.895e-05" rpy="0 0 0" />
      <mass value="0.44491793" />
      <inertia ixx="0.00028057" ixy="3.5e-05" ixz="2.3e-05" iyy="0.00024754" iyz="7e-05" izz="0.0002873" />
    </inertial>
    <visual>
      <origin xyz="0 0 0" rpy="0 0 0" />
      <geometry>
        <mesh filename="package://kuavo_assets/models/biped_s13/meshes/l_arm_pitch.STL" />
      </geometry>
      <material name="">
        <color rgba="1 1 1 1" />
      </material>
    </visual>
  </link>
  <joint name="zarm_l1_joint" type="revolute">
    <origin xyz="0.0073474151 0.16250437899999998 0.20242688398" rpy="0 0 0" />
    <parent link="waist_yaw_link" />
    <child link="zarm_l1_link" />
    <axis xyz="0 1 0" />
    <limit lower="-3.14159265358979" upper="2.0943951023932" effort="12" velocity="7.32666666666667" />
    <dynamics damping="0.2" friction="0.0" />
  </joint>
  <link name="zarm_l2_link">
    <inertial>
      <origin xyz="0.00025941 0.0 -0.03684584" rpy="0 0 0" />
      <mass value="0.2598439" />
      <inertia ixx="0.0003221" ixy="0.0" ixz="-6.2e-05" iyy="0.00043526" iyz="0.0" izz="0.00030902" />
    </inertial>
    <visual>
      <origin xyz="0 0 0" rpy="0 0 0" />
      <geometry>
        <mesh filename="package://kuavo_assets/models/biped_s13/meshes/l_arm_roll.STL" />
      </geometry>
      <material name="">
        <color rgba="1 1 1 1" />
      </material>
    </visual>
  </link>
  <joint name="zarm_l2_joint" type="revolute">
    <origin xyz="0 0 0" rpy="0 0 0" />
    <parent link="zarm_l1_link" />
    <child link="zarm_l2_link" />
    <axis xyz="1 0 0" />
    <limit lower="-0.349065850398866" upper="3.49065850398866" effort="12" velocity="7.32666666666667" />
    <dynamics damping="0.2" friction="0.0" />
  </joint>
  <link name="zarm_l3_link">
    <inertial>
      <origin xyz="-0.0001383 -0.00323921 -0.14314847" rpy="0 0 0" />
      <mass value="0.77406554" />
      <inertia ixx="0.00201794" ixy="-2.6e-05" ixz="-3e-05" iyy="0.00198657" iyz="-0.00011116" izz="0.00042873" />
    </inertial>
    <visual>
      <origin xyz="0 0 0" rpy="0 0 0" />
      <geometry>
        <mesh filename="package://kuavo_assets/models/biped_s13/meshes/l_arm_yaw.STL" />
      </geometry>
      <material name="">
        <color rgba="1 1 1 1" />
      </material>
    </visual>
  </link>
  <joint name="zarm_l3_joint" type="revolute">
    <origin xyz="0 0 0" rpy="0 0 0" />
    <parent link="zarm_l2_link" />
    <child link="zarm_l3_link" />
    <axis xyz="0 0 1" />
    <limit lower="-1.5707963267949" upper="1.5707963267949" effort="12" velocity="7.32666666666667" />
    <dynamics damping="0.2" friction="0.0" />
  </joint>
  <link name="zarm_l4_link">
    <inertial>
      <origin xyz="0.00776368 -0.00672119 -0.18040057" rpy="0 0 0" />
      <mass value="0.48320221" />
      <inertia ixx="0.00308555" ixy="0" ixz="0" iyy="0.00338093" iyz="0" izz="0.00054057" />
    </inertial>
    <visual>
      <origin xyz="0 0 0" rpy="0 0 0" />
      <geometry>
        <mesh filename="package://kuavo_assets/models/biped_s13/meshes/l_forearm_hand.STL" />
      </geometry>
      <material name="">
        <color rgba="1 1 1 1" />
      </material>
    </visual>
  </link>
  <joint name="zarm_l4_joint" type="revolute">
    <origin xyz="0 0 -0.188" rpy="0 0 0" />
    <parent link="zarm_l3_link" />
    <child link="zarm_l4_link" />
    <axis xyz="0 1 0" />
    <limit lower="-2.26892802759263" upper="0.0" effort="12" velocity="7.32666666666667" />
    <dynamics damping="0.2" friction="0.0" />
  </joint>
  <link name="zarm_l7_end_effector">
    <collision>
      <origin rpy="0 0 0" xyz="0 0 0" />
      <geometry>
        <sphere radius="0.005" />
      </geometry>
    </collision>
  </link>
  <joint name="zarm_l7_end_effector_joint" type="fixed">
    <origin xyz="0 -0.00 -0.17" rpy="0 0 0" />
    <parent link="zarm_l4_link" />
    <child link="zarm_l7_end_effector" />
  </joint>
  <link name="zarm_r1_link">
    <inertial>
      <origin xyz="0.00335581 0.00249177 1.809e-05" rpy="0 0 0" />
      <mass value="0.44491659" />
      <inertia ixx="0.00028057" ixy="-3.5e-05" ixz="2.4e-05" iyy="0.00024753" iyz="-6e-05" izz="0.00028729" />
    </inertial>
    <visual>
      <origin xyz="0 0 0" rpy="0 0 0" />
      <geometry>
        <mesh filename="package://kuavo_assets/models/biped_s13/meshes/r_arm_pitch.STL" />
      </geometry>
      <material name="">
        <color rgba="1 1 1 1" />
      </material>
    </visual>
  </link>
  <joint name="zarm_r1_joint" type="revolute">
    <origin xyz="0.0073474151 -0.16250437899999998 0.20242688398" rpy="0 0 0" />
    <parent link="waist_yaw_link" />
    <child link="zarm_r1_link" />
    <axis xyz="0 1 0" />
    <limit lower="-3.14159265358979" upper="2.0943951023932" effort="12" velocity="7.32666666666667" />
    <dynamics damping="0.2" friction="0.0" />
  </joint>
  <link name="zarm_r2_link">
    <inertial>
      <origin xyz="0.0002594 0.0 -0.03684556" rpy="0 0 0" />
      <mass value="0.25983512" />
      <inertia ixx="0.00032209" ixy="0.0" ixz="-6.2e-05" iyy="0.00043526" iyz="0.0" izz="0.00030901" />
    </inertial>
    <visual>
      <origin xyz="0 0 0" rpy="0 0 0" />
      <geometry>
        <mesh filename="package://kuavo_assets/models/biped_s13/meshes/r_arm_roll.STL" />
      </geometry>
      <material name="">
        <color rgba="1 1 1 1" />
      </material>
    </visual>
  </link>
  <joint name="zarm_r2_joint" type="revolute">
    <origin xyz="0 0 0" rpy="0 0 0" />
    <parent link="zarm_r1_link" />
    <child link="zarm_r2_link" />
    <axis xyz="1 0 0" />
    <limit lower="-3.49065850398866" upper="0.349065850398866" effort="12" velocity="7.32666666666667" />
    <dynamics damping="0.2" friction="0.0" />
  </joint>
  <link name="zarm_r3_link">
    <inertial>
      <origin xyz="-0.00013784 0.00323927 -0.14314868" rpy="0 0 0" />
      <mass value="0.774042" />
      <inertia ixx="0.00201792" ixy="2.6e-05" ixz="-3e-05" iyy="0.00198653" iyz="0.00011115" izz="0.00042871" />
    </inertial>
    <visual>
      <origin xyz="0 0 0" rpy="0 0 0" />
      <geometry>
        <mesh filename="package://kuavo_assets/models/biped_s13/meshes/r_arm_yaw.STL" />
      </geometry>
      <material name="">
        <color rgba="1 1 1 1" />
      </material>
    </visual>
  </link>
  <joint name="zarm_r3_joint" type="revolute">
    <origin xyz="0 0 0" rpy="0 0 0" />
    <parent link="zarm_r2_link" />
    <child link="zarm_r3_link" />
    <axis xyz="0 0 1" />
    <limit lower="-1.5707963267949" upper="1.5707963267949" effort="12" velocity="7.32666666666667" />
    <dynamics damping="0.2" friction="0.0" />
  </joint>
  <link name="zarm_r4_link">
    <inertial>
      <origin xyz="0.00776368 0.00672119 -0.18040057" rpy="0 0 0" />
      <mass value="0.48320221" />
       <inertia ixx="0.00308555" ixy="0" ixz="0" iyy="0.00338093" iyz="0" izz="0.00054057" />
    </inertial>
    <visual>
      <origin xyz="0 0 0" rpy="0 0 0" />
      <geometry>
        <mesh filename="package://kuavo_assets/models/biped_s13/meshes/r_forearm_hand.STL" />
      </geometry>
      <material name="">
        <color rgba="1 1 1 1" />
      </material>
    </visual>
  </link>
  <joint name="zarm_r4_joint" type="revolute">
    <origin xyz="0 0 -0.188" rpy="0 0 0" />
    <parent link="zarm_r3_link" />
    <child link="zarm_r4_link" />
    <axis xyz="0 1 0" />
    <limit lower="-2.26892802759263" upper="0.0" effort="12" velocity="7.32666666666667" />
    <dynamics damping="0.2" friction="0.0" />
  </joint>
  <link name="zarm_r7_end_effector">
    <collision>
      <origin rpy="0 0 0" xyz="0 0 0" />
      <geometry>
        <sphere radius="0.005" />
      </geometry>
    </collision>
  </link>
  <joint name="zarm_r7_end_effector_joint" type="fixed">
    <origin xyz="0 0.00 -0.17" rpy="0 0 0" />
    <parent link="zarm_r4_link" />
    <child link="zarm_r7_end_effector" />
  </joint>
  <link name="zhead_1_link">
    <inertial>
      <origin xyz="-2.17e-06 0 0" rpy="0 0 0" />
      <mass value="0.8600171" />
      <inertia ixx="0.00182827" ixy="0" ixz="0" iyy="0.00158462" iyz="0" izz="0.00060882" />
    </inertial>
    <visual>
      <origin xyz="0 0 0" rpy="0 0 0" />
      <geometry>
        <mesh filename="package://kuavo_assets/models/biped_s13/meshes/head_yaw.STL" />
      </geometry>
      <material name="">
        <color rgba="1 1 1 1" />
      </material>
    </visual>
  </link>
  <joint name="zhead_1_joint" type="revolute">
    <origin xyz="0.0 0.0 0.33128227967" rpy="0 0 0" />
    <parent link="waist_yaw_link" />
    <child link="zhead_1_link" />
    <axis xyz="0 0 1" />
    <limit lower="-1.5707963267949" upper="1.5707963267949" effort="50" velocity="8.37333333333333" />
    <dynamics damping="0.2" friction="0.0" />
  </joint>
  <link name="zhead_2_link">
    <inertial>
      <origin xyz="0.01483981 -0.0004003 0.03127021" rpy="0 0 0" />
      <mass value="0.35420007" />
      <inertia ixx="0.00092946" ixy="0" ixz="0" iyy="0.00095408" iyz="0" izz="0.00114126" />
    </inertial>
    <visual>
      <origin xyz="0 0 0" rpy="0 0 0" />
      <geometry>
        <mesh filename="package://kuavo_assets/models/biped_s13/meshes/head_pitch.STL" />
      </geometry>
      <material name="">
        <color rgba="1 1 1 1" />
      </material>
    </visual>
  </link>
  <joint name="zhead_2_joint" type="revolute">
    <origin xyz="0 0 0" rpy="0 0 0" />
    <parent link="zhead_1_link" />
    <child link="zhead_2_link" />
    <axis xyz="0 1 0" />
    <limit lower="-0.349065850398866" upper="0.523598775598299" effort="50" velocity="8.37333333333333" />
    <dynamics damping="0.2" friction="0.0" />
  </joint>

    <!-- 在原有的gazebo插件配置后添加 -->
  <!-- 真值 -->
  <gazebo>
    <plugin filename="libgazebo_ros_p3d.so" name="p3d_base_controller">
      <alwaysOn>true</alwaysOn>
      <updateRate>500.0</updateRate>
      <bodyName>base_link</bodyName>
      <topicName>ground_truth/state</topicName>
      <gaussianNoise>0</gaussianNoise>
      <frameName>world</frameName>
      <xyzOffsets>0 0 0</xyzOffsets>
      <rpyOffsets>0 0 0</rpyOffsets>
    </plugin>
  </gazebo>

  <!-- 左脚 -->
  <gazebo reference="leg_l6_link">
    <mu1>1.5</mu1>
    <mu2>2.5</mu2>
    <self_collide>1</self_collide>
    <kp value="1000000.0"/>
    <kd value="100.0"/>
    <maxVel>3</maxVel>
    <minDepth>0.00</minDepth>
  </gazebo>
  <gazebo reference="l_foot_heel">
    <mu1>1.5</mu1>
    <mu2>2.5</mu2>
    <self_collide>1</self_collide>
    <kp value="1000000.0"/>
    <kd value="100.0"/>
    <maxVel>3</maxVel>
    <minDepth>0.00</minDepth>
  </gazebo>
  <gazebo reference="l_foot_toe">
    <mu1>1.5</mu1>
    <mu2>2.5</mu2>
    <self_collide>1</self_collide>
    <kp value="1000000.0"/>
    <kd value="100.0"/>
    <maxVel>3</maxVel>
    <minDepth>0.00</minDepth>
  </gazebo>
  <gazebo reference="lr_foot_heel">
    <mu1>1.5</mu1>
    <mu2>2.5</mu2>
    <self_collide>1</self_collide>
    <kp value="1000000.0"/>
    <kd value="100.0"/>
    <maxVel>3</maxVel>
    <minDepth>0.00</minDepth>
  </gazebo>
  <gazebo reference="lr_foot_toe">
    <mu1>1.5</mu1>
    <mu2>2.5</mu2>
    <self_collide>1</self_collide>
    <kp value="1000000.0"/>
    <kd value="100.0"/>
    <maxVel>3</maxVel>
    <minDepth>0.00</minDepth>
  </gazebo>
  <gazebo reference="ll_foot_heel">
    <mu1>1.5</mu1>
    <mu2>2.5</mu2>
    <self_collide>1</self_collide>
    <kp value="1000000.0"/>
    <kd value="100.0"/>
    <maxVel>3</maxVel>
    <minDepth>0.00</minDepth>
  </gazebo>
  <gazebo reference="ll_foot_toe">
    <mu1>1.5</mu1>
    <mu2>2.5</mu2>
    <self_collide>1</self_collide>
    <kp value="1000000.0"/>
    <kd value="100.0"/>
    <maxVel>3</maxVel>
    <minDepth>0.00</minDepth>
  </gazebo>

  <!-- 右脚 -->
  <gazebo reference="leg_r6_link">
    <mu1>1.5</mu1>
    <mu2>2.5</mu2>
    <self_collide>1</self_collide>
    <kp value="1000000.0"/>
    <kd value="100.0"/>
    <maxVel>3</maxVel>
    <minDepth>0.00</minDepth>
  </gazebo>
  <gazebo reference="r_foot_heel">
    <mu1>1.5</mu1>
    <mu2>2.5</mu2>
    <self_collide>1</self_collide>
    <kp value="1000000.0"/>
    <kd value="100.0"/>
    <maxVel>3</maxVel>
    <minDepth>0.00</minDepth>
  </gazebo>
  <gazebo reference="r_foot_toe">
    <mu1>1.5</mu1>
    <mu2>2.5</mu2>
    <self_collide>1</self_collide>
    <kp value="1000000.0"/>
    <kd value="100.0"/>
    <maxVel>3</maxVel>
    <minDepth>0.00</minDepth>
  </gazebo>
  <gazebo reference="rl_foot_toe">
    <mu1>1.5</mu1>
    <mu2>2.5</mu2>
    <self_collide>1</self_collide>
    <kp value="1000000.0"/>
    <kd value="100.0"/>
    <maxVel>3</maxVel>
    <minDepth>0.00</minDepth>
  </gazebo>
  <gazebo reference="rl_foot_heel">
    <mu1>1.5</mu1>
    <mu2>2.5</mu2>
    <self_collide>1</self_collide>
    <kp value="1000000.0"/>
    <kd value="100.0"/>
    <maxVel>3</maxVel>
    <minDepth>0.00</minDepth>
  </gazebo>
  <gazebo reference="rr_foot_toe">
    <mu1>1.5</mu1>
    <mu2>2.5</mu2>
    <self_collide>1</self_collide>
    <kp value="1000000.0"/>
    <kd value="100.0"/>
    <maxVel>3</maxVel>
    <minDepth>0.00</minDepth>
  </gazebo>
  <gazebo reference="rr_foot_heel">
    <mu1>1.5</mu1>
    <mu2>2.5</mu2>
    <self_collide>1</self_collide>
    <kp value="1000000.0"/>
    <kd value="100.0"/>
    <maxVel>3</maxVel>
    <minDepth>0.00</minDepth>
  </gazebo>

  <!-- 仿真插件 -->
  <gazebo>
    <plugin name="gazebo_shm_interface" filename="libgazebo_sim_shm_interface.so">
      <!-- IMU配置 gazebo中fixed连接的link都只能获取第一个-->
      <imu>
        <frame_id>dummy_link</frame_id>
      </imu>
      
      <!-- 关节配置 -->
      <joints>
        <!-- 左腿关节 -->
        <joint><name>waist_joint</name></joint>
        <joint><name>leg_l1_joint</name></joint>
        <joint><name>leg_l2_joint</name></joint>
        <joint><name>leg_l3_joint</name></joint>
        <joint><name>leg_l4_joint</name></joint>
        <joint><name>leg_l5_joint</name></joint>
        <joint><name>leg_l6_joint</name></joint>
        
        <!-- 右腿关节 -->
        <joint><name>leg_r1_joint</name></joint>
        <joint><name>leg_r2_joint</name></joint>
        <joint><name>leg_r3_joint</name></joint>
        <joint><name>leg_r4_joint</name></joint>
        <joint><name>leg_r5_joint</name></joint>
        <joint><name>leg_r6_joint</name></joint>

        <!-- 腰部关节 -->
        <joint><name>waist_yaw_joint</name></joint>
        
        <!-- 左臂关节 -->
        <joint><name>zarm_l1_joint</name></joint>
        <joint><name>zarm_l2_joint</name></joint>
        <joint><name>zarm_l3_joint</name></joint>
        <joint><name>zarm_l4_joint</name></joint>

        
        <!-- 右臂关节 -->
        <joint><name>zarm_r1_joint</name></joint>
        <joint><name>zarm_r2_joint</name></joint>
        <joint><name>zarm_r3_joint</name></joint>
        <joint><name>zarm_r4_joint</name></joint>

        
        <!-- 头部关节 -->
        <joint><name>zhead_1_joint</name></joint>
        <joint><name>zhead_2_joint</name></joint>
      </joints>
      
      <!-- 接触传感器配置 -->
      <contacts>
        <contact><link>ll_foot_toe</link></contact>
        <contact><link>ll_foot_heel</link></contact>
        <contact><link>lr_foot_toe</link></contact>
        <contact><link>lr_foot_heel</link></contact>
        <contact><link>rl_foot_toe</link></contact>
        <contact><link>rl_foot_heel</link></contact>
        <contact><link>rr_foot_toe</link></contact>
        <contact><link>rr_foot_heel</link></contact>
      </contacts>
      </plugin>
  </gazebo>
</robot>
