<?xml version="1.0" ?>
<!-- =================================================================================== -->
<!-- |    This document was autogenerated by xacro from /home/fandes/workspace/kuavo-ros-control/src/humanoid-control/humanoid_interface_drake/models/biped_gen4.0/urdf/biped_v3_full.xacro | -->
<!-- |    EDITING THIS FILE BY HAND IS NOT RECOMMENDED                                 | -->
<!-- =================================================================================== -->
<robot name="biped_v3_full" xmlns:drake="https://drake.mit.edu">
  <link name="torso">
    <inertial>
      <origin xyz="-0.00505 0.0014 0.18077" rpy="0 0 0" />
      <mass value="23.2869" />
      <inertia ixx="0.28214" ixy="3e-05" ixz="0.01114" iyy="0.20534" iyz="0.00044" izz="0.13735" />
    </inertial>
    <visual>
      <origin rpy="0 0 0" xyz="0 0 0"/>
      <geometry>
        <mesh filename="../../meshes/base_link.STL"/>
      </geometry>
      <material name="">
        <color rgba="0.43137 0.45098 0.43137 1"/>
      </material>
    </visual>
    <!-- <collision>
      <origin xyz="0 0 0" rpy="0 0 0" />
      <geometry>
        <mesh filename="../../meshes/base_link.STL" />
      </geometry>
    </collision> -->
  </link>
  <link name="leg_l1_link">
    <inertial>
      <origin xyz="-0.00624961 -5.6e-06 -0.00874166" rpy="0 0 0" />
      <mass value="1.79206533" />
      <inertia ixx="0.00211603" ixy="7.6e-07" ixz="0.000107" iyy="0.00302948" iyz="4.73e-06" izz="0.00399385" />
    </inertial>
    <visual>
      <origin xyz="0 0 0" rpy="0 0 0" />
      <geometry>
        <mesh filename="../../meshes/l_leg_roll.STL" />
      </geometry>
      <material name="">
        <color rgba="1 1 1 1" />
      </material>
    </visual>
  </link>
  <joint name="leg_l1_joint" type="revolute">
    <origin xyz="-0.0025 0.087 -0.066" rpy="0 0 0" />
    <parent link="torso" />
    <child link="leg_l1_link" />
    <axis xyz="1 0 0" />
    <limit lower="-0.314159265358979" upper="0.663225115757845" effort="180.0" velocity="23.55" />
  </joint>
  <transmission type="SimpleTransmission">
    <joint name="leg_l1_joint" />
    <actuator name="leg_l1_joint_motor" />
  </transmission>
  <link name="leg_l2_link">
    <inertial>
      <origin xyz="4.471e-05 0.04985881 -0.11682314" rpy="0 0 0" />
      <mass value="1.67630577" />
      <inertia ixx="0.00548763" ixy="-2.73e-06" ixz="-9.2e-07" iyy="0.0041542" iyz="0.00050833" izz="0.00426092" />
    </inertial>
    <visual>
      <origin xyz="0 0 0" rpy="0 0 0" />
      <geometry>
        <mesh filename="../../meshes/l_leg_yaw.STL" />
      </geometry>
      <material name="">
        <color rgba="1 1 1 1" />
      </material>
    </visual>
  </link>
  <joint name="leg_l2_joint" type="revolute">
    <origin xyz="0 0 0" rpy="0 0 0" />
    <parent link="leg_l1_link" />
    <child link="leg_l2_link" />
    <axis xyz="0 0 1" />
    <limit lower="-1.0471975511966" upper="0.523598775598299" effort="100.0" velocity="41.3433333333333" />
  </joint>
  <transmission type="SimpleTransmission">
    <joint name="leg_l2_joint" />
    <actuator name="leg_l2_joint_motor" />
  </transmission>
  <link name="leg_l3_link">
    <inertial>
      <origin xyz="-0.00238348 -0.02309435 -0.06304956" rpy="0 0 0" />
      <mass value="2.46847" />
      <inertia ixx="0.02435272" ixy="4.518e-05" ixz="0.00123822" iyy="0.02479772" iyz="0.00261624" izz="0.00478829" />
    </inertial>
    <visual>
      <origin xyz="0 0 0" rpy="0 0 0" />
      <geometry>
        <mesh filename="../../meshes/l_leg_pitch.STL" />
      </geometry>
      <material name="">
        <color rgba="1 1 1 1" />
      </material>
    </visual>
  </link>
  <joint name="leg_l3_joint" type="revolute">
    <origin xyz="0 0.02545000000000 -0.1287" rpy="0 0 0" />
    <parent link="leg_l2_link" />
    <child link="leg_l3_link" />
    <axis xyz="0 1 0" />
    <limit lower="-1.83259571459405" upper="1.0471975511966" effort="100.0" velocity="41.3433333333333" />
  </joint>
  <transmission type="SimpleTransmission">
    <joint name="leg_l3_joint" />
    <actuator name="leg_l3_joint_motor" />
  </transmission>
  <link name="leg_l4_link">
    <inertial>
      <origin xyz="0.00304104 -4.1e-05 -0.12213928" rpy="0 0 0" />
      <mass value="1.86452506" />
      <inertia ixx="0.01537791" ixy="7.85e-06" ixz="-0.00010781" iyy="0.01559985" iyz="-0.00015323" izz="0.00123021" />
    </inertial>
    <visual>
      <origin xyz="0 0 0" rpy="0 0 0" />
      <geometry>
        <mesh filename="../../meshes/l_knee.STL" />
      </geometry>
      <material name="">
        <color rgba="1 1 1 1" />
      </material>
    </visual>
  </link>
  <joint name="leg_l4_joint" type="revolute">
    <origin xyz="-0.010390161952608 0 -0.249783995753446" rpy="0 0 0" />
    <parent link="leg_l3_link" />
    <child link="leg_l4_link" />
    <axis xyz="0 1 0" />
    <limit lower="0.0" upper="2.18166156499291" effort="100.0" velocity="41.3433333333333" />
  </joint>
  <transmission type="SimpleTransmission">
    <joint name="leg_l4_joint" />
    <actuator name="leg_l4_joint_motor" />
  </transmission>
  <link name="leg_l5_link">
    <inertial>
      <origin xyz="0.0 0.0 0.0" rpy="0 0 0" />
      <mass value="0.06923929" />
      <inertia ixx="6.66e-06" ixy="0.0" ixz="0.0" iyy="6.66e-06" iyz="0.0" izz="1.172e-05" />
    </inertial>
    <visual>
      <origin xyz="0 0 0" rpy="0 0 0" />
      <geometry>
        <mesh filename="../../meshes/l_foot_pitch.STL" />
      </geometry>
      <material name="">
        <color rgba="1 1 1 1" />
      </material>
    </visual>
  </link>
  <joint name="leg_l5_joint" type="revolute">
    <origin xyz="0 0 -0.346000000000004" rpy="0 0 0" />
    <parent link="leg_l4_link" />
    <child link="leg_l5_link" />
    <axis xyz="0 1 0" />
    <limit lower="-0.610865238198015" upper="0.523598775598299" effort="36.0" velocity="23.0266666666667" />
  </joint>
  <transmission type="SimpleTransmission">
    <joint name="leg_l5_joint" />
    <actuator name="leg_l5_joint_motor" />
  </transmission>
  <link name="leg_l6_link">
    <inertial>
      <origin xyz="-0.00987056 -7.58e-06 -0.03365514" rpy="0 0 0" />
      <mass value="0.58358325" />
      <inertia ixx="0.0006342" ixy="1.4e-07" ixz="0.00031564" iyy="0.00227317" iyz="-2e-08" izz="0.00239382" />
    </inertial>
    <visual>
      <origin xyz="0 0 0" rpy="0 0 0" />
      <geometry>
        <mesh filename="../../meshes/l_foot_roll.STL" />
      </geometry>
      <material name="">
        <color rgba="1 1 1 1" />
      </material>
    </visual>
  </link>
  <joint name="leg_l6_joint" type="revolute">
    <origin xyz="0 0 0" rpy="0 0 0" />
    <parent link="leg_l5_link" />
    <child link="leg_l6_link" />
    <axis xyz="1 0 0" />
    <limit lower="-0.349065850398866" upper="0.349065850398866" effort="36.0" velocity="23.0266666666667" />
  </joint>
  <transmission type="SimpleTransmission">
    <joint name="leg_l6_joint" />
    <actuator name="leg_l6_joint_motor" />
  </transmission>
  <frame link="leg_l6_link" name="l_foot_sole" xyz="0.0205085 0.0 -0.0465"/>
  <frame link="leg_l6_link" name="l_foot_toe" xyz="0.142507 0.0 -0.0465"/>
  <frame link="leg_l6_link" name="l_foot_heel" xyz="-0.10149 0.0 -0.0465"/>
  <link name="leg_r1_link">
    <inertial>
      <origin xyz="-0.00624961 5.65e-06 -0.00874165" rpy="0 0 0" />
      <mass value="1.79206572" />
      <inertia ixx="0.00211603" ixy="-7.6e-07" ixz="0.000107" iyy="0.00302948" iyz="-4.73e-06" izz="0.00399385" />
    </inertial>
    <visual>
      <origin xyz="0 0 0" rpy="0 0 0" />
      <geometry>
        <mesh filename="../../meshes/r_leg_roll.STL" />
      </geometry>
      <material name="">
        <color rgba="1 1 1 1" />
      </material>
    </visual>
  </link>
  <joint name="leg_r1_joint" type="revolute">
    <origin xyz="-0.0025 -0.087 -0.066" rpy="0 0 0" />
    <parent link="torso" />
    <child link="leg_r1_link" />
    <axis xyz="1 0 0" />
    <limit lower="-0.663225115757845" upper="0.314159265358979" effort="180.0" velocity="23.55" />
  </joint>
  <transmission type="SimpleTransmission">
    <joint name="leg_r1_joint" />
    <actuator name="leg_r1_joint_motor" />
  </transmission>
  <link name="leg_r2_link">
    <inertial>
      <origin xyz="4.471e-05 -0.04985878 -0.11682313" rpy="0 0 0" />
      <mass value="1.67630636" />
      <inertia ixx="0.00548764" ixy="2.73e-06" ixz="-9.2e-07" iyy="0.00415421" iyz="-0.00050832" izz="0.00426093" />
    </inertial>
    <visual>
      <origin xyz="0 0 0" rpy="0 0 0" />
      <geometry>
        <mesh filename="../../meshes/r_leg_yaw.STL" />
      </geometry>
      <material name="">
        <color rgba="1 1 1 1" />
      </material>
    </visual>
  </link>
  <joint name="leg_r2_joint" type="revolute">
    <origin xyz="0 0 0" rpy="0 0 0" />
    <parent link="leg_r1_link" />
    <child link="leg_r2_link" />
    <axis xyz="0 0 1" />
    <limit lower="-0.523598775598299" upper="1.0471975511966" effort="100.0" velocity="41.3433333333333" />
  </joint>
  <transmission type="SimpleTransmission">
    <joint name="leg_r2_joint" />
    <actuator name="leg_r2_joint_motor" />
  </transmission>
  <link name="leg_r3_link">
    <inertial>
      <origin xyz="-0.00238153 0.02309009 -0.06305853" rpy="0 0 0" />
      <mass value="2.46916674" />
      <inertia ixx="0.02435155" ixy="-4.518e-05" ixz="0.00123747" iyy="0.02479853" iyz="-0.00261573" izz="0.0047908" />
    </inertial>
    <visual>
      <origin xyz="0 0 0" rpy="0 0 0" />
      <geometry>
        <mesh filename="../../meshes/r_leg_pitch.STL" />
      </geometry>
      <material name="">
        <color rgba="1 1 1 1" />
      </material>
    </visual>
  </link>
  <joint name="leg_r3_joint" type="revolute">
    <origin xyz="0 -0.02545000000000 -0.1287" rpy="0 0 0" />
    <parent link="leg_r2_link" />
    <child link="leg_r3_link" />
    <axis xyz="0 1 0" />
    <limit lower="-1.83259571459405" upper="1.0471975511966" effort="100.0" velocity="41.3433333333333" />
  </joint>
  <transmission type="SimpleTransmission">
    <joint name="leg_r3_joint" />
    <actuator name="leg_r3_joint_motor" />
  </transmission>
  <link name="leg_r4_link">
    <inertial>
      <origin xyz="0.00304109 4.102e-05 -0.12213983" rpy="0 0 0" />
      <mass value="1.86454133" />
      <inertia ixx="0.01537809" ixy="-7.85e-06" ixz="-0.00010779" iyy="0.01560001" iyz="0.00015322" izz="0.00123022" />
    </inertial>
    <visual>
      <origin xyz="0 0 0" rpy="0 0 0" />
      <geometry>
        <mesh filename="../../meshes/r_knee.STL" />
      </geometry>
      <material name="">
        <color rgba="1 1 1 1" />
      </material>
    </visual>
  </link>
  <joint name="leg_r4_joint" type="revolute">
    <origin xyz="-0.0103901619526017 0 -0.249783995753447" rpy="0 0 0" />
    <parent link="leg_r3_link" />
    <child link="leg_r4_link" />
    <axis xyz="0 1 0" />
    <limit lower="0.0" upper="2.18166156499291" effort="100.0" velocity="41.3433333333333" />
  </joint>
  <transmission type="SimpleTransmission">
    <joint name="leg_r4_joint" />
    <actuator name="leg_r4_joint_motor" />
  </transmission>
  <link name="leg_r5_link">
    <inertial>
      <origin xyz="0.0 0.0 0.0" rpy="0 0 0" />
      <mass value="0.06923929" />
      <inertia ixx="6.66e-06" ixy="0.0" ixz="0.0" iyy="6.66e-06" iyz="0.0" izz="1.172e-05" />
    </inertial>
    <visual>
      <origin xyz="0 0 0" rpy="0 0 0" />
      <geometry>
        <mesh filename="../../meshes/r_foot_pitch.STL" />
      </geometry>
      <material name="">
        <color rgba="1 1 1 1" />
      </material>
    </visual>
  </link>
  <joint name="leg_r5_joint" type="revolute">
    <origin xyz="0 0 -0.346000000000011" rpy="0 0 0" />
    <parent link="leg_r4_link" />
    <child link="leg_r5_link" />
    <axis xyz="0 1 0" />
    <limit lower="-0.523598775598299" upper="0.523598775598299" effort="36.0" velocity="23.0266666666667" />
  </joint>
  <transmission type="SimpleTransmission">
    <joint name="leg_r5_joint" />
    <actuator name="leg_r5_joint_motor" />
  </transmission>
  <link name="leg_r6_link">
    <inertial>
      <origin xyz="-0.00987049 7.65e-06 -0.03365512" rpy="0 0 0" />
      <mass value="0.58358273" />
      <inertia ixx="0.0006342" ixy="-1.4e-07" ixz="0.00031564" iyy="0.00227317" iyz="2e-08" izz="0.00239382" />
    </inertial>
    <visual>
      <origin xyz="0 0 0" rpy="0 0 0" />
      <geometry>
        <mesh filename="../../meshes/r_foot_roll.STL" />
      </geometry>
      <material name="">
        <color rgba="1 1 1 1" />
      </material>
    </visual>
  </link>
  <joint name="leg_r6_joint" type="revolute">
    <origin xyz="0 0 0" rpy="0 0 0" />
    <parent link="leg_r5_link" />
    <child link="leg_r6_link" />
    <axis xyz="1 0 0" />
    <limit lower="-0.349065850398866" upper="0.349065850398866" effort="36.0" velocity="23.0266666666667" />
  </joint>
  <transmission type="SimpleTransmission">
    <joint name="leg_r6_joint" />
    <actuator name="leg_r6_joint_motor" />
  </transmission>
  <frame link="leg_r6_link" name="r_foot_sole" xyz="0.0205085 -0.0 -0.0465"/>
  <frame link="leg_r6_link" name="r_foot_toe" xyz="0.142507 -0.0 -0.0465"/>
  <frame link="leg_r6_link" name="r_foot_heel" xyz="-0.10149 -0.0 -0.0465"/>
  <!-- =========================================================== Arms ================================================================= -->
  <link name="zarm_l1_link">
    <inertial>
      <origin xyz="-0.00083 -0.02218 0.00035" rpy="0 0 0" />
      <mass value="0.962" />
      <inertia ixx="0.00225" ixy="-3e-05" ixz="0.0" iyy="0.00099" iyz="-2e-05" izz="0.00227" />
    </inertial>
    <visual>
      <origin xyz="0 0 0" rpy="0 0 0" />
      <geometry>
        <mesh filename="../../meshes/l_arm_pitch.STL" />
      </geometry>
      <material name="">
        <color rgba="1 1 1 1" />
      </material>
    </visual>
  </link>
  <joint name="zarm_l1_joint" type="revolute">
    <origin xyz="-0.0175 0.28469999999999995 0.3245" rpy="0 0 0" />
    <parent link="base_link" />
    <child link="zarm_l1_link" />
    <axis xyz="0 1 0" />
    <limit lower="-3.14159265358979" upper="1.5707963267949" effort="100.0" velocity="41.3433333333333" />
  </joint>
  <transmission type="SimpleTransmission">
    <joint name="zarm_l1_joint" />
    <actuator name="zarm_l1_joint_motor" />
  </transmission>
  <link name="zarm_l2_link">
    <inertial>
      <origin xyz="-0.00791 0.0 -0.04655" rpy="0 0 0" />
      <mass value="0.57" />
      <inertia ixx="0.00163" ixy="0.0" ixz="5e-05" iyy="0.00211" iyz="0.0" izz="0.00122" />
    </inertial>
    <visual>
      <origin xyz="0 0 0" rpy="0 0 0" />
      <geometry>
        <mesh filename="../../meshes/l_arm_roll.STL" />
      </geometry>
      <material name="">
        <color rgba="1 1 1 1" />
      </material>
    </visual>
  </link>
  <joint name="zarm_l2_joint" type="revolute">
    <origin xyz="0 0 0" rpy="0 0 0" />
    <parent link="zarm_l1_link" />
    <child link="zarm_l2_link" />
    <axis xyz="1 0 0" />
    <limit lower="-0.349065850398866" upper="2.0943951023932" effort="50.0" velocity="19.154" />
  </joint>
  <transmission type="SimpleTransmission">
    <joint name="zarm_l2_joint" />
    <actuator name="zarm_l2_joint_motor" />
  </transmission>
  <link name="zarm_l3_link">
    <inertial>
      <origin xyz="0.00628 0.00107 -0.20878" rpy="0 0 0" />
      <mass value="1.65" />
      <inertia ixx="0.00815" ixy="-4e-05" ixz="0.00085" iyy="0.00828" iyz="0.00014" izz="0.00206" />
    </inertial>
    <visual>
      <origin xyz="0 0 0" rpy="0 0 0" />
      <geometry>
        <mesh filename="../../meshes/l_arm_yaw.STL" />
      </geometry>
      <material name="">
        <color rgba="1 1 1 1" />
      </material>
    </visual>
  </link>
  <joint name="zarm_l3_joint" type="revolute">
    <origin xyz="0 0 0" rpy="0 0 0" />
    <parent link="zarm_l2_link" />
    <child link="zarm_l3_link" />
    <axis xyz="0 0 1" />
    <limit lower="-1.5707963267949" upper="1.5707963267949" effort="39.0" velocity="18.84" />
  </joint>
  <transmission type="SimpleTransmission">
    <joint name="zarm_l3_joint" />
    <actuator name="zarm_l3_joint_motor" />
  </transmission>
  <link name="zarm_l4_link">
    <inertial>
      <origin xyz="-0.01611 0.00143 -0.04857" rpy="0 0 0" />
      <mass value="0.429" />
      <inertia ixx="0.00135" ixy="0.0" ixz="-0.0001" iyy="0.00114" iyz="0.0" izz="0.00083" />
    </inertial>
    <visual>
      <origin xyz="0 0 0" rpy="0 0 0" />
      <geometry>
        <mesh filename="../../meshes/l_forearm.STL" />
      </geometry>
      <material name="">
        <color rgba="1 1 1 1" />
      </material>
    </visual>
  </link>
  <joint name="zarm_l4_joint" type="revolute">
    <origin xyz="0.0200000000000006 0 -0.283699999999996" rpy="0 0 0" />
    <parent link="zarm_l3_link" />
    <child link="zarm_l4_link" />
    <axis xyz="0 1 0" />
    <limit lower="-2.61799387799149" upper="0.0" effort="50.0" velocity="18.84" />
  </joint>
  <transmission type="SimpleTransmission">
    <joint name="zarm_l4_joint" />
    <actuator name="zarm_l4_joint_motor" />
  </transmission>
  <link name="zarm_l5_link">
    <inertial>
      <origin xyz="-0.00207 0.00018 -0.05079" rpy="0 0 0" />
      <mass value="0.61" />
      <inertia ixx="0.00107" ixy="0.0" ixz="-4e-05" iyy="0.00146" iyz="0.0" izz="0.00083" />
    </inertial>
    <visual>
      <origin xyz="0 0 0" rpy="0 0 0" />
      <geometry>
        <mesh filename="../../meshes/l_hand_yaw.STL" />
      </geometry>
      <material name="">
        <color rgba="1 1 1 1" />
      </material>
    </visual>
  </link>
  <joint name="zarm_l5_joint" type="revolute">
    <origin xyz="-0.0200000000000025 0 -0.127037274261591" rpy="0 0 0" />
    <parent link="zarm_l4_link" />
    <child link="zarm_l5_link" />
    <axis xyz="0 0 1" />
    <limit lower="-1.5707963267949" upper="1.5707963267949" effort="12.0" velocity="21.666" />
  </joint>
  <transmission type="SimpleTransmission">
    <joint name="zarm_l5_joint" />
    <actuator name="zarm_l5_joint_motor" />
  </transmission>
  <link name="zarm_l6_link">
    <inertial>
      <origin xyz="-0.00111 0.00335 -0.01335" rpy="0 0 0" />
      <mass value="0.331" />
      <inertia ixx="0.00022" ixy="0.0" ixz="0.0" iyy="0.00027" iyz="0.0" izz="0.00028" />
    </inertial>
    <visual>
      <origin xyz="0 0 0" rpy="0 0 0" />
      <geometry>
        <mesh filename="../../meshes/l_hand_roll.STL" />
      </geometry>
      <material name="">
        <color rgba="1 1 1 1" />
      </material>
    </visual>
  </link>
  <joint name="zarm_l6_joint" type="revolute">
    <origin xyz="0.000199999999999079 0 -0.106462725738415" rpy="0 0 0" />
    <parent link="zarm_l5_link" />
    <child link="zarm_l6_link" />
    <axis xyz="1 0 0" />
    <limit lower="-1.30899693899575" upper="0.698131700797732" effort="12.0" velocity="21.666" />
  </joint>
  <transmission type="SimpleTransmission">
    <joint name="zarm_l6_joint" />
    <actuator name="zarm_l6_joint_motor" />
  </transmission>
  <link name="zarm_l7_link">
    <inertial>
      <origin xyz="0.00186 0.01014 -0.09044" rpy="0 0 0" />
      <mass value="0.64" />
      <inertia ixx="0.00071" ixy="1e-05" ixz="2e-05" iyy="0.0007" iyz="-4e-05" izz="0.00012" />
    </inertial>
    <visual>
      <origin xyz="0 0 0" rpy="0 0 0" />
      <geometry>
        <mesh filename="../../meshes/l_hand_pitch.STL" />
      </geometry>
      <material name="">
        <color rgba="1 1 1 1" />
      </material>
    </visual>
  </link>
  <joint name="zarm_l7_joint" type="revolute">
    <origin xyz="0 0 -0.0210004653879916" rpy="0 0 0" />
    <parent link="zarm_l6_link" />
    <child link="zarm_l7_link" />
    <axis xyz="0 1 0" />
    <limit lower="-0.698131700797732" upper="0.698131700797732" effort="12.0" velocity="21.666" />
  </joint>
  <transmission type="SimpleTransmission">
    <joint name="zarm_l7_joint" />
    <actuator name="zarm_l7_joint_motor" />
  </transmission>
  <!-- right arm -->
  <link name="zarm_r1_link">
    <inertial>
      <origin xyz="-0.00083 0.02218 0.00035" rpy="0 0 0" />
      <mass value="0.962" />
      <inertia ixx="0.00225" ixy="3e-05" ixz="0.0" iyy="0.00099" iyz="2e-05" izz="0.00227" />
    </inertial>
    <visual>
      <origin xyz="0 0 0" rpy="0 0 0" />
      <geometry>
        <mesh filename="../../meshes/r_arm_pitch.STL" />
      </geometry>
      <material name="">
        <color rgba="1 1 1 1" />
      </material>
    </visual>
  </link>
  <joint name="zarm_r1_joint" type="revolute">
    <origin xyz="-0.0175 -0.28469999999999995 0.3245" rpy="0 0 0" />
    <parent link="base_link" />
    <child link="zarm_r1_link" />
    <axis xyz="0 1 0" />
    <limit lower="-3.14159265358979" upper="1.5707963267949" effort="100.0" velocity="41.3433333333333" />
  </joint>
  <transmission type="SimpleTransmission">
    <joint name="zarm_r1_joint" />
    <actuator name="zarm_r1_joint_motor" />
  </transmission>
  <link name="zarm_r2_link">
    <inertial>
      <origin xyz="-0.00791 0.0 -0.04655" rpy="0 0 0" />
      <mass value="0.57" />
      <inertia ixx="0.00163" ixy="0.0" ixz="5e-05" iyy="0.00211" iyz="0.0" izz="0.00122" />
    </inertial>
    <visual>
      <origin xyz="0 0 0" rpy="0 0 0" />
      <geometry>
        <mesh filename="../../meshes/r_arm_roll.STL" />
      </geometry>
      <material name="">
        <color rgba="1 1 1 1" />
      </material>
    </visual>
  </link>
  <joint name="zarm_r2_joint" type="revolute">
    <origin xyz="0 0 0" rpy="0 0 0" />
    <parent link="zarm_r1_link" />
    <child link="zarm_r2_link" />
    <axis xyz="1 0 0" />
    <limit lower="-2.0943951023932" upper="0.349065850398866" effort="50.0" velocity="19.154" />
  </joint>
  <transmission type="SimpleTransmission">
    <joint name="zarm_r2_joint" />
    <actuator name="zarm_r2_joint_motor" />
  </transmission>
  <link name="zarm_r3_link">
    <inertial>
      <origin xyz="0.00628 -0.00107 -0.20878" rpy="0 0 0" />
      <mass value="1.65" />
      <inertia ixx="0.00815" ixy="4e-05" ixz="0.00085" iyy="0.00828" iyz="-0.00014" izz="0.00206" />
    </inertial>
    <visual>
      <origin xyz="0 0 0" rpy="0 0 0" />
      <geometry>
        <mesh filename="../../meshes/r_arm_yaw.STL" />
      </geometry>
      <material name="">
        <color rgba="1 1 1 1" />
      </material>
    </visual>
  </link>
  <joint name="zarm_r3_joint" type="revolute">
    <origin xyz="0 0 0" rpy="0 0 0" />
    <parent link="zarm_r2_link" />
    <child link="zarm_r3_link" />
    <axis xyz="0 0 1" />
    <limit lower="-1.5707963267949" upper="1.5707963267949" effort="39.0" velocity="18.84" />
  </joint>
  <transmission type="SimpleTransmission">
    <joint name="zarm_r3_joint" />
    <actuator name="zarm_r3_joint_motor" />
  </transmission>
  <link name="zarm_r4_link">
    <inertial>
      <origin xyz="-0.01611 -0.00143 -0.04857" rpy="0 0 0" />
      <mass value="0.429" />
      <inertia ixx="0.00135" ixy="0.0" ixz="-0.0001" iyy="0.00114" iyz="0.0" izz="0.00083" />
    </inertial>
    <visual>
      <origin xyz="0 0 0" rpy="0 0 0" />
      <geometry>
        <mesh filename="../../meshes/r_forearm.STL" />
      </geometry>
      <material name="">
        <color rgba="1 1 1 1" />
      </material>
    </visual>
  </link>
  <joint name="zarm_r4_joint" type="revolute">
    <origin xyz="0.0200000000000024 0 -0.2837" rpy="0 0 0" />
    <parent link="zarm_r3_link" />
    <child link="zarm_r4_link" />
    <axis xyz="0 1 0" />
    <limit lower="-2.61799387799149" upper="0.0" effort="50.0" velocity="18.84" />
  </joint>
  <transmission type="SimpleTransmission">
    <joint name="zarm_r4_joint" />
    <actuator name="zarm_r4_joint_motor" />
  </transmission>
  <link name="zarm_r5_link">
    <inertial>
      <origin xyz="-0.00207 -0.00018 -0.05079" rpy="0 0 0" />
      <mass value="0.61" />
      <inertia ixx="0.00107" ixy="0.0" ixz="-4e-05" iyy="0.00146" iyz="0.0" izz="0.00083" />
    </inertial>
    <visual>
      <origin xyz="0 0 0" rpy="0 0 0" />
      <geometry>
        <mesh filename="../../meshes/r_hand_yaw.STL" />
      </geometry>
      <material name="">
        <color rgba="1 1 1 1" />
      </material>
    </visual>
  </link>
  <joint name="zarm_r5_joint" type="revolute">
    <origin xyz="-0.0200000000000001 0 -0.127037274261587" rpy="0 0 0" />
    <parent link="zarm_r4_link" />
    <child link="zarm_r5_link" />
    <axis xyz="0 0 1" />
    <limit lower="-1.5707963267949" upper="1.5707963267949" effort="12.0" velocity="21.666" />
  </joint>
  <transmission type="SimpleTransmission">
    <joint name="zarm_r5_joint" />
    <actuator name="zarm_r5_joint_motor" />
  </transmission>
  <link name="zarm_r6_link">
    <inertial>
      <origin xyz="-0.00111 -0.00335 -0.01335" rpy="0 0 0" />
      <mass value="0.331" />
      <inertia ixx="0.00022" ixy="0.0" ixz="0.0" iyy="0.00027" iyz="0.0" izz="0.00028" />
    </inertial>
    <visual>
      <origin xyz="0 0 0" rpy="0 0 0" />
      <geometry>
        <mesh filename="../../meshes/r_hand_roll.STL" />
      </geometry>
      <material name="">
        <color rgba="1 1 1 1" />
      </material>
    </visual>
  </link>
  <joint name="zarm_r6_joint" type="revolute">
    <origin xyz="0 0 -0.106462725738415" rpy="0 0 0" />
    <parent link="zarm_r5_link" />
    <child link="zarm_r6_link" />
    <axis xyz="1 0 0" />
    <limit lower="-0.698131700797732" upper="1.30899693899575" effort="12.0" velocity="21.666" />
  </joint>
  <transmission type="SimpleTransmission">
    <joint name="zarm_r6_joint" />
    <actuator name="zarm_r6_joint_motor" />
  </transmission>
  <link name="zarm_r7_link">
    <inertial>
      <origin xyz="0.00186 -0.01014 -0.09044" rpy="0 0 0" />
      <mass value="0.64" />
      <inertia ixx="0.00069" ixy="-1e-05" ixz="2e-05" iyy="0.00068" iyz="5e-05" izz="0.00012" />
    </inertial>
    <visual>
      <origin xyz="0 0 0" rpy="0 0 0" />
      <geometry>
        <mesh filename="../../meshes/r_hand_pitch.STL" />
      </geometry>
      <material name="">
        <color rgba="1 1 1 1" />
      </material>
    </visual>
  </link>
  <joint name="zarm_r7_joint" type="revolute">
    <origin xyz="0 0 -0.0209999999999999" rpy="0 0 0" />
    <parent link="zarm_r6_link" />
    <child link="zarm_r7_link" />
    <axis xyz="0 1 0" />
    <limit lower="-0.698131700797732" upper="0.698131700797732" effort="12.0" velocity="21.666" />
  </joint>
  <transmission type="SimpleTransmission">
    <joint name="zarm_r7_joint" />
    <actuator name="zarm_r7_joint_motor" />
  </transmission>
  <!-- end frame -->
  <!-- <frame link="l_hand_pitch" name="l_hand_sole" xyz="0 0 -0.1" /> -->
  <!-- end frame -->
  <!-- <frame link="r_hand_pitch" name="r_hand_sole" xyz="0 0 -0.1" /> -->
</robot>

