<?xml version='1.0' encoding='utf-8'?>
<robot name="biped_s49">
  <mujoco>
    <compiler meshdir="../meshes/" balanceinertia="true" discardvisual="false" />
  </mujoco>
  <link name="dummy_link" />
  <link name="base_link">
    <inertial>
      <origin xyz="-0.0185005 0.00031952 0.1929569" rpy="0 0 0" />
      <mass value="28.27893803" />
      <inertia ixx="0.93103133" ixy="0.00011763" ixz="-0.07210993" iyy="0.82590532" iyz="6.88e-06" izz="0.27686612" />
    </inertial>
    <visual>
      <origin xyz="0 0 0" rpy="0 0 0" />
      <geometry>
        <mesh filename="package://kuavo_assets/models/biped_s49/meshes/torso.STL" />
      </geometry>
      <material name="">
        <color rgba="1 1 1 1" />
      </material>
    </visual>
    <collision>
      <origin xyz="-0.01 0 0.40" rpy="1.57 0 0" />
      <geometry>
        <capsule radius="0.14" length="0.12" />
      </geometry>
    </collision>
    <collision>
      <origin xyz="0 0 0.13" rpy="0 0 0" />
      <geometry>
        <capsule radius="0.13" length="0.08" />
      </geometry>
    </collision>
  </link>
  <joint name="base_link_to_dummy_link" type="fixed">
    <origin xyz="0 0 0" rpy="0 0 0" />
    <parent link="base_link" />
    <child link="dummy_link" />
  </joint>
  <link name="leg_l1_link">
    <inertial>
      <origin xyz="-0.00430148 -2.708e-05 -0.00851195" rpy="0 0 0" />
      <mass value="1.71093115" />
      <inertia ixx="0.00206092" ixy="1.97e-06" ixz="6.944e-05" iyy="0.00277274" iyz="-5.1e-06" izz="0.00370826" />
    </inertial>
    <visual>
      <origin xyz="0 0 0" rpy="0 0 0" />
      <geometry>
        <mesh filename="package://kuavo_assets/models/biped_s49/meshes/l_leg_roll.STL" />
      </geometry>
      <material name="">
        <color rgba="1 1 1 1" />
      </material>
    </visual>
    <collision>
      <origin xyz="-0.105 0 0" rpy="0 -1.5708 0" />
      <geometry><cylinder radius="0.06" length="0.07" /></geometry>
    </collision>
  </link>
  <joint name="leg_l1_joint" type="revolute">
    <origin xyz="-0.0024999 0.087 -0.066" rpy="0 0 0" />
    <parent link="base_link" />
    <child link="leg_l1_link" />
    <axis xyz="1 0 0" />
    <limit lower="-0.314159265358979" upper="0.663225115757845" effort="180.0" velocity="10.46" />
    <dynamics damping="0.02" friction="0.02" />
  </joint>
  <link name="leg_l2_link">
    <inertial>
      <origin xyz="0.0 -0.00231118 -0.09062539" rpy="0 0 0" />
      <mass value="0.58029165" />
      <inertia ixx="0.00223984" ixy="0.0" ixz="3e-08" iyy="0.00123175" iyz="-6.98e-06" izz="0.00146391" />
    </inertial>
    <visual>
      <origin xyz="0 0 0" rpy="0 0 0" />
      <geometry>
        <mesh filename="package://kuavo_assets/models/biped_s49/meshes/l_leg_yaw.STL" />
      </geometry>
      <material name="">
        <color rgba="1 1 1 1" />
      </material>
    </visual>
  </link>
  <joint name="leg_l2_joint" type="revolute">
    <origin xyz="0 0 0" rpy="0 0 0" />
    <parent link="leg_l1_link" />
    <child link="leg_l2_link" />
    <axis xyz="0 0 1" />
    <limit lower="-0.872664625997165" upper="0.785398163397448" effort="22.2" velocity="10.46" />
    <dynamics damping="0.02" friction="0.02" />
  </joint>
  <link name="leg_l3_link">
    <inertial>
      <origin xyz="0.00150537 0.01199614 -0.08411619" rpy="0 0 0" />
      <mass value="4.50393141" />
      <inertia ixx="0.0389365" ixy="7.866e-05" ixz="0.00102086" iyy="0.03942609" iyz="0.00219138" izz="0.00999961" />
    </inertial>
    <visual>
      <origin xyz="0 0 0" rpy="0 0 0" />
      <geometry>
        <mesh filename="package://kuavo_assets/models/biped_s49/meshes/l_leg_pitch.STL" />
      </geometry>
      <material name="">
        <color rgba="1 1 1 1" />
      </material>
    </visual>
    <collision>
      <origin xyz="0 0 0" rpy="-1.5708 0 0" />
      <geometry><cylinder radius="0.06" length="0.14" /></geometry>
    </collision>
    <collision>
      <origin xyz="0 0 -0.125" rpy="0 0 0" />
      <geometry><capsule radius="0.06" length="0.25" /></geometry>
    </collision>
  </link>
  <joint name="leg_l3_joint" type="revolute">
    <origin xyz="0.000500354536093913 -0.00100000000000011 -0.1287" rpy="0 0 0" />
    <parent link="leg_l2_link" />
    <child link="leg_l3_link" />
    <axis xyz="0 1 0" />
    <limit lower="-2.00712863979348" upper="1.5707963267949" effort="72.0" velocity="20.93" />
    <dynamics damping="0.02" friction="0.02" />
  </joint>
  <link name="leg_l4_link">
    <inertial>
      <origin xyz="0.00696242 5.314e-05 -0.11549851" rpy="0 0 0" />
      <mass value="1.62776815" />
      <inertia ixx="0.01243912" ixy="-2.29e-06" ixz="5.881e-05" iyy="0.01229563" iyz="-2.895e-05" izz="0.00097937" />
    </inertial>
    <visual>
      <origin xyz="0 0 0" rpy="0 0 0" />
      <geometry>
        <mesh filename="package://kuavo_assets/models/biped_s49/meshes/l_knee.STL" />
      </geometry>
      <material name="">
        <color rgba="1 1 1 1" />
      </material>
    </visual>
    <collision>
      <origin xyz="0 0 -0.17" rpy="0 0 0" />
      <geometry><capsule radius="0.04" length="0.34" /></geometry>
    </collision>
  </link>
  <joint name="leg_l4_joint" type="revolute">
    <origin xyz="-6.87185435835039E-05 0 -0.284" rpy="0 0 0" />
    <parent link="leg_l3_link" />
    <child link="leg_l4_link" />
    <axis xyz="0 1 0" />
    <limit lower="0.0" upper="2.53072741539178" effort="135.0" velocity="11.62" />
    <dynamics damping="0.02" friction="0.02" />
  </joint>
  <link name="leg_l5_link">
    <inertial>
      <origin xyz="0.0 0.0 0.0" rpy="0 0 0" />
      <mass value="0.07193524" />
      <inertia ixx="6.92e-06" ixy="0.0" ixz="0.0" iyy="6.92e-06" iyz="0.0" izz="1.218e-05" />
    </inertial>
    <visual>
      <origin xyz="0 0 0" rpy="0 0 0" />
      <geometry>
        <mesh filename="package://kuavo_assets/models/biped_s49/meshes/l_foot_pitch.STL" />
      </geometry>
      <material name="">
        <color rgba="1 1 1 1" />
      </material>
    </visual>
  </link>
  <joint name="leg_l5_joint" type="revolute">
    <origin xyz="-0.000431635992531742 0 -0.346000000000001" rpy="0 0 0" />
    <parent link="leg_l4_link" />
    <child link="leg_l5_link" />
    <axis xyz="0 1 0" />
    <limit lower="-0.872664625997165" upper="0.349065850398866" effort="46.0" velocity="10.46" />
    <dynamics damping="0.02" friction="0.02" />
  </joint>
  <link name="leg_l6_link">
    <inertial>
      <origin xyz="0.03732754 -2.22e-06 -0.03883977" rpy="0 0 0" />
      <mass value="0.49861272" />
      <inertia ixx="0.00039242" ixy="3e-08" ixz="4.664e-05" iyy="0.00158655" iyz="0.0" izz="0.00172576" />
    </inertial>
    <visual>
      <origin xyz="0 0 0" rpy="0 0 0" />
      <geometry>
        <mesh filename="package://kuavo_assets/models/biped_s49/meshes/l_foot_roll.STL" />
      </geometry>
      <material name="">
        <color rgba="1 1 1 1" />
      </material>
    </visual>
    <!-- 2 box + 11 capsules (match XML) -->
    <collision>
    	<origin xyz="0.0488 0 0" rpy="0 0 0" />
	    <geometry>
		    <box size="0.25 0.1 0.04" />
	    </geometry>
    </collision>
  </link>
  <joint name="leg_l6_joint" type="revolute">
    <origin xyz="0 0 0" rpy="0 0 0" />
    <parent link="leg_l5_link" />
    <child link="leg_l6_link" />
    <axis xyz="1 0 0" />
    <limit lower="-0.261799387799149" upper="0.261799387799149" effort="30.0" velocity="10.46" />
    <dynamics damping="0.02" friction="0.02" />
  </joint>
  <link name="ll_foot_toe">
    <collision>
      <origin rpy="0 0 0" xyz="0 0 0" />
      <geometry>
        <sphere radius="0.005" />
      </geometry>
    </collision>
  </link>
  <joint name="ll_foot_toe_joint" type="fixed">
    <origin xyz="0.17084 0.04773 -0.0595" rpy="0 0 0" />
    <parent link="leg_l6_link" />
    <child link="ll_foot_toe" />
  </joint>
  <link name="ll_foot_heel">
    <collision>
      <origin rpy="0 0 0" xyz="0 0 0" />
      <geometry>
        <sphere radius="0.005" />
      </geometry>
    </collision>
  </link>
  <joint name="ll_foot_heel_joint" type="fixed">
    <origin xyz="-0.073164 0.04773 -0.0595" rpy="0 0 0" />
    <parent link="leg_l6_link" />
    <child link="ll_foot_heel" />
  </joint>
  <link name="lr_foot_toe">
    <collision>
      <origin rpy="0 0 0" xyz="0 0 0" />
      <geometry>
        <sphere radius="0.005" />
      </geometry>
    </collision>
  </link>
  <joint name="lr_foot_toe_joint" type="fixed">
    <origin xyz="0.17084 -0.04773 -0.0595" rpy="0 0 0" />
    <parent link="leg_l6_link" />
    <child link="lr_foot_toe" />
  </joint>
  <link name="lr_foot_heel">
    <collision>
      <origin rpy="0 0 0" xyz="0 0 0" />
      <geometry>
        <sphere radius="0.005" />
      </geometry>
    </collision>
  </link>
  <joint name="lr_foot_heel_joint" type="fixed">
    <origin xyz="-0.073164 -0.04773 -0.0595" rpy="0 0 0" />
    <parent link="leg_l6_link" />
    <child link="lr_foot_heel" />
  </joint>
  <link name="l_foot_toe">
    <collision>
      <origin rpy="0 0 0" xyz="0 0 0" />
      <geometry>
        <sphere radius="0.005" />
      </geometry>
    </collision>
  </link>
  <joint name="l_foot_toe_joint" type="fixed">
    <origin xyz="0.17084 0.0 -0.0595" rpy="0 0 0" />
    <parent link="leg_l6_link" />
    <child link="l_foot_toe" />
  </joint>
  <link name="l_foot_heel">
    <collision>
      <origin rpy="0 0 0" xyz="0 0 0" />
      <geometry>
        <sphere radius="0.005" />
      </geometry>
    </collision>
  </link>
  <joint name="l_foot_heel_joint" type="fixed">
    <origin xyz="-0.073164 0.0 -0.0595" rpy="0 0 0" />
    <parent link="leg_l6_link" />
    <child link="l_foot_heel" />
  </joint>
  <link name="leg_r1_link">
    <inertial>
      <origin xyz="-0.00430146 2.709e-05 -0.00851195" rpy="0 0 0" />
      <mass value="1.71093008" />
      <inertia ixx="0.00206092" ixy="-1.97e-06" ixz="6.944e-05" iyy="0.00277274" iyz="5.1e-06" izz="0.00370826" />
    </inertial>
    <visual>
      <origin xyz="0 0 0" rpy="0 0 0" />
      <geometry>
        <mesh filename="package://kuavo_assets/models/biped_s49/meshes/r_leg_roll.STL" />
      </geometry>
      <material name="">
        <color rgba="1 1 1 1" />
      </material>
    </visual>
    <collision>
      <origin xyz="-0.105 0 0" rpy="0 -1.5708 0" />
      <geometry><cylinder radius="0.06" length="0.07" /></geometry>
    </collision>
  </link>
  <joint name="leg_r1_joint" type="revolute">
    <origin xyz="-0.0024999 -0.087 -0.066" rpy="0 0 0" />
    <parent link="base_link" />
    <child link="leg_r1_link" />
    <axis xyz="1 0 0" />
    <limit lower="-0.663225115757845" upper="0.314159265358979" effort="127.0" velocity="10.46" />
    <dynamics damping="0.02" friction="0.02" />
  </joint>
  <link name="leg_r2_link">
    <inertial>
      <origin xyz="0.0 0.00231118 -0.09062539" rpy="0 0 0" />
      <mass value="0.58029165" />
      <inertia ixx="0.00223984" ixy="0.0" ixz="-3e-08" iyy="0.00123175" iyz="6.98e-06" izz="0.00146391" />
    </inertial>
    <visual>
      <origin xyz="0 0 0" rpy="0 0 0" />
      <geometry>
        <mesh filename="package://kuavo_assets/models/biped_s49/meshes/r_leg_yaw.STL" />
      </geometry>
      <material name="">
        <color rgba="1 1 1 1" />
      </material>
    </visual>
  </link>
  <joint name="leg_r2_joint" type="revolute">
    <origin xyz="0 0 0" rpy="0 0 0" />
    <parent link="leg_r1_link" />
    <child link="leg_r2_link" />
    <axis xyz="0 0 1" />
    <limit lower="-0.785398163397448" upper="0.872664625997165" effort="22.2" velocity="10.46" />
    <dynamics damping="0.02" friction="0.02" />
  </joint>
  <link name="leg_r3_link">
    <inertial>
      <origin xyz="0.00208315 -0.01199644 -0.08411379" rpy="0 0 0" />
      <mass value="4.50385993" />
      <inertia ixx="0.03893478" ixy="-7.792e-05" ixz="0.00103064" iyy="0.03942522" iyz="-0.00219154" izz="0.01000016" />
    </inertial>
    <visual>
      <origin xyz="0 0 0" rpy="0 0 0" />
      <geometry>
        <mesh filename="package://kuavo_assets/models/biped_s49/meshes/r_leg_pitch.STL" />
      </geometry>
      <material name="">
        <color rgba="1 1 1 1" />
      </material>
    </visual>
    <collision>
      <origin xyz="0 0 0" rpy="-1.5708 0 0" />
      <geometry><cylinder radius="0.06" length="0.14" /></geometry>
    </collision>
    <collision>
      <origin xyz="0 0 -0.125" rpy="0 0 0" />
      <geometry><capsule radius="0.06" length="0.25" /></geometry>
    </collision>
  </link>
  <joint name="leg_r3_joint" type="revolute">
    <origin xyz="-4.88006581312577E-05 0 -0.1287" rpy="0 0 0" />
    <parent link="leg_r2_link" />
    <child link="leg_r3_link" />
    <axis xyz="0 1 0" />
    <limit lower="-2.00712863979348" upper="1.5707963267949" effort="72.0" velocity="20.93" />
    <dynamics damping="0.02" friction="0.02" />
  </joint>
  <link name="leg_r4_link">
    <inertial>
      <origin xyz="0.00743231 -5.343e-05 -0.11558701" rpy="0 0 0" />
      <mass value="1.62655699" />
      <inertia ixx="0.01241258" ixy="2.28e-06" ixz="6.289e-05" iyy="0.0122692" iyz="2.902e-05" izz="0.00097927" />
    </inertial>
    <visual>
      <origin xyz="0 0 0" rpy="0 0 0" />
      <geometry>
        <mesh filename="package://kuavo_assets/models/biped_s49/meshes/r_knee.STL" />
      </geometry>
      <material name="">
        <color rgba="1 1 1 1" />
      </material>
    </visual>
    <collision>
      <origin xyz="0 0 -0.17" rpy="0 0 0" />
      <geometry><capsule radius="0.04" length="0.34" /></geometry>
    </collision>
  </link>
  <joint name="leg_r4_joint" type="revolute">
    <origin xyz="0.000147138572785148 0 -0.283999982974744" rpy="0 0 0" />
    <parent link="leg_r3_link" />
    <child link="leg_r4_link" />
    <axis xyz="0 1 0" />
    <limit lower="0.0" upper="2.53072741539178" effort="135.0" velocity="11.62" />
    <dynamics damping="0.02" friction="0.02" />
  </joint>
  <link name="leg_r5_link">
    <inertial>
      <origin xyz="0.0 0.0 0.0" rpy="0 0 0" />
      <mass value="0.07193524" />
      <inertia ixx="6.92e-06" ixy="0.0" ixz="0.0" iyy="6.92e-06" iyz="0.0" izz="1.218e-05" />
    </inertial>
    <visual>
      <origin xyz="0 0 0" rpy="0 0 0" />
      <geometry>
        <mesh filename="package://kuavo_assets/models/biped_s49/meshes/r_foot_pitch.STL" />
      </geometry>
      <material name="">
        <color rgba="1 1 1 1" />
      </material>
    </visual>
  </link>
  <joint name="leg_r5_joint" type="revolute">
    <origin xyz="0.000119806050928577 0 -0.345999979257963" rpy="0 0 0" />
    <parent link="leg_r4_link" />
    <child link="leg_r5_link" />
    <axis xyz="0 1 0" />
    <limit lower="-0.872664625997165" upper="0.349065850398866" effort="46.0" velocity="10.46" />
    <dynamics damping="0.02" friction="0.02" />
  </joint>
  <link name="leg_r6_link">
    <inertial>
      <origin xyz="0.03734098 -2.22e-06 -0.03882684" rpy="0 0 0" />
      <mass value="0.49861272" />
      <inertia ixx="0.00039238" ixy="3e-08" ixz="4.618e-05" iyy="0.00158655" iyz="0.0" izz="0.00172579" />
    </inertial>
    <visual>
      <origin xyz="0 0 0" rpy="0 0 0" />
      <geometry>
        <mesh filename="package://kuavo_assets/models/biped_s49/meshes/r_foot_roll.STL" />
      </geometry>
      <material name="">
        <color rgba="1 1 1 1" />
      </material>
    </visual>
    <!-- 2 box + 11 capsules (match XML) -->
    <collision>
    	<origin xyz="0.0488 0 0" rpy="0 0 0" />
	    <geometry>
		    <box size="0.25 0.1 0.04" />
	    </geometry>
    </collision>
  </link>
  <joint name="leg_r6_joint" type="revolute">
    <origin xyz="0 0 0" rpy="0 0 0" />
    <parent link="leg_r5_link" />
    <child link="leg_r6_link" />
    <axis xyz="1 0 0" />
    <limit lower="-0.261799387799149" upper="0.261799387799149" effort="30.0" velocity="10.46" />
    <dynamics damping="0.02" friction="0.02" />
  </joint>
  <link name="rl_foot_toe">
    <collision>
      <origin rpy="0 0 0" xyz="0 0 0" />
      <geometry>
        <sphere radius="0.005" />
      </geometry>
    </collision>
  </link>
  <joint name="rl_foot_toe_joint" type="fixed">
    <origin xyz="0.17084 0.04773 -0.0595" rpy="0 0 0" />
    <parent link="leg_r6_link" />
    <child link="rl_foot_toe" />
  </joint>
  <link name="rl_foot_heel">
    <collision>
      <origin rpy="0 0 0" xyz="0 0 0" />
      <geometry>
        <sphere radius="0.005" />
      </geometry>
    </collision>
  </link>
  <joint name="rl_foot_heel_joint" type="fixed">
    <origin xyz="-0.073164 0.04773 -0.0595" rpy="0 0 0" />
    <parent link="leg_r6_link" />
    <child link="rl_foot_heel" />
  </joint>
  <link name="rr_foot_toe">
    <collision>
      <origin rpy="0 0 0" xyz="0 0 0" />
      <geometry>
        <sphere radius="0.005" />
      </geometry>
    </collision>
  </link>
  <joint name="rr_foot_toe_joint" type="fixed">
    <origin xyz="0.17084 -0.04773 -0.0595" rpy="0 0 0" />
    <parent link="leg_r6_link" />
    <child link="rr_foot_toe" />
  </joint>
  <link name="rr_foot_heel">
    <collision>
      <origin rpy="0 0 0" xyz="0 0 0" />
      <geometry>
        <sphere radius="0.005" />
      </geometry>
    </collision>
  </link>
  <joint name="rr_foot_heel_joint" type="fixed">
    <origin xyz="-0.073164 -0.04773 -0.0595" rpy="0 0 0" />
    <parent link="leg_r6_link" />
    <child link="rr_foot_heel" />
  </joint>
  <link name="r_foot_toe">
    <collision>
      <origin rpy="0 0 0" xyz="0 0 0" />
      <geometry>
        <sphere radius="0.005" />
      </geometry>
    </collision>
  </link>
  <joint name="r_foot_toe_joint" type="fixed">
    <origin xyz="0.17084 0.0 -0.0595" rpy="0 0 0" />
    <parent link="leg_r6_link" />
    <child link="r_foot_toe" />
  </joint>
  <link name="r_foot_heel">
    <collision>
      <origin rpy="0 0 0" xyz="0 0 0" />
      <geometry>
        <sphere radius="0.005" />
      </geometry>
    </collision>
  </link>
  <joint name="r_foot_heel_joint" type="fixed">
    <origin xyz="-0.073164 0.0 -0.0595" rpy="0 0 0" />
    <parent link="leg_r6_link" />
    <child link="r_foot_heel" />
  </joint>
  <link name="zarm_l1_link">
    <inertial>
      <origin xyz="0.00194934 -0.01222074 -0.00024523" rpy="0 0 0" />
      <mass value="0.95200000" />
      <inertia ixx="0.00177952" ixy="-0.00003936" ixz="-0.00000075" iyy="0.00088093" iyz="0.00000096" izz="0.00174476" />
    </inertial>
    <visual>
      <origin xyz="0 0 0" rpy="0 0 0" />
      <geometry>
        <mesh filename="package://kuavo_assets/models/biped_s49/meshes/l_arm_pitch.STL" />
      </geometry>
      <material name="">
        <color rgba="1 1 1 1" />
      </material>
    </visual>
    <collision>
      <origin xyz="0 0 0" rpy="0 1.5708 0" />
      <geometry>
        <capsule radius="0.05" length="0.04" />
      </geometry>
    </collision>
  </link>
  <joint name="zarm_l1_joint" type="revolute">
    <origin xyz="-0.017499853 0.29269999999999996 0.4245" rpy="0 0 0" />
    <parent link="base_link" />
    <child link="zarm_l1_link" />
    <axis xyz="0 1 0" />
    <limit lower="-3.14159265358979" upper="1.5707963267949" effort="66.67" velocity="18.8" />
    <dynamics damping="0.02" friction="0.02" />
  </joint>
  <link name="zarm_l2_link">
    <inertial>
      <origin xyz="-0.00112901 0.00000665 -0.04637050" rpy="0 0 0" />
      <mass value="0.38500000" />
      <inertia ixx="0.00080437" ixy="-0.00000011" ixz="-0.00001699" iyy="0.00115579" iyz="-0.00000014" izz="0.00070010" />
    </inertial>
    <visual>
      <origin xyz="0 0 0" rpy="0 0 0" />
      <geometry>
        <mesh filename="package://kuavo_assets/models/biped_s49/meshes/l_arm_roll.STL" />
      </geometry>
      <material name="">
        <color rgba="1 1 1 1" />
      </material>
    </visual>
  </link>
  <joint name="zarm_l2_joint" type="revolute">
    <origin xyz="0 0 0" rpy="0 0 0" />
    <parent link="zarm_l1_link" />
    <child link="zarm_l2_link" />
    <axis xyz="1 0 0" />
    <limit lower="-0.349065850398866" upper="2.0943951023932" effort="75.0" velocity="8.0" />
    <dynamics damping="0.02" friction="0.02" />
  </joint>
  <link name="zarm_l3_link">
    <inertial>
      <origin xyz="0.00936999 0.00334408 -0.22965779" rpy="0 0 0" />
      <mass value="1.75450000" />
      <inertia ixx="0.00694471" ixy="-0.00006963" ixz="0.00081484" iyy="0.00704370" iyz="0.00033391" izz="0.00183829" />
    </inertial>
    <visual>
      <origin xyz="0 0 0" rpy="0 0 0" />
      <geometry>
        <mesh filename="package://kuavo_assets/models/biped_s49/meshes/l_arm_yaw.STL" />
      </geometry>
      <material name="">
        <color rgba="1 1 1 1" />
      </material>
    </visual>
    <collision>
      <origin xyz="0 0 -0.18" rpy="0 0 0" />
      <geometry>
        <capsule radius="0.045" length="0.14" />
      </geometry>
    </collision>
  </link>
  <joint name="zarm_l3_joint" type="revolute">
    <origin xyz="0 0 0" rpy="0 0 0" />
    <parent link="zarm_l2_link" />
    <child link="zarm_l3_link" />
    <axis xyz="0 0 1" />
    <limit lower="-1.5707963267949" upper="1.5707963267949" effort="57.0" velocity="7.5" />
    <dynamics damping="0.02" friction="0.02" />
  </joint>
  <link name="zarm_l4_link">
    <inertial>
      <origin xyz="-0.01825634 0.00149605 -0.06877688" rpy="0 0 0" />
      <mass value="0.60780000" />
      <inertia ixx="0.00144524" ixy="-0.00000754" ixz="-0.00012207" iyy="0.00125753" iyz="-0.00003303" izz="0.00065063" />
    </inertial>
    <visual>
      <origin xyz="0 0 0" rpy="0 0 0" />
      <geometry>
        <mesh filename="package://kuavo_assets/models/biped_s49/meshes/l_forearm.STL" />
      </geometry>
      <material name="">
        <color rgba="1 1 1 1" />
      </material>
    </visual>
    <collision>
      <origin xyz="-0.02 0 -0.14" rpy="0 0 0" />
      <geometry>
        <capsule radius="0.045" length="0.18" />
      </geometry>
    </collision>
  </link>
  <joint name="zarm_l4_joint" type="revolute">
    <origin xyz="0.0200000000000006 0 -0.283699999999996" rpy="0 0 0" />
    <parent link="zarm_l3_link" />
    <child link="zarm_l4_link" />
    <axis xyz="0 1 0" />
    <limit lower="-2.61799387799149" upper="0.0" effort="75.0" velocity="8.0" />
    <dynamics damping="0.02" friction="0.02" />
  </joint>
  <link name="zarm_l5_link">
    <inertial>
      <origin xyz="-0.00874165 -0.00001372 -0.05033323" rpy="0 0 0" />
      <mass value="0.63690000" />
      <inertia ixx="0.00063700" ixy="-0.00000007" ixz="-0.00005666" iyy="0.00094941" iyz="0.00000002" izz="0.00054303" />
    </inertial>
    <visual>
      <origin xyz="0 0 0" rpy="0 0 0" />
      <geometry>
        <mesh filename="package://kuavo_assets/models/biped_s49/meshes/l_hand_yaw.STL" />
      </geometry>
      <material name="">
        <color rgba="1 1 1 1" />
      </material>
    </visual>
  </link>
  <joint name="zarm_l5_joint" type="revolute">
    <origin xyz="-0.0200000000000025 0 -0.127037274261591" rpy="0 0 0" />
    <parent link="zarm_l4_link" />
    <child link="zarm_l5_link" />
    <axis xyz="0 0 1" />
    <limit lower="-1.5707963267949" upper="1.5707963267949" effort="14.1" velocity="17.5" />
    <dynamics damping="0.02" friction="0.02" />
  </joint>
  <link name="zarm_l6_link">
    <inertial>
      <origin xyz="-0.00158864 0.00654094 -0.01506679" rpy="0 0 0" />
      <mass value="0.47390000" />
      <inertia ixx="0.00018068" ixy="-0.00000464" ixz="0.00001148" iyy="0.00025494" iyz="0.00001047" izz="0.00026772" />
    </inertial>
    <visual>
      <origin xyz="0 0 0" rpy="0 0 0" />
      <geometry>
        <mesh filename="package://kuavo_assets/models/biped_s49/meshes/l_hand_roll.STL" />
      </geometry>
      <material name="">
        <color rgba="1 1 1 1" />
      </material>
    </visual>
  </link>
  <joint name="zarm_l6_joint" type="revolute">
    <origin xyz="0.000199999999999079 0 -0.106462725738415" rpy="0 0 0" />
    <parent link="zarm_l5_link" />
    <child link="zarm_l6_link" />
    <axis xyz="1 0 0" />
    <limit lower="-1.30899693899575" upper="0.698131700797732" effort="14.1" velocity="17.5" />
    <dynamics damping="0.02" friction="0.02" />
  </joint>
  <link name="zarm_l7_link">
    <inertial>
      <origin xyz="0.00186 0.01014 -0.09044" rpy="0 0 0" />
      <mass value="0.0542110173081966" />
      <inertia ixx="0.00071" ixy="1e-05" ixz="2e-05" iyy="0.0007" iyz="-4e-05" izz="0.00012" />
    </inertial>
    <visual>
      <origin xyz="0 0 0" rpy="0 0 0" />
      <geometry>
        <mesh filename="package://kuavo_assets/models/biped_s49/meshes/l_hand_pitch.STL" />
      </geometry>
      <material name="">
        <color rgba="1 1 1 1" />
      </material>
    </visual>
    <collision>
      <origin xyz="0 0 -0.158" rpy="0 0 -3.1415" />
      <geometry>
        <box size="0.08 0.05 0.16" />
      </geometry>
    </collision>
    <collision>
      <origin xyz="0.0505 -0.0292 -0.116372" rpy="0 -0.2545 0" />
      <geometry>
        <cylinder radius="0.01" length="0.08" />
      </geometry>
    </collision>
  </link>
  <joint name="zarm_l7_joint" type="revolute">
    <origin xyz="0 0 -0.0210004653879916" rpy="0 0 0" />
    <parent link="zarm_l6_link" />
    <child link="zarm_l7_link" />
    <axis xyz="0 1 0" />
    <limit lower="-0.698131700797732" upper="0.698131700797732" effort="14.1" velocity="17.5" />
    <dynamics damping="0.02" friction="0.02" />
  </joint>
  <link name="zarm_l7_end_effector">
  </link>
  <joint name="zarm_l7_end_effector_joint" type="fixed">
    <origin xyz="0 -0.03 -0.17" rpy="0 0 0" />
    <parent link="zarm_l7_link" />
    <child link="zarm_l7_end_effector" />
  </joint>
  <link name="zarm_r1_link">
    <inertial>
      <origin xyz="0.00194934 0.01222074 -0.00024523" rpy="0 0 0" />
      <mass value="0.95200000" />
      <inertia ixx="0.00177952" ixy="0.00003936" ixz="-0.00000075" iyy="0.00088093" iyz="-0.00000096" izz="0.00174476" />
    </inertial>
    <visual>
      <origin xyz="0 0 0" rpy="0 0 0" />
      <geometry>
        <mesh filename="package://kuavo_assets/models/biped_s49/meshes/r_arm_pitch.STL" />
      </geometry>
      <material name="">
        <color rgba="1 1 1 1" />
      </material>
    </visual>
    <collision>
      <origin xyz="0 0 0" rpy="0 1.5708 0" />
      <geometry>
        <capsule radius="0.05" length="0.04" />
      </geometry>
    </collision>
  </link>
  <joint name="zarm_r1_joint" type="revolute">
    <origin xyz="-0.017499853 -0.29269999999999996 0.4245" rpy="0 0 0" />
    <parent link="base_link" />
    <child link="zarm_r1_link" />
    <axis xyz="0 1 0" />
    <limit lower="-3.14159265358979" upper="1.5707963267949" effort="66.67" velocity="18.8" />
    <dynamics damping="0.02" friction="0.02" />
  </joint>
  <link name="zarm_r2_link">
    <inertial>
      <origin xyz="-0.00112901 -0.00000665 -0.04637050" rpy="0 0 0" />
      <mass value="0.38500000" />
      <inertia ixx="0.00080437" ixy="0.00000011" ixz="-0.00001699" iyy="0.00115579" iyz="0.00000014" izz="0.00070010" />
    </inertial>
    <visual>
      <origin xyz="0 0 0" rpy="0 0 0" />
      <geometry>
        <mesh filename="package://kuavo_assets/models/biped_s49/meshes/r_arm_roll.STL" />
      </geometry>
      <material name="">
        <color rgba="1 1 1 1" />
      </material>
    </visual>
  </link>
  <joint name="zarm_r2_joint" type="revolute">
    <origin xyz="0 0 0" rpy="0 0 0" />
    <parent link="zarm_r1_link" />
    <child link="zarm_r2_link" />
    <axis xyz="1 0 0" />
    <limit lower="-2.0943951023932" upper="0.349065850398866" effort="75.0" velocity="8.0" />
    <dynamics damping="0.02" friction="0.02" />
  </joint>
  <link name="zarm_r3_link">
    <inertial>
      <origin xyz="0.00936999 -0.00334408 -0.22965779" rpy="0 0 0" />
      <mass value="1.75450000" />
      <inertia ixx="0.00694471" ixy="0.00006963" ixz="0.00081484" iyy="0.00704370" iyz="-0.00033391" izz="0.00183829" />
    </inertial>
    <visual>
      <origin xyz="0 0 0" rpy="0 0 0" />
      <geometry>
        <mesh filename="package://kuavo_assets/models/biped_s49/meshes/r_arm_yaw.STL" />
      </geometry>
      <material name="">
        <color rgba="1 1 1 1" />
      </material>
    </visual>
    <collision>
      <origin xyz="0 0 -0.18" rpy="0 0 0" />
      <geometry>
        <capsule radius="0.045" length="0.14" />
      </geometry>
    </collision>
  </link>
  <joint name="zarm_r3_joint" type="revolute">
    <origin xyz="0 0 0" rpy="0 0 0" />
    <parent link="zarm_r2_link" />
    <child link="zarm_r3_link" />
    <axis xyz="0 0 1" />
    <limit lower="-1.5707963267949" upper="1.5707963267949" effort="57.0" velocity="7.5" />
    <dynamics damping="0.02" friction="0.02" />
  </joint>
  <link name="zarm_r4_link">
    <inertial>
      <origin xyz="-0.01825634 -0.00149605 -0.06877688" rpy="0 0 0" />
      <mass value="0.60780000" />
      <inertia ixx="0.00144524" ixy="0.00000754" ixz="-0.00012207" iyy="0.00125753" iyz="0.00003303" izz="0.00065063" />
    </inertial>
    <visual>
      <origin xyz="0 0 0" rpy="0 0 0" />
      <geometry>
        <mesh filename="package://kuavo_assets/models/biped_s49/meshes/r_forearm.STL" />
      </geometry>
      <material name="">
        <color rgba="1 1 1 1" />
      </material>
    </visual>
    <collision>
      <origin xyz="-0.02 0 -0.14" rpy="0 0 0" />
      <geometry>
        <capsule radius="0.045" length="0.18" />
      </geometry>
    </collision>
  </link>
  <joint name="zarm_r4_joint" type="revolute">
    <origin xyz="0.0200000000000024 0 -0.2837" rpy="0 0 0" />
    <parent link="zarm_r3_link" />
    <child link="zarm_r4_link" />
    <axis xyz="0 1 0" />
    <limit lower="-2.61799387799149" upper="0.0" effort="75.0" velocity="8.0" />
    <dynamics damping="0.02" friction="0.02" />
  </joint>
  <link name="zarm_r5_link">
    <inertial>
      <origin xyz="-0.00874165 0.00001372 -0.05033323" rpy="0 0 0" />
      <mass value="0.63690000" />
      <inertia ixx="0.00063700" ixy="0.00000007" ixz="-0.00005666" iyy="0.00094941" iyz="-0.00000002" izz="0.00054303" />
    </inertial>
    <visual>
      <origin xyz="0 0 0" rpy="0 0 0" />
      <geometry>
        <mesh filename="package://kuavo_assets/models/biped_s49/meshes/r_hand_yaw.STL" />
      </geometry>
      <material name="">
        <color rgba="1 1 1 1" />
      </material>
    </visual>
  </link>
  <joint name="zarm_r5_joint" type="revolute">
    <origin xyz="-0.0200000000000001 0 -0.127037274261587" rpy="0 0 0" />
    <parent link="zarm_r4_link" />
    <child link="zarm_r5_link" />
    <axis xyz="0 0 1" />
    <limit lower="-1.5707963267949" upper="1.5707963267949" effort="14.1" velocity="17.5" />
    <dynamics damping="0.02" friction="0.02" />
  </joint>
  <link name="zarm_r6_link">
    <inertial>
      <origin xyz="-0.00158864 -0.00654094 -0.01506679" rpy="0 0 0" />
      <mass value="0.47390000" />
      <inertia ixx="0.00018068" ixy="0.00000464" ixz="0.00001148" iyy="0.00025494" iyz="-0.00001047" izz="0.00026772" />
    </inertial>
    <visual>
      <origin xyz="0 0 0" rpy="0 0 0" />
      <geometry>
        <mesh filename="package://kuavo_assets/models/biped_s49/meshes/r_hand_roll.STL" />
      </geometry>
      <material name="">
        <color rgba="1 1 1 1" />
      </material>
    </visual>
  </link>
  <joint name="zarm_r6_joint" type="revolute">
    <origin xyz="0 0 -0.106462725738415" rpy="0 0 0" />
    <parent link="zarm_r5_link" />
    <child link="zarm_r6_link" />
    <axis xyz="1 0 0" />
    <limit lower="-0.698131700797732" upper="1.30899693899575" effort="14.1" velocity="17.5" />
    <dynamics damping="0.02" friction="0.02" />
  </joint>
  <link name="zarm_r7_link">
    <inertial>
      <origin xyz="0.00000000 -0.01153440 -0.03004157" rpy="0 0 0" />
      <mass value="0.11660000" />
      <inertia ixx="0.00013730" ixy="-0.00000004" ixz="-0.00000002" iyy="0.00008156" iyz="0.00002135" izz="0.00010541" />
    </inertial>
    <visual>
      <origin xyz="0 0 0" rpy="0 0 0" />
      <geometry>
        <mesh filename="package://kuavo_assets/models/biped_s49/meshes/r_hand_pitch.STL" />
      </geometry>
      <material name="">
        <color rgba="1 1 1 1" />
      </material>
    </visual>
    <collision>
      <origin xyz="0 0 -0.158" rpy="0 0 -3.1415" />
      <geometry>
        <box size="0.08 0.05 0.16" />
      </geometry>
    </collision>
    <collision>
      <origin xyz="0.0505 0.0292 -0.116372" rpy="0 -0.2545 0" />
      <geometry>
        <cylinder radius="0.01" length="0.08" />
      </geometry>
    </collision>
  </link>
  <joint name="zarm_r7_joint" type="revolute">
    <origin xyz="0 0 -0.0209999999999999" rpy="0 0 0" />
    <parent link="zarm_r6_link" />
    <child link="zarm_r7_link" />
    <axis xyz="0 1 0" />
    <limit lower="-0.698131700797732" upper="0.698131700797732" effort="14.1" velocity="17.5" />
    <dynamics damping="0.02" friction="0.02" />
  </joint>
  <link name="zarm_r7_end_effector">
  </link>
  <joint name="zarm_r7_end_effector_joint" type="fixed">
    <origin xyz="0 0.03 -0.17" rpy="0 0 0" />
    <parent link="zarm_r7_link" />
    <child link="zarm_r7_end_effector" />
  </joint>

  
  <link name="l_palm">
    <inertial>
      <origin xyz="0.0017239 0.0051432 -0.031065" rpy="0 0 0" />
      <mass value="0.427" />
      <inertia ixx="0.0010405" ixy="-3.7268E-05" ixz="-3.9415E-05" iyy="0.0013244" iyz="-4.7638E-05" izz="0.00053219" />
    </inertial>
    <visual>
      <origin xyz="0 0 0" rpy="0 0 0" />
      <geometry>
        <mesh filename="package://kuavo_assets/models/biped_s49/meshes/l_palm.STL" />
      </geometry>
      <material name="">
        <color rgba="0.75294 0.75294 0.75294 1" />
      </material>
    </visual>
    <collision>
      <origin xyz="0 0 0" rpy="0 0 0" />
      <geometry>
        <mesh filename="package://kuavo_assets/models/biped_s49/meshes/l_palm.STL" />
      </geometry>
    </collision>
  </link>
  <link name="l_thumb_prox">
    <inertial>
      <origin xyz="0.0017239 0.0051432 -0.031065" rpy="0 0 0" />
      <mass value="0.005" />
      <inertia ixx="0.0010405" ixy="-3.7268E-05" ixz="-3.9415E-05" iyy="0.0013244" iyz="-4.7638E-05" izz="0.00053219" />
    </inertial>
    <visual>
      <origin xyz="0 0 0" rpy="0 0 0" />
      <geometry>
        <mesh filename="package://kuavo_assets/models/biped_s49/meshes/l_thumb_prox.STL" />
      </geometry>
      <material name="">
        <color rgba="0.75294 0.75294 0.75294 1" />
      </material>
    </visual>
    <collision>
      <origin xyz="0 0 0" rpy="0 0 0" />
      <geometry>
        <mesh filename="package://kuavo_assets/models/biped_s49/meshes/l_thumb_prox.STL" />
      </geometry>
    </collision>
  </link>
  <joint name="l_thumbCMC" type="revolute">
    <origin xyz="-0.0245 0.022632 0.023263" rpy="0.14578 -1.0699 -0.12808" />
    <parent link="l_palm" />
    <child link="l_thumb_prox" />
    <axis xyz="0 1 0" />
    <limit lower="0" upper="1.5708" effort="0" velocity="0" />
    <dynamics damping="0" friction="0" />
  </joint>
  <link name="l_thumb_dist">
    <inertial>
      <origin xyz="0.0017239 0.0051432 -0.031065" rpy="0 0 0" />
      <mass value="0.04" />
      <inertia ixx="0.0010405" ixy="-3.7268E-05" ixz="-3.9415E-05" iyy="0.0013244" iyz="-4.7638E-05" izz="0.00053219" />
    </inertial>
    <visual>
      <origin xyz="0 0 0" rpy="0 0 0" />
      <geometry>
        <mesh filename="package://kuavo_assets/models/biped_s49/meshes/l_thumb_dist.STL" />
      </geometry>
      <material name="">
        <color rgba="0.75294 0.75294 0.75294 1" />
      </material>
    </visual>
    <collision>
      <origin xyz="0 0 0" rpy="0 0 0" />
      <geometry>
        <mesh filename="package://kuavo_assets/models/biped_s49/meshes/l_thumb_dist.STL" />
      </geometry>
    </collision>
  </link>
  <joint name="l_thumbMCP" type="revolute">
    <origin xyz="0 0 0.013647" rpy="0.87266 -0.49642 0" />
    <parent link="l_thumb_prox" />
    <child link="l_thumb_dist" />
    <axis xyz="-1 0 0" />
    <limit lower="0" upper="0.8727" effort="0" velocity="0" />
    <dynamics damping="0" friction="0" />
  </joint>
  <link name="l_Index_prox">
    <inertial>
      <origin xyz="0.0017239 0.0051432 -0.031065" rpy="0 0 0" />
      <mass value="0.008" />
      <inertia ixx="0.0010405" ixy="-3.7268E-05" ixz="-3.9415E-05" iyy="0.0013244" iyz="-4.7638E-05" izz="0.00053219" />
    </inertial>
    <visual>
      <origin xyz="0 0 0" rpy="0 0 0" />
      <geometry>
        <mesh filename="package://kuavo_assets/models/biped_s49/meshes/l_Index_prox.STL" />
      </geometry>
      <material name="">
        <color rgba="0.75294 0.75294 0.75294 1" />
      </material>
    </visual>
    <collision>
      <origin xyz="0 0 0" rpy="0 0 0" />
      <geometry>
        <mesh filename="package://kuavo_assets/models/biped_s49/meshes/l_Index_prox.STL" />
      </geometry>
    </collision>
  </link>
  <joint name="l_indexMCP" type="revolute">
    <origin xyz="-0.029003 0.088291 0.0022155" rpy="-0.029415 0.05236 0.034907" />
    <parent link="l_palm" />
    <child link="l_Index_prox" />
    <axis xyz="1 0 0" />
    <limit lower="0" upper="1.309" effort="0" velocity="0" />
    <dynamics damping="0" friction="0" />
  </joint>
  <link name="l_index_dist">
    <inertial>
      <origin xyz="0.0017239 0.0051432 -0.031065" rpy="0 0 0" />
      <mass value="0.011" />
      <inertia ixx="0.0010405" ixy="-3.7268E-05" ixz="-3.9415E-05" iyy="0.0013244" iyz="-4.7638E-05" izz="0.00053219" />
    </inertial>
    <visual>
      <origin xyz="0 0 0" rpy="0 0 0" />
      <geometry>
        <mesh filename="package://kuavo_assets/models/biped_s49/meshes/l_index_dist.STL" />
      </geometry>
      <material name="">
        <color rgba="0.75294 0.75294 0.75294 1" />
      </material>
    </visual>
    <collision>
      <origin xyz="0 0 0" rpy="0 0 0" />
      <geometry>
        <mesh filename="package://kuavo_assets/models/biped_s49/meshes/l_index_dist.STL" />
      </geometry>
    </collision>
  </link>
  <joint name="l_indexPIP" type="revolute">
    <origin xyz="0 0.035 0" rpy="0.19353 0 0" />
    <parent link="l_Index_prox" />
    <child link="l_index_dist" />
    <axis xyz="1 0 0" />
    <limit lower="0" upper="1.25" effort="0" velocity="0" />
  </joint>
  <link name="l_middle_prox">
    <inertial>
      <origin xyz="0.0017239 0.0051432 -0.031065" rpy="0 0 0" />
      <mass value="0.011" />
      <inertia ixx="0.0010405" ixy="-3.7268E-05" ixz="-3.9415E-05" iyy="0.0013244" iyz="-4.7638E-05" izz="0.00053219" />
    </inertial>
    <visual>
      <origin xyz="0 0 0" rpy="0 0 0" />
      <geometry>
        <mesh filename="package://kuavo_assets/models/biped_s49/meshes/l_middle_prox.STL" />
      </geometry>
      <material name="">
        <color rgba="0.75294 0.75294 0.75294 1" />
      </material>
    </visual>
    <collision>
      <origin xyz="0 0 0" rpy="0 0 0" />
      <geometry>
        <mesh filename="package://kuavo_assets/models/biped_s49/meshes/l_middle_prox.STL" />
      </geometry>
    </collision>
  </link>
  <joint name="l_middleMCP" type="revolute">
    <origin xyz="-0.008 0.092284 -0.0017707" rpy="0 0 0" />
    <parent link="l_palm" />
    <child link="l_middle_prox" />
    <axis xyz="1 0 0" />
    <limit lower="0" upper="1.309" effort="0" velocity="0" />
    <dynamics damping="0" friction="0" />
  </joint>
  <link name="l_middle_dist">
    <inertial>
      <origin xyz="0.0017239 0.0051432 -0.031065" rpy="0 0 0" />
      <mass value="0.011" />
      <inertia ixx="0.0010405" ixy="-3.7268E-05" ixz="-3.9415E-05" iyy="0.0013244" iyz="-4.7638E-05" izz="0.00053219" />
    </inertial>
    <visual>
      <origin xyz="0 0 0" rpy="0 0 0" />
      <geometry>
        <mesh filename="package://kuavo_assets/models/biped_s49/meshes/l_middle_dist.STL" />
      </geometry>
      <material name="">
        <color rgba="0.75294 0.75294 0.75294 1" />
      </material>
    </visual>
    <collision>
      <origin xyz="0 0 0" rpy="0 0 0" />
      <geometry>
        <mesh filename="package://kuavo_assets/models/biped_s49/meshes/l_middle_dist.STL" />
      </geometry>
    </collision>
  </link>
  <joint name="l_middlePIP" type="revolute">
    <origin xyz="0 0.042 0" rpy="0.18357 0 0" />
    <parent link="l_middle_prox" />
    <child link="l_middle_dist" />
    <axis xyz="1 0 0" />
    <limit lower="0" upper="1.25" effort="0" velocity="0" />
  </joint>
  <link name="l_ring_prox">
    <inertial>
      <origin xyz="0.0017239 0.0051432 -0.031065" rpy="0 0 0" />
      <mass value="0.011" />
      <inertia ixx="0.0010405" ixy="-3.7268E-05" ixz="-3.9415E-05" iyy="0.0013244" iyz="-4.7638E-05" izz="0.00053219" />
    </inertial>
    <visual>
      <origin xyz="0 0 0" rpy="0 0 0" />
      <geometry>
        <mesh filename="package://kuavo_assets/models/biped_s49/meshes/l_ring_prox.STL" />
      </geometry>
      <material name="">
        <color rgba="0.75294 0.75294 0.75294 1" />
      </material>
    </visual>
    <collision>
      <origin xyz="0 0 0" rpy="0 0 0" />
      <geometry>
        <mesh filename="package://kuavo_assets/models/biped_s49/meshes/l_ring_prox.STL" />
      </geometry>
    </collision>
  </link>
  <joint name="l_ringMCP" type="revolute">
    <origin xyz="0.013103 0.090291 -0.0017845" rpy="-0.0092374 -0.05236 -0.034907" />
    <parent link="l_palm" />
    <child link="l_ring_prox" />
    <axis xyz="1 0 0" />
    <limit lower="0" upper="1.309" effort="0" velocity="0" />
    <dynamics damping="0" friction="0" />
  </joint>
  <link name="l_ring_dist">
    <inertial>
      <origin xyz="0.0017239 0.0051432 -0.031065" rpy="0 0 0" />
      <mass value="0.008" />
      <inertia ixx="0.0010405" ixy="-3.7268E-05" ixz="-3.9415E-05" iyy="0.0013244" iyz="-4.7638E-05" izz="0.00053219" />
    </inertial>
    <visual>
      <origin xyz="0 0 0" rpy="0 0 0" />
      <geometry>
        <mesh filename="package://kuavo_assets/models/biped_s49/meshes/l_ring_dist.STL" />
      </geometry>
      <material name="">
        <color rgba="0.75294 0.75294 0.75294 1" />
      </material>
    </visual>
    <collision>
      <origin xyz="0 0 0" rpy="0 0 0" />
      <geometry>
        <mesh filename="package://kuavo_assets/models/biped_s49/meshes/l_ring_dist.STL" />
      </geometry>
    </collision>
  </link>
  <joint name="l_ringPIP" type="revolute">
    <origin xyz="0 0.042 0" rpy="0.16583 0 0" />
    <parent link="l_ring_prox" />
    <child link="l_ring_dist" />
    <axis xyz="1 0 0" />
    <limit lower="0" upper="1.25" effort="0" velocity="0" />
  </joint>
  <link name="l_little_prox">
    <inertial>
      <origin xyz="-5.4618E-07 0.016662 0.00040738" rpy="0 0 0" />
      <mass value="0.008" />
      <inertia ixx="3.3526E-07" ixy="2.8461E-11" ixz="-2.3358E-12" iyy="1.0129E-07" iyz="2.1346E-08" izz="3.7096E-07" />
    </inertial>
    <visual>
      <origin xyz="0 0 0" rpy="0 0 0" />
      <geometry>
        <mesh filename="package://kuavo_assets/models/biped_s49/meshes/l_little_prox.STL" />
      </geometry>
      <material name="">
        <color rgba="1 1 1 1" />
      </material>
    </visual>
    <collision>
      <origin xyz="0 0 0" rpy="0 0 0" />
      <geometry>
        <mesh filename="package://kuavo_assets/models/biped_s49/meshes/l_little_prox.STL" />
      </geometry>
    </collision>
  </link>
  <joint name="l_littleMCP" type="revolute">
    <origin xyz="0.033731 0.083777 0.0022155" rpy="-0.024909 -0.05236 -0.069813" />
    <parent link="l_palm" />
    <child link="l_little_prox" />
    <axis xyz="1 0 0" />
    <limit lower="0" upper="1.309" effort="0" velocity="0" />
    <dynamics damping="0" friction="0" />
  </joint>
  <link name="l_little_dist">
    <inertial>
      <origin xyz="0.0017239 0.0051432 -0.031065" rpy="0 0 0" />
      <mass value="0.008" />
      <inertia ixx="0.0010405" ixy="-3.7268E-05" ixz="-3.9415E-05" iyy="0.0013244" iyz="-4.7638E-05" izz="0.00053219" />
    </inertial>
    <visual>
      <origin xyz="0 0 0" rpy="0 0 0" />
      <geometry>
        <mesh filename="package://kuavo_assets/models/biped_s49/meshes/l_little_dist.STL" />
      </geometry>
      <material name="">
        <color rgba="0.75294 0.75294 0.75294 1" />
      </material>
    </visual>
    <collision>
      <origin xyz="0 0 0" rpy="0 0 0" />
      <geometry>
        <mesh filename="package://kuavo_assets/models/biped_s49/meshes/l_little_dist.STL" />
      </geometry>
    </collision>
  </link>
  <joint name="l_littlePIP" type="revolute">
    <origin xyz="0 0.035 0" rpy="0.20294 0 0" />
    <parent link="l_little_prox" />
    <child link="l_little_dist" />
    <axis xyz="1 0 0" />
    <limit lower="0" upper="1.25" effort="0" velocity="0" />
  </joint>
  <link name="r_palm">
    <inertial>
      <origin xyz="-0.00099373 0.040537 -0.0022835" rpy="0 0 0" />
      <mass value="0.427" />
      <inertia ixx="0.0010405" ixy="-3.7268E-05" ixz="-3.9415E-05" iyy="0.0013244" iyz="-4.7638E-05" izz="0.00053219" />
    </inertial>
    <visual>
      <origin xyz="0 0 0" rpy="0 0 0" />
      <geometry>
        <mesh filename="package://kuavo_assets/models/biped_s49/meshes/r_palm.STL" />
      </geometry>
      <material name="">
        <color rgba="0.75294 0.75294 0.75294 1" />
      </material>
    </visual>
    <collision>
      <origin xyz="0 0 0" rpy="0 0 0" />
      <geometry>
        <mesh filename="package://kuavo_assets/models/biped_s49/meshes/r_palm.STL" />
      </geometry>
    </collision>
  </link>
  <link name="r_thumb_prox">
    <inertial>
      <origin xyz="0.0062041 -7.9383E-08 0.0015306" rpy="0 0 0" />
      <mass value="0.005" />
      <inertia ixx="4.0639E-08" ixy="5.8675E-13" ixz="2.4299E-09" iyy="9.2485E-08" iyz="7.1049E-13" izz="8.5586E-08" />
    </inertial>
    <visual>
      <origin xyz="0 0 0" rpy="0 0 0" />
      <geometry>
        <mesh filename="package://kuavo_assets/models/biped_s49/meshes/r_thumb_prox.STL" />
      </geometry>
      <material name="">
        <color rgba="0.75294 0.75294 0.75294 1" />
      </material>
    </visual>
    <collision>
      <origin xyz="0 0 0" rpy="0 0 0" />
      <geometry>
        <mesh filename="package://kuavo_assets/models/biped_s49/meshes/r_thumb_prox.STL" />
      </geometry>
    </collision>
  </link>
  <joint name="r_thumbCMC" type="revolute">
    <origin xyz="0.0245 0.0242 0.021628" rpy="0 -0.49642 0" />
    <parent link="r_palm" />
    <child link="r_thumb_prox" />
    <axis xyz="0 -1 0" />
    <limit lower="0" upper="1.5708" effort="0" velocity="0" />
    <dynamics damping="0" friction="0" />
  </joint>
  <link name="r_thumb_dist">
    <inertial>
      <origin xyz="0.0083564 0.037204 -3.5884E-07" rpy="0 0 0" />
      <mass value="0.04" />
      <inertia ixx="7.1498E-06" ixy="2.0157E-07" ixz="-6.0726E-11" iyy="9.1501E-07" iyz="5.4502E-10" izz="6.8747E-06" />
    </inertial>
    <visual>
      <origin xyz="0 0 0" rpy="0 0 0" />
      <geometry>
        <mesh filename="package://kuavo_assets/models/biped_s49/meshes/r_thumb_dist.STL" />
      </geometry>
      <material name="">
        <color rgba="0.75294 0.75294 0.75294 1" />
      </material>
    </visual>
    <collision>
      <origin xyz="0 0 0" rpy="0 0 0" />
      <geometry>
        <mesh filename="package://kuavo_assets/models/biped_s49/meshes/r_thumb_dist.STL" />
      </geometry>
    </collision>
  </link>
  <joint name="r_thumbMCP" type="revolute">
    <origin xyz="0.013647 0 0" rpy="-0.39332 0.31115 -0.93514" />
    <parent link="r_thumb_prox" />
    <child link="r_thumb_dist" />
    <axis xyz="0 0 1" />
    <limit lower="0" upper="0.87266" effort="0" velocity="0" />
    <dynamics damping="0" friction="0" />

  </joint>
  <link name="r_index_prox">
    <inertial>
      <origin xyz="-5.571E-07 0.016609 0.00045746" rpy="0 0 0" />
      <mass value="0.008" />
      <inertia ixx="3.3526E-07" ixy="2.9401E-11" ixz="-2.4782E-12" iyy="1.0133E-07" iyz="2.0576E-08" izz="3.7092E-07" />
    </inertial>
    <visual>
      <origin xyz="0 0 0" rpy="0 0 0" />
      <geometry>
        <mesh filename="package://kuavo_assets/models/biped_s49/meshes/r_index_prox.STL" />
      </geometry>
      <material name="">
        <color rgba="0.75294 0.75294 0.75294 1" />
      </material>
    </visual>
    <collision>
      <origin xyz="0 0 0" rpy="0 0 0" />
      <geometry>
        <mesh filename="package://kuavo_assets/models/biped_s49/meshes/r_index_prox.STL" />
      </geometry>
    </collision>
  </link>
  <joint name="r_indexMCP" type="revolute">
    <origin xyz="0.029003 0.088231 -0.0039488" rpy="-0.09929 -0.054667 -0.031168" />
    <parent link="r_palm" />
    <child link="r_index_prox" />
    <axis xyz="1 0 0" />
    <limit lower="0" upper="1.309" effort="0" velocity="0" />
    <dynamics damping="0" friction="0" />
  </joint>
  <link name="r_index_dist">
    <inertial>
      <origin xyz="5.9401E-06 0.025449 0.003278" rpy="0 0 0" />
      <mass value="0.011" />
      <inertia ixx="8.4801E-07" ixy="-1.0878E-09" ixz="-1.3683E-10" iyy="1.4147E-07" iyz="-1.0078E-07" izz="8.5502E-07" />
    </inertial>
    <visual>
      <origin xyz="0 0 0" rpy="0 0 0" />
      <geometry>
        <mesh filename="package://kuavo_assets/models/biped_s49/meshes/r_index_dist.STL" />
      </geometry>
      <material name="">
        <color rgba="0.75294 0.75294 0.75294 1" />
      </material>
    </visual>
    <collision>
      <origin xyz="0 0 0" rpy="0 0 0" />
      <geometry>
        <mesh filename="package://kuavo_assets/models/biped_s49/meshes/r_index_dist.STL" />
      </geometry>
    </collision>
  </link>
  <joint name="r_indexPIP" type="revolute">
    <origin xyz="0 0.035 0" rpy="0.19353 0 0" />
    <parent link="r_index_prox" />
    <child link="r_index_dist" />
    <axis xyz="1 0 0" />
    <limit lower="0" upper="1.25" effort="0" velocity="0" />
  </joint>
  <link name="r_middle_prox">
    <inertial>
      <origin xyz="2.3779E-07 0.020205 0.00053993" rpy="0 0 0" />
      <mass value="0.011" />
      <inertia ixx="5.5624E-07" ixy="8E-12" ixz="-8.5151E-12" iyy="1.3298E-07" iyz="2.669E-08" izz="6.0146E-07" />
    </inertial>
    <visual>
      <origin xyz="0 0 0" rpy="0 0 0" />
      <geometry>
        <mesh filename="package://kuavo_assets/models/biped_s49/meshes/r_middle_prox.STL" />
      </geometry>
      <material name="">
        <color rgba="0.75294 0.75294 0.75294 1" />
      </material>
    </visual>
    <collision>
      <origin xyz="0 0 0" rpy="0 0 0" />
      <geometry>
        <mesh filename="package://kuavo_assets/models/biped_s49/meshes/r_middle_prox.STL" />
      </geometry>
    </collision>
  </link>
  <joint name="r_middleMCP" type="revolute">
    <origin xyz="0.008 0.091935 -0.0082038" rpy="-0.069813 0 0" />
    <parent link="r_palm" />
    <child link="r_middle_prox" />
    <axis xyz="1 0 0" />
    <limit lower="0" upper="1.309" effort="0" velocity="0" />
  </joint>
  <link name="r_middle_dist">
    <inertial>
      <origin xyz="5.9404E-06 0.025449 0.003278" rpy="0 0 0" />
      <mass value="0.011" />
      <inertia ixx="8.4801E-07" ixy="-1.0879E-09" ixz="-1.3705E-10" iyy="1.4147E-07" iyz="-1.0078E-07" izz="8.5501E-07" />
    </inertial>
    <visual>
      <origin xyz="0 0 0" rpy="0 0 0" />
      <geometry>
        <mesh filename="package://kuavo_assets/models/biped_s49/meshes/r_middle_dist.STL" />
      </geometry>
      <material name="">
        <color rgba="0.75294 0.75294 0.75294 1" />
      </material>
    </visual>
    <collision>
      <origin xyz="0 0 0" rpy="0 0 0" />
      <geometry>
        <mesh filename="package://kuavo_assets/models/biped_s49/meshes/r_middle_dist.STL" />
      </geometry>
    </collision>
  </link>
  <joint name="r_middlePIP" type="revolute">
    <origin xyz="0 0.042 0" rpy="0.18357 0 0" />
    <parent link="r_middle_prox" />
    <child link="r_middle_dist" />
    <axis xyz="1 0 0" />
    <limit lower="0" upper="1.25" effort="0" velocity="0" />
  </joint>
  <link name="r_ring_prox">
    <inertial>
      <origin xyz="2.4507E-07 0.020236 0.00042373" rpy="0 0 0" />
      <mass value="0.011" />
      <inertia ixx="5.5623E-07" ixy="7.4604E-12" ixz="-8.5876E-12" iyy="1.3295E-07" iyz="2.7719E-08" izz="6.0149E-07" />
    </inertial>
    <visual>
      <origin xyz="0 0 0" rpy="0 0 0" />
      <geometry>
        <mesh filename="package://kuavo_assets/models/biped_s49/meshes/r_ring_prox.STL" />
      </geometry>
      <material name="">
        <color rgba="0.75294 0.75294 0.75294 1" />
      </material>
    </visual>
    <collision>
      <origin xyz="0 0 0" rpy="0 0 0" />
      <geometry>
        <mesh filename="package://kuavo_assets/models/biped_s49/meshes/r_ring_prox.STL" />
      </geometry>
    </collision>
  </link>
  <joint name="r_ringMCP" type="revolute">
    <origin xyz="-0.013103 0.089947 -0.0080786" rpy="-0.079113 0.054667 0.031168" />
    <parent link="r_palm" />
    <child link="r_ring_prox" />
    <axis xyz="1 0 0" />
    <limit lower="0" upper="1.309" effort="0" velocity="0" />
  </joint>
  <link name="r_ring_dist">
    <inertial>
      <origin xyz="5.5799E-07 0.020388 0.0029077" rpy="0 0 0" />
      <mass value="0.008" />
      <inertia ixx="3.6793E-07" ixy="-6.504E-13" ixz="-1.1541E-11" iyy="8.4208E-08" iyz="-4.5737E-08" izz="3.8369E-07" />
    </inertial>
    <visual>
      <origin xyz="0 0 0" rpy="0 0 0" />
      <geometry>
        <mesh filename="package://kuavo_assets/models/biped_s49/meshes/r_ring_dist.STL" />
      </geometry>
      <material name="">
        <color rgba="0.75294 0.75294 0.75294 1" />
      </material>
    </visual>
    <collision>
      <origin xyz="0 0 0" rpy="0 0 0" />
      <geometry>
        <mesh filename="package://kuavo_assets/models/biped_s49/meshes/r_ring_dist.STL" />
      </geometry>
    </collision>
  </link>
  <joint name="r_ringPIP" type="revolute">
    <origin xyz="0 0.042 0" rpy="0.16583 0 0" />
    <parent link="r_ring_prox" />
    <child link="r_ring_dist" />
    <axis xyz="1 0 0" />
    <limit lower="0" upper="1.25" effort="0" velocity="0" />
  </joint>
  <link name="r_little_prox">
    <inertial>
      <origin xyz="-5.4618E-07 0.016662 0.00040738" rpy="0 0 0" />
      <mass value="0.008" />
      <inertia ixx="3.3526E-07" ixy="2.8461E-11" ixz="-2.3358E-12" iyy="1.0129E-07" iyz="2.1346E-08" izz="3.7096E-07" />
    </inertial>
    <visual>
      <origin xyz="0 0 0" rpy="0 0 0" />
      <geometry>
        <mesh filename="package://kuavo_assets/models/biped_s49/meshes/r_little_prox.STL" />
      </geometry>
      <material name="">
        <color rgba="0.75294 0.75294 0.75294 1" />
      </material>
    </visual>
    <collision>
      <origin xyz="0 0 0" rpy="0 0 0" />
      <geometry>
        <mesh filename="package://kuavo_assets/models/biped_s49/meshes/r_little_prox.STL" />
      </geometry>
    </collision>
  </link>
  <joint name="r_littleMCP" type="revolute">
    <origin xyz="-0.033731 0.083727 -0.0036339" rpy="-0.094666 0.057099 0.065996" />
    <parent link="r_palm" />
    <child link="r_little_prox" />
    <axis xyz="1 0 0" />
    <limit lower="0" upper="1.309" effort="0" velocity="0" />
  </joint>
  <link name="r_little_dist">
    <inertial>
      <origin xyz="1.062E-05 0.017869 0.0020864" rpy="0 0 0" />
      <mass value="0.008" />
      <inertia ixx="2.3262E-07" ixy="-4.9135E-10" ixz="-4.9506E-11" iyy="6.4304E-08" iyz="-2.3564E-08" izz="2.4916E-07" />
    </inertial>
    <visual>
      <origin xyz="0 0 0" rpy="0 0 0" />
      <geometry>
        <mesh filename="package://kuavo_assets/models/biped_s49/meshes/r_little_dist.STL" />
      </geometry>
      <material name="">
        <color rgba="0.75294 0.75294 0.75294 1" />
      </material>
    </visual>
    <collision>
      <origin xyz="0 0 0" rpy="0 0 0" />
      <geometry>
        <mesh filename="package://kuavo_assets/models/biped_s49/meshes/r_little_dist.STL" />
      </geometry>
    </collision>
  </link>
  <joint name="r_littlePIP" type="revolute">
    <origin xyz="0 0.035 0" rpy="0.20294 0 0" />
    <parent link="r_little_prox" />
    <child link="r_little_dist" />
    <axis xyz="1 0 0" />
    <limit lower="0" upper="1.25" effort="0" velocity="0" />
  </joint>
  <joint name="l_palm_fixed_joint" type="fixed">
    <parent link="zarm_l7_link" />
    <child link="l_palm" />
    <origin xyz="0 0 -0.07" rpy="-1.57 0 -3.14" />
  </joint>
  <joint name="r_palm_fixed_joint" type="fixed">
    <parent link="zarm_r7_link" />
    <child link="r_palm" />
    <origin xyz="0 0 -0.07" rpy="-1.57 0 0" />
  </joint>
  
  <link name="zhead_1_link">
    <inertial>
      <origin xyz="2e-05 0.00605 -0.01052" rpy="0 0 0" />
      <mass value="0.35" />
      <inertia ixx="7e-05" ixy="0.0" ixz="0.0" iyy="5e-05" iyz="0.0" izz="5e-05" />
    </inertial>
    <visual>
      <origin xyz="0 0 0" rpy="0 0 0" />
      <geometry>
        <mesh filename="package://kuavo_assets/models/biped_s49/meshes/head_yaw.STL" />
      </geometry>
      <material name="">
        <color rgba="1 1 1 1" />
      </material>
    </visual>
  </link>
  <joint name="zhead_1_joint" type="revolute">
    <origin xyz="-0.018499853 0.0 0.6014" rpy="0 0 0" />
    <parent link="base_link" />
    <child link="zhead_1_link" />
    <axis xyz="0 0 1" />
    <limit lower="-1.5707963267949" upper="1.5707963267949" effort="1.5" velocity="5.23333333333333" />
    <dynamics damping="0.02" friction="0.02" />
  </joint>
  <link name="zhead_2_link">
    <inertial>
      <origin xyz="0.02648 -0.00142 0.10674" rpy="0 0 0" />
      <mass value="0.5492" />
      <inertia ixx="0.00346" ixy="-3e-05" ixz="0.00017" iyy="0.00348" iyz="-7e-05" izz="0.00222" />
    </inertial>
    <visual>
      <origin xyz="0 0 0" rpy="0 0 0" />
      <geometry>
        <mesh filename="package://kuavo_assets/models/biped_s49/meshes/head_pitch.STL" />
      </geometry>
      <material name="">
        <color rgba="1 1 1 1" />
      </material>
    </visual>
    <collision>
      <origin xyz="0.02 0 0.07" rpy="0 0 0" />
      <geometry>
        <sphere radius="0.11"/>
      </geometry>
    </collision>
  </link>
  <joint name="zhead_2_joint" type="revolute">
    <origin xyz="0 0 0" rpy="0 0 0" />
    <parent link="zhead_1_link" />
    <child link="zhead_2_link" />
    <axis xyz="0 1 0" />
    <limit lower="-0.523598775598299" upper="0.523598775598299" effort="12.0" velocity="5.23333333333333" />
    <dynamics damping="0.02" friction="0.02" />
  </joint>
  <link name="camera">
    <inertial>
      <origin xyz="-0.0110151953425729 -0.047537884051738 -0.000424186924504522" rpy="0 0 0" />
      <mass value="0.0497265773443356" />
      <inertia ixx="5.98915749180566E-05" ixy="-2.37367664899747E-07" ixz="1.1063908098364E-07" iyy="5.85534933735723E-06" iyz="-9.37601013594939E-08" izz="5.93979980552286E-05" />
    </inertial>
    <visual>
      <origin xyz="0 0 0" rpy="0 0 0" />
      <geometry>
        <mesh filename="package://kuavo_assets/models/biped_s49/meshes/camera.STL" />
      </geometry>
      <material name="">
        <color rgba="1 1 1 1" />
      </material>
    </visual>
  </link>
  <joint name="camera" type="fixed">
    <origin xyz="0.102420738776518 -0.0475000000000003 0.126192926717169" rpy="3.14159265358979 0.383972435438723 0" />
    <parent link="zhead_2_link" />
    <child link="camera" />
  </joint>

  <link name="camera_base">
    <inertial>
      <origin xyz="-5.55111512312578E-17 -4.4419175457545E-19 0.00100000000000011" rpy="0 0 0" />
      <mass value="0.0000392699081698732" />
      <inertia ixx="7.4449200905385E-11" ixy="3.01192140313567E-27" ixz="1.70444442625673E-24" iyy="7.4449200905385E-11" iyz="2.72974080552399E-27" izz="1.22718463030854E-10" />
    </inertial>
    <visual>
      <origin xyz="0 0 0" rpy="0 0 0" />
      <geometry>
        <mesh filename="package://kuavo_assets/models/biped_s49/meshes/camera_base.STL" />
      </geometry>
      <material name="">
        <color rgba="1 1 1 1" />
      </material>
    </visual>
  </link>
  <joint name="camera_base" type="fixed">
    <origin xyz="0.0932759773834307 0 0.145322661773667" rpy="3.14159265358979 0.383972435438723 0" />
    <parent link="zhead_2_link" />
    <child link="camera_base" />
  </joint>

  <link name="radar">
    <inertial>
      <origin xyz="-0.000169547665515829 -5.97889663913359E-06 -0.0189252009085568" rpy="0 0 0" />
      <mass value="0.149896342265089" />
      <inertia ixx="8.50848760861648E-05" ixy="6.13387165669695E-09" ixz="-2.11395069307914E-08" iyy="7.4407064439256E-05" iyz="1.79787433943266E-08" izz="9.0848870289101E-05" />
    </inertial>
    <visual>
      <origin xyz="0 0 0" rpy="0 0 0" />
      <geometry>
        <mesh filename="package://kuavo_assets/models/biped_s49/meshes/radar.STL" />
      </geometry>
      <material name="">
        <color rgba="1 1 1 1" />
      </material>
    </visual>
  </link>
  <joint name="radar" type="fixed">
    <origin xyz="0.0217799337881943 0 0.105417258037133" rpy="0 0.229686043245049 0" />
    <parent link="zhead_2_link" />
    <child link="radar" />
  </joint>

  <link name="l_hand_tripod">
    <inertial>
      <origin xyz="0.0653430919091347 -0.00776026775236038 -0.0648805742218587" rpy="0 0 0" />
      <mass value="0.0342669089979502" />
      <inertia ixx="1.59850149176395E-05" ixy="-5.29139847447712E-06" ixz="1.78131910236665E-05" iyy="9.8758759051122E-05" iyz="-2.71719747666022E-07" izz="9.75721402715185E-05" />
    </inertial>
    <visual>
      <origin xyz="0 0 0" rpy="0 0 0" />
      <geometry>
        <mesh filename="package://kuavo_assets/models/biped_s49/meshes/l_hand_tripod.STL" />
      </geometry>
      <material name="">
        <color rgba="1 1 1 1" />
      </material>
    </visual>
  </link>
  <joint name="l_hand_tripod_joint" type="fixed">
    <origin xyz="0.0 0.0 0.0" rpy="0.0 0.0 0.0" />
    <parent link="zarm_l7_link" />
    <child link="l_hand_tripod" />
    <axis xyz="0 0 0" />
  </joint>

  <link name="l_hand_camera">
    <inertial>
      <origin xyz="-5.55111512312578E-17 -5.55111512312578E-17 0.0114631923429834" rpy="0 0 0" />
      <mass value="0.038145442577304" />
      <inertia ixx="6.90025820370885E-06" ixy="2.08889460021576E-21" ixz="-6.35274710440725E-22" iyy="6.86774271974419E-06" iyz="-4.21980924697416E-22" izz="1.04248094301688E-05" />
    </inertial>
    <visual>
      <origin xyz="0 0 0" rpy="0 -1.57 0" />
      <geometry>
        <mesh filename="package://kuavo_assets/models/biped_s49/meshes/l_hand_camera.STL" />
      </geometry>
      <material name="">
        <color rgba="1 1 1 1" />
      </material>
    </visual>
  </link>
  <joint name="l_hand_camera_joint" type="fixed">
    <origin xyz="0.11540559159102 -0.0145586110669961 -0.110123491595499" rpy="1.919862177193763 0.753528063917894 -2.897246568680842" />
    <parent link="l_hand_tripod" />
    <child link="l_hand_camera" />
    <axis xyz="0 0 0" />
  </joint>

  <link name="r_hand_tripod">
    <inertial>
      <origin xyz="0.0653431459436017 0.00833186007885223 -0.0625275130281983" rpy="0 0 0" />
      <mass value="0.034266881719861" />
      <inertia ixx="1.5985004453075E-05" ixy="5.17271984897294E-06" ixz="1.78480505198324E-05" iyy="9.87551311174154E-05" iyz="2.79574204670866E-07" izz="9.75758243581943E-05" />
    </inertial>
    <visual>
      <origin xyz="0 0 0" rpy="0 0 0" />
      <geometry>
        <mesh filename="package://kuavo_assets/models/biped_s49/meshes/r_hand_tripod.STL" />
      </geometry>
      <material name="">
        <color rgba="1 1 1 1" />
      </material>
    </visual>
  </link>
  <joint name="r_hand_tripod_joint" type="fixed">
    <origin xyz="0.0 0.0 0.0" rpy="0.0 0.0 0.0" />
    <parent link="zarm_r7_link" />
    <child link="r_hand_tripod" />
    <axis xyz="0 0 0" />
  </joint>

  <link name="r_hand_camera">
    <inertial>
      <origin xyz="0 5.55111512312578E-17 0.0114631923429834" rpy="0 0 0" />
      <mass value="0.038145442577304" />
      <inertia ixx="6.90025820370885E-06" ixy="-5.73053564581591E-21" ixz="-1.27054942088145E-21" iyy="6.8677427197442E-06" iyz="7.56979586483243E-22" izz="1.04248094301688E-05" />
    </inertial>
    <visual>
      <origin xyz="0 0 0" rpy="0 -1.57 0" />
      <geometry>
        <mesh filename="package://kuavo_assets/models/biped_s49/meshes/r_hand_camera.STL" />
      </geometry>
      <material name="">
        <color rgba="1 1 1 1" />
      </material>
    </visual>
  </link>
  <joint name="r_hand_camera_joint" type="fixed">
    <origin xyz="0.115405591590931 0.0154312352120435 -0.107724128430896" rpy="1.208853693239594  0.751879414295006 2.888346587751982" />
    <parent link="r_hand_tripod" />
    <child link="r_hand_camera" />
    <axis xyz="0 0 0" />
  </joint>
</robot>