<?xml version="1.0" ?>
<!-- =================================================================================== -->
<!-- |    This document was autogenerated by xacro from /home/fandes/workspace/kuavo-ros-control/src/humanoid-control/humanoid_interface_drake/models/biped_gen4.2/urdf/biped_v3.xacro | -->
<!-- |    EDITING THIS FILE BY HAND IS NOT RECOMMENDED                                 | -->
<!-- =================================================================================== -->
<robot name="biped_v3" xmlns:drake="https://drake.mit.edu">
  <link name="torso">
    <inertial>
      <origin xyz="-0.05544692 -8.47e-06 -0.01711528" rpy="0 0 0" />
      <mass value="18.31059052" />
      <inertia ixx="0.0667764" ixy="-1.17e-05" ixz="-0.01674051" iyy="0.04863528" iyz="-2.3e-05" izz="0.06510003" />
    </inertial>
    <visual>
      <origin xyz="0 0 0" rpy="0 0 0" />
      <geometry>
        <mesh filename="../../meshes/waist.STL" />
      </geometry>
      <material name="">
        <color rgba="1 1 1 1" />
      </material>
    </visual>
    <!-- <collision>
      <origin xyz="0 0 0" rpy="0 0 0" />
      <geometry>
        <mesh filename="../../meshes/torso.STL" />
      </geometry>
    </collision> -->
  </link>
  <link name="waist_yaw_link">
    <inertial>
      <origin xyz="-0.00159612 0.00020086 0.1617458" rpy="0 0 0" />
      <mass value="14.40420829" />
      <inertia ixx="0.26137016" ixy="0.00016429" ixz="-0.00061701" iyy="0.18547942" iyz="-0.00031301" izz="0.15250849" />
    </inertial>
    <visual>
      <origin xyz="0 0 0" rpy="0 0 0" />
      <geometry>
        <mesh filename="../../meshes/waist_yaw.STL" />
      </geometry>
      <material name="">
        <color rgba="1 1 1 1" />
      </material>
    </visual>
  </link>
  <joint name="waist_yaw_joint" type="fixed">
    <origin xyz="0 0 0.1114" rpy="0 0 0" />
    <parent link="torso" />
    <child link="waist_yaw_link" />
    <axis xyz="0 0 1" />
    <limit lower="-2.0943951023932" upper="2.0943951023932" effort="180.0" velocity="23.55" />
  </joint>
  <link name="leg_l1_link">
    <inertial>
      <origin xyz="-0.00557048 0.0001034 0.00085759" rpy="0 0 0" />
      <mass value="1.64455435" />
      <inertia ixx="0.00163506" ixy="0" ixz="0" iyy="0.00216311" iyz="0" izz="0.00221783" />
    </inertial>
    <visual>
      <origin xyz="0 0 0" rpy="0 0 0" />
      <geometry>
        <mesh filename="../../meshes/l_leg_roll.STL" />
      </geometry>
      <material name="">
        <color rgba="1 1 1 1" />
      </material>
    </visual>
  </link>
  <joint name="leg_l1_joint" type="revolute">
    <origin xyz="0.0 0.095075 -0.066" rpy="0 0 0" />
    <parent link="torso" />
    <child link="leg_l1_link" />
    <axis xyz="1 0 0" />
    <limit lower="-0.314159265358979" upper="0.663225115757845" effort="180.0" velocity="23.55" />
    <dynamics damping="0.2" friction="0.0" />
  </joint>
  <transmission type="SimpleTransmission">
    <joint name="leg_l1_joint" />
    <actuator name="leg_l1_joint_motor" />
  </transmission>
  <link name="leg_l2_link">
    <inertial>
      <origin xyz="0.00016522 -0.0009135 -0.08522232" rpy="0 0 0" />
      <mass value="0.66827879" />
      <inertia ixx="0.00270485" ixy="-9.1e-05" ixz="4.5e-05" iyy="0.00142441" iyz="-6.247e-05" izz="0.00203171" />
    </inertial>
    <visual>
      <origin xyz="0 0 0" rpy="0 0 0" />
      <geometry>
        <mesh filename="../../meshes/l_leg_yaw.STL" />
      </geometry>
      <material name="">
        <color rgba="1 1 1 1" />
      </material>
    </visual>
  </link>
  <joint name="leg_l2_joint" type="revolute">
    <origin xyz="0 0 0" rpy="0 0 0" />
    <parent link="leg_l1_link" />
    <child link="leg_l2_link" />
    <axis xyz="0 0 1" />
    <limit lower="-1.91986217719376" upper="0.785398163397448" effort="100.0" velocity="41.3433333333333" />
    <dynamics damping="0.2" friction="0.0" />
  </joint>
  <transmission type="SimpleTransmission">
    <joint name="leg_l2_joint" />
    <actuator name="leg_l2_joint_motor" />
  </transmission>
  <link name="leg_l3_link">
    <inertial>
      <origin xyz="0.00257848 0.01034304 -0.07701646" rpy="0 0 0" />
      <mass value="5.8434291" />
      <inertia ixx="0.0458011" ixy="0" ixz="0" iyy="0.04329809" iyz="0" izz="0.016013" />
    </inertial>
    <visual>
      <origin xyz="0 0 0" rpy="0 0 0" />
      <geometry>
        <mesh filename="../../meshes/l_leg_pitch.STL" />
      </geometry>
      <material name="">
        <color rgba="1 1 1 1" />
      </material>
    </visual>
  </link>
  <joint name="leg_l3_joint" type="revolute">
    <origin xyz="0 0 -0.1287" rpy="0 0 0" />
    <parent link="leg_l2_link" />
    <child link="leg_l3_link" />
    <axis xyz="0 1 0" />
    <limit lower="-1.91986217719376" upper="1.5707963267949" effort="100.0" velocity="41.3433333333333" />
    <dynamics damping="0.2" friction="0.0" />
  </joint>
  <transmission type="SimpleTransmission">
    <joint name="leg_l3_joint" />
    <actuator name="leg_l3_joint_motor" />
  </transmission>
  <link name="leg_l4_link">
    <inertial>
      <origin xyz="0.00197388 0.00024837 -0.16654127" rpy="0 0 0" />
      <mass value="3.9518102" />
      <inertia ixx="0.04536357" ixy="-6.3e-05" ixz="-0.00020999" iyy="0.04473961" iyz="-0.00019395" izz="0.00182132" />
    </inertial>
    <visual>
      <origin xyz="0 0 0" rpy="0 0 0" />
      <geometry>
        <mesh filename="../../meshes/l_knee.STL" />
      </geometry>
      <material name="">
        <color rgba="1 1 1 1" />
      </material>
    </visual>
  </link>
  <joint name="leg_l4_joint" type="revolute">
    <origin xyz="0 0 -0.284" rpy="0 0 0" />
    <parent link="leg_l3_link" />
    <child link="leg_l4_link" />
    <axis xyz="0 1 0" />
    <limit lower="0.0" upper="2.53072741539178" effort="180.0" velocity="23.55" />
    <dynamics damping="0.2" friction="0.0" />
  </joint>
  <transmission type="SimpleTransmission">
    <joint name="leg_l4_joint" />
    <actuator name="leg_l4_joint_motor" />
  </transmission>
  <link name="leg_l5_link">
    <inertial>
      <origin xyz="0.0 0.0 0.0" rpy="0 0 0" />
      <mass value="0.07848005" />
      <inertia ixx="7.6e-05" ixy="0.0" ixz="0.0" iyy="7.6e-05" iyz="0.0" izz="1.318e-05" />
    </inertial>
    <visual>
      <origin xyz="0 0 0" rpy="0 0 0" />
      <geometry>
        <mesh filename="../../meshes/l_foot_pitch.STL" />
      </geometry>
      <material name="">
        <color rgba="1 1 1 1" />
      </material>
    </visual>
  </link>
  <joint name="leg_l5_joint" type="revolute">
    <origin xyz="-6.0000000117628E-05 0 -0.416000000000006" rpy="0 0 0" />
    <parent link="leg_l4_link" />
    <child link="leg_l5_link" />
    <axis xyz="0 1 0" />
    <limit lower="-0.872664625997165" upper="0.349065850398866" effort="36.0" velocity="23.0266666666667" />
    <dynamics damping="0.2" friction="0.0" />
  </joint>
  <transmission type="SimpleTransmission">
    <joint name="leg_l5_joint" />
    <actuator name="leg_l5_joint_motor" />
  </transmission>
  <link name="leg_l6_link">
    <inertial>
      <origin xyz="0.03128029 -2.11e-06 -0.03618572" rpy="0 0 0" />
      <mass value="0.58491513" />
      <inertia ixx="0.00046778" ixy="2e-05" ixz="0.00010442" iyy="0.00176376" iyz="0.0" izz="0.00188181" />
    </inertial>
    <visual>
      <origin xyz="0 0 0" rpy="0 0 0" />
      <geometry>
        <mesh filename="../../meshes/l_foot_roll.STL" />
      </geometry>
      <material name="">
        <color rgba="1 1 1 1" />
      </material>
    </visual>
  </link>
  <joint name="leg_l6_joint" type="revolute">
    <origin xyz="0 0 0" rpy="0 0 0" />
    <parent link="leg_l5_link" />
    <child link="leg_l6_link" />
    <axis xyz="1 0 0" />
    <limit lower="-0.261799387799149" upper="0.261799387799149" effort="36.0" velocity="23.0266666666667" />
    <dynamics damping="0.2" friction="0.0" />
  </joint>
  <transmission type="SimpleTransmission">
    <joint name="leg_l6_joint" />
    <actuator name="leg_l6_joint_motor" />
  </transmission>
  <frame link="leg_l6_link" name="l_foot_sole" xyz="0.04883799999999999 0.0 -0.0595" />
  <frame link="leg_l6_link" name="l_foot_toe" xyz="0.17084 0.0 -0.0595" />
  <frame link="leg_l6_link" name="l_foot_heel" xyz="-0.073164 0.0 -0.0595" />
  <link name="leg_r1_link">
    <inertial>
      <origin xyz="-0.00553134 -0.00012646 0.00087795" rpy="0 0 0" />
      <mass value="1.64458061" />
      <inertia ixx="0.00163851" ixy="0" ixz="0" iyy="0.00216627" iyz="0" izz="0.00221857" />
    </inertial>
    <visual>
      <origin xyz="0 0 0" rpy="0 0 0" />
      <geometry>
        <mesh filename="../../meshes/r_leg_roll.STL" />
      </geometry>
      <material name="">
        <color rgba="1 1 1 1" />
      </material>
    </visual>
  </link>
  <joint name="leg_r1_joint" type="revolute">
    <origin xyz="0.0 -0.095075 -0.066" rpy="0 0 0" />
    <parent link="torso" />
    <child link="leg_r1_link" />
    <axis xyz="1 0 0" />
    <limit lower="-0.663225115757845" upper="0.314159265358979" effort="180.0" velocity="23.55" />
    <dynamics damping="0.2" friction="0.0" />
  </joint>
  <transmission type="SimpleTransmission">
    <joint name="leg_r1_joint" />
    <actuator name="leg_r1_joint_motor" />
  </transmission>
  <link name="leg_r2_link">
    <inertial>
      <origin xyz="-0.00016522 0.0009135 -0.08522232" rpy="0 0 0" />
      <mass value="0.66827879" />
      <inertia ixx="0.00270485" ixy="-9.1e-05" ixz="-4.5e-05" iyy="0.00142441" iyz="6.247e-05" izz="0.00203171" />
    </inertial>
    <visual>
      <origin xyz="0 0 0" rpy="0 0 0" />
      <geometry>
        <mesh filename="../../meshes/r_leg_yaw.STL" />
      </geometry>
      <material name="">
        <color rgba="1 1 1 1" />
      </material>
    </visual>
  </link>
  <joint name="leg_r2_joint" type="revolute">
    <origin xyz="0 0 0" rpy="0 0 0" />
    <parent link="leg_r1_link" />
    <child link="leg_r2_link" />
    <axis xyz="0 0 1" />
    <limit lower="-0.785398163397448" upper="1.91986217719376" effort="100.0" velocity="41.3433333333333" />
    <dynamics damping="0.2" friction="0.0" />
  </joint>
  <transmission type="SimpleTransmission">
    <joint name="leg_r2_joint" />
    <actuator name="leg_r2_joint_motor" />
  </transmission>
  <link name="leg_r3_link">
    <inertial>
      <origin xyz="0.00268686 -0.01036567 -0.07700447" rpy="0 0 0" />
      <mass value="5.84104988" />
      <inertia ixx="0.04579387" ixy="0" ixz="0" iyy="0.04330015" iyz="0" izz="0.01600773" />
    </inertial>
    <visual>
      <origin xyz="0 0 0" rpy="0 0 0" />
      <geometry>
        <mesh filename="../../meshes/r_leg_pitch.STL" />
      </geometry>
      <material name="">
        <color rgba="1 1 1 1" />
      </material>
    </visual>
  </link>
  <joint name="leg_r3_joint" type="revolute">
    <origin xyz="0 0 -0.128699999999999" rpy="0 0 0" />
    <parent link="leg_r2_link" />
    <child link="leg_r3_link" />
    <axis xyz="0 1 0" />
    <limit lower="-1.91986217719376" upper="1.5707963267949" effort="100.0" velocity="41.3433333333333" />
    <dynamics damping="0.2" friction="0.0" />
  </joint>
  <transmission type="SimpleTransmission">
    <joint name="leg_r3_joint" />
    <actuator name="leg_r3_joint_motor" />
  </transmission>
  <link name="leg_r4_link">
    <inertial>
      <origin xyz="0.00226376 -0.00032432 -0.16655795" rpy="0 0 0" />
      <mass value="3.95182115" />
      <inertia ixx="0.04536281" ixy="-2.3e-05" ixz="-6.078e-05" iyy="0.04472851" iyz="0.00018537" izz="0.00180857" />
    </inertial>
    <visual>
      <origin xyz="0 0 0" rpy="0 0 0" />
      <geometry>
        <mesh filename="../../meshes/r_knee.STL" />
      </geometry>
      <material name="">
        <color rgba="1 1 1 1" />
      </material>
    </visual>
  </link>
  <joint name="leg_r4_joint" type="revolute">
    <origin xyz="0 0 -0.284000000000001" rpy="0 0 0" />
    <parent link="leg_r3_link" />
    <child link="leg_r4_link" />
    <axis xyz="0 1 0" />
    <limit lower="0.0" upper="2.53072741539178" effort="180.0" velocity="23.55" />
    <dynamics damping="0.2" friction="0.0" />
  </joint>
  <transmission type="SimpleTransmission">
    <joint name="leg_r4_joint" />
    <actuator name="leg_r4_joint_motor" />
  </transmission>
  <link name="leg_r5_link">
    <inertial>
      <origin xyz="0.0 0.0 0.0" rpy="0 0 0" />
      <mass value="0.07848005" />
      <inertia ixx="7.6e-05" ixy="0.0" ixz="0.0" iyy="7.6e-05" iyz="0.0" izz="1.318e-05" />
    </inertial>
    <visual>
      <origin xyz="0 0 0" rpy="0 0 0" />
      <geometry>
        <mesh filename="../../meshes/r_foot_pitch.STL" />
      </geometry>
      <material name="">
        <color rgba="1 1 1 1" />
      </material>
    </visual>
  </link>
  <joint name="leg_r5_joint" type="revolute">
    <origin xyz="-6.00000001180747E-05 0 -0.416000000000007" rpy="0 0 0" />
    <parent link="leg_r4_link" />
    <child link="leg_r5_link" />
    <axis xyz="0 1 0" />
    <limit lower="-0.872664625997165" upper="0.349065850398866" effort="36.0" velocity="23.0266666666667" />
    <dynamics damping="0.2" friction="0.0" />
  </joint>
  <transmission type="SimpleTransmission">
    <joint name="leg_r5_joint" />
    <actuator name="leg_r5_joint_motor" />
  </transmission>
  <link name="leg_r6_link">
    <inertial>
      <origin xyz="0.03128029 -2.11e-06 -0.03618572" rpy="0 0 0" />
      <mass value="0.58491513" />
      <inertia ixx="0.00046778" ixy="2e-05" ixz="0.00010442" iyy="0.00176376" iyz="0.0" izz="0.00188181" />
    </inertial>
    <visual>
      <origin xyz="0 0 0" rpy="0 0 0" />
      <geometry>
        <mesh filename="../../meshes/r_foot_roll.STL" />
      </geometry>
      <material name="">
        <color rgba="1 1 1 1" />
      </material>
    </visual>
  </link>
  <joint name="leg_r6_joint" type="revolute">
    <origin xyz="0 0 0" rpy="0 0 0" />
    <parent link="leg_r5_link" />
    <child link="leg_r6_link" />
    <axis xyz="1 0 0" />
    <limit lower="-0.261799387799149" upper="0.261799387799149" effort="36.0" velocity="23.0266666666667" />
    <dynamics damping="0.2" friction="0.0" />
  </joint>
  <transmission type="SimpleTransmission">
    <joint name="leg_r6_joint" />
    <actuator name="leg_r6_joint_motor" />
  </transmission>
  <frame link="leg_r6_link" name="r_foot_sole" xyz="0.04883799999999999 0.0 -0.0595" />
  <frame link="leg_r6_link" name="r_foot_toe" xyz="0.17084 0.0 -0.0595" />
  <frame link="leg_r6_link" name="r_foot_heel" xyz="-0.073164 0.0 -0.0595" />
</robot>

