<?xml version='1.0' encoding='utf-8'?>
<mujoco model="biped_s61">
  <compiler angle="radian" meshdir="../meshes/" />
  <size njmax="500" nconmax="100" />

  <asset>
    <mesh name="base_link" file="base_link.STL"/>
    <mesh name="wheel_left_front" file="wheel_left_front.STL"/>
    <mesh name="wheel_right_front" file="wheel_right_front.STL"/>
    <mesh name="wheel_left_behind" file="wheel_left_behind.STL"/>
    <mesh name="wheel_right_behind" file="wheel_right_behind.STL"/>
    <mesh name="knee_link" file="knee_link.STL"/>
    <mesh name="leg_Link" file="leg_Link.STL"/>
    <mesh name="waist_pitch_Link" file="waist_pitch_Link.STL"/>
    <mesh name="waist_yaw_Link" file="waist_yaw_Link.STL"/>
    <mesh name="torso" file="torso.STL"/>
    <mesh name="l_arm_pitch" file="l_arm_pitch.STL"/>
    <mesh name="l_arm_roll" file="l_arm_roll.STL"/>
    <mesh name="l_arm_yaw" file="l_arm_yaw.STL"/>
    <mesh name="l_forearm" file="l_forearm.STL"/>
    <mesh name="l_hand_yaw" file="l_hand_yaw.STL"/>
    <mesh name="l_hand_roll" file="l_hand_roll.STL"/>
    <mesh name="l_hand_pitch_noHand" file="l_hand_pitch_noHand.STL"/>
    <mesh name="r_arm_pitch" file="r_arm_pitch.STL"/>
    <mesh name="r_arm_roll" file="r_arm_roll.STL"/>
    <mesh name="r_arm_yaw" file="r_arm_yaw.STL"/>
    <mesh name="r_forearm" file="r_forearm.STL"/>
    <mesh name="r_hand_yaw" file="r_hand_yaw.STL"/>
    <mesh name="r_hand_roll" file="r_hand_roll.STL"/>
    <mesh name="r_hand_pitch_noHand" file="r_hand_pitch_noHand.STL"/>
    <mesh name="head_yaw" file="head_yaw.STL"/>
    <mesh name="head_pitch" file="head_pitch.STL"/>
    <mesh name="head_camera" file="head_camera.STL"/>
    <mesh name="head_radar" file="head_radar.STL"/>
  </asset>

  <worldbody>
    <body name="base_link" pos="0 0 0">
      <freejoint />
      <site name="imu" pos="0 0 0" />
      <inertial pos="0.00537945 -0.000630114 0.198965" quat="0.019647 0.695011 -0.0174445 0.718519" mass="400.275" diaginertia="9.46041 6.41364 6.2676"/>
      <geom type="mesh" contype="0" conaffinity="0" group="1" density="0" rgba="1 1 1 1" mesh="base_link"/>
      <geom pos="0.232489 0.232489 0.13035" quat="0.92388 0 0 0.382683" type="mesh" contype="0" conaffinity="0" group="1" density="0" rgba="1 1 1 1" mesh="wheel_left_front"/>
      <geom pos="0.232489 -0.232489 0.13035" quat="0.92388 0 0 -0.382683" type="mesh" contype="0" conaffinity="0" group="1" density="0" rgba="1 1 1 1" mesh="wheel_right_front"/>
      <geom pos="-0.232489 0.232489 0.13035" quat="0.382683 0 0 0.92388" type="mesh" contype="0" conaffinity="0" group="1" density="0" rgba="1 1 1 1" mesh="wheel_left_behind"/>
      <geom pos="-0.232489 -0.232489 0.13035" quat="0.382683 0 0 -0.92388" type="mesh" contype="0" conaffinity="0" group="1" density="0" rgba="1 1 1 1" mesh="wheel_right_behind"/>
      <geom pos="0.098 0 0.270643" type="mesh" contype="0" conaffinity="0" group="1" density="0" rgba="1 1 1 1" mesh="knee_link"/>
      <body name="LF_wheel_yaw" pos="0.232489 0.232489 0.13035">
        <inertial pos="0 0 0" mass="0.0001" diaginertia="0.0000001 0.0000001 0.0000001"/>
        <joint name="LF_wheel_yaw_joint" pos="0 0 0" axis="0 0 1"/>
        <body name="LF_wheel_pitch">
          <inertial pos="0 0 0" mass="0.0001" diaginertia="0.0000001 0.0000001 0.0000001"/>
          <joint name="LF_wheel_pitch_joint" pos="0 0 0" axis="0 1 0"/>
          <geom size="0.13035 0.015" quat="0.707107 0.707107 0 0" type="cylinder" rgba="1 1 1 0" friction="3.0 0.001 0.001"/>
        </body>
      </body>
      <body name="RF_wheel_yaw" pos="0.232489 -0.232489 0.13035">
        <inertial pos="0 0 0" mass="0.0001" diaginertia="0.0000001 0.0000001 0.0000001"/>
        <joint name="RF_wheel_yaw_joint" pos="0 0 0" axis="0 0 1"/>
        <body name="RF_wheel_pitch">
          <inertial pos="0 0 0" mass="0.0001" diaginertia="0.0000001 0.0000001 0.0000001"/>
          <joint name="RF_wheel_pitch_joint" pos="0 0 0" axis="0 1 0"/>
          <geom size="0.13035 0.015" quat="0.707107 0.707107 0 0" type="cylinder" rgba="1 1 1 0" friction="3.0 0.001 0.001"/>
        </body>
      </body>
      <body name="LB_wheel_yaw" pos="-0.232489 0.232489 0.13035">
        <inertial pos="0 0 0" mass="0.0001" diaginertia="0.0000001 0.0000001 0.0000001"/>
        <joint name="LB_wheel_yaw_joint" pos="0 0 0" axis="0 0 1"/>
        <body name="LB_wheel_pitch">
          <inertial pos="0 0 0" mass="0.0001" diaginertia="0.0000001 0.0000001 0.0000001"/>
          <joint name="LB_wheel_pitch_joint" pos="0 0 0" axis="0 1 0"/>
          <geom size="0.13035 0.015" quat="0.707107 0.707107 0 0" type="cylinder" rgba="1 1 1 0" friction="3.0 0.001 0.001"/>
        </body>
      </body>
      <body name="RB_wheel_yaw" pos="-0.232489 -0.232489 0.13035">
        <inertial pos="0 0 0" mass="0.0001" diaginertia="0.00000001 0.0000001 0.0000001"/>
        <joint name="RB_wheel_yaw_joint" pos="0 0 0" axis="0 0 1"/>
        <body name="RB_wheel_pitch">
          <inertial pos="0 0 0" mass="0.0001" diaginertia="0.0000001 0.0000001 0.0000001"/>
          <joint name="RB_wheel_pitch_joint" pos="0 0 0" axis="0 1 0"/>
          <geom size="0.13035 0.015" quat="0.707107 0.707107 0 0" type="cylinder" rgba="1 1 1 0" friction="3.0 0.001 0.001"/>
        </body>
      </body>
      <body name="knee_link" pos="0.098 0 0.376143">
        <inertial pos="-0.228954 0.00062518 0.0881745" quat="-0.0046512 0.823659 0.0121074 0.566937" mass="13.4136" diaginertia="0.488625 0.449931 0.0890849"/>
        <joint name="knee_joint" pos="0 0 0" axis="0 1 0" range="0 1.44862" actuatorfrcrange="-668.53 668.53" damping="0.0"/>
        <geom type="mesh" contype="0" conaffinity="0" group="1" density="0" rgba="1 1 1 1" mesh="leg_Link"/>
        <body name="leg_link" pos="-0.46521 0 0.18325">
          <inertial pos="0.247062 0.0113029 0.0677251" quat="0.57029 0.439766 0.420379 0.551957" mass="9.78118" diaginertia="0.390917 0.373424 0.0334399"/>
          <joint name="leg_joint" pos="0 0 0" axis="0 1 0" range="-2.80998 0" actuatorfrcrange="-668.53 668.53"/>
          <geom type="mesh" contype="0" conaffinity="0" group="1" density="0" rgba="1 1 1 1" mesh="waist_pitch_Link"/>
          <body name="waist_pitch_link" pos="0.48296 0 0.12941">
            <inertial pos="-0.00148154 0 0.0584625" quat="0.707107 0.707107 0 0" mass="4.65998" diaginertia="0.047446 0.0387095 0.0364961"/>
            <joint name="waist_pitch_joint" pos="0 0 0" axis="0 1 0" range="-0.15708 2.98451" actuatorfrcrange="-618.48 618.48" damping="0.0"/>
            <geom type="mesh" contype="0" conaffinity="0" group="1" density="0" rgba="1 1 1 1" mesh="waist_yaw_Link"/>
            <body name="waist_yaw_link" pos="0 0 0.235">
              <inertial pos="0.00159298 -0.00027078 0.131874" mass="11.5609" diaginertia="0.246636 0.159377 0.158813"/>
              <joint name="waist_yaw_joint" pos="0 0 0" axis="0 0 1" range="-3.14159 3.14159" actuatorfrcrange="-618.48 618.48" damping="0.0"/>
              <geom type="mesh" contype="0" conaffinity="0" group="1" density="0" rgba="1 1 1 1" mesh="torso"/>
              <body name="zarm_l1_link" pos="0 0.2527 0.242">
                <inertial pos="0.00166796 -0.008241 0.00012987" quat="0.707107 0.707107 0 0" mass="0.916533" diaginertia="0.00126587 0.00124337 0.00086921"/>
                <joint name="zarm_l1_joint" pos="0 0 0" axis="0 1 0" range="-3.14159 1.5708" actuatorfrcrange="-66 66" damping="0.0"/>
                <geom pos="0 -0.081 0" quat="1 0 0 0" type="mesh" contype="0" conaffinity="0" group="1" density="0" rgba="1 1 1 1" mesh="l_arm_pitch"/>
                <body name="zarm_l2_link">
                  <inertial pos="-0.00080994 4.86e-06 -0.0465103" quat="0.707107 0 0 0.707107" mass="0.387674" diaginertia="0.00116144 0.00080739 0.00070223"/>
                  <joint name="zarm_l2_joint" pos="0 0 0" axis="1 0 0" range="-0.349066 3.49066" actuatorfrcrange="-75 75" damping="0.0"/>
                  <geom type="mesh" contype="0" conaffinity="0" group="1" density="0" rgba="1 1 1 1" mesh="l_arm_roll"/>
                  <body name="zarm_l3_link">
                    <inertial pos="0.00943019 0.00343988 -0.113045" quat="0.707107 0 0 0.707107" mass="1.77927" diaginertia="0.0100458 0.00992856 0.00185422"/>
                    <joint name="zarm_l3_joint" pos="0 0 0" axis="0 0 1" range="-1.48353 1.48353" actuatorfrcrange="-57 57" damping="0.0"/>
                    <geom type="mesh" contype="0" conaffinity="0" group="1" density="0" rgba="1 1 1 1" mesh="l_arm_yaw"/>
                    <body name="zarm_l4_link" pos="0.02 0 -0.2837">
                      <inertial pos="-0.0182993 0.00087167 -0.0693662" mass="0.585078" diaginertia="0.00143291 0.00125018 0.00068356"/>
                      <joint name="zarm_l4_joint" pos="0 0 0" axis="0 1 0" range="-2.61799 0" actuatorfrcrange="-75 75" damping="0.0"/>
                      <geom type="mesh" contype="0" conaffinity="0" group="1" density="0" rgba="1 1 1 1" mesh="l_forearm"/>
                      <body name="zarm_l5_link" pos="-0.02 0 -0.1195">
                        <inertial pos="0.0002609 1.322e-05 -0.0608394" quat="0.707107 0 0 0.707107" mass="0.6868" diaginertia="0.00122518 0.00086873 0.00066873"/>
                        <joint name="zarm_l5_joint" pos="0 0 0" axis="0 0 1" range="-1.5708 1.5708" actuatorfrcrange="-14.1 14.1" damping="0.0"/>
                        <geom type="mesh" contype="0" conaffinity="0" group="1" density="0" rgba="1 1 1 1" mesh="l_hand_yaw"/>
                        <body name="zarm_l6_link" pos="0 0 -0.114">
                          <inertial pos="0.00019162 0 -0.0174775" quat="0 0.707107 0 0.707107" mass="0.393872" diaginertia="0.0002021 0.00019853 0.00018535"/>
                          <joint name="zarm_l6_joint" pos="0 0 0" axis="1 0 0" range="-1.309 0.698132" actuatorfrcrange="-14.1 14.1" damping="0.0"/>
                          <geom type="mesh" contype="0" conaffinity="0" group="1" density="0" rgba="1 1 1 1" mesh="l_hand_roll"/>
                          <body name="zarm_l7_link" pos="0 0 -0.021">
                            <inertial pos="0 0 -0.102359" quat="0.707107 0 0 0.707107" mass="0.715902" diaginertia="0.00106704 0.00106284 0.00106143"/>
                            <joint name="zarm_l7_joint" pos="0 0 0" axis="0 1 0" range="-0.698132 0.698132" actuatorfrcrange="-14.1 14.1" damping="0.0"/>
                            <geom type="mesh" contype="0" conaffinity="0" group="1" density="0" rgba="1 1 1 1" mesh="l_hand_pitch_noHand"/>
                            <geom size="0.005" pos="0 0 -0.17"/>
                          </body>
                        </body>
                      </body>
                    </body>
                  </body>
                </body>
              </body>
              <body name="zarm_r1_link" pos="0 -0.2527 0.242">
                <inertial pos="-0.00166796 0.00839971 0.00012987" quat="0.707107 0.707107 0 0" mass="0.916533" diaginertia="0.00126587 0.00124337 0.00086921"/>
                <joint name="zarm_r1_joint" pos="0 0 0" axis="0 1 0" range="-3.14159 1.5708" actuatorfrcrange="-66 66" damping="0.0"/>
                <geom pos="0 0.081 0" quat="1 0 0 0" type="mesh" contype="0" conaffinity="0" group="1" density="0" rgba="1 1 1 1" mesh="r_arm_pitch"/>
                <body name="zarm_r2_link">
                  <inertial pos="-0.00080994 -4.86e-06 -0.0465103" quat="0.707107 0 0 0.707107" mass="0.387674" diaginertia="0.00116144 0.00080739 0.00070223"/>
                  <joint name="zarm_r2_joint" pos="0 0 0" axis="1 0 0" range="-3.49066 0.349066" actuatorfrcrange="-75 75" damping="0.0"/>
                  <geom type="mesh" contype="0" conaffinity="0" group="1" density="0" rgba="1 1 1 1" mesh="r_arm_roll"/>
                  <body name="zarm_r3_link">
                    <inertial pos="0.00943019 -0.00343988 -0.113045" quat="0.707107 0 0 0.707107" mass="1.77927" diaginertia="0.0100458 0.00992856 0.00185422"/>
                    <joint name="zarm_r3_joint" pos="0 0 0" axis="0 0 1" range="-1.48353 1.48353" actuatorfrcrange="-57 57" damping="0.0"/>
                    <geom type="mesh" contype="0" conaffinity="0" group="1" density="0" rgba="1 1 1 1" mesh="r_arm_yaw"/>
                    <body name="zarm_r4_link" pos="0.02 0 -0.2837">
                      <inertial pos="-0.0182993 -0.00087167 -0.0693662" mass="0.585078" diaginertia="0.00143291 0.00125018 0.00068356"/>
                      <joint name="zarm_r4_joint" pos="0 0 0" axis="0 1 0" range="-2.61799 0" actuatorfrcrange="-75 75" damping="0.0"/>
                      <geom type="mesh" contype="0" conaffinity="0" group="1" density="0" rgba="1 1 1 1" mesh="r_forearm"/>
                      <body name="zarm_r5_link" pos="-0.02 0 -0.1195">
                        <inertial pos="-0.0002609 1.322e-05 -0.0608394" quat="0.707107 0 0 0.707107" mass="0.6868" diaginertia="0.00122518 0.00086873 0.00066873"/>
                        <joint name="zarm_r5_joint" pos="0 0 0" axis="0 0 1" range="-1.5708 1.5708" actuatorfrcrange="-14.1 14.1" damping="0.0"/>
                        <geom type="mesh" contype="0" conaffinity="0" group="1" density="0" rgba="1 1 1 1" mesh="r_hand_yaw"/>
                        <body name="zarm_r6_link" pos="0 0 -0.114">
                          <inertial pos="0.00019162 0 -0.0174775" quat="0 0.707107 0 0.707107" mass="0.393872" diaginertia="0.0002021 0.00019853 0.00018535"/>
                          <joint name="zarm_r6_joint" pos="0 0 0" axis="1 0 0" range="-0.698132 1.309" actuatorfrcrange="-14.1 14.1" damping="0.0"/>
                          <geom type="mesh" contype="0" conaffinity="0" group="1" density="0" rgba="1 1 1 1" mesh="r_hand_roll"/>
                          <body name="zarm_r7_link" pos="0 0 -0.021">
                            <inertial pos="0 0 -0.102359" quat="0.707107 0 0 0.707107" mass="0.715902" diaginertia="0.00106704 0.00106284 0.00106143"/>
                            <joint name="zarm_r7_joint" pos="0 0 0" axis="0 1 0" range="-0.698132 0.698132" actuatorfrcrange="-14.1 14.1" damping="0.0"/>
                            <geom type="mesh" contype="0" conaffinity="0" group="1" density="0" rgba="1 1 1 1" mesh="r_hand_pitch_noHand"/>
                            <geom size="0.005" pos="0 0 -0.17"/>
                          </body>
                        </body>
                      </body>
                    </body>
                  </body>
                </body>
              </body>
              <body name="zhead_1_link" pos="0 0 0.3164">
                <inertial pos="0.00173082 -0.0033509 0.0948508" quat="1 4.68903e-05 2.29385e-05 4.13671e-05" mass="0.836974" diaginertia="0.00192825 0.00185813 0.000600654"/>
                <joint name="zhead_1_joint" pos="0 0 0" axis="0 0 1" range="-1.57 1.57" actuatorfrcrange="-15.5 15.5" damping="0.0"/>
                <geom type="mesh" contype="0" conaffinity="0" group="1" density="0" rgba="1 1 1 1" mesh="head_yaw"/>
                <geom pos="0 0 0.059701" quat="1 0 0 0" type="mesh" contype="0" conaffinity="0" group="1" density="0" rgba="0.611765 0.658824 0.670588 1" mesh="head_radar"/>
                <body name="zhead_2_link" pos="0 0 0.13795">
                  <inertial pos="0.030745 -0.00383958 0.0356665" quat="0.0350967 0.715721 -0.0948585 0.691023" mass="0.851207" diaginertia="0.00556572 0.00531893 0.00393134"/>
                  <joint name="zhead_2_joint" pos="0 0 0" axis="0 1 0" range="-0.526 0.526" actuatorfrcrange="-14.5 14.5" damping="0.0"/>
                  <geom type="mesh" contype="0" conaffinity="0" group="1" density="0" rgba="1 1 1 1" mesh="head_pitch"/>
                  <geom pos="0.099478 0 0.032897" quat="0.984018 0 0.17807 0" type="mesh" contype="0" conaffinity="0" group="1" density="0" rgba="1 1 1 1" mesh="head_camera"/>
                </body>
              </body>
            </body>
          </body>
        </body>
      </body>
    </body>
  </worldbody>
  <actuator>
    <motor gear="1" joint="LF_wheel_yaw_joint"   name="LF_wheel_yaw_joint_motor"   ctrllimited="true" ctrlrange="-40 40"  />
    <motor gear="1" joint="LF_wheel_pitch_joint" name="LF_wheel_pitch_joint_motor" ctrllimited="true" ctrlrange="-40 40"  />
    <motor gear="1" joint="RF_wheel_yaw_joint"   name="RF_wheel_yaw_joint_motor"   ctrllimited="true" ctrlrange="-40 40"  />
    <motor gear="1" joint="RF_wheel_pitch_joint" name="RF_wheel_pitch_joint_motor" ctrllimited="true" ctrlrange="-40 40"  />
    <motor gear="1" joint="LB_wheel_yaw_joint"   name="LB_wheel_yaw_joint_motor"   ctrllimited="true" ctrlrange="-40 40"  />
    <motor gear="1" joint="LB_wheel_pitch_joint" name="LB_wheel_pitch_joint_motor" ctrllimited="true" ctrlrange="-40 40"  />
    <motor gear="1" joint="RB_wheel_yaw_joint"   name="RB_wheel_yaw_joint_motor"   ctrllimited="true" ctrlrange="-40 40"  />
    <motor gear="1" joint="RB_wheel_pitch_joint" name="RB_wheel_pitch_joint_motor" ctrllimited="true" ctrlrange="-40 40"  />

    <motor gear="1" joint="knee_joint" name="knee_joint_motor" ctrllimited="true" ctrlrange="-668.53 668.53" />
    <motor gear="1" joint="leg_joint" name="leg_joint_motor" ctrllimited="true" ctrlrange="-668.53 668.53" />
    <motor gear="1" joint="waist_pitch_joint" name="waist_pitch_joint_motor" ctrllimited="true" ctrlrange="-618.48 618.48" />
    <motor gear="1" joint="waist_yaw_joint" name="waist_yaw_joint_motor" ctrllimited="true" ctrlrange="-618.48 618.48" />
    <motor gear="1" joint="zarm_l1_joint" name="zarm_l1_joint_motor" ctrllimited="true" ctrlrange="-66 66" />
    <motor gear="1" joint="zarm_l2_joint" name="zarm_l2_joint_motor" ctrllimited="true" ctrlrange="-75 75" />
    <motor gear="1" joint="zarm_l3_joint" name="zarm_l3_joint_motor" ctrllimited="true" ctrlrange="-57 57" />
    <motor gear="1" joint="zarm_l4_joint" name="zarm_l4_joint_motor" ctrllimited="true" ctrlrange="-75 75" />
    <motor gear="1" joint="zarm_l5_joint" name="zarm_l5_joint_motor" ctrllimited="true" ctrlrange="-14.1 14.1" />
    <motor gear="1" joint="zarm_l6_joint" name="zarm_l6_joint_motor" ctrllimited="true" ctrlrange="-14.1 14.1" />
    <motor gear="1" joint="zarm_l7_joint" name="zarm_l7_joint_motor" ctrllimited="true" ctrlrange="-14.1 14.1" />
    <motor gear="1" joint="zarm_r1_joint" name="zarm_r1_joint_motor" ctrllimited="true" ctrlrange="-66 66" />
    <motor gear="1" joint="zarm_r2_joint" name="zarm_r2_joint_motor" ctrllimited="true" ctrlrange="-75 75" />
    <motor gear="1" joint="zarm_r3_joint" name="zarm_r3_joint_motor" ctrllimited="true" ctrlrange="-57 57" />
    <motor gear="1" joint="zarm_r4_joint" name="zarm_r4_joint_motor" ctrllimited="true" ctrlrange="-75 75" />
    <motor gear="1" joint="zarm_r5_joint" name="zarm_r5_joint_motor" ctrllimited="true" ctrlrange="-14.1 14.1" />
    <motor gear="1" joint="zarm_r6_joint" name="zarm_r6_joint_motor" ctrllimited="true" ctrlrange="-14.1 14.1" />
    <motor gear="1" joint="zarm_r7_joint" name="zarm_r7_joint_motor" ctrllimited="true" ctrlrange="-14.1 14.1" />
    <motor gear="1" joint="zhead_1_joint" name="zhead_1_joint_motor" ctrllimited="true" ctrlrange="-14.1 14.1" />
    <motor gear="1" joint="zhead_2_joint" name="zhead_2_joint_motor" ctrllimited="true" ctrlrange="-14.1 14.1" />
  </actuator>
  <sensor>
    <accelerometer name="BodyAcc" site="imu" />
    <velocimeter name="BodyVel" site="imu" />
    <gyro name="BodyGyro" site="imu" />
    <framepos name="BodyPos" objtype="site" objname="imu" />
    <framequat name="BodyQuat" objtype="site" objname="imu" />

    <jointpos name="LF_wheel_yaw_joint_pos"   joint="LF_wheel_yaw_joint"   />
    <jointpos name="LF_wheel_pitch_joint_pos" joint="LF_wheel_pitch_joint" />
    <jointpos name="RF_wheel_yaw_joint_pos"   joint="RF_wheel_yaw_joint"   />
    <jointpos name="RF_wheel_pitch_joint_pos" joint="RF_wheel_pitch_joint" />
    <jointpos name="LB_wheel_yaw_joint_pos"   joint="LB_wheel_yaw_joint"   />
    <jointpos name="LB_wheel_pitch_joint_pos" joint="LB_wheel_pitch_joint" />
    <jointpos name="RB_wheel_yaw_joint_pos"   joint="RB_wheel_yaw_joint"   />
    <jointpos name="RB_wheel_pitch_joint_pos" joint="RB_wheel_pitch_joint" />

    <jointpos name="knee_joint_pos" joint="knee_joint" />
    <jointpos name="leg_joint_pos" joint="leg_joint" />
    <jointpos name="waist_pitch_joint_pos" joint="waist_pitch_joint" />
    <jointpos name="waist_yaw_joint_pos" joint="waist_yaw_joint" />
    <jointpos name="zarm_l1_joint_pos" joint="zarm_l1_joint" />
    <jointpos name="zarm_l2_joint_pos" joint="zarm_l2_joint" />
    <jointpos name="zarm_l3_joint_pos" joint="zarm_l3_joint" />
    <jointpos name="zarm_l4_joint_pos" joint="zarm_l4_joint" />
    <jointpos name="zarm_l5_joint_pos" joint="zarm_l5_joint" />
    <jointpos name="zarm_l6_joint_pos" joint="zarm_l6_joint" />
    <jointpos name="zarm_l7_joint_pos" joint="zarm_l7_joint" />
    <jointpos name="zarm_r1_joint_pos" joint="zarm_r1_joint" />
    <jointpos name="zarm_r2_joint_pos" joint="zarm_r2_joint" />
    <jointpos name="zarm_r3_joint_pos" joint="zarm_r3_joint" />
    <jointpos name="zarm_r4_joint_pos" joint="zarm_r4_joint" />
    <jointpos name="zarm_r5_joint_pos" joint="zarm_r5_joint" />
    <jointpos name="zarm_r6_joint_pos" joint="zarm_r6_joint" />
    <jointpos name="zarm_r7_joint_pos" joint="zarm_r7_joint" />
    <jointpos name="zhead_1_joint_pos" joint="zhead_1_joint" />
    <jointpos name="zhead_2_joint_pos" joint="zhead_2_joint" />

    <jointvel name="LF_wheel_yaw_joint_vel"   joint="LF_wheel_yaw_joint"   />
    <jointvel name="LF_wheel_pitch_joint_vel" joint="LF_wheel_pitch_joint" />
    <jointvel name="RF_wheel_yaw_joint_vel"   joint="RF_wheel_yaw_joint"   />
    <jointvel name="RF_wheel_pitch_joint_vel" joint="RF_wheel_pitch_joint" />
    <jointvel name="LB_wheel_yaw_joint_vel"   joint="LB_wheel_yaw_joint"   />
    <jointvel name="LB_wheel_pitch_joint_vel" joint="LB_wheel_pitch_joint" />
    <jointvel name="RB_wheel_yaw_joint_vel"   joint="RB_wheel_yaw_joint"   />
    <jointvel name="RB_wheel_pitch_joint_vel" joint="RB_wheel_pitch_joint" />

    <jointvel name="knee_joint_vel" joint="knee_joint" />
    <jointvel name="leg_joint_vel" joint="leg_joint" />
    <jointvel name="waist_pitch_joint_vel" joint="waist_pitch_joint" />
    <jointvel name="waist_yaw_joint_vel" joint="waist_yaw_joint" />
    <jointvel name="zarm_l1_joint_vel" joint="zarm_l1_joint" />
    <jointvel name="zarm_l2_joint_vel" joint="zarm_l2_joint" />
    <jointvel name="zarm_l3_joint_vel" joint="zarm_l3_joint" />
    <jointvel name="zarm_l4_joint_vel" joint="zarm_l4_joint" />
    <jointvel name="zarm_l5_joint_vel" joint="zarm_l5_joint" />
    <jointvel name="zarm_l6_joint_vel" joint="zarm_l6_joint" />
    <jointvel name="zarm_l7_joint_vel" joint="zarm_l7_joint" />
    <jointvel name="zarm_r1_joint_vel" joint="zarm_r1_joint" />
    <jointvel name="zarm_r2_joint_vel" joint="zarm_r2_joint" />
    <jointvel name="zarm_r3_joint_vel" joint="zarm_r3_joint" />
    <jointvel name="zarm_r4_joint_vel" joint="zarm_r4_joint" />
    <jointvel name="zarm_r5_joint_vel" joint="zarm_r5_joint" />
    <jointvel name="zarm_r6_joint_vel" joint="zarm_r6_joint" />
    <jointvel name="zarm_r7_joint_vel" joint="zarm_r7_joint" />
    <jointvel name="zhead_1_joint_vel" joint="zhead_1_joint" />
    <jointvel name="zhead_2_joint_vel" joint="zhead_2_joint" />
  </sensor>
</mujoco>
