<?xml version='1.0' encoding='utf-8'?>
<robot name="biped_s60">
  <mujoco>
    <compiler meshdir="../meshes/"
              balanceinertia="true"
              discardvisual="false" />
  </mujoco>
  <link name="base_link">
    <inertial>
      <origin xyz="0.000389910994978911 0.00140427472303049 0.059155398355868"
              rpy="0 0 0" />
      <mass value="97.77291318" />
      <inertia ixx="0.0019898467172166"
               ixy="-9.8e-05"
               ixz="5e-05"
               iyy="0.00328176736755805"
               iyz="0.000182260661996114"
               izz="0.00200808104859443" />
    </inertial>
    <visual>
      <origin xyz="0.2265 0 0.1853"
              rpy="0 0 0" />
      <geometry>
        <mesh filename="../../meshes/chassis.STL" />
      </geometry>
      <material name="">
        <color rgba="1 1 1 1" />
      </material>
    </visual>
  </link>
  <link name="knee_link">
    <inertial>
      <origin xyz="-0.23814509 0.06477318 0.05709786"
              rpy="0 0 0" />
      <mass value="5.39660196" />
      <inertia ixx="0.0181941"
               ixy="-3.368e-05"
               ixz="0.03867457"
               iyy="0.18698546"
               iyz="9.1e-05"
               izz="0.1696571" />
    </inertial>
    <visual>
      <origin xyz="0 0 0"
              rpy="0 0 0" />
      <geometry>
        <mesh filename="../../meshes/knee_pitch.STL" />
      </geometry>
      <material name="">
        <color rgba="1 1 1 1" />
      </material>
    </visual>
  </link>
  <joint name="knee_joint"
         type="revolute">
    <origin xyz="0.2265 0.017 0.2658"
            rpy="0 0.0 0" />
    <parent link="base_link" />
    <child link="knee_link" />
    <axis xyz="0 1 0" />
    <limit lower="0"
           upper="1.448"
           effort="668.53"
           velocity="25.33" />
    <dynamics damping="0.2"
              friction="0.0" />
  </joint>
  <link name="leg_link">
    <inertial>
      <origin xyz="0.23828732 -0.00731845 0.03851197"
              rpy="0 0 0" />
      <mass value="12.35650958" />
      <inertia ixx="0.04100244"
               ixy="-0.0044715"
               ixz="-0.09155463"
               iyy="0.62558367"
               iyz="-0.00089808"
               izz="0.60922308" />
    </inertial>
    <visual>
      <origin xyz="0 0 0"
              rpy="0 0 0" />
      <geometry>
        <mesh filename="../../meshes/leg_pitch.STL" />
      </geometry>
      <material name="">
        <color rgba="1 1 1 1" />
      </material>
    </visual>
  </link>
  <joint name="leg_joint"
         type="revolute">
    <origin xyz="-0.48618 0 0.11672"
            rpy="0 -0.251 0" />
    <parent link="knee_link" />
    <child link="leg_link" />
    <axis xyz="0 1 0" />
    <limit lower="-2.81"
           upper="0.0"
           effort="668.53"
           velocity="25.33" />
  </joint>
  <link name="waist_link">
    <inertial>
      <origin xyz="-0.00042629 -0.01633525 0.12667958"
              rpy="0 0 0" />
      <mass value="5.4305643" />
      <inertia ixx="0.03360578"
               ixy="-0.00023065"
               ixz="-0.00020076"
               iyy="0.02736911"
               iyz="0.00037584"
               izz="0.02207442" />
    </inertial>
    <visual>
      <origin xyz="0 0 0"
              rpy="0 0 0" />
      <geometry>
        <mesh filename="../../meshes/waist_pitch.STL" />
      </geometry>
      <material name="">
        <color rgba="1 1 1 1" />
      </material>
    </visual>
  </link>
  <joint name="waist_pitch_joint"
         type="revolute">
    <origin xyz="0.49384 0 0.078217"
            rpy="0 0.236 0" />
    <parent link="leg_link" />
    <child link="waist_link" />
    <axis xyz=" 0 1 0" />
    <limit lower="0.0"
           upper="0.9"
           effort="618.48"
           velocity="25.33" />
    <dynamics damping="0.2"
              friction="0.0" />
  </joint>
  <link name="waist_yaw_link">
    <inertial>
      <origin xyz="0.00159298 -0.00027078 0.13187420"
              rpy="0 0 0" />
      <mass value="11.56094002" />
      <inertia ixx="0.24663556"
               ixy="0.0"
               ixz="0.0"
               iyy="0.15937676"
               iyz="0.0"
               izz="0.15881326" />
    </inertial>
    <visual>
      <origin xyz="0 0 0"
              rpy="0 0 0" />
      <geometry>
        <mesh filename="../../meshes/torso.STL" />
      </geometry>
      <material name="">
        <color rgba="1 1 1 1" />
      </material>
    </visual>
    <collision>
      <origin xyz="0 0 0"
              rpy="0 0 0" />
      <geometry>
        <cylinder radius="0.15"
                  length="0.6" />
      </geometry>
    </collision>
  </link>
  <joint name="waist_yaw_joint"
         type="revolute">
    <origin xyz="0.0 -0.0165 0.209"
            rpy="0 0 0" />
    <parent link="waist_link" />
    <child link="waist_yaw_link" />
    <axis xyz="0 0 1" />
    <limit lower="-3.238"
           upper="3.238"
           effort="618.48"
           velocity="25.33" />
    <dynamics damping="0.2"
              friction="0.0" />
  </joint>
  <link name="zarm_l1_link">
    <inertial>
      <origin xyz="0.00166796 -0.008241 0.00012987"
              rpy="0 0 0" />
      <mass value="0.91653322" />
      <inertia ixx="0.00126587"
               ixy="0.0"
               ixz="0.0"
               iyy="0.00086921"
               iyz="0.0"
               izz="0.00124337" />
    </inertial>
    <visual>
      <origin xyz="0 -0.081 0"
              rpy="0 0 0" />
      <geometry>
        <mesh filename="../../meshes/l_arm_pitch.STL" />
      </geometry>
      <material name="">
        <color rgba="1 1 1 1" />
      </material>
    </visual>
  </link>
  <joint name="zarm_l1_joint"
         type="revolute">
    <origin xyz="0 0.1717 0.242"
            rpy="0 0 0" />
    <parent link="waist_yaw_link" />
    <child link="zarm_l1_link" />
    <axis xyz="0 1 0" />
    <limit lower="-2.4"
           upper="0.6"
           effort="66.0"
           velocity="18.8" />
  </joint>
  <link name="zarm_l2_link">
    <inertial>
      <origin xyz="-0.00080994 0.00000486 -0.04651026"
              rpy="0 0 0" />
      <mass value="0.38767390" />
      <inertia ixx="0.00080739"
               ixy="0.0"
               ixz="0.0"
               iyy="0.00116144"
               iyz="0.0"
               izz="0.00070223" />
    </inertial>
    <visual>
      <origin xyz="0 0 0"
              rpy="0 0 0" />
      <geometry>
        <mesh filename="../../meshes/l_arm_roll.STL" />
      </geometry>
      <material name="">
        <color rgba="1 1 1 1" />
      </material>
    </visual>
  </link>
  <joint name="zarm_l2_joint"
         type="revolute">
    <origin xyz="0 0.081 0"
            rpy="0 0 0" />
    <parent link="zarm_l1_link" />
    <child link="zarm_l2_link" />
    <axis xyz="1 0 0" />
    <limit lower="-0.349065850398866"
           upper="1.46"
           effort="75.0"
           velocity="8.0" />
  </joint>
  <link name="zarm_l3_link">
    <inertial>
      <origin xyz="0.00943019 0.00343988 -0.11304538"
              rpy="0 0 0" />
      <mass value="1.77926875" />
      <inertia ixx="0.00992856"
               ixy="0.0"
               ixz="0.0"
               iyy="0.01004582"
               iyz="0.0"
               izz="0.00185422" />
    </inertial>
    <visual>
      <origin xyz="0 0 0"
              rpy="0 0 0" />
      <geometry>
        <mesh filename="../../meshes/l_arm_yaw.STL" />
      </geometry>
      <material name="">
        <color rgba="1 1 1 1" />
      </material>
    </visual>
  </link>
  <joint name="zarm_l3_joint"
         type="revolute">
    <origin xyz="0 0 0"
            rpy="0 0 0" />
    <parent link="zarm_l2_link" />
    <child link="zarm_l3_link" />
    <axis xyz="0 0 1" />
    <limit lower="-1.5707963267949"
           upper="0.46"
           effort="57.0"
           velocity="7.5" />
  </joint>
  <link name="zarm_l4_link">
    <inertial>
      <origin xyz="-0.01829932 0.00087167 -0.06936622"
              rpy="0 0 0" />
      <mass value="0.58507821" />
      <inertia ixx="0.00143291"
               ixy="0.0"
               ixz="0.0"
               iyy="0.00125018"
               iyz="0.0"
               izz="0.00068356" />
    </inertial>
    <visual>
      <origin xyz="0 0 0"
              rpy="0 0 0" />
      <geometry>
        <mesh filename="../../meshes/l_forearm.STL" />
      </geometry>
      <material name="">
        <color rgba="1 1 1 1" />
      </material>
    </visual>
  </link>
  <joint name="zarm_l4_joint"
         type="revolute">
    <origin xyz="0.02 0 -0.2837"
            rpy="0 0 0" />
    <parent link="zarm_l3_link" />
    <child link="zarm_l4_link" />
    <axis xyz="0 1 0" />
    <limit lower="-2.61799387799149"
           upper="0.0"
           effort="75.0"
           velocity="8.0" />
  </joint>
  <link name="zarm_l5_link">
    <inertial>
      <origin xyz="0.00026090 0.00001322 -0.06083944"
              rpy="0 0 0" />
      <mass value="0.68679955" />
      <inertia ixx="0.00086873"
               ixy="0.0"
               ixz="0.0"
               iyy="0.00122518"
               iyz="0.0"
               izz="0.00066873" />
    </inertial>
    <visual>
      <origin xyz="0 0 0"
              rpy="0 0 0" />
      <geometry>
        <mesh filename="../../meshes/l_hand_yaw.STL" />
      </geometry>
      <material name="">
        <color rgba="1 1 1 1" />
      </material>
    </visual>
  </link>
  <joint name="zarm_l5_joint"
         type="revolute">
    <origin xyz="-0.02 0 -0.1195"
            rpy="0 0 0" />
    <parent link="zarm_l4_link" />
    <child link="zarm_l5_link" />
    <axis xyz="0 0 1" />
    <limit lower="-1.5707963267949"
           upper="1.5707963267949"
           effort="14.1"
           velocity="17.5" />
  </joint>
  <link name="zarm_l6_link">
    <inertial>
      <origin xyz="0.00019162 0.0 -0.01747746"
              rpy="0 0 0" />
      <mass value="0.39387181" />
      <inertia ixx="0.00018535"
               ixy="0.0"
               ixz="0.0"
               iyy="0.00019853"
               iyz="0.0"
               izz="0.00020210" />
    </inertial>
    <visual>
      <origin xyz="0 0 0"
              rpy="0 0 0" />
      <geometry>
        <mesh filename="../../meshes/l_hand_roll.STL" />
      </geometry>
      <material name="">
        <color rgba="1 1 1 1" />
      </material>
    </visual>
  </link>
  <joint name="zarm_l6_joint"
         type="revolute">
    <origin xyz="0.0 0 -0.114"
            rpy="0 0 0" />
    <parent link="zarm_l5_link" />
    <child link="zarm_l6_link" />
    <axis xyz="1 0 0" />
    <limit lower="-1.30899693899575"
           upper="0.698131700797732"
           effort="14.1"
           velocity="17.5" />
  </joint>
  <link name="zarm_l7_link">
    <inertial>
      <origin xyz="0.0 0.0 -0.10230994"
              rpy="0 0 0" />
      <mass value="0.71537800" />
      <inertia ixx="0.001060440"
               ixy="0.0"
               ixz="0.0"
               iyy="0.001064636"
               iyz="0.0"
               izz="0.001061427" />
    </inertial>
    <visual>
      <origin xyz="0 0 0"
              rpy="0 0 0" />
      <geometry>
        <mesh filename="../../meshes/l_hand_pitch_noHand.STL" />
      </geometry>
      <material name="">
        <color rgba="1 1 1 1" />
      </material>
    </visual>
  </link>
  <joint name="zarm_l7_joint"
         type="revolute">
    <origin xyz="0 0 -0.021"
            rpy="0 0 0" />
    <parent link="zarm_l6_link" />
    <child link="zarm_l7_link" />
    <axis xyz="0 1 0" />
    <limit lower="-0.698131700797732"
           upper="0.698131700797732"
           effort="14.1"
           velocity="17.5" />
  </joint>
  <link name="zarm_l7_end_effector">
    <collision>
      <origin rpy="0 0 0"
              xyz="0 0 0" />
      <geometry>
        <sphere radius="0.005" />
      </geometry>
    </collision>
  </link>
  <joint name="zarm_l7_end_effector_joint"
         type="fixed">
    <origin xyz="0 0.0 -0.17"
            rpy="0 0 0" />
    <parent link="zarm_l7_link" />
    <child link="zarm_l7_end_effector" />
  </joint>
  <link name="zarm_l7_virtual_thumb_link">
    <collision>
      <origin rpy="0 0 0"
              xyz="0 0 0" />
      <geometry>
        <sphere radius="0.005" />
      </geometry>
    </collision>
  </link>
  <joint name="zarm_l7_virtual_thumb_joint_ee"
         type="fixed">
    <origin xyz="0.15 0 0"
            rpy="0 0 0" />
    <parent link="zarm_l7_end_effector" />
    <child link="zarm_l7_virtual_thumb_link" />
  </joint>
  <link name="zarm_r1_link">
    <inertial>
      <origin xyz="-0.00166796 0.00839971 0.00012987"
              rpy="0 0 0" />
      <mass value="0.91653322" />
      <inertia ixx="0.00126587"
               ixy="0.0"
               ixz="0.0"
               iyy="0.00086921"
               iyz="0.0"
               izz="0.00124337" />
    </inertial>
    <visual>
      <origin xyz="0 0.081 0"
              rpy="0 0 0" />
      <geometry>
        <mesh filename="../../meshes/r_arm_pitch.STL" />
      </geometry>
      <material name="">
        <color rgba="1 1 1 1" />
      </material>
    </visual>
  </link>
  <joint name="zarm_r1_joint"
         type="revolute">
    <origin xyz="0 -0.1717 0.242"
            rpy="0 0 0" />
    <parent link="waist_yaw_link" />
    <child link="zarm_r1_link" />
    <axis xyz="0 1 0" />
    <limit lower="-2.4"
           upper="0.6"
           effort="66.0"
           velocity="18.8" />
  </joint>
  <link name="zarm_r2_link">
    <inertial>
      <origin xyz="-0.00080994 -0.00000486 -0.04651026"
              rpy="0 0 0" />
      <mass value="0.38767390" />
      <inertia ixx="0.00080739"
               ixy="0.0"
               ixz="0.0"
               iyy="0.00116144"
               iyz="0.0"
               izz="0.00070223" />
    </inertial>
    <visual>
      <origin xyz="0 0 0"
              rpy="0 0 0" />
      <geometry>
        <mesh filename="../../meshes/r_arm_roll.STL" />
      </geometry>
      <material name="">
        <color rgba="1 1 1 1" />
      </material>
    </visual>
    <collision>
      <origin xyz="0 0 -0.15"
              rpy="0 0 0" />
      <geometry>
        <cylinder radius="0.05"
                  length="0.3" />
      </geometry>
    </collision>
  </link>
  <joint name="zarm_r2_joint"
         type="revolute">
    <origin xyz="0 -0.081 0"
            rpy="0 0 0" />
    <parent link="zarm_r1_link" />
    <child link="zarm_r2_link" />
    <axis xyz="1 0 0" />
    <limit lower="-1.46"
           upper="0.349065850398866"
           effort="75.0"
           velocity="8.0" />
  </joint>
  <link name="zarm_r3_link">
    <inertial>
      <origin xyz="0.00943019 -0.00343988 -0.11304538"
              rpy="0 0 0" />
      <mass value="1.77926875" />
      <inertia ixx="0.00992856"
               ixy="0.0"
               ixz="0.0"
               iyy="0.01004582"
               iyz="0.0"
               izz="0.00185422" />
    </inertial>
    <visual>
      <origin xyz="0 0 0"
              rpy="0 0 0" />
      <geometry>
        <mesh filename="../../meshes/r_arm_yaw.STL" />
      </geometry>
      <material name="">
        <color rgba="1 1 1 1" />
      </material>
    </visual>
  </link>
  <joint name="zarm_r3_joint"
         type="revolute">
    <origin xyz="0 0 0"
            rpy="0 0 0" />
    <parent link="zarm_r2_link" />
    <child link="zarm_r3_link" />
    <axis xyz="0 0 1" />
    <limit lower="-0.46"
           upper="1.5707963267949"
           effort="57.0"
           velocity="7.5" />
  </joint>
  <link name="zarm_r4_link">
    <inertial>
      <origin xyz="-0.01829932 -0.00087167 -0.06936622"
              rpy="0 0 0" />
      <mass value="0.58507821" />
      <inertia ixx="0.00143291"
               ixy="0.0"
               ixz="0.0"
               iyy="0.00125018"
               iyz="0.0"
               izz="0.00068356" />
    </inertial>
    <visual>
      <origin xyz="0 0 0"
              rpy="0 0 0" />
      <geometry>
        <mesh filename="../../meshes/r_forearm.STL" />
      </geometry>
      <material name="">
        <color rgba="1 1 1 1" />
      </material>
    </visual>
    <collision>
      <origin xyz="-0.02 0 -0.13"
              rpy="0 0 0" />
      <geometry>
        <cylinder radius="0.05"
                  length="0.26" />
      </geometry>
    </collision>
  </link>
  <joint name="zarm_r4_joint"
         type="revolute">
    <origin xyz="0.02 0 -0.2837"
            rpy="0 0 0" />
    <parent link="zarm_r3_link" />
    <child link="zarm_r4_link" />
    <axis xyz="0 1 0" />
    <limit lower="-2.61799387799149"
           upper="0.0"
           effort="75.0"
           velocity="8.0" />
  </joint>
  <link name="zarm_r5_link">
    <inertial>
      <origin xyz="-0.00026090 -0.00001322 -0.06083944"
              rpy="0 0 0" />
      <mass value="0.68679955" />
      <inertia ixx="0.00086873"
               ixy="0.0"
               ixz="0.0"
               iyy="0.00122518"
               iyz="0.0"
               izz="0.00066873" />
    </inertial>
    <visual>
      <origin xyz="0 0 0"
              rpy="0 0 0" />
      <geometry>
        <mesh filename="../../meshes/r_hand_yaw.STL" />
      </geometry>
      <material name="">
        <color rgba="1 1 1 1" />
      </material>
    </visual>
  </link>
  <joint name="zarm_r5_joint"
         type="revolute">
    <origin xyz="-0.02 0 -0.1195"
            rpy="0 0 0" />
    <parent link="zarm_r4_link" />
    <child link="zarm_r5_link" />
    <axis xyz="0 0 1" />
    <limit lower="-1.5707963267949"
           upper="1.5707963267949"
           effort="14.1"
           velocity="17.5" />
  </joint>
  <link name="zarm_r6_link">
    <inertial>
      <origin xyz="0.00019162 0.0 -0.01747746"
              rpy="0 0 0" />
      <mass value="0.39387181" />
      <inertia ixx="0.00018535"
               ixy="0.0"
               ixz="0.0"
               iyy="0.00019853"
               iyz="0.0"
               izz="0.00020210" />
    </inertial>
    <visual>
      <origin xyz="0 0 0"
              rpy="0 0 0" />
      <geometry>
        <mesh filename="../../meshes/r_hand_roll.STL" />
      </geometry>
      <material name="">
        <color rgba="1 1 1 1" />
      </material>
    </visual>
  </link>
  <joint name="zarm_r6_joint"
         type="revolute">
    <origin xyz="0.0 0 -0.114"
            rpy="0 0 0" />
    <parent link="zarm_r5_link" />
    <child link="zarm_r6_link" />
    <axis xyz="1 0 0" />
    <limit lower="-0.698131700797732"
           upper="1.30899693899575"
           effort="14.1"
           velocity="17.5" />
  </joint>
  <link name="zarm_r7_link">
    <inertial>
      <origin xyz="0.0 0.0 -0.10230994"
              rpy="0 0 0" />
      <mass value="0.71537800" />
      <inertia ixx="0.001060440"
               ixy="0.0"
               ixz="0.0"
               iyy="0.001064636"
               iyz="0.0"
               izz="0.001061427" />
    </inertial>
    <visual>
      <origin xyz="0 0 0"
              rpy="0 0 0" />
      <geometry>
        <mesh filename="../../meshes/r_hand_pitch_noHand.STL" />
      </geometry>
      <material name="">
        <color rgba="1 1 1 1" />
      </material>
    </visual>
  </link>
  <joint name="zarm_r7_joint"
         type="revolute">
    <origin xyz="0.0 0 -0.021"
            rpy="0 0 0" />
    <parent link="zarm_r6_link" />
    <child link="zarm_r7_link" />
    <axis xyz="0 1 0" />
    <limit lower="-0.698131700797732"
           upper="0.698131700797732"
           effort="14.1"
           velocity="17.5" />
  </joint>
  <link name="zarm_r7_end_effector">
    <collision>
      <origin rpy="0 0 0"
              xyz="0 0 0" />
      <geometry>
        <sphere radius="0.005" />
      </geometry>
    </collision>
  </link>
  <joint name="zarm_r7_end_effector_joint"
         type="fixed">
    <origin xyz="0 0.0 -0.17"
            rpy="0 0 0" />
    <parent link="zarm_r7_link" />
    <child link="zarm_r7_end_effector" />
  </joint>
  <link name="zarm_r7_virtual_thumb_link">
    <collision>
      <origin rpy="0 0 0"
              xyz="0 0 0" />
      <geometry>
        <sphere radius="0.005" />
      </geometry>
    </collision>
  </link>
  <joint name="zarm_r7_virtual_thumb_joint_ee"
         type="fixed">
    <origin xyz="0.15 0 0"
            rpy="0 0 0" />
    <parent link="zarm_r7_end_effector" />
    <child link="zarm_r7_virtual_thumb_link" />
  </joint>
</robot>