<?xml version="1.0" ?>
<!-- =================================================================================== -->
<!-- |    This document was autogenerated by xacro from /home/fandes/workspace/kuavo-ros-control/src/humanoid-control/humanoid_interface_drake/models/biped_gen4.2/urdf/biped_v3_all_joint.xacro | -->
<!-- |    EDITING THIS FILE BY HAND IS NOT RECOMMENDED                                 | -->
<!-- =================================================================================== -->
<robot name="biped_v3_all_joint" xmlns:drake="https://drake.mit.edu">
  <link name="torso">
    <inertial>
      <origin xyz="-0.01005136 -0.00110498 0.14058574" rpy="0 0 0"/>
      <mass value="8.98734703"/>
      <inertia ixx="0.10436018" ixy="0.00037418" ixz="0.00220231"
               iyy="0.08324244" iyz="-0.00108080"
               izz="0.04927332"/>
    </inertial>
    <visual>
      <origin xyz="0 0 0" rpy="0 0 0" />
      <geometry>
        <mesh filename="../../meshes/torso.STL" />
      </geometry>
      <material name="">
        <color rgba="1 1 1 1" />
      </material>
    </visual>
  </link>
  <link name="waist">
    <inertial>
      <origin xyz="0.00202324 -0.00003822 -0.12282710" rpy="0 0 0"/>
      <mass value="5.27737344"/>
      <inertia ixx="0.02656560" ixy="0.00001678" ixz="-0.00000028"
               iyy="0.01821248" iyz="-0.00000269"
               izz="0.02080739"/>
    </inertial>
    <visual>
      <origin xyz="0 0 0" rpy="0 0 0" />
      <geometry>
        <mesh filename="../../meshes/waist.STL" />
      </geometry>
      <material name="">
        <color rgba="1 1 1 1" />
      </material>
    </visual>
  </link>
  <joint name="waist" type="fixed">
    <origin xyz="0 0 0" rpy="0 0 0" />
    <parent link="torso" />
    <child link="waist" />
    <axis xyz="0 0 1" />
    <limit lower="-2.61799387799149" upper="2.61799387799149" effort="50" velocity="8.37333333333333" />
  </joint>
  <link name="leg_l1_link">
    <inertial>
      <origin xyz="-0.00003227 -0.03334417 0.03367064" rpy="0 0 0" />
      <mass value="0.6865" />
      <inertia
        ixx="0.00126377"
        ixy="0.00001414"
        ixz="-0.00001412"
        iyy="0.00218060"
        iyz="0.00004419"
        izz="0.00217034" />
    </inertial>
    <visual>
      <origin xyz="0 0 0" rpy="0 0 0" />
      <geometry>
        <mesh filename="../../meshes/l_leg_pitch.STL" />
      </geometry>
      <material name="">
        <color rgba="1 1 1 1" />
      </material>
    </visual>
  </link>
  <joint name="leg_l1_joint" type="revolute">
    <origin xyz="0 0.12441 -0.22265" rpy="0 0 0"/>
    <parent link="waist" />
    <child link="leg_l1_link" />
    <axis xyz="0 0.70711 -0.70711" />
    <limit lower="-3.228" upper="2.44346" effort="150" velocity="14.6" />
    <dynamics damping="0.2" friction="0.1" />
  </joint>
  <transmission type="SimpleTransmission">
    <joint name="leg_l1_joint" />
    <actuator name="leg_l1_joint_motor" />
  </transmission>
  <link name="leg_l2_link">
    <inertial>
      <origin xyz="0.00997750 0.00006468 -0.00976037" rpy="0 0 0" />
      <mass value="2.054" />
      <inertia
        ixx="0.00431431"
        ixy="0.00000608"
        ixz="-0.00014901"
        iyy="0.00400702"
        iyz="-0.00000584"
        izz="0.00326276" />
    </inertial>
    <visual>
      <origin xyz="0 0 0" rpy="0 0 0" />
      <geometry>
        <mesh filename="../../meshes/l_leg_roll.STL" />
      </geometry>
      <material name="">
        <color rgba="1 1 1 1" />
      </material>
    </visual>
  </link>
  <joint name="leg_l2_joint" type="revolute">
    <origin xyz="0 0 0" rpy="0 0 0" />
    <parent link="leg_l1_link" />
    <child link="leg_l2_link" />
    <axis xyz="1 0 0" />
    <limit lower="-0.837758" upper="2.40855" effort="150" velocity="14.6" />
    <dynamics damping="0.2" friction="0.1" />
  </joint>
  <transmission type="SimpleTransmission">
    <joint name="leg_l2_joint" />
    <actuator name="leg_l2_joint_motor" />
  </transmission>
  <link name="leg_l3_link">
    <inertial>
      <origin xyz="-0.01402491 -0.00139317 -0.15993926" rpy="0 0 0" />
      <mass value="3.2746" />
      <inertia
        ixx="0.01347200"
        ixy="-0.00009787"
        ixz="-0.00236299"
        iyy="0.01460281"
        iyz="-0.00025458"
        izz="0.00559251" />
    </inertial>
    <visual>
      <origin xyz="0 0 0" rpy="0 0 0" />
      <geometry>
        <mesh filename="../../meshes/l_leg_yaw.STL" />
      </geometry>
      <material name="">
        <color rgba="1 1 1 1" />
      </material>
    </visual>
  </link>
  <joint name="leg_l3_joint" type="revolute">
    <origin xyz="0 0 0" rpy="0 0 0" />
    <parent link="leg_l2_link" />
    <child link="leg_l3_link" />
    <axis xyz="0 0 1" />
    <limit lower="-1.7453" upper="1.7453" effort="70" velocity="12.0" />
    <dynamics damping="0.2" friction="0.1" />
  </joint>
  <transmission type="SimpleTransmission">
    <joint name="leg_l3_joint" />
    <actuator name="leg_l3_joint_motor" />
  </transmission>
  <link name="leg_l4_link">
    <inertial>
      <origin xyz="0.02266979 0.00479531 -0.11412872" rpy="0 0 0" />
      <mass value="2.4454" />
      <inertia
        ixx="0.01333243"
        ixy="0.00025106"
        ixz="0.00029427"
        iyy="0.01330983"
        iyz="-0.00133540"
        izz="0.00318742" />
    </inertial>
    <visual>
      <origin xyz="0 0 0" rpy="0 0 0" />
      <geometry>
        <mesh filename="../../meshes/l_knee.STL" />
      </geometry>
      <material name="">
        <color rgba="1 1 1 1" />
      </material>
    </visual>
  </link>
  <joint name="leg_l4_joint" type="revolute">
    <origin xyz="-0.03 0 -0.213" rpy="0 0 0" />
    <parent link="leg_l3_link" />
    <child link="leg_l4_link" />
    <axis xyz="0 1 0" />
    <limit lower="-0.08726646" upper="2.530727" effort="150" velocity="14.6" />
    <dynamics damping="0.2" friction="0.1" />
  </joint>
  <transmission type="SimpleTransmission">
    <joint name="leg_l4_joint" />
    <actuator name="leg_l4_joint_motor" />
  </transmission>
  <link name="leg_l5_link">
    <inertial>
      <origin xyz="-0.00344503 -0.00000752 -0.00936005" rpy="0 0 0" />
      <mass value="0.1314" />
      <inertia
        ixx="0.00002019"
        ixy="0.00000000"
        ixz="-0.00000328"
        iyy="0.00002431"
        iyz="0.00000000"
        izz="0.00001384" />
    </inertial>
    <visual>
      <origin xyz="0 0 0" rpy="0 0 0" />
      <geometry>
        <mesh filename="../../meshes/l_foot_pitch.STL" />
      </geometry>
      <material name="">
        <color rgba="1 1 1 1" />
      </material>
    </visual>
  </link>
  <joint name="leg_l5_joint" type="revolute">
    <origin xyz="0.03 0 -0.276" rpy="0 0 0" />
    <parent link="leg_l4_link" />
    <child link="leg_l5_link" />
    <axis xyz="0 1 0" />
    <limit lower="-0.872664625997165" upper="0.523598775598299" effort="74" velocity="17.0" />
    <dynamics damping="0.2" friction="0.1" />
  </joint>
  <transmission type="SimpleTransmission">
    <joint name="leg_l5_joint" />
    <actuator name="leg_l5_joint_motor" />
  </transmission>
  <link name="leg_l6_link">
    <inertial>
      <origin xyz="0.02860311 0.00007463 -0.01983204" rpy="0 0 0" />
      <mass value="0.5783271" />
      <inertia
        ixx="0.00028622"
        ixy="-0.00000001"
        ixz="0.00013017"
        iyy="0.00147216"
        iyz="-0.00000093"
        izz="0.00158313" />
    </inertial>
    <visual>
      <origin xyz="0 0 0" rpy="0 0 0" />
      <geometry>
        <mesh filename="../../meshes/l_foot_roll.STL" />
      </geometry>
      <material name="">
        <color rgba="1 1 1 1" />
      </material>
    </visual>
  </link>
  <joint name="leg_l6_joint" type="revolute">
    <origin xyz="0 0 -0.018" rpy="0 0 0" />
    <parent link="leg_l5_link" />
    <child link="leg_l6_link" />
    <axis xyz="1 0 0" />
    <limit lower="-0.261799387799149" upper="0.261799387799149" effort="74" velocity="17.0" />
    <dynamics damping="0.2" friction="0.1" />
  </joint>
  <transmission type="SimpleTransmission">
    <joint name="leg_l6_joint" />
    <actuator name="leg_l6_joint_motor" />
  </transmission>
  <!-- sssssssss -->
  <link name="l_l_bar_y">
    <inertial>
      <origin rpy="0 0 0" xyz="-0.017639 -0.0012332 0.0047224"/>
      <mass value="0.041379"/>
      <inertia ixx="6.3487E-06" ixy="-2.7168E-06" ixz="4.9324E-06" iyy="2.8379E-05" iyz="7.2737E-07" izz="2.3451E-05"/>
    </inertial>
    <visual>
      <origin rpy="0 0 0" xyz="0 0 0"/>
      <geometry>
        <mesh filename="../../meshes/l_l_bar.STL"/>
      </geometry>
      <material name="">
        <color rgba="0.6902 0.65882 0.63922 1"/>
      </material>
    </visual>
    <!-- <collision>
      <origin xyz="0 0 0" rpy="0 0 0" />
      <geometry>
        <mesh filename="../../meshes/l_l_bar.STL" />
      </geometry>
    </collision> -->
  </link>
  <joint name="l_l_bar_y" type="continuous">
    <origin rpy="0 0 0" xyz="0 0.0318 -0.09"/>
    <parent link="leg_l4_link"/>
    <child link="l_l_bar_y"/>
    <axis xyz="0 1 0"/>
    <!-- <limit lower="-1.58" upper="0.50" effort="74" velocity="47" /> -->
  </joint>
  <transmission type="SimpleTransmission">
    <joint name="l_l_bar_y"/>
    <actuator name="l_l_bar_y_motor">
      <drake:gear_ratio value="10.0"/>
      <drake:rotor_inertia value="0.0001002"/>
    </actuator>
  </transmission>
  <link name="l_l_tendon_y">
    <inertial>
      <origin rpy="0 0 0" xyz="-1.3642E-05 -0.00048331 -0.13953"/>
      <mass value="0.13223"/>
      <inertia ixx="0.00049161" ixy="3.0645E-12" ixz="1.52E-08" iyy="0.00048973" iyz="-2.4263E-07" izz="4.775E-06"/>
    </inertial>
    <visual>
      <origin rpy="0 0 0" xyz="0 0 0"/>
      <geometry>
        <mesh filename="../../meshes/l_l_tendon.STL"/>
      </geometry>
      <material name="">
        <color rgba="0.6902 0.65882 0.63922 1"/>
      </material>
    </visual>
    <!-- <collision>
      <origin xyz="0 0 0" rpy="0 0 0" />
      <geometry>
        <mesh filename="../../meshes/l_l_tendon.STL" />
      </geometry>
    </collision> -->
  </link>
  <drake:joint name="l_l_tendon_y" type="universal">
    <origin rpy="0 0 0" xyz="-0.056027 -0.0085 0.015"/>
    <parent link="l_l_bar_y"/>
    <child link="l_l_tendon_y"/>
  </drake:joint>
  <frame link="l_l_tendon_y" name="l_l_tendon_socket" xyz="0 0 -0.256"/>
  <link name="l_r_bar_y">
    <inertial>
      <origin rpy="0 0 0" xyz="-0.017639 0.0012332 0.0047224"/>
      <mass value="0.041379"/>
      <inertia ixx="6.3486E-06" ixy="2.7168E-06" ixz="4.9323E-06" iyy="2.8379E-05" iyz="-7.2736E-07" izz="2.3451E-05"/>
    </inertial>
    <visual>
      <origin rpy="0 0 0" xyz="0 0 0"/>
      <geometry>
        <mesh filename="../../meshes/l_r_bar.STL"/>
      </geometry>
      <material name="">
        <color rgba="0.6902 0.65882 0.63922 1"/>
      </material>
    </visual>
    <!-- <collision>
      <origin xyz="0 0 0" rpy="0 0 0" />
      <geometry>
        <mesh filename="../../meshes/l_r_bar.STL" />
      </geometry>
    </collision> -->
  </link>
  <joint name="l_r_bar_y" type="continuous">
    <origin rpy="0 0 0" xyz="0 -0.0362 -0.153"/>
    <parent link="leg_l4_link"/>
    <child link="l_r_bar_y"/>
    <axis xyz="0 1 0"/>
  </joint>
  <link name="l_r_tendon_y">
    <inertial>
      <origin rpy="0 0 0" xyz="-1.9777E-05 0.00047927 -0.10625"/>
      <mass value="0.10643"/>
      <inertia ixx="0.0001972" ixy="4.1988E-12" ixz="-1.2811E-08" iyy="0.00019587" iyz="1.7341E-07" izz="3.9152E-06"/>
    </inertial>
    <visual>
      <origin rpy="0 0 0" xyz="0 0 0"/>
      <geometry>
        <mesh filename="../../meshes/l_r_tendon.STL"/>
      </geometry>
      <material name="">
        <color rgba="0.6902 0.65882 0.63922 1"/>
      </material>
    </visual>
    <!-- <collision>
      <origin xyz="0 0 0" rpy="0 0 0" />
      <geometry>
        <mesh filename="../../meshes/l_r_tendon.STL" />
      </geometry>
    </collision> -->
  </link>
  <drake:joint name="l_r_tendon_y" type="universal">
    <origin rpy="0 0 0" xyz="-0.056027 0.0085 0.015"/>
    <parent link="l_r_bar_y"/>
    <child link="l_r_tendon_y"/>
  </drake:joint>
  <frame link="l_r_tendon_y" name="l_r_tendon_socket" xyz="0 0 -0.193"/>
  <transmission type="SimpleTransmission">
    <joint name="l_r_bar_y"/>
    <actuator name="l_r_bar_y_motor">
      <drake:gear_ratio value="10.0"/>
      <drake:rotor_inertia value="0.0001002"/>
    </actuator>
  </transmission>
  <frame link="leg_l6_link" name="l_l_foot_socket" xyz="-0.056027 0.0255 0.015"/>
  <frame link="leg_l6_link" name="l_r_foot_socket" xyz="-0.056027 -0.0255 0.015"/>
  <!-- 曲柄 -->
  <frame link="l_l_bar_y" name="l_l_foot_bar_frame" xyz="0 -0.0085 0"/>
  <frame link="l_r_bar_y" name="l_r_foot_bar_frame" xyz="0 0.0085 0"/>
  <link name="leg_r1_link">
    <inertial>
      <origin xyz="-0.00003227 0.03334417 0.03367064" rpy="0 0 0" />
      <mass value="0.6865" />
      <inertia
        ixx="0.00126377"
        ixy="-0.00001414"
        ixz="-0.00001412"
        iyy="0.00218060"
        iyz="-0.00004419"
        izz="0.00217034" />
    </inertial>
    <visual>
      <origin xyz="0 0 0" rpy="0 0 0" />
      <geometry>
        <mesh filename="../../meshes/r_leg_pitch.STL" />
      </geometry>
      <material name="">
        <color rgba="1 1 1 1" />
      </material>
    </visual>
  </link>
  <joint name="leg_r1_joint" type="revolute">
    <origin xyz="0.0 -0.12441 -0.22265" rpy="0 0 0" />
    <parent link="waist" />
    <child link="leg_r1_link" />
    <axis xyz="0 -0.70711 -0.70711" />
    <limit lower="-2.44346" upper="3.228" effort="150" velocity="14.6" />
    <dynamics damping="0.2" friction="0.1" />
  </joint>
  <transmission type="SimpleTransmission">
    <joint name="leg_r1_joint" />
    <actuator name="leg_r1_joint_motor" />
  </transmission>
  <link name="leg_r2_link">
    <inertial>
      <origin xyz="0.00997750 -0.00006468 -0.00976037" rpy="0 0 0" />
      <mass value="2.054" />
      <inertia
        ixx="0.00431431"
        ixy="-0.00000608"
        ixz="-0.00014901"
        iyy="0.00400702"
        iyz="0.00000584"
        izz="0.00326276" />
    </inertial>
    <visual>
      <origin xyz="0 0 0" rpy="0 0 0" />
      <geometry>
        <mesh filename="../../meshes/r_leg_roll.STL" />
      </geometry>
      <material name="">
        <color rgba="1 1 1 1" />
      </material>
    </visual>
  </link>
  <joint name="leg_r2_joint" type="revolute">
    <origin xyz="0 0 0" rpy="0 0 0" />
    <parent link="leg_r1_link" />
    <child link="leg_r2_link" />
    <axis xyz="1 0 0" />
    <limit lower="-2.40855" upper="0.837758" effort="150" velocity="14.6" />
    <dynamics damping="0.2" friction="0.1" />
  </joint>
  <transmission type="SimpleTransmission">
    <joint name="leg_r2_joint" />
    <actuator name="leg_r2_joint_motor" />
  </transmission>
  <link name="leg_r3_link">
    <inertial>
      <origin xyz="-0.01402491 0.00139317 -0.15993926" rpy="0 0 0" />
      <mass value="3.2746" />
      <inertia
        ixx="0.01347200"
        ixy="0.00009787"
        ixz="-0.00236299"
        iyy="0.01460281"
        iyz="0.00025458"
        izz="0.00559251" />
    </inertial>
    <visual>
      <origin xyz="0 0 0" rpy="0 0 0" />
      <geometry>
        <mesh filename="../../meshes/r_leg_yaw.STL" />
      </geometry>
      <material name="">
        <color rgba="1 1 1 1" />
      </material>
    </visual>
  </link>
  <joint name="leg_r3_joint" type="revolute">
    <origin xyz="0 0 0" rpy="0 0 0" />
    <parent link="leg_r2_link" />
    <child link="leg_r3_link" />
    <axis xyz="0 0 1" />
    <limit lower="-1.7453" upper="1.7453" effort="70" velocity="12.0" />
    <dynamics damping="0.2" friction="0.1" />
  </joint>
  <transmission type="SimpleTransmission">
    <joint name="leg_r3_joint" />
    <actuator name="leg_r3_joint_motor" />
  </transmission>
  <link name="leg_r4_link">
    <inertial>
      <origin xyz="0.02266979 -0.00479531 -0.11412872" rpy="0 0 0" />
      <mass value="2.4454" />
      <inertia
        ixx="0.01333243"
        ixy="-0.00025106"
        ixz="0.00029427"
        iyy="0.01330983"
        iyz="0.00133540"
        izz="0.00318742" />
    </inertial>
    <visual>
      <origin xyz="0 0 0" rpy="0 0 0" />
      <geometry>
        <mesh filename="../../meshes/r_knee.STL" />
      </geometry>
      <material name="">
        <color rgba="1 1 1 1" />
      </material>
    </visual>
  </link>
  <joint name="leg_r4_joint" type="revolute">
    <origin xyz="-0.03 0 -0.213" rpy="0 0 0" />
    <parent link="leg_r3_link" />
    <child link="leg_r4_link" />
    <axis xyz="0 1 0" />
    <limit lower="-0.08726646" upper="2.530727" effort="150" velocity="14.6" />
    <dynamics damping="0.2" friction="0.1" />
  </joint>
  <transmission type="SimpleTransmission">
    <joint name="leg_r4_joint" />
    <actuator name="leg_r4_joint_motor" />
  </transmission>
  <link name="leg_r5_link">
    <inertial>
      <origin xyz="-0.00344503 0.00000752 -0.00936005" rpy="0 0 0" />
      <mass value="0.1314" />
      <inertia
        ixx="0.00002019"
        ixy="0.00000000"
        ixz="-0.00000328"
        iyy="0.00002431"
        iyz="0.00000000"
        izz="0.00001384" />
    </inertial>
    <visual>
      <origin xyz="0 0 0" rpy="0 0 0" />
      <geometry>
        <mesh filename="../../meshes/r_foot_pitch.STL" />
      </geometry>
      <material name="">
        <color rgba="1 1 1 1" />
      </material>
    </visual>
  </link>
  <joint name="leg_r5_joint" type="revolute">
    <origin xyz="0.03 0 -0.276" rpy="0 0 0" />
    <parent link="leg_r4_link" />
    <child link="leg_r5_link" />
    <axis xyz="0 1 0" />
    <limit lower="-0.872664625997165" upper="0.523598775598299" effort="74" velocity="17.0" />
    <dynamics damping="0.2" friction="0.1" />
  </joint>
  <transmission type="SimpleTransmission">
    <joint name="leg_r5_joint" />
    <actuator name="leg_r5_joint_motor" />
  </transmission>
  <link name="leg_r6_link">
    <inertial>
      <origin xyz="0.02860311 -0.00007463 -0.01983204" rpy="0 0 0" />
      <mass value="0.5783271" />
      <inertia
        ixx="0.00028622"
        ixy="0.00000001"
        ixz="0.00013017"
        iyy="0.00147216"
        iyz="0.00000093"
        izz="0.00158313" />
    </inertial>
    <visual>
      <origin xyz="0 0 0" rpy="0 0 0" />
      <geometry>
        <mesh filename="../../meshes/r_foot_roll.STL" />
      </geometry>
      <material name="">
        <color rgba="1 1 1 1" />
      </material>
    </visual>
  </link>
  <joint name="leg_r6_joint" type="revolute">
    <origin xyz="0 0 -0.018" rpy="0 0 0" />
    <parent link="leg_r5_link" />
    <child link="leg_r6_link" />
    <axis xyz="1 0 0" />
    <limit lower="-0.261799387799149" upper="0.261799387799149" effort="74" velocity="17.0" />
    <dynamics damping="0.2" friction="0.1" />
  </joint>
  <transmission type="SimpleTransmission">
    <joint name="leg_r6_joint" />
    <actuator name="leg_r6_joint_motor" />
  </transmission>
  <!--        ssss -->
  <!-- sssssssss -->
  <link name="r_r_bar_y">
    <inertial>
      <origin rpy="0 0 0" xyz="-0.0176387949701166 0.0012332409395871 0.00472242692632874"/>
      <mass value="0.0413794520732275"/>
      <inertia ixx="6.34865185942549E-06" ixy="2.71679945417066E-06" ixz="4.93236590933488E-06" iyy="2.83792003165434E-05" iyz="-7.27368169902599E-07" izz="2.34510462869433E-05"/>
    </inertial>
    <visual>
      <origin rpy="0 0 0" xyz="0 0 0"/>
      <geometry>
        <mesh filename="../../meshes/r_r_bar.STL"/>
      </geometry>
      <material name="">
        <color rgba="0.690196078431373 0.658823529411765 0.63921568627451 1"/>
      </material>
    </visual>
    <!-- <collision>
      <origin xyz="0 0 0" rpy="0 0 0" />
      <geometry>
        <mesh filename="../../meshes/r_r_bar.STL" />
      </geometry>
    </collision> -->
  </link>
  <joint name="r_r_bar_y" type="continuous">
    <origin rpy="0 0 0" xyz="0 -0.0318 -0.09"/>
    <parent link="leg_r4_link"/>
    <child link="r_r_bar_y"/>
    <axis xyz="0 1 0"/>
  </joint>
  <link name="r_r_tendon_y">
    <inertial>
      <origin rpy="0 0 0" xyz="-1.36421989666846E-05 0.000483312127349173 -0.139530966436641"/>
      <mass value="0.132228698944171"/>
      <inertia ixx="0.000491608612358556" ixy="-3.05402199174078E-12" ixz="1.51985653969833E-08" iyy="0.000489725321370326" iyz="2.42627969905164E-07" izz="4.77496090027913E-06"/>
    </inertial>
    <visual>
      <origin rpy="0 0 0" xyz="0 0 0"/>
      <geometry>
        <mesh filename="../../meshes/r_r_tendon.STL"/>
      </geometry>
      <material name="">
        <color rgba="0.690196078431373 0.658823529411765 0.63921568627451 1"/>
      </material>
    </visual>
    <!-- <collision>
      <origin xyz="0 0 0" rpy="0 0 0" />
      <geometry>
        <mesh filename="../../meshes/r_r_tendon.STL" />
      </geometry>
    </collision> -->
  </link>
  <drake:joint name="r_r_tendon_y" type="universal">
    <origin rpy="0 0 0" xyz="-0.056027 0.0085 0.015"/>
    <parent link="r_r_bar_y"/>
    <child link="r_r_tendon_y"/>
  </drake:joint>
  <frame link="r_r_tendon_y" name="r_r_tendon_socket" xyz="0 0 -0.256"/>
  <transmission type="SimpleTransmission">
    <joint name="r_r_bar_y"/>
    <actuator name="r_r_bar_y_motor">
      <drake:gear_ratio value="10.0"/>
      <drake:rotor_inertia value="0.0001002"/>
    </actuator>
  </transmission>
  <link name="r_l_bar_y">
    <inertial>
      <origin rpy="0 0 0" xyz="-0.0176387868876003 -0.00123323826800568 0.00472240978820238"/>
      <mass value="0.0413794348706216"/>
      <inertia ixx="6.34864114001538E-06" ixy="-2.71679701707313E-06" ixz="4.93234664344148E-06" iyy="2.83791841625158E-05" iyz="7.2736352651351E-07" izz="2.34510398457472E-05"/>
    </inertial>
    <visual>
      <origin rpy="0 0 0" xyz="0 0 0"/>
      <geometry>
        <mesh filename="../../meshes/r_l_bar.STL"/>
      </geometry>
      <material name="">
        <color rgba="0.690196078431373 0.658823529411765 0.63921568627451 1"/>
      </material>
    </visual>
    <!-- <collision>
      <origin xyz="0 0 0" rpy="0 0 0" />
      <geometry>
        <mesh filename="../../meshes/r_l_bar.STL" />
      </geometry>
    </collision> -->
  </link>
  <joint name="r_l_bar_y" type="continuous">
    <origin rpy="0 0 0" xyz="0 0.0362 -0.153"/>
    <parent link="leg_r4_link"/>
    <child link="r_l_bar_y"/>
    <axis xyz="0 1 0"/>
  </joint>
  <transmission type="SimpleTransmission">
    <joint name="r_l_bar_y"/>
    <actuator name="r_l_bar_y_motor">
      <drake:gear_ratio value="10.0"/>
      <drake:rotor_inertia value="0.0001002"/>
    </actuator>
  </transmission>
  <link name="r_l_tendon_y">
    <inertial>
      <origin rpy="0 0 0" xyz="-1.97765085516513E-05 -0.00047926628765782 -0.106248164342492"/>
      <mass value="0.106425376742002"/>
      <inertia ixx="0.000197199480044112" ixy="-4.20204697681874E-12" ixz="-1.28105270857608E-08" iyy="0.00019587468108075" iyz="-1.73407864727289E-07" izz="3.91523487668242E-06"/>
    </inertial>
    <visual>
      <origin rpy="0 0 0" xyz="0 0 0"/>
      <geometry>
        <mesh filename="../../meshes/r_l_tendon.STL"/>
      </geometry>
      <material name="">
        <color rgba="0.690196078431373 0.658823529411765 0.63921568627451 1"/>
      </material>
    </visual>
    <!-- <collision>
      <origin xyz="0 0 0" rpy="0 0 0" />
      <geometry>
        <mesh filename="../../meshes/r_l_tendon.STL" />
      </geometry>
    </collision> -->
  </link>
  <drake:joint name="r_l_tendon_y" type="universal">
    <origin rpy="0 0 0" xyz="-0.056027 -0.0085 0.015"/>
    <parent link="r_l_bar_y"/>
    <child link="r_l_tendon_y"/>
  </drake:joint>
  <frame link="r_l_tendon_y" name="r_l_tendon_socket" xyz="0 0 -0.193"/>
  <frame link="leg_r6_link" name="r_l_foot_socket" xyz="-0.056027 0.0255 0.015"/>
  <frame link="leg_r6_link" name="r_r_foot_socket" xyz="-0.056027 -0.0255 0.015"/>
  <!-- 曲柄 -->
  <frame link="r_l_bar_y" name="r_l_foot_bar_frame" xyz="0 -0.0085 0"/>
  <frame link="r_r_bar_y" name="r_r_foot_bar_frame" xyz="0 0.0085 0"/>
  <!-- =========================================================== Arms ================================================================= -->
  <link name="zarm_l1_link">
    <inertial>
      <origin xyz="0.01773604 -0.00289047 -0.00006872" rpy="0 0 0"/>
      <mass value="0.84760000"/>
      <inertia
        ixx="0.00073101"
        ixy="-0.00004199"
        ixz="-0.00000127"
        iyy="0.00088866"
        iyz="-0.00000149"
        izz="0.00101122"/>
    </inertial>
    <visual>
      <origin xyz="0 0 0" rpy="0 0 0" />
      <geometry>
        <mesh filename="../../meshes/l_arm_pitch.STL" />
      </geometry>
      <material name="">
        <color rgba="1 1 1 1" />
      </material>
    </visual>
  </link>
  <joint name="zarm_l1_joint" type="revolute">
    <origin xyz="0 0.181 0.23843" rpy="0 0 0" />
    <parent link="torso" />
    <child link="zarm_l1_link" />
    <axis xyz="0 1 0" />
    <limit lower="-3.14159265358979" upper="2.0943951023932" effort="14.1" velocity="10.5" />
  </joint>
  <transmission type="SimpleTransmission">
    <joint name="zarm_l1_joint" />
    <actuator name="zarm_l1_joint_motor" />
  </transmission>
  <link name="zarm_l2_link">
    <inertial>
      <origin xyz="0.00199256 0.00000000 -0.03214647" rpy="0 0 0"/>
      <mass value="0.36680000"/>
      <inertia
        ixx="0.00053752"
        ixy="0.00000001"
        ixz="-0.00002375"
        iyy="0.00078576"
        iyz="0.00000000"
        izz="0.00057618"/>
    </inertial>
    <visual>
      <origin xyz="0 0 0" rpy="0 0 0" />
      <geometry>
        <mesh filename="../../meshes/l_arm_roll.STL" />
      </geometry>
      <material name="">
        <color rgba="1 1 1 1" />
      </material>
    </visual>
  </link>
  <joint name="zarm_l2_joint" type="revolute">
    <origin xyz="0 0 0" rpy="0.17453 0 0" />
    <parent link="zarm_l1_link" />
    <child link="zarm_l2_link" />
    <axis xyz="1 0 0" />
    <limit lower="-0.52" upper="3.316" effort="37" velocity="15.0" />
  </joint>
  <transmission type="SimpleTransmission">
    <joint name="zarm_l2_joint" />
    <actuator name="zarm_l2_joint_motor" />
  </transmission>
  <link name="zarm_l3_link">
    <inertial>
      <origin xyz="-0.00007730 -0.00993640 -0.15083251" rpy="0 0 0" />
      <mass value="1.51660000"/>
      <inertia
        ixx="0.00716993"
        ixy="0.00000142"
        ixz="0.00000316"
        iyy="0.00677305"
        iyz="-0.00085824"
        izz="0.00141913"/>
    </inertial>
    <visual>
      <origin xyz="0 0 0" rpy="0 0 0" />
      <geometry>
        <mesh filename="../../meshes/l_arm_yaw.STL" />
      </geometry>
      <material name="">
        <color rgba="1 1 1 1" />
      </material>
    </visual>
  </link>
  <joint name="zarm_l3_joint" type="revolute">
    <origin xyz="0 0 0" rpy="0 0 0" />
    <parent link="zarm_l2_link" />
    <child link="zarm_l3_link" />
    <axis xyz="0 0 1" />
    <limit lower="-1.5707963267949" upper="1.5707963267949" effort="37" velocity="15.0" />
  </joint>
  <transmission type="SimpleTransmission">
    <joint name="zarm_l3_joint" />
    <actuator name="zarm_l3_joint_motor" />
  </transmission>
  <link name="zarm_l4_link">
    <inertial>
      <origin xyz="-0.00104921 -0.00289774 -0.05095618" rpy="0 0 0"/>
      <mass value="0.34500000"/>
      <inertia
        ixx="0.00124963"
        ixy="0.00000224"
        ixz="0.00000372"
        iyy="0.00103949"
        iyz="0.00004727"
        izz="0.00047814"/>
    </inertial>
    <visual>
      <origin xyz="0 0 0" rpy="0 0 0" />
      <geometry>
        <mesh filename="../../meshes/l_forearm.STL" />
      </geometry>
      <material name="">
        <color rgba="1 1 1 1" />
      </material>
    </visual>
  </link>
  <joint name="zarm_l4_joint" type="revolute">
    <origin xyz="0 0 -0.2085" rpy="0 0 0" />
    <parent link="zarm_l3_link" />
    <child link="zarm_l4_link" />
    <axis xyz="0 1 0" />
    <limit lower="-2.26892802759263" upper="0.08726" effort="37" velocity="15.0" />
  </joint>
  <transmission type="SimpleTransmission">
    <joint name="zarm_l4_joint" />
    <actuator name="zarm_l4_joint_motor" />
  </transmission>
  <link name="zarm_r1_link">
    <inertial>
      <origin xyz="0.01773604 0.00289047 -0.00006872" rpy="0 0 0"/>
      <mass value="0.84760000"/>
      <inertia
        ixx="0.00073101"
        ixy="0.00004199"
        ixz="-0.00000127"
        iyy="0.00088866"
        iyz="0.00000149"
        izz="0.00101122"/>
    </inertial>
    <visual>
      <origin xyz="0 0 0" rpy="0 0 0" />
      <geometry>
        <mesh filename="../../meshes/r_arm_pitch.STL" />
      </geometry>
      <material name="">
        <color rgba="1 1 1 1" />
      </material>
    </visual>
  </link>
  <joint name="zarm_r1_joint" type="revolute">
    <origin xyz="0 -0.181 0.23843" rpy="0 0 0" />
    <parent link="torso" />
    <child link="zarm_r1_link" />
    <axis xyz="0 1 0" />
    <limit lower="-3.14159265358979" upper="2.0943951023932" effort="14.1" velocity="10.5" />
  </joint>
  <transmission type="SimpleTransmission">
    <joint name="zarm_r1_joint" />
    <actuator name="zarm_r1_joint_motor" />
  </transmission>
  <link name="zarm_r2_link">
    <inertial>
      <origin xyz="0.00199256 0.00000000 -0.03214647" rpy="0 0 0"/>
      <mass value="0.36680000"/>
      <inertia
        ixx="0.00053752"
        ixy="-0.00000001"
        ixz="-0.00002375"
        iyy="0.00078576"
        iyz="0.00000000"
        izz="0.00057618"/>
    </inertial>
    <visual>
      <origin xyz="0 0 0" rpy="0 0 0"/>
      <geometry>
        <mesh filename="../../meshes/r_arm_roll.STL" />
      </geometry>
      <material name="">
        <color rgba="1 1 1 1" />
      </material>
    </visual>
  </link>
  <joint name="zarm_r2_joint" type="revolute">
    <origin xyz="0 0 0" rpy="-0.17453 0 0" />
    <parent link="zarm_r1_link" />
    <child link="zarm_r2_link" />
    <axis xyz="1 0 0" />
    <limit lower="-3.3161" upper="0.52" effort="37.0" velocity="15.0" />
    <dynamics damping="0.2" friction="0.1" />
  </joint>
  <transmission type="SimpleTransmission">
    <joint name="zarm_r2_joint" />
    <actuator name="zarm_r2_joint_motor" />
  </transmission>
  <link name="zarm_r3_link">
    <inertial>
      <origin xyz="-0.00007730 0.00993640 -0.15083251" rpy="0 0 0"/>
      <mass value="1.51660000"/>
      <inertia
        ixx="0.00716993"
        ixy="-0.00000142"
        ixz="0.00000316"
        iyy="0.00677305"
        iyz="0.00085824"
        izz="0.00141913"/>
    </inertial>
    <visual>
      <origin xyz="0 0 0" rpy="0 0 0" />
      <geometry>
        <mesh filename="../../meshes/r_arm_yaw.STL" />
      </geometry>
      <material name="">
        <color rgba="1 1 1 1" />
      </material>
    </visual>
  </link>
  <joint name="zarm_r3_joint" type="revolute">
    <origin xyz="0 0 0" rpy="0 0 0" />
    <parent link="zarm_r2_link" />
    <child link="zarm_r3_link" />
    <axis xyz="0 0 1" />
    <limit lower="-1.5707963267949" upper="1.5707963267949" effort="37.0" velocity="15.0" />
  </joint>
  <transmission type="SimpleTransmission">
    <joint name="zarm_r3_joint" />
    <actuator name="zarm_r3_joint_motor" />
  </transmission>
  <link name="zarm_r4_link">
    <inertial>
      <origin xyz="-0.00104921 0.00289774 -0.05095618" rpy="0 0 0"/>
      <mass value="0.34500000"/>
      <inertia
        ixx="0.00124963"
        ixy="-0.00000224"
        ixz="0.00000372"
        iyy="0.00103949"
        iyz="-0.00004727"
        izz="0.00047814"/>
    </inertial>
    <visual>
      <origin xyz="0 0 0" rpy="0 0 0" />
      <geometry>
        <mesh filename="../../meshes/r_forearm.STL" />
      </geometry>
      <material name="">
        <color rgba="1 1 1 1" />
      </material>
    </visual>
  </link>
  <joint name="zarm_r4_joint" type="revolute">
    <origin xyz="0 0 -0.2085" rpy="0 0 0"/>
    <parent link="zarm_r3_link" />
    <child link="zarm_r4_link" />
    <axis xyz="0 1 0" />
    <limit lower="-2.26892802759263" upper="0.08726" effort="37.0" velocity="15.0" />
  </joint>
  <transmission type="SimpleTransmission">
    <joint name="zarm_r4_joint" />
    <actuator name="zarm_r4_joint_motor" />
  </transmission>
  <!-- end frame -->
  <!-- <frame link="l_hand_pitch" name="l_hand_sole" xyz="0 0 -0.1" /> -->
  <!-- end frame -->
  <!-- <frame link="r_hand_pitch" name="r_hand_sole" xyz="0 0 -0.1" /> -->
</robot>

