<?xml version="1.0" ?>
<!-- =================================================================================== -->
<!-- |    This document was autogenerated by xacro from /home/fandes/workspace/kuavo-ros-control/src/humanoid-control/humanoid_interface_drake/models/biped_gen4.0/urdf/biped_v3_arm.xacro | -->
<!-- |    EDITING THIS FILE BY HAND IS NOT RECOMMENDED                                 | -->
<!-- =================================================================================== -->
<robot name="biped_v3_arm" xmlns:drake="https://drake.mit.edu">
  <link name="torso">
    <inertial>
      <origin xyz="-0.01005136 -0.00110498 0.14058574" rpy="0 0 0"/>
      <mass value="8.37744703"/>
      <inertia ixx="0.10436018" ixy="0.00037418" ixz="0.00220231"
               iyy="0.08324244" iyz="-0.00108080"
               izz="0.04927332"/>
    </inertial>
    <visual>
      <origin xyz="0 0 0" rpy="0 0 0" />
      <geometry>
        <mesh filename="../../meshes/torso.STL" />
      </geometry>
      <material name="">
        <color rgba="1 1 1 1" />
      </material>
    </visual>
  </link>
  <link name="waist">
    <inertial>
      <origin xyz="0.00202324 -0.00003822 -0.12282710" rpy="0 0 0"/>
      <mass value="5.27737344"/>
      <inertia ixx="0.02656560" ixy="0.00001678" ixz="-0.00000028"
               iyy="0.01821248" iyz="-0.00000269"
               izz="0.02080739"/>
    </inertial>
    <visual>
      <origin xyz="0 0 0" rpy="0 0 0" />
      <geometry>
        <mesh filename="../../meshes/waist.STL" />
      </geometry>
      <material name="">
        <color rgba="1 1 1 1" />
      </material>
    </visual>
  </link>
  <joint name="waist" type="fixed">
    <origin xyz="0 0 0" rpy="0 0 0" />
    <parent link="torso" />
    <child link="waist" />
    <axis xyz="0 0 1" />
    <limit lower="-2.61799387799149" upper="2.61799387799149" effort="80" velocity="12.0" />
    <dynamics damping="0.2" friction="0.0" />
  </joint>
  <!-- =========================================================== Arms ================================================================= -->
  <link name="zarm_l1_link">
    <inertial>
      <origin xyz="0.01773604 -0.00289047 -0.00006872" rpy="0 0 0"/>
      <mass value="0.84760000"/>
      <inertia
        ixx="0.00073101"
        ixy="-0.00004199"
        ixz="-0.00000127"
        iyy="0.00088866"
        iyz="-0.00000149"
        izz="0.00101122"/>
    </inertial>
    <visual>
      <origin xyz="0 0 0" rpy="0 0 0" />
      <geometry>
        <mesh filename="../../meshes/l_arm_pitch.STL" />
      </geometry>
      <material name="">
        <color rgba="1 1 1 1" />
      </material>
    </visual>
  </link>
  <joint name="zarm_l1_joint" type="revolute">
    <origin xyz="0 0.181 0.23843" rpy="0 0 0" />
    <parent link="torso" />
    <child link="zarm_l1_link" />
    <axis xyz="0 1 0" />
    <limit lower="-3.14159265358979" upper="2.0943951023932" effort="14.1" velocity="10.5" />
    <dynamics damping="0.2" friction="0.0" />
  </joint>
  <transmission type="SimpleTransmission">
    <joint name="zarm_l1_joint" />
    <actuator name="zarm_l1_joint_motor" />
  </transmission>
  <link name="zarm_l2_link">
    <inertial>
      <origin xyz="0.00199256 0.00000000 -0.03214647" rpy="0 0 0"/>
      <mass value="0.36680000"/>
      <inertia
        ixx="0.00053752"
        ixy="0.00000001"
        ixz="-0.00002375"
        iyy="0.00078576"
        iyz="0.00000000"
        izz="0.00057618"/>
    </inertial>
    <visual>
      <origin xyz="0 0 0" rpy="0 0 0" />
      <geometry>
        <mesh filename="../../meshes/l_arm_roll.STL" />
      </geometry>
      <material name="">
        <color rgba="1 1 1 1" />
      </material>
    </visual>
  </link>
  <joint name="zarm_l2_joint" type="revolute">
    <origin xyz="0 0 0" rpy="0.17453 0 0" />
    <parent link="zarm_l1_link" />
    <child link="zarm_l2_link" />
    <axis xyz="1 0 0" />
    <limit lower="-0.52" upper="3.316" effort="37" velocity="15.0" />
    <dynamics damping="0.2" friction="0.0" />
  </joint>
  <transmission type="SimpleTransmission">
    <joint name="zarm_l2_joint" />
    <actuator name="zarm_l2_joint_motor" />
  </transmission>
  <link name="zarm_l3_link">
    <inertial>
      <origin xyz="-0.00007730 -0.00993640 -0.15083251" rpy="0 0 0" />
      <mass value="1.51660000"/>
      <inertia
        ixx="0.00716993"
        ixy="0.00000142"
        ixz="0.00000316"
        iyy="0.00677305"
        iyz="-0.00085824"
        izz="0.00141913"/>
    </inertial>
    <visual>
      <origin xyz="0 0 0" rpy="0 0 0" />
      <geometry>
        <mesh filename="../../meshes/l_arm_yaw.STL" />
      </geometry>
      <material name="">
        <color rgba="1 1 1 1" />
      </material>
    </visual>
  </link>
  <joint name="zarm_l3_joint" type="revolute">
    <origin xyz="0 0 0" rpy="0 0 0" />
    <parent link="zarm_l2_link" />
    <child link="zarm_l3_link" />
    <axis xyz="0 0 1" />
    <limit lower="-1.5707963267949" upper="1.5707963267949" effort="37" velocity="15.0" />
    <dynamics damping="0.2" friction="0.0" />
  </joint>
  <transmission type="SimpleTransmission">
    <joint name="zarm_l3_joint" />
    <actuator name="zarm_l3_joint_motor" />
  </transmission>
  <link name="zarm_l4_link">
    <inertial>
      <origin xyz="-0.00104921 -0.00289774 -0.05095618" rpy="0 0 0"/>
      <mass value="0.34500000"/>
      <inertia
        ixx="0.00124963"
        ixy="0.00000224"
        ixz="0.00000372"
        iyy="0.00103949"
        iyz="0.00004727"
        izz="0.00047814"/>
    </inertial>
    <visual>
      <origin xyz="0 0 0" rpy="0 0 0" />
      <geometry>
        <mesh filename="../../meshes/l_forearm.STL" />
      </geometry>
      <material name="">
        <color rgba="1 1 1 1" />
      </material>
    </visual>
  </link>
  <joint name="zarm_l4_joint" type="revolute">
    <origin xyz="0 0 -0.2085" rpy="0 0 0" />
    <parent link="zarm_l3_link" />
    <child link="zarm_l4_link" />
    <axis xyz="0 1 0" />
    <limit lower="-2.26892802759263" upper="0.08726" effort="37" velocity="15.0" />
    <dynamics damping="0.2" friction="0.0" />
  </joint>
  <transmission type="SimpleTransmission">
    <joint name="zarm_l4_joint" />
    <actuator name="zarm_l4_joint_motor" />
  </transmission>
  <link name="l_handball">
    <inertial>
      <!-- Y坐标取反（但原始值为0，所以不变） -->
      <origin xyz="0 0 -0.08819581" rpy="0 0 0"/>
      <mass value="0.17660000"/>
      <inertia
        ixx="0.00046676"
        ixy="0.00000000"
        ixz="0.00000000"
        iyy="0.00046683"
        iyz="0.00000000"
        izz="0.00008009"/>
    </inertial>
    <visual>
      <origin xyz="0 0 0" rpy="0 0 0"/>
      <geometry>
        <mesh filename="package://biped_s17/meshes/l_handball.STL"/>
      </geometry>
      <material name="">
        <color rgba="1 1 1 1" />
      </material>
    </visual>
  </link>

  <!-- Joint connecting zarm_l4_link to l_handball -->
  <joint name="l_handball_joint" type="fixed">
    <origin xyz="0 0 -0.085236" rpy="0 0 0"/>
    <parent link="zarm_l4_link"/>
    <child link="l_handball"/>
  </joint>
  <link name="zarm_l7_end_effector">
    <collision>
      <origin rpy="0 0 0" xyz="0 0 0" />
      <geometry>
        <sphere radius="0.005" />
      </geometry>
    </collision>
  </link>
  <joint name="zarm_l7_end_effector_joint" type="fixed">
    <origin xyz="0 0.0 -0.2175" rpy="0 0 0" />
    <parent link="zarm_l4_link" />
    <child link="zarm_l7_end_effector" />
  </joint>
  <link name="zarm_r1_link">
    <inertial>
      <origin xyz="0.01773604 0.00289047 -0.00006872" rpy="0 0 0"/>
      <mass value="0.84760000"/>
      <inertia
        ixx="0.00073101"
        ixy="0.00004199"
        ixz="-0.00000127"
        iyy="0.00088866"
        iyz="0.00000149"
        izz="0.00101122"/>
    </inertial>
    <visual>
      <origin xyz="0 0 0" rpy="0 0 0" />
      <geometry>
        <mesh filename="../../meshes/r_arm_pitch.STL" />
      </geometry>
      <material name="">
        <color rgba="1 1 1 1" />
      </material>
    </visual>
  </link>
  <joint name="zarm_r1_joint" type="revolute">
    <origin xyz="0 -0.181 0.23843" rpy="0 0 0" />
    <parent link="torso" />
    <child link="zarm_r1_link" />
    <axis xyz="0 1 0" />
    <limit lower="-3.14159265358979" upper="2.0943951023932" effort="14.1" velocity="10.5" />
    <dynamics damping="0.2" friction="0.0" />
  </joint>
  <transmission type="SimpleTransmission">
    <joint name="zarm_r1_joint" />
    <actuator name="zarm_r1_joint_motor" />
  </transmission>
  <link name="zarm_r2_link">
    <inertial>
      <origin xyz="0.00199256 0.00000000 -0.03214647" rpy="0 0 0"/>
      <mass value="0.36680000"/>
      <inertia
        ixx="0.00053752"
        ixy="-0.00000001"
        ixz="-0.00002375"
        iyy="0.00078576"
        iyz="0.00000000"
        izz="0.00057618"/>
    </inertial>
    <visual>
      <origin xyz="0 0 0" rpy="0 0 0" />
      <geometry>
        <mesh filename="../../meshes/r_arm_roll.STL" />
      </geometry>
      <material name="">
        <color rgba="1 1 1 1" />
      </material>
    </visual>
  </link>
  <joint name="zarm_r2_joint" type="revolute">
    <origin xyz="0 0 0" rpy="-0.17453 0 0" />
    <parent link="zarm_r1_link" />
    <child link="zarm_r2_link" />
    <axis xyz="1 0 0" />
    <limit lower="-3.3161" upper="0.52" effort="37.0" velocity="15.0" />
    <dynamics damping="0.2" friction="0.0" />
  </joint>
  <transmission type="SimpleTransmission">
    <joint name="zarm_r2_joint" />
    <actuator name="zarm_r2_joint_motor" />
  </transmission>
  <link name="zarm_r3_link">
    <inertial>
      <origin xyz="-0.00007730 0.00993640 -0.15083251" rpy="0 0 0"/>
      <mass value="1.51660000"/>
      <inertia
        ixx="0.00716993"
        ixy="-0.00000142"
        ixz="0.00000316"
        iyy="0.00677305"
        iyz="0.00085824"
        izz="0.00141913"/>
    </inertial>
    <visual>
      <origin xyz="0 0 0" rpy="0 0 0" />
      <geometry>
        <mesh filename="../../meshes/r_arm_yaw.STL" />
      </geometry>
      <material name="">
        <color rgba="1 1 1 1" />
      </material>
    </visual>
  </link>
  <joint name="zarm_r3_joint" type="revolute">
    <origin xyz="0 0 0" rpy="0 0 0" />
    <parent link="zarm_r2_link" />
    <child link="zarm_r3_link" />
    <axis xyz="0 0 1" />
    <limit lower="-1.5707963267949" upper="1.5707963267949" effort="37.0" velocity="15.0" />
    <dynamics damping="0.2" friction="0.0" />
  </joint>
  <transmission type="SimpleTransmission">
    <joint name="zarm_r3_joint" />
    <actuator name="zarm_r3_joint_motor" />
  </transmission>
  <link name="zarm_r4_link">
    <inertial>
      <origin xyz="-0.00104921 0.00289774 -0.05095618" rpy="0 0 0"/>
      <mass value="0.34500000"/>
      <inertia
        ixx="0.00124963"
        ixy="-0.00000224"
        ixz="0.00000372"
        iyy="0.00103949"
        iyz="-0.00004727"
        izz="0.00047814"/>
    </inertial>
    <visual>
      <origin xyz="0 0 0" rpy="0 0 0" />
      <geometry>
        <mesh filename="../../meshes/r_forearm.STL" />
      </geometry>
      <material name="">
        <color rgba="1 1 1 1" />
      </material>
    </visual>
  </link>
  <joint name="zarm_r4_joint" type="revolute">
    <origin xyz="0 0 -0.2085" rpy="0 0 0"/>
    <parent link="zarm_r3_link" />
    <child link="zarm_r4_link" />
    <axis xyz="0 1 0" />
    <limit lower="-2.26892802759263" upper="0.08726" effort="37.0" velocity="15.0" />
    <dynamics damping="0.2" friction="0.0" />
  </joint>
  <transmission type="SimpleTransmission">
    <joint name="zarm_r4_joint" />
    <actuator name="zarm_r4_joint_motor" />
  </transmission>
  <!-- r_handball link with updated inertial properties -->
  <link name="r_handball">
    <inertial>
      <origin xyz="0 0 -0.08819581" rpy="0 0 0"/>
      <mass value="0.17660000"/>
      <inertia
        ixx="0.00046676"
        ixy="0.00000000"
        ixz="0.00000000"
        iyy="0.00046683"
        iyz="0.00000000"
        izz="0.00008009"/>
    </inertial>
    <visual>
      <origin xyz="0 0 0" rpy="0 0 0"/>
      <geometry>
        <mesh filename="package://biped_s17/meshes/r_handball.STL"/>
      </geometry>
      <material name="">
        <color rgba="1 1 1 1" />
      </material>
    </visual>
  </link>

  <!-- Joint connecting r_forearm to r_handball -->
  <joint name="r_handball_joint" type="fixed">
    <origin xyz="0 0 -0.085236" rpy="0 0 0"/>
    <parent link="zarm_r4_link"/>
    <child link="r_handball"/>
  </joint>
  <link name="zarm_r7_end_effector">
    <collision>
      <origin rpy="0 0 0" xyz="0 0 0" />
      <geometry>
        <sphere radius="0.005" />
      </geometry>
    </collision>
  </link>
  <joint name="zarm_r7_end_effector_joint" type="fixed">
    <origin xyz="0 0.0 -0.2175" rpy="0 0 0" />
    <parent link="zarm_r4_link" />
    <child link="zarm_r7_end_effector" />
  </joint>
  <!-- end frame -->
  <!-- <frame link="l_hand_pitch" name="l_hand_sole" xyz="0 0 -0.1" /> -->
  <!-- end frame -->
  <!-- <frame link="r_hand_pitch" name="r_hand_sole" xyz="0 0 -0.1" /> -->
</robot>
