<?xml version="1.0" ?>
<!-- =================================================================================== -->
<!-- |    This document was autogenerated by xacro from /home/fandes/workspace/kuavo-ros-control/src/humanoid-control/humanoid_interface_drake/models/biped_gen4.2/urdf/Larm.xacro | -->
<!-- |    EDITING THIS FILE BY HAND IS NOT RECOMMENDED                                 | -->
<!-- =================================================================================== -->
<robot name="Larm" xmlns:drake="https://drake.mit.edu">
  <!-- =========================================================== Arms ================================================================= -->
  <link name="l_arm_pitch">
    <inertial>
      <origin rpy="0 0 0" xyz="0.01852427 -0.00307832 -0.00006089"/>
      <mass value="0.80328906"/>
      <inertia ixx="0.00065573" ixy="-0.00004427" ixz="-0.00000010" iyy="0.00082825" iyz="-0.00000114" izz="0.00093564"/>
    </inertial>
    <visual>
      <origin rpy="0 0 0" xyz="0 0 0"/>
      <geometry>
        <mesh filename="../../meshes/l_arm_pitch.STL"/>
      </geometry>
      <material name="">
        <color rgba="1 1 1 1"/>
      </material>
    </visual>
  </link>
  <joint name="l_arm_pitch" type="continuous">
    <origin rpy="0 0 0" xyz="0.0 0.18100293 0.23992606"/>
    <parent link="torso"/>
    <child link="l_arm_pitch"/>
    <axis xyz="0 1 0"/>
    <limit effort="12" lower="-3.14159265358979" upper="2.0943951023932" velocity="7.32666666666667"/>
  </joint>
  <transmission type="SimpleTransmission">
    <joint name="l_arm_pitch"/>
    <actuator name="l_arm_pitch_motor"/>
  </transmission>
  <link name="l_arm_roll">
    <inertial>
      <origin rpy="0 0 0" xyz="0.00217668 0.00574680 -0.03258678"/>
      <mass value="0.32360735"/>
      <inertia ixx="0.00046909" ixy="0.0" ixz="-0.00002559" iyy="0.00068110" iyz="0.0" izz="0.00049735"/>
    </inertial>
    <visual>
      <origin rpy="0 0 0" xyz="0 0 0"/>
      <geometry>
        <mesh filename="../../meshes/l_arm_roll.STL"/>
      </geometry>
      <material name="">
        <color rgba="1 1 1 1"/>
      </material>
    </visual>
  </link>
  <joint name="l_arm_roll" type="continuous">
    <origin rpy="0 0 0" xyz="0 0 0"/>
    <parent link="l_arm_pitch"/>
    <child link="l_arm_roll"/>
    <axis xyz="1 0 0"/>
    <limit effort="12" lower="-0.52" upper="3.316" velocity="7.32666666666667"/>
  </joint>
  <transmission type="SimpleTransmission">
    <joint name="l_arm_roll"/>
    <actuator name="l_arm_roll_motor"/>
  </transmission>
  <link name="l_arm_yaw">
    <inertial>
      <origin rpy="0 0 0" xyz="-0.00006747 -0.01016408 -0.15041767"/>
      <mass value="1.46578996"/>
      <inertia ixx="0.00696550" ixy="0.00000046" ixz="0.00000200" iyy="0.00656301" iyz="-0.00085646" izz="0.00135717"/>
    </inertial>
    <visual>
      <origin rpy="0 0 0" xyz="0 0 0"/>
      <geometry>
        <mesh filename="../../meshes/l_arm_yaw.STL"/>
      </geometry>
      <material name="">
        <color rgba="1 1 1 1"/>
      </material>
    </visual>
  </link>
  <joint name="l_arm_yaw" type="continuous">
    <origin rpy="0 0 0" xyz="0 0 0"/>
    <parent link="l_arm_roll"/>
    <child link="l_arm_yaw"/>
    <axis xyz="0 0 1"/>
    <limit effort="12" lower="-1.5707963267949" upper="1.5707963267949" velocity="7.32666666666667"/>
  </joint>
  <transmission type="SimpleTransmission">
    <joint name="l_arm_yaw"/>
    <actuator name="l_arm_yaw_motor"/>
  </transmission>
  <link name="l_forearm_pitch">
    <inertial>
      <origin rpy="0 0 0" xyz="-0.00081309 -0.01331683 -0.08985563"/>
      <mass value="0.42136972"/>
      <inertia ixx="0.00335991" ixy="0.00000193" ixz="0.00001686" iyy="0.00315848" iyz="0.00008493" izz="0.00049447"/>
    </inertial>
    <visual>
      <origin rpy="0 0 0" xyz="0 0 0"/>
      <geometry>
        <mesh filename="../../meshes/l_forearm_pitch.STL"/>
      </geometry>
      <material name="">
        <color rgba="1 1 1 1"/>
      </material>
    </visual>
  </link>
  <joint name="l_forearm_pitch" type="continuous">
    <origin rpy="0 0 0" xyz="0 0.0 -0.20533"/>
    <parent link="l_arm_yaw"/>
    <child link="l_forearm_pitch"/>
    <axis xyz="0 1 0"/>
    <limit effort="12" lower="-2.26892802759263" upper="0.08726" velocity="7.32666666666667"/>
  </joint>
  <transmission type="SimpleTransmission">
    <joint name="l_forearm_pitch"/>
    <actuator name="l_forearm_pitch_motor"/>
  </transmission>
  <link name="l_hand_yaw">
    <inertial>
      <origin rpy="0 0 0" xyz="0.000113133463122583 0.00969227839919062 0.0817960696431681"/>
      <mass value="0.380792"/>
      <inertia ixx="7.64923984145487E-05" ixy="8.51098127601464E-09" ixz="-1.4070355859132E-08" iyy="0.000122231132554914" iyz="1.11226968994633E-06" izz="8.44935061342021E-05"/>
    </inertial>
    <visual>
      <origin rpy="0 0 0" xyz="0 0 0"/>
      <geometry>
        <mesh filename="../../meshes/l_hand_yaw.STL"/>
      </geometry>
      <material name="">
        <color rgba="1 1 1 1"/>
      </material>
    </visual>
  </link>
  <joint name="l_hand_yaw" type="continuous">
    <origin rpy="0 0 0" xyz="0 0 -0.191049997298861"/>
    <parent link="l_forearm_pitch"/>
    <child link="l_hand_yaw"/>
    <axis xyz="0 0 1"/>
    <limit effort="12" lower="-3.14159265358979" upper="2.0943951023932" velocity="7.32666666666667"/>
  </joint>
  <transmission type="SimpleTransmission">
    <joint name="l_hand_yaw"/>
    <actuator name="l_hand_yaw_motor"/>
  </transmission>
  <link name="l_hand_pitch">
    <inertial>
      <origin rpy="0 0 0" xyz="0.00810609786663821 0.00489663150092601 0.00622488608908427"/>
      <mass value="0.376651"/>
      <inertia ixx="4.77321490368476E-05" ixy="3.05261917457107E-06" ixz="4.77827164947654E-06" iyy="3.43814769749139E-05" iyz="-4.59311499587155E-06" izz="2.49955336560135E-05"/>
    </inertial>
    <visual>
      <origin rpy="0 0 0" xyz="0 0 0"/>
      <geometry>
        <mesh filename="../../meshes/l_hand_pitch.STL"/>
      </geometry>
      <material name="">
        <color rgba="1 1 1 1"/>
      </material>
    </visual>
  </link>
  <joint name="l_hand_pitch" type="continuous">
    <origin rpy="0 0 0" xyz="0 0 0"/>
    <parent link="l_hand_yaw"/>
    <child link="l_hand_pitch"/>
    <axis xyz="0 1 0"/>
    <limit effort="12" lower="-3.14159265358979" upper="2.0943951023932" velocity="7.32666666666667"/>
  </joint>
  <transmission type="SimpleTransmission">
    <joint name="l_hand_pitch"/>
    <actuator name="l_hand_pitch_motor"/>
  </transmission>
  <link name="l_hand_roll">
    <inertial>
      <origin rpy="0 0 0" xyz="0.0055750097939089 0.00647363667890594 -0.0826245715087526"/>
      <mass value="0.704669"/>
      <inertia ixx="8.04371746531483E-05" ixy="2.770174858381E-07" ixz="-4.63354764745673E-06" iyy="0.000116536814280971" iyz="1.04534418501281E-05" izz="0.000111690600253046"/>
    </inertial>
    <visual>
      <origin rpy="0 0 0" xyz="0 0 0"/>
      <geometry>
        <mesh filename="../../meshes/l_hand_roll.STL"/>
      </geometry>
      <material name="">
        <color rgba="1 1 1 1"/>
      </material>
    </visual>
  </link>
  <joint name="l_hand_roll" type="continuous">
    <origin rpy="0 0 0" xyz="0 0 0"/>
    <parent link="l_hand_pitch"/>
    <child link="l_hand_roll"/>
    <axis xyz="1 0 0"/>
    <limit effort="12" lower="-3.14159265358979" upper="2.0943951023932" velocity="7.32666666666667"/>
  </joint>
  <transmission type="SimpleTransmission">
    <joint name="l_hand_roll"/>
    <actuator name="l_hand_roll_motor"/>
  </transmission>
  <!-- end frame -->
  <!-- <frame link="l_hand_pitch" name="l_hand_sole" xyz="0 0 -0.1" /> -->
</robot>

