<?xml version="1.0" ?>
<!-- =================================================================================== -->
<!-- |    This document was autogenerated by xacro from /home/fandes/workspace/kuavo-ros-control/src/humanoid-control/humanoid_interface_drake/models/biped_gen4.2/urdf/Rarm.xacro | -->
<!-- |    EDITING THIS FILE BY HAND IS NOT RECOMMENDED                                 | -->
<!-- =================================================================================== -->
<robot name="Rarm" xmlns:drake="https://drake.mit.edu">
  <!-- right arm -->
  <link name="r_arm_pitch">
    <inertial>
      <origin rpy="0 0 0" xyz="0.01852427 0.00307832 -0.00006089"/>
      <mass value="0.80328906"/>
      <inertia ixx="0.00065573" ixy="0.00004427" ixz="-0.00000010" iyy="0.00082825" iyz="0.00000114" izz="0.00093564"/>
    </inertial>
    <visual>
      <origin rpy="0 0 0" xyz="0 0 0"/>
      <geometry>
        <mesh filename="../../meshes/r_arm_pitch.STL"/>
      </geometry>
      <material name="">
        <color rgba="1 1 1 1"/>
      </material>
    </visual>
  </link>
  <joint name="r_arm_pitch" type="continuous">
    <origin rpy="0 0 0" xyz="0.0 -0.18100293 0.23992606"/>
    <parent link="torso"/>
    <child link="r_arm_pitch"/>
    <axis xyz="0 1 0"/>
    <limit effort="12" lower="-3.14159265358979" upper="2.0943951023932" velocity="7.32666666666667"/>
  </joint>
  <transmission type="SimpleTransmission">
    <joint name="r_arm_pitch"/>
    <actuator name="r_arm_pitch_motor"/>
  </transmission>
  <link name="r_arm_roll">
    <inertial>
      <origin rpy="0 0 0" xyz="0.00217668 -0.00574680 -0.03258678"/>
      <mass value="0.32360735"/>
      <inertia ixx="0.00046909" ixy="0.0" ixz="-0.00002559" iyy="0.00068110" iyz="0.0" izz="0.00049735"/>
    </inertial>
    <visual>
      <origin rpy="0 0 0" xyz="0 0 0"/>
      <geometry>
        <mesh filename="../../meshes/r_arm_roll.STL"/>
      </geometry>
      <material name="">
        <color rgba="1 1 1 1"/>
      </material>
    </visual>
  </link>
  <joint name="r_arm_roll" type="continuous">
    <origin rpy="0 0 0" xyz="0 0 0"/>
    <parent link="r_arm_pitch"/>
    <child link="r_arm_roll"/>
    <axis xyz="1 0 0"/>
    <limit effort="12" lower="-3.14159265358979" upper="2.0943951023932" velocity="7.32666666666667"/>
  </joint>
  <transmission type="SimpleTransmission">
    <joint name="r_arm_roll"/>
    <actuator name="r_arm_roll_motor"/>
  </transmission>
  <link name="r_arm_yaw">
    <inertial>
      <origin rpy="0 0 0" xyz="-0.00006747 0.01016408 -0.15041767"/>
      <mass value="1.46578996"/>
      <inertia ixx="0.00696550" ixy="-0.00000046" ixz="0.00000200" iyy="0.00656301" iyz="0.00085646" izz="0.00135717"/>
    </inertial>
    <visual>
      <origin rpy="0 0 0" xyz="0 0 0"/>
      <geometry>
        <mesh filename="../../meshes/r_arm_yaw.STL"/>
      </geometry>
      <material name="">
        <color rgba="1 1 1 1"/>
      </material>
    </visual>
  </link>
  <joint name="r_arm_yaw" type="continuous">
    <origin rpy="0 0 0" xyz="0 0 0"/>
    <parent link="r_arm_roll"/>
    <child link="r_arm_yaw"/>
    <axis xyz="0 -0.17365 -0.98481"/>
    <limit effort="12" lower="-1.5707963267949" upper="1.5707963267949" velocity="7.32666666666667"/>
  </joint>
  <transmission type="SimpleTransmission">
    <joint name="r_arm_yaw"/>
    <actuator name="r_arm_yaw_motor"/>
  </transmission>
  <link name="r_forearm_pitch">
    <inertial>
      <origin rpy="0 0 0" xyz="-0.00081309 0.01331683 -0.08985563"/>
      <mass value="0.42136972"/>
      <inertia ixx="0.00335991" ixy="-0.00000193" ixz="0.00001686" iyy="0.00315848" iyz="-0.00008493" izz="0.00049447"/>
    </inertial>
    <visual>
      <origin rpy="0 0 0" xyz="0 0 0"/>
      <geometry>
        <mesh filename="../../meshes/r_forearm_pitch.STL"/>
      </geometry>
      <material name="">
        <color rgba="1 1 1 1"/>
      </material>
    </visual>
  </link>
  <joint name="r_forearm_pitch" type="continuous">
    <origin rpy="0 0 0" xyz="0 -0.0 -0.20533"/>
    <parent link="r_arm_yaw"/>
    <child link="r_forearm_pitch"/>
    <axis xyz="0 -0.98481 0.17365"/>
    <limit effort="12" lower="-2.26892802759263" upper="0.08726" velocity="7.32666666666667"/>
  </joint>
  <transmission type="SimpleTransmission">
    <joint name="r_forearm_pitch"/>
    <actuator name="r_forearm_pitch_motor"/>
  </transmission>
  <link name="r_hand_yaw">
    <inertial>
      <origin rpy="0 0 0" xyz="-0.000113133331993445 -0.0097448351680483 0.0817960724173413"/>
      <mass value="0.380792"/>
      <inertia ixx="7.64923982725728E-05" ixy="8.51115986496426E-09" ixz="1.40703608309957E-08" iyy="0.000122231132626729" iyz="-1.11226978982942E-06" izz="8.44935061081861E-05"/>
    </inertial>
    <visual>
      <origin rpy="0 0 0" xyz="0 0 0"/>
      <geometry>
        <mesh filename="../../meshes/r_hand_yaw.STL"/>
      </geometry>
      <material name="">
        <color rgba="1 1 1 1"/>
      </material>
    </visual>
  </link>
  <joint name="r_hand_yaw" type="continuous">
    <origin rpy="0 0 0" xyz="0 0 -0.191050000125729"/>
    <parent link="r_forearm_pitch"/>
    <child link="r_hand_yaw"/>
    <axis xyz="0 0 1"/>
    <limit effort="12" lower="-3.14159265358979" upper="2.0943951023932" velocity="7.32666666666667"/>
  </joint>
  <transmission type="SimpleTransmission">
    <joint name="r_hand_yaw"/>
    <actuator name="r_hand_yaw_motor"/>
  </transmission>
  <link name="r_hand_pitch">
    <inertial>
      <origin rpy="0 0 0" xyz="0.00735986990228184 -0.0047523802551166 0.00605888061339196"/>
      <mass value="0.376651"/>
      <inertia ixx="4.77321358097824E-05" ixy="-2.99709432812988E-06" ixz="4.71488437974188E-06" iyy="3.42470226388499E-05" iyz="4.61094199971347E-06" izz="2.51299600072388E-05"/>
    </inertial>
    <visual>
      <origin rpy="0 0 0" xyz="0 0 0"/>
      <geometry>
        <mesh filename="../../meshes/r_hand_pitch.STL"/>
      </geometry>
      <material name="">
        <color rgba="1 1 1 1"/>
      </material>
    </visual>
  </link>
  <joint name="r_hand_pitch" type="continuous">
    <origin rpy="0 0 0" xyz="0 0 0"/>
    <parent link="r_hand_yaw"/>
    <child link="r_hand_pitch"/>
    <axis xyz="0 1 0"/>
    <limit effort="12" lower="-3.14159265358979" upper="2.0943951023932" velocity="7.32666666666667"/>
  </joint>
  <transmission type="SimpleTransmission">
    <joint name="r_hand_pitch"/>
    <actuator name="r_hand_pitch_motor"/>
  </transmission>
  <link name="r_hand_roll">
    <inertial>
      <origin rpy="0 0 0" xyz="0.0045944493552252 -0.00586927010446042 -0.0836324643988434"/>
      <mass value="0.704669"/>
      <inertia ixx="0.000160651543151659" ixy="-5.37963063503334E-07" ixz="-9.47669219939636E-06" iyy="0.000229393712149694" iyz="-2.08351527945055E-05" izz="0.000219277776699058"/>
    </inertial>
    <visual>
      <origin rpy="0 0 0" xyz="0 0 0"/>
      <geometry>
        <mesh filename="../../meshes/r_hand_roll.STL"/>
      </geometry>
      <material name="">
        <color rgba="1 1 1 1"/>
      </material>
    </visual>
  </link>
  <joint name="r_hand_roll" type="continuous">
    <origin rpy="0 0 0" xyz="0 0 0"/>
    <parent link="r_hand_pitch"/>
    <child link="r_hand_roll"/>
    <axis xyz="1 0 0"/>
    <limit effort="12" lower="-3.14159265358979" upper="2.0943951023932" velocity="7.32666666666667"/>
  </joint>
  <transmission type="SimpleTransmission">
    <joint name="r_hand_roll"/>
    <actuator name="r_hand_roll_motor"/>
  </transmission>
  <!-- end frame -->
  <!-- <frame link="r_hand_pitch" name="r_hand_sole" xyz="0 0 -0.1" /> -->
</robot>

