<?xml version='1.0' encoding='utf-8'?>
<robot name="biped_s41">
  <mujoco>
    <compiler meshdir="../meshes/" balanceinertia="true" discardvisual="false" />
  </mujoco>
  <link name="dummy_link" />
  <link name="base_link">
    <inertial>
      <origin xyz="-0.00505 0.0014 0.18077" rpy="0 0 0" />
      <mass value="23.8489" />
      <inertia ixx="0.28214" ixy="3e-05" ixz="0.01114" iyy="0.20534" iyz="0.00044" izz="0.13735" />
    </inertial>
    <visual>
      <origin xyz="0 0 0" rpy="0 0 0" />
      <geometry>
        <mesh filename="package://kuavo_assets/models/biped_s41/meshes/base_link.STL" />
      </geometry>
      <material name="">
        <color rgba="1 1 1 1" />
      </material>
    </visual>
  </link>
  <joint name="dummy_to_base_link" type="fixed">
    <origin xyz="0 0 0" rpy="0 0 0" />
    <parent link="dummy_link" />
    <child link="base_link" />
    <dynamics damping="0.2" friction="0.0"/>
  </joint>
  <link name="leg_l1_link">
    <inertial>
      <origin xyz="-0.00430148 -2.708e-05 -0.00851195" rpy="0 0 0" />
      <mass value="1.71093115" />
      <inertia ixx="0.00206092" ixy="1.97e-06" ixz="6.944e-05" iyy="0.00277274" iyz="-5.1e-06" izz="0.00370826" />
    </inertial>
    <visual>
      <origin xyz="0 0 0" rpy="0 0 0" />
      <geometry>
        <mesh filename="package://kuavo_assets/models/biped_s41/meshes/l_leg_roll.STL" />
      </geometry>
      <material name="">
        <color rgba="1 1 1 1" />
      </material>
    </visual>
  </link>
  <joint name="leg_l1_joint" type="revolute">
    <origin xyz="-0.0025 0.087 -0.066" rpy="0 0 0" />
    <parent link="base_link" />
    <child link="leg_l1_link" />
    <axis xyz="1 0 0" />
    <limit lower="-0.314159265358979" upper="0.663225115757845" effort="180.0" velocity="23.55" />
    <dynamics damping="0.2" friction="0.0"/>
  </joint>
  <link name="leg_l2_link">
    <inertial>
      <origin xyz="0.0 -0.00231118 -0.09062539" rpy="0 0 0" />
      <mass value="0.58029165" />
      <inertia ixx="0.00223984" ixy="0.0" ixz="3e-08" iyy="0.00123175" iyz="-6.98e-06" izz="0.00146391" />
    </inertial>
    <visual>
      <origin xyz="0 0 0" rpy="0 0 0" />
      <geometry>
        <mesh filename="package://kuavo_assets/models/biped_s41/meshes/l_leg_yaw.STL" />
      </geometry>
      <material name="">
        <color rgba="1 1 1 1" />
      </material>
    </visual>
  </link>
  <joint name="leg_l2_joint" type="revolute">
    <origin xyz="0 0 0" rpy="0 0 0" />
    <parent link="leg_l1_link" />
    <child link="leg_l2_link" />
    <axis xyz="0 0 1" />
    <limit lower="-0.872664625997165" upper="0.785398163397448" effort="100.0" velocity="41.3433333333333" />
    <dynamics damping="0.5" friction="0.0"/>
  </joint>
  <link name="leg_l3_link">
    <inertial>
      <origin xyz="0.00150537 0.01199614 -0.08411619" rpy="0 0 0" />
      <mass value="4.50393141" />
      <inertia ixx="0.0389365" ixy="7.866e-05" ixz="0.00102086" iyy="0.03942609" iyz="0.00219138" izz="0.00999961" />
    </inertial>
    <visual>
      <origin xyz="0 0 0" rpy="0 0 0" />
      <geometry>
        <mesh filename="package://kuavo_assets/models/biped_s41/meshes/l_leg_pitch.STL" />
      </geometry>
      <material name="">
        <color rgba="1 1 1 1" />
      </material>
    </visual>
  </link>
  <joint name="leg_l3_joint" type="revolute">
    <origin xyz="0.000500354536093913 -0.00100000000000011 -0.1287" rpy="0 0 0" />
    <parent link="leg_l2_link" />
    <child link="leg_l3_link" />
    <axis xyz="0 1 0" />
    <limit lower="-2.00712863979348" upper="1.5707963267949" effort="100.0" velocity="41.3433333333333" />
    <dynamics damping="0.2" friction="0.0"/>
  </joint>
  <link name="leg_l4_link">
    <inertial>
      <origin xyz="0.00696242 5.314e-05 -0.11549851" rpy="0 0 0" />
      <mass value="1.62776815" />
      <inertia ixx="0.01243912" ixy="-2.29e-06" ixz="5.881e-05" iyy="0.01229563" iyz="-2.895e-05" izz="0.00097937" />
    </inertial>
    <visual>
      <origin xyz="0 0 0" rpy="0 0 0" />
      <geometry>
        <mesh filename="package://kuavo_assets/models/biped_s41/meshes/l_knee.STL" />
      </geometry>
      <material name="">
        <color rgba="1 1 1 1" />
      </material>
    </visual>
  </link>
  <joint name="leg_l4_joint" type="revolute">
    <origin xyz="-6.87185435835039E-05 0 -0.284" rpy="0 0 0" />
    <parent link="leg_l3_link" />
    <child link="leg_l4_link" />
    <axis xyz="0 1 0" />
    <limit lower="0.0" upper="2.53072741539178" effort="180.0" velocity="23.55" />
    <dynamics damping="0.2" friction="0.0"/>
  </joint>
  <link name="leg_l5_link">
    <inertial>
      <origin xyz="0.0 0.0 0.0" rpy="0 0 0" />
      <mass value="0.07193524" />
      <inertia ixx="6.92e-04" ixy="0.0" ixz="0.0" iyy="6.92e-04" iyz="0.0" izz="1.218e-04" />
    </inertial>
    <visual>
      <origin xyz="0 0 0" rpy="0 0 0" />
      <geometry>
        <mesh filename="package://kuavo_assets/models/biped_s41/meshes/l_foot_pitch.STL" />
      </geometry>
      <material name="">
        <color rgba="1 1 1 1" />
      </material>
    </visual>
  </link>
  <joint name="leg_l5_joint" type="revolute">
    <origin xyz="-0.000431635992531742 0 -0.346000000000001" rpy="0 0 0" />
    <parent link="leg_l4_link" />
    <child link="leg_l5_link" />
    <axis xyz="0 1 0" />
    <limit lower="-0.872664625997165" upper="0.349065850398866" effort="36.0" velocity="23.0266666666667" />
    <dynamics damping="0.2" friction="0.0"/>
  </joint>
  <link name="leg_l6_link">
    <inertial>
      <origin xyz="0.03732754 -2.22e-06 -0.03883977" rpy="0 0 0" />
      <mass value="0.49861272" />
      <inertia ixx="0.00039242" ixy="3e-08" ixz="4.664e-05" iyy="0.00158655" iyz="0.0" izz="0.00172576" />
    </inertial>
    <visual>
      <origin xyz="0 0 0" rpy="0 0 0" />
      <geometry>
        <mesh filename="package://kuavo_assets/models/biped_s41/meshes/l_foot_roll.STL" />
      </geometry>
      <material name="">
        <color rgba="1 1 1 1" />
      </material>
    </visual>
  </link>
  <joint name="leg_l6_joint" type="revolute">
    <origin xyz="0 0 0" rpy="0 0 0" />
    <parent link="leg_l5_link" />
    <child link="leg_l6_link" />
    <axis xyz="1 0 0" />
    <limit lower="-0.261799387799149" upper="0.261799387799149" effort="36.0" velocity="23.0266666666667" />
    <dynamics damping="0.2" friction="0.0"/>
  </joint>
  <link name="ll_foot_toe">
    <collision>
      <origin rpy="0 0 0" xyz="0 0 0" />
      <geometry>
        <sphere radius="0.005" />
      </geometry>
    </collision>
  </link>
  <joint name="ll_foot_toe_joint" type="fixed">
    <origin xyz="0.17084 0.04773 -0.0595" rpy="0 0 0" />
    <parent link="leg_l6_link" />
    <child link="ll_foot_toe" />
    <dynamics damping="0.2" friction="0.0"/>
  </joint>
  <link name="ll_foot_heel">
    <collision>
      <origin rpy="0 0 0" xyz="0 0 0" />
      <geometry>
        <sphere radius="0.005" />
      </geometry>
    </collision>
  </link>
  <joint name="ll_foot_heel_joint" type="fixed">
    <origin xyz="-0.073164 0.04773 -0.0595" rpy="0 0 0" />
    <parent link="leg_l6_link" />
    <child link="ll_foot_heel" />
    <dynamics damping="0.2" friction="0.0"/>
  </joint>
  <link name="lr_foot_toe">
    <collision>
      <origin rpy="0 0 0" xyz="0 0 0" />
      <geometry>
        <sphere radius="0.005" />
      </geometry>
    </collision>
  </link>
  <joint name="lr_foot_toe_joint" type="fixed">
    <origin xyz="0.17084 -0.04773 -0.0595" rpy="0 0 0" />
    <parent link="leg_l6_link" />
    <child link="lr_foot_toe" />
    <dynamics damping="0.2" friction="0.0"/>
  </joint>
  <link name="lr_foot_heel">
    <collision>
      <origin rpy="0 0 0" xyz="0 0 0" />
      <geometry>
        <sphere radius="0.005" />
      </geometry>
    </collision>
  </link>
  <joint name="lr_foot_heel_joint" type="fixed">
    <origin xyz="-0.073164 -0.04773 -0.0595" rpy="0 0 0" />
    <parent link="leg_l6_link" />
    <child link="lr_foot_heel" />
    <dynamics damping="0.2" friction="0.0"/>
  </joint>
  <link name="l_foot_toe">
    <collision>
      <origin rpy="0 0 0" xyz="0 0 0" />
      <geometry>
        <sphere radius="0.005" />
      </geometry>
    </collision>
  </link>
  <joint name="l_foot_toe_joint" type="fixed">
    <origin xyz="0.17084 0.0 -0.0595" rpy="0 0 0" />
    <parent link="leg_l6_link" />
    <child link="l_foot_toe" />
    <dynamics damping="0.2" friction="0.0"/>
  </joint>
  <link name="l_foot_heel">
    <collision>
      <origin rpy="0 0 0" xyz="0 0 0" />
      <geometry>
        <sphere radius="0.005" />
      </geometry>
    </collision>
  </link>
  <joint name="l_foot_heel_joint" type="fixed">
    <origin xyz="-0.073164 0.0 -0.0595" rpy="0 0 0" />
    <parent link="leg_l6_link" />
    <child link="l_foot_heel" />
    <dynamics damping="0.2" friction="0.0"/>
  </joint>
  <link name="leg_r1_link">
    <inertial>
      <origin xyz="-0.00430146 2.709e-05 -0.00851195" rpy="0 0 0" />
      <mass value="1.71093008" />
      <inertia ixx="0.00206092" ixy="-1.97e-06" ixz="6.944e-05" iyy="0.00277274" iyz="5.1e-06" izz="0.00370826" />
    </inertial>
    <visual>
      <origin xyz="0 0 0" rpy="0 0 0" />
      <geometry>
        <mesh filename="package://kuavo_assets/models/biped_s41/meshes/r_leg_roll.STL" />
      </geometry>
      <material name="">
        <color rgba="1 1 1 1" />
      </material>
    </visual>
  </link>
  <joint name="leg_r1_joint" type="revolute">
    <origin xyz="-0.0025 -0.087 -0.066" rpy="0 0 0" />
    <parent link="base_link" />
    <child link="leg_r1_link" />
    <axis xyz="1 0 0" />
    <limit lower="-0.663225115757845" upper="0.314159265358979" effort="180.0" velocity="23.55" />
    <dynamics damping="0.2" friction="0.0"/>
  </joint>
  <link name="leg_r2_link">
    <inertial>
      <origin xyz="0.0 0.00231118 -0.09062539" rpy="0 0 0" />
      <mass value="0.58029165" />
      <inertia ixx="0.00223984" ixy="0.0" ixz="-3e-08" iyy="0.00123175" iyz="6.98e-06" izz="0.00146391" />
    </inertial>
    <visual>
      <origin xyz="0 0 0" rpy="0 0 0" />
      <geometry>
        <mesh filename="package://kuavo_assets/models/biped_s41/meshes/r_leg_yaw.STL" />
      </geometry>
      <material name="">
        <color rgba="1 1 1 1" />
      </material>
    </visual>
  </link>
  <joint name="leg_r2_joint" type="revolute">
    <origin xyz="0 0 0" rpy="0 0 0" />
    <parent link="leg_r1_link" />
    <child link="leg_r2_link" />
    <axis xyz="0 0 1" />
    <limit lower="-0.785398163397448" upper="0.872664625997165" effort="100.0" velocity="41.3433333333333" />
    <dynamics damping="0.5" friction="0.0"/>
  </joint>
  <link name="leg_r3_link">
    <inertial>
      <origin xyz="0.00208315 -0.01199644 -0.08411379" rpy="0 0 0" />
      <mass value="4.50385993" />
      <inertia ixx="0.03893478" ixy="-7.792e-05" ixz="0.00103064" iyy="0.03942522" iyz="-0.00219154" izz="0.01000016" />
    </inertial>
    <visual>
      <origin xyz="0 0 0" rpy="0 0 0" />
      <geometry>
        <mesh filename="package://kuavo_assets/models/biped_s41/meshes/r_leg_pitch.STL" />
      </geometry>
      <material name="">
        <color rgba="1 1 1 1" />
      </material>
    </visual>
  </link>
  <joint name="leg_r3_joint" type="revolute">
    <origin xyz="-4.88006581312577E-05 0 -0.1287" rpy="0 0 0" />
    <parent link="leg_r2_link" />
    <child link="leg_r3_link" />
    <axis xyz="0 1 0" />
    <limit lower="-2.00712863979348" upper="1.5707963267949" effort="100.0" velocity="41.3433333333333" />
    <dynamics damping="0.2" friction="0.0"/>
  </joint>
  <link name="leg_r4_link">
    <inertial>
      <origin xyz="0.00743231 -5.343e-05 -0.11558701" rpy="0 0 0" />
      <mass value="1.62655699" />
      <inertia ixx="0.01241258" ixy="2.28e-06" ixz="6.289e-05" iyy="0.0122692" iyz="2.902e-05" izz="0.00097927" />
    </inertial>
    <visual>
      <origin xyz="0 0 0" rpy="0 0 0" />
      <geometry>
        <mesh filename="package://kuavo_assets/models/biped_s41/meshes/r_knee.STL" />
      </geometry>
      <material name="">
        <color rgba="1 1 1 1" />
      </material>
    </visual>
  </link>
  <joint name="leg_r4_joint" type="revolute">
    <origin xyz="0.000147138572785148 0 -0.283999982974744" rpy="0 0 0" />
    <parent link="leg_r3_link" />
    <child link="leg_r4_link" />
    <axis xyz="0 1 0" />
    <limit lower="0.0" upper="2.53072741539178" effort="180.0" velocity="23.55" />
    <dynamics damping="0.2" friction="0.0"/>
  </joint>
  <link name="leg_r5_link">
    <inertial>
      <origin xyz="0.0 0.0 0.0" rpy="0 0 0" />
      <mass value="0.07193524" />
      <inertia ixx="6.92e-04" ixy="0.0" ixz="0.0" iyy="6.92e-04" iyz="0.0" izz="1.218e-04" />
    </inertial>
    <visual>
      <origin xyz="0 0 0" rpy="0 0 0" />
      <geometry>
        <mesh filename="package://kuavo_assets/models/biped_s41/meshes/r_foot_pitch.STL" />
      </geometry>
      <material name="">
        <color rgba="1 1 1 1" />
      </material>
    </visual>
  </link>
  <joint name="leg_r5_joint" type="revolute">
    <origin xyz="0.000119806050928577 0 -0.345999979257963" rpy="0 0 0" />
    <parent link="leg_r4_link" />
    <child link="leg_r5_link" />
    <axis xyz="0 1 0" />
    <limit lower="-0.872664625997165" upper="0.349065850398866" effort="36.0" velocity="23.0266666666667" />
    <dynamics damping="0.2" friction="0.0"/>
  </joint>
  <link name="leg_r6_link">
    <inertial>
      <origin xyz="0.03734098 -2.22e-06 -0.03882684" rpy="0 0 0" />
      <mass value="0.49861272" />
      <inertia ixx="0.00039238" ixy="3e-08" ixz="4.618e-05" iyy="0.00158655" iyz="0.0" izz="0.00172579" />
    </inertial>
    <visual>
      <origin xyz="0 0 0" rpy="0 0 0" />
      <geometry>
        <mesh filename="package://kuavo_assets/models/biped_s41/meshes/r_foot_roll.STL" />
      </geometry>
      <material name="">
        <color rgba="1 1 1 1" />
      </material>
    </visual>
  </link>
  <joint name="leg_r6_joint" type="revolute">
    <origin xyz="0 0 0" rpy="0 0 0" />
    <parent link="leg_r5_link" />
    <child link="leg_r6_link" />
    <axis xyz="1 0 0" />
    <limit lower="-0.261799387799149" upper="0.261799387799149" effort="36.0" velocity="23.0266666666667" />
    <dynamics damping="0.2" friction="0.0"/>
  </joint>
  <link name="rl_foot_toe">
    <collision>
      <origin rpy="0 0 0" xyz="0 0 0" />
      <geometry>
        <sphere radius="0.005" />
      </geometry>
    </collision>
  </link>
  <joint name="rl_foot_toe_joint" type="fixed">
    <origin xyz="0.17084 0.04773 -0.0595" rpy="0 0 0" />
    <parent link="leg_r6_link" />
    <child link="rl_foot_toe" />
    <dynamics damping="0.2" friction="0.0"/>
  </joint>
  <link name="rl_foot_heel">
    <collision>
      <origin rpy="0 0 0" xyz="0 0 0" />
      <geometry>
        <sphere radius="0.005" />
      </geometry>
    </collision>
  </link>
  <joint name="rl_foot_heel_joint" type="fixed">
    <origin xyz="-0.073164 0.04773 -0.0595" rpy="0 0 0" />
    <parent link="leg_r6_link" />
    <child link="rl_foot_heel" />
    <dynamics damping="0.2" friction="0.0"/>
  </joint>
  <link name="rr_foot_toe">
    <collision>
      <origin rpy="0 0 0" xyz="0 0 0" />
      <geometry>
        <sphere radius="0.005" />
      </geometry>
    </collision>
  </link>
  <joint name="rr_foot_toe_joint" type="fixed">
    <origin xyz="0.17084 -0.04773 -0.0595" rpy="0 0 0" />
    <parent link="leg_r6_link" />
    <child link="rr_foot_toe" />
    <dynamics damping="0.2" friction="0.0"/>
  </joint>
  <link name="rr_foot_heel">
    <collision>
      <origin rpy="0 0 0" xyz="0 0 0" />
      <geometry>
        <sphere radius="0.005" />
      </geometry>
    </collision>
  </link>
  <joint name="rr_foot_heel_joint" type="fixed">
    <origin xyz="-0.073164 -0.04773 -0.0595" rpy="0 0 0" />
    <parent link="leg_r6_link" />
    <child link="rr_foot_heel" />
    <dynamics damping="0.2" friction="0.0"/>
  </joint>
  <link name="r_foot_toe">
    <collision>
      <origin rpy="0 0 0" xyz="0 0 0" />
      <geometry>
        <sphere radius="0.005" />
      </geometry>
    </collision>
  </link>
  <joint name="r_foot_toe_joint" type="fixed">
    <origin xyz="0.17084 0.0 -0.0595" rpy="0 0 0" />
    <parent link="leg_r6_link" />
    <child link="r_foot_toe" />
    <dynamics damping="0.2" friction="0.0"/>
  </joint>
  <link name="r_foot_heel">
    <collision>
      <origin rpy="0 0 0" xyz="0 0 0" />
      <geometry>
        <sphere radius="0.005" />
      </geometry>
    </collision>
  </link>
  <joint name="r_foot_heel_joint" type="fixed">
    <origin xyz="-0.073164 0.0 -0.0595" rpy="0 0 0" />
    <parent link="leg_r6_link" />
    <child link="r_foot_heel" />
    <dynamics damping="0.2" friction="0.0"/>
  </joint>
  <link name="zarm_l1_link">
    <inertial>
      <origin xyz="0.008 -0.00158 0.0036" rpy="0 0 0" />
      <mass value="1.15" />
      <inertia ixx="0.0006" ixy="5e-05" ixz="1e-05" iyy="0.00048" iyz="-6e-05" izz="0.0007" />
    </inertial>
    <visual>
      <origin xyz="0 0 0" rpy="0 0 0" />
      <geometry>
        <mesh filename="package://kuavo_assets/models/biped_s41/meshes/l_arm_pitch.STL" />
      </geometry>
      <material name="">
        <color rgba="1 1 1 1" />
      </material>
    </visual>
  </link>
  <joint name="zarm_l1_joint" type="revolute">
    <origin xyz="-0.0175 0.25886 0.3245" rpy="0 0 0" />
    <parent link="base_link" />
    <child link="zarm_l1_link" />
    <axis xyz="0 1 0" />
    <limit lower="-2.61799387799149" upper="0.523598775598299" effort="100.0" velocity="41.3433333333333" />
    <dynamics damping="0.2" friction="0.0"/>
  </joint>
  <link name="zarm_l2_link">
    <inertial>
      <origin xyz="0.00144 0.02159 -0.0202" rpy="0 0 0" />
      <mass value="0.226" />
      <inertia ixx="0.0003" ixy="3e-05" ixz="1e-05" iyy="0.00061" iyz="5e-05" izz="0.00057" />
    </inertial>
    <visual>
      <origin xyz="0 0 0" rpy="0 0 0" />
      <geometry>
        <mesh filename="package://kuavo_assets/models/biped_s41/meshes/l_arm_roll.STL" />
      </geometry>
      <material name="">
        <color rgba="1 1 1 1" />
      </material>
    </visual>
  </link>
  <joint name="zarm_l2_joint" type="revolute">
    <origin xyz="0 0 0" rpy="0 0 0" />
    <parent link="zarm_l1_link" />
    <child link="zarm_l2_link" />
    <axis xyz="1 0 0" />
    <limit lower="-0.349065850398866" upper="2.0943951023932" effort="50.0" velocity="19.154" />
    <dynamics damping="0.2" friction="0.0"/>
  </joint>
  <link name="zarm_l3_link">
    <inertial>
      <origin xyz="-0.00157 -3e-05 -0.13318" rpy="0 0 0" />
      <mass value="1.166" />
      <inertia ixx="0.00245" ixy="-1e-05" ixz="-1e-05" iyy="0.0022" iyz="0.0" izz="0.00112" />
    </inertial>
    <visual>
      <origin xyz="0 0 0" rpy="0 0 0" />
      <geometry>
        <mesh filename="package://kuavo_assets/models/biped_s41/meshes/l_arm_yaw.STL" />
      </geometry>
      <material name="">
        <color rgba="1 1 1 1" />
      </material>
    </visual>
  </link>
  <joint name="zarm_l3_joint" type="revolute">
    <origin xyz="0 0 0" rpy="0 0 0" />
    <parent link="zarm_l2_link" />
    <child link="zarm_l3_link" />
    <axis xyz="0 0 1" />
    <limit lower="-1.5707963267949" upper="1.5707963267949" effort="20.0" velocity="18.84" />
    <dynamics damping="0.2" friction="0.0"/>
  </joint>
  <link name="zarm_l4_link">
    <inertial>
      <origin xyz="-4e-05 0.0098 -0.05283" rpy="0 0 0" />
      <mass value="0.575" />
      <inertia ixx="0.00098" ixy="0.0" ixz="0.0" iyy="0.00062" iyz="-0.00016" izz="0.00088" />
    </inertial>
    <visual>
      <origin xyz="0 0 0" rpy="0 0 0" />
      <geometry>
        <mesh filename="package://kuavo_assets/models/biped_s41/meshes/l_forearm.STL" />
      </geometry>
      <material name="">
        <color rgba="1 1 1 1" />
      </material>
    </visual>
  </link>
  <joint name="zarm_l4_joint" type="revolute">
    <origin xyz="0 0 -0.1646" rpy="0 0 0" />
    <parent link="zarm_l3_link" />
    <child link="zarm_l4_link" />
    <axis xyz="0 1 0" />
    <limit lower="-1.5707963267949" upper="0.0" effort="20.0" velocity="18.84" />
    <dynamics damping="0.2" friction="0.0"/>
  </joint>
  <link name="zarm_l5_link">
    <inertial>
      <origin xyz="-0.00011 0.00421 -0.11168" rpy="0 0 0" />
      <mass value="0.46" />
      <inertia ixx="0.00077" ixy="0.0" ixz="0.0" iyy="0.0005" iyz="-4e-05" izz="0.00063" />
    </inertial>
    <visual>
      <origin xyz="0 0 0" rpy="0 0 0" />
      <geometry>
        <mesh filename="package://kuavo_assets/models/biped_s41/meshes/l_hand_yaw.STL" />
      </geometry>
      <material name="">
        <color rgba="1 1 1 1" />
      </material>
    </visual>
  </link>
  <joint name="zarm_l5_joint" type="revolute">
    <origin xyz="0 0 0" rpy="0 0 0" />
    <parent link="zarm_l4_link" />
    <child link="zarm_l5_link" />
    <axis xyz="0 0 1" />
    <limit lower="-1.5707963267949" upper="1.5707963267949" effort="6.0" velocity="21.666" />
    <dynamics damping="0.2" friction="0.0"/>
  </joint>
  <link name="zarm_l6_link">
    <inertial>
      <origin xyz="0.00253 0.00382 -0.05356" rpy="0 0 0" />
      <mass value="0.35" />
      <inertia ixx="0.00023" ixy="0.0" ixz="0.0" iyy="0.00024" iyz="-4e-05" izz="0.00019" />
    </inertial>
    <visual>
      <origin xyz="0 0 0" rpy="0 0 0" />
      <geometry>
        <mesh filename="package://kuavo_assets/models/biped_s41/meshes/l_hand_pitch.STL" />
      </geometry>
      <material name="">
        <color rgba="1 1 1 1" />
      </material>
    </visual>
  </link>
  <joint name="zarm_l6_joint" type="revolute">
    <origin xyz="0 0 -0.132050000125748" rpy="0 0 0" />
    <parent link="zarm_l5_link" />
    <child link="zarm_l6_link" />
    <axis xyz="0 1 0" />
    <limit lower="-1.5707963267949" upper="1.5707963267949" effort="6.0" velocity="21.666" />
    <dynamics damping="0.2" friction="0.0"/>
  </joint>
  <link name="zarm_l7_link">
    <inertial>
      <origin xyz="0.00267 0.00748 -0.07162" rpy="0 0 0" />
      <mass value="0.81" />
      <inertia ixx="0.00117" ixy="2e-05" ixz="0.0" iyy="0.00128" iyz="-2e-05" izz="0.00036" />
    </inertial>
    <visual>
      <origin xyz="0 0 0" rpy="0 0 0" />
      <geometry>
        <mesh filename="package://kuavo_assets/models/biped_s41/meshes/l_hand_roll.STL" />
      </geometry>
      <material name="">
        <color rgba="1 1 1 1" />
      </material>
    </visual>
  </link>
  <joint name="zarm_l7_joint" type="revolute">
    <origin xyz="0 0 -0.0589999999999999" rpy="0 0 0" />
    <parent link="zarm_l6_link" />
    <child link="zarm_l7_link" />
    <axis xyz="1 0 0" />
    <limit lower="-1.5707963267949" upper="1.5707963267949" effort="6.0" velocity="21.666" />
    <dynamics damping="0.2" friction="0.0"/>
  </joint>
  <link name="zarm_l7_end_effector">
    <collision>
      <origin rpy="0 0 0" xyz="0 0 0" />
      <geometry>
        <sphere radius="0.005" />
      </geometry>
    </collision>
  </link>
  <joint name="zarm_l7_end_effector_joint" type="fixed">
    <origin xyz="0 -0.03 -0.17" rpy="0 0 0" />
    <parent link="zarm_l7_link" />
    <child link="zarm_l7_end_effector" />
    <dynamics damping="0.2" friction="0.0"/>
  </joint>
  <link name="zarm_r1_link">
    <inertial>
      <origin xyz="0.008 0.00158 -0.0036" rpy="0 0 0" />
      <mass value="1.15" />
      <inertia ixx="0.0006" ixy="-5e-05" ixz="-1e-05" iyy="0.00048" iyz="-6e-05" izz="0.0007" />
    </inertial>
    <visual>
      <origin xyz="0 0 0" rpy="0 0 0" />
      <geometry>
        <mesh filename="package://kuavo_assets/models/biped_s41/meshes/r_arm_pitch.STL" />
      </geometry>
      <material name="">
        <color rgba="1 1 1 1" />
      </material>
    </visual>
  </link>
  <joint name="zarm_r1_joint" type="revolute">
    <origin xyz="-0.0175 -0.25886 0.3245" rpy="0 0 0" />
    <parent link="base_link" />
    <child link="zarm_r1_link" />
    <axis xyz="0 1 0" />
    <limit lower="-2.61799387799149" upper="0.523598775598299" effort="100.0" velocity="41.3433333333333" />
    <dynamics damping="0.2" friction="0.0"/>
  </joint>
  <link name="zarm_r2_link">
    <inertial>
      <origin xyz="0.00144 -0.02159 -0.02021" rpy="0 0 0" />
      <mass value="0.226" />
      <inertia ixx="0.0003" ixy="-3e-05" ixz="1e-05" iyy="0.00061" iyz="-5e-05" izz="0.00057" />
    </inertial>
    <visual>
      <origin xyz="0 0 0" rpy="0 0 0" />
      <geometry>
        <mesh filename="package://kuavo_assets/models/biped_s41/meshes/r_arm_roll.STL" />
      </geometry>
      <material name="">
        <color rgba="1 1 1 1" />
      </material>
    </visual>
  </link>
  <joint name="zarm_r2_joint" type="revolute">
    <origin xyz="0 0 0" rpy="0 0 0" />
    <parent link="zarm_r1_link" />
    <child link="zarm_r2_link" />
    <axis xyz="1 0 0" />
    <limit lower="-2.0943951023932" upper="0.349065850398866" effort="50.0" velocity="19.154" />
    <dynamics damping="0.2" friction="0.0"/>
  </joint>
  <link name="zarm_r3_link">
    <inertial>
      <origin xyz="-0.00157 3e-05 -0.13318" rpy="0 0 0" />
      <mass value="1.166" />
      <inertia ixx="0.00245" ixy="1e-05" ixz="-1e-05" iyy="0.0022" iyz="0.0" izz="0.00112" />
    </inertial>
    <visual>
      <origin xyz="0 0 0" rpy="0 0 0" />
      <geometry>
        <mesh filename="package://kuavo_assets/models/biped_s41/meshes/r_arm_yaw.STL" />
      </geometry>
      <material name="">
        <color rgba="1 1 1 1" />
      </material>
    </visual>
  </link>
  <joint name="zarm_r3_joint" type="revolute">
    <origin xyz="0 0 0" rpy="0 0 0" />
    <parent link="zarm_r2_link" />
    <child link="zarm_r3_link" />
    <axis xyz="0 0 1" />
    <limit lower="-1.5707963267949" upper="1.5707963267949" effort="20.0" velocity="18.84" />
    <dynamics damping="0.2" friction="0.0"/>
  </joint>
  <link name="zarm_r4_link">
    <inertial>
      <origin xyz="-4e-05 -0.0098 -0.05283" rpy="0 0 0" />
      <mass value="0.575" />
      <inertia ixx="0.00098" ixy="0.0" ixz="0.0" iyy="0.00062" iyz="0.00016" izz="0.00088" />
    </inertial>
    <visual>
      <origin xyz="0 0 0" rpy="0 0 0" />
      <geometry>
        <mesh filename="package://kuavo_assets/models/biped_s41/meshes/r_forearm.STL" />
      </geometry>
      <material name="">
        <color rgba="1 1 1 1" />
      </material>
    </visual>
  </link>
  <joint name="zarm_r4_joint" type="revolute">
    <origin xyz="0 0 -0.1646" rpy="0 0 0" />
    <parent link="zarm_r3_link" />
    <child link="zarm_r4_link" />
    <axis xyz="0 1 0" />
    <limit lower="-1.5707963267949" upper="0.0" effort="20.0" velocity="18.84" />
    <dynamics damping="0.2" friction="0.0"/>
  </joint>
  <link name="zarm_r5_link">
    <inertial>
      <origin xyz="-0.00011 -0.00421 -0.11168" rpy="0 0 0" />
      <mass value="0.46" />
      <inertia ixx="0.00077" ixy="0.0" ixz="0.0" iyy="0.0005" iyz="4e-05" izz="0.00063" />
    </inertial>
    <visual>
      <origin xyz="0 0 0" rpy="0 0 0" />
      <geometry>
        <mesh filename="package://kuavo_assets/models/biped_s41/meshes/r_hand_yaw.STL" />
      </geometry>
      <material name="">
        <color rgba="1 1 1 1" />
      </material>
    </visual>
  </link>
  <joint name="zarm_r5_joint" type="revolute">
    <origin xyz="0 0 0" rpy="0 0 0" />
    <parent link="zarm_r4_link" />
    <child link="zarm_r5_link" />
    <axis xyz="0 0 1" />
    <limit lower="-1.5707963267949" upper="1.5707963267949" effort="6.0" velocity="21.666" />
    <dynamics damping="0.2" friction="0.0"/>
  </joint>
  <link name="zarm_r6_link">
    <inertial>
      <origin xyz="0.00253 -0.00382 -0.05356" rpy="0 0 0" />
      <mass value="0.35" />
      <inertia ixx="0.00023" ixy="0.0" ixz="0.0" iyy="0.00024" iyz="4e-05" izz="0.00019" />
    </inertial>
    <visual>
      <origin xyz="0 0 0" rpy="0 0 0" />
      <geometry>
        <mesh filename="package://kuavo_assets/models/biped_s41/meshes/r_hand_pitch.STL" />
      </geometry>
      <material name="">
        <color rgba="1 1 1 1" />
      </material>
    </visual>
  </link>
  <joint name="zarm_r6_joint" type="revolute">
    <origin xyz="0 0 -0.132050000240097" rpy="0 0 0" />
    <parent link="zarm_r5_link" />
    <child link="zarm_r6_link" />
    <axis xyz="0 1 0" />
    <limit lower="-1.5707963267949" upper="1.5707963267949" effort="6.0" velocity="21.666" />
    <dynamics damping="0.2" friction="0.0"/>
  </joint>
  <link name="zarm_r7_link">
    <inertial>
      <origin xyz="0.00267 -0.00748 -0.07162" rpy="0 0 0" />
      <mass value="0.81" />
      <inertia ixx="0.00098" ixy="-1e-05" ixz="1e-05" iyy="0.00104" iyz="1e-05" izz="0.00027" />
    </inertial>
    <visual>
      <origin xyz="0 0 0" rpy="0 0 0" />
      <geometry>
        <mesh filename="package://kuavo_assets/models/biped_s41/meshes/r_hand_roll.STL" />
      </geometry>
      <material name="">
        <color rgba="1 1 1 1" />
      </material>
    </visual>
  </link>
  <joint name="zarm_r7_joint" type="revolute">
    <origin xyz="0 0 -0.0589999999999999" rpy="0 0 0" />
    <parent link="zarm_r6_link" />
    <child link="zarm_r7_link" />
    <axis xyz="1 0 0" />
    <limit lower="-1.5707963267949" upper="1.5707963267949" effort="6.0" velocity="21.666" />
    <dynamics damping="0.2" friction="0.0"/>
  </joint>
  <link name="zarm_r7_end_effector">
    <collision>
      <origin rpy="0 0 0" xyz="0 0 0" />
      <geometry>
        <sphere radius="0.005" />
      </geometry>
    </collision>
  </link>
  <joint name="zarm_r7_end_effector_joint" type="fixed">
    <origin xyz="0 0.03 -0.17" rpy="0 0 0" />
    <parent link="zarm_r7_link" />
    <child link="zarm_r7_end_effector" />
    <dynamics damping="0.2" friction="0.0"/>
  </joint>
  <link name="zhead_1_link">
    <inertial>
      <origin xyz="0.0 0.01245 -0.02982" rpy="0 0 0" />
      <mass value="0.082" />
      <inertia ixx="7e-05" ixy="0.0" ixz="0.0" iyy="6e-05" iyz="-2e-05" izz="8e-05" />
    </inertial>
    <visual>
      <origin xyz="0 0 0" rpy="0 0 0" />
      <geometry>
        <mesh
          filename="package://kuavo_assets/models/biped_s41/meshes/head_yaw.STL" />
      </geometry>
      <material name="">
        <color rgba="1 1 1 1" />
      </material>
    </visual>
  </link>
  <joint name="zhead_1_joint" type="revolute">
    <origin xyz="-0.0175 0.0 0.5014" rpy="0 0 0" />
    <parent link="base_link" />
    <child link="zhead_1_link" />
    <axis xyz="0 0 1" />
    <limit lower="-1.5707963267949" upper="1.5707963267949" effort="1.5" velocity="5.23333333333333" />
    <dynamics damping="0.2" friction="0.0"/>
  </joint>
  <link name="zhead_2_link">
    <inertial>
      <origin xyz="0.01106 0.00069 0.0586" rpy="0 0 0" />
      <mass value="1.379" />
      <inertia ixx="0.003" ixy="1e-05" ixz="0.0003" iyy="0.00301" iyz="5e-05" izz="0.00281" />
    </inertial>
    <visual>
      <origin xyz="0 0 0" rpy="0 0 0" />
      <geometry>
        <mesh filename="package://kuavo_assets/models/biped_s41/meshes/head_pitch.STL" />
      </geometry>
      <material name="">
        <color rgba="1 1 1 1" />
      </material>
    </visual>
  </link>
  <joint name="zhead_2_joint" type="revolute">
    <origin xyz="0 0 0" rpy="0 0 0" />
    <parent link="zhead_1_link" />
    <child link="zhead_2_link" />
    <axis xyz="0 1 0" />
    <limit lower="-0.523598775598299" upper="0.523598775598299" effort="6.0" velocity="9.734" />
    <dynamics damping="0.2" friction="0.0"/>
  </joint>
  <link name="camera">
    <inertial>
      <origin xyz="-0.04336 -0.01736 -0.01161" rpy="0 0 0" />
      <mass value="0.047" />
      <inertia ixx="0.00065" ixy="0.0" ixz="0.00015" iyy="0.00091" iyz="0.0" izz="0.00105" />
    </inertial>
    <visual>
      <origin xyz="0 0 0" rpy="0 0 0" />
      <geometry>
        <mesh filename="package://kuavo_assets/models/biped_s41/meshes/camera.STL" />
      </geometry>
      <material name="">
        <color rgba="1 1 1 1" />
      </material>
    </visual>
  </link>
  <joint name="camera" type="fixed">
    <origin xyz="0.0919101155958193 0.0175000000022731 0.0617838754768194" rpy="0 0.610865238198013 0" />
    <parent link="zhead_2_link" />
    <child link="camera" />
    <dynamics damping="0.2" friction="0.0"/>
  </joint>

  <link
    name="camera_base">
    <inertial>
      <origin
        xyz="0.00354055612698423 0.00140393663616134 0.0124511788327371"
        rpy="0 0 0" />
      <mass
        value="0.0170255961584929" />
      <inertia
        ixx="1.09182620877589E-05"
        ixy="1.05354237503678E-07"
        ixz="1.05871360812799E-08"
        iyy="8.57178923448405E-07"
        iyz="1.6401848102306E-08"
        izz="1.02869873531782E-05" />
    </inertial>
    <visual>
      <origin
        xyz="0 0 0"
        rpy="0 0 0" />
      <geometry>
        <mesh
          filename="package://kuavo_assets/models/biped_s41/meshes/camera_base.STL" />
      </geometry>
      <material
        name="">
        <color
          rgba="1 1 1 1" />
      </material>
    </visual>
    <collision>
      <origin
        xyz="0 0 0"
        rpy="0 0 0" />
      <geometry>
        <mesh
          filename="package://kuavo_assets/models/biped_s41/meshes/camera_base.STL" />
      </geometry>
    </collision>
  </link>
  <joint
    name="camera_base"
    type="fixed">
    <origin
      xyz="0.0766792844154498 0 0.0571889355165869"
      rpy="0 0.610865238198013 0" />
    <parent
      link="zhead_2_link" />
    <child
      link="camera_base" />
  </joint>

  <!-- 在原有的gazebo插件配置后添加 -->
  <!-- 真值 -->
  <gazebo>
    <plugin filename="libgazebo_ros_p3d.so" name="p3d_base_controller">
      <alwaysOn>true</alwaysOn>
      <updateRate>500.0</updateRate>
      <bodyName>dummy_link</bodyName>
      <topicName>ground_truth/state</topicName>
      <gaussianNoise>0</gaussianNoise>
      <frameName>world</frameName>
      <xyzOffsets>0 0 0</xyzOffsets>
      <rpyOffsets>0 0 0</rpyOffsets>
    </plugin>
  </gazebo>

  <!-- 左脚 -->
  <gazebo reference="leg_l6_link">
    <mu1>1.5</mu1>
    <mu2>2.5</mu2>
    <self_collide>1</self_collide>
    <kp value="1000000.0"/>
    <kd value="100.0"/>
    <maxVel>3</maxVel>
    <minDepth>0.00</minDepth>
  </gazebo>
  <gazebo reference="l_foot_heel">
    <mu1>1.5</mu1>
    <mu2>2.5</mu2>
    <self_collide>1</self_collide>
    <kp value="1000000.0"/>
    <kd value="100.0"/>
    <maxVel>3</maxVel>
    <minDepth>0.00</minDepth>
  </gazebo>
  <gazebo reference="l_foot_toe">
    <mu1>1.5</mu1>
    <mu2>2.5</mu2>
    <self_collide>1</self_collide>
    <kp value="1000000.0"/>
    <kd value="100.0"/>
    <maxVel>3</maxVel>
    <minDepth>0.00</minDepth>
  </gazebo>
  <gazebo reference="lr_foot_heel">
    <mu1>1.5</mu1>
    <mu2>2.5</mu2>
    <self_collide>1</self_collide>
    <kp value="1000000.0"/>
    <kd value="100.0"/>
    <maxVel>3</maxVel>
    <minDepth>0.00</minDepth>
  </gazebo>
  <gazebo reference="lr_foot_toe">
    <mu1>1.5</mu1>
    <mu2>2.5</mu2>
    <self_collide>1</self_collide>
    <kp value="1000000.0"/>
    <kd value="100.0"/>
    <maxVel>3</maxVel>
    <minDepth>0.00</minDepth>
  </gazebo>
  <gazebo reference="ll_foot_heel">
    <mu1>1.5</mu1>
    <mu2>2.5</mu2>
    <self_collide>1</self_collide>
    <kp value="1000000.0"/>
    <kd value="100.0"/>
    <maxVel>3</maxVel>
    <minDepth>0.00</minDepth>
  </gazebo>
  <gazebo reference="ll_foot_toe">
    <mu1>1.5</mu1>
    <mu2>2.5</mu2>
    <self_collide>1</self_collide>
    <kp value="1000000.0"/>
    <kd value="100.0"/>
    <maxVel>3</maxVel>
    <minDepth>0.00</minDepth>
  </gazebo>

  <!-- 右脚 -->
  <gazebo reference="leg_r6_link">
    <mu1>1.5</mu1>
    <mu2>2.5</mu2>
    <self_collide>1</self_collide>
    <kp value="1000000.0"/>
    <kd value="100.0"/>
    <maxVel>3</maxVel>
    <minDepth>0.00</minDepth>
  </gazebo>
  <gazebo reference="r_foot_heel">
    <mu1>1.5</mu1>
    <mu2>2.5</mu2>
    <self_collide>1</self_collide>
    <kp value="1000000.0"/>
    <kd value="100.0"/>
    <maxVel>3</maxVel>
    <minDepth>0.00</minDepth>
  </gazebo>
  <gazebo reference="r_foot_toe">
    <mu1>1.5</mu1>
    <mu2>2.5</mu2>
    <self_collide>1</self_collide>
    <kp value="1000000.0"/>
    <kd value="100.0"/>
    <maxVel>3</maxVel>
    <minDepth>0.00</minDepth>
  </gazebo>
  <gazebo reference="rl_foot_toe">
    <mu1>1.5</mu1>
    <mu2>2.5</mu2>
    <self_collide>1</self_collide>
    <kp value="1000000.0"/>
    <kd value="100.0"/>
    <maxVel>3</maxVel>
    <minDepth>0.00</minDepth>
  </gazebo>
  <gazebo reference="rl_foot_heel">
    <mu1>1.5</mu1>
    <mu2>2.5</mu2>
    <self_collide>1</self_collide>
    <kp value="1000000.0"/>
    <kd value="100.0"/>
    <maxVel>3</maxVel>
    <minDepth>0.00</minDepth>
  </gazebo>
  <gazebo reference="rr_foot_toe">
    <mu1>1.5</mu1>
    <mu2>2.5</mu2>
    <self_collide>1</self_collide>
    <kp value="1000000.0"/>
    <kd value="100.0"/>
    <maxVel>3</maxVel>
    <minDepth>0.00</minDepth>
  </gazebo>
  <gazebo reference="rr_foot_heel">
    <mu1>1.5</mu1>
    <mu2>2.5</mu2>
    <self_collide>1</self_collide>
    <kp value="1000000.0"/>
    <kd value="100.0"/>
    <maxVel>3</maxVel>
    <minDepth>0.00</minDepth>
  </gazebo>

  <!-- 仿真插件 -->
  <gazebo>
    <plugin name="gazebo_shm_interface" filename="libgazebo_sim_shm_interface.so">
      <!-- IMU配置 gazebo中fixed连接的link都只能获取第一个-->
      <imu>
        <frame_id>dummy_link</frame_id>
      </imu>
      
      <!-- 关节配置 -->
      <joints>
        <!-- 左腿关节 -->
        <joint><name>leg_l1_joint</name></joint>
        <joint><name>leg_l2_joint</name></joint>
        <joint><name>leg_l3_joint</name></joint>
        <joint><name>leg_l4_joint</name></joint>
        <joint><name>leg_l5_joint</name></joint>
        <joint><name>leg_l6_joint</name></joint>
        
        <!-- 右腿关节 -->
        <joint><name>leg_r1_joint</name></joint>
        <joint><name>leg_r2_joint</name></joint>
        <joint><name>leg_r3_joint</name></joint>
        <joint><name>leg_r4_joint</name></joint>
        <joint><name>leg_r5_joint</name></joint>
        <joint><name>leg_r6_joint</name></joint>
        
        <!-- 左臂关节 -->
        <joint><name>zarm_l1_joint</name></joint>
        <joint><name>zarm_l2_joint</name></joint>
        <joint><name>zarm_l3_joint</name></joint>
        <joint><name>zarm_l4_joint</name></joint>
        <joint><name>zarm_l5_joint</name></joint>
        <joint><name>zarm_l6_joint</name></joint>
        <joint><name>zarm_l7_joint</name></joint>
        
        <!-- 右臂关节 -->
        <joint><name>zarm_r1_joint</name></joint>
        <joint><name>zarm_r2_joint</name></joint>
        <joint><name>zarm_r3_joint</name></joint>
        <joint><name>zarm_r4_joint</name></joint>
        <joint><name>zarm_r5_joint</name></joint>
        <joint><name>zarm_r6_joint</name></joint>
        <joint><name>zarm_r7_joint</name></joint>
        
        <!-- 头部关节 -->
        <joint><name>zhead_1_joint</name></joint>
        <joint><name>zhead_2_joint</name></joint>
      </joints>
      
      <!-- 接触传感器配置 -->
      <contacts>
        <contact><link>ll_foot_toe</link></contact>
        <contact><link>ll_foot_heel</link></contact>
        <contact><link>lr_foot_toe</link></contact>
        <contact><link>lr_foot_heel</link></contact>
        <contact><link>rl_foot_toe</link></contact>
        <contact><link>rl_foot_heel</link></contact>
        <contact><link>rr_foot_toe</link></contact>
        <contact><link>rr_foot_heel</link></contact>
      </contacts>
      </plugin>
  </gazebo>
  
</robot>
