<?xml version='1.0' encoding='utf-8'?>
<mujoco model="biped_s46">
  <compiler angle="radian" meshdir="../meshes/" />
  <size njmax="500" nconmax="100" />
  <asset>
    <mesh name="torso" file="torso.STL" />
    <mesh name="l_leg_roll" file="l_leg_roll.STL" />
    <mesh name="l_leg_yaw" file="l_leg_yaw.STL" />
    <mesh name="l_leg_pitch" file="l_leg_pitch.STL" />
    <mesh name="l_knee" file="l_knee.STL" />
    <mesh name="l_foot_pitch" file="l_foot_pitch.STL" />
    <mesh name="l_foot_roll" file="l_foot_roll.STL" />
    <mesh name="r_leg_roll" file="r_leg_roll.STL" />
    <mesh name="r_leg_yaw" file="r_leg_yaw.STL" />
    <mesh name="r_leg_pitch" file="r_leg_pitch.STL" />
    <mesh name="r_knee" file="r_knee.STL" />
    <mesh name="r_foot_pitch" file="r_foot_pitch.STL" />
    <mesh name="r_foot_roll" file="r_foot_roll.STL" />
    <mesh name="l_arm_pitch" file="l_arm_pitch.STL" />
    <mesh name="l_arm_roll" file="l_arm_roll.STL" />
    <mesh name="l_arm_yaw" file="l_arm_yaw.STL" />
    <mesh name="l_forearm" file="l_forearm.STL" />
    <mesh name="l_hand_yaw" file="l_hand_yaw.STL" />
    <mesh name="l_hand_roll" file="l_hand_roll.STL" />
    <mesh name="l_hand_pitch" file="l_hand_pitch.STL" />
    <mesh name="r_arm_pitch" file="r_arm_pitch.STL" />
    <mesh name="r_arm_roll" file="r_arm_roll.STL" />
    <mesh name="r_arm_yaw" file="r_arm_yaw.STL" />
    <mesh name="r_forearm" file="r_forearm.STL" />
    <mesh name="r_hand_yaw" file="r_hand_yaw.STL" />
    <mesh name="r_hand_roll" file="r_hand_roll.STL" />
    <mesh name="r_hand_pitch" file="r_hand_pitch.STL" />
    <mesh name="head_yaw" file="head_yaw.STL" />
    <mesh name="head_pitch" file="head_pitch.STL" />
    <mesh name="head_camera" file="head_camera.STL" />
  </asset>
  <worldbody>
    <body name="base_link" pos="0 0 0.82">
      <freejoint />
      <site name="imu" pos="0 0 0" />
      <inertial pos="-0.00761 0.00182 0.21995" quat="0.998529 4.54328e-05 0.0542216 0.000512508" mass="26.8303" diaginertia="0.938886 0.825905 0.269012" />
      <geom type="mesh" contype="0" conaffinity="0" group="1" density="0" rgba="1 1 1 1" mesh="torso" />
      <body name="leg_l1_link" pos="-0.0024999 0.087 -0.066">
        <inertial pos="-0.00402302 0.00013568 -0.00908713" quat="-0.00566884 0.723807 0.00605909 0.689952" mass="1.75436" diaginertia="0.00377365 0.00281073 0.002133" />
        <joint name="leg_l1_joint" pos="0 0 0" axis="1 0 0" range="-0.314159 0.663225" actuatorfrcrange="-180 180" damping="0.2" />
        <geom type="mesh" contype="0" conaffinity="0" group="1" density="0" rgba="1 1 1 1" mesh="l_leg_roll" />
        <body name="leg_l2_link">
          <inertial pos="-0.00277949 0.00478016 -0.0778348" quat="0.779415 0.625672 -0.0267531 0.0182007" mass="0.651964" diaginertia="0.00252814 0.00192832 0.0013047" />
          <joint name="leg_l2_joint" pos="0 0 0" axis="0 0 1" range="-0.872665 0.785398" actuatorfrcrange="-100 100" damping="0.2" />
          <geom type="mesh" contype="0" conaffinity="0" group="1" density="0" rgba="1 1 1 1" mesh="l_leg_yaw" />
          <body name="leg_l3_link" pos="0 0 -0.1287">
            <inertial pos="0.00106133 0.00970189 -0.082999" quat="0.747795 0.0205056 -0.0433254 0.662197" mass="4.78669" diaginertia="0.0438713 0.0424814 0.0108916" />
            <joint name="leg_l3_joint" pos="0 0 0" axis="0 1 0" range="-2.00713 1.5708" actuatorfrcrange="-100 100" damping="0.2" />
            <geom type="mesh" contype="0" conaffinity="0" group="1" density="0" rgba="1 1 1 1" mesh="l_leg_pitch" />
            <body name="leg_l4_link" pos="0 0 -0.284">
              <inertial pos="0.00811619 -1.521e-05 -0.110503" quat="0.692694 -0.00356377 -0.00077448 0.721222" mass="1.8783" diaginertia="0.0154377 0.0153452 0.00111621" />
              <joint name="leg_l4_joint" pos="0 0 0" axis="0 1 0" range="0 2.53073" actuatorfrcrange="-180 180" damping="0.2" />
              <geom type="mesh" contype="0" conaffinity="0" group="1" density="0" rgba="1 1 1 1" mesh="l_knee" />
              <body name="leg_l5_link" pos="0 0 -0.346">
                <inertial pos="0 0 0" quat="0.5 0.5 -0.5 0.5" mass="0.0719352" diaginertia="1.218e-05 6.92e-06 6.92e-06" />
                <joint name="leg_l5_joint" pos="0 0 0" axis="0 1 0" range="-0.872665 0.349066" actuatorfrcrange="-36 36" damping="0.2" />
                <geom type="mesh" contype="0" conaffinity="0" group="1" density="0" rgba="1 1 1 1" mesh="l_foot_pitch" />
                <body name="leg_l6_link">
                  <inertial pos="0.0286226 1.67708e-05 -0.0388468" quat="2.33986e-05 0.726543 4.17054e-05 0.687121" mass="0.765024" diaginertia="0.00310035 0.00293209 0.000791096" />
                  <joint name="leg_l6_joint" pos="0 0 0" axis="1 0 0" range="-0.261799 0.261799" actuatorfrcrange="-36 36" damping="0.2" />
                  <geom type="mesh" contype="0" conaffinity="0" group="1" density="0" rgba="1 1 1 1" mesh="l_foot_roll" />
                  <geom size="0.005" pos="0.17475 0.05623 -0.0695" />
                  <geom size="0.005" pos="-0.07838 0.05623 -0.0695" />
                  <geom size="0.005" pos="0.17475 -0.05623 -0.0695" />
                  <geom size="0.005" pos="-0.07838 -0.05623 -0.0695" />
                  <geom size="0.005" pos="0.17475 0 -0.0695" />
                  <geom size="0.005" pos="-0.07838 0 -0.0695" />
                </body>
              </body>
            </body>
          </body>
        </body>
      </body>
      <body name="leg_r1_link" pos="-0.0024999 -0.087 -0.066">
        <inertial pos="-0.004023 -0.00013567 -0.00908714" quat="0.00566884 0.723807 -0.00605909 0.689952" mass="1.75436" diaginertia="0.00377365 0.00281073 0.002133" />
        <joint name="leg_r1_joint" pos="0 0 0" axis="1 0 0" range="-0.663225 0.314159" actuatorfrcrange="-180 180" damping="0.2" />
        <geom type="mesh" contype="0" conaffinity="0" group="1" density="0" rgba="1 1 1 1" mesh="r_leg_roll" />
        <body name="leg_r2_link">
          <inertial pos="-0.00277949 -0.00477985 -0.077836" quat="0.625672 0.779415 -0.0182021 0.0267546" mass="0.651944" diaginertia="0.00252807 0.00192829 0.00130467" />
          <joint name="leg_r2_joint" pos="0 0 0" axis="0 0 1" range="-0.785398 0.872665" actuatorfrcrange="-100 100" damping="0.2" />
          <geom type="mesh" contype="0" conaffinity="0" group="1" density="0" rgba="1 1 1 1" mesh="r_leg_yaw" />
          <body name="leg_r3_link" pos="0 0 -0.1287">
            <inertial pos="0.0010631 -0.00970056 -0.0830053" quat="0.662201 -0.0433265 0.0205153 0.747791" mass="4.78628" diaginertia="0.0438668 0.0424769 0.0108912" />
            <joint name="leg_r3_joint" pos="0 0 0" axis="0 1 0" range="-2.00713 1.5708" actuatorfrcrange="-100 100" damping="0.2" />
            <geom type="mesh" contype="0" conaffinity="0" group="1" density="0" rgba="1 1 1 1" mesh="r_leg_pitch" />
            <body name="leg_r4_link" pos="0 0 -0.284">
              <inertial pos="0.00810188 3.554e-05 -0.110376" quat="0.716783 -0.00073364 -0.00348684 0.697287" mass="1.87881" diaginertia="0.0158285 0.0156955 0.00148831" />
              <joint name="leg_r4_joint" pos="0 0 0" axis="0 1 0" range="0 2.53073" actuatorfrcrange="-180 180" damping="0.2" />
              <geom type="mesh" contype="0" conaffinity="0" group="1" density="0" rgba="1 1 1 1" mesh="r_knee" />
              <body name="leg_r5_link" pos="0 0 -0.346">
                <inertial pos="0 0 0" quat="0.5 0.5 -0.5 0.5" mass="0.0719352" diaginertia="1.218e-05 6.92e-06 6.92e-06" />
                <joint name="leg_r5_joint" pos="0 0 0" axis="0 1 0" range="-0.872665 0.349066" actuatorfrcrange="-36 36" damping="0.2" />
                <geom type="mesh" contype="0" conaffinity="0" group="1" density="0" rgba="1 1 1 1" mesh="r_foot_pitch" />
                <body name="leg_r6_link">
                  <inertial pos="0.0286226 1.67708e-05 -0.0388468" quat="2.33986e-05 0.726543 4.17054e-05 0.687121" mass="0.765024" diaginertia="0.00310035 0.00293209 0.000791096" />
                  <joint name="leg_r6_joint" pos="0 0 0" axis="1 0 0" range="-0.261799 0.261799" actuatorfrcrange="-36 36" damping="0.2" />
                  <geom type="mesh" contype="0" conaffinity="0" group="1" density="0" rgba="1 1 1 1" mesh="r_foot_roll" />
                  <geom size="0.005" pos="0.17475 0.05623 -0.0695" />
                  <geom size="0.005" pos="-0.07838 0.05623 -0.0695" />
                  <geom size="0.005" pos="0.17475 -0.05623 -0.0695" />
                  <geom size="0.005" pos="-0.07838 -0.05623 -0.0695" />
                  <geom size="0.005" pos="0.17475 0 -0.0695" />
                  <geom size="0.005" pos="-0.07838 0 -0.0695" />
                </body>
              </body>
            </body>
          </body>
        </body>
      </body>
      <body name="zarm_l1_link" pos="-0.0174999 0.2927 0.445">
        <inertial pos="-0.00083 -0.02218 0.00035" quat="0.507855 0.504005 -0.503768 0.484025" mass="0.962" diaginertia="0.00227032 0.0022507 0.000988974" />
        <joint name="zarm_l1_joint" pos="0 0 0" axis="0 1 0" range="-3.14159 1.5708" actuatorfrcrange="-100 100" damping="0.2" />
        <geom type="mesh" contype="0" conaffinity="0" group="1" density="0" rgba="1 1 1 1" mesh="l_arm_pitch" />
        <body name="zarm_l2_link">
          <inertial pos="-0.00791 0 -0.04655" quat="0.705843 -0.0422654 -0.0422654 0.705843" mass="0.57" diaginertia="0.00211 0.00163601 0.00121399" />
          <joint name="zarm_l2_joint" pos="0 0 0" axis="1 0 0" range="-0.349066 2.0944" actuatorfrcrange="-50 50" damping="0.2" />
          <geom type="mesh" contype="0" conaffinity="0" group="1" density="0" rgba="1 1 1 1" mesh="l_arm_roll" />
          <body name="zarm_l3_link">
            <inertial pos="0.00628 0.00107 -0.20878" quat="0.46857 -0.0547044 -0.0420079 0.88073" mass="1.65" diaginertia="0.00829713 0.00825256 0.00194031" />
            <joint name="zarm_l3_joint" pos="0 0 0" axis="0 0 1" range="-1.5708 1.5708" actuatorfrcrange="-39 39" damping="0.2" />
            <geom type="mesh" contype="0" conaffinity="0" group="1" density="0" rgba="1 1 1 1" mesh="l_arm_yaw" />
            <body name="zarm_l4_link" pos="0.02 0 -0.2837">
              <inertial pos="-0.01611 0.00143 -0.04857" quat="0.99579 0 0.0916646 0" mass="0.429" diaginertia="0.00136857 0.00114 0.000811432" />
              <joint name="zarm_l4_joint" pos="0 0 0" axis="0 1 0" range="-2.61799 0" actuatorfrcrange="-50 50" damping="0.2" />
              <geom type="mesh" contype="0" conaffinity="0" group="1" density="0" rgba="1 1 1 1" mesh="l_forearm" />
              <body name="zarm_l5_link" pos="-0.02 0 -0.126">
                <inertial pos="-0.00207 0.00018 -0.05079" quat="0.70482 0.0568167 0.0568167 0.70482" mass="0.61" diaginertia="0.00146 0.00107649 0.000823509" />
                <joint name="zarm_l5_joint" pos="0 0 0" axis="0 0 1" range="-1.5708 1.5708" actuatorfrcrange="-12 12" damping="0.2" />
                <geom type="mesh" contype="0" conaffinity="0" group="1" density="0" rgba="1 1 1 1" mesh="l_hand_yaw" />
                <body name="zarm_l6_link" pos="0 0 -0.1075">
                  <inertial pos="-0.00111 0.00335 -0.01335" quat="0 0.707107 0 0.707107" mass="0.331" diaginertia="0.00028 0.00027 0.00022" />
                  <joint name="zarm_l6_joint" pos="0 0 0" axis="1 0 0" range="-1.309 0.698132" actuatorfrcrange="-12 12" damping="0.2" />
                  <geom type="mesh" contype="0" conaffinity="0" group="1" density="0" rgba="1 1 1 1" mesh="l_hand_roll" />
                  <body name="zarm_l7_link" pos="0 0 -0.021">
                    <inertial pos="0.00185848 0.0101072 -0.090505" quat="0.961232 -0.0391052 -0.00682346 0.272869" mass="0.640524" diaginertia="0.000720114 0.00070104 0.000117174" />
                    <joint name="zarm_l7_joint" pos="0 0 0" axis="0 1 0" range="-0.698132 0.698132" actuatorfrcrange="-12 12" damping="0.2" />
                    <geom type="mesh" contype="0" conaffinity="0" group="1" density="0" rgba="1 1 1 1" mesh="l_hand_pitch" />
                    <geom size="0.005" pos="0 -0.03 -0.17" />
                  </body>
                </body>
              </body>
            </body>
          </body>
        </body>
      </body>
      <body name="zarm_r1_link" pos="-0.0174999 -0.2927 0.445">
        <inertial pos="-0.00083 0.02218 0.00035" quat="0.504005 0.507855 -0.484025 0.503768" mass="0.962" diaginertia="0.00227032 0.0022507 0.000988974" />
        <joint name="zarm_r1_joint" pos="0 0 0" axis="0 1 0" range="-3.14159 1.5708" actuatorfrcrange="-100 100" damping="0.2" />
        <geom type="mesh" contype="0" conaffinity="0" group="1" density="0" rgba="1 1 1 1" mesh="r_arm_pitch" />
        <body name="zarm_r2_link">
          <inertial pos="-0.00791 0 -0.04655" quat="0.705843 -0.0422654 -0.0422654 0.705843" mass="0.57" diaginertia="0.00211 0.00163601 0.00121399" />
          <joint name="zarm_r2_joint" pos="0 0 0" axis="1 0 0" range="-2.0944 0.349066" actuatorfrcrange="-50 50" damping="0.2" />
          <geom type="mesh" contype="0" conaffinity="0" group="1" density="0" rgba="1 1 1 1" mesh="r_arm_roll" />
          <body name="zarm_r3_link">
            <inertial pos="0.00628 -0.00107 -0.20878" quat="0.88073 -0.0420079 -0.0547044 0.46857" mass="1.65" diaginertia="0.00829713 0.00825256 0.00194031" />
            <joint name="zarm_r3_joint" pos="0 0 0" axis="0 0 1" range="-1.5708 1.5708" actuatorfrcrange="-39 39" damping="0.2" />
            <geom type="mesh" contype="0" conaffinity="0" group="1" density="0" rgba="1 1 1 1" mesh="r_arm_yaw" />
            <body name="zarm_r4_link" pos="0.02 0 -0.2837">
              <inertial pos="-0.01611 -0.00143 -0.04857" quat="0.99579 0 0.0916646 0" mass="0.429" diaginertia="0.00136857 0.00114 0.000811432" />
              <joint name="zarm_r4_joint" pos="0 0 0" axis="0 1 0" range="-2.61799 0" actuatorfrcrange="-50 50" damping="0.2" />
              <geom type="mesh" contype="0" conaffinity="0" group="1" density="0" rgba="1 1 1 1" mesh="r_forearm" />
              <body name="zarm_r5_link" pos="-0.02 0 -0.126">
                <inertial pos="-0.00207 -0.00018 -0.05079" quat="0.70482 0.0568167 0.0568167 0.70482" mass="0.61" diaginertia="0.00146 0.00107649 0.000823509" />
                <joint name="zarm_r5_joint" pos="0 0 0" axis="0 0 1" range="-1.5708 1.5708" actuatorfrcrange="-12 12" damping="0.2" />
                <geom type="mesh" contype="0" conaffinity="0" group="1" density="0" rgba="1 1 1 1" mesh="r_hand_yaw" />
                <body name="zarm_r6_link" pos="0 0 -0.1075">
                  <inertial pos="-0.00111 -0.00335 -0.01335" quat="0 0.707107 0 0.707107" mass="0.331" diaginertia="0.00028 0.00027 0.00022" />
                  <joint name="zarm_r6_joint" pos="0 0 0" axis="1 0 0" range="-0.698132 1.309" actuatorfrcrange="-12 12" damping="0.2" />
                  <geom type="mesh" contype="0" conaffinity="0" group="1" density="0" rgba="1 1 1 1" mesh="r_hand_roll" />
                  <body name="zarm_r7_link" pos="0 0 -0.021">
                    <inertial pos="0.00185848 -0.0101072 -0.090505" quat="0.956166 0.0488773 -0.0039771 -0.288691" mass="0.640524" diaginertia="0.000700271 0.000682658 0.000115399" />
                    <joint name="zarm_r7_joint" pos="0 0 0" axis="0 1 0" range="-0.698132 0.698132" actuatorfrcrange="-12 12" damping="0.2" />
                    <geom type="mesh" contype="0" conaffinity="0" group="1" density="0" rgba="1 1 1 1" mesh="r_hand_pitch" />
                    <geom size="0.005" pos="0 0.03 -0.17" />
                  </body>
                </body>
              </body>
            </body>
          </body>
        </body>
      </body>
      <body name="zhead_1_link" pos="-0.0184999 0 0.6014">
        <inertial pos="-0.00031 0.00037 -0.01205" mass="0.35" diaginertia="7e-05 5e-05 5e-05" />
        <joint name="zhead_1_joint" pos="0 0 0" axis="0 0 1" range="-1.5708 1.5708" actuatorfrcrange="-1.5 1.5" damping="0.2" />
        <geom type="mesh" contype="0" conaffinity="0" group="1" density="0" rgba="1 1 1 1" mesh="head_yaw" />
        <body name="zhead_2_link">
          <inertial pos="0.0268676 0.000378234 0.0745327" quat="0.443488 -0.113722 -0.0346749 0.88836" mass="0.835026" diaginertia="0.0045993 0.00450499 0.00301055" />
          <joint name="zhead_2_joint" pos="0 0 0" axis="0 1 0" range="-0.523599 0.523599" actuatorfrcrange="-12 12" damping="0.2" />
          <geom type="mesh" contype="0" conaffinity="0" group="1" density="0" rgba="1 1 1 1" mesh="head_pitch" />
          <geom pos="0.117357 0.0176534 0.152372" quat="0.970296 0 0.241922 0" type="mesh" contype="0" conaffinity="0" group="1" density="0" rgba="1 1 1 1" mesh="head_camera" />
        </body>
      </body>
    </body>
  </worldbody>
  <actuator>
    <motor gear="1" joint="leg_l1_joint" name="leg_l1_joint_motor" ctrllimited="true" ctrlrange="-180 180" />
    <motor gear="1" joint="leg_l2_joint" name="leg_l2_joint_motor" ctrllimited="true" ctrlrange="-100 100" />
    <motor gear="1" joint="leg_l3_joint" name="leg_l3_joint_motor" ctrllimited="true" ctrlrange="-100 100" />
    <motor gear="1" joint="leg_l4_joint" name="leg_l4_joint_motor" ctrllimited="true" ctrlrange="-180 180" />
    <motor gear="1" joint="leg_l5_joint" name="leg_l5_joint_motor" ctrllimited="true" ctrlrange="-36 36" />
    <motor gear="1" joint="leg_l6_joint" name="leg_l6_joint_motor" ctrllimited="true" ctrlrange="-36 36" />
    <motor gear="1" joint="leg_r1_joint" name="leg_r1_joint_motor" ctrllimited="true" ctrlrange="-180 180" />
    <motor gear="1" joint="leg_r2_joint" name="leg_r2_joint_motor" ctrllimited="true" ctrlrange="-100 100" />
    <motor gear="1" joint="leg_r3_joint" name="leg_r3_joint_motor" ctrllimited="true" ctrlrange="-100 100" />
    <motor gear="1" joint="leg_r4_joint" name="leg_r4_joint_motor" ctrllimited="true" ctrlrange="-180 180" />
    <motor gear="1" joint="leg_r5_joint" name="leg_r5_joint_motor" ctrllimited="true" ctrlrange="-36 36" />
    <motor gear="1" joint="leg_r6_joint" name="leg_r6_joint_motor" ctrllimited="true" ctrlrange="-36 36" />
    <motor gear="1" joint="zarm_l1_joint" name="zarm_l1_joint_motor" ctrllimited="true" ctrlrange="-100 100" />
    <motor gear="1" joint="zarm_l2_joint" name="zarm_l2_joint_motor" ctrllimited="true" ctrlrange="-50 50" />
    <motor gear="1" joint="zarm_l3_joint" name="zarm_l3_joint_motor" ctrllimited="true" ctrlrange="-39 39" />
    <motor gear="1" joint="zarm_l4_joint" name="zarm_l4_joint_motor" ctrllimited="true" ctrlrange="-50 50" />
    <motor gear="1" joint="zarm_l5_joint" name="zarm_l5_joint_motor" ctrllimited="true" ctrlrange="-12 12" />
    <motor gear="1" joint="zarm_l6_joint" name="zarm_l6_joint_motor" ctrllimited="true" ctrlrange="-12 12" />
    <motor gear="1" joint="zarm_l7_joint" name="zarm_l7_joint_motor" ctrllimited="true" ctrlrange="-12 12" />
    <motor gear="1" joint="zarm_r1_joint" name="zarm_r1_joint_motor" ctrllimited="true" ctrlrange="-100 100" />
    <motor gear="1" joint="zarm_r2_joint" name="zarm_r2_joint_motor" ctrllimited="true" ctrlrange="-50 50" />
    <motor gear="1" joint="zarm_r3_joint" name="zarm_r3_joint_motor" ctrllimited="true" ctrlrange="-39 39" />
    <motor gear="1" joint="zarm_r4_joint" name="zarm_r4_joint_motor" ctrllimited="true" ctrlrange="-50 50" />
    <motor gear="1" joint="zarm_r5_joint" name="zarm_r5_joint_motor" ctrllimited="true" ctrlrange="-12 12" />
    <motor gear="1" joint="zarm_r6_joint" name="zarm_r6_joint_motor" ctrllimited="true" ctrlrange="-12 12" />
    <motor gear="1" joint="zarm_r7_joint" name="zarm_r7_joint_motor" ctrllimited="true" ctrlrange="-12 12" />
    <motor gear="1" joint="zhead_1_joint" name="zhead_1_joint_motor" ctrllimited="true" ctrlrange="-1.5 1.5" />
    <motor gear="1" joint="zhead_2_joint" name="zhead_2_joint_motor" ctrllimited="true" ctrlrange="-12 12" />
  </actuator>
  <sensor>
    <accelerometer name="BodyAcc" site="imu" />
    <velocimeter name="BodyVel" site="imu" />
    <gyro name="BodyGyro" site="imu" />
    <framepos name="BodyPos" objtype="site" objname="imu" />
    <framequat name="BodyQuat" objtype="site" objname="imu" />
    <jointpos name="leg_l1_joint_pos" joint="leg_l1_joint" />
    <jointpos name="leg_l2_joint_pos" joint="leg_l2_joint" />
    <jointpos name="leg_l3_joint_pos" joint="leg_l3_joint" />
    <jointpos name="leg_l4_joint_pos" joint="leg_l4_joint" />
    <jointpos name="leg_l5_joint_pos" joint="leg_l5_joint" />
    <jointpos name="leg_l6_joint_pos" joint="leg_l6_joint" />
    <jointpos name="leg_r1_joint_pos" joint="leg_r1_joint" />
    <jointpos name="leg_r2_joint_pos" joint="leg_r2_joint" />
    <jointpos name="leg_r3_joint_pos" joint="leg_r3_joint" />
    <jointpos name="leg_r4_joint_pos" joint="leg_r4_joint" />
    <jointpos name="leg_r5_joint_pos" joint="leg_r5_joint" />
    <jointpos name="leg_r6_joint_pos" joint="leg_r6_joint" />
    <jointpos name="zarm_l1_joint_pos" joint="zarm_l1_joint" />
    <jointpos name="zarm_l2_joint_pos" joint="zarm_l2_joint" />
    <jointpos name="zarm_l3_joint_pos" joint="zarm_l3_joint" />
    <jointpos name="zarm_l4_joint_pos" joint="zarm_l4_joint" />
    <jointpos name="zarm_l5_joint_pos" joint="zarm_l5_joint" />
    <jointpos name="zarm_l6_joint_pos" joint="zarm_l6_joint" />
    <jointpos name="zarm_l7_joint_pos" joint="zarm_l7_joint" />
    <jointpos name="zarm_r1_joint_pos" joint="zarm_r1_joint" />
    <jointpos name="zarm_r2_joint_pos" joint="zarm_r2_joint" />
    <jointpos name="zarm_r3_joint_pos" joint="zarm_r3_joint" />
    <jointpos name="zarm_r4_joint_pos" joint="zarm_r4_joint" />
    <jointpos name="zarm_r5_joint_pos" joint="zarm_r5_joint" />
    <jointpos name="zarm_r6_joint_pos" joint="zarm_r6_joint" />
    <jointpos name="zarm_r7_joint_pos" joint="zarm_r7_joint" />
    <jointpos name="zhead_1_joint_pos" joint="zhead_1_joint" />
    <jointpos name="zhead_2_joint_pos" joint="zhead_2_joint" />
    <jointvel name="leg_l1_joint_vel" joint="leg_l1_joint" />
    <jointvel name="leg_l2_joint_vel" joint="leg_l2_joint" />
    <jointvel name="leg_l3_joint_vel" joint="leg_l3_joint" />
    <jointvel name="leg_l4_joint_vel" joint="leg_l4_joint" />
    <jointvel name="leg_l5_joint_vel" joint="leg_l5_joint" />
    <jointvel name="leg_l6_joint_vel" joint="leg_l6_joint" />
    <jointvel name="leg_r1_joint_vel" joint="leg_r1_joint" />
    <jointvel name="leg_r2_joint_vel" joint="leg_r2_joint" />
    <jointvel name="leg_r3_joint_vel" joint="leg_r3_joint" />
    <jointvel name="leg_r4_joint_vel" joint="leg_r4_joint" />
    <jointvel name="leg_r5_joint_vel" joint="leg_r5_joint" />
    <jointvel name="leg_r6_joint_vel" joint="leg_r6_joint" />
    <jointvel name="zarm_l1_joint_vel" joint="zarm_l1_joint" />
    <jointvel name="zarm_l2_joint_vel" joint="zarm_l2_joint" />
    <jointvel name="zarm_l3_joint_vel" joint="zarm_l3_joint" />
    <jointvel name="zarm_l4_joint_vel" joint="zarm_l4_joint" />
    <jointvel name="zarm_l5_joint_vel" joint="zarm_l5_joint" />
    <jointvel name="zarm_l6_joint_vel" joint="zarm_l6_joint" />
    <jointvel name="zarm_l7_joint_vel" joint="zarm_l7_joint" />
    <jointvel name="zarm_r1_joint_vel" joint="zarm_r1_joint" />
    <jointvel name="zarm_r2_joint_vel" joint="zarm_r2_joint" />
    <jointvel name="zarm_r3_joint_vel" joint="zarm_r3_joint" />
    <jointvel name="zarm_r4_joint_vel" joint="zarm_r4_joint" />
    <jointvel name="zarm_r5_joint_vel" joint="zarm_r5_joint" />
    <jointvel name="zarm_r6_joint_vel" joint="zarm_r6_joint" />
    <jointvel name="zarm_r7_joint_vel" joint="zarm_r7_joint" />
    <jointvel name="zhead_1_joint_vel" joint="zhead_1_joint" />
    <jointvel name="zhead_2_joint_vel" joint="zhead_2_joint" />
  </sensor>
</mujoco>
