<?xml version='1.0' encoding='utf-8'?>
<robot name="biped_s54">
  <mujoco>
    <compiler meshdir="../meshes/" balanceinertia="true" discardvisual="false" />
  </mujoco>
  <link name="base_link">
    <inertial>
      <!-- 质心：( -0.04862767, -0.00011335, -0.01073125 ) -->
      <origin xyz="-0.04862767 -0.00011335 -0.01073125" rpy="0 0 0" />
      <!-- 质量：7.54372700 kg -->
      <mass value="7.54373" />
      <!-- 惯性张量：由重心决定，对齐输出坐标系 -->
      <inertia
        ixx="0.08017682"
        ixy="0.00007096"
        ixz="-0.01913378"
        iyy="0.05814749"
        iyz="0.00006879"
        izz="0.07704308" />
    </inertial>
    <visual>
      <origin xyz="0 0 0" rpy="0 0 0" />
      <geometry>
        <mesh filename="../../meshes/torso.STL" />
      </geometry>
      <material name="">
        <color rgba="1 1 1 1" />
      </material>
    </visual>
  </link>
  <link name="waist_yaw_link">
    <inertial>
      <!-- 质心：( -0.00204947, -0.00083286, 0.17189597 ) -->
      <origin xyz="-0.00204947 -0.00083286 0.17189597" rpy="0 0 0" />
      <!-- 质量：17.39118181 kg -->
      <mass value="17.39118" />
      <!-- ✅ 由重心决定，并且对齐输出的坐标系（使用负张量记数法）- 来自waist_yaw Lxx/Lyy/Lzz -->
      <inertia
        ixx="0.34870252"
        ixy="0.00016632"
        ixz="0.00524373"
        iyy="0.26683447"
        iyz="0.00039067"
        izz="0.21260401" />
    </inertial>
    <visual>
      <origin xyz="0 0 0" rpy="0 0 0" />
      <geometry>
        <mesh filename="../../meshes/waist_yaw.STL" />
      </geometry>
      <material name="">
        <color rgba="1 1 1 1" />
      </material>
    </visual>
  </link>
  <joint name="waist_yaw_joint" type="fixed">
    <origin xyz="0 0 0.1114" rpy="0 0 0" />
    <parent link="base_link" />
    <child link="waist_yaw_link" />
    <axis xyz="0 0 1" />
    <limit lower="-3.14159" upper="3.14159" effort="102.0" velocity="8.7" />
    <dynamics damping="0.02" friction="0.0" />
  </joint>
  <!-- ============ l_arm_pitch ============ -->
  <!-- 坐标系：l_arm_pitch_roll_yaw -->
  <link
    name="zarm_l1_link">
    <inertial>
      <!-- 质心：( 0.00158747, -0.01043185, 0.00030593 ) -->
      <origin xyz="0.00158747 -0.01043185 0.00030593" rpy="0 0 0" />
      <!-- 质量：0.96331759 kg -->
      <mass value="0.96332" />
      <!-- ✅ 由重心决定，并且对齐输出的坐标系（使用负张量记数法） -->
      <inertia
        ixx="0.00140558"
        ixy="-0.00001295"
        ixz="0.00000090"
        iyy="0.00088012"
        iyz="-0.00000328"
        izz="0.00138366" />
    </inertial>
    <visual>
      <origin xyz="0 0 0" rpy="0 0 0" />
      <geometry>
        <mesh
          filename="../../meshes/l_arm_pitch.STL" />
      </geometry>
      <material
        name="">
        <color
          rgba="1 1 1 1" />
      </material>
    </visual>
  </link>
  <joint
    name="zarm_l1_joint"
    type="revolute">
    <origin
      xyz="-0.003 0.2527 0.283"
      rpy="0 0 0" />
    <parent
      link="waist_yaw_link" />
    <child
      link="zarm_l1_link" />
    <axis
      xyz="0 1 0" />
    <limit lower="-3.14159265358979" upper="1.5707963267949" effort="66.0" velocity="18.8" />
    <dynamics damping="0.02" friction="0.0" />
  </joint>
  <!-- ============ l_arm_roll ============ -->
  <!-- 坐标系：l_arm_pitch_roll_yaw -->
  <link
    name="zarm_l2_link">
    <inertial>
      <!-- 质心：( -0.00184339, -0.00000348, -0.04708172 ) -->
      <origin xyz="-0.00184339 -0.00000348 -0.04708172" rpy="0 0 0" />
      <!-- 质量：0.44946057 kg -->
      <mass value="0.44946" />
      <!-- ✅ 由重心决定，并且对齐输出的坐标系（使用负张量记数法） -->
      <inertia
        ixx="0.00089068"
        ixy="0.00000011"
        ixz="-0.00001710"
        iyy="0.00130230"
        iyz="0.00000014"
        izz="0.00078679" />
    </inertial>
    <visual>
      <origin
        xyz="0 0 0"
        rpy="0 0 0" />
      <geometry>
        <mesh
          filename="../../meshes/l_arm_roll.STL" />
      </geometry>
      <material
        name="">
        <color
          rgba="1 1 1 1" />
      </material>
    </visual>
  </link>
  <joint
    name="zarm_l2_joint"
    type="revolute">
    <origin
      xyz="0 0 0"
      rpy="0 0 0" />
    <parent
      link="zarm_l1_link" />
    <child
      link="zarm_l2_link" />
    <axis
      xyz="1 0 0" />
    <limit lower="-0.349065850398866" upper="3.49065850398866" effort="75.0" velocity="8.0" />
    <dynamics damping="0.02" friction="0.0" />
  </joint>

  <!-- ============ l_arm_yaw ============ -->
  <!-- 坐标系：l_arm_pitch_roll_yaw -->
  <link
    name="zarm_l3_link">
    <inertial>
      <!-- 质心：( 0.00946602, 0.00338592, -0.22979710 ) -->
      <origin xyz="0.00946602 0.00338592 -0.22979710" rpy="0 0 0" />
      <!-- 质量：1.83951250 kg -->
      <mass value="1.83951" />
      <!-- ✅ 由重心决定，并且对齐输出的坐标系（使用负张量记数法） -->
      <inertia
        ixx="0.00720937"
        ixy="-0.00007650"
        ixz="0.00083950"
        iyy="0.00730189"
        iyz="0.00032798"
        izz="0.00197014" />
    </inertial>
    <visual>
      <origin
        xyz="0 0 0"
        rpy="0 0 0" />
      <geometry>
        <mesh
          filename="../../meshes/l_arm_yaw.STL" />
      </geometry>
      <material
        name="">
        <color
          rgba="1 1 1 1" />
      </material>
    </visual>
  </link>
  <joint
    name="zarm_l3_joint"
    type="revolute">
    <origin
      xyz="0 0 0"
      rpy="0 0 0" />
    <parent
      link="zarm_l2_link" />
    <child
      link="zarm_l3_link" />
    <axis
      xyz="0 0 1" />
    <limit lower="-1.48352986419518" upper="1.48352986419518" effort="57.0" velocity="7.5" />
    <dynamics damping="0.02" friction="0.0" />
  </joint>

  <!-- ============ l_foream ============ -->
  <!-- 坐标系：l_foream -->
  <link
    name="zarm_l4_link">
    <inertial>
      <!-- 质心：( -0.01807966, 0.00115288, -0.06638468 ) -->
      <origin xyz="-0.01807966 0.00115288 -0.06638468" rpy="0 0 0" />
      <!-- 质量：0.66448067 kg -->
      <mass value="0.66448" />
      <!-- ✅ 由重心决定，并且对齐输出的坐标系（使用负张量记数法） -->
      <inertia
        ixx="0.00159694"
        ixy="-0.00000774"
        ixz="-0.00013459"
        iyy="0.00136432"
        iyz="-0.00002619"
        izz="0.00073291" />
    </inertial>
    <visual>
      <origin
        xyz="0 0 0"
        rpy="0 0 0" />
      <geometry>
        <mesh
          filename="../../meshes/l_forearm.STL" />
      </geometry>
      <material
        name="">
        <color
          rgba="1 1 1 1" />
      </material>
    </visual>
  </link>
  <joint
    name="zarm_l4_joint"
    type="revolute">
    <origin
      xyz="0.02 0 -0.2837"
      rpy="0 0 0" />
    <parent
      link="zarm_l3_link" />
    <child
      link="zarm_l4_link" />
    <axis
      xyz="0 1 0" />
    <limit lower="-2.61799387799149" upper="0.0" effort="75.0" velocity="8.0" />
    <dynamics damping="0.02" friction="0.0" />
  </joint>

  <!-- ============ l_hand_yaw ============ -->
  <!-- 坐标系：l_hand_yaw -->
  <link
    name="zarm_l5_link">
    <inertial>
      <!-- 质心：( -0.00858374, 0.00001292, -0.05739202 ) -->
      <origin xyz="-0.00858374 0.00001292 -0.05739202" rpy="0 0 0" />
      <!-- 质量：0.67508041 kg -->
      <mass value="0.67508" />
      <!-- ✅ 由重心决定，并且对齐输出的坐标系（使用负张量记数法） -->
      <inertia
        ixx="0.00071024"
        ixy="0.00000007"
        ixz="-0.00006511"
        iyy="0.00105532"
        iyz="-0.00000148"
        izz="0.00059033" />
    </inertial>
    <visual>
      <origin
        xyz="0 0 0"
        rpy="0 0 0" />
      <geometry>
        <mesh
          filename="../../meshes/l_hand_yaw.STL" />
      </geometry>
      <material
        name="">
        <color
          rgba="1 1 1 1" />
      </material>
    </visual>
  </link>
  <joint
    name="zarm_l5_joint"
    type="revolute">
    <origin xyz="-0.02 0 -0.1201" rpy="0 0 0" />
    <parent
      link="zarm_l4_link" />
    <child
      link="zarm_l5_link" />
    <axis
      xyz="0 0 1" />
    <limit lower="-1.5707963267949" upper="1.5707963267949" effort="14.1" velocity="17.5" />
    <dynamics damping="0.02" friction="0.0" />
  </joint>

  <!-- ============ l_hand_roll ============ -->
  <!-- 坐标系：l_hand_roll -->
  <link
    name="zarm_l6_link">
    <inertial>
      <!-- 质心：( -0.00148455, 0.00633133, -0.01455089 ) -->
      <origin xyz="-0.00148455 0.00633133 -0.01455089" rpy="0 0 0" />
      <!-- 质量：0.51483636 kg -->
      <mass value="0.51484" />
      <!-- 惯性张量：由重心决定，对齐输出坐标系 -->
      <inertia
        ixx="0.00020477"
        ixy="-0.00000421"
        ixz="0.00001076"
        iyy="0.00028911"
        iyz="0.00001014"
        izz="0.00030011" />
    </inertial>
    <visual>
      <origin
        xyz="0 0 0"
        rpy="0 0 0" />
      <geometry>
        <mesh
          filename="../../meshes/l_hand_roll.STL" />
      </geometry>
      <material
        name="">
        <color
          rgba="1 1 1 1" />
      </material>
    </visual>
  </link>
  <joint
    name="zarm_l6_joint"
    type="revolute">
    <origin
      xyz="0.0 0 -0.114"
      rpy="0 0 0" />
    <parent
      link="zarm_l5_link" />
    <child
      link="zarm_l6_link" />
    <axis
      xyz="1 0 0" />
    <limit lower="-1.30899693899575" upper="0.698131700797732" effort="14.1" velocity="17.5" />
    <dynamics damping="0.02" friction="0.0" />
  </joint>

  <!-- ============ l_hand_pitch ============ -->
  <!-- 坐标系：l_hand_pitch -->
  <link
    name="zarm_l7_link">
    <inertial>
      <!-- 质心：( 0.03810742, 0.00267575, -0.05086389 ) -->
      <origin xyz="0.00481393 0.00873606 -0.0837543" rpy="0 0 0" />
      <!-- 质量：0.18939501 kg -->
      <mass value="0.7374" />
      <!-- ✅ 由重心决定，并且对齐输出的坐标系（使用负张量记数法） -->
      <inertia
        ixx="0.00112502"
        ixy="0"
        ixz="0"
        iyy="0.00133239"
        iyz="0"
        izz="0.000373427" />
    </inertial>
    <visual>
      <origin
        xyz="0 0 0"
        rpy="0 0 0" />
      <geometry>
        <mesh
          filename="../../meshes/l_hand_pitch_nohand.STL" />
      </geometry>
      <material
        name="">
        <color
          rgba="1 1 1 1" />
      </material>
    </visual>
  </link>
  <joint
    name="zarm_l7_joint"
    type="revolute">
    <origin
      xyz="0 0 -0.021"
      rpy="0 0 0" />
    <parent
      link="zarm_l6_link" />
    <child
      link="zarm_l7_link" />
    <axis
      xyz="0 1 0" />
    <limit lower="-0.698131700797732" upper="0.698131700797732" effort="14.1" velocity="17.5" />
    <dynamics damping="0.02" friction="0.0" />
  </joint>
  <link name="zarm_l7_end_effector">
  </link>
  <joint name="zarm_l7_end_effector_joint" type="fixed">
    <origin xyz="0 0.0 -0.17" rpy="0 0 0" />
    <parent link="zarm_l7_link" />
    <child link="zarm_l7_end_effector" />
  </joint>
  <!-- ============ r_arm_pitch ============ -->
  <!-- 坐标系：r_arm_pitch_roll_yaw -->
  <link
    name="zarm_r1_link">
    <inertial>
      <!-- 质心：左(0.00158747, -0.01043185, 0.00030593) -> 右(0.00158747, 0.01043185, 0.00030593) -->
      <origin xyz="0.00158747 0.01043185 0.00030593" rpy="0 0 0" />
      <!-- 质量：0.96331759 kg -->
      <mass value="0.96332" />
      <!-- 惯性张量：ixy/iyz符号取反，ixz保持不变 -->
      <inertia
        ixx="0.00140558"
        ixy="0.00001295"
        ixz="0.00000090"
        iyy="0.00088012"
        iyz="0.00000328"
        izz="0.00138366" />
    </inertial>
    <visual>
      <origin
        xyz="0 0 0"
        rpy="0 0 0" />
      <geometry>
        <mesh
          filename="../../meshes/r_arm_pitch.STL" />
      </geometry>
      <material
        name="">
        <color
          rgba="1 1 1 1" />
      </material>
    </visual>
  </link>
  <joint
    name="zarm_r1_joint"
    type="revolute">
    <origin
      xyz="-0.003 -0.2527 0.283"
      rpy="0 0 0" />
    <parent
      link="waist_yaw_link" />
    <child
      link="zarm_r1_link" />
    <axis
      xyz="0 1 0" />
    <limit lower="-3.14159265358979" upper="1.5707963267949" effort="66.0" velocity="18.8" />
    <dynamics damping="0.02" friction="0.0" />
  </joint>

  <!-- ============ r_arm_roll ============ -->
  <!-- 坐标系：r_arm_pitch_roll_yaw -->
  <link
    name="zarm_r2_link">
    <inertial>
      <!-- 质心：左(-0.00184339, -0.00000348, -0.04708172) -> 右(-0.00184339, 0.00000348, -0.04708172) -->
      <origin xyz="-0.00184339 0.00000348 -0.04708172" rpy="0 0 0" />
      <!-- 质量：0.44946057 kg -->
      <mass value="0.44946" />
      <!-- 惯性张量：ixy/iyz符号取反，ixz保持不变 -->
      <inertia
        ixx="0.00089068"
        ixy="-0.00000011"
        ixz="-0.00001710"
        iyy="0.00130230"
        iyz="-0.00000014"
        izz="0.00078679" />
    </inertial>
    <visual>
      <origin
        xyz="0 0 0"
        rpy="0 0 0" />
      <geometry>
        <mesh
          filename="../../meshes/r_arm_roll.STL" />
      </geometry>
      <material
        name="">
        <color
          rgba="1 1 1 1" />
      </material>
    </visual>
  </link>
  <joint
    name="zarm_r2_joint"
    type="revolute">
    <origin
      xyz="0 0 0"
      rpy="0 0 0" />
    <parent
      link="zarm_r1_link" />
    <child
      link="zarm_r2_link" />
    <axis
      xyz="1 0 0" />
    <limit lower="-3.49065850398866" upper="0.349065850398866" effort="75.0" velocity="8.0" />
    <dynamics damping="0.02" friction="0.0" />
  </joint>

  <!-- ============ r_arm_yaw ============ -->
  <!-- 坐标系：r_arm_pitch_roll_yaw -->
  <link
    name="zarm_r3_link">
    <inertial>
      <!-- 质心：左(0.00946602, 0.00338592, -0.22979710) -> 右(0.00946602, -0.00338592, -0.22979710) -->
      <origin xyz="0.00946602 -0.00338592 -0.22979710" rpy="0 0 0" />
      <!-- 质量：1.83951250 kg -->
      <mass value="1.83951" />
      <!-- 惯性张量：ixy/iyz符号取反，ixz保持不变 -->
      <inertia
        ixx="0.00720937"
        ixy="0.00007650"
        ixz="0.00083950"
        iyy="0.00730189"
        iyz="-0.00032798"
        izz="0.00197014" />
    </inertial>
    <visual>
      <origin
        xyz="0 0 0"
        rpy="0 0 0" />
      <geometry>
        <mesh
          filename="../../meshes/r_arm_yaw.STL" />
      </geometry>
      <material
        name="">
        <color
          rgba="1 1 1 1" />
      </material>
    </visual>
  </link>
  <joint
    name="zarm_r3_joint"
    type="revolute">
    <origin
      xyz="0 0 0"
      rpy="0 0 0" />
    <parent
      link="zarm_r2_link" />
    <child
      link="zarm_r3_link" />
    <axis
      xyz="0 0 1" />
    <limit lower="-1.48352986419518" upper="1.48352986419518" effort="57.0" velocity="7.5" />
    <dynamics damping="0.02" friction="0.0" />
  </joint>

  <!-- ============ r_foream ============ -->
  <!-- 坐标系：r_foream -->
  <link
    name="zarm_r4_link">
    <inertial>
      <!-- 质心：左(-0.01807966, 0.00115288, -0.06638468) -> 右(-0.01807966, -0.00115288, -0.06638468) -->
      <origin xyz="-0.01807966 -0.00115288 -0.06638468" rpy="0 0 0" />
      <!-- 质量：0.66448067 kg -->
      <mass value="0.66448" />
      <!-- 惯性张量：ixy/iyz符号取反，ixz保持不变 -->
      <inertia
        ixx="0.00159694"
        ixy="0.00000774"
        ixz="-0.00013459"
        iyy="0.00136432"
        iyz="0.00002619"
        izz="0.00073291" />
    </inertial>
    <visual>
      <origin
        xyz="0 0 0"
        rpy="0 0 0" />
      <geometry>
        <mesh
          filename="../../meshes/r_forearm.STL" />
      </geometry>
      <material
        name="">
        <color
          rgba="1 1 1 1" />
      </material>
    </visual>
  </link>
  <joint
    name="zarm_r4_joint"
    type="revolute">
    <origin
      xyz="0.02 0 -0.2837"
      rpy="0 0 0" />
    <parent
      link="zarm_r3_link" />
    <child
      link="zarm_r4_link" />
    <axis
      xyz="0 1 0" />
    <limit lower="-2.61799387799149" upper="0.0" effort="75.0" velocity="8.0" />
    <dynamics damping="0.02" friction="0.0" />
  </joint>

  <!-- ============ r_hand_yaw ============ -->
  <!-- 坐标系：r_hand_yaw -->
  <link
    name="zarm_r5_link">
    <inertial>
      <!-- 质心：左(-0.00858374, 0.00001292, -0.05739202) -> 右(-0.00858374, -0.00001292, -0.05739202) -->
      <origin xyz="-0.00858374 -0.00001292 -0.05739202" rpy="0 0 0" />
      <!-- 质量：0.67508041 kg -->
      <mass value="0.67508" />
      <!-- 惯性张量：ixy/iyz符号取反，ixz保持不变 -->
      <inertia
        ixx="0.00071024"
        ixy="-0.00000007"
        ixz="-0.00006511"
        iyy="0.00105532"
        iyz="0.00000148"
        izz="0.00059033" />
    </inertial>
    <visual>
      <origin
        xyz="0 0 0"
        rpy="0 0 0" />
      <geometry>
        <mesh
          filename="../../meshes/r_hand_yaw.STL" />
      </geometry>
      <material
        name="">
        <color
          rgba="1 1 1 1" />
      </material>
    </visual>
  </link>
  <joint
    name="zarm_r5_joint"
    type="revolute">
    <origin xyz="-0.02 0 -0.1201" rpy="0 0 0" />
    <parent
      link="zarm_r4_link" />
    <child
      link="zarm_r5_link" />
    <axis
      xyz="0 0 1" />
    <limit lower="-1.5707963267949" upper="1.5707963267949" effort="14.1" velocity="17.5" />
    <dynamics damping="0.02" friction="0.0" />
  </joint>

  <!-- ============ r_hand_roll ============ -->
  <!-- 坐标系：r_hand_roll -->
  <link
    name="zarm_r6_link">
    <inertial>
      <!-- 质心：左(-0.00148455, 0.00633133, -0.01455089) -> 右(-0.00148455, -0.00633133, -0.01455089) -->
      <origin xyz="-0.00148455 -0.00633133 -0.01455089" rpy="0 0 0" />
      <!-- 质量：0.51483636 kg -->
      <mass value="0.51484" />
      <!-- 惯性张量：ixy/iyz符号取反，ixz保持不变 -->
      <inertia
        ixx="0.00020477"
        ixy="0.00000421"
        ixz="0.00001076"
        iyy="0.00028911"
        iyz="-0.00001014"
        izz="0.00030011" />
    </inertial>
    <visual>
      <origin
        xyz="0 0 0"
        rpy="0 0 0" />
      <geometry>
        <mesh
          filename="../../meshes/r_hand_roll.STL" />
      </geometry>
      <material
        name="">
        <color
          rgba="1 1 1 1" />
      </material>
    </visual>
  </link>
  <joint
    name="zarm_r6_joint"
    type="revolute">
    <origin
      xyz="0.0 0 -0.114"
      rpy="0 0 0" />
    <parent
      link="zarm_r5_link" />
    <child
      link="zarm_r6_link" />
    <axis
      xyz="1 0 0" />
    <limit lower="-0.698131700797732" upper="1.30899693899575" effort="14.1" velocity="17.5" />
    <dynamics damping="0.02" friction="0.0" />
  </joint>

  <!-- ============ r_hand_pitch ============ -->
  <!-- 坐标系：r_hand_pitch -->
  <link
    name="zarm_r7_link">
    <inertial>
      <!-- 质心：( 0.03616769, -0.00232464, -0.04975256 ) -->
      <origin xyz="0.00481393 -0.00870857 -0.0836411" rpy="0 0 0" />
      <!-- 质量：0.19960270 kg -->
      <mass value="0.7374" />
      <!-- ✅ 由重心决定，并且对齐输出的坐标系（使用负张量记数法） -->
      <inertia
        ixx="0.00110836"
        ixy="0"
        ixz="0"
        iyy="0.00131607"
        iyz="0"
        izz="0.000374168" />
    </inertial>
    <visual>
      <origin
        xyz="0 0 0"
        rpy="0 0 0" />
      <geometry>
        <mesh
          filename="../../meshes/r_hand_pitch_nohand.STL" />
      </geometry>
      <material
        name="">
        <color
          rgba="1 1 1 1" />
      </material>
    </visual>
  </link>
  <joint
    name="zarm_r7_joint"
    type="revolute">
    <origin
      xyz="0.0 0 -0.021"
      rpy="0 0 0" />
    <parent
      link="zarm_r6_link" />
    <child
      link="zarm_r7_link" />
    <axis
      xyz="0 1 0" />
    <limit lower="-0.698131700797732" upper="0.698131700797732" effort="14.1" velocity="17.5" />
    <dynamics damping="0.02" friction="0.0" />
  </joint>
  <link name="zarm_r7_end_effector">
  </link>
  <joint name="zarm_r7_end_effector_joint" type="fixed">
    <origin xyz="0 0.0 -0.17" rpy="0 0 0" />
    <parent link="zarm_r7_link" />
    <child link="zarm_r7_end_effector" />
  </joint>
  </robot>
