<?xml version="1.0" ?>
<!-- =================================================================================== -->
<!-- |    This document was autogenerated by xacro from /home/fandes/workspace/kuavo-ros-control/src/humanoid-control/humanoid_interface_drake/models/biped_gen4.2/urdf/biped_v3.xacro | -->
<!-- |    EDITING THIS FILE BY HAND IS NOT RECOMMENDED                                 | -->
<!-- =================================================================================== -->
<robot name="biped_v3" xmlns:drake="https://drake.mit.edu">
  <link name="torso">
   <inertial>
    <!-- 质心：( -0.04862767, -0.00011335, -0.01073125 ) -->
    <origin xyz="-0.04862767 -0.00011335 -0.01073125" rpy="0 0 0" />
    <!-- 质量：7.54372700 kg -->
    <mass value="7.54373" />
    <!-- 惯性张量：由重心决定，对齐输出坐标系 -->
    <inertia
      ixx="0.08017682"
      ixy="0.00007096"
      ixz="-0.01913378"
      iyy="0.05814749"
      iyz="0.00006879"
      izz="0.07704308" />
    </inertial>
    <visual>
      <origin xyz="0 0 0" rpy="0 0 0" />
      <geometry>
        <mesh filename="../../meshes/torso.STL" />
      </geometry>
      <material name="">
        <color rgba="0.752941176470588 0.752941176470588 0.752941176470588 1" />
      </material>
    </visual>
    <!-- <collision>
      <origin xyz="0 0 0" rpy="0 0 0" />
      <geometry>
        <mesh filename="../../meshes/torso.STL" />
      </geometry>
    </collision> -->
  </link>
  <link name="waist_yaw_link">
    <inertial>
      <!-- 质心：( -0.00204947, -0.00083286, 0.17189597 ) -->
      <origin xyz="0.04204947 -0.00083286 0.17189597" rpy="0 0 0" />
      <!-- 质量：17.39118181 kg -->
      <mass value="33.70028" />
      <!-- ✅ 由重心决定，并且对齐输出的坐标系（使用负张量记数法）- 来自waist_yaw Lxx/Lyy/Lzz -->
      <inertia
        ixx="0.34870252"
        ixy="0.00016632"
        ixz="0.00524373"
        iyy="0.26683447"
        iyz="0.00039067"
        izz="0.21260401" />
    </inertial>
    <visual>
      <origin xyz="0 0 0" rpy="0 0 0" />
      <geometry>
        <mesh filename="../../meshes/waist_yaw.STL" />
      </geometry>
      <material name="">
        <color rgba="1 1 1 1" />
      </material>
    </visual>
  </link>
  <joint name="waist_yaw_joint" type="fixed">
    <origin xyz="0 0 0.1114" rpy="0 0 0" />
    <parent link="torso" />
    <child link="waist_yaw_link" />
    <axis xyz="0 0 1" />
    <limit lower="-3.14159" upper="3.14159" effort="102.0" velocity="8.7" />
    <dynamics damping="0.02" friction="0.0" />
  </joint>
   <!-- ============ l_leg_roll ============ -->
  <!-- 坐标系：l_leg_yaw_roll -->
  <!-- 对称源：r_leg_roll (X-Z平面对称) -->
  <link name="leg_l1_link">
    <inertial>
      <!-- 质心：( -0.00669035, 0.00031614, -0.00217433 ) -->
      <origin xyz="-0.00669035 0.00031614 -0.00217433" rpy="0 0 0" />
      <!-- 质量：1.56066556 kg -->
      <mass value="1.56067" />
      <!-- ✅ 惯性张量：由重心决定，对齐输出坐标系，负张量记数法，ixy/ixz/iyz符号取反 -->
      <inertia
        ixx="0.00193116"
        ixy="-0.00001445"
        ixz="0.00001640"
        iyy="0.00255162"
        iyz="0.00000039"
        izz="0.00258412" />
    </inertial>
    <visual>
      <origin xyz="0 0 0" rpy="0 0 0" />
      <geometry>
        <mesh filename="../../meshes/l_leg_roll.STL" />
      </geometry>
      <material name="">
        <color rgba="1 1 1 1" />
      </material>
    </visual>
  </link>
  <joint name="leg_l1_joint" type="revolute">
    <origin xyz="0.0 0.095075 -0.066" rpy="0 0 0" />
    <parent link="torso" />
    <child link="leg_l1_link" />
    <axis xyz="1 0 0" />
    <limit lower="-0.314159265358979" upper="0.663225115757845" effort="127.0" velocity="10.4" />
    <dynamics damping="0.02" friction="0.0" />
  </joint>
  <transmission type="SimpleTransmission">
    <joint name="leg_l1_joint" />
    <actuator name="leg_l1_joint_motor" />
  </transmission>
  <!-- ============ l_leg_yaw ============ -->
  <!-- 坐标系：l_leg_yaw_roll -->
  <!-- 对称源：r_leg_yaw (X-Z平面对称) -->
  <link name="leg_l2_link">
    <inertial>
      <!-- 质心：( 0.00028446, -0.00794956, -0.09316636 ) -->
      <origin xyz="0.00028446 -0.00794956 -0.09316636" rpy="0 0 0" />
      <!-- 质量：0.77767000 kg -->
      <mass value="0.77767" />
      <!-- ✅ 惯性张量：由重心决定，对齐输出坐标系，负张量记数法，ixy/ixz/iyz符号取反 -->
      <inertia
        ixx="0.00355000"
        ixy="0.00000698"
        ixz="-0.00001062"
        iyy="0.00209625"
        iyz="-0.00031869"
        izz="0.00235880" />
    </inertial>
    <visual>
      <origin xyz="0 0 0" rpy="0 0 0" />
      <geometry>
        <mesh filename="../../meshes/l_leg_yaw.STL" />
      </geometry>
      <material name="">
        <color rgba="1 1 1 1" />
      </material>
    </visual>
  </link>
  <joint name="leg_l2_joint" type="revolute">
    <origin xyz="0 0 0" rpy="0 0 0" />
    <parent link="leg_l1_link" />
    <child link="leg_l2_link" />
    <axis xyz="0 0 1" />
    <limit lower="-0.785398163397448" upper="1.91986217719376" effort="71.0" velocity="8.7" />
    <dynamics damping="0.02" friction="0.0" />
  </joint>
  <transmission type="SimpleTransmission">
    <joint name="leg_l2_joint" />
    <actuator name="leg_l2_joint_motor" />
  </transmission>
  <!-- ============ l_leg_pitch ============ -->
  <!-- 坐标系：l_leg_pitch -->
  <!-- 对称源：r_leg_pitch (X-Z平面对称) -->
  <link name="leg_l3_link">
    <inertial>
      <!-- 质心：( 0.00279899, 0.01532926, -0.08586233 ) -->
      <origin xyz="0.00279899 0.01532926 -0.08586233" rpy="0 0 0" />
      <!-- 质量：6.52431750 kg -->
      <mass value="6.52432" />
      <!-- ✅ 惯性张量：由重心决定，对齐输出坐标系，负张量记数法，ixy/ixz/iyz符号取反 -->
      <inertia
        ixx="0.05865239"
        ixy="0.00013537"
        ixz="0.00154590"
        iyy="0.05732636"
        iyz="0.00115971"
        izz="0.01556119" />
    </inertial>
    <visual>
      <origin xyz="0 0 0" rpy="0 0 0" />
      <geometry>
        <mesh filename="../../meshes/l_leg_pitch.STL" />
      </geometry>
      <material name="">
        <color rgba="1 1 1 1" />
      </material>
    </visual>
  </link>
  <joint name="leg_l3_joint" type="revolute">
    <origin xyz="0 0 -0.1437" rpy="0 0 0" />
    <parent link="leg_l2_link" />
    <child link="leg_l3_link" />
    <axis xyz="0 1 0" />
    <limit lower="-1.91986217719376" upper="1.5707963267949" effort="132" velocity="12.7" />
    <dynamics damping="0.02" friction="0.0" />
  </joint>
  <transmission type="SimpleTransmission">
    <joint name="leg_l3_joint" />
    <actuator name="leg_l3_joint_motor" />
  </transmission>
  <!-- ============ l_knee ============ -->
  <!-- 坐标系：l_knee -->
  <!-- 对称源：r_knee (X-Z平面对称) -->
  <link name="leg_l4_link">
    <inertial>
      <!-- 质心：( 0.00569729, -0.00005180, -0.16159239 ) -->
      <origin xyz="0.00569729 -0.00005180 -0.16159239" rpy="0 0 0" />
      <!-- 质量：3.55158656 kg -->
      <mass value="3.55159" />
      <!-- ✅ 惯性张量：由重心决定，对齐输出坐标系，负张量记数法，ixy/ixz/iyz符号取反 -->
      <inertia
        ixx="0.04304970"
        ixy="-0.00000042"
        ixz="-0.00040640"
        iyy="0.04262733"
        iyz="-0.00004129"
        izz="0.00324950" />
    </inertial>
    <visual>
      <origin xyz="0 0 0" rpy="0 0 0" />
      <geometry>
        <mesh filename="../../meshes/l_knee.STL" />
      </geometry>
      <material name="">
        <color rgba="1 1 1 1" />
      </material>
    </visual>
  </link>
  <joint name="leg_l4_joint" type="revolute">
    <origin xyz="-0.0011639 0 -0.284" rpy="0 0 0" />
    <parent link="leg_l3_link" />
    <child link="leg_l4_link" />
    <axis xyz="0 1 0" />
    <limit lower="0.0" upper="2.53072741539178" effort="280.0" velocity="10.4" />
    <dynamics damping="0.02" friction="0.0" />
  </joint>
  <transmission type="SimpleTransmission">
    <joint name="leg_l4_joint" />
    <actuator name="leg_l4_joint_motor" />
  </transmission>
  <!-- ============ l_foot_pitch ============ -->
  <!-- 坐标系：l_foot_pitch_roll -->
  <!-- 对称源：r_foot_pitch (完全对称) -->
  <link name="leg_l5_link">
    <inertial>
      <!-- 质心：( 0, 0, 0 ) -->
      <origin xyz="0 0 0" rpy="0 0 0" />
      <!-- 质量：0.07553705 kg -->
      <mass value="0.07554" />
      <!-- ✅ 惯性张量：完全对称，与右腿完全相同 -->
      <inertia
        ixx="0.00000729"
        ixy="0.00000000"
        ixz="0.00000000"
        iyy="0.00000729"
        iyz="0.00000000"
        izz="0.00001268" />
    </inertial>
    <visual>
      <origin xyz="0 0 0" rpy="0 0 0" />
      <geometry>
        <mesh filename="../../meshes/l_foot_pitch.STL" />
      </geometry>
      <material name="">
        <color rgba="1 1 1 1" />
      </material>
    </visual>
  </link>
  <joint name="leg_l5_joint" type="revolute">
    <origin xyz="0.002 0 -0.416" rpy="0 0 0" />
    <parent link="leg_l4_link" />
    <child link="leg_l5_link" />
    <axis xyz="0 1 0" />
    <limit lower="-0.872664625997165" upper="0.349065850398866" effort="91.6" velocity="17.8" />
    <dynamics damping="0.02" friction="0.0" />
  </joint>
  <transmission type="SimpleTransmission">
    <joint name="leg_l5_joint" />
    <actuator name="leg_l5_joint_motor" />
  </transmission>
  <!-- ============ l_foot_roll ============ -->
  <!-- 坐标系：l_foot_pitch_roll -->
  <!-- 对称源：r_foot_roll (完全对称，用户覆盖值相同) -->
  <link name="leg_l6_link">
    <inertial>
      <!-- 质心：( 0.03005823, -0.00000161, -0.03531089 ) -->
      <origin xyz="0.03005823 -0.00000161 -0.03531089" rpy="0 0 0" />
      <!-- 质量：0.60537517 kg -->
      <mass value="0.60538" />
      <!-- ✅ 惯性张量：完全对称，与右腿完全相同（质心Y为负，无需镜像） -->
      <inertia
        ixx="0.00049465"
        ixy="0.00000004"
        ixz="0.00014546"
        iyy="0.00188391"
        iyz="0.00000000"
        izz="0.00198778" />
    </inertial>
    <visual>
      <origin xyz="0 0 0" rpy="0 0 0" />
      <geometry>
        <mesh filename="../../meshes/l_foot_roll.STL" />
      </geometry>
      <material name="">
        <color rgba="1 1 1 1" />
      </material>
    </visual>
  </link>
  <joint name="leg_l6_joint" type="revolute">
    <origin xyz="0 0 0" rpy="0 0 0" />
    <parent link="leg_l5_link" />
    <child link="leg_l6_link" />
    <axis xyz="1 0 0" />
    <limit lower="-0.261799387799149" upper="0.261799387799149" effort="30.0" velocity="17.8" />
    <dynamics damping="0.02" friction="0.0" />
  </joint>
  <transmission type="SimpleTransmission">
    <joint name="leg_l6_joint" />
    <actuator name="leg_l6_joint_motor" />
  </transmission>
  <frame link="leg_l6_link" name="l_foot_sole" xyz="0.04883799999999999 0.0 -0.0595" />
  <frame link="leg_l6_link" name="l_foot_toe" xyz="0.17084 0.0 -0.0595" />
  <frame link="leg_l6_link" name="l_foot_heel" xyz="-0.073164 0.0 -0.0595" />
  <!-- ============ r_leg_roll ============ -->
  <!-- 坐标系：r_leg_roll_yaw -->
  <link name="leg_r1_link">
    <inertial>
      <!-- 质心：左(-0.00669035, 0.00031614, -0.00217433) -> 右(-0.00669035, -0.00031614, -0.00217433) -->
      <origin xyz="-0.00669035 -0.00031614 -0.00217433" rpy="0 0 0" />
      <!-- 质量：1.56066556 kg -->
      <mass value="1.56067" />
      <!-- 惯性张量：ixy/iyz符号取反，ixz保持不变 -->
      <inertia
        ixx="0.00193116"
        ixy="0.00001445"
        ixz="0.00001640"
        iyy="0.00255162"
        iyz="-0.00000039"
        izz="0.00258412" />
    </inertial>
    <visual>
      <origin xyz="0 0 0" rpy="0 0 0" />
      <geometry>
        <mesh filename="../../meshes/r_leg_roll.STL" />
      </geometry>
      <material name="">
        <color rgba="1 1 1 1" />
      </material>
    </visual>
  </link>
  <joint name="leg_r1_joint" type="revolute">
    <origin xyz="0.0 -0.095075 -0.066" rpy="0 0 0" />
    <parent link="torso" />
    <child link="leg_r1_link" />
    <axis xyz="1 0 0" />
    <limit lower="-0.663225115757845" upper="0.314159265358979" effort="127.0" velocity="10.4" />
    <dynamics damping="0.02" friction="0.0" />
  </joint>
  <transmission type="SimpleTransmission">
    <joint name="leg_r1_joint" />
    <actuator name="leg_r1_joint_motor" />
  </transmission>
  <!-- ============ r_leg_yaw ============ -->
  <!-- 坐标系：r_leg_roll_yaw -->
  <link name="leg_r2_link">
    <inertial>
      <!-- 质心：左(0.00028446, -0.00794956, -0.09316636) -> 右(0.00028446, 0.00794956, -0.09316636) -->
      <origin xyz="0.00028446 0.00794956 -0.09316636" rpy="0 0 0" />
      <!-- 质量：0.77767000 kg -->
      <mass value="0.77767" />
      <!-- 惯性张量：ixy/iyz符号取反，ixz保持不变 -->
      <inertia
        ixx="0.00355000"
        ixy="-0.00000698"
        ixz="-0.00001062"
        iyy="0.00209625"
        iyz="0.00031869"
        izz="0.00235880" />
    </inertial>
    <visual>
      <origin xyz="0 0 0" rpy="0 0 0" />
      <geometry>
        <mesh filename="../../meshes/r_leg_yaw.STL" />
      </geometry>
      <material name="">
        <color rgba="1 1 1 1" />
      </material>
    </visual>
  </link>
  <joint name="leg_r2_joint" type="revolute">
    <origin xyz="0 0 0" rpy="0 0 0" />
    <parent link="leg_r1_link" />
    <child link="leg_r2_link" />
    <axis xyz="0 0 1" />
    <limit lower="-1.91986217719376" upper="0.785398163397448" effort="71.0" velocity="8.7" />
    <dynamics damping="0.02" friction="0.0" />
  </joint>
  <transmission type="SimpleTransmission">
    <joint name="leg_r2_joint" />
    <actuator name="leg_r2_joint_motor" />
  </transmission>
  <!-- ============ r_leg_pitch ============ -->
  <!-- 坐标系：r_leg_pitch -->
  <link name="leg_r3_link">
    <inertial>
      <!-- 质心：左(0.00279899, 0.01532926, -0.08586233) -> 右(0.00279899, -0.01532926, -0.08586233) -->
      <origin xyz="0.00279899 -0.01532926 -0.08586233" rpy="0 0 0" />
      <!-- 质量：6.52431750 kg -->
      <mass value="6.52432" />
      <!-- 惯性张量：ixy/iyz符号取反，ixz保持不变 -->
      <inertia
        ixx="0.05865239"
        ixy="-0.00013537"
        ixz="0.00154590"
        iyy="0.05732636"
        iyz="-0.00115971"
        izz="0.01556119" />
    </inertial>
    <visual>
      <origin xyz="0 0 0" rpy="0 0 0" />
      <geometry>
        <mesh filename="../../meshes/r_leg_pitch.STL" />
      </geometry>
      <material name="">
        <color rgba="1 1 1 1" />
      </material>
    </visual>
  </link>
  <joint name="leg_r3_joint" type="revolute">
    <origin xyz="0 0 -0.1437" rpy="0 0 0" />
    <parent link="leg_r2_link" />
    <child link="leg_r3_link" />
    <axis xyz="0 1 0" />
    <limit lower="-1.91986217719376" upper="1.5707963267949" effort="132.0" velocity="12.7" />
    <dynamics damping="0.02" friction="0.0" />
  </joint>
  <transmission type="SimpleTransmission">
    <joint name="leg_r3_joint" />
    <actuator name="leg_r3_joint_motor" />
  </transmission>
  <!-- ============ r_knee ============ -->
  <!-- 坐标系：r_knee -->
  <link name="leg_r4_link">
    <inertial>
      <!-- 质心：左(0.00569729, -0.00005180, -0.16159239) -> 右(0.00569729, 0.00005180, -0.16159239) -->
      <origin xyz="0.00569729 0.00005180 -0.16159239" rpy="0 0 0" />
      <!-- 质量：3.55158656 kg -->
      <mass value="3.55159" />
      <!-- 惯性张量：ixy/iyz符号取反，ixz保持不变 -->
      <inertia
        ixx="0.04304970"
        ixy="0.00000042"
        ixz="-0.00040640"
        iyy="0.04262733"
        iyz="0.00004129"
        izz="0.00324950" />
    </inertial>
    <visual>
      <origin xyz="0 0 0" rpy="0 0 0" />
      <geometry>
        <mesh filename="../../meshes/r_knee.STL" />
      </geometry>
      <material name="">
        <color rgba="1 1 1 1" />
      </material>
    </visual>
  </link>
  <joint name="leg_r4_joint" type="revolute">
    <origin xyz="-0.0011639 0 -0.284" rpy="0 0 0" />
    <parent link="leg_r3_link" />
    <child link="leg_r4_link" />
    <axis xyz="0 1 0" />
    <limit lower="0.0" upper="2.53072741539178" effort="280.0" velocity="10.4" />
    <dynamics damping="0.02" friction="0.0" />
  </joint>
  <transmission type="SimpleTransmission">
    <joint name="leg_r4_joint" />
    <actuator name="leg_r4_joint_motor" />
  </transmission>
  <!-- ============ r_foot_pitch ============ -->
  <!-- 坐标系：r_foot_pitch_roll -->
  <link name="leg_r5_link">
    <inertial>
      <!-- 质心：( 0, 0, 0 ) - 质心在原点，无需镜像 -->
      <origin xyz="0 0 0" rpy="0 0 0" />
      <!-- 质量：0.07553705 kg -->
      <mass value="0.07554" />
      <!-- 惯性张量：完全对称，无需改变符号 -->
      <inertia
        ixx="0.00000729"
        ixy="0.00000000"
        ixz="0.00000000"
        iyy="0.00000729"
        iyz="0.00000000"
        izz="0.00001268" />
    </inertial>
    <visual>
      <origin xyz="0 0 0" rpy="0 0 0" />
      <geometry>
        <mesh filename="../../meshes/r_foot_pitch.STL" />
      </geometry>
      <material name="">
        <color rgba="1 1 1 1" />
      </material>
    </visual>
  </link>
  <joint name="leg_r5_joint" type="revolute">
    <origin xyz="0.002 0 -0.416" rpy="0 0 0" />
    <parent link="leg_r4_link" />
    <child link="leg_r5_link" />
    <axis xyz="0 1 0" />
    <limit lower="-0.872664625997165" upper="0.349065850398866" effort="91.6" velocity="17.8" />
    <dynamics damping="0.02" friction="0.0" />
  </joint>
  <transmission type="SimpleTransmission">
    <joint name="leg_r5_joint" />
    <actuator name="leg_r5_joint_motor" />
  </transmission>
  <!-- ============ r_foot_roll ============ -->
  <!-- 坐标系：r_foot_pitch_roll -->
  <link name="leg_r6_link">
    <inertial>
      <!-- 质心：左(0.03005823, -0.00000161, -0.03531089) -> 右(0.03005823, 0.00000161, -0.03531089) -->
      <origin xyz="0.03005823 0.00000161 -0.03531089" rpy="0 0 0" />
      <!-- 质量：0.60537517 kg -->
      <mass value="0.60538" />
      <!-- 惯性张量：ixy/iyz符号取反，ixz保持不变 -->
      <inertia
        ixx="0.00049465"
        ixy="-0.00000004"
        ixz="0.00014546"
        iyy="0.00188391"
        iyz="0.00000000"
        izz="0.00198778" />
    </inertial>
    <visual>
      <origin xyz="0 0 0" rpy="0 0 0" />
      <geometry>
        <mesh filename="../../meshes/r_foot_roll.STL" />
      </geometry>
      <material name="">
        <color rgba="1 1 1 1" />
      </material>
    </visual>
  </link>
  <joint name="leg_r6_joint" type="revolute">
    <origin xyz="0 0 0" rpy="0 0 0" />
    <parent link="leg_r5_link" />
    <child link="leg_r6_link" />
    <axis xyz="1 0 0" />
    <limit lower="-0.261799387799149" upper="0.261799387799149" effort="30.0" velocity="17.8" />
    <dynamics damping="0.02" friction="0.0" />
  </joint>
  <transmission type="SimpleTransmission">
    <joint name="leg_r6_joint" />
    <actuator name="leg_r6_joint_motor" />
  </transmission>
  <frame link="leg_r6_link" name="r_foot_sole" xyz="0.04883799999999999 0.0 -0.0595" />
  <frame link="leg_r6_link" name="r_foot_toe" xyz="0.17084 0.0 -0.0595" />
  <frame link="leg_r6_link" name="r_foot_heel" xyz="-0.073164 0.0 -0.0595" />
</robot>

