<?xml version="1.0" ?>
<!-- =================================================================================== -->
<!-- |    This document was autogenerated by xacro from /home/fandes/workspace/kuavo-ros-control/src/humanoid-control/humanoid_interface_drake/models/biped_gen4.2/urdf/biped_v3.xacro | -->
<!-- |    EDITING THIS FILE BY HAND IS NOT RECOMMENDED                                 | -->
<!-- =================================================================================== -->
<robot name="biped_v3" xmlns:drake="https://drake.mit.edu">
  <link name="torso">
    <inertial>
      <origin xyz="-0.00125701 -0.00011621 0.07634255" rpy="0 0 0" />
      <mass value="11.53225692" />
      <inertia ixx="0.04387174" ixy="-1.165e-05" ixz="-2.045e-05" iyy="0.02873935" iyz="-0.00014024" izz="0.03498757" />
    </inertial>
    <visual>
      <origin xyz="0 0 0" rpy="0 0 0" />
      <geometry>
        <mesh filename="../../meshes/torso.STL" />
      </geometry>
      <material name="">
        <color rgba="1 1 1 1" />
      </material>
    </visual>
  </link>
  <link name="waist">
    <inertial>
      <origin xyz="0.00044512 0.00021941 -0.09828156" rpy="0 0 0" />
      <mass value="3.54871761" />
      <inertia ixx="0.01402915" ixy="5.86e-06" ixz="9.26e-06" iyy="0.00850232" iyz="7.03e-06" izz="0.0108444" />
    </inertial>
    <visual>
      <origin xyz="0 0 0" rpy="0 0 0" />
      <geometry>
        <mesh filename="../../meshes/waist.STL" />
      </geometry>
      <material name="">
        <color rgba="1 1 1 1" />
      </material>
    </visual>
  </link>
  <joint name="waist" type="fixed">
    <origin xyz="0 0 0" rpy="0 0 0" />
    <parent link="torso" />
    <child link="waist" />
    <axis xyz="0 0 1" />
    <limit lower="-2.0943951023932" upper="2.0943951023932" effort="50" velocity="8.37333333333333" />
  </joint>
  <link name="leg_l1_link">
    <inertial>
      <origin xyz="-0.00619745 -0.02691802 0.02588144" rpy="0 0 0" />
      <mass value="0.20744641" />
      <inertia ixx="0.00016479" ixy="-1.387e-05" ixz="1.379e-05" iyy="0.0003572" iyz="2.307e-05" izz="0.00036246" />
    </inertial>
    <visual>
      <origin xyz="0 0 0" rpy="0 0 0" />
      <geometry>
        <mesh filename="../../meshes/l_leg_pitch.STL" />
      </geometry>
      <material name="">
        <color rgba="1 1 1 1" />
      </material>
    </visual>
  </link>
  <joint name="leg_l1_joint" type="revolute">
    <origin xyz="0.0 0.10853553 -0.18853553" rpy="0 0 0" />
    <parent link="waist" />
    <child link="leg_l1_link" />
    <axis xyz="0 0.70711 -0.70711" />
    <limit lower="-2.0943951023932" upper="1.5707963267949" effort="180" velocity="23.55" />
  </joint>
  <transmission type="SimpleTransmission">
    <joint name="leg_l1_joint" />
    <actuator name="leg_l1_joint_motor" />
  </transmission>
  <link name="leg_l2_link">
    <inertial>
      <origin xyz="-0.00098722 0.00077479 -0.00862244" rpy="0 0 0" />
      <mass value="0.98810091" />
      <inertia ixx="0.00121545" ixy="-4.42e-06" ixz="4.324e-05" iyy="0.0012024" iyz="3.023e-05" izz="0.00087397" />
    </inertial>
    <visual>
      <origin xyz="0 0 0" rpy="0 0 0" />
      <geometry>
        <mesh filename="../../meshes/l_leg_roll.STL" />
      </geometry>
      <material name="">
        <color rgba="1 1 1 1" />
      </material>
    </visual>
  </link>
  <joint name="leg_l2_joint" type="revolute">
    <origin xyz="0.00100000000000005 0 0" rpy="0 0 0" />
    <parent link="leg_l1_link" />
    <child link="leg_l2_link" />
    <axis xyz="1 0 0" />
    <limit lower="-1.14668131856027" upper="0.872664625997165" effort="100" velocity="41.3433333333333" />
  </joint>
  <transmission type="SimpleTransmission">
    <joint name="leg_l2_joint" />
    <actuator name="leg_l2_joint_motor" />
  </transmission>
  <link name="leg_l3_link">
    <inertial>
      <origin xyz="-0.01036605 0.00124714 -0.13772711" rpy="0 0 0" />
      <mass value="1.70623945" />
      <inertia ixx="0.0045722" ixy="4.264e-05" ixz="-0.00075108" iyy="0.00491267" iyz="0.00016727" izz="0.00171576" />
    </inertial>
    <visual>
      <origin xyz="0 0 0" rpy="0 0 0" />
      <geometry>
        <mesh filename="../../meshes/l_leg_yaw.STL" />
      </geometry>
      <material name="">
        <color rgba="1 1 1 1" />
      </material>
    </visual>
  </link>
  <joint name="leg_l3_joint" type="revolute">
    <origin xyz="0 0 0" rpy="0 0 0" />
    <parent link="leg_l2_link" />
    <child link="leg_l3_link" />
    <axis xyz="0 0 1" />
    <limit lower="-0.818384886260141" upper="1.5707963267949" effort="100" velocity="41.3433333333333" />
  </joint>
  <transmission type="SimpleTransmission">
    <joint name="leg_l3_joint" />
    <actuator name="leg_l3_joint_motor" />
  </transmission>
  <link name="leg_l4_link">
    <inertial>
      <origin xyz="0.02455489 -0.00415947 -0.1003268" rpy="0 0 0" />
      <mass value="1.33885586" />
      <inertia ixx="0.00557083" ixy="-6.627e-05" ixz="-0.00019424" iyy="0.0057856" iyz="0.00036072" izz="0.00093401" />
    </inertial>
    <visual>
      <origin xyz="0 0 0" rpy="0 0 0" />
      <geometry>
        <mesh filename="../../meshes/l_knee.STL" />
      </geometry>
      <material name="">
        <color rgba="1 1 1 1" />
      </material>
    </visual>
  </link>
  <joint name="leg_l4_joint" type="revolute">
    <origin xyz="-0.0219999999999992 0 -0.183499999999999" rpy="0 0 0" />
    <parent link="leg_l3_link" />
    <child link="leg_l4_link" />
    <axis xyz="0 1 0" />
    <limit lower="0.0" upper="2.61799387799149" effort="180" velocity="23.55" />
  </joint>
  <transmission type="SimpleTransmission">
    <joint name="leg_l4_joint" />
    <actuator name="leg_l4_joint_motor" />
  </transmission>
  <link name="leg_l5_link">
    <inertial>
      <origin xyz="0.0 0.0 0.0" rpy="0 0 0" />
      <mass value="0.07193524" />
      <inertia ixx="6.92e-06" ixy="0.0" ixz="0.0" iyy="6.92e-06" iyz="0.0" izz="1.218e-05" />
    </inertial>
    <visual>
      <origin xyz="0 0 0" rpy="0 0 0" />
      <geometry>
        <mesh filename="../../meshes/l_foot_pitch.STL" />
      </geometry>
      <material name="">
        <color rgba="1 1 1 1" />
      </material>
    </visual>
  </link>
  <joint name="leg_l5_joint" type="revolute">
    <origin xyz="0.0210000000000002 0 -0.234999999999996" rpy="0 0 0" />
    <parent link="leg_l4_link" />
    <child link="leg_l5_link" />
    <axis xyz="0 1 0" />
    <limit lower="-0.872664625997165" upper="0.523598775598299" effort="36" velocity="23.0266666666667" />
  </joint>
  <transmission type="SimpleTransmission">
    <joint name="leg_l5_joint" />
    <actuator name="leg_l5_joint_motor" />
  </transmission>
  <link name="leg_l6_link">
    <inertial>
      <origin xyz="-0.00773988 0.0 -0.02559918" rpy="0 0 0" />
      <mass value="0.37196339" />
      <inertia ixx="0.00016784" ixy="0.0" ixz="8.528e-05" iyy="0.00066357" iyz="0.0" izz="0.00067873" />
    </inertial>
    <visual>
      <origin xyz="0 0 0" rpy="0 0 0" />
      <geometry>
        <mesh filename="../../meshes/l_foot_roll_big.STL" />
      </geometry>
      <material name="">
        <color rgba="1 1 1 1" />
      </material>
    </visual>
  </link>
  <joint name="leg_l6_joint" type="revolute">
    <origin xyz="0 0 0" rpy="0 0 0" />
    <parent link="leg_l5_link" />
    <child link="leg_l6_link" />
    <axis xyz="1 0 0" />
    <limit lower="-0.261799387799149" upper="0.261799387799149" effort="36" velocity="23.0266666666667" />
  </joint>
  <transmission type="SimpleTransmission">
    <joint name="leg_l6_joint" />
    <actuator name="leg_l6_joint_motor" />
  </transmission>
  <!-- sssssssss -->
  <frame link="leg_l6_link" name="l_foot_sole" xyz="0.0185 0.0 -0.0435"/>
  <frame link="leg_l6_link" name="l_foot_toe" xyz="0.126 0.0 -0.0435"/>
  <frame link="leg_l6_link" name="l_foot_heel" xyz="-0.089 0.0 -0.0435"/>
  <link name="leg_r1_link">
    <inertial>
      <origin xyz="-0.00619607 0.02691963 0.02587995" rpy="0 0 0" />
      <mass value="0.20744688" />
      <inertia ixx="0.00016477" ixy="1.385e-05" ixz="1.38e-05" iyy="0.00035721" iyz="-2.306e-05" izz="0.00036244" />
    </inertial>
    <visual>
      <origin xyz="0 0 0" rpy="0 0 0" />
      <geometry>
        <mesh filename="../../meshes/r_leg_pitch.STL" />
      </geometry>
      <material name="">
        <color rgba="1 1 1 1" />
      </material>
    </visual>
  </link>
  <joint name="leg_r1_joint" type="revolute">
    <origin xyz="0.0 -0.10853553 -0.18853553" rpy="0 0 0" />
    <parent link="waist" />
    <child link="leg_r1_link" />
    <axis xyz="0 -0.70711 -0.70711" />
    <limit lower="-1.5707963267949" upper="2.0943951023932" effort="180" velocity="23.55" />
  </joint>
  <transmission type="SimpleTransmission">
    <joint name="leg_r1_joint" />
    <actuator name="leg_r1_joint_motor" />
  </transmission>
  <link name="leg_r2_link">
    <inertial>
      <origin xyz="-0.00091758 -0.00072548 -0.00869132" rpy="0 0 0" />
      <mass value="0.98808814" />
      <inertia ixx="0.00121433" ixy="5.41e-06" ixz="4.213e-05" iyy="0.0011961" iyz="-2.86e-05" izz="0.0008713" />
    </inertial>
    <visual>
      <origin xyz="0 0 0" rpy="0 0 0" />
      <geometry>
        <mesh filename="../../meshes/r_leg_roll.STL" />
      </geometry>
      <material name="">
        <color rgba="1 1 1 1" />
      </material>
    </visual>
  </link>
  <joint name="leg_r2_joint" type="revolute">
    <origin xyz="0.001 0 0" rpy="0 0 0" />
    <parent link="leg_r1_link" />
    <child link="leg_r2_link" />
    <axis xyz="1 0 0" />
    <limit lower="-0.872664625997165" upper="1.14668131856027" effort="100" velocity="41.3433333333333" />
  </joint>
  <transmission type="SimpleTransmission">
    <joint name="leg_r2_joint" />
    <actuator name="leg_r2_joint_motor" />
  </transmission>
  <link name="leg_r3_link">
    <inertial>
      <origin xyz="-0.01040262 -0.00122173 -0.13769028" rpy="0 0 0" />
      <mass value="1.70622839" />
      <inertia ixx="0.00457655" ixy="-4.152e-05" ixz="-0.00075285" iyy="0.00491455" iyz="-0.00016988" izz="0.001716" />
    </inertial>
    <visual>
      <origin xyz="0 0 0" rpy="0 0 0" />
      <geometry>
        <mesh filename="../../meshes/r_leg_yaw.STL" />
      </geometry>
      <material name="">
        <color rgba="1 1 1 1" />
      </material>
    </visual>
  </link>
  <joint name="leg_r3_joint" type="revolute">
    <origin xyz="0 0 0" rpy="0 0 0" />
    <parent link="leg_r2_link" />
    <child link="leg_r3_link" />
    <axis xyz="0 0 1" />
    <limit lower="-1.5707963267949" upper="0.818384886260141" effort="100" velocity="41.3433333333333" />
  </joint>
  <transmission type="SimpleTransmission">
    <joint name="leg_r3_joint" />
    <actuator name="leg_r3_joint_motor" />
  </transmission>
  <link name="leg_r4_link">
    <inertial>
      <origin xyz="0.02457018 0.00415925 -0.10028559" rpy="0 0 0" />
      <mass value="1.33884142" />
      <inertia ixx="0.00556089" ixy="6.661e-05" ixz="-0.00019274" iyy="0.00577497" iyz="-0.00036076" izz="0.00093328" />
    </inertial>
    <visual>
      <origin xyz="0 0 0" rpy="0 0 0" />
      <geometry>
        <mesh filename="../../meshes/r_knee.STL" />
      </geometry>
      <material name="">
        <color rgba="1 1 1 1" />
      </material>
    </visual>
  </link>
  <joint name="leg_r4_joint" type="revolute">
    <origin xyz="-0.022 0 -0.1835" rpy="0 0 0" />
    <parent link="leg_r3_link" />
    <child link="leg_r4_link" />
    <axis xyz="0 1 0" />
    <limit lower="0.0" upper="2.61799387799149" effort="180" velocity="23.55" />
  </joint>
  <transmission type="SimpleTransmission">
    <joint name="leg_r4_joint" />
    <actuator name="leg_r4_joint_motor" />
  </transmission>
  <link name="leg_r5_link">
    <inertial>
      <origin xyz="0.0 0.0 0.0" rpy="0 0 0" />
      <mass value="0.07193524" />
      <inertia ixx="6.92e-06" ixy="0.0" ixz="0.0" iyy="6.92e-06" iyz="0.0" izz="1.218e-05" />
    </inertial>
    <visual>
      <origin xyz="0 0 0" rpy="0 0 0" />
      <geometry>
        <mesh filename="../../meshes/r_foot_pitch.STL" />
      </geometry>
      <material name="">
        <color rgba="1 1 1 1" />
      </material>
    </visual>
  </link>
  <joint name="leg_r5_joint" type="revolute">
    <origin xyz="0.021 0 -0.235" rpy="0 0 0" />
    <parent link="leg_r4_link" />
    <child link="leg_r5_link" />
    <axis xyz="0 1 0" />
    <limit lower="-0.872664625997165" upper="0.523598775598299" effort="36" velocity="23.0266666666667" />
  </joint>
  <transmission type="SimpleTransmission">
    <joint name="leg_r5_joint" />
    <actuator name="leg_r5_joint_motor" />
  </transmission>
  <link name="leg_r6_link">
    <inertial>
      <origin xyz="-0.00773988 0.0 -0.02559918" rpy="0 0 0" />
      <mass value="0.37196339" />
      <inertia ixx="0.00016784" ixy="0.0" ixz="8.528e-05" iyy="0.00066357" iyz="0.0" izz="0.00067873" />
    </inertial>
    <visual>
      <origin xyz="0 0 0" rpy="0 0 0" />
      <geometry>
        <mesh filename="../../meshes/r_foot_roll_big.STL" />
      </geometry>
      <material name="">
        <color rgba="1 1 1 1" />
      </material>
    </visual>
  </link>
  <joint name="leg_r6_joint" type="revolute">
    <origin xyz="0 0 0" rpy="0 0 0" />
    <parent link="leg_r5_link" />
    <child link="leg_r6_link" />
    <axis xyz="1 0 0" />
    <limit lower="-0.261799387799149" upper="0.261799387799149" effort="36" velocity="23.0266666666667" />
  </joint>
  <transmission type="SimpleTransmission">
    <joint name="leg_r6_joint" />
    <actuator name="leg_r6_joint_motor" />
  </transmission>
  <!-- sssssssss -->
  <frame link="leg_r6_link" name="r_foot_sole" xyz="0.0185 0.0 -0.0435"/>
  <frame link="leg_r6_link" name="r_foot_toe" xyz="0.126 0.0 -0.0435"/>
  <frame link="leg_r6_link" name="r_foot_heel" xyz="-0.089 0.0 -0.0435"/>
</robot>

