<?xml version='1.0' encoding='utf-8'?>
<robot name="biped_s14">
  <mujoco>
    <compiler meshdir="../meshes/" balanceinertia="true" discardvisual="false" />
  </mujoco>
  <link name="dummy_link" />
  <link name="base_link">
    <inertial>
      <origin xyz="0.0015256 0.0 -0.11927572" rpy="0 0 0" />
      <mass value="4.60775998" />
      <inertia ixx="0.02101967" ixy="0" ixz="0" iyy="0.01458184" iyz="0" izz="0.01454453" />
    </inertial>
    <visual>
      <origin xyz="0 0 0" rpy="0 0 0" />
      <geometry>
        <mesh filename="package://kuavo_assets/models/biped_s14/meshes/waist.STL" />
      </geometry>
      <material name="">
        <color rgba="1 1 1 1" />
      </material>
    </visual>
    <collision>
      <origin xyz="0.005 0 -0.12" rpy="0 0 0" />
      <geometry>
        <sphere radius="0.08"/>
      </geometry>
    </collision>
  </link>
  <joint name="dummy_to_base_link" type="fixed">
    <origin xyz="0 0 0" rpy="0 0 0" />
    <parent link="dummy_link" />
    <child link="base_link" />
  </joint>
  <link name="leg_l1_link">
    <inertial>
      <origin xyz="-0.00211304 -0.02890487 0.0293713" rpy="0 0 0" />
      <mass value="0.42877473" />
      <inertia ixx="0.00068732" ixy="3.303e-05" ixz="-3.348e-05" iyy="0.00109694" iyz="4.173e-05" izz="0.00108874" />
    </inertial>
    <visual>
      <origin xyz="0 0 0" rpy="0 0 0" />
      <geometry>
        <mesh filename="package://kuavo_assets/models/biped_s14/meshes/l_leg_pitch.STL" />
      </geometry>
      <material name="">
        <color rgba="1 1 1 1" />
      </material>
    </visual>
    <collision>
      <origin xyz="-0.028 -0.02 0.02" rpy="0.786 0 0" />
      <geometry>
        <capsule radius="0.04" length="0.048" />
      </geometry>
    </collision>
    <collision>
      <origin xyz="0.028 -0.02 0.02" rpy="0.786 0 0" />
      <geometry>
        <capsule radius="0.04" length="0.048" />
      </geometry>
    </collision>
  </link>
  <joint name="leg_l1_joint" type="revolute">
    <origin xyz="0.0 0.11751771999999999 -0.21991623" rpy="0 0 0" />
    <parent link="base_link" />
    <child link="leg_l1_link" />
    <axis xyz="0 0.70711 -0.70711" />
    <limit lower="-3.228" upper="2.44346" effort="80.0" velocity="7.0" />
    <dynamics damping="0.2" friction="0.0" />
  </joint>
  <link name="leg_l2_link">
    <inertial>
      <origin xyz="0.0036925 -0.00030734 -0.05334815" rpy="0 0 0" />
      <mass value="2.50010758" />
      <inertia ixx="0.00737592" ixy="0" ixz="0" iyy="0.00723089" iyz="0" izz="0.002556" />
    </inertial>
    <visual>
      <origin xyz="0 0 0" rpy="0 0 0" />
      <geometry>
        <mesh filename="package://kuavo_assets/models/biped_s14/meshes/l_leg_roll.STL" />
      </geometry>
      <material name="">
        <color rgba="1 1 1 1" />
      </material>
    </visual>
    <collision>
      <origin xyz="0 0 -0.045" rpy="0 0 0" />
      <geometry>
        <capsule radius="0.05" length="0.09" />
      </geometry>
    </collision>
  </link>
  <joint name="leg_l2_joint" type="revolute">
    <origin xyz="0 0 0" rpy="0 0 0" />
    <parent link="leg_l1_link" />
    <child link="leg_l2_link" />
    <axis xyz="1 0 0" />
    <limit lower="-0.847008285992848" upper="2.41413942135856" effort="63.0" velocity="10.8" />
    <dynamics damping="0.2" friction="0.0" />
  </joint>
  <link name="leg_l3_link">
    <inertial>
      <origin xyz="-0.01672163 -0.00529551 -0.17406611" rpy="0 0 0" />
      <mass value="1.10966483" />
      <inertia ixx="0.00126836" ixy="0" ixz="0" iyy="0.00154328" iyz="0" izz="0.00122709" />
    </inertial>
    <visual>
      <origin xyz="0 0 0" rpy="0 0 0" />
      <geometry>
        <mesh filename="package://kuavo_assets/models/biped_s14/meshes/l_leg_yaw.STL" />
      </geometry>
      <material name="">
        <color rgba="1 1 1 1" />
      </material>
    </visual>
    <collision>
      <origin xyz="-0.021 0 -0.182" rpy="1.57 0 0" />
      <geometry>
        <capsule radius="0.045" length="0.03" />
      </geometry>
    </collision>
  </link>
  <joint name="leg_l3_joint" type="revolute">
    <origin xyz="0 0 0" rpy="0 0 0" />
    <parent link="leg_l2_link" />
    <child link="leg_l3_link" />
    <axis xyz="0 0 1" />
    <limit lower="-1.66" upper="1.66" effort="80.0" velocity="7.0" />
    <dynamics damping="0.2" friction="0.0" />
  </joint>
  <link name="leg_l4_link">
    <inertial>
      <origin xyz="0.02232088 0.00803122 -0.10490235" rpy="0 0 0" />
      <mass value="1.55001765" />
      <inertia ixx="0.00671114" ixy="0" ixz="0" iyy="0.00671651" iyz="0" izz="0.0012886" />
    </inertial>
    <visual>
      <origin xyz="0 0 0" rpy="0 0 0" />
      <geometry>
        <mesh filename="package://kuavo_assets/models/biped_s14/meshes/l_knee.STL" />
      </geometry>
      <material name="">
        <color rgba="1 1 1 1" />
      </material>
    </visual>
    <collision>
      <origin xyz="0.021 0 -0.15" rpy="0 0 0" />
      <geometry>
        <capsule radius="0.035" length="0.15" />
      </geometry>
    </collision>
    <collision>
      <origin xyz="0.07 0 0.01" rpy="1.57 0 0" />
      <geometry>
        <capsule radius="0.005" length="0.04" />
      </geometry>
    </collision>
    <collision>
      <origin xyz="0.072 0 -0.05" rpy="1.57 0 0" />
      <geometry>
        <capsule radius="0.005" length="0.02" />
      </geometry>
    </collision>
  </link>
  <joint name="leg_l4_joint" type="revolute">
    <origin xyz="-0.0209999999999696 0 -0.181999999999961" rpy="0 0 0" />
    <parent link="leg_l3_link" />
    <child link="leg_l4_link" />
    <axis xyz="0 1 0" />
    <limit lower="0.0" upper="2.61799387799149" effort="63.0" velocity="10.8" />
    <dynamics damping="0.2" friction="0.0" />
  </joint>
  <link name="leg_l5_link">
    <inertial>
      <origin xyz="0.0 0.0 0.0" rpy="0 0 0" />
      <mass value="0.06923766" />
      <inertia ixx="6.7e-04" ixy="0.0" ixz="0.0" iyy="6.7e-04" iyz="0.0" izz="1.172e-04" />
    </inertial>
    <visual>
      <origin xyz="0 0 0" rpy="0 0 0" />
      <geometry>
        <mesh filename="package://kuavo_assets/models/biped_s14/meshes/l_foot_pitch.STL" />
      </geometry>
      <material name="">
        <color rgba="1 1 1 1" />
      </material>
    </visual>
  </link>
  <joint name="leg_l5_joint" type="revolute">
    <origin xyz="0.0209999999999503 0 -0.235000000000001" rpy="0 0 0" />
    <parent link="leg_l4_link" />
    <child link="leg_l5_link" />
    <axis xyz="0 1 0" />
    <limit lower="-0.872664625997165" upper="0.523598775598299" effort="27.0" velocity="10.2" />
    <dynamics damping="0.2" friction="0.0" />
  </joint>
  <link name="leg_l6_link">
    <inertial>
      <origin xyz="-0.0041052 0.0 -0.02650576" rpy="0 0 0" />
      <mass value="0.34819252" />
      <inertia ixx="0.00020982" ixy="0.0" ixz="0" iyy="0.00090207" iyz="0.0" izz="0.00094979" />
    </inertial>
    <visual>
      <origin xyz="0 0 0" rpy="0 0 0" />
      <geometry>
        <mesh filename="package://kuavo_assets/models/biped_s14/meshes/l_foot_roll.STL" />
      </geometry>
      <material name="">
        <color rgba="1 1 1 1" />
      </material>
    </visual>
    <collision>
        <origin xyz="-0.05 0.0 -0.046" rpy="0 0 0"/>
        <geometry>
            <cylinder radius="0.035" length="0.005"/>
        </geometry>
    </collision>
    <collision>
        <origin xyz="0.08 0.0 -0.046" rpy="0 0 0"/>
        <geometry>
            <cylinder radius="0.04" length="0.005"/>
        </geometry>
    </collision>
    <collision>
        <origin xyz="0.01 0.0 -0.046" rpy="0 0 0"/>
        <geometry>
            <box size="0.12 0.07 0.005"/>
        </geometry>
    </collision>
  </link>
  <joint name="leg_l6_joint" type="revolute">
    <origin xyz="0 0 0" rpy="0 0 0" />
    <parent link="leg_l5_link" />
    <child link="leg_l6_link" />
    <axis xyz="1 0 0" />
    <limit lower="-0.261799387799149" upper="0.261799387799149" effort="15.0" velocity="10.2" />
    <dynamics damping="0.2" friction="0.0" />
  </joint>
  <link name="ll_foot_toe">
    <collision>
      <origin rpy="0 0 0" xyz="0 0 0" />
      <geometry>
        <sphere radius="0.005" />
      </geometry>
    </collision>
  </link>
  <joint name="ll_foot_toe_joint" type="fixed">
    <origin xyz="0.121 0.03824834 -0.0435" rpy="0 0 0" />
    <parent link="leg_l6_link" />
    <child link="ll_foot_toe" />
  </joint>
  <link name="ll_foot_heel">
    <collision>
      <origin rpy="0 0 0" xyz="0 0 0" />
      <geometry>
        <sphere radius="0.005" />
      </geometry>
    </collision>
  </link>
  <joint name="ll_foot_heel_joint" type="fixed">
    <origin xyz="-0.084 0.03824834 -0.0435" rpy="0 0 0" />
    <parent link="leg_l6_link" />
    <child link="ll_foot_heel" />
  </joint>
  <link name="lr_foot_toe">
    <collision>
      <origin rpy="0 0 0" xyz="0 0 0" />
      <geometry>
        <sphere radius="0.005" />
      </geometry>
    </collision>
  </link>
  <joint name="lr_foot_toe_joint" type="fixed">
    <origin xyz="0.121 -0.03824834 -0.0435" rpy="0 0 0" />
    <parent link="leg_l6_link" />
    <child link="lr_foot_toe" />
  </joint>
  <link name="lr_foot_heel">
    <collision>
      <origin rpy="0 0 0" xyz="0 0 0" />
      <geometry>
        <sphere radius="0.005" />
      </geometry>
    </collision>
  </link>
  <joint name="lr_foot_heel_joint" type="fixed">
    <origin xyz="-0.084 -0.03824834 -0.0435" rpy="0 0 0" />
    <parent link="leg_l6_link" />
    <child link="lr_foot_heel" />
  </joint>
  <link name="l_foot_toe">
    <collision>
      <origin rpy="0 0 0" xyz="0 0 0" />
      <geometry>
        <sphere radius="0.005" />
      </geometry>
    </collision>
  </link>
  <joint name="l_foot_toe_joint" type="fixed">
    <origin xyz="0.121 0.0 -0.0435" rpy="0 0 0" />
    <parent link="leg_l6_link" />
    <child link="l_foot_toe" />
  </joint>
  <link name="l_foot_heel">
    <collision>
      <origin rpy="0 0 0" xyz="0 0 0" />
      <geometry>
        <sphere radius="0.005" />
      </geometry>
    </collision>
  </link>
  <joint name="l_foot_heel_joint" type="fixed">
    <origin xyz="-0.084 0.0 -0.0435" rpy="0 0 0" />
    <parent link="leg_l6_link" />
    <child link="l_foot_heel" />
  </joint>
  <link name="leg_r1_link">
    <inertial>
      <origin xyz="-0.00211304 0.02890487 0.0293713" rpy="0 0 0" />
      <mass value="0.42877473" />
      <inertia ixx="0.00068732" ixy="-3.303e-05" ixz="-3.348e-05" iyy="0.00109694" iyz="-4.173e-05" izz="0.00108874" />
    </inertial>
    <visual>
      <origin xyz="0 0 0" rpy="0 0 0" />
      <geometry>
        <mesh filename="package://kuavo_assets/models/biped_s14/meshes/r_leg_pitch.STL" />
      </geometry>
      <material name="">
        <color rgba="1 1 1 1" />
      </material>
    </visual>
    <collision>
      <origin xyz="-0.028 0.02 0.02" rpy="-0.786 0 0" />
      <geometry>
        <capsule radius="0.04" length="0.048" />
      </geometry>
    </collision>
    <collision>
      <origin xyz="0.028 0.02 0.02" rpy="-0.786 0 0" />
      <geometry>
        <capsule radius="0.04" length="0.048" />
      </geometry>
    </collision>
  </link>
  <joint name="leg_r1_joint" type="revolute">
    <origin xyz="0.0 -0.11751771999999999 -0.21991623" rpy="0 0 0" />
    <parent link="base_link" />
    <child link="leg_r1_link" />
    <axis xyz="0 -0.70711 -0.70711" />
    <limit lower="-2.44" upper="3.23" effort="80.0" velocity="7.0" />
    <dynamics damping="0.2" friction="0.0" />
  </joint>
  <link name="leg_r2_link">
    <inertial>
      <origin xyz="0.0036925 0.00030734 -0.05334815" rpy="0 0 0" />
      <mass value="2.50010758" />
      <inertia ixx="0.00737592" ixy="0" ixz="0" iyy="0.00723089" iyz="0" izz="0.002556" />
    </inertial>
    <visual>
      <origin xyz="0 0 0" rpy="0 0 0" />
      <geometry>
        <mesh filename="package://kuavo_assets/models/biped_s14/meshes/r_leg_roll.STL" />
      </geometry>
      <material name="">
        <color rgba="1 1 1 1" />
      </material>
    </visual>
    <collision>
      <origin xyz="0 0 -0.045" rpy="0 0 0" />
      <geometry>
        <capsule radius="0.05" length="0.09" />
      </geometry>
    </collision>
  </link>
  <joint name="leg_r2_joint" type="revolute">
    <origin xyz="0 0 0" rpy="0 0 0" />
    <parent link="leg_r1_link" />
    <child link="leg_r2_link" />
    <axis xyz="1 0 0" />
    <limit lower="-2.41" upper="0.845961088441652" effort="63.0" velocity="10.8" />
    <dynamics damping="0.2" friction="0.0" />
  </joint>
  <link name="leg_r3_link">
    <inertial>
      <origin xyz="-0.01672163 0.00529551 -0.17406611" rpy="0 0 0" />
      <mass value="1.10966483" />
      <inertia ixx="0.00126836" ixy="0" ixz="0" iyy="0.00154328" iyz="0" izz="0.00122709" />
    </inertial>
    <visual>
      <origin xyz="0 0 0" rpy="0 0 0" />
      <geometry>
        <mesh filename="package://kuavo_assets/models/biped_s14/meshes/r_leg_yaw.STL" />
      </geometry>
      <material name="">
        <color rgba="1 1 1 1" />
      </material>
    </visual>
    <collision>
      <origin xyz="-0.021 0 -0.182" rpy="1.57 0 0" />
      <geometry>
        <capsule radius="0.045" length="0.03" />
      </geometry>
    </collision>
  </link>
  <joint name="leg_r3_joint" type="revolute">
    <origin xyz="0 0 0" rpy="0 0 0" />
    <parent link="leg_r2_link" />
    <child link="leg_r3_link" />
    <axis xyz="0 0 1" />
    <limit lower="-1.66" upper="1.66" effort="80.0" velocity="7.0" />
    <dynamics damping="0.2" friction="0.0" />
  </joint>
  <link name="leg_r4_link">
    <inertial>
      <origin xyz="0.02232088 -0.00803122 -0.10490235" rpy="0 0 0" />
      <mass value="1.55001765" />
      <inertia ixx="0.00671114" ixy="0" ixz="0" iyy="0.00671651" iyz="0" izz="0.0012886" />
    </inertial>
    <visual>
      <origin xyz="0 0 0" rpy="0 0 0" />
      <geometry>
        <mesh filename="package://kuavo_assets/models/biped_s14/meshes/r_knee.STL" />
      </geometry>
      <material name="">
        <color rgba="1 1 1 1" />
      </material>
    </visual>
    <collision>
      <origin xyz="0.021 0 -0.15" rpy="0 0 0" />
      <geometry>
        <capsule radius="0.035" length="0.15" />
      </geometry>
    </collision>
    <collision>
      <origin xyz="0.07 0 0.01" rpy="1.57 0 0" />
      <geometry>
        <capsule radius="0.005" length="0.04" />
      </geometry>
    </collision>
    <collision>
      <origin xyz="0.072 0 -0.05" rpy="1.57 0 0" />
      <geometry>
        <capsule radius="0.005" length="0.02" />
      </geometry>
    </collision>
  </link>
  <joint name="leg_r4_joint" type="revolute">
    <origin xyz="-0.0209999999999696 0 -0.181999999999961" rpy="0 0 0" />
    <parent link="leg_r3_link" />
    <child link="leg_r4_link" />
    <axis xyz="0 1 0" />
    <limit lower="0.0" upper="2.61799387799149" effort="63.0" velocity="10.8" />
    <dynamics damping="0.2" friction="0.0" />
  </joint>
  <link name="leg_r5_link">
    <inertial>
      <origin xyz="0.0 0.0 0.0" rpy="0 0 0" />
      <mass value="0.06923766" />
      <inertia ixx="6.7e-04" ixy="0.0" ixz="0.0" iyy="6.7e-04" iyz="0.0" izz="1.172e-04" />
    </inertial>
    <visual>
      <origin xyz="0 0 0" rpy="0 0 0" />
      <geometry>
        <mesh filename="package://kuavo_assets/models/biped_s14/meshes/r_foot_pitch.STL" />
      </geometry>
      <material name="">
        <color rgba="1 1 1 1" />
      </material>
    </visual>
  </link>
  <joint name="leg_r5_joint" type="revolute">
    <origin xyz="0.0209999999999503 0 -0.235000000000001" rpy="0 0 0" />
    <parent link="leg_r4_link" />
    <child link="leg_r5_link" />
    <axis xyz="0 1 0" />
    <limit lower="-0.872664625997165" upper="0.523598775598299" effort="27.0" velocity="10.2" />
    <dynamics damping="0.2" friction="0.0" />
  </joint>
  <link name="leg_r6_link">
    <inertial>
      <origin xyz="-0.0041052 0.0 -0.02650576" rpy="0 0 0" />
      <mass value="0.34819252" />
      <inertia ixx="0.00020982" ixy="0.0" ixz="0.0" iyy="0.00090207" iyz="0.0" izz="0.00094979" />
    </inertial>
    <visual>
      <origin xyz="0 0 0" rpy="0 0 0" />
      <geometry>
        <mesh filename="package://kuavo_assets/models/biped_s14/meshes/r_foot_roll.STL" />
      </geometry>
      <material name="">
        <color rgba="1 1 1 1" />
      </material>
    </visual>
    <collision>
        <origin xyz="-0.05 0.0 -0.046" rpy="0 0 0"/>
        <geometry>
            <cylinder radius="0.035" length="0.005"/>
        </geometry>
    </collision>
    <collision>
        <origin xyz="0.08 0.0 -0.046" rpy="0 0 0"/>
        <geometry>
            <cylinder radius="0.04" length="0.005"/>
        </geometry>
    </collision>
    <collision>
        <origin xyz="0.01 0.0 -0.046" rpy="0 0 0"/>
        <geometry>
            <box size="0.12 0.07 0.005"/>
        </geometry>
    </collision>
  </link>
  <joint name="leg_r6_joint" type="revolute">
    <origin xyz="0 0 0" rpy="0 0 0" />
    <parent link="leg_r5_link" />
    <child link="leg_r6_link" />
    <axis xyz="1 0 0" />
    <limit lower="-0.261799387799149" upper="0.261799387799149" effort="15.0" velocity="10.2" />
    <dynamics damping="0.2" friction="0.0" />
  </joint>
  <link name="rl_foot_toe">
    <collision>
      <origin rpy="0 0 0" xyz="0 0 0" />
      <geometry>
        <sphere radius="0.005" />
      </geometry>
    </collision>
  </link>
  <joint name="rl_foot_toe_joint" type="fixed">
    <origin xyz="0.121 0.03824834 -0.0435" rpy="0 0 0" />
    <parent link="leg_r6_link" />
    <child link="rl_foot_toe" />
  </joint>
  <link name="rl_foot_heel">
    <collision>
      <origin rpy="0 0 0" xyz="0 0 0" />
      <geometry>
        <sphere radius="0.005" />
      </geometry>
    </collision>
  </link>
  <joint name="rl_foot_heel_joint" type="fixed">
    <origin xyz="-0.084 0.03824834 -0.0435" rpy="0 0 0" />
    <parent link="leg_r6_link" />
    <child link="rl_foot_heel" />
  </joint>
  <link name="rr_foot_toe">
    <collision>
      <origin rpy="0 0 0" xyz="0 0 0" />
      <geometry>
        <sphere radius="0.005" />
      </geometry>
    </collision>
  </link>
  <joint name="rr_foot_toe_joint" type="fixed">
    <origin xyz="0.121 -0.03824834 -0.0435" rpy="0 0 0" />
    <parent link="leg_r6_link" />
    <child link="rr_foot_toe" />
  </joint>
  <link name="rr_foot_heel">
    <collision>
      <origin rpy="0 0 0" xyz="0 0 0" />
      <geometry>
        <sphere radius="0.005" />
      </geometry>
    </collision>
  </link>
  <joint name="rr_foot_heel_joint" type="fixed">
    <origin xyz="-0.084 -0.03824834 -0.0435" rpy="0 0 0" />
    <parent link="leg_r6_link" />
    <child link="rr_foot_heel" />
  </joint>
  <link name="r_foot_toe">
    <collision>
      <origin rpy="0 0 0" xyz="0 0 0" />
      <geometry>
        <sphere radius="0.005" />
      </geometry>
    </collision>
  </link>
  <joint name="r_foot_toe_joint" type="fixed">
    <origin xyz="0.121 0.0 -0.0435" rpy="0 0 0" />
    <parent link="leg_r6_link" />
    <child link="r_foot_toe" />
  </joint>
  <link name="r_foot_heel">
    <collision>
      <origin rpy="0 0 0" xyz="0 0 0" />
      <geometry>
        <sphere radius="0.005" />
      </geometry>
    </collision>
  </link>
  <joint name="r_foot_heel_joint" type="fixed">
    <origin xyz="-0.084 0.0 -0.0435" rpy="0 0 0" />
    <parent link="leg_r6_link" />
    <child link="r_foot_heel" />
  </joint>
  <link name="waist_yaw_link">
    <inertial>
      <origin xyz="-0.00602072 0.0 0.14657555" rpy="0 0 0" />
      <mass value="8.620776" />
      <inertia ixx="0.08597904" ixy="0" ixz="0" iyy="0.06733076" iyz="0" izz="0.0420581" />
    </inertial>
    <visual>
      <origin xyz="0 0 0" rpy="0 0 0" />
      <geometry>
        <mesh filename="package://kuavo_assets/models/biped_s14/meshes/torso.STL" />
      </geometry>
      <material name="">
        <color rgba="1 1 1 1" />
      </material>
    </visual>
    <collision>
      <origin xyz="0.01 0 0.14" rpy="0 0 0" />
      <geometry>
        <box size="0.14 0.2 0.26" />
      </geometry>
    </collision>
    <collision>
      <origin xyz="-0.09 0 0.285" rpy="1.5708 0 0" />
      <geometry>
        <cylinder radius="0.005" length="0.1" />
      </geometry>
    </collision>
  </link>
  <joint name="waist_yaw_joint" type="revolute">
    <origin xyz="0 0 0" rpy="0 0 0" />
    <parent link="base_link" />
    <child link="waist_yaw_link" />
    <axis xyz="0 0 1" />
    <limit lower="-2.61799387799149" upper="2.61799387799149" effort="80.0" velocity="7.0" />
    <dynamics damping="0.2" friction="0.0" />
  </joint>
  <link name="zarm_l1_link">
    <inertial>
      <origin xyz="0.00360552 -0.00144553 1.956e-05" rpy="0 0 0" />
      <mass value="0.3730157" />
      <inertia ixx="0.00020228" ixy="0" ixz="0" iyy="0.00020881" iyz="0" izz="0.00022776" />
    </inertial>
    <visual>
      <origin xyz="0 0 0" rpy="0 0 0" />
      <geometry>
        <mesh filename="package://kuavo_assets/models/biped_s14/meshes/l_arm_pitch.STL" />
      </geometry>
      <material name="">
        <color rgba="1 1 1 1" />
      </material>
    </visual>
    <collision>
      <origin xyz="0 0 0" rpy="0 1.5708 0" />
      <geometry>
        <capsule radius="0.035" length="0.04" />
      </geometry>
    </collision>
  </link>
  <joint name="zarm_l1_joint" type="revolute">
    <origin xyz="0.00029999 0.17350292 0.23992606" rpy="0 0 0" />
    <parent link="waist_yaw_link" />
    <child link="zarm_l1_link" />
    <axis xyz="0 1 0" />
    <limit lower="-3.14159265358979" upper="2.0943951023932" effort="14.1" velocity="10.5" />
    <dynamics damping="0.2" friction="0.0" />
  </joint>
  <link name="zarm_l2_link">
    <inertial>
      <origin xyz="0.00089424 0.0 -0.04238937" rpy="0 0 0" />
      <mass value="0.15112869" />
      <inertia ixx="0.00017363" ixy="0.0" ixz="0.0" iyy="0.00022693" iyz="0.0" izz="0.00015667" />
    </inertial>
    <visual>
      <origin xyz="0 0 0" rpy="0 0 0" />
      <geometry>
        <mesh filename="package://kuavo_assets/models/biped_s14/meshes/l_arm_roll.STL" />
      </geometry>
      <material name="">
        <color rgba="1 1 1 1" />
      </material>
    </visual>
    <collision>
      <origin xyz="0 0 -0.08" rpy="0 0 0" />
      <geometry>
        <capsule radius="0.035" length="0.06" />
      </geometry>
    </collision>
  </link>
  <joint name="zarm_l2_joint" type="revolute">
    <origin xyz="0 0 0" rpy="0 0 0" />
    <parent link="zarm_l1_link" />
    <child link="zarm_l2_link" />
    <axis xyz="1 0 0" />
    <limit lower="-0.349065850398866" upper="3.49065850398866" effort="14.1" velocity="10.5" />
    <dynamics damping="0.2" friction="0.0" />
  </joint>
  <link name="zarm_l3_link">
    <inertial>
      <origin xyz="-0.00011141 -0.00359387 -0.14417629" rpy="0 0 0" />
      <mass value="0.66922333" />
      <inertia ixx="0.00172455" ixy="-8e-05" ixz="-3e-05" iyy="0.0016933" iyz="-0.00010419" izz="0.00031788" />
    </inertial>
    <visual>
      <origin xyz="0 0 0" rpy="0 0 0" />
      <geometry>
        <mesh filename="package://kuavo_assets/models/biped_s14/meshes/l_arm_yaw.STL" />
      </geometry>
      <material name="">
        <color rgba="1 1 1 1" />
      </material>
    </visual>
  </link>
  <joint name="zarm_l3_joint" type="revolute">
    <origin xyz="0 0 0" rpy="0 0 0" />
    <parent link="zarm_l2_link" />
    <child link="zarm_l3_link" />
    <axis xyz="0 0 1" />
    <limit lower="-1.5707963267949" upper="1.5707963267949" effort="14.1" velocity="10.5" />
    <dynamics damping="0.2" friction="0.0" />
  </joint>
  <link name="zarm_l4_link">
    <inertial>
      <origin xyz="-0.00053745 -0.00090249 -0.13492575" rpy="0 0 0" />
      <mass value="0.56269441" />
      <inertia ixx="0.00085774" ixy="-1.9e-05" ixz="6.3e-05" iyy="0.00081063" iyz="1.372e-05" izz="0.00012136" />
    </inertial>
    <visual>
      <origin xyz="0 0 0" rpy="0 0 0" />
      <geometry>
        <mesh filename="package://kuavo_assets/models/biped_s14/meshes/l_forearm.STL" />
      </geometry>
      <material name="">
        <color rgba="1 1 1 1" />
      </material>
    </visual>
    <collision>
      <origin xyz="0 0 0" rpy="1.57 0 0" />
      <geometry>
        <capsule radius="0.034" length="0.03" />
      </geometry>
    </collision>
    <collision>
      <origin xyz="0 0 -0.1" rpy="0 0 0" />
      <geometry>
        <capsule radius="0.025" length="0.12" />
      </geometry>
    </collision>
    <collision>
      <origin xyz="0 0 -0.2" rpy="0 0 0" />
      <geometry>
        <sphere radius="0.025" />
      </geometry>
    </collision>
  </link>
  <joint name="zarm_l4_joint" type="revolute">
    <origin xyz="0 0 -0.187999999999999" rpy="0 0 0" />
    <parent link="zarm_l3_link" />
    <child link="zarm_l4_link" />
    <axis xyz="0 1 0" />
    <limit lower="-2.26892802759263" upper="0.0" effort="14.1" velocity="10.5" />
    <dynamics damping="0.2" friction="0.0" />
  </joint>
  <link name="zarm_l7_end_effector">
    <collision>
      <origin rpy="0 0 0" xyz="0 0 0" />
      <geometry>
        <sphere radius="0.005" />
      </geometry>
    </collision>
  </link>
  <joint name="zarm_l7_end_effector_joint" type="fixed">
    <origin xyz="0 -0.03 -0.17" rpy="0 0 0" />
    <parent link="zarm_l4_link" />
    <child link="zarm_l7_end_effector" />
  </joint>
  <link name="zarm_r1_link">
    <inertial>
      <origin xyz="0.00360552 0.00144553 1.956e-05" rpy="0 0 0" />
      <mass value="0.3730157" />
      <inertia ixx="0.00020228" ixy="0" ixz="0" iyy="0.00020881" iyz="0" izz="0.00022776" />
    </inertial>
    <visual>
      <origin xyz="0 0 0" rpy="0 0 0" />
      <geometry>
        <mesh filename="package://kuavo_assets/models/biped_s14/meshes/r_arm_pitch.STL" />
      </geometry>
      <material name="">
        <color rgba="1 1 1 1" />
      </material>
    </visual>
    <collision>
      <origin xyz="0 0 0" rpy="0 1.5708 0" />
      <geometry>
        <capsule radius="0.035" length="0.04" />
      </geometry>
    </collision>
  </link>
  <joint name="zarm_r1_joint" type="revolute">
    <origin xyz="0.00029999 -0.17350292 0.23992606" rpy="0 0 0" />
    <parent link="waist_yaw_link" />
    <child link="zarm_r1_link" />
    <axis xyz="0 1 0" />
    <limit lower="-3.14159265358979" upper="2.0943951023932" effort="14.1" velocity="10.5" />
    <dynamics damping="0.2" friction="0.0" />
  </joint>
  <link name="zarm_r2_link">
    <inertial>
      <origin xyz="0.00089424 0.0 -0.04238937" rpy="0 0 0" />
      <mass value="0.15112869" />
      <inertia ixx="0.00017363" ixy="0.0" ixz="0.0" iyy="0.00022693" iyz="0.0" izz="0.00015667" />
    </inertial>
    <visual>
      <origin xyz="0 0 0" rpy="0 0 0" />
      <geometry>
        <mesh filename="package://kuavo_assets/models/biped_s14/meshes/r_arm_roll.STL" />
      </geometry>
      <material name="">
        <color rgba="1 1 1 1" />
      </material>
    </visual>
    <collision>
      <origin xyz="0 0 -0.08" rpy="0 0 0" />
      <geometry>
        <capsule radius="0.035" length="0.06" />
      </geometry>
    </collision>
  </link>
  <joint name="zarm_r2_joint" type="revolute">
    <origin xyz="0 0 0" rpy="0 0 0" />
    <parent link="zarm_r1_link" />
    <child link="zarm_r2_link" />
    <axis xyz="1 0 0" />
    <limit lower="-3.49065850398866" upper="0.349065850398866" effort="14.1" velocity="10.5" />
    <dynamics damping="0.2" friction="0.0" />
  </joint>
  <link name="zarm_r3_link">
    <inertial>
      <origin xyz="-0.00011141 0.00359387 -0.14417629" rpy="0 0 0" />
      <mass value="0.66922057" />
      <inertia ixx="0.00172455" ixy="8e-05" ixz="-3e-05" iyy="0.0016933" iyz="0.00010419" izz="0.00031788" />
    </inertial>
    <visual>
      <origin xyz="0 0 0" rpy="0 0 0" />
      <geometry>
        <mesh filename="package://kuavo_assets/models/biped_s14/meshes/r_arm_yaw.STL" />
      </geometry>
      <material name="">
        <color rgba="1 1 1 1" />
      </material>
    </visual>
  </link>
  <joint name="zarm_r3_joint" type="revolute">
    <origin xyz="0 0 0" rpy="0 0 0" />
    <parent link="zarm_r2_link" />
    <child link="zarm_r3_link" />
    <axis xyz="0 0 1" />
    <limit lower="-1.5707963267949" upper="1.5707963267949" effort="14.1" velocity="10.5" />
    <dynamics damping="0.2" friction="0.0" />
  </joint>
  <link name="zarm_r4_link">
    <inertial>
      <origin xyz="-0.00053745 0.00090249 -0.13492575" rpy="0 0 0" />
      <mass value="0.56269441" />
      <inertia ixx="0.00085774" ixy="1.9e-05" ixz="6.3e-05" iyy="0.00081063" iyz="-1.372e-05" izz="0.00012136" />
    </inertial>
    <visual>
      <origin xyz="0 0 0" rpy="0 0 0" />
      <geometry>
        <mesh filename="package://kuavo_assets/models/biped_s14/meshes/r_forearm.STL" />
      </geometry>
      <material name="">
        <color rgba="1 1 1 1" />
      </material>
    </visual>
    <collision>
      <origin xyz="0 0 0" rpy="1.57 0 0" />
      <geometry>
        <capsule radius="0.034" length="0.03" />
      </geometry>
    </collision>
    <collision>
      <origin xyz="0 0 -0.1" rpy="0 0 0" />
      <geometry>
        <capsule radius="0.025" length="0.12" />
      </geometry>
    </collision>
    <collision>
      <origin xyz="0 0 -0.2" rpy="0 0 0" />
      <geometry>
        <sphere radius="0.025" />
      </geometry>
    </collision>
  </link>
  <joint name="zarm_r4_joint" type="revolute">
    <origin xyz="0 0 -0.187999999999999" rpy="0 0 0" />
    <parent link="zarm_r3_link" />
    <child link="zarm_r4_link" />
    <axis xyz="0 1 0" />
    <limit lower="-2.26892802759263" upper="0.0" effort="14.1" velocity="10.5" />
    <dynamics damping="0.2" friction="0.0" />
  </joint>
  <link name="zarm_r7_end_effector">
    <collision>
      <origin rpy="0 0 0" xyz="0 0 0" />
      <geometry>
        <sphere radius="0.005" />
      </geometry>
    </collision>
  </link>
  <joint name="zarm_r7_end_effector_joint" type="fixed">
    <origin xyz="0 0.03 -0.17" rpy="0 0 0" />
    <parent link="zarm_r4_link" />
    <child link="zarm_r7_end_effector" />
  </joint>
  <link name="zhead_1_link">
    <inertial>
      <origin xyz="-0.00081546 0.0 0.01680967" rpy="0 0 0" />
      <mass value="1.03077542" />
      <inertia ixx="0.00215593" ixy="0" ixz="0" iyy="0.00186198" iyz="0" izz="0.0007462" />
    </inertial>
    <visual>
      <origin xyz="0 0 0" rpy="0 0 0" />
      <geometry>
        <mesh
          filename="package://kuavo_assets/models/biped_s14/meshes/head_yaw.STL" />
      </geometry>
      <material name="">
        <color rgba="1 1 1 1" />
      </material>
    </visual>
    <collision>
      <origin xyz="0 0 0" rpy="0 0 0" />
      <geometry>
        <capsule radius="0.035" length="0.1" />
      </geometry>
    </collision>
  </link>
  <joint name="zhead_1_joint" type="revolute">
    <origin xyz="0 0 0.35618885" rpy="0 0 0" />
    <parent link="waist_yaw_link" />
    <child link="zhead_1_link" />
    <axis xyz="0 0 1" />
    <limit lower="-1.5707963267949" upper="1.5707963267949" effort="1.5" velocity="5.23" />
    <dynamics damping="0.2" friction="0.0" />
  </joint>
  <link name="zhead_2_link">
    <inertial>
      <origin xyz="0.01466399 0.0 0.05742895" rpy="0 0 0" />
      <mass value="0.33654975" />
      <inertia ixx="0.00121758" ixy="0" ixz="0" iyy="0.00141543" iyz="0" izz="0.00148598" />
    </inertial>
    <visual>
      <origin xyz="0 0 0" rpy="0 0 0" />
      <geometry>
        <mesh filename="package://kuavo_assets/models/biped_s14/meshes/head_pitch.STL" />
      </geometry>
      <material name="">
        <color rgba="1 1 1 1" />
      </material>
    </visual>
    <collision>
      <origin xyz="0 0 0.035" rpy="0 0 0" />
      <geometry>
        <sphere radius="0.075" />
      </geometry>
    </collision>
  </link>
  <joint name="zhead_2_joint" type="revolute">
    <origin xyz="0 0 0" rpy="0 0 0" />
    <parent link="zhead_1_link" />
    <child link="zhead_2_link" />
    <axis xyz="0 1 0" />
    <limit lower="-0.349065850398866" upper="0.785398163397448" effort="12.0" velocity="5.23" />
    <dynamics damping="0.2" friction="0.0" />
  </joint>
  <link name="camera">
    <inertial>
      <origin xyz="-0.0070337 -0.011323 -0.00015273" rpy="0 0 0" />
      <mass value="0.000011119" />
      <inertia ixx="9.6895E-06" ixy="-4.491E-07" ixz="-3.7878E-09" iyy="1.1202E-06" iyz="-3.8935E-10" izz="9.3246E-06" />
    </inertial>
    <visual>
      <origin xyz="0 0 0" rpy="0 0 0" />
      <geometry>
        <mesh filename="package://kuavo_assets/models/biped_s14/meshes/camera.STL" />
      </geometry>
      <material name="">
        <color rgba="1 1 1 1" />
      </material>
    </visual>
  </link>
  <joint name="camera_joint" type="fixed">
    <origin xyz="0.069468 0.0112 0.057945" rpy="-0.014569 0.27114 -0.054347" />
    <parent link="zhead_2_link" />
    <child link="camera" />
    <axis xyz="0 0 0" />
  </joint>
  <link name="camera_base">
    <inertial>
      <origin xyz="-1.3878E-17 -2.7105E-20 0.001" rpy="0 0 0" />
      <mass value="0.00003927" />
      <inertia ixx="7.4449E-11" ixy="-7.3468E-39" ixz="3.2312E-27" iyy="7.4449E-11" iyz="1.072E-27" izz="1.2272E-10" />
    </inertial>
    <visual>
      <origin xyz="0 0 0" rpy="0 0 0" />
      <geometry>
        <mesh filename="package://kuavo_assets/models/biped_s14/meshes/camera_base.STL" />
      </geometry>
      <material name="">
        <color rgba="1 1 1 1" />
      </material>
    </visual>
    <collision>
      <origin xyz="0 0 0" rpy="0 0 0" />
      <geometry>
        <mesh filename="package://kuavo_assets/models/biped_s14/meshes/camera_base.STL" />
      </geometry>
    </collision>
  </link>
  <joint name="camera_base_joint" type="fixed">
    <origin xyz="0.049912 0.0002 0.050414" rpy="0 0.27152 0" />
    <parent link="zhead_2_link" />
    <child link="camera_base" />
    <axis xyz="0 0 0" />
  </joint>
</robot>
