<?xml version="1.0" ?>
<!-- =================================================================================== -->
<!-- |    This document was autogenerated by xacro from /home/fandes/workspace/kuavo-ros-control/src/humanoid-control/humanoid_interface_drake/models/biped_gen4.2/urdf/biped_v3.xacro | -->
<!-- |    EDITING THIS FILE BY HAND IS NOT RECOMMENDED                                 | -->
<!-- =================================================================================== -->
<robot name="biped_v3" xmlns:drake="https://drake.mit.edu">
  <link name="torso">
    <inertial>
      <origin xyz="0.0016929 0.0 -0.11846153" rpy="0 0 0" />
      <mass value="3.17438719" />
      <inertia ixx="0.02255479" ixy="0.0" ixz="0.0" iyy="0.01532956" iyz="0.0" izz="0.0166717" />
    </inertial>
    <visual>
      <origin xyz="0 0 0" rpy="0 0 0" />
      <geometry>
        <mesh filename="../../meshes/waist.STL" />
      </geometry>
      <material name="">
        <color rgba="1 1 1 1" />
      </material>
    </visual>
  </link>
  <link name="waist_yaw_link">
    <inertial>
      <origin xyz="0.00227055 0.0 0.1163574" rpy="0 0 0" />
      <mass value="11.23288758" />
      <inertia ixx="0.06356019" ixy="0.0" ixz="0.0" iyy="0.05314952" iyz="0.0" izz="0.03434989" />
    </inertial>
    <visual>
      <origin xyz="0 0 0" rpy="0 0 0" />
      <geometry>
        <mesh filename="../../meshes/torso.STL" />
      </geometry>
      <material name="">
        <color rgba="1 1 1 1" />
      </material>
    </visual>
  </link>
  <joint name="waist_yaw_joint" type="fixed">
    <origin xyz="0 0 0" rpy="0 0 0" />
    <parent link="torso" />
    <child link="waist_yaw_link" />
    <axis xyz="0 0 1" />
    <limit lower="-2.0943951023932" upper="2.0943951023932" effort="50" velocity="8.37333333333333" />
  </joint>
  <link name="leg_l1_link">
    <inertial>
      <origin xyz="-0.01281625 -0.02411867 0.0242652" rpy="0 0 0" />
      <mass value="0.41179806" />
      <inertia ixx="0.00053434" ixy="-1.716e-05" ixz="1.637e-05" iyy="0.00095375" iyz="6.321e-05" izz="0.00095062" />
    </inertial>
    <visual>
      <origin xyz="0 0 0" rpy="0 0 0" />
      <geometry>
        <mesh filename="../../meshes/l_leg_pitch.STL" />
      </geometry>
      <material name="">
        <color rgba="1 1 1 1" />
      </material>
    </visual>
  </link>
  <joint name="leg_l1_joint" type="revolute">
    <origin xyz="0.0 0.1143350698 -0.21673502307" rpy="0 0 0" />
    <parent link="torso" />
    <child link="leg_l1_link" />
    <axis xyz="0 0.70711 -0.70711" />
    <limit lower="-1.65806278939461" upper="1.5707963267949" effort="180" velocity="23.55" />
  </joint>
  <transmission type="SimpleTransmission">
    <joint name="leg_l1_joint" />
    <actuator name="leg_l1_joint_motor" />
  </transmission>
  <link name="leg_l2_link">
    <inertial>
      <origin xyz="-0.00113407 0.00022674 -0.055039" rpy="0 0 0" />
      <mass value="2.60733021" />
      <inertia ixx="0.00748166" ixy="0.0" ixz="0.0" iyy="0.00726718" iyz="0.0" izz="0.00283326" />
    </inertial>
    <visual>
      <origin xyz="0 0 0" rpy="0 0 0" />
      <geometry>
        <mesh filename="../../meshes/l_leg_roll.STL" />
      </geometry>
      <material name="">
        <color rgba="1 1 1 1" />
      </material>
    </visual>
  </link>
  <joint name="leg_l2_joint" type="revolute">
    <origin xyz="0 0 0" rpy="0 0 0" />
    <parent link="leg_l1_link" />
    <child link="leg_l2_link" />
    <axis xyz="1 0 0" />
    <limit lower="-1.0471975511966" upper="0.847008285992848" effort="100" velocity="41.3433333333333" />
  </joint>
  <transmission type="SimpleTransmission">
    <joint name="leg_l2_joint" />
    <actuator name="leg_l2_joint_motor" />
  </transmission>
  <link name="leg_l3_link">
    <inertial>
      <origin xyz="-0.01486413 -0.00438159 -0.17562576" rpy="0 0 0" />
      <mass value="1.03798929" />
      <inertia ixx="0.00130665" ixy="0.0" ixz="0.0" iyy="0.00143771" iyz="0.0" izz="0.00092289" />
    </inertial>
    <visual>
      <origin xyz="0 0 0" rpy="0 0 0" />
      <geometry>
        <mesh filename="../../meshes/l_leg_yaw.STL" />
      </geometry>
      <material name="">
        <color rgba="1 1 1 1" />
      </material>
    </visual>
  </link>
  <joint name="leg_l3_joint" type="revolute">
    <origin xyz="0 0 0" rpy="0 0 0" />
    <parent link="leg_l2_link" />
    <child link="leg_l3_link" />
    <axis xyz="0 0 1" />
    <limit lower="-1.91986217719376" upper="0.878424212528746" effort="100" velocity="41.3433333333333" />
  </joint>
  <transmission type="SimpleTransmission">
    <joint name="leg_l3_joint" />
    <actuator name="leg_l3_joint_motor" />
  </transmission>
  <link name="leg_l4_link">
    <inertial>
      <origin xyz="0.02276414 0.00634133 -0.09717249" rpy="0 0 0" />
      <mass value="1.78407172" />
      <inertia ixx="0.00775509" ixy="0.0" ixz="0.0" iyy="0.00820174" iyz="0.0" izz="0.00156093" />
    </inertial>
    <visual>
      <origin xyz="0 0 0" rpy="0 0 0" />
      <geometry>
        <mesh filename="../../meshes/l_knee.STL" />
      </geometry>
      <material name="">
        <color rgba="1 1 1 1" />
      </material>
    </visual>
  </link>
  <joint name="leg_l4_joint" type="revolute">
    <origin xyz="-0.021 0 -0.182" rpy="0 0 0" />
    <parent link="leg_l3_link" />
    <child link="leg_l4_link" />
    <axis xyz="0 1 0" />
    <limit lower="0.0" upper="2.61799387799149" effort="180" velocity="23.55" />
  </joint>
  <transmission type="SimpleTransmission">
    <joint name="leg_l4_joint" />
    <actuator name="leg_l4_joint_motor" />
  </transmission>
  <link name="leg_l5_link">
    <inertial>
      <origin xyz="0.0 0.0 0.0" rpy="0 0 0" />
      <mass value="0.06923766" />
      <inertia ixx="6.7e-05" ixy="0.0" ixz="0.0" iyy="6.7e-05" iyz="0.0" izz="1.172e-05" />
    </inertial>
    <visual>
      <origin xyz="0 0 0" rpy="0 0 0" />
      <geometry>
        <mesh filename="../../meshes/l_foot_pitch.STL" />
      </geometry>
      <material name="">
        <color rgba="1 1 1 1" />
      </material>
    </visual>
  </link>
  <joint name="leg_l5_joint" type="revolute">
    <origin xyz="0.021 0 -0.235" rpy="0 0 0" />
    <parent link="leg_l4_link" />
    <child link="leg_l5_link" />
    <axis xyz="0 1 0" />
    <limit lower="-0.872664625997165" upper="0.523598775598299" effort="36" velocity="23.0266666666667" />
  </joint>
  <transmission type="SimpleTransmission">
    <joint name="leg_l5_joint" />
    <actuator name="leg_l5_joint_motor" />
  </transmission>
  <link name="leg_l6_link">
    <inertial>
      <origin xyz="-0.00076721 2.797e-05 -0.02337788" rpy="0 0 0" />
      <mass value="0.38565431" />
      <inertia ixx="0.00026927" ixy="0.0" ixz="0.0" iyy="0.00114572" iyz="0.0" izz="0.00129886" />
    </inertial>
    <visual>
      <origin xyz="0 0 0" rpy="0 0 0" />
      <geometry>
        <mesh filename="../../meshes/l_foot_roll.STL" />
      </geometry>
      <material name="">
        <color rgba="1 1 1 1" />
      </material>
    </visual>
  </link>
  <joint name="leg_l6_joint" type="revolute">
    <origin xyz="0 0 0" rpy="0 0 0" />
    <parent link="leg_l5_link" />
    <child link="leg_l6_link" />
    <axis xyz="1 0 0" />
    <limit lower="-0.261799387799149" upper="0.261799387799149" effort="36" velocity="23.0266666666667" />
  </joint>
  <transmission type="SimpleTransmission">
    <joint name="leg_l6_joint" />
    <actuator name="leg_l6_joint_motor" />
  </transmission>
  <frame link="leg_l6_link" name="l_foot_sole" xyz="0.0 0.0 -0.0435" />
  <frame link="leg_l6_link" name="l_foot_toe" xyz="0.126 0.0 -0.0435" />
  <frame link="leg_l6_link" name="l_foot_heel" xyz="-0.089 0.0 -0.0435" />
  <link name="leg_r1_link">
    <inertial>
      <origin xyz="-0.01281237 0.02411826 0.02426469" rpy="0 0 0" />
      <mass value="0.4119068" />
      <inertia ixx="0.00053445" ixy="1.725e-05" ixz="1.639e-05" iyy="0.00095388" iyz="-6.324e-05" izz="0.00095076" />
    </inertial>
    <visual>
      <origin xyz="0 0 0" rpy="0 0 0" />
      <geometry>
        <mesh filename="../../meshes/r_leg_pitch.STL" />
      </geometry>
      <material name="">
        <color rgba="1 1 1 1" />
      </material>
    </visual>
  </link>
  <joint name="leg_r1_joint" type="revolute">
    <origin xyz="0.0 -0.1143350698 -0.21673502307" rpy="0 0 0" />
    <parent link="torso" />
    <child link="leg_r1_link" />
    <axis xyz="0 -0.70711 -0.70711" />
    <limit lower="-1.65806278939461" upper="1.5707963267949" effort="180" velocity="23.55" />
  </joint>
  <transmission type="SimpleTransmission">
    <joint name="leg_r1_joint" />
    <actuator name="leg_r1_joint_motor" />
  </transmission>
  <link name="leg_r2_link">
    <inertial>
      <origin xyz="-0.00091249 -5.402e-05 -0.0552687" rpy="0 0 0" />
      <mass value="2.60770806" />
      <inertia ixx="0.00748166" ixy="0.0" ixz="0.0" iyy="0.00726718" iyz="0.0" izz="0.00283326" />
    </inertial>
    <visual>
      <origin xyz="0 0 0" rpy="0 0 0" />
      <geometry>
        <mesh filename="../../meshes/r_leg_roll.STL" />
      </geometry>
      <material name="">
        <color rgba="1 1 1 1" />
      </material>
    </visual>
  </link>
  <joint name="leg_r2_joint" type="revolute">
    <origin xyz="0 0 0" rpy="0 0 0" />
    <parent link="leg_r1_link" />
    <child link="leg_r2_link" />
    <axis xyz="1 0 0" />
    <limit lower="-1.0471975511966" upper="0.847008285992848" effort="100" velocity="41.3433333333333" />
  </joint>
  <transmission type="SimpleTransmission">
    <joint name="leg_r2_joint" />
    <actuator name="leg_r2_joint_motor" />
  </transmission>
  <link name="leg_r3_link">
    <inertial>
      <origin xyz="-0.0150602 0.00499577 -0.17454657" rpy="0 0 0" />
      <mass value="1.03798252" />
      <inertia ixx="0.00130665" ixy="0.0" ixz="0.0" iyy="0.00143771" iyz="0.0" izz="0.00092289" />
    </inertial>
    <visual>
      <origin xyz="0 0 0" rpy="0 0 0" />
      <geometry>
        <mesh filename="../../meshes/r_leg_yaw.STL" />
      </geometry>
      <material name="">
        <color rgba="1 1 1 1" />
      </material>
    </visual>
  </link>
  <joint name="leg_r3_joint" type="revolute">
    <origin xyz="0 0 0" rpy="0 0 0" />
    <parent link="leg_r2_link" />
    <child link="leg_r3_link" />
    <axis xyz="0 0 1" />
    <limit lower="-1.91986217719376" upper="0.878424212528746" effort="100" velocity="41.3433333333333" />
  </joint>
  <transmission type="SimpleTransmission">
    <joint name="leg_r3_joint" />
    <actuator name="leg_r3_joint_motor" />
  </transmission>
  <link name="leg_r4_link">
    <inertial>
      <origin xyz="0.02271993 -0.0079271 -0.09808788" rpy="0 0 0" />
      <mass value="1.78444026" />
      <inertia ixx="0.00775509" ixy="0.0" ixz="0.0" iyy="0.00820174" iyz="0.0" izz="0.00156093" />
    </inertial>
    <visual>
      <origin xyz="0 0 0" rpy="0 0 0" />
      <geometry>
        <mesh filename="../../meshes/r_knee.STL" />
      </geometry>
      <material name="">
        <color rgba="1 1 1 1" />
      </material>
    </visual>
  </link>
  <joint name="leg_r4_joint" type="revolute">
    <origin xyz="-0.021 0 -0.182" rpy="0 0 0" />
    <parent link="leg_r3_link" />
    <child link="leg_r4_link" />
    <axis xyz="0 1 0" />
    <limit lower="0.0" upper="2.61799387799149" effort="180" velocity="23.55" />
  </joint>
  <transmission type="SimpleTransmission">
    <joint name="leg_r4_joint" />
    <actuator name="leg_r4_joint_motor" />
  </transmission>
  <link name="leg_r5_link">
    <inertial>
      <origin xyz="0.0 0.0 0.0" rpy="0 0 0" />
      <mass value="0.06923766" />
      <inertia ixx="6.7e-05" ixy="0.0" ixz="0.0" iyy="6.7e-05" iyz="0.0" izz="1.172e-05" />
    </inertial>
    <visual>
      <origin xyz="0 0 0" rpy="0 0 0" />
      <geometry>
        <mesh filename="../../meshes/r_foot_pitch.STL" />
      </geometry>
      <material name="">
        <color rgba="1 1 1 1" />
      </material>
    </visual>
  </link>
  <joint name="leg_r5_joint" type="revolute">
    <origin xyz="0.021 0 -0.235" rpy="0 0 0" />
    <parent link="leg_r4_link" />
    <child link="leg_r5_link" />
    <axis xyz="0 1 0" />
    <limit lower="-0.872664625997165" upper="0.523598775598299" effort="36" velocity="23.0266666666667" />
  </joint>
  <transmission type="SimpleTransmission">
    <joint name="leg_r5_joint" />
    <actuator name="leg_r5_joint_motor" />
  </transmission>
  <link name="leg_r6_link">
    <inertial>
      <origin xyz="-0.00075494 -2.665e-05 -0.02339266" rpy="0 0 0" />
      <mass value="0.38537958" />
      <inertia ixx="0.00026927" ixy="0.0" ixz="0.0" iyy="0.00114572" iyz="0.0" izz="0.00129886" />
    </inertial>
    <visual>
      <origin xyz="0 0 0" rpy="0 0 0" />
      <geometry>
        <mesh filename="../../meshes/r_foot_roll.STL" />
      </geometry>
      <material name="">
        <color rgba="1 1 1 1" />
      </material>
    </visual>
  </link>
  <joint name="leg_r6_joint" type="revolute">
    <origin xyz="0 0 0" rpy="0 0 0" />
    <parent link="leg_r5_link" />
    <child link="leg_r6_link" />
    <axis xyz="1 0 0" />
    <limit lower="-0.261799387799149" upper="0.261799387799149" effort="36" velocity="23.0266666666667" />
  </joint>
  <transmission type="SimpleTransmission">
    <joint name="leg_r6_joint" />
    <actuator name="leg_r6_joint_motor" />
  </transmission>
  <frame link="leg_r6_link" name="r_foot_sole" xyz="0.0 0.0 -0.0435" />
  <frame link="leg_r6_link" name="r_foot_toe" xyz="0.126 0.0 -0.0435" />
  <frame link="leg_r6_link" name="r_foot_heel" xyz="-0.089 0.0 -0.0435" />
</robot>
