<?xml version="1.0" ?>
<!-- =================================================================================== -->
<!-- |    This document was autogenerated by xacro from /home/fandes/workspace/kuavo-ros-control/src/humanoid-control/humanoid_interface_drake/models/biped_gen4.0/urdf/biped_v3_arm.xacro | -->
<!-- |    EDITING THIS FILE BY HAND IS NOT RECOMMENDED                                 | -->
<!-- =================================================================================== -->
<robot name="biped_v3_arm" xmlns:drake="https://drake.mit.edu">
  <link name="torso">
    <inertial>
      <origin xyz="0.0016929 2.043e-05 -0.11846153" rpy="0 0 0" />
      <mass value="5.17438719" />
      <inertia ixx="0.02255479" ixy="4.3e-05" ixz="-6.6e-05" iyy="0.01532956" iyz="1.7e-05" izz="0.0166717" />
    </inertial>
    <visual>
      <origin xyz="0 0 0" rpy="0 0 0" />
      <geometry>
        <mesh filename="../../meshes/waist.STL" />
      </geometry>
      <material name="">
        <color rgba="1 1 1 1" />
      </material>
    </visual>
  </link>
  <link name="waist_yaw_link">
    <inertial>
      <origin xyz="0.00227055 6.536e-05 0.1163574" rpy="0 0 0" />
      <mass value="7.34228758" />
      <inertia ixx="0.06356019" ixy="-4.28e-05" ixz="0.00087983" iyy="0.05314952" iyz="1.365e-05" izz="0.03434989" />
    </inertial>
    <visual>
      <origin xyz="0 0 0" rpy="0 0 0" />
      <geometry>
        <mesh filename="../../meshes/torso.STL" />
      </geometry>
      <material name="">
        <color rgba="1 1 1 1" />
      </material>
    </visual>
  </link>
  <joint name="waist_yaw_joint" type="fixed">
    <origin xyz="0 0 0" rpy="0 0 0" />
    <parent link="torso" />
    <child link="waist_yaw_link" />
    <axis xyz="0 0 1" />
    <limit lower="-2.0943951023932" upper="2.0943951023932" effort="50" velocity="8.37333333333333" />
  </joint>
  <!-- =========================================================== Arms ================================================================= -->
  <link name="zarm_l1_link">
    <inertial>
      <origin xyz="0.00335591 -0.00249177 1.895e-05" rpy="0 0 0" />
      <mass value="0.44491793" />
      <inertia ixx="0.00028057" ixy="3.5e-05" ixz="2.3e-05" iyy="0.00024754" iyz="7e-05" izz="0.0002873" />
    </inertial>
    <visual>
      <origin xyz="0 0 0" rpy="0 0 0" />
      <geometry>
        <mesh filename="../../meshes/l_arm_pitch.STL" />
      </geometry>
      <material name="">
        <color rgba="1 1 1 1" />
      </material>
    </visual>
  </link>
  <joint name="zarm_l1_joint" type="revolute">
    <origin xyz="0.0073474151 0.16250437899999998 0.20242688398" rpy="0 0 0" />
    <parent link="waist_yaw_link" />
    <child link="zarm_l1_link" />
    <axis xyz="0 1 0" />
    <limit lower="-3.14159265358979" upper="0.0" effort="12" velocity="7.32666666666667" />
  </joint>
  <transmission type="SimpleTransmission">
    <joint name="zarm_l1_joint" />
    <actuator name="zarm_l1_joint_motor" />
  </transmission>
  <link name="zarm_l2_link">
    <inertial>
      <origin xyz="0.00025941 0.0 -0.03684584" rpy="0 0 0" />
      <mass value="0.2598439" />
      <inertia ixx="0.0003221" ixy="0.0" ixz="-6.2e-05" iyy="0.00043526" iyz="0.0" izz="0.00030902" />
    </inertial>
    <visual>
      <origin xyz="0 0 0" rpy="0 0 0" />
      <geometry>
        <mesh filename="../../meshes/l_arm_roll.STL" />
      </geometry>
      <material name="">
        <color rgba="1 1 1 1" />
      </material>
    </visual>
  </link>
  <joint name="zarm_l2_joint" type="revolute">
    <origin xyz="0 0 0" rpy="0 0 0" />
    <parent link="zarm_l1_link" />
    <child link="zarm_l2_link" />
    <axis xyz="1 0 0" />
    <limit lower="-0.349065850398866" upper="3.49065850398866" effort="12" velocity="7.32666666666667" />
  </joint>
  <transmission type="SimpleTransmission">
    <joint name="zarm_l2_joint" />
    <actuator name="zarm_l2_joint_motor" />
  </transmission>
  <link name="zarm_l3_link">
    <inertial>
      <origin xyz="-0.0001383 -0.00323921 -0.14314847" rpy="0 0 0" />
      <mass value="0.77406554" />
      <inertia ixx="0.00201794" ixy="-2.6e-05" ixz="-3e-05" iyy="0.00198657" iyz="-0.00011116" izz="0.00042873" />
    </inertial>
    <visual>
      <origin xyz="0 0 0" rpy="0 0 0" />
      <geometry>
        <mesh filename="../../meshes/l_arm_yaw.STL" />
      </geometry>
      <material name="">
        <color rgba="1 1 1 1" />
      </material>
    </visual>
  </link>
  <joint name="zarm_l3_joint" type="revolute">
    <origin xyz="0 0 0" rpy="0 0 0" />
    <parent link="zarm_l2_link" />
    <child link="zarm_l3_link" />
    <axis xyz="0 0 1" />
    <limit lower="-1.5707963267949" upper="1.5707963267949" effort="12" velocity="7.32666666666667" />
  </joint>
  <transmission type="SimpleTransmission">
    <joint name="zarm_l3_joint" />
    <actuator name="zarm_l3_joint_motor" />
  </transmission>
  <link name="zarm_l4_link">
    <inertial>
      <origin xyz="-0.00091965 -2.274e-05 -0.06567892" rpy="0 0 0" />
      <mass value="0.2274965" />
      <inertia ixx="0.00109021" ixy="-6.4e-05" ixz="8.8e-05" iyy="0.00099134" iyz="-1.9e-05" izz="0.00021171" />
    </inertial>
    <visual>
      <origin xyz="0 0 0" rpy="0 0 0" />
      <geometry>
        <mesh filename="../../meshes/l_forearm.STL" />
      </geometry>
      <material name="">
        <color rgba="1 1 1 1" />
      </material>
    </visual>
  </link>
  <joint name="zarm_l4_joint" type="revolute">
    <origin xyz="0 0 -0.188" rpy="0 0 0" />
    <parent link="zarm_l3_link" />
    <child link="zarm_l4_link" />
    <axis xyz="0 1 0" />
    <limit lower="-2.26892802759263" upper="0.0" effort="12" velocity="7.32666666666667" />
  </joint>
  <transmission type="SimpleTransmission">
    <joint name="zarm_l4_joint" />
    <actuator name="zarm_l4_joint_motor" />
  </transmission>
  <link name="zarm_r1_link">
    <inertial>
      <origin xyz="0.00335581 0.00249177 1.809e-05" rpy="0 0 0" />
      <mass value="0.44491659" />
      <inertia ixx="0.00028057" ixy="-3.5e-05" ixz="2.4e-05" iyy="0.00024753" iyz="-6e-05" izz="0.00028729" />
    </inertial>
    <visual>
      <origin xyz="0 0 0" rpy="0 0 0" />
      <geometry>
        <mesh filename="../../meshes/r_arm_pitch.STL" />
      </geometry>
      <material name="">
        <color rgba="1 1 1 1" />
      </material>
    </visual>
  </link>
  <joint name="zarm_r1_joint" type="revolute">
    <origin xyz="0.0073474151 -0.16250437899999998 0.20242688398" rpy="0 0 0" />
    <parent link="waist_yaw_link" />
    <child link="zarm_r1_link" />
    <axis xyz="0 1 0" />
    <limit lower="-3.14159265358979" upper="0.0" effort="12" velocity="7.32666666666667" />
  </joint>
  <transmission type="SimpleTransmission">
    <joint name="zarm_r1_joint" />
    <actuator name="zarm_r1_joint_motor" />
  </transmission>
  <link name="zarm_r2_link">
    <inertial>
      <origin xyz="0.0002594 0.0 -0.03684556" rpy="0 0 0" />
      <mass value="0.25983512" />
      <inertia ixx="0.00032209" ixy="0.0" ixz="-6.2e-05" iyy="0.00043526" iyz="0.0" izz="0.00030901" />
    </inertial>
    <visual>
      <origin xyz="0 0 0" rpy="0 0 0" />
      <geometry>
        <mesh filename="../../meshes/r_arm_roll.STL" />
      </geometry>
      <material name="">
        <color rgba="1 1 1 1" />
      </material>
    </visual>
  </link>
  <joint name="zarm_r2_joint" type="revolute">
    <origin xyz="0 0 0" rpy="0 0 0" />
    <parent link="zarm_r1_link" />
    <child link="zarm_r2_link" />
    <axis xyz="1 0 0" />
    <limit lower="-3.49065850398866" upper="0.349065850398866" effort="12" velocity="7.32666666666667" />
  </joint>
  <transmission type="SimpleTransmission">
    <joint name="zarm_r2_joint" />
    <actuator name="zarm_r2_joint_motor" />
  </transmission>
  <link name="zarm_r3_link">
    <inertial>
      <origin xyz="-0.00013784 0.00323927 -0.14314868" rpy="0 0 0" />
      <mass value="0.774042" />
      <inertia ixx="0.00201792" ixy="2.6e-05" ixz="-3e-05" iyy="0.00198653" iyz="0.00011115" izz="0.00042871" />
    </inertial>
    <visual>
      <origin xyz="0 0 0" rpy="0 0 0" />
      <geometry>
        <mesh filename="../../meshes/r_arm_yaw.STL" />
      </geometry>
      <material name="">
        <color rgba="1 1 1 1" />
      </material>
    </visual>
  </link>
  <joint name="zarm_r3_joint" type="revolute">
    <origin xyz="0 0 0" rpy="0 0 0" />
    <parent link="zarm_r2_link" />
    <child link="zarm_r3_link" />
    <axis xyz="0 0 1" />
    <limit lower="-1.5707963267949" upper="1.5707963267949" effort="12" velocity="7.32666666666667" />
  </joint>
  <transmission type="SimpleTransmission">
    <joint name="zarm_r3_joint" />
    <actuator name="zarm_r3_joint_motor" />
  </transmission>
  <link name="zarm_r4_link">
    <inertial>
      <origin xyz="-0.00091857 2.37e-05 -0.06568304" rpy="0 0 0" />
      <mass value="0.22747514" />
      <inertia ixx="0.00109014" ixy="6.5e-05" ixz="8.8e-05" iyy="0.00099128" iyz="1.7e-05" izz="0.00021169" />
    </inertial>
    <visual>
      <origin xyz="0 0 0" rpy="0 0 0" />
      <geometry>
        <mesh filename="../../meshes/r_forearm.STL" />
      </geometry>
      <material name="">
        <color rgba="1 1 1 1" />
      </material>
    </visual>
  </link>
  <joint name="zarm_r4_joint" type="revolute">
    <origin xyz="0 0 -0.188" rpy="0 0 0" />
    <parent link="zarm_r3_link" />
    <child link="zarm_r4_link" />
    <axis xyz="0 1 0" />
    <limit lower="-2.26892802759263" upper="0.0" effort="12" velocity="7.32666666666667" />
  </joint>
  <transmission type="SimpleTransmission">
    <joint name="zarm_r4_joint" />
    <actuator name="zarm_r4_joint_motor" />
  </transmission>
  <!-- end frame -->
  <!-- <frame link="l_hand_pitch" name="l_hand_sole" xyz="0 0 -0.1" /> -->
  <!-- end frame -->
  <!-- <frame link="r_hand_pitch" name="r_hand_sole" xyz="0 0 -0.1" /> -->
</robot>
