<?xml version='1.0' encoding='utf-8'?>
<mujoco model="biped_s48">
  <compiler angle="radian" meshdir="../meshes/" />
  <size njmax="500" nconmax="100" />
  <default>
    <joint limited="true" armature="0.05" damping="0.02" frictionloss="0.02"/>
    <motor ctrllimited="true" ctrlrange="-100 100"/>
    <!-- <geom contype="1" conaffinity="1" condim="1" solref="0.005 1"/> -->
    <equality solref="0.005 1"/>
    <default class="collision">
      <!-- User parameter for geoms is used to identify collision types -->
      <geom material="collision" contype="4" conaffinity="4" user="2" rgba="0.9 0.3 0.3 0.2"/>
      <default class="collision-left">
        <geom contype="1" conaffinity="2" rgba="0.3 0.9 0.3 0.2"/>
      </default>
      <default class="collision-right">
        <geom contype="2" conaffinity="1" rgba="0.3 0.3 0.9 0.2"/>
      </default>
    </default>
  </default>
  <asset>
    <texture type="skybox" builtin="gradient" rgb1="0.4 0.6 0.8" width="128" height="128"/>
    <texture name="grid" type="2d" builtin="checker" rgb1=".1 .2 .3" rgb2=".2 .3 .4" width="300" height="300"/>
    <material name="grid" texture="grid" texrepeat="8 8" reflectance=".1"/>
    <material name="collision" rgba="0.1 0.5 0.9 0"/>
    <mesh name="torso" file="torso.STL" />
    <mesh name="l_leg_roll" file="l_leg_roll.STL" />
    <mesh name="l_leg_yaw" file="l_leg_yaw.STL" />
    <mesh name="l_leg_pitch" file="l_leg_pitch.STL" />
    <mesh name="l_knee" file="l_knee.STL" />
    <mesh name="l_foot_pitch" file="l_foot_pitch.STL" />
    <mesh name="l_foot_roll" file="l_foot_roll.STL" />
    <mesh name="r_leg_roll" file="r_leg_roll.STL" />
    <mesh name="r_leg_yaw" file="r_leg_yaw.STL" />
    <mesh name="r_leg_pitch" file="r_leg_pitch.STL" />
    <mesh name="r_knee" file="r_knee.STL" />
    <mesh name="r_foot_pitch" file="r_foot_pitch.STL" />
    <mesh name="r_foot_roll" file="r_foot_roll.STL" />
    <mesh name="l_arm_pitch" file="l_arm_pitch.STL" />
    <mesh name="l_arm_roll" file="l_arm_roll.STL" />
    <mesh name="l_arm_yaw" file="l_arm_yaw.STL" />
    <mesh name="l_forearm" file="l_forearm.STL" />
    <mesh name="l_hand_yaw" file="l_hand_yaw.STL" />
    <mesh name="l_hand_roll" file="l_hand_roll.STL" />
    <mesh name="l_hand_pitch" file="l_hand_pitch.STL" />
    <mesh name="r_arm_pitch" file="r_arm_pitch.STL" />
    <mesh name="r_arm_roll" file="r_arm_roll.STL" />
    <mesh name="r_arm_yaw" file="r_arm_yaw.STL" />
    <mesh name="r_forearm" file="r_forearm.STL" />
    <mesh name="r_hand_yaw" file="r_hand_yaw.STL" />
    <mesh name="r_hand_roll" file="r_hand_roll.STL" />
    <mesh name="r_hand_pitch" file="r_hand_pitch.STL" />
    <mesh name="head_yaw" file="head_yaw.STL" />
    <mesh name="head_pitch" file="head_pitch.STL" />
    <mesh name="camera" file="camera.STL" />
    <mesh name="radar" file="radar.STL" />
    <mesh name="l_palm" file="l_palm.STL" />
    <mesh name="l_thumb_prox" file="l_thumb_prox.STL" />
    <mesh name="l_thumb_dist" file="l_thumb_dist.STL" />
    <mesh name="l_Index_prox" file="l_Index_prox.STL" />
    <mesh name="l_index_dist" file="l_index_dist.STL" />
    <mesh name="l_middle_prox" file="l_middle_prox.STL" />
    <mesh name="l_middle_dist" file="l_middle_dist.STL" />
    <mesh name="l_ring_prox" file="l_ring_prox.STL" />
    <mesh name="l_ring_dist" file="l_ring_dist.STL" />
    <mesh name="l_little_prox" file="l_little_prox.STL" />
    <mesh name="l_little_dist" file="l_little_dist.STL" />
    <mesh name="r_palm" file="r_palm.STL" />
    <mesh name="r_thumb_prox" file="r_thumb_prox.STL" />
    <mesh name="r_thumb_dist" file="r_thumb_dist.STL" />
    <mesh name="r_index_prox" file="r_index_prox.STL" />
    <mesh name="r_index_dist" file="r_index_dist.STL" />
    <mesh name="r_middle_prox" file="r_middle_prox.STL" />
    <mesh name="r_middle_dist" file="r_middle_dist.STL" />
    <mesh name="r_ring_prox" file="r_ring_prox.STL" />
    <mesh name="r_ring_dist" file="r_ring_dist.STL" />
    <mesh name="r_little_prox" file="r_little_prox.STL" />
    <mesh name="r_little_dist" file="r_little_dist.STL" />
  </asset>
  <worldbody>
    <body name="base_link" pos="0 0 0.82">
      <freejoint />
      <site name="imu" pos="0 0 0" />
      <inertial pos="-0.00761 0.00182 0.21995" quat="0.998529 4.54328e-05 0.0542216 0.000512508" mass="27.2560" diaginertia="0.938886 0.825905 0.269012" />
      <geom type="mesh" contype="0" conaffinity="0" group="1" density="0" rgba="1 1 1 1" mesh="torso" />
      <geom size="0.14 0.06" pos="-0.01 0 0.4" quat="0.707388 0.706825 0 0" type="capsule" group="3"  class="collision"/>
      <geom size="0.13 0.04" pos="0 0 0.13" type="capsule" group="3"  class="collision"/>

      <body name="leg_l1_link" pos="-0.0024999 0.087 -0.066">
        <inertial pos="-0.00430148 -2.708e-05 -0.00851195" quat="-0.000746146 0.721814 -0.00298446 0.69208" mass="1.71093" diaginertia="0.00371121 0.00277272 0.00205799"/>
        <joint name="leg_l1_joint" pos="0 0 0" axis="1 0 0" range="-0.314159 0.663225" actuatorfrcrange="-127 127" armature="0.05" damping="0.02" frictionloss="0.02" />
        <geom type="mesh" contype="0" conaffinity="0" group="1" density="0" rgba="1 1 1 1" mesh="l_leg_roll" />
        <geom size="0.06 0.035" pos="-0.105 0 0" quat="0.707105 0 -0.707108 0" type="cylinder" group="3"  class="collision-left"/>
        <body name="leg_l2_link">
          <inertial pos="0 -0.00231118 -0.0906254" quat="0.696411 0.717644 -1.38707e-05 1.34603e-05" mass="0.580292" diaginertia="0.00223984 0.00146412 0.00123154"/>
          <joint name="leg_l2_joint" pos="0 0 0" axis="0 0 1" range="-0.872665 0.785398" actuatorfrcrange="-22.2 22.2" armature="0.05" damping="0.02" frictionloss="0.02" />
          <geom type="mesh" contype="0" conaffinity="0" group="1" density="0" rgba="1 1 1 1" mesh="l_leg_yaw" />
          <body name="leg_l3_link" pos="0.000500355 -0.001 -0.1287">
            <inertial pos="0.00150537 0.0119961 -0.0841162" quat="0.783717 0.018124 -0.0364866 0.619781" mass="4.50393" diaginertia="0.0396246 0.0389355 0.00980214"/>
            <joint name="leg_l3_joint" pos="0 0 0" axis="0 1 0" range="-2.00713 1.5708" actuatorfrcrange="-72 72" armature="0.05" damping="0.02" frictionloss="0.02" />
            <geom type="mesh" contype="0" conaffinity="0" group="1" density="0" rgba="1 1 1 1" mesh="l_leg_pitch" />
            <geom type='cylinder' size='0.06' fromto='0 -0.07 0 0 0.07 0' group="3"  class="collision-left"/>
            <geom type='capsule' size='0.06' fromto='0 0 0 0 0 -0.25' group="3"  class="collision-left"/>
            <body name="leg_l4_link" pos="-6.87185e-05 0 -0.284">
              <inertial pos="0.00696242 5.314e-05 -0.115499" quat="0.99996 -0.00125674 -0.00257659 -0.00848361" mass="1.62777" diaginertia="0.0124395 0.0122957 0.000978994"/>
              <joint name="leg_l4_joint" pos="0 0 0" axis="0 1 0" range="0 2.53073" actuatorfrcrange="-135 135" armature="0.05" damping="0.02" frictionloss="0.02" />
              <geom type="mesh" contype="0" conaffinity="0" group="1" density="0" rgba="1 1 1 1" mesh="l_knee" />
              <geom type='capsule' size='0.04' fromto='0 0 0 0 0 -0.34' group="3"  class="collision-left"/>
              <body name="leg_l5_link" pos="-0.000431636 0 -0.346">
                <inertial pos="0 0 0" quat="0.5 0.5 -0.5 0.5" mass="0.0719352" diaginertia="1.218e-05 6.92e-06 6.92e-06" />
                <joint name="leg_l5_joint" pos="0 0 0" axis="0 1 0" range="-0.872665 0.349066" actuatorfrcrange="-46 46" armature="0.05" damping="0.02" frictionloss="0.02" />
                <geom type="mesh" contype="0" conaffinity="0" group="1" density="0" rgba="1 1 1 1" mesh="l_foot_pitch" />
                <body name="leg_l6_link">
                  <site name="l_ft_frame" pos="0 0 0" size="0.02 0.02 0.02" rgba="1 1 1 1" type="box" group="3"/>
                  <inertial pos="0.0373996 -2.2061e-06 -0.0389691" quat="1.14784e-05 0.71913 -5.49597e-06 0.694876" mass="0.501754" diaginertia="0.00177936 0.00163509 0.000396929"/>
                  <joint name="leg_l6_joint" pos="0 0 0" axis="1 0 0" range="-0.261799 0.261799" actuatorfrcrange="-30 30" armature="0.05" damping="0.02" frictionloss="0.02" />
                  <geom type="mesh" contype="0" conaffinity="0" group="1" density="0" rgba="1 1 1 1" mesh="l_foot_roll" />
                  <geom type="capsule" size="0.008" fromto="-0.008 -0.046 -0.044 -0.008  0.046 -0.044" group="3"  class="collision-left"/>
                  <geom type="capsule" size="0.008" fromto="-0.016 -0.046 -0.051 -0.016  0.046 -0.051" group="3"  class="collision-left"/>
                  <geom type="box" size="0.045 0.05 0.0054" pos="0.042 0 -0.041" group="3"  class="collision-left"/>
                  <geom type="capsule" size="0.008" fromto="-0.063 -0.038 -0.054 -0.063  0.038 -0.054" group="3"  class="collision-left"/>
                  <geom type="box" size="0.021 0.048 0.0054" pos="-0.036 0 -0.054" group="3"  class="collision-left"/>
                  <geom type="capsule" size="0.008" fromto="0.09 -0.046 -0.043 0.09  0.046 -0.043" group="3"  class="collision-left"/>
                  <geom type="capsule" size="0.008" fromto="0.1 -0.046 -0.046 0.1  0.046 -0.046" group="3"  class="collision-left"/>
                  <geom type="capsule" size="0.008" fromto="0.109 -0.046 -0.05 0.109  0.046 -0.05" group="3"  class="collision-left"/>
                  <geom type="capsule" size="0.008" fromto="0.12 -0.046 -0.053 0.12  0.046 -0.053" group="3"  class="collision-left"/>
                  <geom type="capsule" size="0.008" fromto="0.13 -0.046 -0.054 0.13  0.046 -0.054" group="3"  class="collision-left"/>
                  <geom type="capsule" size="0.008" fromto="0.139 -0.041 -0.054 0.139  0.041 -0.054" group="3"  class="collision-left"/>
                  <geom type="capsule" size="0.008" fromto="0.152 -0.032 -0.054 0.152 0.032 -0.054" group="3"  class="collision-left"/>
                  <geom type="capsule" size="0.008" fromto="0.165 -0.02 -0.054 0.165  0.02 -0.054" group="3"  class="collision-left"/>
                </body>
              </body>
            </body>
          </body>
        </body>
      </body>
      <body name="leg_r1_link" pos="-0.0024999 -0.087 -0.066">
        <inertial pos="-0.00430146 2.709e-05 -0.00851195" quat="0.000746146 0.721814 0.00298446 0.69208" mass="1.71093" diaginertia="0.00371121 0.00277272 0.00205799"/>
        <joint name="leg_r1_joint" pos="0 0 0" axis="1 0 0" range="-0.663225 0.314159" actuatorfrcrange="-127 127" armature="0.05" damping="0.02" frictionloss="0.02" />
        <geom type="mesh" contype="0" conaffinity="0" group="1" density="0" rgba="1 1 1 1" mesh="r_leg_roll" />
        <geom type='cylinder' size='0.06' fromto='-0.14 0 0 -0.07 0 0' group="3"  class="collision-right"/>
        <body name="leg_r2_link">
          <inertial pos="0 0.00231118 -0.0906254" quat="0.717644 0.696411 1.34603e-05 -1.38707e-05" mass="0.580292" diaginertia="0.00223984 0.00146412 0.00123154"/>
          <joint name="leg_r2_joint" pos="0 0 0" axis="0 0 1" range="-0.785398 0.872665" actuatorfrcrange="-22.2 22.2" armature="0.05" damping="0.02" frictionloss="0.02" />
          <geom type="mesh" contype="0" conaffinity="0" group="1" density="0" rgba="1 1 1 1" mesh="r_leg_yaw" />
          <body name="leg_r3_link" pos="-4.88007e-05 0 -0.1287">
            <inertial pos="0.00208315 -0.0119964 -0.0841138" quat="0.619803 -0.0366218 0.0180205 0.783696" mass="4.50386" diaginertia="0.0396237 0.0389344 0.00980197"/>
            <joint name="leg_r3_joint" pos="0 0 0" axis="0 1 0" range="-2.00713 1.5708" actuatorfrcrange="-72 72" armature="0.05" damping="0.02" frictionloss="0.02" />
            <geom type="mesh" contype="0" conaffinity="0" group="1" density="0" rgba="1 1 1 1" mesh="r_leg_pitch" />
            <geom type='cylinder' size='0.06' fromto='0 -0.07 0 0 0.07 0' group="3"  class="collision-right"/>
            <geom type='capsule' size='0.06' fromto='0 0 0 0 0 -0.25' group="3"  class="collision-right"/>
            <body name="leg_r4_link" pos="0.000147139 0 -0.284">
              <inertial pos="0.00743231 -5.343e-05 -0.115587" quat="0.999959 0.0012612 -0.00276098 0.00849144" mass="1.62656" diaginertia="0.012413 0.0122692 0.00097885"/>
              <joint name="leg_r4_joint" pos="0 0 0" axis="0 1 0" range="0 2.53073" actuatorfrcrange="-135 135" armature="0.05" damping="0.02" frictionloss="0.02" />
              <geom type="mesh" contype="0" conaffinity="0" group="1" density="0" rgba="1 1 1 1" mesh="r_knee" />
              <geom type='capsule' size='0.04' fromto='0 0 0 0 0 -0.34' group="3"  class="collision-right"/>
              <body name="leg_r5_link" pos="0.000119806 0 -0.346">
                <inertial pos="0 0 0" quat="0.5 0.5 -0.5 0.5" mass="0.0719352" diaginertia="1.218e-05 6.92e-06 6.92e-06" />
                <joint name="leg_r5_joint" pos="0 0 0" axis="0 1 0" range="-0.872665 0.349066" actuatorfrcrange="-46 46" armature="0.05" damping="0.02" frictionloss="0.02" />
                <geom type="mesh" contype="0" conaffinity="0" group="1" density="0" rgba="1 1 1 1" mesh="r_foot_pitch" />
                <body name="leg_r6_link">
                  <site name="r_ft_frame" pos="0 0 0" size="0.02 0.02 0.02" rgba="1 1 1 1" type="box" group="3"/>
                  <inertial pos="0.037413 -2.2061e-06 -0.0389563" quat="1.14537e-05 0.719014 -5.52258e-06 0.694996" mass="0.501754" diaginertia="0.00177936 0.00163509 0.000396923"/>
                  <joint name="leg_r6_joint" pos="0 0 0" axis="1 0 0" range="-0.261799 0.261799" actuatorfrcrange="-30 30" armature="0.05" damping="0.02" frictionloss="0.02" />
                  <geom type="mesh" contype="0" conaffinity="0" group="1" density="0" rgba="1 1 1 1" mesh="r_foot_roll" />
                  <geom type="box" size="0.045 0.05 0.0054" pos="0.042 0 -0.041" group="3"  class="collision-right"/>
                  <geom type="capsule" size="0.008" fromto="-0.008 -0.046 -0.044 -0.008  0.046 -0.044" group="3"  class="collision-right"/>
                  <geom type="capsule" size="0.008" fromto="-0.016 -0.046 -0.051 -0.016  0.046 -0.051" group="3"  class="collision-right"/>
                  <geom type="capsule" size="0.008" fromto="-0.063 -0.038 -0.054 -0.063  0.038 -0.054" group="3"  class="collision-right"/>
                  <geom type="box" size="0.021 0.048 0.0054" pos="-0.036 0 -0.054" group="3"  class="collision-right"/>
                  <geom type="capsule" size="0.008" fromto="0.09 -0.046 -0.043 0.09  0.046 -0.043" group="3"  class="collision-right"/>
                  <geom type="capsule" size="0.008" fromto="0.1 -0.046 -0.046 0.1  0.046 -0.046" group="3"  class="collision-right"/>
                  <geom type="capsule" size="0.008" fromto="0.109 -0.046 -0.05 0.109  0.046 -0.05" group="3"  class="collision-right"/>
                  <geom type="capsule" size="0.008" fromto="0.12 -0.046 -0.053 0.12  0.046 -0.053" group="3"  class="collision-right"/>
                  <geom type="capsule" size="0.008" fromto="0.13 -0.046 -0.054 0.13  0.046 -0.054" group="3"  class="collision-right"/>
                  <geom type="capsule" size="0.008" fromto="0.139 -0.041 -0.054 0.139  0.041 -0.054" group="3"  class="collision-right"/>
                  <geom type="capsule" size="0.008" fromto="0.152 -0.032 -0.054 0.152 0.032 -0.054" group="3"  class="collision-right"/>
                  <geom type="capsule" size="0.008" fromto="0.165 -0.02 -0.054 0.165  0.02 -0.054" group="3"  class="collision-right"/>
                </body>
              </body>
            </body>
          </body>
        </body>
      </body>
      <body name="zarm_l1_link" pos="-0.0174999 0.2927 0.4245">
        <inertial pos="0.00194934 -0.0122207 -0.00024523" quat="0.707107 0.706685 -0.00777912 -0.0231186" mass="0.952" diaginertia="0.00178126 0.00174474 0.000879208"/>
        <joint name="zarm_l1_joint" pos="0 0 0" axis="0 1 0" range="-3.14159 1.5708" actuatorfrcrange="-66.67 66.67" armature="0.05" damping="0.02" frictionloss="0.02" />
        <geom type="mesh" contype="0" conaffinity="0" group="1" density="0" rgba="1 1 1 1" mesh="l_arm_pitch" />
        <geom type="capsule" size="0.05 0.02" quat="0.707105 0 0.707108 0" group="3"  class="collision-left"/>
        <body name="zarm_l2_link">
          <inertial pos="-0.00112901 0.00000665 -0.04637050" quat="0.704818 0.0555201 0.0557454 0.705012" mass="0.385" diaginertia="0.00115579 0.000807069 0.000697401"/>
          <joint name="zarm_l2_joint" pos="0 0 0" axis="1 0 0" range="-0.349066 2.0944" actuatorfrcrange="-75 75" armature="0.05" damping="0.02" frictionloss="0.02" />
          <geom type="mesh" contype="0" conaffinity="0" group="1" density="0" rgba="1 1 1 1" mesh="l_arm_roll" />
          <body name="zarm_l3_link">
            <inertial pos="0.00936999 0.00334408 -0.229658" quat="0.937426 0.0561381 -0.061759 -0.338033" mass="1.7545" diaginertia="0.00708615 0.00705081 0.00168974"/>
            <joint name="zarm_l3_joint" pos="0 0 0" axis="0 0 1" range="-1.5708 1.5708" actuatorfrcrange="-57 57" armature="0.05" damping="0.02" frictionloss="0.02" />
            <geom type="mesh" contype="0" conaffinity="0" group="1" density="0" rgba="1 1 1 1" mesh="l_arm_yaw" />
            <geom type="capsule" size="0.045 0.07" pos="0 0 -0.18" group="3"  class="collision-left"/>
            <body name="zarm_l4_link" pos="0.02 0 -0.2837">
              <inertial pos="-0.0182563 0.00149605 -0.0687769" quat="0.99685 -0.0272991 0.07434 -0.00421608" mass="0.6078" diaginertia="0.0014636 0.00125932 0.00063048"/>
              <joint name="zarm_l4_joint" pos="0 0 0" axis="0 1 0" range="-2.61799 0" actuatorfrcrange="-75 75" armature="0.05" damping="0.02" frictionloss="0.02" />
              <geom type="mesh" contype="0" conaffinity="0" group="1" density="0" rgba="1 1 1 1" mesh="l_forearm" />
              <geom type="capsule" size="0.045 0.09" pos="-0.02 0 -0.14" group="3"  class="collision-left"/>
              <body name="zarm_l5_link" pos="-0.02 0 -0.127037">
                <inertial pos="-0.00874165 -1.372e-05 -0.0503332" quat="0.690034 0.154059 0.154039 0.690211" mass="0.6369" diaginertia="0.00094941 0.000663622 0.000516408"/>
                <joint name="zarm_l5_joint" pos="0 0 0" axis="0 0 1" range="-1.5708 1.5708" actuatorfrcrange="-14.1 14.1" armature="0.05" damping="0.02" frictionloss="0.02" />
                <geom type="mesh" contype="0" conaffinity="0" group="1" density="0" rgba="1 1 1 1" mesh="l_hand_yaw" />
                <body name="zarm_l6_link" pos="0.0002 0 -0.106463">
                  <inertial pos="-0.00158864 0.00654094 -0.0150668" quat="0.126491 0.725864 0.203587 0.644727" mass="0.4739" diaginertia="0.000274263 0.000250357 0.000178721"/>
                  <joint name="zarm_l6_joint" pos="0 0 0" axis="1 0 0" range="-1.309 0.698132" actuatorfrcrange="-14.1 14.1" armature="0.05" damping="0.02" frictionloss="0.02" />
                  <geom type="mesh" contype="0" conaffinity="0" group="1" density="0" rgba="1 1 1 1" mesh="l_hand_roll" />
                  <body name="zarm_l7_link" pos="0 0 -0.0210005">
                    <inertial pos="0.00556076 0.014547 -0.077823" quat="0.784821 -0.129166 0.119653 0.594185" mass="0.716601" diaginertia="0.00296397 0.0028177 0.000438519"/>
                    <joint name="zarm_l7_joint" pos="0 0 0" axis="0 1 0" range="-0.698132 0.698132" actuatorfrcrange="-14.1 14.1" armature="0.05" damping="0.02" frictionloss="0.02" />
                    <geom type="mesh" contype="0" conaffinity="0" group="1" density="0" rgba="1 1 1 1" mesh="l_hand_pitch" />
                    <geom size="0.005" pos="0 -0.03 -0.17" />
                    <body name="l_palm" pos="0 0 -0.07" quat="0.000563312 -0.000562864 0.706825 -0.707388">
                      <inertial pos="0.0017239 0.0051432 -0.031065" quat="1 0 0 0" mass="0.427" diaginertia="0.0010405 0.0013244 0.00053219" />
                      <geom type="mesh" contype="0" conaffinity="0" group="1" density="0" rgba="0.75294 0.75294 0.75294 1" mesh="l_palm" />
                    </body>
                    <body name="l_thumb_prox" pos="0.024537 -0.023242 -0.0926135" quat="0.349346 -0.374856 0.58539 -0.628298">
                        <inertial pos="0.0017239 0.0051432 -0.031065" quat="0.663344 0.00923928 0.0504839 0.746552" mass="0.005" diaginertia="9e-05 7e-05 5e-05" />
                        <joint name="l_thumbCMC" pos="0 0 0" axis="0 1 0" limited="true" range="0 1.5708" damping="1.0" />
                        <geom type="mesh" contype="0" conaffinity="0" group="1" rgba="0.75294 0.75294 0.75294 1" mesh="l_thumb_prox" />
                        <geom type="mesh" rgba="0.75294 0.75294 0.75294 1" mesh="l_thumb_prox" />
                        <body name="l_thumb_dist" pos="0 0 0.013647" quat="0.878534 0.409665 -0.222652 0.103824">
                            <inertial pos="0.0017239 0.0051432 -0.031065" quat="0.663344 0.00923928 0.0504839 0.746552" mass="0.04" diaginertia="9e-05 7e-05 5e-05" />
                            <joint name="l_thumbMCP" pos="0 0 0" axis="-1 0 0" limited="true" range="0 0.8727" damping="1.0" />
                            <geom type="mesh" contype="0" conaffinity="0" group="1" rgba="0.75294 0.75294 0.75294 1" mesh="l_thumb_dist" />
                            <geom type="mesh" rgba="0.75294 0.75294 0.75294 1" mesh="l_thumb_dist" />
                        </body>
                    </body>
                    <body name="l_Index_prox" pos="0.0290066 -0.00223961 -0.158289" quat="-0.00514945 0.0303624 0.71714 -0.696248">
                        <inertial pos="0.0017239 0.0051432 -0.031065" quat="0.663344 0.00923928 0.0504839 0.746552" mass="0.008" diaginertia="9e-05 7e-05 5e-05" />
                        <joint name="l_indexMCP" pos="0 0 0" axis="1 0 0" limited="true" range="0 1.309" damping="1.0" />
                        <geom type="mesh" contype="0" conaffinity="0" group="1" rgba="0.75294 0.75294 0.75294 1" mesh="l_Index_prox" />
                        <geom type="mesh" rgba="0.75294 0.75294 0.75294 1" mesh="l_Index_prox" />
                        <body name="l_index_dist" pos="0 0.035 0" quat="0.995322 0.0966141 0 0">
                            <inertial pos="0.0017239 0.0051432 -0.031065" quat="0.663344 0.00923928 0.0504839 0.746552" mass="0.011" diaginertia="9e-05 7e-05 5e-05" />
                            <joint name="l_indexPIP" pos="0 0 0" axis="1 0 0" limited="true" range="0 2.0944" damping="1.0" />
                            <geom type="mesh" contype="0" conaffinity="0" group="1" rgba="0.75294 0.75294 0.75294 1" mesh="l_index_dist" />
                            <geom type="mesh" rgba="0.75294 0.75294 0.75294 1" mesh="l_index_dist" />
                        </body>
                    </body>
                    <body name="l_middle_prox" pos="0.00799729 0.00170995 -0.162285" quat="0.000563312 -0.000562864 0.706825 -0.707388">
                        <inertial pos="0.0017239 0.0051432 -0.031065" quat="0.663344 0.00923928 0.0504839 0.746552" mass="0.011" diaginertia="9e-05 7e-05 5e-05" />
                        <joint name="l_middleMCP" pos="0 0 0" axis="1 0 0" limited="true" range="0 1.309" damping="1.0" />
                        <geom type="mesh" contype="0" conaffinity="0" group="1" rgba="0.75294 0.75294 0.75294 1" mesh="l_middle_prox" />
                        <geom type="mesh" rgba="0.75294 0.75294 0.75294 1" mesh="l_middle_prox" />
                        <body name="l_middle_dist" pos="0 0.042 0" quat="0.995791 0.0916562 0 0">
                            <inertial pos="0.0017239 0.0051432 -0.031065" quat="0.663344 0.00923928 0.0504839 0.746552" mass="0.011" diaginertia="9e-05 7e-05 5e-05" />
                            <joint name="l_middlePIP" pos="0 0 0" axis="1 0 0" limited="true" range="0 2.0944" damping="1.0" />
                            <geom type="mesh" contype="0" conaffinity="0" group="1" rgba="0.75294 0.75294 0.75294 1" mesh="l_middle_dist" />
                            <geom type="mesh" rgba="0.75294 0.75294 0.75294 1" mesh="l_middle_dist" />
                        </body>
                    </body>
                    <body name="l_ring_prox" pos="-0.0131057 0.00169173 -0.160292" quat="0.00657584 -0.0314397 0.71003 -0.703438">
                        <inertial pos="0.0017239 0.0051432 -0.031065" quat="0.663344 0.00923928 0.0504839 0.746552" mass="0.011" diaginertia="9e-05 7e-05 5e-05" />
                        <joint name="l_ringMCP" pos="0 0 0" axis="1 0 0" limited="true" range="0 1.309" damping="1.0" />
                        <geom type="mesh" contype="0" conaffinity="0" group="1" rgba="0.75294 0.75294 0.75294 1" mesh="l_ring_prox" />
                        <geom type="mesh" rgba="0.75294 0.75294 0.75294 1" mesh="l_ring_prox" />
                        <body name="l_ring_dist" pos="0 0.042 0" quat="0.996565 0.08282 0 0">
                            <inertial pos="0.0017239 0.0051432 -0.031065" quat="0.663344 0.00923928 0.0504839 0.746552" mass="0.008" diaginertia="9e-05 7e-05 5e-05" />
                            <joint name="l_ringPIP" pos="0 0 0" axis="1 0 0" limited="true" range="0 2.0944" damping="1.0" />
                            <geom type="mesh" contype="0" conaffinity="0" group="1" rgba="0.75294 0.75294 0.75294 1" mesh="l_ring_dist" />
                            <geom type="mesh" rgba="0.75294 0.75294 0.75294 1" mesh="l_ring_dist" />
                        </body>
                    </body>
                    <body name="l_little_prox" pos="-0.0337273 -0.00233593 -0.153775" quat="-0.00616957 -0.0436547 0.715503 -0.697217">
                        <inertial pos="-5.4618e-07 0.016662 0.00040738" quat="0.519207 0.480025 -0.479962 0.519265" mass="0.008" diaginertia="9e-05 7e-05 5e-05" />
                        <joint name="l_littleMCP" pos="0 0 0" axis="1 0 0" limited="true" range="0 1.309" damping="1.0" />
                        <geom type="mesh" contype="0" conaffinity="0" group="1" rgba="1 1 1 1" mesh="l_little_prox" />
                        <geom type="mesh" rgba="1 1 1 1" mesh="l_little_prox" />
                        <body name="l_little_dist" pos="0 0.035 0" quat="0.994856 0.101296 0 0">
                            <inertial pos="0.0017239 0.0051432 -0.031065" quat="0.663344 0.00923928 0.0504839 0.746552" mass="0.008" diaginertia="9e-05 7e-05 5e-05" />
                            <joint name="l_littlePIP" pos="0 0 0" axis="1 0 0" limited="true" range="0 2.0944" damping="1.0" />
                            <geom type="mesh" contype="0" conaffinity="0" group="1" rgba="0.75294 0.75294 0.75294 1" mesh="l_little_dist" />
                            <geom type="mesh" rgba="0.75294 0.75294 0.75294 1" mesh="l_little_dist" />
                        </body>
                    </body>
                  </body>
                </body>
              </body>
            </body>
          </body>
        </body>
      </body>
      <body name="zarm_r1_link" pos="-0.0174999 -0.2927 0.4245">
        <inertial pos="0.00194934 0.0122207 -0.00024523" quat="0.706685 0.707107 0.0231186 0.00777912" mass="0.952" diaginertia="0.00178126 0.00174474 0.000879208"/>
        <joint name="zarm_r1_joint" pos="0 0 0" axis="0 1 0" range="-3.14159 1.5708" actuatorfrcrange="-66.67 66.67" armature="0.05" damping="0.02" frictionloss="0.02" />
        <geom type="mesh" contype="0" conaffinity="0" group="1" density="0" rgba="1 1 1 1" mesh="r_arm_pitch" />
        <geom type="capsule" size="0.05 0.02" quat="0.707105 0 0.707108 0" group="3"  class="collision-right"/>
        <body name="zarm_r2_link">
          <inertial pos="-0.00112901 -6.65e-06 -0.0463705" quat="0.705012 0.0557454 0.0555201 0.704818" mass="0.385" diaginertia="0.00115579 0.000807069 0.000697401"/>
          <joint name="zarm_r2_joint" pos="0 0 0" axis="1 0 0" range="-2.0944 0.349066" actuatorfrcrange="-75 75" armature="0.05" damping="0.02" frictionloss="0.02" />
          <geom type="mesh" contype="0" conaffinity="0" group="1" density="0" rgba="1 1 1 1" mesh="r_arm_roll" />
          <body name="zarm_r3_link">
            <inertial pos="0.00936999 -0.00334408 -0.229658" quat="0.937426 -0.0561381 -0.061759 0.338033" mass="1.7545" diaginertia="0.00708615 0.00705081 0.00168974"/>
            <joint name="zarm_r3_joint" pos="0 0 0" axis="0 0 1" range="-1.5708 1.5708" actuatorfrcrange="-57 57" armature="0.05" damping="0.02" frictionloss="0.02" />
            <geom type="mesh" contype="0" conaffinity="0" group="1" density="0" rgba="1 1 1 1" mesh="r_arm_yaw" />
            <geom type="capsule" size="0.045 0.07" pos="0 0 -0.18" group="3"  class="collision-right"/>
            <body name="zarm_r4_link" pos="0.02 0 -0.2837">
              <inertial pos="-0.0182563 -0.00149605 -0.0687769" quat="0.99685 0.0272991 0.07434 0.00421608" mass="0.6078" diaginertia="0.0014636 0.00125932 0.00063048"/>
              <joint name="zarm_r4_joint" pos="0 0 0" axis="0 1 0" range="-2.61799 0" actuatorfrcrange="-75 75" armature="0.05" damping="0.02" frictionloss="0.02" />
              <geom type="mesh" contype="0" conaffinity="0" group="1" density="0" rgba="1 1 1 1" mesh="r_forearm" />
              <geom type="capsule" size="0.045 0.09" pos="-0.02 0 -0.14" group="3"  class="collision-right"/>
              <body name="zarm_r5_link" pos="-0.02 0 -0.127037">
                <inertial pos="-0.00874165 1.372e-05 -0.0503332" quat="0.690211 0.154039 0.154059 0.690034" mass="0.6369" diaginertia="0.00094941 0.000663622 0.000516408"/>
                <joint name="zarm_r5_joint" pos="0 0 0" axis="0 0 1" range="-1.5708 1.5708" actuatorfrcrange="-14.1 14.1" armature="0.05" damping="0.02" frictionloss="0.02" />
                <geom type="mesh" contype="0" conaffinity="0" group="1" density="0" rgba="1 1 1 1" mesh="r_hand_yaw" />
                <body name="zarm_r6_link" pos="0 0 -0.106463">
                  <inertial pos="-0.00158864 -0.00654094 -0.0150668" quat="-0.126491 0.725864 -0.203587 0.644727" mass="0.4739" diaginertia="0.000274263 0.000250357 0.000178721"/>
                  <joint name="zarm_r6_joint" pos="0 0 0" axis="1 0 0" range="-0.698132 1.309" actuatorfrcrange="-14.1 14.1" armature="0.05" damping="0.02" frictionloss="0.02" />
                  <geom type="mesh" contype="0" conaffinity="0" group="1" density="0" rgba="1 1 1 1" mesh="r_hand_roll" />
                  <body name="zarm_r7_link" pos="0 0 -0.021">
                    <inertial pos="0.00396437 -0.0029234 -0.0777105" quat="0.623417 -0.146745 0.130093 0.756897" mass="0.716601" diaginertia="0.00301142 0.00293978 0.000509113"/>
                    <joint name="zarm_r7_joint" pos="0 0 0" axis="0 1 0" range="-0.698132 0.698132" actuatorfrcrange="-14.1 14.1" armature="0.05" damping="0.02" frictionloss="0.02" />
                    <geom type="mesh" contype="0" conaffinity="0" group="1" density="0" rgba="1 1 1 1" mesh="r_hand_pitch" />
                    <geom size="0.005" pos="0 0.03 -0.17" />
                    <body name="r_palm" pos="0 0 -0.07" quat="0.707388 -0.706825 0 0">
                      <inertial pos="-0.00099373 0.040537 -0.0022835" quat="1 0 0 0" mass="0.427" diaginertia="0.0010405 0.0013244 0.00053219" />
                      <geom type="mesh" contype="0" conaffinity="0" group="1" density="0" rgba="0.75294 0.75294 0.75294 1" mesh="r_palm" />
                    </body>
                    <body name="r_thumb_prox" pos="0.0245 0.0216473 -0.0941828" quat="0.685709 -0.685164 -0.173784 0.173645">
                        <inertial pos="0.0062041 -7.9383e-08 0.0015306" quat="0.486357 0.51328 0.51328 0.486357" mass="0.005" diaginertia="9e-05 7e-05 5e-05" />
                        <joint name="r_thumbCMC" pos="0 0 0" axis="0 -1 0" limited="true" range="0 1.5708" damping="1.0" />
                        <geom type="mesh" contype="0" conaffinity="0" group="1" rgba="1 1 1 1" mesh="r_thumb_prox" />
                        <geom type="mesh" rgba="1 1 1 1" mesh="r_thumb_prox" />
                        <body name="r_thumb_dist" pos="0.013647 0 0" quat="0.878532 -0.103824 0.222655 -0.409666">
                            <inertial pos="0.0083564 0.037204 -3.5884e-07" quat="0.707048 0.706981 0.0114675 0.0113604" mass="0.04" diaginertia="9e-05 7e-05 5e-05" />
                            <joint name="r_thumbMCP" pos="0 0 0" axis="0 0 1" limited="true" range="0 0.87266" damping="1.0" />
                            <geom type="mesh" contype="0" conaffinity="0" group="1" rgba="0.75294 0.75294 0.75294 1" mesh="r_thumb_dist" />
                            <geom type="mesh" rgba="0.75294 0.75294 0.75294 1" mesh="r_thumb_dist" />
                        </body>
                    </body>
                    <body name="r_index_prox" pos="0.029003 -0.00387854 -0.158234" quat="0.670793 -0.740977 -0.0307155 0.00677999">
                        <inertial pos="-5.571e-07 0.016609 0.00045746" quat="0.518542 0.480744 -0.480679 0.518602" mass="0.008" diaginertia="9e-05 7e-05 5e-05" />
                        <joint name="r_indexMCP" pos="0 0 0" axis="1 0 0" limited="true" range="0 1.309" damping="1.0" />
                        <geom type="mesh" contype="0" conaffinity="0" group="1" rgba="0.75294 0.75294 0.75294 1" mesh="r_index_prox" />
                        <geom type="mesh" rgba="0.75294 0.75294 0.75294 1" mesh="r_index_prox" />
                        <body name="r_index_dist" pos="0 0.035 0" quat="0.995322 0.0966141 0 0">
                            <inertial pos="5.9401e-06 0.025449 0.003278" quat="0.464988 0.533023 -0.533381 0.463873" mass="0.011" diaginertia="9e-05 7e-05 5e-05" />
                            <joint name="r_indexPIP" pos="0 0 0" axis="1 0 0" limited="true" range="0 2.0944" damping="1.0" />
                            <geom type="mesh" contype="0" conaffinity="0" group="1" rgba="0.75294 0.75294 0.75294 1" mesh="r_index_dist" />
                            <geom type="mesh" rgba="0.75294 0.75294 0.75294 1" mesh="r_index_dist" />
                        </body>
                    </body>
                    <body name="r_middle_prox" pos="0.008 -0.00813059 -0.161942" quat="0.68229 -0.731082 0 0">
                        <inertial pos="2.3779e-07 0.020205 0.00053993" quat="0.51393 0.485582 -0.485656 0.514028" mass="0.011" diaginertia="9e-05 7e-05 5e-05" />
                        <joint name="r_middleMCP" pos="0 0 0" axis="1 0 0" limited="true" range="0 1.309" damping="1.0" />
                        <geom type="mesh" contype="0" conaffinity="0" group="1" rgba="0.75294 0.75294 0.75294 1" mesh="r_middle_prox" />
                        <geom type="mesh" rgba="0.75294 0.75294 0.75294 1" mesh="r_middle_prox" />
                        <body name="r_middle_dist" pos="0 0.042 0" quat="0.995791 0.0916562 0 0">
                            <inertial pos="5.9404e-06 0.025449 0.003278" quat="0.464985 0.533021 -0.533384 0.463874" mass="0.011" diaginertia="9e-05 7e-05 5e-05" />
                            <joint name="r_middlePIP" pos="0 0 0" axis="1 0 0" limited="true" range="0 2.0944" damping="1.0" />
                            <geom type="mesh" contype="0" conaffinity="0" group="1" rgba="0.75294 0.75294 0.75294 1" mesh="r_middle_dist" />
                            <geom type="mesh" rgba="0.75294 0.75294 0.75294 1" mesh="r_middle_dist" />
                        </body>
                    </body>
                    <body name="r_ring_prox" pos="-0.013103 -0.00800697 -0.159953" quat="0.678234 -0.734173 0.0306456 -0.00708951">
                        <inertial pos="2.4507e-07 0.020236 0.00042373" quat="0.514454 0.485027 -0.48511 0.514552" mass="0.011" diaginertia="9e-05 7e-05 5e-05" />
                        <joint name="r_ringMCP" pos="0 0 0" axis="1 0 0" limited="true" range="0 1.309" damping="1.0" />
                        <geom type="mesh" contype="0" conaffinity="0" group="1" rgba="0.75294 0.75294 0.75294 1" mesh="r_ring_prox" />
                        <geom type="mesh" rgba="0.75294 0.75294 0.75294 1" mesh="r_ring_prox" />
                        <body name="r_ring_dist" pos="0 0.042 0" quat="0.996565 0.08282 0 0">
                            <inertial pos="5.5799e-07 0.020388 0.0029077" quat="0.461493 0.535513 -0.535785 0.46172" mass="0.008" diaginertia="9e-05 7e-05 5e-05" />
                            <joint name="r_ringPIP" pos="0 0 0" axis="1 0 0" limited="true" range="0 2.0944" damping="1.0" />
                            <geom type="mesh" contype="0" conaffinity="0" group="1" rgba="0.75294 0.75294 0.75294 1" mesh="r_ring_dist" />
                            <geom type="mesh" rgba="0.75294 0.75294 0.75294 1" mesh="r_ring_dist" />
                        </body>
                    </body>
                    <body name="r_little_prox" pos="-0.033731 -0.00356722 -0.15373" quat="0.671815 -0.739434 0.0432936 0.00521716">
                        <inertial pos="-5.4618e-07 0.016662 0.00040738" quat="0.519207 0.480025 -0.479962 0.519265" mass="0.008" diaginertia="9e-05 7e-05 5e-05" />
                        <joint name="r_littleMCP" pos="0 0 0" axis="1 0 0" limited="true" range="0 1.309" damping="1.0" />
                        <geom type="mesh" contype="0" conaffinity="0" group="1" rgba="0.75294 0.75294 0.75294 1" mesh="r_little_prox" />
                        <geom type="mesh" rgba="0.75294 0.75294 0.75294 1" mesh="r_little_prox" />
                        <body name="r_little_dist" pos="0 0.035 0" quat="0.994856 0.11296 0 0">
                            <inertial pos="1.062e-05 0.017869 0.0020864" quat="0.468752 0.529699 -0.53072 0.466934" mass="0.008" diaginertia="9e-05 7e-05 5e-05" />
                            <joint name="r_littlePIP" pos="0 0 0" axis="1 0 0" limited="true" range="0 2.0944" damping="1.0" />
                            <geom type="mesh" contype="0" conaffinity="0" group="1" rgba="0.75294 0.75294 0.75294 1" mesh="r_little_dist" />
                            <geom type="mesh" rgba="0.75294 0.75294 0.75294 1" mesh="r_little_dist" />
                        </body>
                    </body>
                  </body>
                </body>
              </body>
            </body>
          </body>
        </body>
      </body>
      <body name="zhead_1_link" pos="-0.0184999 0 0.6014">
        <inertial pos="2e-05 0.00605 -0.01052" mass="0.35" diaginertia="7e-05 5e-05 5e-05" />
        <joint name="zhead_1_joint" pos="0 0 0" axis="0 0 1" range="-1.5708 1.5708" actuatorfrcrange="-1.5 1.5" armature="0.05" damping="0.02" frictionloss="0.02" />
        <geom type="mesh" contype="0" conaffinity="0" group="1" density="0" rgba="1 1 1 1" mesh="head_yaw" />
        <body name="zhead_2_link">
          <inertial pos="0.0559806 0.00164259 0.0742994" quat="0.917221 0.110613 -0.290405 -0.249268" mass="0.882026" diaginertia="0.00751713 0.00731157 0.00385539"/>
          <joint name="zhead_2_joint" pos="0 0 0" axis="0 1 0" range="-0.523599 0.523599" actuatorfrcrange="-12 12" armature="0.05" damping="0.02" frictionloss="0.02" />
          <geom type="mesh" contype="0" conaffinity="0" group="1" density="0" rgba="1 1 1 1" mesh="head_pitch" />
          <geom size="0.11" pos="0.02 0 0.07" type="sphere" group="3"  class="collision"/>
          <geom pos="0.096751 0.0175003 0.125953" quat="0.970296 0 0.241922 0" type="mesh" contype="0" conaffinity="0" group="1" density="0" rgba="1 1 1 1" mesh="camera" />
          <geom pos="0.0217799 0 0.105417" quat="0.993413 0 0.114591 0" type="mesh" contype="0" conaffinity="0" group="1" density="0" rgba="1 1 1 1" mesh="radar" />
        </body>
      </body>
    </body>
  </worldbody>
  <actuator>
    <motor gear="1" joint="leg_l1_joint" name="leg_l1_joint_motor" ctrllimited="true" ctrlrange="-127 127" />
    <motor gear="1" joint="leg_l2_joint" name="leg_l2_joint_motor" ctrllimited="true" ctrlrange="-22.2 22.2" />
    <motor gear="1" joint="leg_l3_joint" name="leg_l3_joint_motor" ctrllimited="true" ctrlrange="-72 72" />
    <motor gear="1" joint="leg_l4_joint" name="leg_l4_joint_motor" ctrllimited="true" ctrlrange="-135 135" />
    <motor gear="1" joint="leg_l5_joint" name="leg_l5_joint_motor" ctrllimited="true" ctrlrange="-46 46" />
    <motor gear="1" joint="leg_l6_joint" name="leg_l6_joint_motor" ctrllimited="true" ctrlrange="-30 30" />
    <motor gear="1" joint="leg_r1_joint" name="leg_r1_joint_motor" ctrllimited="true" ctrlrange="-127 127" />
    <motor gear="1" joint="leg_r2_joint" name="leg_r2_joint_motor" ctrllimited="true" ctrlrange="-22.2 22.2" />
    <motor gear="1" joint="leg_r3_joint" name="leg_r3_joint_motor" ctrllimited="true" ctrlrange="-72 72" />
    <motor gear="1" joint="leg_r4_joint" name="leg_r4_joint_motor" ctrllimited="true" ctrlrange="-135 135" />
    <motor gear="1" joint="leg_r5_joint" name="leg_r5_joint_motor" ctrllimited="true" ctrlrange="-46 46" />
    <motor gear="1" joint="leg_r6_joint" name="leg_r6_joint_motor" ctrllimited="true" ctrlrange="-30 30" />
    <motor gear="1" joint="zarm_l1_joint" name="zarm_l1_joint_motor" ctrllimited="true" ctrlrange="-66.67 66.67" />
    <motor gear="1" joint="zarm_l2_joint" name="zarm_l2_joint_motor" ctrllimited="true" ctrlrange="-75 75" />
    <motor gear="1" joint="zarm_l3_joint" name="zarm_l3_joint_motor" ctrllimited="true" ctrlrange="-57 57" />
    <motor gear="1" joint="zarm_l4_joint" name="zarm_l4_joint_motor" ctrllimited="true" ctrlrange="-75 75" />
    <motor gear="1" joint="zarm_l5_joint" name="zarm_l5_joint_motor" ctrllimited="true" ctrlrange="-14.1 14.1" />
    <motor gear="1" joint="zarm_l6_joint" name="zarm_l6_joint_motor" ctrllimited="true" ctrlrange="-14.1 14.1" />
    <motor gear="1" joint="zarm_l7_joint" name="zarm_l7_joint_motor" ctrllimited="true" ctrlrange="-14.1 14.1" />
    <motor gear="1" joint="zarm_r1_joint" name="zarm_r1_joint_motor" ctrllimited="true" ctrlrange="-66.67 66.67" />
    <motor gear="1" joint="zarm_r2_joint" name="zarm_r2_joint_motor" ctrllimited="true" ctrlrange="-75 75" />
    <motor gear="1" joint="zarm_r3_joint" name="zarm_r3_joint_motor" ctrllimited="true" ctrlrange="-57 57" />
    <motor gear="1" joint="zarm_r4_joint" name="zarm_r4_joint_motor" ctrllimited="true" ctrlrange="-75 75" />
    <motor gear="1" joint="zarm_r5_joint" name="zarm_r5_joint_motor" ctrllimited="true" ctrlrange="-14.1 14.1" />
    <motor gear="1" joint="zarm_r6_joint" name="zarm_r6_joint_motor" ctrllimited="true" ctrlrange="-14.1 14.1" />
    <motor gear="1" joint="zarm_r7_joint" name="zarm_r7_joint_motor" ctrllimited="true" ctrlrange="-14.1 14.1" />
    <motor gear="1" joint="zhead_1_joint" name="zhead_1_joint_motor" ctrllimited="true" ctrlrange="-3 3" />
    <motor gear="1" joint="zhead_2_joint" name="zhead_2_joint_motor" ctrllimited="true" ctrlrange="-14.1 14.1" />
    <position gear="1" joint="l_thumbCMC" name="l_thumbCMC_motor" ctrllimited="true" ctrlrange="0 1.5708" />
    <position gear="1" joint="l_thumbMCP" name="l_thumbMCP_motor" ctrllimited="true" ctrlrange="0 0.872" />
    <position gear="1" joint="l_indexMCP" name="l_indexMCP_motor" ctrllimited="true" ctrlrange="0 1.309" />
    <position gear="1" joint="l_indexPIP" name="l_indexPIP_motor" ctrllimited="true" ctrlrange="0 1.25" />
    <position gear="1" joint="l_middleMCP" name="l_middleMCP_motor" ctrllimited="true" ctrlrange="0 1.309" />
    <position gear="1" joint="l_middlePIP" name="l_middlePIP_motor" ctrllimited="true" ctrlrange="0 1.25" />
    <position gear="1" joint="l_ringMCP" name="l_ringMCP_motor" ctrllimited="true" ctrlrange="0 1.309" />
    <position gear="1" joint="l_ringPIP" name="l_ringPIP_motor" ctrllimited="true" ctrlrange="0 1.25" />
    <position gear="1" joint="l_littleMCP" name="l_littleMCP_motor" ctrllimited="true" ctrlrange="0 1.309" />
    <position gear="1" joint="l_littlePIP" name="l_littlePIP_motor" ctrllimited="true" ctrlrange="0 1.25" />
    <position gear="1" joint="r_thumbCMC" name="r_thumbCMC_motor" ctrllimited="true" ctrlrange="0 1.5708" />
    <position gear="1" joint="r_thumbMCP" name="r_thumbMCP_motor" ctrllimited="true" ctrlrange="0 0.872" />
    <position gear="1" joint="r_indexMCP" name="r_indexMCP_motor" ctrllimited="true" ctrlrange="0 1.3095" />
    <position gear="1" joint="r_indexPIP" name="r_indexPIP_motor" ctrllimited="true" ctrlrange="0 1.25" />
    <position gear="1" joint="r_middleMCP" name="r_middleMCP_motor" ctrllimited="true" ctrlrange="0 1.309" />
    <position gear="1" joint="r_middlePIP" name="r_middlePIP_motor" ctrllimited="true" ctrlrange="0 1.25" />
    <position gear="1" joint="r_ringMCP" name="r_ringMCP_motor" ctrllimited="true" ctrlrange="0 1.309" />
    <position gear="1" joint="r_ringPIP" name="r_ringPIP_motor" ctrllimited="true" ctrlrange="0 1.25" />
    <position gear="1" joint="r_littleMCP" name="r_littleMCP_motor" ctrllimited="true" ctrlrange="0 1.309" />
    <position gear="1" joint="r_littlePIP" name="r_littlePIP_motor" ctrllimited="true" ctrlrange="0 1.25" />
  </actuator>
  <sensor>
    <accelerometer name="BodyAcc" site="imu" />
    <velocimeter name="BodyVel" site="imu" />
    <gyro name="BodyGyro" site="imu" />
    <framepos name="BodyPos" objtype="site" objname="imu" />
    <framequat name="BodyQuat" objtype="site" objname="imu" />
    <force name="l_force" site="l_ft_frame"/>
    <torque name="l_torque" site="l_ft_frame"/>
    <force name="r_force" site="r_ft_frame"/>
    <torque name="r_torque" site="r_ft_frame"/>
    <jointpos name="leg_l1_joint_pos" joint="leg_l1_joint" />
    <jointpos name="leg_l2_joint_pos" joint="leg_l2_joint" />
    <jointpos name="leg_l3_joint_pos" joint="leg_l3_joint" />
    <jointpos name="leg_l4_joint_pos" joint="leg_l4_joint" />
    <jointpos name="leg_l5_joint_pos" joint="leg_l5_joint" />
    <jointpos name="leg_l6_joint_pos" joint="leg_l6_joint" />
    <jointpos name="leg_r1_joint_pos" joint="leg_r1_joint" />
    <jointpos name="leg_r2_joint_pos" joint="leg_r2_joint" />
    <jointpos name="leg_r3_joint_pos" joint="leg_r3_joint" />
    <jointpos name="leg_r4_joint_pos" joint="leg_r4_joint" />
    <jointpos name="leg_r5_joint_pos" joint="leg_r5_joint" />
    <jointpos name="leg_r6_joint_pos" joint="leg_r6_joint" />
    <jointpos name="zarm_l1_joint_pos" joint="zarm_l1_joint" />
    <jointpos name="zarm_l2_joint_pos" joint="zarm_l2_joint" />
    <jointpos name="zarm_l3_joint_pos" joint="zarm_l3_joint" />
    <jointpos name="zarm_l4_joint_pos" joint="zarm_l4_joint" />
    <jointpos name="zarm_l5_joint_pos" joint="zarm_l5_joint" />
    <jointpos name="zarm_l6_joint_pos" joint="zarm_l6_joint" />
    <jointpos name="zarm_l7_joint_pos" joint="zarm_l7_joint" />
    <jointpos name="zarm_r1_joint_pos" joint="zarm_r1_joint" />
    <jointpos name="zarm_r2_joint_pos" joint="zarm_r2_joint" />
    <jointpos name="zarm_r3_joint_pos" joint="zarm_r3_joint" />
    <jointpos name="zarm_r4_joint_pos" joint="zarm_r4_joint" />
    <jointpos name="zarm_r5_joint_pos" joint="zarm_r5_joint" />
    <jointpos name="zarm_r6_joint_pos" joint="zarm_r6_joint" />
    <jointpos name="zarm_r7_joint_pos" joint="zarm_r7_joint" />
    <jointpos name="zhead_1_joint_pos" joint="zhead_1_joint" />
    <jointpos name="zhead_2_joint_pos" joint="zhead_2_joint" />
    <jointpos name="l_thumbCMC_pos" joint="l_thumbCMC" />
    <jointpos name="l_thumbMCP_pos" joint="l_thumbMCP" />
    <jointpos name="l_indexMCP_pos" joint="l_indexMCP" />
    <jointpos name="l_indexPIP_pos" joint="l_indexPIP" />
    <jointpos name="l_middleMCP_pos" joint="l_middleMCP" />
    <jointpos name="l_middlePIP_pos" joint="l_middlePIP" />
    <jointpos name="l_ringMCP_pos" joint="l_ringMCP" />
    <jointpos name="l_ringPIP_pos" joint="l_ringPIP" />
    <jointpos name="l_littleMCP_pos" joint="l_littleMCP" />
    <jointpos name="l_littlePIP_pos" joint="l_littlePIP" />
    <jointpos name="r_thumbCMC_pos" joint="r_thumbCMC" />
    <jointpos name="r_thumbMCP_pos" joint="r_thumbMCP" />
    <jointpos name="r_indexMCP_pos" joint="r_indexMCP" />
    <jointpos name="r_indexPIP_pos" joint="r_indexPIP" />
    <jointpos name="r_middleMCP_pos" joint="r_middleMCP" />
    <jointpos name="r_middlePIP_pos" joint="r_middlePIP" />
    <jointpos name="r_ringMCP_pos" joint="r_ringMCP" />
    <jointpos name="r_ringPIP_pos" joint="r_ringPIP" />
    <jointpos name="r_littleMCP_pos" joint="r_littleMCP" />
    <jointpos name="r_littlePIP_pos" joint="r_littlePIP" />
    <jointvel name="leg_l1_joint_vel" joint="leg_l1_joint" />
    <jointvel name="leg_l2_joint_vel" joint="leg_l2_joint" />
    <jointvel name="leg_l3_joint_vel" joint="leg_l3_joint" />
    <jointvel name="leg_l4_joint_vel" joint="leg_l4_joint" />
    <jointvel name="leg_l5_joint_vel" joint="leg_l5_joint" />
    <jointvel name="leg_l6_joint_vel" joint="leg_l6_joint" />
    <jointvel name="leg_r1_joint_vel" joint="leg_r1_joint" />
    <jointvel name="leg_r2_joint_vel" joint="leg_r2_joint" />
    <jointvel name="leg_r3_joint_vel" joint="leg_r3_joint" />
    <jointvel name="leg_r4_joint_vel" joint="leg_r4_joint" />
    <jointvel name="leg_r5_joint_vel" joint="leg_r5_joint" />
    <jointvel name="leg_r6_joint_vel" joint="leg_r6_joint" />
    <jointvel name="zarm_l1_joint_vel" joint="zarm_l1_joint" />
    <jointvel name="zarm_l2_joint_vel" joint="zarm_l2_joint" />
    <jointvel name="zarm_l3_joint_vel" joint="zarm_l3_joint" />
    <jointvel name="zarm_l4_joint_vel" joint="zarm_l4_joint" />
    <jointvel name="zarm_l5_joint_vel" joint="zarm_l5_joint" />
    <jointvel name="zarm_l6_joint_vel" joint="zarm_l6_joint" />
    <jointvel name="zarm_l7_joint_vel" joint="zarm_l7_joint" />
    <jointvel name="zarm_r1_joint_vel" joint="zarm_r1_joint" />
    <jointvel name="zarm_r2_joint_vel" joint="zarm_r2_joint" />
    <jointvel name="zarm_r3_joint_vel" joint="zarm_r3_joint" />
    <jointvel name="zarm_r4_joint_vel" joint="zarm_r4_joint" />
    <jointvel name="zarm_r5_joint_vel" joint="zarm_r5_joint" />
    <jointvel name="zarm_r6_joint_vel" joint="zarm_r6_joint" />
    <jointvel name="zarm_r7_joint_vel" joint="zarm_r7_joint" />
    <jointvel name="zhead_1_joint_vel" joint="zhead_1_joint" />
    <jointvel name="zhead_2_joint_vel" joint="zhead_2_joint" />
    <jointvel name="l_thumbCMC_vel" joint="l_thumbCMC" />
    <jointvel name="l_thumbMCP_vel" joint="l_thumbMCP" />
    <jointvel name="l_indexMCP_vel" joint="l_indexMCP" />
    <jointvel name="l_indexPIP_vel" joint="l_indexPIP" />
    <jointvel name="l_middleMCP_vel" joint="l_middleMCP" />
    <jointvel name="l_middlePIP_vel" joint="l_middlePIP" />
    <jointvel name="l_ringMCP_vel" joint="l_ringMCP" />
    <jointvel name="l_ringPIP_vel" joint="l_ringPIP" />
    <jointvel name="l_littleMCP_vel" joint="l_littleMCP" />
    <jointvel name="l_littlePIP_vel" joint="l_littlePIP" />
    <jointvel name="r_thumbCMC_vel" joint="r_thumbCMC" />
    <jointvel name="r_thumbMCP_vel" joint="r_thumbMCP" />
    <jointvel name="r_indexMCP_vel" joint="r_indexMCP" />
    <jointvel name="r_indexPIP_vel" joint="r_indexPIP" />
    <jointvel name="r_middleMCP_vel" joint="r_middleMCP" />
    <jointvel name="r_middlePIP_vel" joint="r_middlePIP" />
    <jointvel name="r_ringMCP_vel" joint="r_ringMCP" />
    <jointvel name="r_ringPIP_vel" joint="r_ringPIP" />
    <jointvel name="r_littleMCP_vel" joint="r_littleMCP" />
    <jointvel name="r_littlePIP_vel" joint="r_littlePIP" />
  </sensor>
</mujoco>
