<?xml version='1.0' encoding='utf-8'?>
<mujoco model="biped_s60">
  <compiler angle="radian" meshdir="../meshes/" />
  <size njmax="500" nconmax="100" />
  <asset>
    <mesh name="torso" file="torso.STL" />
    <mesh name="chassic" file="chassis.STL" />
    <mesh name="LF_wheel_yaw" file="LF_wheel_yaw.STL"/>
    <mesh name="LF_wheel_pitch" file="LF_wheel_pitch.STL"/>
    <mesh name="RF_wheel_yaw" file="RF_wheel_yaw.STL"/>
    <mesh name="RF_wheel_pitch" file="RF_wheel_pitch.STL"/>
    <mesh name="LB_wheel_yaw" file="LB_wheel_yaw.STL"/>
    <mesh name="LB_wheel_pitch" file="LB_wheel_pitch.STL"/>
    <mesh name="RB_wheel_yaw" file="RB_wheel_yaw.STL"/>
    <mesh name="RB_wheel_pitch" file="RB_wheel_pitch.STL"/>
    <mesh name="knee_pitch" file="knee_pitch.STL" />
    <mesh name="leg_pitch" file="leg_pitch.STL" />
    <mesh name="waist_pitch" file="waist_pitch.STL" />
    <mesh name="l_arm_pitch" file="l_arm_pitch.STL" />
    <mesh name="l_arm_roll" file="l_arm_roll.STL" />
    <mesh name="l_arm_yaw" file="l_arm_yaw.STL" />
    <mesh name="l_forearm" file="l_forearm.STL" />
    <mesh name="l_hand_yaw" file="l_hand_yaw.STL" />
    <mesh name="l_hand_roll" file="l_hand_roll.STL" />
    <mesh name="l_hand_pitch_noHand" file="l_hand_pitch_noHand.STL"/>
    <mesh name="l_hand_pitch" file="l_hand_pitch.STL" />
    <mesh name="r_arm_pitch" file="r_arm_pitch.STL" />
    <mesh name="r_arm_roll" file="r_arm_roll.STL" />
    <mesh name="r_arm_yaw" file="r_arm_yaw.STL" />
    <mesh name="r_forearm" file="r_forearm.STL" />
    <mesh name="r_hand_yaw" file="r_hand_yaw.STL" />
    <mesh name="r_hand_roll" file="r_hand_roll.STL" />
    <mesh name="r_hand_pitch" file="r_hand_pitch.STL" />
    <mesh name="r_hand_pitch_noHand" file="r_hand_pitch_noHand.STL"/>
    <mesh name="head_yaw_new" file="head_yaw_new.STL"/>
    <mesh name="head_pitch_new" file="head_pitch_new.STL"/>
    <mesh name="camera" file="camera.STL"/>
    <mesh name="radar" file="radar.STL"/>
  </asset>
  <worldbody>
    <body name="base_link" pos="0 0 0.1905">
      <freejoint />
      <site name="imu" pos="0 0 0" />
      <inertial pos="0.000389911 0.00140427 0.0591554" quat="0.647461 -0.21624 -0.323424 0.65531" mass="400.77291318" diaginertia="0.00331348 0.00204609 0.00192012" />
      <geom pos="0.2265 0 0.1853" quat="1 0 0 0" type="mesh" contype="0" conaffinity="0" group="1" density="0" rgba="1 1 1 1" mesh="chassic"/>
      <body name="LF_wheel_yaw" pos="0.253 0.1785 0.1853">
        <inertial pos="-0.00119726 -0.0347619 -0.0565346" quat="-0.0461497 0.653955 -0.0319252 0.75445" mass="0.234959" diaginertia="0.000280772 0.000254085 0.000154061"/>
        <joint name="LF_wheel_yaw_joint" pos="0 0 0" axis="0 0 1"/>
        <geom type="mesh" contype="0" conaffinity="0" group="1" density="0" rgba="0.752941 0.752941 0.752941 1" mesh="LF_wheel_yaw"/>
        <body name="LF_wheel_pitch" pos="0 0 -0.1103">
          <inertial pos="-7.69836e-07 0.0355138 7.43471e-06" quat="0.524636 0.474075 0.473988 0.524733" mass="0.522591" diaginertia="0.00193109 0.00104476 0.0010446"/>
          <joint name="LF_wheel_pitch_joint" pos="0 0 0" axis="0 1 0"/>
          <geom pos="0 -0.03595 0" quat="1 0 0 0" type="mesh" contype="0" conaffinity="0" group="1" density="0" rgba="0.52549 0.545098 0.545098 1" mesh="LF_wheel_pitch"/>
          <geom size="0.075 0.0265" quat="0.707107 0.707107 0 0" type="cylinder" rgba="0.52549 0.545098 0.545098 1"/>
        </body>
      </body>
      <body name="RF_wheel_yaw" pos="0.253 -0.1785 0.1853">
        <inertial pos="-0.000341355 0.0201288 -0.0220552" quat="0.00956902 0.68623 0.00247771 0.727317" mass="0.417517" diaginertia="0.000657396 0.00045829 0.000351353"/>
        <joint name="RF_wheel_yaw_joint" pos="0 0 0" axis="0 0 1"/>
        <geom type="mesh" contype="0" conaffinity="0" group="1" density="0" rgba="0.752941 0.752941 0.752941 1" mesh="RF_wheel_yaw"/>
        <body name="RF_wheel_pitch" pos="0 0 -0.1103">
          <inertial pos="7.69836e-07 -0.0355138 7.43471e-06" quat="0.474075 0.524636 0.524733 0.473988" mass="0.522591" diaginertia="0.00193109 0.00104476 0.0010446"/>
          <joint name="RF_wheel_pitch_joint" pos="0 0 0" axis="0 1 0" actuatorfrcrange="-10 10" damping="0.1"/>
          <geom pos="0 0.03595 0" quat="1 0 0 0" type="mesh" contype="0" conaffinity="0" group="1" density="0" rgba="0.52549 0.545098 0.545098 1" mesh="RF_wheel_pitch"/>
          <geom size="0.075 0.0265" quat="0.707107 0.707107 0 0" type="cylinder" rgba="0.52549 0.545098 0.545098 1"/>
        </body>
      </body>
      <body name="LB_wheel_yaw" pos="-0.253 0.1785 0.1853">
        <inertial pos="-0.00119726 -0.0347619 -0.0565346" quat="-0.0461497 0.653955 -0.0319252 0.75445" mass="0.234959" diaginertia="0.000280772 0.000254085 0.000154061"/>
        <joint name="LB_wheel_yaw_joint" pos="0 0 0" axis="0 0 1" actuatorfrcrange="-100 100" damping="0.0" />
        <geom type="mesh" contype="0" conaffinity="0" group="1" density="0" rgba="0.752941 0.752941 0.752941 1" mesh="LB_wheel_yaw"/>
        <body name="LB_wheel_pitch" pos="0 0 -0.1103">
          <inertial pos="-7.69836e-07 0.0355138 7.43471e-06" quat="0.524636 0.474075 0.473988 0.524733" mass="0.522591" diaginertia="0.00193109 0.00104476 0.0010446"/>
          <joint name="LB_wheel_pitch_joint" pos="0 0 0" axis="0 1 0"/>
          <geom pos="0 -0.03595 0" quat="1 0 0 0" type="mesh" contype="0" conaffinity="0" group="1" density="0" rgba="0.52549 0.545098 0.545098 1" mesh="LB_wheel_pitch"/>
          <geom size="0.075 0.0265" quat="0.707107 0.707107 0 0" type="cylinder" rgba="0.52549 0.545098 0.545098 1"/>
        </body>
      </body>
      <body name="RB_wheel_yaw" pos="-0.253 -0.1785 0.1853">
        <inertial pos="-0.000341355 0.0201288 -0.0220552" quat="0.00956902 0.68623 0.00247772 0.727317" mass="0.417517" diaginertia="0.000657396 0.00045829 0.000351353"/>
        <joint name="RB_wheel_yaw_joint" pos="0 0 0" axis="0 0 1"/>
        <geom type="mesh" contype="0" conaffinity="0" group="1" density="0" rgba="0.752941 0.752941 0.752941 1" mesh="RB_wheel_yaw"/>
        <body name="RB_wheel_pitch" pos="0 0 -0.1103">
          <inertial pos="7.69836e-07 -0.0355138 7.43471e-06" quat="0.474075 0.524636 0.524733 0.473988" mass="0.522591" diaginertia="0.00193109 0.00104476 0.0010446"/>
          <joint name="RB_wheel_pitch_joint" pos="0 0 0" axis="0 1 0"/>
          <geom pos="0 0.03595 0" quat="1 0 0 0" type="mesh" contype="0" conaffinity="0" group="1" density="0" rgba="0.52549 0.545098 0.545098 1" mesh="RB_wheel_pitch"/>
          <geom size="0.075 0.0265" quat="0.707107 0.707107 0 0" type="cylinder" rgba="0.52549 0.545098 0.545098 1"/>
        </body>
      </body>
      <body name="knee_link" pos="0.2265 0.017 0.2658">
        <inertial pos="-0.238145 0.0647732 0.0570979" quat="0.435351 0.558119 0.552674 0.439914" mass="5.3966" diaginertia="0.186986 0.17896 0.0088904"/>
        <joint name="knee_joint" pos="0 0 0" axis="0 1 0" range="0 1.44862" actuatorfrcrange="-668.53 668.53" damping="0.0"/>
        <geom type="mesh" contype="0" conaffinity="0" group="1" density="0" rgba="1 1 1 1" mesh="knee_pitch"/>
        <body name="leg_link" pos="-0.48618 0 0.11672" quat="0.992135 0 -0.125171 0">
          <inertial pos="0.238287 -0.00731845 0.038512" quat="0.56065 0.435077 0.482792 0.513119" mass="12.3565" diaginertia="0.625637 0.623592 0.0265803"/>
          <joint name="leg_joint" pos="0 0 0" axis="0 1 0" range="-2.80998 0" actuatorfrcrange="-668.53 668.53"/>
          <geom type="mesh" contype="0" conaffinity="0" group="1" density="0" rgba="1 1 1 1" mesh="leg_pitch"/>
          <body name="waist_link" pos="0.49384 0 0.078217" quat="0.993046 0 0.117726 0">
            <inertial pos="-0.00042629 -0.0163352 0.12668" quat="0.999173 0.034722 0.0086428 -0.0193137" mass="5.43056" diaginertia="0.0336183 0.0273861 0.0220449"/>
            <joint name="waist_pitch_joint" pos="0 0 0" axis="0 1 0" range="-0.15708 2.98451" actuatorfrcrange="-618.48 618.48" damping="0.0"/>
            <geom type="mesh" contype="0" conaffinity="0" group="1" density="0" rgba="1 1 1 1" mesh="waist_pitch"/>
            <body name="waist_yaw_link" pos="0 -0.0165 0.209">
              <inertial pos="0.00159298 -0.00027078 0.131874" mass="11.5609" diaginertia="0.246636 0.159377 0.158813"/>
              <joint name="waist_yaw_joint" pos="0 0 0" axis="0 0 1" range="-3.14159 3.14159" actuatorfrcrange="-618.48 618.48" damping="0.0"/>
              <geom type="mesh" contype="0" conaffinity="0" group="1" density="0" rgba="1 1 1 1" mesh="torso"/>
              <body name="zarm_l1_link" pos="0 0.2527 0.242">
                <inertial pos="0.00166796 -0.008241 0.00012987" quat="0.707107 0.707107 0 0" mass="0.916533" diaginertia="0.00126587 0.00124337 0.00086921"/>
                <joint name="zarm_l1_joint" pos="0 0 0" axis="0 1 0" range="-3.14159 1.5708" actuatorfrcrange="-66 66" damping="0.0"/>
                <geom pos="0 -0.081 0" quat="1 0 0 0" type="mesh" contype="0" conaffinity="0" group="1" density="0" rgba="1 1 1 1" mesh="l_arm_pitch"/>
                <body name="zarm_l2_link">
                  <inertial pos="-0.00080994 4.86e-06 -0.0465103" quat="0.707107 0 0 0.707107" mass="0.387674" diaginertia="0.00116144 0.00080739 0.00070223"/>
                  <joint name="zarm_l2_joint" pos="0 0 0" axis="1 0 0" range="-0.349066 3.49066" actuatorfrcrange="-75 75" damping="0.0"/>
                  <geom type="mesh" contype="0" conaffinity="0" group="1" density="0" rgba="1 1 1 1" mesh="l_arm_roll"/>
                  <body name="zarm_l3_link">
                    <inertial pos="0.00943019 0.00343988 -0.113045" quat="0.707107 0 0 0.707107" mass="1.77927" diaginertia="0.0100458 0.00992856 0.00185422"/>
                    <joint name="zarm_l3_joint" pos="0 0 0" axis="0 0 1" range="-1.48353 1.48353" actuatorfrcrange="-57 57" damping="0.0"/>
                    <geom type="mesh" contype="0" conaffinity="0" group="1" density="0" rgba="1 1 1 1" mesh="l_arm_yaw"/>
                    <body name="zarm_l4_link" pos="0.02 0 -0.2837">
                      <inertial pos="-0.0182993 0.00087167 -0.0693662" mass="0.585078" diaginertia="0.00143291 0.00125018 0.00068356"/>
                      <joint name="zarm_l4_joint" pos="0 0 0" axis="0 1 0" range="-2.61799 0" actuatorfrcrange="-75 75" damping="0.0"/>
                      <geom type="mesh" contype="0" conaffinity="0" group="1" density="0" rgba="1 1 1 1" mesh="l_forearm"/>
                      <body name="zarm_l5_link" pos="-0.02 0 -0.1195">
                        <inertial pos="0.0002609 1.322e-05 -0.0608394" quat="0.707107 0 0 0.707107" mass="0.6868" diaginertia="0.00122518 0.00086873 0.00066873"/>
                        <joint name="zarm_l5_joint" pos="0 0 0" axis="0 0 1" range="-1.5708 1.5708" actuatorfrcrange="-14.1 14.1" damping="0.0"/>
                        <geom type="mesh" contype="0" conaffinity="0" group="1" density="0" rgba="1 1 1 1" mesh="l_hand_yaw"/>
                        <body name="zarm_l6_link" pos="0 0 -0.114">
                          <inertial pos="0.00019162 0 -0.0174775" quat="0 0.707107 0 0.707107" mass="0.393872" diaginertia="0.0002021 0.00019853 0.00018535"/>
                          <joint name="zarm_l6_joint" pos="0 0 0" axis="1 0 0" range="-1.309 0.698132" actuatorfrcrange="-14.1 14.1" damping="0.0"/>
                          <geom type="mesh" contype="0" conaffinity="0" group="1" density="0" rgba="1 1 1 1" mesh="l_hand_roll"/>
                          <body name="zarm_l7_link" pos="0 0 -0.021">
                            <inertial pos="0 0 -0.102359" quat="0.707107 0 0 0.707107" mass="0.715902" diaginertia="0.00106704 0.00106284 0.00106143"/>
                            <joint name="zarm_l7_joint" pos="0 0 0" axis="0 1 0" range="-0.698132 0.698132" actuatorfrcrange="-14.1 14.1" damping="0.0"/>
                            <geom type="mesh" contype="0" conaffinity="0" group="1" density="0" rgba="1 1 1 1" mesh="l_hand_pitch_noHand"/>
                          </body>
                        </body>
                      </body>
                    </body>
                  </body>
                </body>
              </body>
              <body name="zarm_r1_link" pos="0 -0.2527 0.242">
                <inertial pos="-0.00166796 0.00839971 0.00012987" quat="0.707107 0.707107 0 0" mass="0.916533" diaginertia="0.00126587 0.00124337 0.00086921"/>
                <joint name="zarm_r1_joint" pos="0 0 0" axis="0 1 0" range="-3.14159 1.5708" actuatorfrcrange="-66 66" damping="0.0"/>
                <geom pos="0 0.081 0" quat="1 0 0 0" type="mesh" contype="0" conaffinity="0" group="1" density="0" rgba="1 1 1 1" mesh="r_arm_pitch"/>
                <body name="zarm_r2_link">
                  <inertial pos="-0.00080994 -4.86e-06 -0.0465103" quat="0.707107 0 0 0.707107" mass="0.387674" diaginertia="0.00116144 0.00080739 0.00070223"/>
                  <joint name="zarm_r2_joint" pos="0 0 0" axis="1 0 0" range="-3.49066 0.349066" actuatorfrcrange="-75 75" damping="0.0"/>
                  <geom type="mesh" contype="0" conaffinity="0" group="1" density="0" rgba="1 1 1 1" mesh="r_arm_roll"/>
                  <body name="zarm_r3_link">
                    <inertial pos="0.00943019 -0.00343988 -0.113045" quat="0.707107 0 0 0.707107" mass="1.77927" diaginertia="0.0100458 0.00992856 0.00185422"/>
                    <joint name="zarm_r3_joint" pos="0 0 0" axis="0 0 1" range="-1.48353 1.48353" actuatorfrcrange="-57 57" damping="0.0"/>
                    <geom type="mesh" contype="0" conaffinity="0" group="1" density="0" rgba="1 1 1 1" mesh="r_arm_yaw"/>
                    <body name="zarm_r4_link" pos="0.02 0 -0.2837">
                      <inertial pos="-0.0182993 -0.00087167 -0.0693662" mass="0.585078" diaginertia="0.00143291 0.00125018 0.00068356"/>
                      <joint name="zarm_r4_joint" pos="0 0 0" axis="0 1 0" range="-2.61799 0" actuatorfrcrange="-75 75" damping="0.0"/>
                      <geom type="mesh" contype="0" conaffinity="0" group="1" density="0" rgba="1 1 1 1" mesh="r_forearm"/>
                      <body name="zarm_r5_link" pos="-0.02 0 -0.1195">
                        <inertial pos="-0.0002609 -1.322e-05 -0.0608394" quat="0.707107 0 0 0.707107" mass="0.6868" diaginertia="0.00122518 0.00086873 0.00066873"/>
                        <joint name="zarm_r5_joint" pos="0 0 0" axis="0 0 1" range="-1.5708 1.5708" actuatorfrcrange="-14.1 14.1" damping="0.0"/>
                        <geom type="mesh" contype="0" conaffinity="0" group="1" density="0" rgba="1 1 1 1" mesh="r_hand_yaw"/>
                        <body name="zarm_r6_link" pos="0 0 -0.114">
                          <inertial pos="0.00019162 0 -0.0174775" quat="0 0.707107 0 0.707107" mass="0.393872" diaginertia="0.0002021 0.00019853 0.00018535"/>
                          <joint name="zarm_r6_joint" pos="0 0 0" axis="1 0 0" range="-0.698132 1.309" actuatorfrcrange="-14.1 14.1" damping="0.0"/>
                          <geom type="mesh" contype="0" conaffinity="0" group="1" density="0" rgba="1 1 1 1" mesh="r_hand_roll"/>
                          <body name="zarm_r7_link" pos="0 0 -0.021">
                            <inertial pos="0 0 -0.102359" quat="0.707107 0 0 0.707107" mass="0.715902" diaginertia="0.00106704 0.00106284 0.00106143"/>
                            <joint name="zarm_r7_joint" pos="0 0 0" axis="0 1 0" range="-0.698132 0.698132" actuatorfrcrange="-14.1 14.1" damping="0.0"/>
                            <geom type="mesh" contype="0" conaffinity="0" group="1" density="0" rgba="1 1 1 1" mesh="r_hand_pitch_noHand"/>
                          </body>
                        </body>
                      </body>
                    </body>
                  </body>
                </body>
              </body>
              <body name="zhead_1_link" pos="0 0 0.3164">
                <inertial pos="0.00173082 -0.0033509 0.0948508" quat="1 4.68903e-05 2.29385e-05 4.13671e-05" mass="0.836974" diaginertia="0.00192825 0.00185813 0.000600654"/>
                <joint name="zhead_1_joint" pos="0 0 0" axis="0 0 1" range="-1.57 1.57" actuatorfrcrange="-15.5 15.5" damping="0.0"/>
                <geom type="mesh" contype="0" conaffinity="0" group="1" density="0" rgba="1 1 1 1" mesh="head_yaw_new"/>
                <geom pos="0 0 0.059701" quat="1 0 0 0" type="mesh" contype="0" conaffinity="0" group="1" density="0" rgba="0.611765 0.658824 0.670588 1" mesh="radar"/>
                <body name="zhead_2_link" pos="0 0 0.13795">
                  <inertial pos="0.030745 -0.00383958 0.0356665" quat="0.0350967 0.715721 -0.0948585 0.691023" mass="0.851207" diaginertia="0.00556572 0.00531893 0.00393134"/>
                  <joint name="zhead_2_joint" pos="0 0 0" axis="0 1 0" range="-0.526 0.526" actuatorfrcrange="-14.5 14.5" damping="0.0"/>
                  <geom type="mesh" contype="0" conaffinity="0" group="1" density="0" rgba="1 1 1 1" mesh="head_pitch_new"/>
                  <geom pos="0.099478 0 0.032897" quat="0.984018 0 0.17807 0" type="mesh" contype="0" conaffinity="0" group="1" density="0" rgba="1 1 1 1" mesh="camera"/>
                </body>
              </body>
            </body>
          </body>
        </body>
      </body>
    </body>
  </worldbody>
  <actuator>
    <motor gear="1" joint="LF_wheel_yaw_joint"   name="LF_wheel_yaw_joint_motor"   ctrllimited="true" ctrlrange="-60 60"  />
    <motor gear="1" joint="LF_wheel_pitch_joint" name="LF_wheel_pitch_joint_motor" ctrllimited="true" ctrlrange="-60 60"  />
    <motor gear="1" joint="RF_wheel_yaw_joint"   name="RF_wheel_yaw_joint_motor"   ctrllimited="true" ctrlrange="-60 60"  />
    <motor gear="1" joint="RF_wheel_pitch_joint" name="RF_wheel_pitch_joint_motor" ctrllimited="true" ctrlrange="-60 60"  />
    <motor gear="1" joint="LB_wheel_yaw_joint"   name="LB_wheel_yaw_joint_motor"   ctrllimited="true" ctrlrange="-60 60"  />
    <motor gear="1" joint="LB_wheel_pitch_joint" name="LB_wheel_pitch_joint_motor" ctrllimited="true" ctrlrange="-60 60"  />
    <motor gear="1" joint="RB_wheel_yaw_joint"   name="RB_wheel_yaw_joint_motor"   ctrllimited="true" ctrlrange="-60 60"  />
    <motor gear="1" joint="RB_wheel_pitch_joint" name="RB_wheel_pitch_joint_motor" ctrllimited="true" ctrlrange="-60 60"  />

    <motor gear="1" joint="knee_joint" name="knee_joint_motor" ctrllimited="true" ctrlrange="-668.53 668.53" />
    <motor gear="1" joint="leg_joint" name="leg_joint_motor" ctrllimited="true" ctrlrange="-668.53 668.53" />
    <motor gear="1" joint="waist_pitch_joint" name="waist_pitch_joint_motor" ctrllimited="true" ctrlrange="-618.48 618.48" />
    <motor gear="1" joint="waist_yaw_joint" name="waist_yaw_joint_motor" ctrllimited="true" ctrlrange="-618.48 618.48" />
    <motor gear="1" joint="zarm_l1_joint" name="zarm_l1_joint_motor" ctrllimited="true" ctrlrange="-66 66" />
    <motor gear="1" joint="zarm_l2_joint" name="zarm_l2_joint_motor" ctrllimited="true" ctrlrange="-75 75" />
    <motor gear="1" joint="zarm_l3_joint" name="zarm_l3_joint_motor" ctrllimited="true" ctrlrange="-57 57" />
    <motor gear="1" joint="zarm_l4_joint" name="zarm_l4_joint_motor" ctrllimited="true" ctrlrange="-75 75" />
    <motor gear="1" joint="zarm_l5_joint" name="zarm_l5_joint_motor" ctrllimited="true" ctrlrange="-14.1 14.1" />
    <motor gear="1" joint="zarm_l6_joint" name="zarm_l6_joint_motor" ctrllimited="true" ctrlrange="-14.1 14.1" />
    <motor gear="1" joint="zarm_l7_joint" name="zarm_l7_joint_motor" ctrllimited="true" ctrlrange="-14.1 14.1" />
    <motor gear="1" joint="zarm_r1_joint" name="zarm_r1_joint_motor" ctrllimited="true" ctrlrange="-66 66" />
    <motor gear="1" joint="zarm_r2_joint" name="zarm_r2_joint_motor" ctrllimited="true" ctrlrange="-75 75" />
    <motor gear="1" joint="zarm_r3_joint" name="zarm_r3_joint_motor" ctrllimited="true" ctrlrange="-57 57" />
    <motor gear="1" joint="zarm_r4_joint" name="zarm_r4_joint_motor" ctrllimited="true" ctrlrange="-75 75" />
    <motor gear="1" joint="zarm_r5_joint" name="zarm_r5_joint_motor" ctrllimited="true" ctrlrange="-14.1 14.1" />
    <motor gear="1" joint="zarm_r6_joint" name="zarm_r6_joint_motor" ctrllimited="true" ctrlrange="-14.1 14.1" />
    <motor gear="1" joint="zarm_r7_joint" name="zarm_r7_joint_motor" ctrllimited="true" ctrlrange="-14.1 14.1" />
    <motor gear="1" joint="zhead_1_joint" name="zhead_1_joint_motor" ctrllimited="true" ctrlrange="-14.1 14.1" />
    <motor gear="1" joint="zhead_2_joint" name="zhead_2_joint_motor" ctrllimited="true" ctrlrange="-14.1 14.1" />
  </actuator>
  <sensor>
    <accelerometer name="BodyAcc" site="imu" />
    <velocimeter name="BodyVel" site="imu" />
    <gyro name="BodyGyro" site="imu" />
    <framepos name="BodyPos" objtype="site" objname="imu" />
    <framequat name="BodyQuat" objtype="site" objname="imu" />

    <jointpos name="LF_wheel_yaw_joint_pos"   joint="LF_wheel_yaw_joint"   />
    <jointpos name="LF_wheel_pitch_joint_pos" joint="LF_wheel_pitch_joint" />
    <jointpos name="RF_wheel_yaw_joint_pos"   joint="RF_wheel_yaw_joint"   />
    <jointpos name="RF_wheel_pitch_joint_pos" joint="RF_wheel_pitch_joint" />
    <jointpos name="LB_wheel_yaw_joint_pos"   joint="LB_wheel_yaw_joint"   />
    <jointpos name="LB_wheel_pitch_joint_pos" joint="LB_wheel_pitch_joint" />
    <jointpos name="RB_wheel_yaw_joint_pos"   joint="RB_wheel_yaw_joint"   />
    <jointpos name="RB_wheel_pitch_joint_pos" joint="RB_wheel_pitch_joint" />

    <jointpos name="knee_joint_pos" joint="knee_joint" />
    <jointpos name="leg_joint_pos" joint="leg_joint" />
    <jointpos name="waist_pitch_joint_pos" joint="waist_pitch_joint" />
    <jointpos name="waist_yaw_joint_pos" joint="waist_yaw_joint" />
    <jointpos name="zarm_l1_joint_pos" joint="zarm_l1_joint" />
    <jointpos name="zarm_l2_joint_pos" joint="zarm_l2_joint" />
    <jointpos name="zarm_l3_joint_pos" joint="zarm_l3_joint" />
    <jointpos name="zarm_l4_joint_pos" joint="zarm_l4_joint" />
    <jointpos name="zarm_l5_joint_pos" joint="zarm_l5_joint" />
    <jointpos name="zarm_l6_joint_pos" joint="zarm_l6_joint" />
    <jointpos name="zarm_l7_joint_pos" joint="zarm_l7_joint" />
    <jointpos name="zarm_r1_joint_pos" joint="zarm_r1_joint" />
    <jointpos name="zarm_r2_joint_pos" joint="zarm_r2_joint" />
    <jointpos name="zarm_r3_joint_pos" joint="zarm_r3_joint" />
    <jointpos name="zarm_r4_joint_pos" joint="zarm_r4_joint" />
    <jointpos name="zarm_r5_joint_pos" joint="zarm_r5_joint" />
    <jointpos name="zarm_r6_joint_pos" joint="zarm_r6_joint" />
    <jointpos name="zarm_r7_joint_pos" joint="zarm_r7_joint" />
    <jointpos name="zhead_1_joint_pos" joint="zhead_1_joint" />
    <jointpos name="zhead_2_joint_pos" joint="zhead_2_joint" />

    <jointvel name="LF_wheel_yaw_joint_vel"   joint="LF_wheel_yaw_joint"   />
    <jointvel name="LF_wheel_pitch_joint_vel" joint="LF_wheel_pitch_joint" />
    <jointvel name="RF_wheel_yaw_joint_vel"   joint="RF_wheel_yaw_joint"   />
    <jointvel name="RF_wheel_pitch_joint_vel" joint="RF_wheel_pitch_joint" />
    <jointvel name="LB_wheel_yaw_joint_vel"   joint="LB_wheel_yaw_joint"   />
    <jointvel name="LB_wheel_pitch_joint_vel" joint="LB_wheel_pitch_joint" />
    <jointvel name="RB_wheel_yaw_joint_vel"   joint="RB_wheel_yaw_joint"   />
    <jointvel name="RB_wheel_pitch_joint_vel" joint="RB_wheel_pitch_joint" />

    <jointvel name="knee_joint_vel" joint="knee_joint" />
    <jointvel name="leg_joint_vel" joint="leg_joint" />
    <jointvel name="waist_pitch_joint_vel" joint="waist_pitch_joint" />
    <jointvel name="waist_yaw_joint_vel" joint="waist_yaw_joint" />
    <jointvel name="zarm_l1_joint_vel" joint="zarm_l1_joint" />
    <jointvel name="zarm_l2_joint_vel" joint="zarm_l2_joint" />
    <jointvel name="zarm_l3_joint_vel" joint="zarm_l3_joint" />
    <jointvel name="zarm_l4_joint_vel" joint="zarm_l4_joint" />
    <jointvel name="zarm_l5_joint_vel" joint="zarm_l5_joint" />
    <jointvel name="zarm_l6_joint_vel" joint="zarm_l6_joint" />
    <jointvel name="zarm_l7_joint_vel" joint="zarm_l7_joint" />
    <jointvel name="zarm_r1_joint_vel" joint="zarm_r1_joint" />
    <jointvel name="zarm_r2_joint_vel" joint="zarm_r2_joint" />
    <jointvel name="zarm_r3_joint_vel" joint="zarm_r3_joint" />
    <jointvel name="zarm_r4_joint_vel" joint="zarm_r4_joint" />
    <jointvel name="zarm_r5_joint_vel" joint="zarm_r5_joint" />
    <jointvel name="zarm_r6_joint_vel" joint="zarm_r6_joint" />
    <jointvel name="zarm_r7_joint_vel" joint="zarm_r7_joint" />
    <jointvel name="zhead_1_joint_vel" joint="zhead_1_joint" />
    <jointvel name="zhead_2_joint_vel" joint="zhead_2_joint" />
  </sensor>


  <!-- 用于固定底盘，可在测试关节可达空间时使用 -->
  <!-- <equality>
    <weld name="weld" body1="world" body2="base_link" relpose="0 0 0.1905 1 0 0 0"/>
  </equality> -->
</mujoco>
